File: XRR/CWO014_reflectivity.ras
*RAS_DATA_START
*RAS_HEADER_START
*DISP_FMT_X "%.4f"
*DISP_FMT_Y "%.0f"
*DISP_FULLSCALE "30425041.6999999990"
*DISP_LINE_COLOR "255.0000000000"
*DISP_LINE_STYLE "0.0000000000"
*DISP_LINE_WIDTH "0.2500000000"
*DISP_NOTE "Collected Data-54"
*DISP_OFFSET_Y "0.0000000000"
*DISP_PEAKSEARCH_UNIT_Y "cps"
*DISP_RANGE_BOTTOM "0.0100000000"
*DISP_RANGE_LEFT "-0.0006000000"
*DISP_RANGE_LOGCUTOFF "0.0100000000"
*DISP_RANGE_RIGHT "6.0006000000"
*DISP_RANGE_TOP "30425041.6999999990"
*DISP_SCALE_MODE_Y "2.0000000000"
*DISP_TAB_NAME "2-Theta/Omega"
*DISP_TITLE_Y "Intensity"
*DISP_UNIT_Y "cps"
*DISP_WINDOW_NAME "MSG_MACROENGINE"
*FILE_COMMENT " "
*FILE_MD5 ""
*FILE_MEMO " "
*FILE_OPERATOR "administrator"
*FILE_PART_ID "MEAS_KHP2_00055"
*FILE_SAMPLE "CWO 014"
*FILE_TYPE "RAS_RAW"
*FILE_USERGROUP "System Manager"
*FILE_VERSION "1.0000000000"
*HW_ATTACHMENT_ID "ATT0025"
*HW_ATTACHMENT_NAME "標準|Standard"
*HW_COUNTER_ID-0 "CUT0025"
*HW_COUNTER_ID-1 "CUT0020"
*HW_COUNTER_ID-2 "CUT0020"
*HW_COUNTER_ID-3 "CSL0021"
*HW_COUNTER_ID-4 "CMC0021"
*HW_COUNTER_NAME-0 "D/teX Ultra|D/teX Ultra"
*HW_COUNTER_NAME-1 "None|None"
*HW_COUNTER_NAME-2 "None|None"
*HW_COUNTER_NAME-3 "BBM|BBM"
*HW_COUNTER_NAME-4 "検出器モノクロメータ|Detector monochromator"
*HW_COUNTER_SELECT_NAME "D/teX Ultra|D/teX Ultra"
*HW_GONIOMETER_ID "GON0023"
*HW_GONIOMETER_NAME "SmartLab|SmartLab"
*HW_GONIOMETER_RADIUS-0 "90.0"
*HW_GONIOMETER_RADIUS-1 "114.0"
*HW_GONIOMETER_RADIUS-2 "190.0"
*HW_GONIOMETER_RADIUS-3 "300.0"
*HW_GONIOMETER_RADIUS-4 "187.0"
*HW_GONIOMETER_RADIUS-5 "300.0"
*HW_GONIOMETER_RADIUS-6 "113.0"
*HW_GONIOMETER_RADIUS-7 "331.0"
*HW_I_OPT_ID-0 "CBO0021"
*HW_I_OPT_ID-1 "ICR0021"
*HW_I_OPT_ID-2 "ISL0021"
*HW_I_OPT_ID-3 "ISO0021"
*HW_I_OPT_ID-4 "IAD0021"
*HW_I_OPT_ID-5 "IPR0001"
*HW_I_OPT_NAME-0 "CBOユニット|CBO unit"
*HW_I_OPT_NAME-1 "標準入射光学ユニット|Standard incident optical unit"
*HW_I_OPT_NAME-2 "標準入射スリットボックス|Standard incident slit box"
*HW_I_OPT_NAME-3 "入射平行スリット|Incident parallel slit"
*HW_I_OPT_NAME-4 "長手制限スリット|Length limiting slit"
*HW_I_OPT_NAME-5 "None|None"
*HW_R_ATTENUATER_AUTOMODE "1"
*HW_R_OPT_ID-0 "RSS0021"
*HW_R_OPT_ID-1 "RCR0023"
*HW_R_OPT_ID-2 "RSO0021"
*HW_R_OPT_ID-3 "RRS0021"
*HW_R_OPT_ID-4 "ATN0021"
*HW_R_OPT_ID-5 "RFL0021"
*HW_R_OPT_ID-6 "RAD0021"
*HW_R_OPT_NAME-0 "標準受光スリットボックス1|Standard receiving slit box # 1"
*HW_R_OPT_NAME-1 "標準受光光学ユニット1|Standard receiving unit # 1"
*HW_R_OPT_NAME-2 "標準受光光学ユニット2|Standard receiving optical unit # 2"
*HW_R_OPT_NAME-3 "標準受光スリットボックス2|Standard receiving slit box # 2"
*HW_R_OPT_NAME-4 "標準アッテネータ|Standard Attenuator"
*HW_R_OPT_NAME-5 "Cu Kβ|Cu K-beta"
*HW_R_OPT_NAME-6 "調整用受光スリット|Alignment receiving slit"
*HW_SAMPLE_HOLDER_ID "SMP0021"
*HW_SAMPLE_HOLDER_NAME "χφZクレードル|Chi phi Z cradle"
*HW_XG_CURRENT_MAX "200"
*HW_XG_CURRENT_MIN "10"
*HW_XG_CURRENT_RESOLUTION "1"
*HW_XG_CURRENT_UNIT "mA"
*HW_XG_FOCUS "0.4mm x 8mm"
*HW_XG_FOCUS_TYPE "Normal"
*HW_XG_ID "1700"
*HW_XG_NAME "9kW 開放管(45kV 200mA ID:1700)|9kW Rotating anode(45kV 200mA ID:1700)"
*HW_XG_TARGET_ATOMIC_NUMBER "29.0000000000"
*HW_XG_TARGET_NAME "Cu"
*HW_XG_TYPE "Rota"
*HW_XG_VOLTAGE_MAX "45"
*HW_XG_VOLTAGE_MIN "20"
*HW_XG_VOLTAGE_RESOLUTION "1"
*HW_XG_VOLTAGE_UNIT "kV"
*HW_XG_WATT_MAX "9.00"
*HW_XG_WATT_UNIT "kW"
*HW_XG_WAVE_LENGTH_ALPHA1 "1.540593"
*HW_XG_WAVE_LENGTH_ALPHA2 "1.544414"
*HW_XG_WAVE_LENGTH_BETA "1.392250"
*MEAS_COND_AXIS_NAME-0 "Theta/2-Theta"
*MEAS_COND_AXIS_NAME-1 "2-Theta"
*MEAS_COND_AXIS_NAME-2 "Omega"
*MEAS_COND_AXIS_NAME-3 "Chi"
*MEAS_COND_AXIS_NAME-4 "Phi"
*MEAS_COND_AXIS_NAME-5 "Z"
*MEAS_COND_AXIS_NAME-6 "2-Theta/Omega"
*MEAS_COND_AXIS_NAME-7 "Theta_s"
*MEAS_COND_AXIS_NAME-8 "Theta_d"
*MEAS_COND_AXIS_NAME-9 "Ts"
*MEAS_COND_AXIS_NAME-10 "CBO selection slit"
*MEAS_COND_AXIS_NAME-11 "M"
*MEAS_COND_AXIS_NAME-12 "Incident parallel slit"
*MEAS_COND_AXIS_NAME-13 "Incident slit"
*MEAS_COND_AXIS_NAME-14 ""
*MEAS_COND_AXIS_NAME-15 "Zs"
*MEAS_COND_AXIS_NAME-16 "Incident optical device"
*MEAS_COND_AXIS_NAME-17 "Omega_m"
*MEAS_COND_AXIS_NAME-18 "Length limiting slit"
*MEAS_COND_AXIS_NAME-19 "Center slit"
*MEAS_COND_AXIS_NAME-20 "Filter"
*MEAS_COND_AXIS_NAME-21 "Receiving slit # 1"
*MEAS_COND_AXIS_NAME-22 "Receiving slit # 2"
*MEAS_COND_AXIS_NAME-23 "Receiving optical device"
*MEAS_COND_AXIS_NAME-24 "Receiving parallel slit"
*MEAS_COND_AXIS_NAME-25 "Alignment receiving slit"
*MEAS_COND_AXIS_NAME-26 ""
*MEAS_COND_AXIS_NAME-27 ""
*MEAS_COND_AXIS_NAME-28 "Zd"
*MEAS_COND_AXIS_NAME-29 "Attenuator"
*MEAS_COND_AXIS_NAME-30 "Diffracted beam monochromator"
*MEAS_COND_AXIS_NAME-31 "Monochromator slit"
*MEAS_COND_AXIS_NAME-32 "Primary beam"
*MEAS_COND_AXIS_NAME-33 ""
*MEAS_COND_AXIS_NAME-34 ""
*MEAS_COND_AXIS_NAME-35 "PHA"
*MEAS_COND_AXIS_NAME_INTERNAL-0 "TwoThetaTheta"
*MEAS_COND_AXIS_NAME_INTERNAL-1 "TwoTheta"
*MEAS_COND_AXIS_NAME_INTERNAL-2 "Omega"
*MEAS_COND_AXIS_NAME_INTERNAL-3 "Chi"
*MEAS_COND_AXIS_NAME_INTERNAL-4 "Phi"
*MEAS_COND_AXIS_NAME_INTERNAL-5 "Z"
*MEAS_COND_AXIS_NAME_INTERNAL-6 "TwoThetaOmega"
*MEAS_COND_AXIS_NAME_INTERNAL-7 "ThetaS"
*MEAS_COND_AXIS_NAME_INTERNAL-8 "ThetaD"
*MEAS_COND_AXIS_NAME_INTERNAL-9 "Ts"
*MEAS_COND_AXIS_NAME_INTERNAL-10 "CBO"
*MEAS_COND_AXIS_NAME_INTERNAL-11 "CBO-M"
*MEAS_COND_AXIS_NAME_INTERNAL-12 "IncidentSollerSlit"
*MEAS_COND_AXIS_NAME_INTERNAL-13 "IncidentSlitBox"
*MEAS_COND_AXIS_NAME_INTERNAL-14 "IncidentSlitBox-_Axis"
*MEAS_COND_AXIS_NAME_INTERNAL-15 "Zs"
*MEAS_COND_AXIS_NAME_INTERNAL-16 "IncidentMonochromator"
*MEAS_COND_AXIS_NAME_INTERNAL-17 "IncidentMonochromator-OmegaM"
*MEAS_COND_AXIS_NAME_INTERNAL-18 "IncidentAxdSlit"
*MEAS_COND_AXIS_NAME_INTERNAL-19 "CenterSlit"
*MEAS_COND_AXIS_NAME_INTERNAL-20 "Filter"
*MEAS_COND_AXIS_NAME_INTERNAL-21 "ReceivingSlitBox1"
*MEAS_COND_AXIS_NAME_INTERNAL-22 "ReceivingSlitBox2"
*MEAS_COND_AXIS_NAME_INTERNAL-23 "ReceivingOptics"
*MEAS_COND_AXIS_NAME_INTERNAL-24 "ReceivingSollerSlit"
*MEAS_COND_AXIS_NAME_INTERNAL-25 "ReceivingAxdSlit"
*MEAS_COND_AXIS_NAME_INTERNAL-26 "ReceivingSlitBox1-_Axis"
*MEAS_COND_AXIS_NAME_INTERNAL-27 "ReceivingSlitBox2-_Axis"
*MEAS_COND_AXIS_NAME_INTERNAL-28 "ReceivingSlitBox2-Zd"
*MEAS_COND_AXIS_NAME_INTERNAL-29 "Attenuator"
*MEAS_COND_AXIS_NAME_INTERNAL-30 "CounterMonochromator"
*MEAS_COND_AXIS_NAME_INTERNAL-31 "CounterSlit"
*MEAS_COND_AXIS_NAME_INTERNAL-32 "IncidentPrimary"
*MEAS_COND_AXIS_NAME_INTERNAL-33 "AlphaR"
*MEAS_COND_AXIS_NAME_INTERNAL-34 "BetaR"
*MEAS_COND_AXIS_NAME_INTERNAL-35 "PHA"
*MEAS_COND_AXIS_NAME_MAGICNO-0 "83951616.0000000000"
*MEAS_COND_AXIS_NAME_MAGICNO-1 "268632064.0000000000"
*MEAS_COND_AXIS_NAME_MAGICNO-2 "268500992.0000000000"
*MEAS_COND_AXIS_NAME_MAGICNO-3 "268500992.0000000000"
*MEAS_COND_AXIS_NAME_MAGICNO-4 "268500992.0000000000"
*MEAS_COND_AXIS_NAME_MAGICNO-5 "285278208.0000000000"
*MEAS_COND_AXIS_NAME_MAGICNO-6 "83951616.0000000000"
*MEAS_COND_AXIS_NAME_MAGICNO-7 "131072.0000000000"
*MEAS_COND_AXIS_NAME_MAGICNO-8 "131072.0000000000"
*MEAS_COND_AXIS_NAME_MAGICNO-9 "318898176.0000000000"
*MEAS_COND_AXIS_NAME_MAGICNO-10 "20971521.0000000000"
*MEAS_COND_AXIS_NAME_MAGICNO-11 "285343744.0000000000"
*MEAS_COND_AXIS_NAME_MAGICNO-12 "20971521.0000000000"
*MEAS_COND_AXIS_NAME_MAGICNO-13 "22020097.0000000000"
*MEAS_COND_AXIS_NAME_MAGICNO-14 "25165824.0000000000"
*MEAS_COND_AXIS_NAME_MAGICNO-15 "318898176.0000000000"
*MEAS_COND_AXIS_NAME_MAGICNO-16 "20971521.0000000000"
*MEAS_COND_AXIS_NAME_MAGICNO-17 "285343744.0000000000"
*MEAS_COND_AXIS_NAME_MAGICNO-18 "20971521.0000000000"
*MEAS_COND_AXIS_NAME_MAGICNO-19 "20971521.0000000000"
*MEAS_COND_AXIS_NAME_MAGICNO-20 "20971521.0000000000"
*MEAS_COND_AXIS_NAME_MAGICNO-21 "23068673.0000000000"
*MEAS_COND_AXIS_NAME_MAGICNO-22 "23068673.0000000000"
*MEAS_COND_AXIS_NAME_MAGICNO-23 "20971521.0000000000"
*MEAS_COND_AXIS_NAME_MAGICNO-24 "20971521.0000000000"
*MEAS_COND_AXIS_NAME_MAGICNO-25 "20971521.0000000000"
*MEAS_COND_AXIS_NAME_MAGICNO-26 "25165824.0000000000"
*MEAS_COND_AXIS_NAME_MAGICNO-27 "25165824.0000000000"
*MEAS_COND_AXIS_NAME_MAGICNO-28 "285343744.0000000000"
*MEAS_COND_AXIS_NAME_MAGICNO-29 "17301505.0000000000"
*MEAS_COND_AXIS_NAME_MAGICNO-30 "20971521.0000000000"
*MEAS_COND_AXIS_NAME_MAGICNO-31 "20971521.0000000000"
*MEAS_COND_AXIS_NAME_MAGICNO-32 "20971521.0000000000"
*MEAS_COND_AXIS_NAME_MAGICNO-33 "8388608.0000000000"
*MEAS_COND_AXIS_NAME_MAGICNO-34 "8388608.0000000000"
*MEAS_COND_AXIS_NAME_MAGICNO-35 "0.0000000000"
*MEAS_COND_AXIS_OFFSET-0 "-"
*MEAS_COND_AXIS_OFFSET-1 "0.8950000000"
*MEAS_COND_AXIS_OFFSET-2 "0.7066000000"
*MEAS_COND_AXIS_OFFSET-3 "0.0000000000"
*MEAS_COND_AXIS_OFFSET-4 "0.0000000000"
*MEAS_COND_AXIS_OFFSET-5 "-"
*MEAS_COND_AXIS_OFFSET-6 "-"
*MEAS_COND_AXIS_OFFSET-7 "0.7066000000"
*MEAS_COND_AXIS_OFFSET-8 "0.1884000000"
*MEAS_COND_AXIS_OFFSET-9 "-"
*MEAS_COND_AXIS_OFFSET-10 "-"
*MEAS_COND_AXIS_OFFSET-11 "-"
*MEAS_COND_AXIS_OFFSET-12 "-"
*MEAS_COND_AXIS_OFFSET-13 "-"
*MEAS_COND_AXIS_OFFSET-14 "-"
*MEAS_COND_AXIS_OFFSET-15 "-"
*MEAS_COND_AXIS_OFFSET-16 "-"
*MEAS_COND_AXIS_OFFSET-17 "-"
*MEAS_COND_AXIS_OFFSET-18 "-"
*MEAS_COND_AXIS_OFFSET-19 "-"
*MEAS_COND_AXIS_OFFSET-20 "-"
*MEAS_COND_AXIS_OFFSET-21 "-"
*MEAS_COND_AXIS_OFFSET-22 "-"
*MEAS_COND_AXIS_OFFSET-23 "-"
*MEAS_COND_AXIS_OFFSET-24 "-"
*MEAS_COND_AXIS_OFFSET-25 "-"
*MEAS_COND_AXIS_OFFSET-26 "-"
*MEAS_COND_AXIS_OFFSET-27 "-"
*MEAS_COND_AXIS_OFFSET-28 "-"
*MEAS_COND_AXIS_OFFSET-29 "-"
*MEAS_COND_AXIS_OFFSET-30 "-"
*MEAS_COND_AXIS_OFFSET-31 "-"
*MEAS_COND_AXIS_OFFSET-32 "-"
*MEAS_COND_AXIS_OFFSET-33 "0.0000000000"
*MEAS_COND_AXIS_OFFSET-34 "0.0000000000"
*MEAS_COND_AXIS_OFFSET-35 "-"
*MEAS_COND_AXIS_POSITION-0 "-0.0008000000"
*MEAS_COND_AXIS_POSITION-1 "-0.0008000000"
*MEAS_COND_AXIS_POSITION-2 "-0.0004000000"
*MEAS_COND_AXIS_POSITION-3 "0.0000000000"
*MEAS_COND_AXIS_POSITION-4 "0.0000000000"
*MEAS_COND_AXIS_POSITION-5 "-1.4203000000"
*MEAS_COND_AXIS_POSITION-6 "-0.0008000000"
*MEAS_COND_AXIS_POSITION-7 "-0.0004000000"
*MEAS_COND_AXIS_POSITION-8 "-0.0004000000"
*MEAS_COND_AXIS_POSITION-9 "-4.7636900000"
*MEAS_COND_AXIS_POSITION-10 "PB"
*MEAS_COND_AXIS_POSITION-11 "0.0000000000"
*MEAS_COND_AXIS_POSITION-12 "Soller_slit_open_s"
*MEAS_COND_AXIS_POSITION-13 "0.250mm"
*MEAS_COND_AXIS_POSITION-14 "0.2500000000"
*MEAS_COND_AXIS_POSITION-15 "-0.9021900000"
*MEAS_COND_AXIS_POSITION-16 "Ge(220)x2"
*MEAS_COND_AXIS_POSITION-17 "0.0000000000"
*MEAS_COND_AXIS_POSITION-18 "2.0mm"
*MEAS_COND_AXIS_POSITION-19 "None"
*MEAS_COND_AXIS_POSITION-20 "None"
*MEAS_COND_AXIS_POSITION-21 "0.250mm"
*MEAS_COND_AXIS_POSITION-22 "0.250mm"
*MEAS_COND_AXIS_POSITION-23 "No_unit"
*MEAS_COND_AXIS_POSITION-24 "Soller_slit_5.0deg"
*MEAS_COND_AXIS_POSITION-25 "None"
*MEAS_COND_AXIS_POSITION-26 "0.2500000000"
*MEAS_COND_AXIS_POSITION-27 "0.2500000000"
*MEAS_COND_AXIS_POSITION-28 "0.0893700000"
*MEAS_COND_AXIS_POSITION-29 "1/10000"
*MEAS_COND_AXIS_POSITION-30 "None"
*MEAS_COND_AXIS_POSITION-31 "None"
*MEAS_COND_AXIS_POSITION-32 "None"
*MEAS_COND_AXIS_POSITION-33 "0.0000000000"
*MEAS_COND_AXIS_POSITION-34 "43.1000000000"
*MEAS_COND_AXIS_POSITION-35 "34.0000000000"
*MEAS_COND_AXIS_UNIT-0 "deg"
*MEAS_COND_AXIS_UNIT-1 "deg"
*MEAS_COND_AXIS_UNIT-2 "deg"
*MEAS_COND_AXIS_UNIT-3 "deg"
*MEAS_COND_AXIS_UNIT-4 "deg"
*MEAS_COND_AXIS_UNIT-5 "mm"
*MEAS_COND_AXIS_UNIT-6 "deg"
*MEAS_COND_AXIS_UNIT-7 "deg"
*MEAS_COND_AXIS_UNIT-8 "deg"
*MEAS_COND_AXIS_UNIT-9 "mm"
*MEAS_COND_AXIS_UNIT-10 ""
*MEAS_COND_AXIS_UNIT-11 "pulse"
*MEAS_COND_AXIS_UNIT-12 ""
*MEAS_COND_AXIS_UNIT-13 ""
*MEAS_COND_AXIS_UNIT-14 "mm"
*MEAS_COND_AXIS_UNIT-15 "mm"
*MEAS_COND_AXIS_UNIT-16 ""
*MEAS_COND_AXIS_UNIT-17 "pulse"
*MEAS_COND_AXIS_UNIT-18 ""
*MEAS_COND_AXIS_UNIT-19 ""
*MEAS_COND_AXIS_UNIT-20 ""
*MEAS_COND_AXIS_UNIT-21 ""
*MEAS_COND_AXIS_UNIT-22 ""
*MEAS_COND_AXIS_UNIT-23 ""
*MEAS_COND_AXIS_UNIT-24 ""
*MEAS_COND_AXIS_UNIT-25 ""
*MEAS_COND_AXIS_UNIT-26 "mm"
*MEAS_COND_AXIS_UNIT-27 "mm"
*MEAS_COND_AXIS_UNIT-28 "mm"
*MEAS_COND_AXIS_UNIT-29 ""
*MEAS_COND_AXIS_UNIT-30 ""
*MEAS_COND_AXIS_UNIT-31 ""
*MEAS_COND_AXIS_UNIT-32 ""
*MEAS_COND_AXIS_UNIT-33 "deg"
*MEAS_COND_AXIS_UNIT-34 "deg"
*MEAS_COND_AXIS_UNIT-35 "div"
*MEAS_COND_COUNTER_CNTLOSS_CORR "0.0000000000"
*MEAS_COND_COUNTER_PHABASE "34.0000000000"
*MEAS_COND_COUNTER_PHAWINDOW "19.0000000000"
*MEAS_COND_COUNTER_PHA_UNIT "div"
*MEAS_COND_COUNTER_TAUDIFF "2.0000000000"
*MEAS_COND_COUNTER_TAUINT "0.1000000000"
*MEAS_COND_IRRADIATION_MODE "OFF"
*MEAS_COND_IRRADIATION_WIDTH ""
*MEAS_COND_OPT_ATTR "High resolution parallel beam Ge(220)x2/RS"
*MEAS_COND_OPT_NAME "@High resolution PB-Ge(220)x2"
*MEAS_COND_UNSYMMETRIC_MODE "OFF"
*MEAS_COND_XG_CURRENT "200.0000000000"
*MEAS_COND_XG_VOLTAGE "45.0000000000"
*MEAS_COND_XG_WAVE_TYPE "Ka1"
*MEAS_DATA_COUNT "3001.0000000000"
*MEAS_SCAN_AXIS_X "2-Theta/Omega"
*MEAS_SCAN_AXIS_X_INTERNAL "TwoThetaOmega"
*MEAS_SCAN_END_TIME "07/27/23 11:47:14"
*MEAS_SCAN_MODE "CONTINUOUS"
*MEAS_SCAN_MONITOR "0"
*MEAS_SCAN_RESOLUTION_X "0.0002"
*MEAS_SCAN_SPEED "0.500000"
*MEAS_SCAN_SPEED_UNIT "deg/min"
*MEAS_SCAN_SPEED_USER "0.500000"
*MEAS_SCAN_START "0.0000000000"
*MEAS_SCAN_START_TIME "07/27/23 11:34:43"
*MEAS_SCAN_STEP "0.0020000000"
*MEAS_SCAN_STOP "6.0000000000"
*MEAS_SCAN_UNIT_X "deg"
*MEAS_SCAN_UNIT_Y "counts"
*RAS_HEADER_END
*RAS_INT_START
0.0000 5995360.5000 1.0000
0.0060 5948330.0000 1.0000
0.0120 5811514.0000 1.0000
0.0180 5613048.0000 1.0000
0.0240 5368930.5000 1.0000
0.0300 4973239.0000 1.0000
0.0360 4452041.5000 1.0000
0.0420 3439160.7500 1.0000
0.0480 2557993.0000 1.0000
0.0540 1693099.7500 1.0000
0.0600 1055081.3750 1.0000
0.0660 524147.9375 1.0000
0.0720 261481.8906 1.0000
0.0780 148611.7344 1.0000
0.0840 97944.9219 1.0000
0.0900 76339.0938 1.0000
0.0960 67736.9844 1.0000
0.1020 62248.0156 1.0000
0.1080 61756.4688 1.0000
0.1140 66671.9609 1.0000
0.1200 72764.1953 1.0000
0.1260 73769.6328 1.0000
0.1320 75691.1406 1.0000
0.1380 77515.8359 1.0000
0.1440 77597.7656 1.0000
0.1500 82654.7578 1.0000
0.1560 88687.4063 1.0000
0.1620 92709.1797 1.0000
0.1680 95844.6641 1.0000
0.1740 97110.7813 1.0000
0.1800 102622.0859 1.0000
0.1860 105236.2344 1.0000
0.1920 107909.9688 1.0000
0.1980 111328.4688 1.0000
0.2040 114024.5391 1.0000
0.2100 112140.2656 1.0000
0.2160 121881.8828 1.0000
0.2220 119736.9375 1.0000
0.2280 126529.2578 1.0000
0.2340 131146.8438 1.0000
0.2400 131571.3594 1.0000
0.2460 133485.4219 1.0000
0.2520 139115.9063 1.0000
0.2580 145684.7813 1.0000
0.2640 138453.0469 1.0000
0.2700 150816.2656 1.0000
0.2760 151121.6094 1.0000
0.2820 148976.6719 1.0000
0.2880 160624.9063 1.0000
0.2940 163149.6875 1.0000
0.3000 163350.7656 1.0000
0.3060 164914.7969 1.0000
0.3120 170664.4375 1.0000
0.3180 169033.3750 1.0000
0.3240 177486.5313 1.0000
0.3300 182081.7813 1.0000
0.3360 182394.5781 1.0000
0.3420 184003.2813 1.0000
0.3480 193447.0000 1.0000
0.3540 189164.5625 1.0000
0.3600 194102.3906 1.0000
0.3660 198027.3438 1.0000
0.3720 195107.8281 1.0000
0.3780 195852.6094 1.0000
0.3840 202503.4219 1.0000
0.3900 203963.1719 1.0000
0.3960 207910.4531 1.0000
0.4020 203218.4063 1.0000
0.4080 216676.4219 1.0000
0.4140 218158.5156 1.0000
0.4200 214874.0781 1.0000
0.4260 220832.2500 1.0000
0.4320 219551.2500 1.0000
0.4380 224101.7969 1.0000
0.4440 229866.3281 1.0000
0.4500 227445.8125 1.0000
0.4560 230275.9531 1.0000
0.4620 233806.1563 1.0000
0.4680 235318.0469 1.0000
0.4740 235884.0781 1.0000
0.4800 243316.9063 1.0000
0.4860 242274.2188 1.0000
0.4920 246996.0781 1.0000
0.4980 246943.9375 1.0000
0.5040 253207.4688 1.0000
0.5100 251420.0156 1.0000
0.5160 244016.9844 1.0000
0.5220 251531.7344 1.0000
0.5280 254049.0625 1.0000
0.5340 259433.7656 1.0000
0.5400 254667.2188 1.0000
0.5460 258949.6563 1.0000
0.5520 259247.5625 1.0000
0.5580 259605.0625 1.0000
0.5640 262532.0313 1.0000
0.5700 265451.5313 1.0000
0.5760 264453.5313 1.0000
0.5820 259977.4375 1.0000
0.5880 259873.1719 1.0000
0.5940 258487.9063 1.0000
0.6000 259322.0469 1.0000
0.6060 250570.9844 1.0000
0.6120 253058.5156 1.0000
0.6180 251293.4063 1.0000
0.6240 238528.0156 1.0000
0.6300 234037.0469 1.0000
0.6360 225181.7031 1.0000
0.6420 223692.1719 1.0000
0.6480 203821.6563 1.0000
0.6540 196455.8750 1.0000
0.6600 186855.7656 1.0000
0.6660 166687.3438 1.0000
0.6720 155850.9219 1.0000
0.6780 142221.5938 1.0000
0.6840 127467.6719 1.0000
0.6900 122090.4141 1.0000
0.6960 108982.4375 1.0000
0.7020 98004.5000 1.0000
0.7080 92642.1484 1.0000
0.7140 85425.3125 1.0000
0.7200 82267.4766 1.0000
0.7260 73926.0313 1.0000
0.7320 68615.8125 1.0000
0.7380 63409.8594 1.0000
0.7440 61937.6680 1.0000
0.7500 57916.8320 1.0000
0.7560 54706.0000 1.0000
0.7620 51234.1680 1.0000
0.7680 48372.1680 1.0000
0.7740 45860.5000 1.0000
0.7800 42802.6680 1.0000
0.7860 40736.1680 1.0000
0.7920 38369.5000 1.0000
0.7980 36018.6680 1.0000
0.8040 34651.3320 1.0000
0.8100 33350.5000 1.0000
0.8160 31209.0000 1.0000
0.8220 29674.3340 1.0000
0.8280 28347.3340 1.0000
0.8340 26995.1660 1.0000
0.8400 25488.8340 1.0000
0.8460 24545.5000 1.0000
0.8520 23470.5000 1.0000
0.8580 22446.0000 1.0000
0.8640 21691.6660 1.0000
0.8700 20435.6660 1.0000
0.8760 19590.5000 1.0000
0.8820 18841.8340 1.0000
0.8880 17733.1660 1.0000
0.8940 17653.8340 1.0000
0.9000 16641.1660 1.0000
0.9060 15916.5000 1.0000
0.9120 15351.6670 1.0000
0.9180 14718.3330 1.0000
0.9240 14168.0000 1.0000
0.9300 13755.5000 1.0000
0.9360 13226.3330 1.0000
0.9420 12723.8330 1.0000
0.9480 12335.6670 1.0000
0.9540 11877.0000 1.0000
0.9600 11363.5000 1.0000
0.9660 10787.6670 1.0000
0.9720 10831.6670 1.0000
0.9780 10245.3330 1.0000
0.9840 9825.5000 1.0000
0.9900 9671.8330 1.0000
0.9960 9144.3330 1.0000
1.0020 9017.1670 1.0000
1.0080 8631.6670 1.0000
1.0140 8602.8330 1.0000
1.0200 8215.0000 1.0000
1.0260 8107.1665 1.0000
1.0320 7725.5000 1.0000
1.0380 7572.0000 1.0000
1.0440 7354.0000 1.0000
1.0500 7035.0000 1.0000
1.0560 7074.1665 1.0000
1.0620 6901.0000 1.0000
1.0680 6615.8335 1.0000
1.0740 6548.5000 1.0000
1.0800 6249.0000 1.0000
1.0860 6056.3335 1.0000
1.0920 5933.5000 1.0000
1.0980 5781.6665 1.0000
1.1040 5783.6665 1.0000
1.1100 5645.0000 1.0000
1.1160 5376.3335 1.0000
1.1220 5286.0000 1.0000
1.1280 5113.6665 1.0000
1.1340 5008.5000 1.0000
1.1400 4937.5000 1.0000
1.1460 4875.6665 1.0000
1.1520 4722.6665 1.0000
1.1580 4666.1665 1.0000
1.1640 4500.5000 1.0000
1.1700 4414.0000 1.0000
1.1760 4353.1665 1.0000
1.1820 4232.5000 1.0000
1.1880 4096.6665 1.0000
1.1940 4155.8335 1.0000
1.2000 3956.3333 1.0000
1.2060 3914.6667 1.0000
1.2120 3834.3333 1.0000
1.2180 3731.5000 1.0000
1.2240 3821.3333 1.0000
1.2300 3592.1667 1.0000
1.2360 3469.0000 1.0000
1.2420 3525.5000 1.0000
1.2480 3553.5000 1.0000
1.2540 3401.0000 1.0000
1.2600 3335.3333 1.0000
1.2660 3356.0000 1.0000
1.2720 3138.6667 1.0000
1.2780 3050.8333 1.0000
1.2840 3035.8333 1.0000
1.2900 2949.5000 1.0000
1.2960 2835.5000 1.0000
1.3020 2884.1667 1.0000
1.3080 2827.5000 1.0000
1.3140 2878.8333 1.0000
1.3200 2684.3333 1.0000
1.3260 2688.3333 1.0000
1.3320 2673.1667 1.0000
1.3380 2540.1667 1.0000
1.3440 2520.0000 1.0000
1.3500 2586.5000 1.0000
1.3560 2414.3333 1.0000
1.3620 2514.6667 1.0000
1.3680 2327.8333 1.0000
1.3740 2277.6667 1.0000
1.3800 2297.0000 1.0000
1.3860 2347.0000 1.0000
1.3920 2213.0000 1.0000
1.3980 2149.8333 1.0000
1.4040 2186.3333 1.0000
1.4100 2103.5000 1.0000
1.4160 2077.1667 1.0000
1.4220 2013.0000 1.0000
1.4280 1962.0000 1.0000
1.4340 1929.8334 1.0000
1.4400 1895.0000 1.0000
1.4460 1883.3334 1.0000
1.4520 1820.3334 1.0000
1.4580 1788.6666 1.0000
1.4640 1795.6666 1.0000
1.4700 1717.5000 1.0000
1.4760 1697.5000 1.0000
1.4820 1670.0000 1.0000
1.4880 1676.0000 1.0000
1.4940 1570.0000 1.0000
1.5000 1535.8334 1.0000
1.5060 1554.3334 1.0000
1.5120 1534.6666 1.0000
1.5180 1493.1666 1.0000
1.5240 1440.3334 1.0000
1.5300 1431.5000 1.0000
1.5360 1368.3334 1.0000
1.5420 1405.6666 1.0000
1.5480 1304.1666 1.0000
1.5540 1314.0000 1.0000
1.5600 1327.8334 1.0000
1.5660 1247.0000 1.0000
1.5720 1328.8334 1.0000
1.5780 1196.8334 1.0000
1.5840 1166.0000 1.0000
1.5900 1218.0000 1.0000
1.5960 1187.6666 1.0000
1.6020 1120.8334 1.0000
1.6080 1145.8334 1.0000
1.6140 1154.8334 1.0000
1.6200 1147.8334 1.0000
1.6260 1026.5000 1.0000
1.6320 1016.3333 1.0000
1.6380 1046.5000 1.0000
1.6440 1025.1666 1.0000
1.6500 999.6667 1.0000
1.6560 940.0000 1.0000
1.6620 997.1667 1.0000
1.6680 888.0000 1.0000
1.6740 958.5000 1.0000
1.6800 886.3333 1.0000
1.6860 889.1667 1.0000
1.6920 881.5000 1.0000
1.6980 848.0000 1.0000
1.7040 876.0000 1.0000
1.7100 824.0000 1.0000
1.7160 817.0000 1.0000
1.7220 822.1667 1.0000
1.7280 806.5000 1.0000
1.7340 810.8333 1.0000
1.7400 814.6667 1.0000
1.7460 785.6667 1.0000
1.7520 734.8333 1.0000
1.7580 738.5000 1.0000
1.7640 773.8333 1.0000
1.7700 731.1667 1.0000
1.7760 735.5000 1.0000
1.7820 696.3333 1.0000
1.7880 678.6667 1.0000
1.7940 742.5000 1.0000
1.8000 660.5000 1.0000
1.8060 623.0000 1.0000
1.8120 660.1667 1.0000
1.8180 675.0000 1.0000
1.8240 622.3333 1.0000
1.8300 695.8333 1.0000
1.8360 587.8333 1.0000
1.8420 577.3333 1.0000
1.8480 604.8333 1.0000
1.8540 618.1667 1.0000
1.8600 568.6667 1.0000
1.8660 546.0000 1.0000
1.8720 559.3333 1.0000
1.8780 597.1667 1.0000
1.8840 583.5000 1.0000
1.8900 578.5000 1.0000
1.8960 582.5000 1.0000
1.9020 545.5000 1.0000
1.9080 587.5000 1.0000
1.9140 542.1667 1.0000
1.9200 514.5000 1.0000
1.9260 550.1667 1.0000
1.9320 539.0000 1.0000
1.9380 527.5000 1.0000
1.9440 534.5000 1.0000
1.9500 505.0000 1.0000
1.9560 525.0000 1.0000
1.9620 512.5000 1.0000
1.9680 458.5000 1.0000
1.9740 453.1667 1.0000
1.9800 477.6667 1.0000
1.9860 489.0000 1.0000
1.9920 470.1667 1.0000
1.9980 451.0000 1.0000
2.0040 451.1667 1.0000
2.0100 450.0000 1.0000
2.0160 436.0000 1.0000
2.0220 469.5000 1.0000
2.0280 481.5000 1.0000
2.0340 426.6667 1.0000
2.0400 466.5000 1.0000
2.0460 441.3333 1.0000
2.0520 388.3333 1.0000
2.0580 402.1667 1.0000
2.0640 403.0000 1.0000
2.0700 431.5000 1.0000
2.0760 428.1667 1.0000
2.0820 408.6667 1.0000
2.0880 390.3333 1.0000
2.0940 422.3333 1.0000
2.1000 431.5000 1.0000
2.1060 392.5000 1.0000
2.1120 384.1667 1.0000
2.1180 418.1667 1.0000
2.1240 391.6667 1.0000
2.1300 355.3333 1.0000
2.1360 397.3333 1.0000
2.1420 367.0000 1.0000
2.1480 381.8333 1.0000
2.1540 360.5000 1.0000
2.1600 382.5000 1.0000
2.1660 325.1667 1.0000
2.1720 319.1667 1.0000
2.1780 327.5000 1.0000
2.1840 343.0000 1.0000
2.1900 377.3333 1.0000
2.1960 317.1667 1.0000
2.2020 361.6667 1.0000
2.2080 329.8333 1.0000
2.2140 321.5000 1.0000
2.2200 310.3333 1.0000
2.2260 314.3333 1.0000
2.2320 334.0000 1.0000
2.2380 290.1667 1.0000
2.2440 287.3333 1.0000
2.2500 319.1667 1.0000
2.2560 303.5000 1.0000
2.2620 270.0000 1.0000
2.2680 309.0000 1.0000
2.2740 290.0000 1.0000
2.2800 280.8333 1.0000
2.2860 289.3333 1.0000
2.2920 246.8333 1.0000
2.2980 279.6667 1.0000
2.3040 273.3333 1.0000
2.3100 278.5000 1.0000
2.3160 297.6667 1.0000
2.3220 268.6667 1.0000
2.3280 236.0000 1.0000
2.3340 215.0000 1.0000
2.3400 247.1667 1.0000
2.3460 255.5000 1.0000
2.3520 243.0000 1.0000
2.3580 272.5000 1.0000
2.3640 222.5000 1.0000
2.3700 252.1667 1.0000
2.3760 251.1667 1.0000
2.3820 217.0000 1.0000
2.3880 224.8333 1.0000
2.3940 219.8333 1.0000
2.4000 227.6667 1.0000
2.4060 208.8333 1.0000
2.4120 182.1667 1.0000
2.4180 211.5000 1.0000
2.4240 208.0000 1.0000
2.4300 218.3333 1.0000
2.4360 205.5000 1.0000
2.4420 205.8333 1.0000
2.4480 221.8333 1.0000
2.4540 195.6667 1.0000
2.4600 221.1667 1.0000
2.4660 208.6667 1.0000
2.4720 200.8333 1.0000
2.4780 197.3333 1.0000
2.4840 182.5000 1.0000
2.4900 180.6667 1.0000
2.4960 215.6667 1.0000
2.5020 154.5000 1.0000
2.5080 176.1667 1.0000
2.5140 167.3333 1.0000
2.5200 157.1667 1.0000
2.5260 188.3333 1.0000
2.5320 254.0000 1.0000
2.5380 178.3333 1.0000
2.5440 149.6667 1.0000
2.5500 176.6667 1.0000
2.5560 159.8333 1.0000
2.5620 149.5000 1.0000
2.5680 159.0000 1.0000
2.5740 164.0000 1.0000
2.5800 146.5000 1.0000
2.5860 135.0000 1.0000
2.5920 147.1667 1.0000
2.5980 150.1667 1.0000
2.6040 150.0000 1.0000
2.6100 166.5000 1.0000
2.6160 148.5000 1.0000
2.6220 141.0000 1.0000
2.6280 133.3333 1.0000
2.6340 127.1667 1.0000
2.6400 136.3333 1.0000
2.6460 143.5000 1.0000
2.6520 140.6667 1.0000
2.6580 132.6667 1.0000
2.6640 120.1667 1.0000
2.6700 135.8333 1.0000
2.6760 123.0000 1.0000
2.6820 137.1667 1.0000
2.6880 142.0000 1.0000
2.6940 121.0000 1.0000
2.7000 131.5000 1.0000
2.7060 128.1667 1.0000
2.7120 124.6667 1.0000
2.7180 111.3333 1.0000
2.7240 120.5000 1.0000
2.7300 108.3333 1.0000
2.7360 125.0000 1.0000
2.7420 130.5000 1.0000
2.7480 133.1667 1.0000
2.7540 118.5000 1.0000
2.7600 107.3333 1.0000
2.7660 127.6667 1.0000
2.7720 125.1667 1.0000
2.7780 140.1667 1.0000
2.7840 122.0000 1.0000
2.7900 132.8333 1.0000
2.7960 115.0000 1.0000
2.8020 111.5000 1.0000
2.8080 115.5000 1.0000
2.8140 126.5000 1.0000
2.8200 117.0000 1.0000
2.8260 109.8333 1.0000
2.8320 98.5000 1.0000
2.8380 124.1667 1.0000
2.8440 125.0000 1.0000
2.8500 108.1667 1.0000
2.8560 117.6667 1.0000
2.8620 122.0000 1.0000
2.8680 106.0000 1.0000
2.8740 97.0000 1.0000
2.8800 111.8333 1.0000
2.8860 99.3333 1.0000
2.8920 113.3333 1.0000
2.8980 107.5000 1.0000
2.9040 109.1667 1.0000
2.9100 95.1667 1.0000
2.9160 97.8333 1.0000
2.9220 117.3333 1.0000
2.9280 94.0000 1.0000
2.9340 98.8333 1.0000
2.9400 90.5000 1.0000
2.9460 107.6667 1.0000
2.9520 100.0000 1.0000
2.9580 103.5000 1.0000
2.9640 93.3333 1.0000
2.9700 88.1667 1.0000
2.9760 101.5000 1.0000
2.9820 90.6667 1.0000
2.9880 79.3333 1.0000
2.9940 96.5000 1.0000
3.0000 81.8333 1.0000
3.0060 95.6667 1.0000
3.0120 96.0000 1.0000
3.0180 101.3333 1.0000
3.0240 98.1667 1.0000
3.0300 82.1667 1.0000
3.0360 96.5000 1.0000
3.0420 87.8333 1.0000
3.0480 83.6667 1.0000
3.0540 83.6667 1.0000
3.0600 86.5000 1.0000
3.0660 90.0000 1.0000
3.0720 79.5000 1.0000
3.0780 89.1667 1.0000
3.0840 67.8333 1.0000
3.0900 74.1667 1.0000
3.0960 90.1667 1.0000
3.1020 77.5000 1.0000
3.1080 76.3333 1.0000
3.1140 77.6667 1.0000
3.1200 76.0000 1.0000
3.1260 80.5000 1.0000
3.1320 77.0000 1.0000
3.1380 77.5000 1.0000
3.1440 67.6667 1.0000
3.1500 68.3333 1.0000
3.1560 81.0000 1.0000
3.1620 78.0000 1.0000
3.1680 75.5000 1.0000
3.1740 83.3333 1.0000
3.1800 78.0000 1.0000
3.1860 88.5000 1.0000
3.1920 62.0000 1.0000
3.1980 82.8333 1.0000
3.2040 64.3333 1.0000
3.2100 80.1667 1.0000
3.2160 68.5000 1.0000
3.2220 68.5000 1.0000
3.2280 62.6667 1.0000
3.2340 62.0000 1.0000
3.2400 60.3333 1.0000
3.2460 63.5000 1.0000
3.2520 64.1667 1.0000
3.2580 63.5000 1.0000
3.2640 59.8333 1.0000
3.2700 66.6667 1.0000
3.2760 65.6667 1.0000
3.2820 68.3333 1.0000
3.2880 65.6667 1.0000
3.2940 47.5000 1.0000
3.3000 56.8333 1.0000
3.3060 58.6667 1.0000
3.3120 57.5000 1.0000
3.3180 61.8333 1.0000
3.3240 69.0000 1.0000
3.3300 63.6667 1.0000
3.3360 64.0000 1.0000
3.3420 60.8333 1.0000
3.3480 53.8333 1.0000
3.3540 70.5000 1.0000
3.3600 57.1667 1.0000
3.3660 62.0000 1.0000
3.3720 60.3333 1.0000
3.3780 55.8333 1.0000
3.3840 55.6667 1.0000
3.3900 50.5000 1.0000
3.3960 49.3333 1.0000
3.4020 43.0000 1.0000
3.4080 53.8333 1.0000
3.4140 48.0000 1.0000
3.4200 58.5000 1.0000
3.4260 70.1667 1.0000
3.4320 53.5000 1.0000
3.4380 51.6667 1.0000
3.4440 55.1667 1.0000
3.4500 53.8333 1.0000
3.4560 57.0000 1.0000
3.4620 51.3333 1.0000
3.4680 51.3333 1.0000
3.4740 51.0000 1.0000
3.4800 48.1667 1.0000
3.4860 47.3333 1.0000
3.4920 57.6667 1.0000
3.4980 36.0000 1.0000
3.5040 47.5000 1.0000
3.5100 45.3333 1.0000
3.5160 51.5000 1.0000
3.5220 45.8333 1.0000
3.5280 39.6667 1.0000
3.5340 48.5000 1.0000
3.5400 43.3333 1.0000
3.5460 42.6667 1.0000
3.5520 53.5000 1.0000
3.5580 45.8333 1.0000
3.5640 40.5000 1.0000
3.5700 46.1667 1.0000
3.5760 45.1667 1.0000
3.5820 34.8333 1.0000
3.5880 34.1667 1.0000
3.5940 46.5000 1.0000
3.6000 47.8333 1.0000
3.6060 47.8333 1.0000
3.6120 46.6667 1.0000
3.6180 38.6667 1.0000
3.6240 42.1667 1.0000
3.6300 40.1667 1.0000
3.6360 34.8333 1.0000
3.6420 32.0000 1.0000
3.6480 35.0000 1.0000
3.6540 35.1667 1.0000
3.6600 36.8333 1.0000
3.6660 36.6667 1.0000
3.6720 35.5000 1.0000
3.6780 33.6667 1.0000
3.6840 29.8333 1.0000
3.6900 38.6667 1.0000
3.6960 38.5000 1.0000
3.7020 32.5000 1.0000
3.7080 53.8333 1.0000
3.7140 41.8333 1.0000
3.7200 33.0000 1.0000
3.7260 41.1667 1.0000
3.7320 36.1667 1.0000
3.7380 28.5000 1.0000
3.7440 31.0000 1.0000
3.7500 36.8333 1.0000
3.7560 35.6667 1.0000
3.7620 47.5000 1.0000
3.7680 34.5000 1.0000
3.7740 32.3333 1.0000
3.7800 30.0000 1.0000
3.7860 28.6667 1.0000
3.7920 38.8333 1.0000
3.7980 32.1667 1.0000
3.8040 33.8333 1.0000
3.8100 48.0000 1.0000
3.8160 35.5000 1.0000
3.8220 33.1667 1.0000
3.8280 33.5000 1.0000
3.8340 28.1667 1.0000
3.8400 34.0000 1.0000
3.8460 29.3333 1.0000
3.8520 28.1667 1.0000
3.8580 38.0000 1.0000
3.8640 37.6667 1.0000
3.8700 21.8333 1.0000
3.8760 24.6667 1.0000
3.8820 31.5000 1.0000
3.8880 25.8333 1.0000
3.8940 26.0000 1.0000
3.9000 24.8333 1.0000
3.9060 37.6667 1.0000
3.9120 29.0000 1.0000
3.9180 37.6667 1.0000
3.9240 23.3333 1.0000
3.9300 23.5000 1.0000
3.9360 35.6667 1.0000
3.9420 32.8333 1.0000
3.9480 26.0000 1.0000
3.9540 33.5000 1.0000
3.9600 26.6667 1.0000
3.9660 25.5000 1.0000
3.9720 20.1667 1.0000
3.9780 32.0000 1.0000
3.9840 27.8333 1.0000
3.9900 32.8333 1.0000
3.9960 25.5000 1.0000
4.0020 18.5000 1.0000
4.0080 30.3333 1.0000
4.0140 21.8333 1.0000
4.0200 24.8333 1.0000
4.0260 24.6667 1.0000
4.0320 26.8333 1.0000
4.0380 16.3333 1.0000
4.0440 21.0000 1.0000
4.0500 26.0000 1.0000
4.0560 24.1667 1.0000
4.0620 20.1667 1.0000
4.0680 24.8333 1.0000
4.0740 23.0000 1.0000
4.0800 18.0000 1.0000
4.0860 26.5000 1.0000
4.0920 21.0000 1.0000
4.0980 22.8333 1.0000
4.1040 27.1667 1.0000
4.1100 29.3333 1.0000
4.1160 14.6667 1.0000
4.1220 35.8333 1.0000
4.1280 22.5000 1.0000
4.1340 26.3333 1.0000
4.1400 15.5000 1.0000
4.1460 21.8333 1.0000
4.1520 19.6667 1.0000
4.1580 17.3333 1.0000
4.1640 28.1667 1.0000
4.1700 23.3333 1.0000
4.1760 24.3333 1.0000
4.1820 32.1667 1.0000
4.1880 18.3333 1.0000
4.1940 24.3333 1.0000
4.2000 15.3333 1.0000
4.2060 25.0000 1.0000
4.2120 13.5000 1.0000
4.2180 26.3333 1.0000
4.2240 23.5000 1.0000
4.2300 22.5000 1.0000
4.2360 19.3333 1.0000
4.2420 22.8333 1.0000
4.2480 17.1667 1.0000
4.2540 17.0000 1.0000
4.2600 15.3333 1.0000
4.2660 15.8333 1.0000
4.2720 23.8333 1.0000
4.2780 20.5000 1.0000
4.2840 24.1667 1.0000
4.2900 15.1667 1.0000
4.2960 19.1667 1.0000
4.3020 17.3333 1.0000
4.3080 9.3333 1.0000
4.3140 16.5000 1.0000
4.3200 19.6667 1.0000
4.3260 17.5000 1.0000
4.3320 15.3333 1.0000
4.3380 14.0000 1.0000
4.3440 19.8333 1.0000
4.3500 24.6667 1.0000
4.3560 21.5000 1.0000
4.3620 20.5000 1.0000
4.3680 14.1667 1.0000
4.3740 18.6667 1.0000
4.3800 20.3333 1.0000
4.3860 16.3333 1.0000
4.3920 12.0000 1.0000
4.3980 17.1667 1.0000
4.4040 9.3333 1.0000
4.4100 19.3333 1.0000
4.4160 14.8333 1.0000
4.4220 30.8333 1.0000
4.4280 19.1667 1.0000
4.4340 21.5000 1.0000
4.4400 13.0000 1.0000
4.4460 14.1667 1.0000
4.4520 12.3333 1.0000
4.4580 13.1667 1.0000
4.4640 12.3333 1.0000
4.4700 21.6667 1.0000
4.4760 12.0000 1.0000
4.4820 12.3333 1.0000
4.4880 16.5000 1.0000
4.4940 17.1667 1.0000
4.5000 15.5000 1.0000
4.5060 17.0000 1.0000
4.5120 10.6667 1.0000
4.5180 10.1667 1.0000
4.5240 22.1667 1.0000
4.5300 7.1667 1.0000
4.5360 18.5000 1.0000
4.5420 12.8333 1.0000
4.5480 13.0000 1.0000
4.5540 6.8333 1.0000
4.5600 15.0000 1.0000
4.5660 16.1667 1.0000
4.5720 13.0000 1.0000
4.5780 15.1667 1.0000
4.5840 10.5000 1.0000
4.5900 11.1667 1.0000
4.5960 18.1667 1.0000
4.6020 12.0000 1.0000
4.6080 15.1667 1.0000
4.6140 18.0000 1.0000
4.6200 17.1667 1.0000
4.6260 11.0000 1.0000
4.6320 16.6667 1.0000
4.6380 14.0000 1.0000
4.6440 14.5000 1.0000
4.6500 17.0000 1.0000
4.6560 11.1667 1.0000
4.6620 11.8333 1.0000
4.6680 7.0000 1.0000
4.6740 8.8333 1.0000
4.6800 12.5000 1.0000
4.6860 18.0000 1.0000
4.6920 11.1667 1.0000
4.6980 5.8333 1.0000
4.7040 14.0000 1.0000
4.7100 17.1667 1.0000
4.7160 9.0000 1.0000
4.7220 13.1667 1.0000
4.7280 12.3333 1.0000
4.7340 13.0000 1.0000
4.7400 13.0000 1.0000
4.7460 18.1667 1.0000
4.7520 17.5000 1.0000
4.7580 14.0000 1.0000
4.7640 6.6667 1.0000
4.7700 9.0000 1.0000
4.7760 11.0000 1.0000
4.7820 9.0000 1.0000
4.7880 9.5000 1.0000
4.7940 9.3333 1.0000
4.8000 15.3333 1.0000
4.8060 11.6667 1.0000
4.8120 13.5000 1.0000
4.8180 9.3333 1.0000
4.8240 12.0000 1.0000
4.8300 14.0000 1.0000
4.8360 11.0000 1.0000
4.8420 9.5000 1.0000
4.8480 9.0000 1.0000
4.8540 11.5000 1.0000
4.8600 11.8333 1.0000
4.8660 8.1667 1.0000
4.8720 9.6667 1.0000
4.8780 6.1667 1.0000
4.8840 12.0000 1.0000
4.8900 8.0000 1.0000
4.8960 9.6667 1.0000
4.9020 10.5000 1.0000
4.9080 4.0000 1.0000
4.9140 4.1667 1.0000
4.9200 14.8333 1.0000
4.9260 7.5000 1.0000
4.9320 12.3333 1.0000
4.9380 10.1667 1.0000
4.9440 7.0000 1.0000
4.9500 13.8333 1.0000
4.9560 10.1667 1.0000
4.9620 14.1667 1.0000
4.9680 3.5000 1.0000
4.9740 14.5000 1.0000
4.9800 8.6667 1.0000
4.9860 6.1667 1.0000
4.9920 10.8333 1.0000
4.9980 14.8333 1.0000
5.0040 11.8333 1.0000
5.0100 10.6667 1.0000
5.0160 8.6667 1.0000
5.0220 8.8333 1.0000
5.0280 9.0000 1.0000
5.0340 15.1667 1.0000
5.0400 4.8333 1.0000
5.0460 6.5000 1.0000
5.0520 9.6667 1.0000
5.0580 6.1667 1.0000
5.0640 12.3333 1.0000
5.0700 10.1667 1.0000
5.0760 5.6667 1.0000
5.0820 6.6667 1.0000
5.0880 8.1667 1.0000
5.0940 8.8333 1.0000
5.1000 3.8333 1.0000
5.1060 4.5000 1.0000
5.1120 15.6667 1.0000
5.1180 8.8333 1.0000
5.1240 10.5000 1.0000
5.1300 10.6667 1.0000
5.1360 10.0000 1.0000
5.1420 5.3333 1.0000
5.1480 4.6667 1.0000
5.1540 5.8333 1.0000
5.1600 5.6667 1.0000
5.1660 6.0000 1.0000
5.1720 3.5000 1.0000
5.1780 12.0000 1.0000
5.1840 2.1667 1.0000
5.1900 13.0000 1.0000
5.1960 7.0000 1.0000
5.2020 8.5000 1.0000
5.2080 8.0000 1.0000
5.2140 11.8333 1.0000
5.2200 5.8333 1.0000
5.2260 6.5000 1.0000
5.2320 6.8333 1.0000
5.2380 3.6667 1.0000
5.2440 8.0000 1.0000
5.2500 3.3333 1.0000
5.2560 7.0000 1.0000
5.2620 7.6667 1.0000
5.2680 5.8333 1.0000
5.2740 6.8333 1.0000
5.2800 6.3333 1.0000
5.2860 4.5000 1.0000
5.2920 5.3333 1.0000
5.2980 11.3333 1.0000
5.3040 11.5000 1.0000
5.3100 4.8333 1.0000
5.3160 8.6667 1.0000
5.3220 6.0000 1.0000
5.3280 1.1667 1.0000
5.3340 5.5000 1.0000
5.3400 8.5000 1.0000
5.3460 3.6667 1.0000
5.3520 8.0000 1.0000
5.3580 11.3333 1.0000
5.3640 0.8333 1.0000
5.3700 3.8333 1.0000
5.3760 7.5000 1.0000
5.3820 9.5000 1.0000
5.3880 4.3333 1.0000
5.3940 1.3333 1.0000
5.4000 7.6667 1.0000
5.4060 4.5000 1.0000
5.4120 5.0000 1.0000
5.4180 11.1667 1.0000
5.4240 1.3333 1.0000
5.4300 7.0000 1.0000
5.4360 6.6667 1.0000
5.4420 6.1667 1.0000
5.4480 1.3333 1.0000
5.4540 2.3333 1.0000
5.4600 9.3333 1.0000
5.4660 4.6667 1.0000
5.4720 1.1667 1.0000
5.4780 3.1667 1.0000
5.4840 7.3333 1.0000
5.4900 5.6667 1.0000
5.4960 8.1667 1.0000
5.5020 2.0000 1.0000
5.5080 6.8333 1.0000
5.5140 5.1667 1.0000
5.5200 4.3333 1.0000
5.5260 2.6667 1.0000
5.5320 6.0000 1.0000
5.5380 3.3333 1.0000
5.5440 7.3333 1.0000
5.5500 5.6667 1.0000
5.5560 0.1667 1.0000
5.5620 3.1667 1.0000
5.5680 3.3333 1.0000
5.5740 2.8333 1.0000
5.5800 3.5000 1.0000
5.5860 6.3333 1.0000
5.5920 4.5000 1.0000
5.5980 5.6667 1.0000
5.6040 4.5000 1.0000
5.6100 3.5000 1.0000
5.6160 3.8333 1.0000
5.6220 5.3333 1.0000
5.6280 3.5000 1.0000
5.6340 6.1667 1.0000
5.6400 2.3333 1.0000
5.6460 4.5000 1.0000
5.6520 3.5000 1.0000
5.6580 4.3333 1.0000
5.6640 1.6667 1.0000
5.6700 3.5000 1.0000
5.6760 6.0000 1.0000
5.6820 7.1667 1.0000
5.6880 3.0000 1.0000
5.6940 1.1667 1.0000
5.7000 3.3333 1.0000
5.7060 9.6667 1.0000
5.7120 3.3333 1.0000
5.7180 0.3333 1.0000
5.7240 0.5000 1.0000
5.7300 2.8333 1.0000
5.7360 4.3333 1.0000
5.7420 4.1667 1.0000
5.7480 2.1667 1.0000
5.7540 7.6667 1.0000
5.7600 9.5000 1.0000
5.7660 4.3333 1.0000
5.7720 3.5000 1.0000
5.7780 2.3333 1.0000
5.7840 3.3333 1.0000
5.7900 5.5000 1.0000
5.7960 0.5000 1.0000
5.8020 6.6667 1.0000
5.8080 5.6667 1.0000
5.8140 1.1667 1.0000
5.8200 2.0000 1.0000
5.8260 5.6667 1.0000
5.8320 3.5000 1.0000
5.8380 7.3333 1.0000
5.8440 1.1667 1.0000
5.8500 2.1667 1.0000
5.8560 4.5000 1.0000
5.8620 0.0000 1.0000
5.8680 3.3333 1.0000
5.8740 2.0000 1.0000
5.8800 3.6667 1.0000
5.8860 4.0000 1.0000
5.8920 6.8333 1.0000
5.8980 3.1667 1.0000
5.9040 2.1667 1.0000
5.9100 4.3333 1.0000
5.9160 4.0000 1.0000
5.9220 3.5000 1.0000
5.9280 3.5000 1.0000
5.9340 0.0000 1.0000
5.9400 5.1667 1.0000
5.9460 2.5000 1.0000
5.9520 5.1667 1.0000
5.9580 5.1667 1.0000
5.9640 3.3333 1.0000
5.9700 5.5000 1.0000
5.9760 5.3333 1.0000
5.9820 3.1667 1.0000
5.9880 0.5000 1.0000
5.9940 8.0000 1.0000
6.0000 4.3333 1.0000
*RAS_INT_END
*RAS_DATA_END