File: XRR/CWOI8_reflectivity.ras
*RAS_DATA_START
*RAS_HEADER_START
*DISP_FMT_X "%.4f"
*DISP_FMT_Y "%.0f"
*DISP_FULLSCALE "28701047.9500000030"
*DISP_LINE_COLOR "255.0000000000"
*DISP_LINE_STYLE "0.0000000000"
*DISP_LINE_WIDTH "0.2500000000"
*DISP_NOTE "Collected Data-3"
*DISP_OFFSET_Y "0.0000000000"
*DISP_PEAKSEARCH_UNIT_Y "cps"
*DISP_RANGE_BOTTOM "0.0100000000"
*DISP_RANGE_LEFT "-0.0006000000"
*DISP_RANGE_LOGCUTOFF "0.0100000000"
*DISP_RANGE_RIGHT "6.0006000000"
*DISP_RANGE_TOP "28701047.9500000030"
*DISP_SCALE_MODE_Y "2.0000000000"
*DISP_TAB_NAME "2-Theta/Omega"
*DISP_TITLE_Y "Intensity"
*DISP_UNIT_Y "cps"
*DISP_WINDOW_NAME "MSG_MACROENGINE"
*FILE_COMMENT " "
*FILE_MD5 ""
*FILE_MEMO " "
*FILE_OPERATOR "administrator"
*FILE_PART_ID "MEAS_KHP2_00055"
*FILE_SAMPLE "CWO I8"
*FILE_TYPE "RAS_RAW"
*FILE_USERGROUP "System Manager"
*FILE_VERSION "1.0000000000"
*HW_ATTACHMENT_ID "ATT0025"
*HW_ATTACHMENT_NAME "標準|Standard"
*HW_COUNTER_ID-0 "CUT0025"
*HW_COUNTER_ID-1 "CUT0020"
*HW_COUNTER_ID-2 "CUT0020"
*HW_COUNTER_ID-3 "CSL0021"
*HW_COUNTER_ID-4 "CMC0021"
*HW_COUNTER_NAME-0 "D/teX Ultra|D/teX Ultra"
*HW_COUNTER_NAME-1 "None|None"
*HW_COUNTER_NAME-2 "None|None"
*HW_COUNTER_NAME-3 "BBM|BBM"
*HW_COUNTER_NAME-4 "検出器モノクロメータ|Detector monochromator"
*HW_COUNTER_SELECT_NAME "D/teX Ultra|D/teX Ultra"
*HW_GONIOMETER_ID "GON0023"
*HW_GONIOMETER_NAME "SmartLab|SmartLab"
*HW_GONIOMETER_RADIUS-0 "90.0"
*HW_GONIOMETER_RADIUS-1 "114.0"
*HW_GONIOMETER_RADIUS-2 "190.0"
*HW_GONIOMETER_RADIUS-3 "300.0"
*HW_GONIOMETER_RADIUS-4 "187.0"
*HW_GONIOMETER_RADIUS-5 "300.0"
*HW_GONIOMETER_RADIUS-6 "113.0"
*HW_GONIOMETER_RADIUS-7 "331.0"
*HW_I_OPT_ID-0 "CBO0021"
*HW_I_OPT_ID-1 "ICR0021"
*HW_I_OPT_ID-2 "ISL0021"
*HW_I_OPT_ID-3 "ISO0021"
*HW_I_OPT_ID-4 "IAD0021"
*HW_I_OPT_ID-5 "IPR0001"
*HW_I_OPT_NAME-0 "CBOユニット|CBO unit"
*HW_I_OPT_NAME-1 "標準入射光学ユニット|Standard incident optical unit"
*HW_I_OPT_NAME-2 "標準入射スリットボックス|Standard incident slit box"
*HW_I_OPT_NAME-3 "入射平行スリット|Incident parallel slit"
*HW_I_OPT_NAME-4 "長手制限スリット|Length limiting slit"
*HW_I_OPT_NAME-5 "None|None"
*HW_R_ATTENUATER_AUTOMODE "1"
*HW_R_OPT_ID-0 "RSS0021"
*HW_R_OPT_ID-1 "RCR0023"
*HW_R_OPT_ID-2 "RSO0021"
*HW_R_OPT_ID-3 "RRS0021"
*HW_R_OPT_ID-4 "ATN0021"
*HW_R_OPT_ID-5 "RFL0021"
*HW_R_OPT_ID-6 "RAD0021"
*HW_R_OPT_NAME-0 "標準受光スリットボックス1|Standard receiving slit box # 1"
*HW_R_OPT_NAME-1 "標準受光光学ユニット1|Standard receiving unit # 1"
*HW_R_OPT_NAME-2 "標準受光光学ユニット2|Standard receiving optical unit # 2"
*HW_R_OPT_NAME-3 "標準受光スリットボックス2|Standard receiving slit box # 2"
*HW_R_OPT_NAME-4 "標準アッテネータ|Standard Attenuator"
*HW_R_OPT_NAME-5 "Cu Kβ|Cu K-beta"
*HW_R_OPT_NAME-6 "調整用受光スリット|Alignment receiving slit"
*HW_SAMPLE_HOLDER_ID "SMP0021"
*HW_SAMPLE_HOLDER_NAME "χφZクレードル|Chi phi Z cradle"
*HW_XG_CURRENT_MAX "200"
*HW_XG_CURRENT_MIN "10"
*HW_XG_CURRENT_RESOLUTION "1"
*HW_XG_CURRENT_UNIT "mA"
*HW_XG_FOCUS "0.4mm x 8mm"
*HW_XG_FOCUS_TYPE "Normal"
*HW_XG_ID "1700"
*HW_XG_NAME "9kW 開放管(45kV 200mA ID:1700)|9kW Rotating anode(45kV 200mA ID:1700)"
*HW_XG_TARGET_ATOMIC_NUMBER "29.0000000000"
*HW_XG_TARGET_NAME "Cu"
*HW_XG_TYPE "Rota"
*HW_XG_VOLTAGE_MAX "45"
*HW_XG_VOLTAGE_MIN "20"
*HW_XG_VOLTAGE_RESOLUTION "1"
*HW_XG_VOLTAGE_UNIT "kV"
*HW_XG_WATT_MAX "9.00"
*HW_XG_WATT_UNIT "kW"
*HW_XG_WAVE_LENGTH_ALPHA1 "1.540593"
*HW_XG_WAVE_LENGTH_ALPHA2 "1.544414"
*HW_XG_WAVE_LENGTH_BETA "1.392250"
*MEAS_COND_AXIS_NAME-0 "Theta/2-Theta"
*MEAS_COND_AXIS_NAME-1 "2-Theta"
*MEAS_COND_AXIS_NAME-2 "Omega"
*MEAS_COND_AXIS_NAME-3 "Chi"
*MEAS_COND_AXIS_NAME-4 "Phi"
*MEAS_COND_AXIS_NAME-5 "Z"
*MEAS_COND_AXIS_NAME-6 "2-Theta/Omega"
*MEAS_COND_AXIS_NAME-7 "Theta_s"
*MEAS_COND_AXIS_NAME-8 "Theta_d"
*MEAS_COND_AXIS_NAME-9 "Ts"
*MEAS_COND_AXIS_NAME-10 "CBO selection slit"
*MEAS_COND_AXIS_NAME-11 "M"
*MEAS_COND_AXIS_NAME-12 "Incident parallel slit"
*MEAS_COND_AXIS_NAME-13 "Incident slit"
*MEAS_COND_AXIS_NAME-14 ""
*MEAS_COND_AXIS_NAME-15 "Zs"
*MEAS_COND_AXIS_NAME-16 "Incident optical device"
*MEAS_COND_AXIS_NAME-17 "Omega_m"
*MEAS_COND_AXIS_NAME-18 "Length limiting slit"
*MEAS_COND_AXIS_NAME-19 "Center slit"
*MEAS_COND_AXIS_NAME-20 "Filter"
*MEAS_COND_AXIS_NAME-21 "Receiving slit # 1"
*MEAS_COND_AXIS_NAME-22 "Receiving slit # 2"
*MEAS_COND_AXIS_NAME-23 "Receiving optical device"
*MEAS_COND_AXIS_NAME-24 "Receiving parallel slit"
*MEAS_COND_AXIS_NAME-25 "Alignment receiving slit"
*MEAS_COND_AXIS_NAME-26 ""
*MEAS_COND_AXIS_NAME-27 ""
*MEAS_COND_AXIS_NAME-28 "Zd"
*MEAS_COND_AXIS_NAME-29 "Attenuator"
*MEAS_COND_AXIS_NAME-30 "Diffracted beam monochromator"
*MEAS_COND_AXIS_NAME-31 "Monochromator slit"
*MEAS_COND_AXIS_NAME-32 "Primary beam"
*MEAS_COND_AXIS_NAME-33 ""
*MEAS_COND_AXIS_NAME-34 ""
*MEAS_COND_AXIS_NAME-35 "PHA"
*MEAS_COND_AXIS_NAME_INTERNAL-0 "TwoThetaTheta"
*MEAS_COND_AXIS_NAME_INTERNAL-1 "TwoTheta"
*MEAS_COND_AXIS_NAME_INTERNAL-2 "Omega"
*MEAS_COND_AXIS_NAME_INTERNAL-3 "Chi"
*MEAS_COND_AXIS_NAME_INTERNAL-4 "Phi"
*MEAS_COND_AXIS_NAME_INTERNAL-5 "Z"
*MEAS_COND_AXIS_NAME_INTERNAL-6 "TwoThetaOmega"
*MEAS_COND_AXIS_NAME_INTERNAL-7 "ThetaS"
*MEAS_COND_AXIS_NAME_INTERNAL-8 "ThetaD"
*MEAS_COND_AXIS_NAME_INTERNAL-9 "Ts"
*MEAS_COND_AXIS_NAME_INTERNAL-10 "CBO"
*MEAS_COND_AXIS_NAME_INTERNAL-11 "CBO-M"
*MEAS_COND_AXIS_NAME_INTERNAL-12 "IncidentSollerSlit"
*MEAS_COND_AXIS_NAME_INTERNAL-13 "IncidentSlitBox"
*MEAS_COND_AXIS_NAME_INTERNAL-14 "IncidentSlitBox-_Axis"
*MEAS_COND_AXIS_NAME_INTERNAL-15 "Zs"
*MEAS_COND_AXIS_NAME_INTERNAL-16 "IncidentMonochromator"
*MEAS_COND_AXIS_NAME_INTERNAL-17 "IncidentMonochromator-OmegaM"
*MEAS_COND_AXIS_NAME_INTERNAL-18 "IncidentAxdSlit"
*MEAS_COND_AXIS_NAME_INTERNAL-19 "CenterSlit"
*MEAS_COND_AXIS_NAME_INTERNAL-20 "Filter"
*MEAS_COND_AXIS_NAME_INTERNAL-21 "ReceivingSlitBox1"
*MEAS_COND_AXIS_NAME_INTERNAL-22 "ReceivingSlitBox2"
*MEAS_COND_AXIS_NAME_INTERNAL-23 "ReceivingOptics"
*MEAS_COND_AXIS_NAME_INTERNAL-24 "ReceivingSollerSlit"
*MEAS_COND_AXIS_NAME_INTERNAL-25 "ReceivingAxdSlit"
*MEAS_COND_AXIS_NAME_INTERNAL-26 "ReceivingSlitBox1-_Axis"
*MEAS_COND_AXIS_NAME_INTERNAL-27 "ReceivingSlitBox2-_Axis"
*MEAS_COND_AXIS_NAME_INTERNAL-28 "ReceivingSlitBox2-Zd"
*MEAS_COND_AXIS_NAME_INTERNAL-29 "Attenuator"
*MEAS_COND_AXIS_NAME_INTERNAL-30 "CounterMonochromator"
*MEAS_COND_AXIS_NAME_INTERNAL-31 "CounterSlit"
*MEAS_COND_AXIS_NAME_INTERNAL-32 "IncidentPrimary"
*MEAS_COND_AXIS_NAME_INTERNAL-33 "AlphaR"
*MEAS_COND_AXIS_NAME_INTERNAL-34 "BetaR"
*MEAS_COND_AXIS_NAME_INTERNAL-35 "PHA"
*MEAS_COND_AXIS_NAME_MAGICNO-0 "83951616.0000000000"
*MEAS_COND_AXIS_NAME_MAGICNO-1 "268632064.0000000000"
*MEAS_COND_AXIS_NAME_MAGICNO-2 "268500992.0000000000"
*MEAS_COND_AXIS_NAME_MAGICNO-3 "268500992.0000000000"
*MEAS_COND_AXIS_NAME_MAGICNO-4 "268500992.0000000000"
*MEAS_COND_AXIS_NAME_MAGICNO-5 "285278208.0000000000"
*MEAS_COND_AXIS_NAME_MAGICNO-6 "83951616.0000000000"
*MEAS_COND_AXIS_NAME_MAGICNO-7 "131072.0000000000"
*MEAS_COND_AXIS_NAME_MAGICNO-8 "131072.0000000000"
*MEAS_COND_AXIS_NAME_MAGICNO-9 "318898176.0000000000"
*MEAS_COND_AXIS_NAME_MAGICNO-10 "20971521.0000000000"
*MEAS_COND_AXIS_NAME_MAGICNO-11 "285343744.0000000000"
*MEAS_COND_AXIS_NAME_MAGICNO-12 "20971521.0000000000"
*MEAS_COND_AXIS_NAME_MAGICNO-13 "22020097.0000000000"
*MEAS_COND_AXIS_NAME_MAGICNO-14 "25165824.0000000000"
*MEAS_COND_AXIS_NAME_MAGICNO-15 "318898176.0000000000"
*MEAS_COND_AXIS_NAME_MAGICNO-16 "20971521.0000000000"
*MEAS_COND_AXIS_NAME_MAGICNO-17 "285343744.0000000000"
*MEAS_COND_AXIS_NAME_MAGICNO-18 "20971521.0000000000"
*MEAS_COND_AXIS_NAME_MAGICNO-19 "20971521.0000000000"
*MEAS_COND_AXIS_NAME_MAGICNO-20 "20971521.0000000000"
*MEAS_COND_AXIS_NAME_MAGICNO-21 "23068673.0000000000"
*MEAS_COND_AXIS_NAME_MAGICNO-22 "23068673.0000000000"
*MEAS_COND_AXIS_NAME_MAGICNO-23 "20971521.0000000000"
*MEAS_COND_AXIS_NAME_MAGICNO-24 "20971521.0000000000"
*MEAS_COND_AXIS_NAME_MAGICNO-25 "20971521.0000000000"
*MEAS_COND_AXIS_NAME_MAGICNO-26 "25165824.0000000000"
*MEAS_COND_AXIS_NAME_MAGICNO-27 "25165824.0000000000"
*MEAS_COND_AXIS_NAME_MAGICNO-28 "285343744.0000000000"
*MEAS_COND_AXIS_NAME_MAGICNO-29 "17301505.0000000000"
*MEAS_COND_AXIS_NAME_MAGICNO-30 "20971521.0000000000"
*MEAS_COND_AXIS_NAME_MAGICNO-31 "20971521.0000000000"
*MEAS_COND_AXIS_NAME_MAGICNO-32 "20971521.0000000000"
*MEAS_COND_AXIS_NAME_MAGICNO-33 "8388608.0000000000"
*MEAS_COND_AXIS_NAME_MAGICNO-34 "8388608.0000000000"
*MEAS_COND_AXIS_NAME_MAGICNO-35 "0.0000000000"
*MEAS_COND_AXIS_OFFSET-0 "-"
*MEAS_COND_AXIS_OFFSET-1 "0.9127000000"
*MEAS_COND_AXIS_OFFSET-2 "0.9118000000"
*MEAS_COND_AXIS_OFFSET-3 "0.0000000000"
*MEAS_COND_AXIS_OFFSET-4 "0.0000000000"
*MEAS_COND_AXIS_OFFSET-5 "-"
*MEAS_COND_AXIS_OFFSET-6 "-"
*MEAS_COND_AXIS_OFFSET-7 "0.9118000000"
*MEAS_COND_AXIS_OFFSET-8 "0.0009000000"
*MEAS_COND_AXIS_OFFSET-9 "-"
*MEAS_COND_AXIS_OFFSET-10 "-"
*MEAS_COND_AXIS_OFFSET-11 "-"
*MEAS_COND_AXIS_OFFSET-12 "-"
*MEAS_COND_AXIS_OFFSET-13 "-"
*MEAS_COND_AXIS_OFFSET-14 "-"
*MEAS_COND_AXIS_OFFSET-15 "-"
*MEAS_COND_AXIS_OFFSET-16 "-"
*MEAS_COND_AXIS_OFFSET-17 "-"
*MEAS_COND_AXIS_OFFSET-18 "-"
*MEAS_COND_AXIS_OFFSET-19 "-"
*MEAS_COND_AXIS_OFFSET-20 "-"
*MEAS_COND_AXIS_OFFSET-21 "-"
*MEAS_COND_AXIS_OFFSET-22 "-"
*MEAS_COND_AXIS_OFFSET-23 "-"
*MEAS_COND_AXIS_OFFSET-24 "-"
*MEAS_COND_AXIS_OFFSET-25 "-"
*MEAS_COND_AXIS_OFFSET-26 "-"
*MEAS_COND_AXIS_OFFSET-27 "-"
*MEAS_COND_AXIS_OFFSET-28 "-"
*MEAS_COND_AXIS_OFFSET-29 "-"
*MEAS_COND_AXIS_OFFSET-30 "-"
*MEAS_COND_AXIS_OFFSET-31 "-"
*MEAS_COND_AXIS_OFFSET-32 "-"
*MEAS_COND_AXIS_OFFSET-33 "0.0000000000"
*MEAS_COND_AXIS_OFFSET-34 "0.0000000000"
*MEAS_COND_AXIS_OFFSET-35 "-"
*MEAS_COND_AXIS_POSITION-0 "-0.0008000000"
*MEAS_COND_AXIS_POSITION-1 "-0.0008000000"
*MEAS_COND_AXIS_POSITION-2 "-0.0004000000"
*MEAS_COND_AXIS_POSITION-3 "0.0000000000"
*MEAS_COND_AXIS_POSITION-4 "0.0000000000"
*MEAS_COND_AXIS_POSITION-5 "-1.4213000000"
*MEAS_COND_AXIS_POSITION-6 "-0.0008000000"
*MEAS_COND_AXIS_POSITION-7 "-0.0004000000"
*MEAS_COND_AXIS_POSITION-8 "-0.0004000000"
*MEAS_COND_AXIS_POSITION-9 "-4.8793100000"
*MEAS_COND_AXIS_POSITION-10 "PB"
*MEAS_COND_AXIS_POSITION-11 "0.0000000000"
*MEAS_COND_AXIS_POSITION-12 "Soller_slit_open_s"
*MEAS_COND_AXIS_POSITION-13 "0.250mm"
*MEAS_COND_AXIS_POSITION-14 "0.2500000000"
*MEAS_COND_AXIS_POSITION-15 "-1.7884400000"
*MEAS_COND_AXIS_POSITION-16 "Ge(220)x2"
*MEAS_COND_AXIS_POSITION-17 "0.0000000000"
*MEAS_COND_AXIS_POSITION-18 "2.0mm"
*MEAS_COND_AXIS_POSITION-19 "None"
*MEAS_COND_AXIS_POSITION-20 "None"
*MEAS_COND_AXIS_POSITION-21 "0.250mm"
*MEAS_COND_AXIS_POSITION-22 "0.250mm"
*MEAS_COND_AXIS_POSITION-23 "No_unit"
*MEAS_COND_AXIS_POSITION-24 "Soller_slit_5.0deg"
*MEAS_COND_AXIS_POSITION-25 "None"
*MEAS_COND_AXIS_POSITION-26 "0.2500000000"
*MEAS_COND_AXIS_POSITION-27 "0.2500000000"
*MEAS_COND_AXIS_POSITION-28 "0.0868700000"
*MEAS_COND_AXIS_POSITION-29 "1/10000"
*MEAS_COND_AXIS_POSITION-30 "None"
*MEAS_COND_AXIS_POSITION-31 "None"
*MEAS_COND_AXIS_POSITION-32 "None"
*MEAS_COND_AXIS_POSITION-33 "0.0000000000"
*MEAS_COND_AXIS_POSITION-34 "0.0000000000"
*MEAS_COND_AXIS_POSITION-35 "34.0000000000"
*MEAS_COND_AXIS_UNIT-0 "deg"
*MEAS_COND_AXIS_UNIT-1 "deg"
*MEAS_COND_AXIS_UNIT-2 "deg"
*MEAS_COND_AXIS_UNIT-3 "deg"
*MEAS_COND_AXIS_UNIT-4 "deg"
*MEAS_COND_AXIS_UNIT-5 "mm"
*MEAS_COND_AXIS_UNIT-6 "deg"
*MEAS_COND_AXIS_UNIT-7 "deg"
*MEAS_COND_AXIS_UNIT-8 "deg"
*MEAS_COND_AXIS_UNIT-9 "mm"
*MEAS_COND_AXIS_UNIT-10 ""
*MEAS_COND_AXIS_UNIT-11 "pulse"
*MEAS_COND_AXIS_UNIT-12 ""
*MEAS_COND_AXIS_UNIT-13 ""
*MEAS_COND_AXIS_UNIT-14 "mm"
*MEAS_COND_AXIS_UNIT-15 "mm"
*MEAS_COND_AXIS_UNIT-16 ""
*MEAS_COND_AXIS_UNIT-17 "pulse"
*MEAS_COND_AXIS_UNIT-18 ""
*MEAS_COND_AXIS_UNIT-19 ""
*MEAS_COND_AXIS_UNIT-20 ""
*MEAS_COND_AXIS_UNIT-21 ""
*MEAS_COND_AXIS_UNIT-22 ""
*MEAS_COND_AXIS_UNIT-23 ""
*MEAS_COND_AXIS_UNIT-24 ""
*MEAS_COND_AXIS_UNIT-25 ""
*MEAS_COND_AXIS_UNIT-26 "mm"
*MEAS_COND_AXIS_UNIT-27 "mm"
*MEAS_COND_AXIS_UNIT-28 "mm"
*MEAS_COND_AXIS_UNIT-29 ""
*MEAS_COND_AXIS_UNIT-30 ""
*MEAS_COND_AXIS_UNIT-31 ""
*MEAS_COND_AXIS_UNIT-32 ""
*MEAS_COND_AXIS_UNIT-33 "deg"
*MEAS_COND_AXIS_UNIT-34 "deg"
*MEAS_COND_AXIS_UNIT-35 "div"
*MEAS_COND_COUNTER_CNTLOSS_CORR "0.0000000000"
*MEAS_COND_COUNTER_PHABASE "34.0000000000"
*MEAS_COND_COUNTER_PHAWINDOW "19.0000000000"
*MEAS_COND_COUNTER_PHA_UNIT "div"
*MEAS_COND_COUNTER_TAUDIFF "2.0000000000"
*MEAS_COND_COUNTER_TAUINT "0.1000000000"
*MEAS_COND_IRRADIATION_MODE "OFF"
*MEAS_COND_IRRADIATION_WIDTH ""
*MEAS_COND_OPT_ATTR "High resolution parallel beam Ge(220)x2/RS"
*MEAS_COND_OPT_NAME "@High resolution PB-Ge(220)x2"
*MEAS_COND_UNSYMMETRIC_MODE "OFF"
*MEAS_COND_XG_CURRENT "200.0000000000"
*MEAS_COND_XG_VOLTAGE "45.0000000000"
*MEAS_COND_XG_WAVE_TYPE "Ka1"
*MEAS_DATA_COUNT "3001.0000000000"
*MEAS_SCAN_AXIS_X "2-Theta/Omega"
*MEAS_SCAN_AXIS_X_INTERNAL "TwoThetaOmega"
*MEAS_SCAN_END_TIME "11/06/23 15:48:58"
*MEAS_SCAN_MODE "CONTINUOUS"
*MEAS_SCAN_MONITOR "0"
*MEAS_SCAN_RESOLUTION_X "0.0002"
*MEAS_SCAN_SPEED "0.500000"
*MEAS_SCAN_SPEED_UNIT "deg/min"
*MEAS_SCAN_SPEED_USER "0.500000"
*MEAS_SCAN_START "0.0000000000"
*MEAS_SCAN_START_TIME "11/06/23 15:36:28"
*MEAS_SCAN_STEP "0.0020000000"
*MEAS_SCAN_STOP "6.0000000000"
*MEAS_SCAN_UNIT_X "deg"
*MEAS_SCAN_UNIT_Y "counts"
*RAS_HEADER_END
*RAS_INT_START
0.0000 5188807.5000 1.0000
0.0060 5407685.5000 1.0000
0.0120 5488644.5000 1.0000
0.0180 5404927.5000 1.0000
0.0240 5335554.0000 1.0000
0.0300 4888832.5000 1.0000
0.0360 4382254.0000 1.0000
0.0420 3513913.0000 1.0000
0.0480 2654122.7500 1.0000
0.0540 1713649.7500 1.0000
0.0600 1102882.7500 1.0000
0.0660 569094.9375 1.0000
0.0720 289418.2813 1.0000
0.0780 168675.8906 1.0000
0.0840 122246.8203 1.0000
0.0900 100246.2656 1.0000
0.0960 90742.9844 1.0000
0.1020 92820.8984 1.0000
0.1080 94645.5859 1.0000
0.1140 94548.7578 1.0000
0.1200 98302.4141 1.0000
0.1260 107597.1641 1.0000
0.1320 114009.6484 1.0000
0.1380 117435.5938 1.0000
0.1440 120675.3516 1.0000
0.1500 122082.9766 1.0000
0.1560 130737.2188 1.0000
0.1620 135190.9531 1.0000
0.1680 136918.8281 1.0000
0.1740 146608.2969 1.0000
0.1800 147420.0938 1.0000
0.1860 156208.4063 1.0000
0.1920 158211.8438 1.0000
0.1980 161086.6563 1.0000
0.2040 166381.9844 1.0000
0.2100 167134.2188 1.0000
0.2160 176555.5781 1.0000
0.2220 180875.2500 1.0000
0.2280 175557.5781 1.0000
0.2340 190244.4688 1.0000
0.2400 197707.0938 1.0000
0.2460 198146.5000 1.0000
0.2520 200783.0000 1.0000
0.2580 209690.4531 1.0000
0.2640 215499.6719 1.0000
0.2700 216698.7656 1.0000
0.2760 224399.7031 1.0000
0.2820 227505.4063 1.0000
0.2880 230484.4844 1.0000
0.2940 237232.1094 1.0000
0.3000 236323.5000 1.0000
0.3060 243510.5469 1.0000
0.3120 248507.9688 1.0000
0.3180 247122.6875 1.0000
0.3240 256104.6250 1.0000
0.3300 267440.0625 1.0000
0.3360 263701.3125 1.0000
0.3420 270739.4063 1.0000
0.3480 273591.8750 1.0000
0.3540 279311.7188 1.0000
0.3600 284696.4063 1.0000
0.3660 288710.7188 1.0000
0.3720 293976.2813 1.0000
0.3780 296985.1563 1.0000
0.3840 294981.7188 1.0000
0.3900 307754.5625 1.0000
0.3960 313533.9688 1.0000
0.4020 305319.1563 1.0000
0.4080 312014.6563 1.0000
0.4140 322843.6250 1.0000
0.4200 322798.9375 1.0000
0.4260 326619.6250 1.0000
0.4320 336860.2188 1.0000
0.4380 328228.3125 1.0000
0.4440 337664.5625 1.0000
0.4500 342766.2813 1.0000
0.4560 345924.0938 1.0000
0.4620 354124.0313 1.0000
0.4680 356321.0938 1.0000
0.4740 354213.4063 1.0000
0.4800 357833.0000 1.0000
0.4860 371507.0000 1.0000
0.4920 373517.9063 1.0000
0.4980 379342.0000 1.0000
0.5040 377077.9063 1.0000
0.5100 377427.9375 1.0000
0.5160 378254.6250 1.0000
0.5220 386499.2500 1.0000
0.5280 386678.0000 1.0000
0.5340 390714.6563 1.0000
0.5400 385233.1563 1.0000
0.5460 392375.5000 1.0000
0.5520 399562.5313 1.0000
0.5580 391317.9375 1.0000
0.5640 395592.9063 1.0000
0.5700 386484.3750 1.0000
0.5760 398691.1563 1.0000
0.5820 396136.5938 1.0000
0.5880 388212.2188 1.0000
0.5940 396233.4063 1.0000
0.6000 405610.0938 1.0000
0.6060 387415.3125 1.0000
0.6120 392114.8438 1.0000
0.6180 379625.0000 1.0000
0.6240 375215.9688 1.0000
0.6300 371946.4063 1.0000
0.6360 355360.3438 1.0000
0.6420 346095.3750 1.0000
0.6480 334290.7500 1.0000
0.6540 313601.0000 1.0000
0.6600 301066.5000 1.0000
0.6660 280481.0000 1.0000
0.6720 259113.5156 1.0000
0.6780 241939.0781 1.0000
0.6840 215685.8750 1.0000
0.6900 200090.3594 1.0000
0.6960 181076.3281 1.0000
0.7020 167700.2344 1.0000
0.7080 149781.0313 1.0000
0.7140 136315.5625 1.0000
0.7200 124183.2266 1.0000
0.7260 112296.6719 1.0000
0.7320 98726.9297 1.0000
0.7380 95278.6406 1.0000
0.7440 87510.6719 1.0000
0.7500 80070.4063 1.0000
0.7560 75482.6094 1.0000
0.7620 68518.9922 1.0000
0.7680 66113.3828 1.0000
0.7740 62180.9844 1.0000
0.7800 63342.8281 1.0000
0.7860 60805.9063 1.0000
0.7920 57018.0000 1.0000
0.7980 54658.5000 1.0000
0.8040 52137.5000 1.0000
0.8100 50665.8320 1.0000
0.8160 48511.6680 1.0000
0.8220 46716.6680 1.0000
0.8280 45028.6680 1.0000
0.8340 43431.8320 1.0000
0.8400 41384.8320 1.0000
0.8460 39794.0000 1.0000
0.8520 38130.0000 1.0000
0.8580 36938.8320 1.0000
0.8640 35032.8320 1.0000
0.8700 33512.8320 1.0000
0.8760 31712.8340 1.0000
0.8820 30497.3340 1.0000
0.8880 29019.5000 1.0000
0.8940 27677.6660 1.0000
0.9000 26408.8340 1.0000
0.9060 25025.5000 1.0000
0.9120 23916.5000 1.0000
0.9180 22919.3340 1.0000
0.9240 21717.3340 1.0000
0.9300 21057.5000 1.0000
0.9360 19944.8340 1.0000
0.9420 19246.5000 1.0000
0.9480 18235.6660 1.0000
0.9540 17953.6660 1.0000
0.9600 17259.0000 1.0000
0.9660 16455.5000 1.0000
0.9720 15849.8330 1.0000
0.9780 15564.8330 1.0000
0.9840 15131.1670 1.0000
0.9900 14874.1670 1.0000
0.9960 14513.1670 1.0000
1.0020 14098.1670 1.0000
1.0080 13987.3330 1.0000
1.0140 13775.6670 1.0000
1.0200 13317.8330 1.0000
1.0260 13119.6670 1.0000
1.0320 13135.6670 1.0000
1.0380 12881.0000 1.0000
1.0440 12533.1670 1.0000
1.0500 12358.3330 1.0000
1.0560 12389.5000 1.0000
1.0620 11928.8330 1.0000
1.0680 11778.5000 1.0000
1.0740 11573.3330 1.0000
1.0800 11247.6670 1.0000
1.0860 11266.1670 1.0000
1.0920 10935.0000 1.0000
1.0980 10667.3330 1.0000
1.1040 10141.8330 1.0000
1.1100 9943.6670 1.0000
1.1160 9902.3330 1.0000
1.1220 9394.8330 1.0000
1.1280 9286.0000 1.0000
1.1340 8973.5000 1.0000
1.1400 8797.1670 1.0000
1.1460 8327.1670 1.0000
1.1520 8049.0000 1.0000
1.1580 7802.0000 1.0000
1.1640 7591.1665 1.0000
1.1700 7163.3335 1.0000
1.1760 7045.8335 1.0000
1.1820 6817.6665 1.0000
1.1880 6568.0000 1.0000
1.1940 6437.8335 1.0000
1.2000 6135.5000 1.0000
1.2060 6066.3335 1.0000
1.2120 5809.6665 1.0000
1.2180 5623.0000 1.0000
1.2240 5608.0000 1.0000
1.2300 5339.8335 1.0000
1.2360 5227.3335 1.0000
1.2420 5022.5000 1.0000
1.2480 4865.6665 1.0000
1.2540 4806.6665 1.0000
1.2600 4693.8335 1.0000
1.2660 4722.0000 1.0000
1.2720 4539.8335 1.0000
1.2780 4446.0000 1.0000
1.2840 4424.1665 1.0000
1.2900 4378.6665 1.0000
1.2960 4331.3335 1.0000
1.3020 4403.0000 1.0000
1.3080 4225.0000 1.0000
1.3140 4225.3335 1.0000
1.3200 4220.1665 1.0000
1.3260 4253.8335 1.0000
1.3320 4140.0000 1.0000
1.3380 4105.5000 1.0000
1.3440 4016.5000 1.0000
1.3500 4185.6665 1.0000
1.3560 3841.8333 1.0000
1.3620 3952.1667 1.0000
1.3680 3926.0000 1.0000
1.3740 3912.8333 1.0000
1.3800 3735.1667 1.0000
1.3860 3711.0000 1.0000
1.3920 3660.5000 1.0000
1.3980 3729.0000 1.0000
1.4040 3609.0000 1.0000
1.4100 3440.3333 1.0000
1.4160 3446.1667 1.0000
1.4220 3243.8333 1.0000
1.4280 3282.3333 1.0000
1.4340 3233.1667 1.0000
1.4400 3053.1667 1.0000
1.4460 2961.6667 1.0000
1.4520 2963.6667 1.0000
1.4580 2773.8333 1.0000
1.4640 2716.1667 1.0000
1.4700 2639.5000 1.0000
1.4760 2553.1667 1.0000
1.4820 2522.6667 1.0000
1.4880 2455.6667 1.0000
1.4940 2409.1667 1.0000
1.5000 2205.5000 1.0000
1.5060 2163.5000 1.0000
1.5120 2192.1667 1.0000
1.5180 2056.1667 1.0000
1.5240 1968.0000 1.0000
1.5300 1952.6666 1.0000
1.5360 1908.3334 1.0000
1.5420 1863.5000 1.0000
1.5480 1767.0000 1.0000
1.5540 1782.6666 1.0000
1.5600 1714.8334 1.0000
1.5660 1701.6666 1.0000
1.5720 1640.8334 1.0000
1.5780 1566.8334 1.0000
1.5840 1617.6666 1.0000
1.5900 1703.8334 1.0000
1.5960 1596.5000 1.0000
1.6020 1599.3334 1.0000
1.6080 1703.0000 1.0000
1.6140 1640.1666 1.0000
1.6200 1580.5000 1.0000
1.6260 1632.1666 1.0000
1.6320 1560.3334 1.0000
1.6380 1525.8334 1.0000
1.6440 1599.3334 1.0000
1.6500 1495.8334 1.0000
1.6560 1456.3334 1.0000
1.6620 1526.3334 1.0000
1.6680 1550.1666 1.0000
1.6740 1526.1666 1.0000
1.6800 1495.5000 1.0000
1.6860 1543.1666 1.0000
1.6920 1516.6666 1.0000
1.6980 1446.8334 1.0000
1.7040 1534.8334 1.0000
1.7100 1488.0000 1.0000
1.7160 1478.6666 1.0000
1.7220 1382.6666 1.0000
1.7280 1392.0000 1.0000
1.7340 1417.1666 1.0000
1.7400 1302.6666 1.0000
1.7460 1293.0000 1.0000
1.7520 1240.5000 1.0000
1.7580 1243.8334 1.0000
1.7640 1213.1666 1.0000
1.7700 1168.1666 1.0000
1.7760 1156.3334 1.0000
1.7820 1164.6666 1.0000
1.7880 991.8333 1.0000
1.7940 1137.6666 1.0000
1.8000 1013.5000 1.0000
1.8060 1040.8334 1.0000
1.8120 995.6667 1.0000
1.8180 966.6667 1.0000
1.8240 930.6667 1.0000
1.8300 915.3333 1.0000
1.8360 882.5000 1.0000
1.8420 853.5000 1.0000
1.8480 891.0000 1.0000
1.8540 823.8333 1.0000
1.8600 815.8333 1.0000
1.8660 806.6667 1.0000
1.8720 763.8333 1.0000
1.8780 732.3333 1.0000
1.8840 736.8333 1.0000
1.8900 721.1667 1.0000
1.8960 724.6667 1.0000
1.9020 732.1667 1.0000
1.9080 640.3333 1.0000
1.9140 706.0000 1.0000
1.9200 685.6667 1.0000
1.9260 658.6667 1.0000
1.9320 686.5000 1.0000
1.9380 647.6667 1.0000
1.9440 683.1667 1.0000
1.9500 693.1667 1.0000
1.9560 657.1667 1.0000
1.9620 651.1667 1.0000
1.9680 669.1667 1.0000
1.9740 675.0000 1.0000
1.9800 685.6667 1.0000
1.9860 694.5000 1.0000
1.9920 688.5000 1.0000
1.9980 627.0000 1.0000
2.0040 647.6667 1.0000
2.0100 665.1667 1.0000
2.0160 666.1667 1.0000
2.0220 658.6667 1.0000
2.0280 633.5000 1.0000
2.0340 640.1667 1.0000
2.0400 606.1667 1.0000
2.0460 621.0000 1.0000
2.0520 644.6667 1.0000
2.0580 587.8333 1.0000
2.0640 612.8333 1.0000
2.0700 580.3333 1.0000
2.0760 584.6667 1.0000
2.0820 595.1667 1.0000
2.0880 559.1667 1.0000
2.0940 581.8333 1.0000
2.1000 549.0000 1.0000
2.1060 540.1667 1.0000
2.1120 518.3333 1.0000
2.1180 496.1667 1.0000
2.1240 488.3333 1.0000
2.1300 463.5000 1.0000
2.1360 441.5000 1.0000
2.1420 397.5000 1.0000
2.1480 430.6667 1.0000
2.1540 438.8333 1.0000
2.1600 374.0000 1.0000
2.1660 407.6667 1.0000
2.1720 375.8333 1.0000
2.1780 378.0000 1.0000
2.1840 354.3333 1.0000
2.1900 373.3333 1.0000
2.1960 334.1667 1.0000
2.2020 356.1667 1.0000
2.2080 337.8333 1.0000
2.2140 337.0000 1.0000
2.2200 321.5000 1.0000
2.2260 316.0000 1.0000
2.2320 300.5000 1.0000
2.2380 375.5000 1.0000
2.2440 300.3333 1.0000
2.2500 288.0000 1.0000
2.2560 295.0000 1.0000
2.2620 277.8333 1.0000
2.2680 330.1667 1.0000
2.2740 275.5000 1.0000
2.2800 312.3333 1.0000
2.2860 310.5000 1.0000
2.2920 292.6667 1.0000
2.2980 276.6667 1.0000
2.3040 274.8333 1.0000
2.3100 294.8333 1.0000
2.3160 294.5000 1.0000
2.3220 300.3333 1.0000
2.3280 303.0000 1.0000
2.3340 288.6667 1.0000
2.3400 320.1667 1.0000
2.3460 303.6667 1.0000
2.3520 290.3333 1.0000
2.3580 307.6667 1.0000
2.3640 318.8333 1.0000
2.3700 284.8333 1.0000
2.3760 308.3333 1.0000
2.3820 307.8333 1.0000
2.3880 295.1667 1.0000
2.3940 264.0000 1.0000
2.4000 248.6667 1.0000
2.4060 253.3333 1.0000
2.4120 282.1667 1.0000
2.4180 255.3333 1.0000
2.4240 219.5000 1.0000
2.4300 280.1667 1.0000
2.4360 223.5000 1.0000
2.4420 271.6667 1.0000
2.4480 238.6667 1.0000
2.4540 264.5000 1.0000
2.4600 212.0000 1.0000
2.4660 211.8333 1.0000
2.4720 210.6667 1.0000
2.4780 217.5000 1.0000
2.4840 196.5000 1.0000
2.4900 177.0000 1.0000
2.4960 197.3333 1.0000
2.5020 162.8333 1.0000
2.5080 167.8333 1.0000
2.5140 188.6667 1.0000
2.5200 174.8333 1.0000
2.5260 182.6667 1.0000
2.5320 149.0000 1.0000
2.5380 163.5000 1.0000
2.5440 177.1667 1.0000
2.5500 190.5000 1.0000
2.5560 156.5000 1.0000
2.5620 195.1667 1.0000
2.5680 164.0000 1.0000
2.5740 150.5000 1.0000
2.5800 143.8333 1.0000
2.5860 136.3333 1.0000
2.5920 152.1667 1.0000
2.5980 172.8333 1.0000
2.6040 160.3333 1.0000
2.6100 138.0000 1.0000
2.6160 155.8333 1.0000
2.6220 126.6667 1.0000
2.6280 159.6667 1.0000
2.6340 151.6667 1.0000
2.6400 147.0000 1.0000
2.6460 150.0000 1.0000
2.6520 141.6667 1.0000
2.6580 144.1667 1.0000
2.6640 127.6667 1.0000
2.6700 152.6667 1.0000
2.6760 135.6667 1.0000
2.6820 137.3333 1.0000
2.6880 149.0000 1.0000
2.6940 161.3333 1.0000
2.7000 170.8333 1.0000
2.7060 118.1667 1.0000
2.7120 144.5000 1.0000
2.7180 123.0000 1.0000
2.7240 134.6667 1.0000
2.7300 133.3333 1.0000
2.7360 125.8333 1.0000
2.7420 125.1667 1.0000
2.7480 122.1667 1.0000
2.7540 130.0000 1.0000
2.7600 116.3333 1.0000
2.7660 138.8333 1.0000
2.7720 117.8333 1.0000
2.7780 123.1667 1.0000
2.7840 103.5000 1.0000
2.7900 112.3333 1.0000
2.7960 111.0000 1.0000
2.8020 115.1667 1.0000
2.8080 109.6667 1.0000
2.8140 108.1667 1.0000
2.8200 99.1667 1.0000
2.8260 83.6667 1.0000
2.8320 97.1667 1.0000
2.8380 87.8333 1.0000
2.8440 93.6667 1.0000
2.8500 77.3333 1.0000
2.8560 81.3333 1.0000
2.8620 69.0000 1.0000
2.8680 85.6667 1.0000
2.8740 51.6667 1.0000
2.8800 72.3333 1.0000
2.8860 76.0000 1.0000
2.8920 74.6667 1.0000
2.8980 78.1667 1.0000
2.9040 71.1667 1.0000
2.9100 64.5000 1.0000
2.9160 77.1667 1.0000
2.9220 71.6667 1.0000
2.9280 69.3333 1.0000
2.9340 57.6667 1.0000
2.9400 84.0000 1.0000
2.9460 78.8333 1.0000
2.9520 80.5000 1.0000
2.9580 69.0000 1.0000
2.9640 69.6667 1.0000
2.9700 71.3333 1.0000
2.9760 70.8333 1.0000
2.9820 83.8333 1.0000
2.9880 65.3333 1.0000
2.9940 65.5000 1.0000
3.0000 87.1667 1.0000
3.0060 61.6667 1.0000
3.0120 66.5000 1.0000
3.0180 76.8333 1.0000
3.0240 78.6667 1.0000
3.0300 72.5000 1.0000
3.0360 68.0000 1.0000
3.0420 74.1667 1.0000
3.0480 77.0000 1.0000
3.0540 82.8333 1.0000
3.0600 71.1667 1.0000
3.0660 72.3333 1.0000
3.0720 85.1667 1.0000
3.0780 75.6667 1.0000
3.0840 71.1667 1.0000
3.0900 66.8333 1.0000
3.0960 66.0000 1.0000
3.1020 55.8333 1.0000
3.1080 53.6667 1.0000
3.1140 61.1667 1.0000
3.1200 74.5000 1.0000
3.1260 61.8333 1.0000
3.1320 58.5000 1.0000
3.1380 57.6667 1.0000
3.1440 46.6667 1.0000
3.1500 55.8333 1.0000
3.1560 58.1667 1.0000
3.1620 34.6667 1.0000
3.1680 47.6667 1.0000
3.1740 57.3333 1.0000
3.1800 41.0000 1.0000
3.1860 48.0000 1.0000
3.1920 41.8333 1.0000
3.1980 42.3333 1.0000
3.2040 44.1667 1.0000
3.2100 39.8333 1.0000
3.2160 39.5000 1.0000
3.2220 38.6667 1.0000
3.2280 37.1667 1.0000
3.2340 41.6667 1.0000
3.2400 43.6667 1.0000
3.2460 37.1667 1.0000
3.2520 52.3333 1.0000
3.2580 39.5000 1.0000
3.2640 36.3333 1.0000
3.2700 37.8333 1.0000
3.2760 42.0000 1.0000
3.2820 39.8333 1.0000
3.2880 45.8333 1.0000
3.2940 43.5000 1.0000
3.3000 21.8333 1.0000
3.3060 34.1667 1.0000
3.3120 45.5000 1.0000
3.3180 27.3333 1.0000
3.3240 32.3333 1.0000
3.3300 38.0000 1.0000
3.3360 41.1667 1.0000
3.3420 34.8333 1.0000
3.3480 28.0000 1.0000
3.3540 31.1667 1.0000
3.3600 32.5000 1.0000
3.3660 39.1667 1.0000
3.3720 44.3333 1.0000
3.3780 33.6667 1.0000
3.3840 33.6667 1.0000
3.3900 39.1667 1.0000
3.3960 45.6667 1.0000
3.4020 25.3333 1.0000
3.4080 36.3333 1.0000
3.4140 50.8333 1.0000
3.4200 48.6667 1.0000
3.4260 32.3333 1.0000
3.4320 36.6667 1.0000
3.4380 38.8333 1.0000
3.4440 33.6667 1.0000
3.4500 28.3333 1.0000
3.4560 23.0000 1.0000
3.4620 34.3333 1.0000
3.4680 34.5000 1.0000
3.4740 41.0000 1.0000
3.4800 34.8333 1.0000
3.4860 31.1667 1.0000
3.4920 30.3333 1.0000
3.4980 32.8333 1.0000
3.5040 32.6667 1.0000
3.5100 26.1667 1.0000
3.5160 26.5000 1.0000
3.5220 25.1667 1.0000
3.5280 27.6667 1.0000
3.5340 27.6667 1.0000
3.5400 20.1667 1.0000
3.5460 23.5000 1.0000
3.5520 26.5000 1.0000
3.5580 20.0000 1.0000
3.5640 20.0000 1.0000
3.5700 26.8333 1.0000
3.5760 25.3333 1.0000
3.5820 25.1667 1.0000
3.5880 25.6667 1.0000
3.5940 19.6667 1.0000
3.6000 17.1667 1.0000
3.6060 18.5000 1.0000
3.6120 25.3333 1.0000
3.6180 21.6667 1.0000
3.6240 24.3333 1.0000
3.6300 27.3333 1.0000
3.6360 17.3333 1.0000
3.6420 19.5000 1.0000
3.6480 25.0000 1.0000
3.6540 24.0000 1.0000
3.6600 18.3333 1.0000
3.6660 26.5000 1.0000
3.6720 19.6667 1.0000
3.6780 18.3333 1.0000
3.6840 23.1667 1.0000
3.6900 16.0000 1.0000
3.6960 25.5000 1.0000
3.7020 28.3333 1.0000
3.7080 17.3333 1.0000
3.7140 13.6667 1.0000
3.7200 28.3333 1.0000
3.7260 24.3333 1.0000
3.7320 30.8333 1.0000
3.7380 39.6667 1.0000
3.7440 26.6667 1.0000
3.7500 21.5000 1.0000
3.7560 22.8333 1.0000
3.7620 27.5000 1.0000
3.7680 18.0000 1.0000
3.7740 26.6667 1.0000
3.7800 22.1667 1.0000
3.7860 19.6667 1.0000
3.7920 12.3333 1.0000
3.7980 17.0000 1.0000
3.8040 21.0000 1.0000
3.8100 22.0000 1.0000
3.8160 18.6667 1.0000
3.8220 23.3333 1.0000
3.8280 13.5000 1.0000
3.8340 18.5000 1.0000
3.8400 19.1667 1.0000
3.8460 16.5000 1.0000
3.8520 16.6667 1.0000
3.8580 13.1667 1.0000
3.8640 16.6667 1.0000
3.8700 17.5000 1.0000
3.8760 17.8333 1.0000
3.8820 11.3333 1.0000
3.8880 12.8333 1.0000
3.8940 18.6667 1.0000
3.9000 18.3333 1.0000
3.9060 8.3333 1.0000
3.9120 11.1667 1.0000
3.9180 12.5000 1.0000
3.9240 16.8333 1.0000
3.9300 12.6667 1.0000
3.9360 11.8333 1.0000
3.9420 18.1667 1.0000
3.9480 11.5000 1.0000
3.9540 13.0000 1.0000
3.9600 10.1667 1.0000
3.9660 8.8333 1.0000
3.9720 10.0000 1.0000
3.9780 14.1667 1.0000
3.9840 10.1667 1.0000
3.9900 14.5000 1.0000
3.9960 7.0000 1.0000
4.0020 5.6667 1.0000
4.0080 11.6667 1.0000
4.0140 22.6667 1.0000
4.0200 17.6667 1.0000
4.0260 12.0000 1.0000
4.0320 8.5000 1.0000
4.0380 14.1667 1.0000
4.0440 9.0000 1.0000
4.0500 17.8333 1.0000
4.0560 8.3333 1.0000
4.0620 12.0000 1.0000
4.0680 9.0000 1.0000
4.0740 12.6667 1.0000
4.0800 14.1667 1.0000
4.0860 14.8333 1.0000
4.0920 17.5000 1.0000
4.0980 21.3333 1.0000
4.1040 19.8333 1.0000
4.1100 12.5000 1.0000
4.1160 17.5000 1.0000
4.1220 16.1667 1.0000
4.1280 10.1667 1.0000
4.1340 15.3333 1.0000
4.1400 12.8333 1.0000
4.1460 13.1667 1.0000
4.1520 17.8333 1.0000
4.1580 7.0000 1.0000
4.1640 13.8333 1.0000
4.1700 14.0000 1.0000
4.1760 13.8333 1.0000
4.1820 12.5000 1.0000
4.1880 10.8333 1.0000
4.1940 3.8333 1.0000
4.2000 8.8333 1.0000
4.2060 9.3333 1.0000
4.2120 14.0000 1.0000
4.2180 11.6667 1.0000
4.2240 8.8333 1.0000
4.2300 12.6667 1.0000
4.2360 10.8333 1.0000
4.2420 8.5000 1.0000
4.2480 13.8333 1.0000
4.2540 7.0000 1.0000
4.2600 13.8333 1.0000
4.2660 6.0000 1.0000
4.2720 9.1667 1.0000
4.2780 6.6667 1.0000
4.2840 11.3333 1.0000
4.2900 11.3333 1.0000
4.2960 7.8333 1.0000
4.3020 11.0000 1.0000
4.3080 0.8333 1.0000
4.3140 9.6667 1.0000
4.3200 11.0000 1.0000
4.3260 3.3333 1.0000
4.3320 7.5000 1.0000
4.3380 6.1667 1.0000
4.3440 3.5000 1.0000
4.3500 13.5000 1.0000
4.3560 11.3333 1.0000
4.3620 8.8333 1.0000
4.3680 4.6667 1.0000
4.3740 15.0000 1.0000
4.3800 8.8333 1.0000
4.3860 5.3333 1.0000
4.3920 8.5000 1.0000
4.3980 7.6667 1.0000
4.4040 12.3333 1.0000
4.4100 13.8333 1.0000
4.4160 14.1667 1.0000
4.4220 6.6667 1.0000
4.4280 12.6667 1.0000
4.4340 2.8333 1.0000
4.4400 7.1667 1.0000
4.4460 9.0000 1.0000
4.4520 17.8333 1.0000
4.4580 10.6667 1.0000
4.4640 12.8333 1.0000
4.4700 8.8333 1.0000
4.4760 12.0000 1.0000
4.4820 6.8333 1.0000
4.4880 7.0000 1.0000
4.4940 11.6667 1.0000
4.5000 9.1667 1.0000
4.5060 8.5000 1.0000
4.5120 8.5000 1.0000
4.5180 11.0000 1.0000
4.5240 10.6667 1.0000
4.5300 7.3333 1.0000
4.5360 3.5000 1.0000
4.5420 5.6667 1.0000
4.5480 6.3333 1.0000
4.5540 8.3333 1.0000
4.5600 9.8333 1.0000
4.5660 5.8333 1.0000
4.5720 3.3333 1.0000
4.5780 7.8333 1.0000
4.5840 4.8333 1.0000
4.5900 11.1667 1.0000
4.5960 9.0000 1.0000
4.6020 9.8333 1.0000
4.6080 5.5000 1.0000
4.6140 3.3333 1.0000
4.6200 5.1667 1.0000
4.6260 4.0000 1.0000
4.6320 6.1667 1.0000
4.6380 4.0000 1.0000
4.6440 6.5000 1.0000
4.6500 12.8333 1.0000
4.6560 4.8333 1.0000
4.6620 2.6667 1.0000
4.6680 8.5000 1.0000
4.6740 7.1667 1.0000
4.6800 8.1667 1.0000
4.6860 3.1667 1.0000
4.6920 10.6667 1.0000
4.6980 6.6667 1.0000
4.7040 5.3333 1.0000
4.7100 4.1667 1.0000
4.7160 11.0000 1.0000
4.7220 5.6667 1.0000
4.7280 9.5000 1.0000
4.7340 4.0000 1.0000
4.7400 12.6667 1.0000
4.7460 8.1667 1.0000
4.7520 4.0000 1.0000
4.7580 5.0000 1.0000
4.7640 13.3333 1.0000
4.7700 4.5000 1.0000
4.7760 4.5000 1.0000
4.7820 6.0000 1.0000
4.7880 12.6667 1.0000
4.7940 6.3333 1.0000
4.8000 8.3333 1.0000
4.8060 9.8333 1.0000
4.8120 9.5000 1.0000
4.8180 2.6667 1.0000
4.8240 2.3333 1.0000
4.8300 7.6667 1.0000
4.8360 5.6667 1.0000
4.8420 4.6667 1.0000
4.8480 4.6667 1.0000
4.8540 7.0000 1.0000
4.8600 6.0000 1.0000
4.8660 8.6667 1.0000
4.8720 4.5000 1.0000
4.8780 7.8333 1.0000
4.8840 0.0000 1.0000
4.8900 7.3333 1.0000
4.8960 4.5000 1.0000
4.9020 7.3333 1.0000
4.9080 4.8333 1.0000
4.9140 10.1667 1.0000
4.9200 3.1667 1.0000
4.9260 6.8333 1.0000
4.9320 3.3333 1.0000
4.9380 5.6667 1.0000
4.9440 6.1667 1.0000
4.9500 4.6667 1.0000
4.9560 4.8333 1.0000
4.9620 3.5000 1.0000
4.9680 3.3333 1.0000
4.9740 4.5000 1.0000
4.9800 3.0000 1.0000
4.9860 1.5000 1.0000
4.9920 0.6667 1.0000
4.9980 2.1667 1.0000
5.0040 6.0000 1.0000
5.0100 10.6667 1.0000
5.0160 6.3333 1.0000
5.0220 3.6667 1.0000
5.0280 3.6667 1.0000
5.0340 3.6667 1.0000
5.0400 4.1667 1.0000
5.0460 2.5000 1.0000
5.0520 3.5000 1.0000
5.0580 3.3333 1.0000
5.0640 2.1667 1.0000
5.0700 3.3333 1.0000
5.0760 6.6667 1.0000
5.0820 3.6667 1.0000
5.0880 4.8333 1.0000
5.0940 2.5000 1.0000
5.1000 4.3333 1.0000
5.1060 6.5000 1.0000
5.1120 0.3333 1.0000
5.1180 2.3333 1.0000
5.1240 2.3333 1.0000
5.1300 5.1667 1.0000
5.1360 9.6667 1.0000
5.1420 2.3333 1.0000
5.1480 5.1667 1.0000
5.1540 3.0000 1.0000
5.1600 3.5000 1.0000
5.1660 4.6667 1.0000
5.1720 4.3333 1.0000
5.1780 2.3333 1.0000
5.1840 6.5000 1.0000
5.1900 6.6667 1.0000
5.1960 4.1667 1.0000
5.2020 4.3333 1.0000
5.2080 3.1667 1.0000
5.2140 6.5000 1.0000
5.2200 2.3333 1.0000
5.2260 6.3333 1.0000
5.2320 2.0000 1.0000
5.2380 8.5000 1.0000
5.2440 4.0000 1.0000
5.2500 3.3333 1.0000
5.2560 1.1667 1.0000
5.2620 2.1667 1.0000
5.2680 5.6667 1.0000
5.2740 3.0000 1.0000
5.2800 1.6667 1.0000
5.2860 4.1667 1.0000
5.2920 1.3333 1.0000
5.2980 0.0000 1.0000
5.3040 4.1667 1.0000
5.3100 8.1667 1.0000
5.3160 3.3333 1.0000
5.3220 4.0000 1.0000
5.3280 4.8333 1.0000
5.3340 3.1667 1.0000
5.3400 3.6667 1.0000
5.3460 1.5000 1.0000
5.3520 3.5000 1.0000
5.3580 1.3333 1.0000
5.3640 4.3333 1.0000
5.3700 4.6667 1.0000
5.3760 8.3333 1.0000
5.3820 3.1667 1.0000
5.3880 5.1667 1.0000
5.3940 8.5000 1.0000
5.4000 4.8333 1.0000
5.4060 2.1667 1.0000
5.4120 5.1667 1.0000
5.4180 6.5000 1.0000
5.4240 9.1667 1.0000
5.4300 3.5000 1.0000
5.4360 1.1667 1.0000
5.4420 6.0000 1.0000
5.4480 0.1667 1.0000
5.4540 3.3333 1.0000
5.4600 5.0000 1.0000
5.4660 0.3333 1.0000
5.4720 4.0000 1.0000
5.4780 0.0000 1.0000
5.4840 0.1667 1.0000
5.4900 2.6667 1.0000
5.4960 4.6667 1.0000
5.5020 0.6667 1.0000
5.5080 3.3333 1.0000
5.5140 4.3333 1.0000
5.5200 4.0000 1.0000
5.5260 4.5000 1.0000
5.5320 4.0000 1.0000
5.5380 0.0000 1.0000
5.5440 5.3333 1.0000
5.5500 0.0000 1.0000
5.5560 2.0000 1.0000
5.5620 0.0000 1.0000
5.5680 0.6667 1.0000
5.5740 5.1667 1.0000
5.5800 7.5000 1.0000
5.5860 6.0000 1.0000
5.5920 0.5000 1.0000
5.5980 2.3333 1.0000
5.6040 2.1667 1.0000
5.6100 1.1667 1.0000
5.6160 5.3333 1.0000
5.6220 0.1667 1.0000
5.6280 2.5000 1.0000
5.6340 4.5000 1.0000
5.6400 2.5000 1.0000
5.6460 0.3333 1.0000
5.6520 1.1667 1.0000
5.6580 0.1667 1.0000
5.6640 2.3333 1.0000
5.6700 2.5000 1.0000
5.6760 0.3333 1.0000
5.6820 0.0000 1.0000
5.6880 2.3333 1.0000
5.6940 0.1667 1.0000
5.7000 6.3333 1.0000
5.7060 4.5000 1.0000
5.7120 1.1667 1.0000
5.7180 1.3333 1.0000
5.7240 3.0000 1.0000
5.7300 5.1667 1.0000
5.7360 2.1667 1.0000
5.7420 3.8333 1.0000
5.7480 9.3333 1.0000
5.7540 3.0000 1.0000
5.7600 4.8333 1.0000
5.7660 0.3333 1.0000
5.7720 0.0000 1.0000
5.7780 0.3333 1.0000
5.7840 4.1667 1.0000
5.7900 2.5000 1.0000
5.7960 4.0000 1.0000
5.8020 0.1667 1.0000
5.8080 3.5000 1.0000
5.8140 1.1667 1.0000
5.8200 4.1667 1.0000
5.8260 0.0000 1.0000
5.8320 2.3333 1.0000
5.8380 0.0000 1.0000
5.8440 4.5000 1.0000
5.8500 0.0000 1.0000
5.8560 4.1667 1.0000
5.8620 0.0000 1.0000
5.8680 3.3333 1.0000
5.8740 0.0000 1.0000
5.8800 2.1667 1.0000
5.8860 4.3333 1.0000
5.8920 0.0000 1.0000
5.8980 1.1667 1.0000
5.9040 0.0000 1.0000
5.9100 2.0000 1.0000
5.9160 0.0000 1.0000
5.9220 0.1667 1.0000
5.9280 0.1667 1.0000
5.9340 2.3333 1.0000
5.9400 0.0000 1.0000
5.9460 1.1667 1.0000
5.9520 2.0000 1.0000
5.9580 4.3333 1.0000
5.9640 4.1667 1.0000
5.9700 0.0000 1.0000
5.9760 0.0000 1.0000
5.9820 1.3333 1.0000
5.9880 1.1667 1.0000
5.9940 3.3333 1.0000
6.0000 2.1667 1.0000
*RAS_INT_END
*RAS_DATA_END