File: XRR/CWOI5anneal_reflectivity.ras
*RAS_DATA_START
*RAS_HEADER_START
*DISP_FMT_X "%.4f"
*DISP_FMT_Y "%.0f"
*DISP_FULLSCALE "27252893.2000000030"
*DISP_LINE_COLOR "255.0000000000"
*DISP_LINE_STYLE "0.0000000000"
*DISP_LINE_WIDTH "0.2500000000"
*DISP_NOTE "Collected Data-5"
*DISP_OFFSET_Y "0.0000000000"
*DISP_PEAKSEARCH_UNIT_Y "cps"
*DISP_RANGE_BOTTOM "0.0100000000"
*DISP_RANGE_LEFT "-0.0006000000"
*DISP_RANGE_LOGCUTOFF "0.0100000000"
*DISP_RANGE_RIGHT "6.0006000000"
*DISP_RANGE_TOP "27252893.2000000030"
*DISP_SCALE_MODE_Y "2.0000000000"
*DISP_TAB_NAME "2-Theta/Omega"
*DISP_TITLE_Y "Intensity"
*DISP_UNIT_Y "cps"
*DISP_WINDOW_NAME "MSG_MACROENGINE"
*FILE_COMMENT " "
*FILE_MD5 ""
*FILE_MEMO " "
*FILE_OPERATOR "administrator"
*FILE_PART_ID "MEAS_KHP2_00055"
*FILE_SAMPLE "CWO I5 aneal"
*FILE_TYPE "RAS_RAW"
*FILE_USERGROUP "System Manager"
*FILE_VERSION "1.0000000000"
*HW_ATTACHMENT_ID "ATT0025"
*HW_ATTACHMENT_NAME "標準|Standard"
*HW_COUNTER_ID-0 "CUT0025"
*HW_COUNTER_ID-1 "CUT0020"
*HW_COUNTER_ID-2 "CUT0020"
*HW_COUNTER_ID-3 "CSL0021"
*HW_COUNTER_ID-4 "CMC0021"
*HW_COUNTER_NAME-0 "D/teX Ultra|D/teX Ultra"
*HW_COUNTER_NAME-1 "None|None"
*HW_COUNTER_NAME-2 "None|None"
*HW_COUNTER_NAME-3 "BBM|BBM"
*HW_COUNTER_NAME-4 "検出器モノクロメータ|Detector monochromator"
*HW_COUNTER_SELECT_NAME "D/teX Ultra|D/teX Ultra"
*HW_GONIOMETER_ID "GON0023"
*HW_GONIOMETER_NAME "SmartLab|SmartLab"
*HW_GONIOMETER_RADIUS-0 "90.0"
*HW_GONIOMETER_RADIUS-1 "114.0"
*HW_GONIOMETER_RADIUS-2 "190.0"
*HW_GONIOMETER_RADIUS-3 "300.0"
*HW_GONIOMETER_RADIUS-4 "187.0"
*HW_GONIOMETER_RADIUS-5 "300.0"
*HW_GONIOMETER_RADIUS-6 "113.0"
*HW_GONIOMETER_RADIUS-7 "331.0"
*HW_I_OPT_ID-0 "CBO0021"
*HW_I_OPT_ID-1 "ICR0021"
*HW_I_OPT_ID-2 "ISL0021"
*HW_I_OPT_ID-3 "ISO0021"
*HW_I_OPT_ID-4 "IAD0021"
*HW_I_OPT_ID-5 "IPR0001"
*HW_I_OPT_NAME-0 "CBOユニット|CBO unit"
*HW_I_OPT_NAME-1 "標準入射光学ユニット|Standard incident optical unit"
*HW_I_OPT_NAME-2 "標準入射スリットボックス|Standard incident slit box"
*HW_I_OPT_NAME-3 "入射平行スリット|Incident parallel slit"
*HW_I_OPT_NAME-4 "長手制限スリット|Length limiting slit"
*HW_I_OPT_NAME-5 "None|None"
*HW_R_ATTENUATER_AUTOMODE "1"
*HW_R_OPT_ID-0 "RSS0021"
*HW_R_OPT_ID-1 "RCR0023"
*HW_R_OPT_ID-2 "RSO0021"
*HW_R_OPT_ID-3 "RRS0021"
*HW_R_OPT_ID-4 "ATN0021"
*HW_R_OPT_ID-5 "RFL0021"
*HW_R_OPT_ID-6 "RAD0021"
*HW_R_OPT_NAME-0 "標準受光スリットボックス1|Standard receiving slit box # 1"
*HW_R_OPT_NAME-1 "標準受光光学ユニット1|Standard receiving unit # 1"
*HW_R_OPT_NAME-2 "標準受光光学ユニット2|Standard receiving optical unit # 2"
*HW_R_OPT_NAME-3 "標準受光スリットボックス2|Standard receiving slit box # 2"
*HW_R_OPT_NAME-4 "標準アッテネータ|Standard Attenuator"
*HW_R_OPT_NAME-5 "Cu Kβ|Cu K-beta"
*HW_R_OPT_NAME-6 "調整用受光スリット|Alignment receiving slit"
*HW_SAMPLE_HOLDER_ID "SMP0021"
*HW_SAMPLE_HOLDER_NAME "χφZクレードル|Chi phi Z cradle"
*HW_XG_CURRENT_MAX "200"
*HW_XG_CURRENT_MIN "10"
*HW_XG_CURRENT_RESOLUTION "1"
*HW_XG_CURRENT_UNIT "mA"
*HW_XG_FOCUS "0.4mm x 8mm"
*HW_XG_FOCUS_TYPE "Normal"
*HW_XG_ID "1700"
*HW_XG_NAME "9kW 開放管(45kV 200mA ID:1700)|9kW Rotating anode(45kV 200mA ID:1700)"
*HW_XG_TARGET_ATOMIC_NUMBER "29.0000000000"
*HW_XG_TARGET_NAME "Cu"
*HW_XG_TYPE "Rota"
*HW_XG_VOLTAGE_MAX "45"
*HW_XG_VOLTAGE_MIN "20"
*HW_XG_VOLTAGE_RESOLUTION "1"
*HW_XG_VOLTAGE_UNIT "kV"
*HW_XG_WATT_MAX "9.00"
*HW_XG_WATT_UNIT "kW"
*HW_XG_WAVE_LENGTH_ALPHA1 "1.540593"
*HW_XG_WAVE_LENGTH_ALPHA2 "1.544414"
*HW_XG_WAVE_LENGTH_BETA "1.392250"
*MEAS_COND_AXIS_NAME-0 "Theta/2-Theta"
*MEAS_COND_AXIS_NAME-1 "2-Theta"
*MEAS_COND_AXIS_NAME-2 "Omega"
*MEAS_COND_AXIS_NAME-3 "Chi"
*MEAS_COND_AXIS_NAME-4 "Phi"
*MEAS_COND_AXIS_NAME-5 "Z"
*MEAS_COND_AXIS_NAME-6 "2-Theta/Omega"
*MEAS_COND_AXIS_NAME-7 "Theta_s"
*MEAS_COND_AXIS_NAME-8 "Theta_d"
*MEAS_COND_AXIS_NAME-9 "Ts"
*MEAS_COND_AXIS_NAME-10 "CBO selection slit"
*MEAS_COND_AXIS_NAME-11 "M"
*MEAS_COND_AXIS_NAME-12 "Incident parallel slit"
*MEAS_COND_AXIS_NAME-13 "Incident slit"
*MEAS_COND_AXIS_NAME-14 ""
*MEAS_COND_AXIS_NAME-15 "Zs"
*MEAS_COND_AXIS_NAME-16 "Incident optical device"
*MEAS_COND_AXIS_NAME-17 "Omega_m"
*MEAS_COND_AXIS_NAME-18 "Length limiting slit"
*MEAS_COND_AXIS_NAME-19 "Center slit"
*MEAS_COND_AXIS_NAME-20 "Filter"
*MEAS_COND_AXIS_NAME-21 "Receiving slit # 1"
*MEAS_COND_AXIS_NAME-22 "Receiving slit # 2"
*MEAS_COND_AXIS_NAME-23 "Receiving optical device"
*MEAS_COND_AXIS_NAME-24 "Receiving parallel slit"
*MEAS_COND_AXIS_NAME-25 "Alignment receiving slit"
*MEAS_COND_AXIS_NAME-26 ""
*MEAS_COND_AXIS_NAME-27 ""
*MEAS_COND_AXIS_NAME-28 "Zd"
*MEAS_COND_AXIS_NAME-29 "Attenuator"
*MEAS_COND_AXIS_NAME-30 "Diffracted beam monochromator"
*MEAS_COND_AXIS_NAME-31 "Monochromator slit"
*MEAS_COND_AXIS_NAME-32 "Primary beam"
*MEAS_COND_AXIS_NAME-33 ""
*MEAS_COND_AXIS_NAME-34 ""
*MEAS_COND_AXIS_NAME-35 "PHA"
*MEAS_COND_AXIS_NAME_INTERNAL-0 "TwoThetaTheta"
*MEAS_COND_AXIS_NAME_INTERNAL-1 "TwoTheta"
*MEAS_COND_AXIS_NAME_INTERNAL-2 "Omega"
*MEAS_COND_AXIS_NAME_INTERNAL-3 "Chi"
*MEAS_COND_AXIS_NAME_INTERNAL-4 "Phi"
*MEAS_COND_AXIS_NAME_INTERNAL-5 "Z"
*MEAS_COND_AXIS_NAME_INTERNAL-6 "TwoThetaOmega"
*MEAS_COND_AXIS_NAME_INTERNAL-7 "ThetaS"
*MEAS_COND_AXIS_NAME_INTERNAL-8 "ThetaD"
*MEAS_COND_AXIS_NAME_INTERNAL-9 "Ts"
*MEAS_COND_AXIS_NAME_INTERNAL-10 "CBO"
*MEAS_COND_AXIS_NAME_INTERNAL-11 "CBO-M"
*MEAS_COND_AXIS_NAME_INTERNAL-12 "IncidentSollerSlit"
*MEAS_COND_AXIS_NAME_INTERNAL-13 "IncidentSlitBox"
*MEAS_COND_AXIS_NAME_INTERNAL-14 "IncidentSlitBox-_Axis"
*MEAS_COND_AXIS_NAME_INTERNAL-15 "Zs"
*MEAS_COND_AXIS_NAME_INTERNAL-16 "IncidentMonochromator"
*MEAS_COND_AXIS_NAME_INTERNAL-17 "IncidentMonochromator-OmegaM"
*MEAS_COND_AXIS_NAME_INTERNAL-18 "IncidentAxdSlit"
*MEAS_COND_AXIS_NAME_INTERNAL-19 "CenterSlit"
*MEAS_COND_AXIS_NAME_INTERNAL-20 "Filter"
*MEAS_COND_AXIS_NAME_INTERNAL-21 "ReceivingSlitBox1"
*MEAS_COND_AXIS_NAME_INTERNAL-22 "ReceivingSlitBox2"
*MEAS_COND_AXIS_NAME_INTERNAL-23 "ReceivingOptics"
*MEAS_COND_AXIS_NAME_INTERNAL-24 "ReceivingSollerSlit"
*MEAS_COND_AXIS_NAME_INTERNAL-25 "ReceivingAxdSlit"
*MEAS_COND_AXIS_NAME_INTERNAL-26 "ReceivingSlitBox1-_Axis"
*MEAS_COND_AXIS_NAME_INTERNAL-27 "ReceivingSlitBox2-_Axis"
*MEAS_COND_AXIS_NAME_INTERNAL-28 "ReceivingSlitBox2-Zd"
*MEAS_COND_AXIS_NAME_INTERNAL-29 "Attenuator"
*MEAS_COND_AXIS_NAME_INTERNAL-30 "CounterMonochromator"
*MEAS_COND_AXIS_NAME_INTERNAL-31 "CounterSlit"
*MEAS_COND_AXIS_NAME_INTERNAL-32 "IncidentPrimary"
*MEAS_COND_AXIS_NAME_INTERNAL-33 "AlphaR"
*MEAS_COND_AXIS_NAME_INTERNAL-34 "BetaR"
*MEAS_COND_AXIS_NAME_INTERNAL-35 "PHA"
*MEAS_COND_AXIS_NAME_MAGICNO-0 "83951616.0000000000"
*MEAS_COND_AXIS_NAME_MAGICNO-1 "268632064.0000000000"
*MEAS_COND_AXIS_NAME_MAGICNO-2 "268500992.0000000000"
*MEAS_COND_AXIS_NAME_MAGICNO-3 "268500992.0000000000"
*MEAS_COND_AXIS_NAME_MAGICNO-4 "268500992.0000000000"
*MEAS_COND_AXIS_NAME_MAGICNO-5 "285278208.0000000000"
*MEAS_COND_AXIS_NAME_MAGICNO-6 "83951616.0000000000"
*MEAS_COND_AXIS_NAME_MAGICNO-7 "131072.0000000000"
*MEAS_COND_AXIS_NAME_MAGICNO-8 "131072.0000000000"
*MEAS_COND_AXIS_NAME_MAGICNO-9 "318898176.0000000000"
*MEAS_COND_AXIS_NAME_MAGICNO-10 "20971521.0000000000"
*MEAS_COND_AXIS_NAME_MAGICNO-11 "285343744.0000000000"
*MEAS_COND_AXIS_NAME_MAGICNO-12 "20971521.0000000000"
*MEAS_COND_AXIS_NAME_MAGICNO-13 "22020097.0000000000"
*MEAS_COND_AXIS_NAME_MAGICNO-14 "25165824.0000000000"
*MEAS_COND_AXIS_NAME_MAGICNO-15 "318898176.0000000000"
*MEAS_COND_AXIS_NAME_MAGICNO-16 "20971521.0000000000"
*MEAS_COND_AXIS_NAME_MAGICNO-17 "285343744.0000000000"
*MEAS_COND_AXIS_NAME_MAGICNO-18 "20971521.0000000000"
*MEAS_COND_AXIS_NAME_MAGICNO-19 "20971521.0000000000"
*MEAS_COND_AXIS_NAME_MAGICNO-20 "20971521.0000000000"
*MEAS_COND_AXIS_NAME_MAGICNO-21 "23068673.0000000000"
*MEAS_COND_AXIS_NAME_MAGICNO-22 "23068673.0000000000"
*MEAS_COND_AXIS_NAME_MAGICNO-23 "20971521.0000000000"
*MEAS_COND_AXIS_NAME_MAGICNO-24 "20971521.0000000000"
*MEAS_COND_AXIS_NAME_MAGICNO-25 "20971521.0000000000"
*MEAS_COND_AXIS_NAME_MAGICNO-26 "25165824.0000000000"
*MEAS_COND_AXIS_NAME_MAGICNO-27 "25165824.0000000000"
*MEAS_COND_AXIS_NAME_MAGICNO-28 "285343744.0000000000"
*MEAS_COND_AXIS_NAME_MAGICNO-29 "17301505.0000000000"
*MEAS_COND_AXIS_NAME_MAGICNO-30 "20971521.0000000000"
*MEAS_COND_AXIS_NAME_MAGICNO-31 "20971521.0000000000"
*MEAS_COND_AXIS_NAME_MAGICNO-32 "20971521.0000000000"
*MEAS_COND_AXIS_NAME_MAGICNO-33 "8388608.0000000000"
*MEAS_COND_AXIS_NAME_MAGICNO-34 "8388608.0000000000"
*MEAS_COND_AXIS_NAME_MAGICNO-35 "0.0000000000"
*MEAS_COND_AXIS_OFFSET-0 "-"
*MEAS_COND_AXIS_OFFSET-1 "0.9117000000"
*MEAS_COND_AXIS_OFFSET-2 "1.1463000000"
*MEAS_COND_AXIS_OFFSET-3 "0.0000000000"
*MEAS_COND_AXIS_OFFSET-4 "0.0000000000"
*MEAS_COND_AXIS_OFFSET-5 "-"
*MEAS_COND_AXIS_OFFSET-6 "-"
*MEAS_COND_AXIS_OFFSET-7 "1.1463000000"
*MEAS_COND_AXIS_OFFSET-8 "-0.2346000000"
*MEAS_COND_AXIS_OFFSET-9 "-"
*MEAS_COND_AXIS_OFFSET-10 "-"
*MEAS_COND_AXIS_OFFSET-11 "-"
*MEAS_COND_AXIS_OFFSET-12 "-"
*MEAS_COND_AXIS_OFFSET-13 "-"
*MEAS_COND_AXIS_OFFSET-14 "-"
*MEAS_COND_AXIS_OFFSET-15 "-"
*MEAS_COND_AXIS_OFFSET-16 "-"
*MEAS_COND_AXIS_OFFSET-17 "-"
*MEAS_COND_AXIS_OFFSET-18 "-"
*MEAS_COND_AXIS_OFFSET-19 "-"
*MEAS_COND_AXIS_OFFSET-20 "-"
*MEAS_COND_AXIS_OFFSET-21 "-"
*MEAS_COND_AXIS_OFFSET-22 "-"
*MEAS_COND_AXIS_OFFSET-23 "-"
*MEAS_COND_AXIS_OFFSET-24 "-"
*MEAS_COND_AXIS_OFFSET-25 "-"
*MEAS_COND_AXIS_OFFSET-26 "-"
*MEAS_COND_AXIS_OFFSET-27 "-"
*MEAS_COND_AXIS_OFFSET-28 "-"
*MEAS_COND_AXIS_OFFSET-29 "-"
*MEAS_COND_AXIS_OFFSET-30 "-"
*MEAS_COND_AXIS_OFFSET-31 "-"
*MEAS_COND_AXIS_OFFSET-32 "-"
*MEAS_COND_AXIS_OFFSET-33 "0.0000000000"
*MEAS_COND_AXIS_OFFSET-34 "0.0000000000"
*MEAS_COND_AXIS_OFFSET-35 "-"
*MEAS_COND_AXIS_POSITION-0 "-0.0008000000"
*MEAS_COND_AXIS_POSITION-1 "-0.0008000000"
*MEAS_COND_AXIS_POSITION-2 "-0.0004000000"
*MEAS_COND_AXIS_POSITION-3 "0.0000000000"
*MEAS_COND_AXIS_POSITION-4 "0.0000000000"
*MEAS_COND_AXIS_POSITION-5 "-1.4289000000"
*MEAS_COND_AXIS_POSITION-6 "-0.0008000000"
*MEAS_COND_AXIS_POSITION-7 "-0.0004000000"
*MEAS_COND_AXIS_POSITION-8 "-0.0004000000"
*MEAS_COND_AXIS_POSITION-9 "-4.8858800000"
*MEAS_COND_AXIS_POSITION-10 "PB"
*MEAS_COND_AXIS_POSITION-11 "0.0000000000"
*MEAS_COND_AXIS_POSITION-12 "Soller_slit_open_s"
*MEAS_COND_AXIS_POSITION-13 "0.250mm"
*MEAS_COND_AXIS_POSITION-14 "0.2500000000"
*MEAS_COND_AXIS_POSITION-15 "-1.8040600000"
*MEAS_COND_AXIS_POSITION-16 "Ge(220)x2"
*MEAS_COND_AXIS_POSITION-17 "0.0000000000"
*MEAS_COND_AXIS_POSITION-18 "2.0mm"
*MEAS_COND_AXIS_POSITION-19 "None"
*MEAS_COND_AXIS_POSITION-20 "None"
*MEAS_COND_AXIS_POSITION-21 "0.250mm"
*MEAS_COND_AXIS_POSITION-22 "0.250mm"
*MEAS_COND_AXIS_POSITION-23 "No_unit"
*MEAS_COND_AXIS_POSITION-24 "Soller_slit_5.0deg"
*MEAS_COND_AXIS_POSITION-25 "None"
*MEAS_COND_AXIS_POSITION-26 "0.2500000000"
*MEAS_COND_AXIS_POSITION-27 "0.2500000000"
*MEAS_COND_AXIS_POSITION-28 "0.0928100000"
*MEAS_COND_AXIS_POSITION-29 "1/10000"
*MEAS_COND_AXIS_POSITION-30 "None"
*MEAS_COND_AXIS_POSITION-31 "None"
*MEAS_COND_AXIS_POSITION-32 "None"
*MEAS_COND_AXIS_POSITION-33 "0.0000000000"
*MEAS_COND_AXIS_POSITION-34 "0.0000000000"
*MEAS_COND_AXIS_POSITION-35 "34.0000000000"
*MEAS_COND_AXIS_UNIT-0 "deg"
*MEAS_COND_AXIS_UNIT-1 "deg"
*MEAS_COND_AXIS_UNIT-2 "deg"
*MEAS_COND_AXIS_UNIT-3 "deg"
*MEAS_COND_AXIS_UNIT-4 "deg"
*MEAS_COND_AXIS_UNIT-5 "mm"
*MEAS_COND_AXIS_UNIT-6 "deg"
*MEAS_COND_AXIS_UNIT-7 "deg"
*MEAS_COND_AXIS_UNIT-8 "deg"
*MEAS_COND_AXIS_UNIT-9 "mm"
*MEAS_COND_AXIS_UNIT-10 ""
*MEAS_COND_AXIS_UNIT-11 "pulse"
*MEAS_COND_AXIS_UNIT-12 ""
*MEAS_COND_AXIS_UNIT-13 ""
*MEAS_COND_AXIS_UNIT-14 "mm"
*MEAS_COND_AXIS_UNIT-15 "mm"
*MEAS_COND_AXIS_UNIT-16 ""
*MEAS_COND_AXIS_UNIT-17 "pulse"
*MEAS_COND_AXIS_UNIT-18 ""
*MEAS_COND_AXIS_UNIT-19 ""
*MEAS_COND_AXIS_UNIT-20 ""
*MEAS_COND_AXIS_UNIT-21 ""
*MEAS_COND_AXIS_UNIT-22 ""
*MEAS_COND_AXIS_UNIT-23 ""
*MEAS_COND_AXIS_UNIT-24 ""
*MEAS_COND_AXIS_UNIT-25 ""
*MEAS_COND_AXIS_UNIT-26 "mm"
*MEAS_COND_AXIS_UNIT-27 "mm"
*MEAS_COND_AXIS_UNIT-28 "mm"
*MEAS_COND_AXIS_UNIT-29 ""
*MEAS_COND_AXIS_UNIT-30 ""
*MEAS_COND_AXIS_UNIT-31 ""
*MEAS_COND_AXIS_UNIT-32 ""
*MEAS_COND_AXIS_UNIT-33 "deg"
*MEAS_COND_AXIS_UNIT-34 "deg"
*MEAS_COND_AXIS_UNIT-35 "div"
*MEAS_COND_COUNTER_CNTLOSS_CORR "0.0000000000"
*MEAS_COND_COUNTER_PHABASE "34.0000000000"
*MEAS_COND_COUNTER_PHAWINDOW "19.0000000000"
*MEAS_COND_COUNTER_PHA_UNIT "div"
*MEAS_COND_COUNTER_TAUDIFF "2.0000000000"
*MEAS_COND_COUNTER_TAUINT "0.1000000000"
*MEAS_COND_IRRADIATION_MODE "OFF"
*MEAS_COND_IRRADIATION_WIDTH ""
*MEAS_COND_OPT_ATTR "High resolution parallel beam Ge(220)x2/RS"
*MEAS_COND_OPT_NAME "@High resolution PB-Ge(220)x2"
*MEAS_COND_UNSYMMETRIC_MODE "OFF"
*MEAS_COND_XG_CURRENT "200.0000000000"
*MEAS_COND_XG_VOLTAGE "45.0000000000"
*MEAS_COND_XG_WAVE_TYPE "Ka1"
*MEAS_DATA_COUNT "3001.0000000000"
*MEAS_SCAN_AXIS_X "2-Theta/Omega"
*MEAS_SCAN_AXIS_X_INTERNAL "TwoThetaOmega"
*MEAS_SCAN_END_TIME "11/07/23 10:31:35"
*MEAS_SCAN_MODE "CONTINUOUS"
*MEAS_SCAN_MONITOR "0"
*MEAS_SCAN_RESOLUTION_X "0.0002"
*MEAS_SCAN_SPEED "0.500000"
*MEAS_SCAN_SPEED_UNIT "deg/min"
*MEAS_SCAN_SPEED_USER "0.500000"
*MEAS_SCAN_START "0.0000000000"
*MEAS_SCAN_START_TIME "11/07/23 10:19:03"
*MEAS_SCAN_STEP "0.0020000000"
*MEAS_SCAN_STOP "6.0000000000"
*MEAS_SCAN_UNIT_X "deg"
*MEAS_SCAN_UNIT_Y "counts"
*RAS_HEADER_END
*RAS_INT_START
0.0000 5140122.0000 1.0000
0.0060 5261904.5000 1.0000
0.0120 5238320.5000 1.0000
0.0180 5178601.5000 1.0000
0.0240 5153500.0000 1.0000
0.0300 4896004.0000 1.0000
0.0360 4507761.0000 1.0000
0.0420 3719275.2500 1.0000
0.0480 2840728.0000 1.0000
0.0540 1974731.3750 1.0000
0.0600 1163407.3750 1.0000
0.0660 630322.6250 1.0000
0.0720 304224.3438 1.0000
0.0780 175699.0781 1.0000
0.0840 109265.4531 1.0000
0.0900 84732.6719 1.0000
0.0960 75639.0078 1.0000
0.1020 77210.4766 1.0000
0.1080 76666.7969 1.0000
0.1140 77992.4922 1.0000
0.1200 80159.7734 1.0000
0.1260 85410.4141 1.0000
0.1320 87860.7109 1.0000
0.1380 88478.8750 1.0000
0.1440 96917.1328 1.0000
0.1500 97110.7813 1.0000
0.1560 102205.0156 1.0000
0.1620 104811.7188 1.0000
0.1680 113056.3359 1.0000
0.1740 114799.1016 1.0000
0.1800 118172.9141 1.0000
0.1860 121256.2734 1.0000
0.1920 125047.1641 1.0000
0.1980 127601.7344 1.0000
0.2040 133127.9375 1.0000
0.2100 135079.2344 1.0000
0.2160 138259.4219 1.0000
0.2220 141044.8594 1.0000
0.2280 143517.5000 1.0000
0.2340 148663.8750 1.0000
0.2400 153348.4844 1.0000
0.2460 155716.8594 1.0000
0.2520 157861.7969 1.0000
0.2580 159999.2969 1.0000
0.2640 168370.5313 1.0000
0.2700 166553.2813 1.0000
0.2760 169733.4688 1.0000
0.2820 180473.0781 1.0000
0.2880 176153.3906 1.0000
0.2940 177925.9531 1.0000
0.3000 189693.3438 1.0000
0.3060 189983.7969 1.0000
0.3120 195874.9531 1.0000
0.3180 199576.4688 1.0000
0.3240 199226.4219 1.0000
0.3300 203903.5938 1.0000
0.3360 206562.4219 1.0000
0.3420 211336.4063 1.0000
0.3480 217294.5781 1.0000
0.3540 216162.5313 1.0000
0.3600 216162.5313 1.0000
0.3660 228518.2969 1.0000
0.3720 229203.4688 1.0000
0.3780 229925.9063 1.0000
0.3840 229717.3750 1.0000
0.3900 234841.4063 1.0000
0.3960 240628.2813 1.0000
0.4020 248880.3438 1.0000
0.4080 247018.4063 1.0000
0.4140 249021.8594 1.0000
0.4200 250213.4844 1.0000
0.4260 257445.2188 1.0000
0.4320 265622.8125 1.0000
0.4380 265712.1875 1.0000
0.4440 257035.5938 1.0000
0.4500 263693.8438 1.0000
0.4560 269413.6875 1.0000
0.4620 274723.9063 1.0000
0.4680 272802.4063 1.0000
0.4740 277516.8125 1.0000
0.4800 278552.0625 1.0000
0.4860 285672.0625 1.0000
0.4920 288293.6563 1.0000
0.4980 291697.2813 1.0000
0.5040 291555.7500 1.0000
0.5100 288651.1563 1.0000
0.5160 289261.8750 1.0000
0.5220 297126.6563 1.0000
0.5280 297193.6875 1.0000
0.5340 299815.2813 1.0000
0.5400 294497.6250 1.0000
0.5460 295234.9375 1.0000
0.5520 305058.4688 1.0000
0.5580 300083.4063 1.0000
0.5640 303077.3750 1.0000
0.5700 299927.0000 1.0000
0.5760 305587.2500 1.0000
0.5820 301505.9063 1.0000
0.5880 300977.1250 1.0000
0.5940 304626.5000 1.0000
0.6000 297454.3438 1.0000
0.6060 293000.6250 1.0000
0.6120 285232.6563 1.0000
0.6180 286037.0000 1.0000
0.6240 271149.0313 1.0000
0.6300 271268.1875 1.0000
0.6360 260982.8906 1.0000
0.6420 248306.8750 1.0000
0.6480 239585.5938 1.0000
0.6540 220407.7344 1.0000
0.6600 207634.8906 1.0000
0.6660 189641.2031 1.0000
0.6720 172183.7656 1.0000
0.6780 160029.0781 1.0000
0.6840 147866.9688 1.0000
0.6900 129910.5234 1.0000
0.6960 121628.6563 1.0000
0.7020 112818.0156 1.0000
0.7080 98280.0703 1.0000
0.7140 94437.0469 1.0000
0.7200 89089.5859 1.0000
0.7260 76569.9766 1.0000
0.7320 72585.4453 1.0000
0.7380 68734.9766 1.0000
0.7440 63692.8711 1.0000
0.7500 61704.3320 1.0000
0.7560 57570.0000 1.0000
0.7620 54042.0000 1.0000
0.7680 50601.3320 1.0000
0.7740 47809.5000 1.0000
0.7800 45743.5000 1.0000
0.7860 42824.1680 1.0000
0.7920 40637.3320 1.0000
0.7980 38837.0000 1.0000
0.8040 36526.8320 1.0000
0.8100 35157.3320 1.0000
0.8160 33535.3320 1.0000
0.8220 31867.1660 1.0000
0.8280 30704.3340 1.0000
0.8340 29090.8340 1.0000
0.8400 27559.5000 1.0000
0.8460 27178.5000 1.0000
0.8520 25672.0000 1.0000
0.8580 24514.8340 1.0000
0.8640 23641.5000 1.0000
0.8700 22835.5000 1.0000
0.8760 22043.5000 1.0000
0.8820 21089.3340 1.0000
0.8880 20308.5000 1.0000
0.8940 19720.0000 1.0000
0.9000 18974.3340 1.0000
0.9060 18232.5000 1.0000
0.9120 17646.8340 1.0000
0.9180 17012.1660 1.0000
0.9240 16404.1660 1.0000
0.9300 15829.8330 1.0000
0.9360 15395.6670 1.0000
0.9420 14949.1670 1.0000
0.9480 14440.0000 1.0000
0.9540 14117.5000 1.0000
0.9600 13623.5000 1.0000
0.9660 13246.6670 1.0000
0.9720 12683.6670 1.0000
0.9780 12408.8330 1.0000
0.9840 11921.3330 1.0000
0.9900 11696.5000 1.0000
0.9960 11127.8330 1.0000
1.0020 10948.0000 1.0000
1.0080 10642.1670 1.0000
1.0140 10257.1670 1.0000
1.0200 9981.1670 1.0000
1.0260 9669.0000 1.0000
1.0320 9382.6670 1.0000
1.0380 9100.8330 1.0000
1.0440 9059.5000 1.0000
1.0500 8721.8330 1.0000
1.0560 8541.1670 1.0000
1.0620 8272.0000 1.0000
1.0680 8136.5000 1.0000
1.0740 7898.1665 1.0000
1.0800 7660.0000 1.0000
1.0860 7358.3335 1.0000
1.0920 7271.8335 1.0000
1.0980 7151.1665 1.0000
1.1040 6879.5000 1.0000
1.1100 6793.3335 1.0000
1.1160 6611.3335 1.0000
1.1220 6460.6665 1.0000
1.1280 6199.0000 1.0000
1.1340 6096.5000 1.0000
1.1400 5927.6665 1.0000
1.1460 5799.5000 1.0000
1.1520 5640.3335 1.0000
1.1580 5638.3335 1.0000
1.1640 5460.0000 1.0000
1.1700 5200.3335 1.0000
1.1760 5230.3335 1.0000
1.1820 4983.3335 1.0000
1.1880 4929.1665 1.0000
1.1940 4834.8335 1.0000
1.2000 4801.6665 1.0000
1.2060 4644.6665 1.0000
1.2120 4464.3335 1.0000
1.2180 4291.5000 1.0000
1.2240 4261.6665 1.0000
1.2300 4354.8335 1.0000
1.2360 4098.1665 1.0000
1.2420 4068.0000 1.0000
1.2480 3956.6667 1.0000
1.2540 3932.5000 1.0000
1.2600 3902.1667 1.0000
1.2660 3727.8333 1.0000
1.2720 3682.8333 1.0000
1.2780 3624.6667 1.0000
1.2840 3530.1667 1.0000
1.2900 3514.0000 1.0000
1.2960 3373.0000 1.0000
1.3020 3309.8333 1.0000
1.3080 3368.0000 1.0000
1.3140 3200.1667 1.0000
1.3200 3090.1667 1.0000
1.3260 3074.3333 1.0000
1.3320 2942.1667 1.0000
1.3380 2936.8333 1.0000
1.3440 2808.5000 1.0000
1.3500 2819.8333 1.0000
1.3560 2745.8333 1.0000
1.3620 2697.8333 1.0000
1.3680 2690.1667 1.0000
1.3740 2639.0000 1.0000
1.3800 2585.8333 1.0000
1.3860 2570.1667 1.0000
1.3920 2523.0000 1.0000
1.3980 2453.1667 1.0000
1.4040 2430.1667 1.0000
1.4100 2463.1667 1.0000
1.4160 2263.1667 1.0000
1.4220 2282.0000 1.0000
1.4280 2223.8333 1.0000
1.4340 2192.6667 1.0000
1.4400 2115.1667 1.0000
1.4460 2033.3334 1.0000
1.4520 2086.5000 1.0000
1.4580 2036.3334 1.0000
1.4640 2026.8334 1.0000
1.4700 1972.3334 1.0000
1.4760 1911.1666 1.0000
1.4820 1895.3334 1.0000
1.4880 1868.1666 1.0000
1.4940 1849.5000 1.0000
1.5000 1742.3334 1.0000
1.5060 1699.0000 1.0000
1.5120 1779.5000 1.0000
1.5180 1726.0000 1.0000
1.5240 1671.0000 1.0000
1.5300 1642.3334 1.0000
1.5360 1597.3334 1.0000
1.5420 1659.1666 1.0000
1.5480 1542.1666 1.0000
1.5540 1482.8334 1.0000
1.5600 1616.5000 1.0000
1.5660 1558.1666 1.0000
1.5720 1544.5000 1.0000
1.5780 1470.3334 1.0000
1.5840 1372.1666 1.0000
1.5900 1355.1666 1.0000
1.5960 1384.5000 1.0000
1.6020 1356.3334 1.0000
1.6080 1367.5000 1.0000
1.6140 1302.1666 1.0000
1.6200 1279.3334 1.0000
1.6260 1279.6666 1.0000
1.6320 1272.6666 1.0000
1.6380 1183.0000 1.0000
1.6440 1233.3334 1.0000
1.6500 1253.8334 1.0000
1.6560 1195.3334 1.0000
1.6620 1203.6666 1.0000
1.6680 1151.6666 1.0000
1.6740 1125.1666 1.0000
1.6800 1103.6666 1.0000
1.6860 1161.3334 1.0000
1.6920 1107.8334 1.0000
1.6980 1103.1666 1.0000
1.7040 1047.6666 1.0000
1.7100 1061.6666 1.0000
1.7160 1005.8333 1.0000
1.7220 983.6667 1.0000
1.7280 952.8333 1.0000
1.7340 976.1667 1.0000
1.7400 978.8333 1.0000
1.7460 881.1667 1.0000
1.7520 911.5000 1.0000
1.7580 899.8333 1.0000
1.7640 931.3333 1.0000
1.7700 902.5000 1.0000
1.7760 907.8333 1.0000
1.7820 906.6667 1.0000
1.7880 797.1667 1.0000
1.7940 800.8333 1.0000
1.8000 829.5000 1.0000
1.8060 816.0000 1.0000
1.8120 794.1667 1.0000
1.8180 841.0000 1.0000
1.8240 754.3333 1.0000
1.8300 761.0000 1.0000
1.8360 757.6667 1.0000
1.8420 743.0000 1.0000
1.8480 752.3333 1.0000
1.8540 741.6667 1.0000
1.8600 676.3333 1.0000
1.8660 688.3333 1.0000
1.8720 727.8333 1.0000
1.8780 679.6667 1.0000
1.8840 667.8333 1.0000
1.8900 650.1667 1.0000
1.8960 628.5000 1.0000
1.9020 677.6667 1.0000
1.9080 653.8333 1.0000
1.9140 634.0000 1.0000
1.9200 646.3333 1.0000
1.9260 601.3333 1.0000
1.9320 615.5000 1.0000
1.9380 624.0000 1.0000
1.9440 583.6667 1.0000
1.9500 576.6667 1.0000
1.9560 566.5000 1.0000
1.9620 576.1667 1.0000
1.9680 577.0000 1.0000
1.9740 565.8333 1.0000
1.9800 529.6667 1.0000
1.9860 542.3333 1.0000
1.9920 514.5000 1.0000
1.9980 524.3333 1.0000
2.0040 537.1667 1.0000
2.0100 517.5000 1.0000
2.0160 505.8333 1.0000
2.0220 511.3333 1.0000
2.0280 488.0000 1.0000
2.0340 460.5000 1.0000
2.0400 469.1667 1.0000
2.0460 481.0000 1.0000
2.0520 528.1667 1.0000
2.0580 446.0000 1.0000
2.0640 429.5000 1.0000
2.0700 460.6667 1.0000
2.0760 453.3333 1.0000
2.0820 431.8333 1.0000
2.0880 422.6667 1.0000
2.0940 461.1667 1.0000
2.1000 392.1667 1.0000
2.1060 422.6667 1.0000
2.1120 420.6667 1.0000
2.1180 405.8333 1.0000
2.1240 397.0000 1.0000
2.1300 396.8333 1.0000
2.1360 388.1667 1.0000
2.1420 402.8333 1.0000
2.1480 409.6667 1.0000
2.1540 407.1667 1.0000
2.1600 349.6667 1.0000
2.1660 381.3333 1.0000
2.1720 365.0000 1.0000
2.1780 357.6667 1.0000
2.1840 373.8333 1.0000
2.1900 363.1667 1.0000
2.1960 373.1667 1.0000
2.2020 358.0000 1.0000
2.2080 332.8333 1.0000
2.2140 363.3333 1.0000
2.2200 343.8333 1.0000
2.2260 309.1667 1.0000
2.2320 367.1667 1.0000
2.2380 322.5000 1.0000
2.2440 298.8333 1.0000
2.2500 318.5000 1.0000
2.2560 297.1667 1.0000
2.2620 337.5000 1.0000
2.2680 304.0000 1.0000
2.2740 322.1667 1.0000
2.2800 278.3333 1.0000
2.2860 295.3333 1.0000
2.2920 300.0000 1.0000
2.2980 284.3333 1.0000
2.3040 278.8333 1.0000
2.3100 285.5000 1.0000
2.3160 273.5000 1.0000
2.3220 268.8333 1.0000
2.3280 258.1667 1.0000
2.3340 251.3333 1.0000
2.3400 288.3333 1.0000
2.3460 267.5000 1.0000
2.3520 251.8333 1.0000
2.3580 260.0000 1.0000
2.3640 277.1667 1.0000
2.3700 273.0000 1.0000
2.3760 257.1667 1.0000
2.3820 250.8333 1.0000
2.3880 245.5000 1.0000
2.3940 212.3333 1.0000
2.4000 230.8333 1.0000
2.4060 232.0000 1.0000
2.4120 214.3333 1.0000
2.4180 259.6667 1.0000
2.4240 212.1667 1.0000
2.4300 211.1667 1.0000
2.4360 237.1667 1.0000
2.4420 200.0000 1.0000
2.4480 210.5000 1.0000
2.4540 231.6667 1.0000
2.4600 207.0000 1.0000
2.4660 207.1667 1.0000
2.4720 235.1667 1.0000
2.4780 217.5000 1.0000
2.4840 201.1667 1.0000
2.4900 183.6667 1.0000
2.4960 201.0000 1.0000
2.5020 206.3333 1.0000
2.5080 194.5000 1.0000
2.5140 183.3333 1.0000
2.5200 184.3333 1.0000
2.5260 185.6667 1.0000
2.5320 203.1667 1.0000
2.5380 182.0000 1.0000
2.5440 188.1667 1.0000
2.5500 210.8333 1.0000
2.5560 171.3333 1.0000
2.5620 182.8333 1.0000
2.5680 173.8333 1.0000
2.5740 173.6667 1.0000
2.5800 178.0000 1.0000
2.5860 198.5000 1.0000
2.5920 152.5000 1.0000
2.5980 163.6667 1.0000
2.6040 158.1667 1.0000
2.6100 142.6667 1.0000
2.6160 178.1667 1.0000
2.6220 164.8333 1.0000
2.6280 159.3333 1.0000
2.6340 189.0000 1.0000
2.6400 167.1667 1.0000
2.6460 149.6667 1.0000
2.6520 156.0000 1.0000
2.6580 142.3333 1.0000
2.6640 146.5000 1.0000
2.6700 155.8333 1.0000
2.6760 152.6667 1.0000
2.6820 138.6667 1.0000
2.6880 151.5000 1.0000
2.6940 123.3333 1.0000
2.7000 135.3333 1.0000
2.7060 144.5000 1.0000
2.7120 127.6667 1.0000
2.7180 133.3333 1.0000
2.7240 138.1667 1.0000
2.7300 153.6667 1.0000
2.7360 134.8333 1.0000
2.7420 144.6667 1.0000
2.7480 129.5000 1.0000
2.7540 140.1667 1.0000
2.7600 130.5000 1.0000
2.7660 125.5000 1.0000
2.7720 133.3333 1.0000
2.7780 126.1667 1.0000
2.7840 116.5000 1.0000
2.7900 129.0000 1.0000
2.7960 119.1667 1.0000
2.8020 128.1667 1.0000
2.8080 130.5000 1.0000
2.8140 134.6667 1.0000
2.8200 113.8333 1.0000
2.8260 133.5000 1.0000
2.8320 124.0000 1.0000
2.8380 109.0000 1.0000
2.8440 107.8333 1.0000
2.8500 158.3333 1.0000
2.8560 112.5000 1.0000
2.8620 119.0000 1.0000
2.8680 108.1667 1.0000
2.8740 121.8333 1.0000
2.8800 118.0000 1.0000
2.8860 110.3333 1.0000
2.8920 110.5000 1.0000
2.8980 109.8333 1.0000
2.9040 98.3333 1.0000
2.9100 116.3333 1.0000
2.9160 83.8333 1.0000
2.9220 111.1667 1.0000
2.9280 105.8333 1.0000
2.9340 95.5000 1.0000
2.9400 102.5000 1.0000
2.9460 100.6667 1.0000
2.9520 89.0000 1.0000
2.9580 87.6667 1.0000
2.9640 103.0000 1.0000
2.9700 92.5000 1.0000
2.9760 103.3333 1.0000
2.9820 83.3333 1.0000
2.9880 104.5000 1.0000
2.9940 86.6667 1.0000
3.0000 91.3333 1.0000
3.0060 89.3333 1.0000
3.0120 105.3333 1.0000
3.0180 87.1667 1.0000
3.0240 78.6667 1.0000
3.0300 80.0000 1.0000
3.0360 95.6667 1.0000
3.0420 79.1667 1.0000
3.0480 89.8333 1.0000
3.0540 84.0000 1.0000
3.0600 90.8333 1.0000
3.0660 72.5000 1.0000
3.0720 71.0000 1.0000
3.0780 82.8333 1.0000
3.0840 83.3333 1.0000
3.0900 85.6667 1.0000
3.0960 86.0000 1.0000
3.1020 81.0000 1.0000
3.1080 63.8333 1.0000
3.1140 98.0000 1.0000
3.1200 67.5000 1.0000
3.1260 76.1667 1.0000
3.1320 84.6667 1.0000
3.1380 69.0000 1.0000
3.1440 85.1667 1.0000
3.1500 87.0000 1.0000
3.1560 85.6667 1.0000
3.1620 64.6667 1.0000
3.1680 72.8333 1.0000
3.1740 86.8333 1.0000
3.1800 77.1667 1.0000
3.1860 77.8333 1.0000
3.1920 68.3333 1.0000
3.1980 76.0000 1.0000
3.2040 67.1667 1.0000
3.2100 54.5000 1.0000
3.2160 91.0000 1.0000
3.2220 56.8333 1.0000
3.2280 58.8333 1.0000
3.2340 62.8333 1.0000
3.2400 70.6667 1.0000
3.2460 71.0000 1.0000
3.2520 68.5000 1.0000
3.2580 55.1667 1.0000
3.2640 58.8333 1.0000
3.2700 62.0000 1.0000
3.2760 53.3333 1.0000
3.2820 54.8333 1.0000
3.2880 71.6667 1.0000
3.2940 77.0000 1.0000
3.3000 63.3333 1.0000
3.3060 61.6667 1.0000
3.3120 44.1667 1.0000
3.3180 64.5000 1.0000
3.3240 59.5000 1.0000
3.3300 71.0000 1.0000
3.3360 61.5000 1.0000
3.3420 51.5000 1.0000
3.3480 47.3333 1.0000
3.3540 56.5000 1.0000
3.3600 51.3333 1.0000
3.3660 53.1667 1.0000
3.3720 53.1667 1.0000
3.3780 43.5000 1.0000
3.3840 58.5000 1.0000
3.3900 44.0000 1.0000
3.3960 57.1667 1.0000
3.4020 48.3333 1.0000
3.4080 47.8333 1.0000
3.4140 41.8333 1.0000
3.4200 49.8333 1.0000
3.4260 46.6667 1.0000
3.4320 47.5000 1.0000
3.4380 53.6667 1.0000
3.4440 51.0000 1.0000
3.4500 48.8333 1.0000
3.4560 48.0000 1.0000
3.4620 61.1667 1.0000
3.4680 63.3333 1.0000
3.4740 47.0000 1.0000
3.4800 50.8333 1.0000
3.4860 52.8333 1.0000
3.4920 55.8333 1.0000
3.4980 56.5000 1.0000
3.5040 40.1667 1.0000
3.5100 42.1667 1.0000
3.5160 45.8333 1.0000
3.5220 51.8333 1.0000
3.5280 43.1667 1.0000
3.5340 55.0000 1.0000
3.5400 46.6667 1.0000
3.5460 50.0000 1.0000
3.5520 40.6667 1.0000
3.5580 36.0000 1.0000
3.5640 45.0000 1.0000
3.5700 43.0000 1.0000
3.5760 47.8333 1.0000
3.5820 40.5000 1.0000
3.5880 40.3333 1.0000
3.5940 40.3333 1.0000
3.6000 32.0000 1.0000
3.6060 37.5000 1.0000
3.6120 35.1667 1.0000
3.6180 37.3333 1.0000
3.6240 38.8333 1.0000
3.6300 51.3333 1.0000
3.6360 41.3333 1.0000
3.6420 40.6667 1.0000
3.6480 38.6667 1.0000
3.6540 48.8333 1.0000
3.6600 33.0000 1.0000
3.6660 47.5000 1.0000
3.6720 41.6667 1.0000
3.6780 34.3333 1.0000
3.6840 33.0000 1.0000
3.6900 36.3333 1.0000
3.6960 41.0000 1.0000
3.7020 49.1667 1.0000
3.7080 34.3333 1.0000
3.7140 46.1667 1.0000
3.7200 35.3333 1.0000
3.7260 31.3333 1.0000
3.7320 31.0000 1.0000
3.7380 32.6667 1.0000
3.7440 37.0000 1.0000
3.7500 50.0000 1.0000
3.7560 35.1667 1.0000
3.7620 42.5000 1.0000
3.7680 38.3333 1.0000
3.7740 33.5000 1.0000
3.7800 29.1667 1.0000
3.7860 28.6667 1.0000
3.7920 29.1667 1.0000
3.7980 30.8333 1.0000
3.8040 35.0000 1.0000
3.8100 40.5000 1.0000
3.8160 39.0000 1.0000
3.8220 33.0000 1.0000
3.8280 24.6667 1.0000
3.8340 29.1667 1.0000
3.8400 34.0000 1.0000
3.8460 34.8333 1.0000
3.8520 27.5000 1.0000
3.8580 34.6667 1.0000
3.8640 32.0000 1.0000
3.8700 27.3333 1.0000
3.8760 36.0000 1.0000
3.8820 34.0000 1.0000
3.8880 29.1667 1.0000
3.8940 49.3333 1.0000
3.9000 30.3333 1.0000
3.9060 35.5000 1.0000
3.9120 36.6667 1.0000
3.9180 24.0000 1.0000
3.9240 32.1667 1.0000
3.9300 22.8333 1.0000
3.9360 32.5000 1.0000
3.9420 31.5000 1.0000
3.9480 30.0000 1.0000
3.9540 32.0000 1.0000
3.9600 26.3333 1.0000
3.9660 31.5000 1.0000
3.9720 23.5000 1.0000
3.9780 22.0000 1.0000
3.9840 31.5000 1.0000
3.9900 35.6667 1.0000
3.9960 35.5000 1.0000
4.0020 29.0000 1.0000
4.0080 27.6667 1.0000
4.0140 25.0000 1.0000
4.0200 21.6667 1.0000
4.0260 31.5000 1.0000
4.0320 30.8333 1.0000
4.0380 21.8333 1.0000
4.0440 33.1667 1.0000
4.0500 26.8333 1.0000
4.0560 26.6667 1.0000
4.0620 33.3333 1.0000
4.0680 18.3333 1.0000
4.0740 26.1667 1.0000
4.0800 26.1667 1.0000
4.0860 17.3333 1.0000
4.0920 33.6667 1.0000
4.0980 31.0000 1.0000
4.1040 22.3333 1.0000
4.1100 27.8333 1.0000
4.1160 18.3333 1.0000
4.1220 28.0000 1.0000
4.1280 27.5000 1.0000
4.1340 24.8333 1.0000
4.1400 31.0000 1.0000
4.1460 21.0000 1.0000
4.1520 21.5000 1.0000
4.1580 18.5000 1.0000
4.1640 22.5000 1.0000
4.1700 24.5000 1.0000
4.1760 24.0000 1.0000
4.1820 27.1667 1.0000
4.1880 21.6667 1.0000
4.1940 28.0000 1.0000
4.2000 24.0000 1.0000
4.2060 18.5000 1.0000
4.2120 20.3333 1.0000
4.2180 21.3333 1.0000
4.2240 23.0000 1.0000
4.2300 25.0000 1.0000
4.2360 27.1667 1.0000
4.2420 36.0000 1.0000
4.2480 16.6667 1.0000
4.2540 19.6667 1.0000
4.2600 20.3333 1.0000
4.2660 16.1667 1.0000
4.2720 15.8333 1.0000
4.2780 15.5000 1.0000
4.2840 23.3333 1.0000
4.2900 18.1667 1.0000
4.2960 22.6667 1.0000
4.3020 22.3333 1.0000
4.3080 18.0000 1.0000
4.3140 21.3333 1.0000
4.3200 17.5000 1.0000
4.3260 23.5000 1.0000
4.3320 21.3333 1.0000
4.3380 19.0000 1.0000
4.3440 24.3333 1.0000
4.3500 23.3333 1.0000
4.3560 20.6667 1.0000
4.3620 29.6667 1.0000
4.3680 25.6667 1.0000
4.3740 19.1667 1.0000
4.3800 14.6667 1.0000
4.3860 26.0000 1.0000
4.3920 19.1667 1.0000
4.3980 19.1667 1.0000
4.4040 19.5000 1.0000
4.4100 22.1667 1.0000
4.4160 19.5000 1.0000
4.4220 14.0000 1.0000
4.4280 28.8333 1.0000
4.4340 15.3333 1.0000
4.4400 23.3333 1.0000
4.4460 21.3333 1.0000
4.4520 14.8333 1.0000
4.4580 20.6667 1.0000
4.4640 26.1667 1.0000
4.4700 9.6667 1.0000
4.4760 23.0000 1.0000
4.4820 15.0000 1.0000
4.4880 16.3333 1.0000
4.4940 13.0000 1.0000
4.5000 11.5000 1.0000
4.5060 20.5000 1.0000
4.5120 19.0000 1.0000
4.5180 21.8333 1.0000
4.5240 17.5000 1.0000
4.5300 17.3333 1.0000
4.5360 12.8333 1.0000
4.5420 11.1667 1.0000
4.5480 20.0000 1.0000
4.5540 13.1667 1.0000
4.5600 11.5000 1.0000
4.5660 14.6667 1.0000
4.5720 10.6667 1.0000
4.5780 23.1667 1.0000
4.5840 10.5000 1.0000
4.5900 20.0000 1.0000
4.5960 19.6667 1.0000
4.6020 22.0000 1.0000
4.6080 14.1667 1.0000
4.6140 13.3333 1.0000
4.6200 15.6667 1.0000
4.6260 13.3333 1.0000
4.6320 10.8333 1.0000
4.6380 15.0000 1.0000
4.6440 17.6667 1.0000
4.6500 10.0000 1.0000
4.6560 6.5000 1.0000
4.6620 12.1667 1.0000
4.6680 14.8333 1.0000
4.6740 19.5000 1.0000
4.6800 11.8333 1.0000
4.6860 10.0000 1.0000
4.6920 16.0000 1.0000
4.6980 15.1667 1.0000
4.7040 17.3333 1.0000
4.7100 11.1667 1.0000
4.7160 7.0000 1.0000
4.7220 17.8333 1.0000
4.7280 9.8333 1.0000
4.7340 14.0000 1.0000
4.7400 15.6667 1.0000
4.7460 16.5000 1.0000
4.7520 13.1667 1.0000
4.7580 21.0000 1.0000
4.7640 13.0000 1.0000
4.7700 16.1667 1.0000
4.7760 9.5000 1.0000
4.7820 13.5000 1.0000
4.7880 19.0000 1.0000
4.7940 7.5000 1.0000
4.8000 11.5000 1.0000
4.8060 18.0000 1.0000
4.8120 9.1667 1.0000
4.8180 18.0000 1.0000
4.8240 13.6667 1.0000
4.8300 15.8333 1.0000
4.8360 11.6667 1.0000
4.8420 17.8333 1.0000
4.8480 19.3333 1.0000
4.8540 18.1667 1.0000
4.8600 17.1667 1.0000
4.8660 13.8333 1.0000
4.8720 11.1667 1.0000
4.8780 12.1667 1.0000
4.8840 17.5000 1.0000
4.8900 9.6667 1.0000
4.8960 16.1667 1.0000
4.9020 6.5000 1.0000
4.9080 9.0000 1.0000
4.9140 12.6667 1.0000
4.9200 12.8333 1.0000
4.9260 13.1667 1.0000
4.9320 19.0000 1.0000
4.9380 13.8333 1.0000
4.9440 11.6667 1.0000
4.9500 12.6667 1.0000
4.9560 16.5000 1.0000
4.9620 18.0000 1.0000
4.9680 17.0000 1.0000
4.9740 9.0000 1.0000
4.9800 11.1667 1.0000
4.9860 9.8333 1.0000
4.9920 16.0000 1.0000
4.9980 8.8333 1.0000
5.0040 19.6667 1.0000
5.0100 8.5000 1.0000
5.0160 9.8333 1.0000
5.0220 13.6667 1.0000
5.0280 12.8333 1.0000
5.0340 12.3333 1.0000
5.0400 11.8333 1.0000
5.0460 16.6667 1.0000
5.0520 13.0000 1.0000
5.0580 9.5000 1.0000
5.0640 12.3333 1.0000
5.0700 18.3333 1.0000
5.0760 8.8333 1.0000
5.0820 10.1667 1.0000
5.0880 9.1667 1.0000
5.0940 15.8333 1.0000
5.1000 12.5000 1.0000
5.1060 12.1667 1.0000
5.1120 10.5000 1.0000
5.1180 3.6667 1.0000
5.1240 10.3333 1.0000
5.1300 10.0000 1.0000
5.1360 17.6667 1.0000
5.1420 17.6667 1.0000
5.1480 7.3333 1.0000
5.1540 9.6667 1.0000
5.1600 12.3333 1.0000
5.1660 14.6667 1.0000
5.1720 10.5000 1.0000
5.1780 10.0000 1.0000
5.1840 7.5000 1.0000
5.1900 11.1667 1.0000
5.1960 14.3333 1.0000
5.2020 11.8333 1.0000
5.2080 5.0000 1.0000
5.2140 8.1667 1.0000
5.2200 9.0000 1.0000
5.2260 7.5000 1.0000
5.2320 5.5000 1.0000
5.2380 12.5000 1.0000
5.2440 11.1667 1.0000
5.2500 5.8333 1.0000
5.2560 11.8333 1.0000
5.2620 12.6667 1.0000
5.2680 12.1667 1.0000
5.2740 13.6667 1.0000
5.2800 7.8333 1.0000
5.2860 10.3333 1.0000
5.2920 12.1667 1.0000
5.2980 6.6667 1.0000
5.3040 9.5000 1.0000
5.3100 7.3333 1.0000
5.3160 7.3333 1.0000
5.3220 7.0000 1.0000
5.3280 10.0000 1.0000
5.3340 15.8333 1.0000
5.3400 5.5000 1.0000
5.3460 8.6667 1.0000
5.3520 10.8333 1.0000
5.3580 6.0000 1.0000
5.3640 8.8333 1.0000
5.3700 6.5000 1.0000
5.3760 4.8333 1.0000
5.3820 12.5000 1.0000
5.3880 6.3333 1.0000
5.3940 6.8333 1.0000
5.4000 5.0000 1.0000
5.4060 6.1667 1.0000
5.4120 7.0000 1.0000
5.4180 12.8333 1.0000
5.4240 5.3333 1.0000
5.4300 6.1667 1.0000
5.4360 10.1667 1.0000
5.4420 5.1667 1.0000
5.4480 12.5000 1.0000
5.4540 10.8333 1.0000
5.4600 7.8333 1.0000
5.4660 9.3333 1.0000
5.4720 8.1667 1.0000
5.4780 10.1667 1.0000
5.4840 15.1667 1.0000
5.4900 11.0000 1.0000
5.4960 12.5000 1.0000
5.5020 4.5000 1.0000
5.5080 4.8333 1.0000
5.5140 3.0000 1.0000
5.5200 7.5000 1.0000
5.5260 9.5000 1.0000
5.5320 11.6667 1.0000
5.5380 3.5000 1.0000
5.5440 9.6667 1.0000
5.5500 3.3333 1.0000
5.5560 11.6667 1.0000
5.5620 7.6667 1.0000
5.5680 9.3333 1.0000
5.5740 6.5000 1.0000
5.5800 4.5000 1.0000
5.5860 10.0000 1.0000
5.5920 6.8333 1.0000
5.5980 6.1667 1.0000
5.6040 10.5000 1.0000
5.6100 13.5000 1.0000
5.6160 14.0000 1.0000
5.6220 7.0000 1.0000
5.6280 13.5000 1.0000
5.6340 8.0000 1.0000
5.6400 6.0000 1.0000
5.6460 14.3333 1.0000
5.6520 6.5000 1.0000
5.6580 11.1667 1.0000
5.6640 9.0000 1.0000
5.6700 8.1667 1.0000
5.6760 9.3333 1.0000
5.6820 8.0000 1.0000
5.6880 4.5000 1.0000
5.6940 5.8333 1.0000
5.7000 9.8333 1.0000
5.7060 8.8333 1.0000
5.7120 5.1667 1.0000
5.7180 5.8333 1.0000
5.7240 9.3333 1.0000
5.7300 8.3333 1.0000
5.7360 3.6667 1.0000
5.7420 11.3333 1.0000
5.7480 7.3333 1.0000
5.7540 12.3333 1.0000
5.7600 10.0000 1.0000
5.7660 8.0000 1.0000
5.7720 5.8333 1.0000
5.7780 5.3333 1.0000
5.7840 8.0000 1.0000
5.7900 8.8333 1.0000
5.7960 6.6667 1.0000
5.8020 11.5000 1.0000
5.8080 8.6667 1.0000
5.8140 1.6667 1.0000
5.8200 3.5000 1.0000
5.8260 6.8333 1.0000
5.8320 6.3333 1.0000
5.8380 4.3333 1.0000
5.8440 1.1667 1.0000
5.8500 3.8333 1.0000
5.8560 7.0000 1.0000
5.8620 3.3333 1.0000
5.8680 7.8333 1.0000
5.8740 1.1667 1.0000
5.8800 4.5000 1.0000
5.8860 6.6667 1.0000
5.8920 5.1667 1.0000
5.8980 4.6667 1.0000
5.9040 5.1667 1.0000
5.9100 3.8333 1.0000
5.9160 5.6667 1.0000
5.9220 4.1667 1.0000
5.9280 9.3333 1.0000
5.9340 6.5000 1.0000
5.9400 2.8333 1.0000
5.9460 0.0000 1.0000
5.9520 5.5000 1.0000
5.9580 6.6667 1.0000
5.9640 2.6667 1.0000
5.9700 13.1667 1.0000
5.9760 4.3333 1.0000
5.9820 4.8333 1.0000
5.9880 6.1667 1.0000
5.9940 6.0000 1.0000
6.0000 6.5000 1.0000
*RAS_INT_END
*RAS_DATA_END