File: XRR/CWOI6_reflectivity.ras
*RAS_DATA_START
*RAS_HEADER_START
*DISP_FMT_X "%.4f"
*DISP_FMT_Y "%.0f"
*DISP_FULLSCALE "29418229.3500000050"
*DISP_LINE_COLOR "255.0000000000"
*DISP_LINE_STYLE "0.0000000000"
*DISP_LINE_WIDTH "0.2500000000"
*DISP_NOTE "Collected Data-1"
*DISP_OFFSET_Y "0.0000000000"
*DISP_PEAKSEARCH_UNIT_Y "cps"
*DISP_RANGE_BOTTOM "0.0100000000"
*DISP_RANGE_LEFT "-0.0006000000"
*DISP_RANGE_LOGCUTOFF "0.0100000000"
*DISP_RANGE_RIGHT "6.0006000000"
*DISP_RANGE_TOP "29418229.3500000050"
*DISP_SCALE_MODE_Y "2.0000000000"
*DISP_TAB_NAME "2-Theta/Omega"
*DISP_TITLE_Y "Intensity"
*DISP_UNIT_Y "cps"
*DISP_WINDOW_NAME "MSG_MACROENGINE"
*FILE_COMMENT " "
*FILE_MD5 ""
*FILE_MEMO " "
*FILE_OPERATOR "Administrator"
*FILE_PART_ID "MEAS_KHP2_00055"
*FILE_SAMPLE "CWO I6"
*FILE_TYPE "RAS_RAW"
*FILE_USERGROUP "System Manager"
*FILE_VERSION "1.0000000000"
*HW_ATTACHMENT_ID "ATT0025"
*HW_ATTACHMENT_NAME "標準|Standard"
*HW_COUNTER_ID-0 "CUT0025"
*HW_COUNTER_ID-1 "CUT0020"
*HW_COUNTER_ID-2 "CUT0020"
*HW_COUNTER_ID-3 "CSL0021"
*HW_COUNTER_ID-4 "CMC0021"
*HW_COUNTER_NAME-0 "D/teX Ultra|D/teX Ultra"
*HW_COUNTER_NAME-1 "None|None"
*HW_COUNTER_NAME-2 "None|None"
*HW_COUNTER_NAME-3 "BBM|BBM"
*HW_COUNTER_NAME-4 "検出器モノクロメータ|Detector monochromator"
*HW_COUNTER_SELECT_NAME "D/teX Ultra|D/teX Ultra"
*HW_GONIOMETER_ID "GON0023"
*HW_GONIOMETER_NAME "SmartLab|SmartLab"
*HW_GONIOMETER_RADIUS-0 "90.0"
*HW_GONIOMETER_RADIUS-1 "114.0"
*HW_GONIOMETER_RADIUS-2 "190.0"
*HW_GONIOMETER_RADIUS-3 "300.0"
*HW_GONIOMETER_RADIUS-4 "187.0"
*HW_GONIOMETER_RADIUS-5 "300.0"
*HW_GONIOMETER_RADIUS-6 "113.0"
*HW_GONIOMETER_RADIUS-7 "331.0"
*HW_I_OPT_ID-0 "CBO0021"
*HW_I_OPT_ID-1 "ICR0021"
*HW_I_OPT_ID-2 "ISL0021"
*HW_I_OPT_ID-3 "ISO0021"
*HW_I_OPT_ID-4 "IAD0021"
*HW_I_OPT_ID-5 "IPR0001"
*HW_I_OPT_NAME-0 "CBOユニット|CBO unit"
*HW_I_OPT_NAME-1 "標準入射光学ユニット|Standard incident optical unit"
*HW_I_OPT_NAME-2 "標準入射スリットボックス|Standard incident slit box"
*HW_I_OPT_NAME-3 "入射平行スリット|Incident parallel slit"
*HW_I_OPT_NAME-4 "長手制限スリット|Length limiting slit"
*HW_I_OPT_NAME-5 "None|None"
*HW_R_ATTENUATER_AUTOMODE "1"
*HW_R_OPT_ID-0 "RSS0021"
*HW_R_OPT_ID-1 "RCR0023"
*HW_R_OPT_ID-2 "RSO0021"
*HW_R_OPT_ID-3 "RRS0021"
*HW_R_OPT_ID-4 "ATN0021"
*HW_R_OPT_ID-5 "RFL0021"
*HW_R_OPT_ID-6 "RAD0021"
*HW_R_OPT_NAME-0 "標準受光スリットボックス1|Standard receiving slit box # 1"
*HW_R_OPT_NAME-1 "標準受光光学ユニット1|Standard receiving unit # 1"
*HW_R_OPT_NAME-2 "標準受光光学ユニット2|Standard receiving optical unit # 2"
*HW_R_OPT_NAME-3 "標準受光スリットボックス2|Standard receiving slit box # 2"
*HW_R_OPT_NAME-4 "標準アッテネータ|Standard Attenuator"
*HW_R_OPT_NAME-5 "Cu Kβ|Cu K-beta"
*HW_R_OPT_NAME-6 "調整用受光スリット|Alignment receiving slit"
*HW_SAMPLE_HOLDER_ID "SMP0021"
*HW_SAMPLE_HOLDER_NAME "χφZクレードル|Chi phi Z cradle"
*HW_XG_CURRENT_MAX "200"
*HW_XG_CURRENT_MIN "10"
*HW_XG_CURRENT_RESOLUTION "1"
*HW_XG_CURRENT_UNIT "mA"
*HW_XG_FOCUS "0.4mm x 8mm"
*HW_XG_FOCUS_TYPE "Normal"
*HW_XG_ID "1700"
*HW_XG_NAME "9kW 開放管(45kV 200mA ID:1700)|9kW Rotating anode(45kV 200mA ID:1700)"
*HW_XG_TARGET_ATOMIC_NUMBER "29.0000000000"
*HW_XG_TARGET_NAME "Cu"
*HW_XG_TYPE "Rota"
*HW_XG_VOLTAGE_MAX "45"
*HW_XG_VOLTAGE_MIN "20"
*HW_XG_VOLTAGE_RESOLUTION "1"
*HW_XG_VOLTAGE_UNIT "kV"
*HW_XG_WATT_MAX "9.00"
*HW_XG_WATT_UNIT "kW"
*HW_XG_WAVE_LENGTH_ALPHA1 "1.540593"
*HW_XG_WAVE_LENGTH_ALPHA2 "1.544414"
*HW_XG_WAVE_LENGTH_BETA "1.392250"
*MEAS_COND_AXIS_NAME-0 "Theta/2-Theta"
*MEAS_COND_AXIS_NAME-1 "2-Theta"
*MEAS_COND_AXIS_NAME-2 "Omega"
*MEAS_COND_AXIS_NAME-3 "Chi"
*MEAS_COND_AXIS_NAME-4 "Phi"
*MEAS_COND_AXIS_NAME-5 "Z"
*MEAS_COND_AXIS_NAME-6 "2-Theta/Omega"
*MEAS_COND_AXIS_NAME-7 "Theta_s"
*MEAS_COND_AXIS_NAME-8 "Theta_d"
*MEAS_COND_AXIS_NAME-9 "Ts"
*MEAS_COND_AXIS_NAME-10 "CBO selection slit"
*MEAS_COND_AXIS_NAME-11 "M"
*MEAS_COND_AXIS_NAME-12 "Incident parallel slit"
*MEAS_COND_AXIS_NAME-13 "Incident slit"
*MEAS_COND_AXIS_NAME-14 ""
*MEAS_COND_AXIS_NAME-15 "Zs"
*MEAS_COND_AXIS_NAME-16 "Incident optical device"
*MEAS_COND_AXIS_NAME-17 "Omega_m"
*MEAS_COND_AXIS_NAME-18 "Length limiting slit"
*MEAS_COND_AXIS_NAME-19 "Center slit"
*MEAS_COND_AXIS_NAME-20 "Filter"
*MEAS_COND_AXIS_NAME-21 "Receiving slit # 1"
*MEAS_COND_AXIS_NAME-22 "Receiving slit # 2"
*MEAS_COND_AXIS_NAME-23 "Receiving optical device"
*MEAS_COND_AXIS_NAME-24 "Receiving parallel slit"
*MEAS_COND_AXIS_NAME-25 "Alignment receiving slit"
*MEAS_COND_AXIS_NAME-26 ""
*MEAS_COND_AXIS_NAME-27 ""
*MEAS_COND_AXIS_NAME-28 "Zd"
*MEAS_COND_AXIS_NAME-29 "Attenuator"
*MEAS_COND_AXIS_NAME-30 "Diffracted beam monochromator"
*MEAS_COND_AXIS_NAME-31 "Monochromator slit"
*MEAS_COND_AXIS_NAME-32 "Primary beam"
*MEAS_COND_AXIS_NAME-33 ""
*MEAS_COND_AXIS_NAME-34 ""
*MEAS_COND_AXIS_NAME-35 "PHA"
*MEAS_COND_AXIS_NAME_INTERNAL-0 "TwoThetaTheta"
*MEAS_COND_AXIS_NAME_INTERNAL-1 "TwoTheta"
*MEAS_COND_AXIS_NAME_INTERNAL-2 "Omega"
*MEAS_COND_AXIS_NAME_INTERNAL-3 "Chi"
*MEAS_COND_AXIS_NAME_INTERNAL-4 "Phi"
*MEAS_COND_AXIS_NAME_INTERNAL-5 "Z"
*MEAS_COND_AXIS_NAME_INTERNAL-6 "TwoThetaOmega"
*MEAS_COND_AXIS_NAME_INTERNAL-7 "ThetaS"
*MEAS_COND_AXIS_NAME_INTERNAL-8 "ThetaD"
*MEAS_COND_AXIS_NAME_INTERNAL-9 "Ts"
*MEAS_COND_AXIS_NAME_INTERNAL-10 "CBO"
*MEAS_COND_AXIS_NAME_INTERNAL-11 "CBO-M"
*MEAS_COND_AXIS_NAME_INTERNAL-12 "IncidentSollerSlit"
*MEAS_COND_AXIS_NAME_INTERNAL-13 "IncidentSlitBox"
*MEAS_COND_AXIS_NAME_INTERNAL-14 "IncidentSlitBox-_Axis"
*MEAS_COND_AXIS_NAME_INTERNAL-15 "Zs"
*MEAS_COND_AXIS_NAME_INTERNAL-16 "IncidentMonochromator"
*MEAS_COND_AXIS_NAME_INTERNAL-17 "IncidentMonochromator-OmegaM"
*MEAS_COND_AXIS_NAME_INTERNAL-18 "IncidentAxdSlit"
*MEAS_COND_AXIS_NAME_INTERNAL-19 "CenterSlit"
*MEAS_COND_AXIS_NAME_INTERNAL-20 "Filter"
*MEAS_COND_AXIS_NAME_INTERNAL-21 "ReceivingSlitBox1"
*MEAS_COND_AXIS_NAME_INTERNAL-22 "ReceivingSlitBox2"
*MEAS_COND_AXIS_NAME_INTERNAL-23 "ReceivingOptics"
*MEAS_COND_AXIS_NAME_INTERNAL-24 "ReceivingSollerSlit"
*MEAS_COND_AXIS_NAME_INTERNAL-25 "ReceivingAxdSlit"
*MEAS_COND_AXIS_NAME_INTERNAL-26 "ReceivingSlitBox1-_Axis"
*MEAS_COND_AXIS_NAME_INTERNAL-27 "ReceivingSlitBox2-_Axis"
*MEAS_COND_AXIS_NAME_INTERNAL-28 "ReceivingSlitBox2-Zd"
*MEAS_COND_AXIS_NAME_INTERNAL-29 "Attenuator"
*MEAS_COND_AXIS_NAME_INTERNAL-30 "CounterMonochromator"
*MEAS_COND_AXIS_NAME_INTERNAL-31 "CounterSlit"
*MEAS_COND_AXIS_NAME_INTERNAL-32 "IncidentPrimary"
*MEAS_COND_AXIS_NAME_INTERNAL-33 "AlphaR"
*MEAS_COND_AXIS_NAME_INTERNAL-34 "BetaR"
*MEAS_COND_AXIS_NAME_INTERNAL-35 "PHA"
*MEAS_COND_AXIS_NAME_MAGICNO-0 "83951616.0000000000"
*MEAS_COND_AXIS_NAME_MAGICNO-1 "268632064.0000000000"
*MEAS_COND_AXIS_NAME_MAGICNO-2 "268500992.0000000000"
*MEAS_COND_AXIS_NAME_MAGICNO-3 "268500992.0000000000"
*MEAS_COND_AXIS_NAME_MAGICNO-4 "268500992.0000000000"
*MEAS_COND_AXIS_NAME_MAGICNO-5 "285278208.0000000000"
*MEAS_COND_AXIS_NAME_MAGICNO-6 "83951616.0000000000"
*MEAS_COND_AXIS_NAME_MAGICNO-7 "131072.0000000000"
*MEAS_COND_AXIS_NAME_MAGICNO-8 "131072.0000000000"
*MEAS_COND_AXIS_NAME_MAGICNO-9 "318898176.0000000000"
*MEAS_COND_AXIS_NAME_MAGICNO-10 "20971521.0000000000"
*MEAS_COND_AXIS_NAME_MAGICNO-11 "285343744.0000000000"
*MEAS_COND_AXIS_NAME_MAGICNO-12 "20971521.0000000000"
*MEAS_COND_AXIS_NAME_MAGICNO-13 "22020097.0000000000"
*MEAS_COND_AXIS_NAME_MAGICNO-14 "25165824.0000000000"
*MEAS_COND_AXIS_NAME_MAGICNO-15 "318898176.0000000000"
*MEAS_COND_AXIS_NAME_MAGICNO-16 "20971521.0000000000"
*MEAS_COND_AXIS_NAME_MAGICNO-17 "285343744.0000000000"
*MEAS_COND_AXIS_NAME_MAGICNO-18 "20971521.0000000000"
*MEAS_COND_AXIS_NAME_MAGICNO-19 "20971521.0000000000"
*MEAS_COND_AXIS_NAME_MAGICNO-20 "20971521.0000000000"
*MEAS_COND_AXIS_NAME_MAGICNO-21 "23068673.0000000000"
*MEAS_COND_AXIS_NAME_MAGICNO-22 "23068673.0000000000"
*MEAS_COND_AXIS_NAME_MAGICNO-23 "20971521.0000000000"
*MEAS_COND_AXIS_NAME_MAGICNO-24 "20971521.0000000000"
*MEAS_COND_AXIS_NAME_MAGICNO-25 "20971521.0000000000"
*MEAS_COND_AXIS_NAME_MAGICNO-26 "25165824.0000000000"
*MEAS_COND_AXIS_NAME_MAGICNO-27 "25165824.0000000000"
*MEAS_COND_AXIS_NAME_MAGICNO-28 "285343744.0000000000"
*MEAS_COND_AXIS_NAME_MAGICNO-29 "17301505.0000000000"
*MEAS_COND_AXIS_NAME_MAGICNO-30 "20971521.0000000000"
*MEAS_COND_AXIS_NAME_MAGICNO-31 "20971521.0000000000"
*MEAS_COND_AXIS_NAME_MAGICNO-32 "20971521.0000000000"
*MEAS_COND_AXIS_NAME_MAGICNO-33 "8388608.0000000000"
*MEAS_COND_AXIS_NAME_MAGICNO-34 "8388608.0000000000"
*MEAS_COND_AXIS_NAME_MAGICNO-35 "0.0000000000"
*MEAS_COND_AXIS_OFFSET-0 "-"
*MEAS_COND_AXIS_OFFSET-1 "0.9237000000"
*MEAS_COND_AXIS_OFFSET-2 "0.9069000000"
*MEAS_COND_AXIS_OFFSET-3 "0.0000000000"
*MEAS_COND_AXIS_OFFSET-4 "0.0000000000"
*MEAS_COND_AXIS_OFFSET-5 "-"
*MEAS_COND_AXIS_OFFSET-6 "-"
*MEAS_COND_AXIS_OFFSET-7 "0.9069000000"
*MEAS_COND_AXIS_OFFSET-8 "0.0168000000"
*MEAS_COND_AXIS_OFFSET-9 "-"
*MEAS_COND_AXIS_OFFSET-10 "-"
*MEAS_COND_AXIS_OFFSET-11 "-"
*MEAS_COND_AXIS_OFFSET-12 "-"
*MEAS_COND_AXIS_OFFSET-13 "-"
*MEAS_COND_AXIS_OFFSET-14 "-"
*MEAS_COND_AXIS_OFFSET-15 "-"
*MEAS_COND_AXIS_OFFSET-16 "-"
*MEAS_COND_AXIS_OFFSET-17 "-"
*MEAS_COND_AXIS_OFFSET-18 "-"
*MEAS_COND_AXIS_OFFSET-19 "-"
*MEAS_COND_AXIS_OFFSET-20 "-"
*MEAS_COND_AXIS_OFFSET-21 "-"
*MEAS_COND_AXIS_OFFSET-22 "-"
*MEAS_COND_AXIS_OFFSET-23 "-"
*MEAS_COND_AXIS_OFFSET-24 "-"
*MEAS_COND_AXIS_OFFSET-25 "-"
*MEAS_COND_AXIS_OFFSET-26 "-"
*MEAS_COND_AXIS_OFFSET-27 "-"
*MEAS_COND_AXIS_OFFSET-28 "-"
*MEAS_COND_AXIS_OFFSET-29 "-"
*MEAS_COND_AXIS_OFFSET-30 "-"
*MEAS_COND_AXIS_OFFSET-31 "-"
*MEAS_COND_AXIS_OFFSET-32 "-"
*MEAS_COND_AXIS_OFFSET-33 "0.0000000000"
*MEAS_COND_AXIS_OFFSET-34 "0.0000000000"
*MEAS_COND_AXIS_OFFSET-35 "-"
*MEAS_COND_AXIS_POSITION-0 "-0.0008000000"
*MEAS_COND_AXIS_POSITION-1 "-0.0008000000"
*MEAS_COND_AXIS_POSITION-2 "-0.0004000000"
*MEAS_COND_AXIS_POSITION-3 "0.0000000000"
*MEAS_COND_AXIS_POSITION-4 "0.0000000000"
*MEAS_COND_AXIS_POSITION-5 "-1.4825000000"
*MEAS_COND_AXIS_POSITION-6 "-0.0008000000"
*MEAS_COND_AXIS_POSITION-7 "-0.0004000000"
*MEAS_COND_AXIS_POSITION-8 "-0.0004000000"
*MEAS_COND_AXIS_POSITION-9 "-4.9359400000"
*MEAS_COND_AXIS_POSITION-10 "PB"
*MEAS_COND_AXIS_POSITION-11 "0.0000000000"
*MEAS_COND_AXIS_POSITION-12 "Soller_slit_open_s"
*MEAS_COND_AXIS_POSITION-13 "0.250mm"
*MEAS_COND_AXIS_POSITION-14 "0.2500000000"
*MEAS_COND_AXIS_POSITION-15 "-0.8884400000"
*MEAS_COND_AXIS_POSITION-16 "Ge(220)x2"
*MEAS_COND_AXIS_POSITION-17 "0.0000000000"
*MEAS_COND_AXIS_POSITION-18 "2.0mm"
*MEAS_COND_AXIS_POSITION-19 "None"
*MEAS_COND_AXIS_POSITION-20 "None"
*MEAS_COND_AXIS_POSITION-21 "0.250mm"
*MEAS_COND_AXIS_POSITION-22 "0.250mm"
*MEAS_COND_AXIS_POSITION-23 "No_unit"
*MEAS_COND_AXIS_POSITION-24 "Soller_slit_5.0deg"
*MEAS_COND_AXIS_POSITION-25 "None"
*MEAS_COND_AXIS_POSITION-26 "0.2500000000"
*MEAS_COND_AXIS_POSITION-27 "0.2500000000"
*MEAS_COND_AXIS_POSITION-28 "0.0887500000"
*MEAS_COND_AXIS_POSITION-29 "1/10000"
*MEAS_COND_AXIS_POSITION-30 "None"
*MEAS_COND_AXIS_POSITION-31 "None"
*MEAS_COND_AXIS_POSITION-32 "None"
*MEAS_COND_AXIS_POSITION-33 "0.0000000000"
*MEAS_COND_AXIS_POSITION-34 "0.0000000000"
*MEAS_COND_AXIS_POSITION-35 "34.0000000000"
*MEAS_COND_AXIS_UNIT-0 "deg"
*MEAS_COND_AXIS_UNIT-1 "deg"
*MEAS_COND_AXIS_UNIT-2 "deg"
*MEAS_COND_AXIS_UNIT-3 "deg"
*MEAS_COND_AXIS_UNIT-4 "deg"
*MEAS_COND_AXIS_UNIT-5 "mm"
*MEAS_COND_AXIS_UNIT-6 "deg"
*MEAS_COND_AXIS_UNIT-7 "deg"
*MEAS_COND_AXIS_UNIT-8 "deg"
*MEAS_COND_AXIS_UNIT-9 "mm"
*MEAS_COND_AXIS_UNIT-10 ""
*MEAS_COND_AXIS_UNIT-11 "pulse"
*MEAS_COND_AXIS_UNIT-12 ""
*MEAS_COND_AXIS_UNIT-13 ""
*MEAS_COND_AXIS_UNIT-14 "mm"
*MEAS_COND_AXIS_UNIT-15 "mm"
*MEAS_COND_AXIS_UNIT-16 ""
*MEAS_COND_AXIS_UNIT-17 "pulse"
*MEAS_COND_AXIS_UNIT-18 ""
*MEAS_COND_AXIS_UNIT-19 ""
*MEAS_COND_AXIS_UNIT-20 ""
*MEAS_COND_AXIS_UNIT-21 ""
*MEAS_COND_AXIS_UNIT-22 ""
*MEAS_COND_AXIS_UNIT-23 ""
*MEAS_COND_AXIS_UNIT-24 ""
*MEAS_COND_AXIS_UNIT-25 ""
*MEAS_COND_AXIS_UNIT-26 "mm"
*MEAS_COND_AXIS_UNIT-27 "mm"
*MEAS_COND_AXIS_UNIT-28 "mm"
*MEAS_COND_AXIS_UNIT-29 ""
*MEAS_COND_AXIS_UNIT-30 ""
*MEAS_COND_AXIS_UNIT-31 ""
*MEAS_COND_AXIS_UNIT-32 ""
*MEAS_COND_AXIS_UNIT-33 "deg"
*MEAS_COND_AXIS_UNIT-34 "deg"
*MEAS_COND_AXIS_UNIT-35 "div"
*MEAS_COND_COUNTER_CNTLOSS_CORR "0.0000000000"
*MEAS_COND_COUNTER_PHABASE "34.0000000000"
*MEAS_COND_COUNTER_PHAWINDOW "19.0000000000"
*MEAS_COND_COUNTER_PHA_UNIT "div"
*MEAS_COND_COUNTER_TAUDIFF "2.0000000000"
*MEAS_COND_COUNTER_TAUINT "0.1000000000"
*MEAS_COND_IRRADIATION_MODE "OFF"
*MEAS_COND_IRRADIATION_WIDTH ""
*MEAS_COND_OPT_ATTR "High resolution parallel beam Ge(220)x2/RS"
*MEAS_COND_OPT_NAME "@High resolution PB-Ge(220)x2"
*MEAS_COND_UNSYMMETRIC_MODE "OFF"
*MEAS_COND_XG_CURRENT "200.0000000000"
*MEAS_COND_XG_VOLTAGE "45.0000000000"
*MEAS_COND_XG_WAVE_TYPE "Ka1"
*MEAS_DATA_COUNT "3001.0000000000"
*MEAS_SCAN_AXIS_X "2-Theta/Omega"
*MEAS_SCAN_AXIS_X_INTERNAL "TwoThetaOmega"
*MEAS_SCAN_END_TIME "10/27/23 10:47:16"
*MEAS_SCAN_MODE "CONTINUOUS"
*MEAS_SCAN_MONITOR "0"
*MEAS_SCAN_RESOLUTION_X "0.0002"
*MEAS_SCAN_SPEED "0.500000"
*MEAS_SCAN_SPEED_UNIT "deg/min"
*MEAS_SCAN_SPEED_USER "0.500000"
*MEAS_SCAN_START "0.0000000000"
*MEAS_SCAN_START_TIME "10/27/23 10:34:47"
*MEAS_SCAN_STEP "0.0020000000"
*MEAS_SCAN_STOP "6.0000000000"
*MEAS_SCAN_UNIT_X "deg"
*MEAS_SCAN_UNIT_Y "counts"
*RAS_HEADER_END
*RAS_INT_START
0.0000 5656906.0000 1.0000
0.0060 5694558.5000 1.0000
0.0120 5621047.0000 1.0000
0.0180 5550294.5000 1.0000
0.0240 5431270.0000 1.0000
0.0300 5158051.5000 1.0000
0.0360 4459903.0000 1.0000
0.0420 3685898.5000 1.0000
0.0480 2651088.7500 1.0000
0.0540 1820951.1250 1.0000
0.0600 1081840.5000 1.0000
0.0660 579745.1250 1.0000
0.0720 297067.0625 1.0000
0.0780 170567.6094 1.0000
0.0840 128838.0469 1.0000
0.0900 103821.1719 1.0000
0.0960 95665.9219 1.0000
0.1020 95494.6250 1.0000
0.1080 95390.3516 1.0000
0.1140 106219.3359 1.0000
0.1200 105102.1797 1.0000
0.1260 111618.9297 1.0000
0.1320 113920.2734 1.0000
0.1380 119699.7031 1.0000
0.1440 124443.8984 1.0000
0.1500 132837.4688 1.0000
0.1560 136665.5938 1.0000
0.1620 135049.4531 1.0000
0.1680 150615.1719 1.0000
0.1740 150250.2344 1.0000
0.1800 155605.1406 1.0000
0.1860 160937.7031 1.0000
0.1920 168951.4531 1.0000
0.1980 171230.4531 1.0000
0.2040 174656.4063 1.0000
0.2100 178864.3594 1.0000
0.2160 179497.4219 1.0000
0.2220 185083.2031 1.0000
0.2280 190117.8594 1.0000
0.2340 197692.1875 1.0000
0.2400 203628.0156 1.0000
0.2460 211530.0469 1.0000
0.2520 209668.1250 1.0000
0.2580 211574.7344 1.0000
0.2640 211798.1563 1.0000
0.2700 225762.6406 1.0000
0.2760 227915.0313 1.0000
0.2820 236733.1250 1.0000
0.2880 236844.8438 1.0000
0.2940 244329.7969 1.0000
0.3000 251837.0938 1.0000
0.3060 250049.6406 1.0000
0.3120 260752.0156 1.0000
0.3180 261355.2656 1.0000
0.3240 265027.0000 1.0000
0.3300 267700.7188 1.0000
0.3360 263418.2813 1.0000
0.3420 283996.3125 1.0000
0.3480 283921.8438 1.0000
0.3540 286617.9375 1.0000
0.3600 292769.7500 1.0000
0.3660 296538.2813 1.0000
0.3720 300157.8750 1.0000
0.3780 305207.4375 1.0000
0.3840 310204.8438 1.0000
0.3900 315522.5000 1.0000
0.3960 313951.0625 1.0000
0.4020 314479.8438 1.0000
0.4080 332793.7813 1.0000
0.4140 337366.6875 1.0000
0.4200 331877.6875 1.0000
0.4260 343034.3750 1.0000
0.4320 343242.9063 1.0000
0.4380 348240.3438 1.0000
0.4440 350690.6250 1.0000
0.4500 353669.7188 1.0000
0.4560 357810.6563 1.0000
0.4620 362726.1563 1.0000
0.4680 363269.8438 1.0000
0.4740 363604.9688 1.0000
0.4800 368185.3125 1.0000
0.4860 370129.1875 1.0000
0.4920 374992.5313 1.0000
0.4980 379468.6250 1.0000
0.5040 384652.2188 1.0000
0.5100 381859.3438 1.0000
0.5160 387884.5313 1.0000
0.5220 387906.8750 1.0000
0.5280 391705.2188 1.0000
0.5340 398668.8125 1.0000
0.5400 395414.1563 1.0000
0.5460 393745.8750 1.0000
0.5520 399331.6875 1.0000
0.5580 401096.7813 1.0000
0.5640 396896.2500 1.0000
0.5700 401960.7188 1.0000
0.5760 403614.1250 1.0000
0.5820 403912.0313 1.0000
0.5880 406272.9375 1.0000
0.5940 399205.0625 1.0000
0.6000 397819.7813 1.0000
0.6060 409095.6250 1.0000
0.6120 399741.3125 1.0000
0.6180 391474.3438 1.0000
0.6240 385970.4688 1.0000
0.6300 369324.8125 1.0000
0.6360 368416.1875 1.0000
0.6420 346706.1250 1.0000
0.6480 326291.9063 1.0000
0.6540 320825.2813 1.0000
0.6600 296754.2813 1.0000
0.6660 284904.9375 1.0000
0.6720 272281.0938 1.0000
0.6780 245655.5000 1.0000
0.6840 229717.3750 1.0000
0.6900 210033.0625 1.0000
0.6960 192203.2188 1.0000
0.7020 178231.2969 1.0000
0.7080 159343.8906 1.0000
0.7140 150175.7656 1.0000
0.7200 135354.7969 1.0000
0.7260 123751.2578 1.0000
0.7320 111648.7188 1.0000
0.7380 103165.7734 1.0000
0.7440 91011.0938 1.0000
0.7500 83868.7344 1.0000
0.7560 80882.2031 1.0000
0.7620 72496.0703 1.0000
0.7680 69673.3906 1.0000
0.7740 66575.1406 1.0000
0.7800 62615.3320 1.0000
0.7860 59030.0000 1.0000
0.7920 56638.8320 1.0000
0.7980 53098.8320 1.0000
0.8040 50989.3320 1.0000
0.8100 48900.1680 1.0000
0.8160 47453.5000 1.0000
0.8220 45530.5000 1.0000
0.8280 44190.8320 1.0000
0.8340 42718.8320 1.0000
0.8400 40938.6680 1.0000
0.8460 39560.8320 1.0000
0.8520 38719.1680 1.0000
0.8580 37556.6680 1.0000
0.8640 36158.6680 1.0000
0.8700 34965.3320 1.0000
0.8760 33798.6680 1.0000
0.8820 32727.0000 1.0000
0.8880 31866.3340 1.0000
0.8940 30604.5000 1.0000
0.9000 29592.8340 1.0000
0.9060 28178.5000 1.0000
0.9120 27345.1660 1.0000
0.9180 25987.0000 1.0000
0.9240 25040.5000 1.0000
0.9300 23926.5000 1.0000
0.9360 23080.1660 1.0000
0.9420 21870.0000 1.0000
0.9480 21351.8340 1.0000
0.9540 20407.3340 1.0000
0.9600 19485.6660 1.0000
0.9660 18795.3340 1.0000
0.9720 17826.1660 1.0000
0.9780 17194.5000 1.0000
0.9840 16731.5000 1.0000
0.9900 16136.0000 1.0000
0.9960 15506.6670 1.0000
1.0020 15059.5000 1.0000
1.0080 14861.6670 1.0000
1.0140 14207.6670 1.0000
1.0200 13932.6670 1.0000
1.0260 13667.8330 1.0000
1.0320 13048.1670 1.0000
1.0380 12857.3330 1.0000
1.0440 12743.0000 1.0000
1.0500 12543.5000 1.0000
1.0560 12424.5000 1.0000
1.0620 12070.3330 1.0000
1.0680 11999.6670 1.0000
1.0740 11642.1670 1.0000
1.0800 11650.5000 1.0000
1.0860 11348.1670 1.0000
1.0920 10951.0000 1.0000
1.0980 11416.3330 1.0000
1.1040 10842.3330 1.0000
1.1100 10693.1670 1.0000
1.1160 10372.1670 1.0000
1.1220 10369.3330 1.0000
1.1280 9985.0000 1.0000
1.1340 9811.5000 1.0000
1.1400 9536.8330 1.0000
1.1460 9280.8330 1.0000
1.1520 9344.0000 1.0000
1.1580 8733.0000 1.0000
1.1640 8517.1670 1.0000
1.1700 8312.6670 1.0000
1.1760 8005.5000 1.0000
1.1820 7844.3335 1.0000
1.1880 7556.6665 1.0000
1.1940 7176.8335 1.0000
1.2000 6964.0000 1.0000
1.2060 6807.8335 1.0000
1.2120 6596.6665 1.0000
1.2180 6442.8335 1.0000
1.2240 6129.5000 1.0000
1.2300 5913.5000 1.0000
1.2360 5670.1665 1.0000
1.2420 5509.5000 1.0000
1.2480 5378.8335 1.0000
1.2540 5299.3335 1.0000
1.2600 5052.5000 1.0000
1.2660 4960.6665 1.0000
1.2720 4897.1665 1.0000
1.2780 4667.0000 1.0000
1.2840 4621.0000 1.0000
1.2900 4592.0000 1.0000
1.2960 4413.8335 1.0000
1.3020 4450.6665 1.0000
1.3080 4358.6665 1.0000
1.3140 4382.8335 1.0000
1.3200 4172.3335 1.0000
1.3260 4228.3335 1.0000
1.3320 4152.8335 1.0000
1.3380 4157.5000 1.0000
1.3440 4166.3335 1.0000
1.3500 4198.5000 1.0000
1.3560 4050.3333 1.0000
1.3620 4107.1665 1.0000
1.3680 4039.0000 1.0000
1.3740 3953.8333 1.0000
1.3800 3889.3333 1.0000
1.3860 3895.5000 1.0000
1.3920 3954.5000 1.0000
1.3980 3815.1667 1.0000
1.4040 3794.1667 1.0000
1.4100 3716.0000 1.0000
1.4160 3761.8333 1.0000
1.4220 3570.1667 1.0000
1.4280 3510.8333 1.0000
1.4340 3510.8333 1.0000
1.4400 3429.6667 1.0000
1.4460 3389.0000 1.0000
1.4520 3279.8333 1.0000
1.4580 3269.5000 1.0000
1.4640 3203.5000 1.0000
1.4700 3060.0000 1.0000
1.4760 3024.8333 1.0000
1.4820 2938.5000 1.0000
1.4880 2850.0000 1.0000
1.4940 2800.0000 1.0000
1.5000 2714.1667 1.0000
1.5060 2675.0000 1.0000
1.5120 2537.3333 1.0000
1.5180 2496.0000 1.0000
1.5240 2518.6667 1.0000
1.5300 2348.3333 1.0000
1.5360 2350.1667 1.0000
1.5420 2262.8333 1.0000
1.5480 2195.8333 1.0000
1.5540 2133.3333 1.0000
1.5600 2035.3334 1.0000
1.5660 2039.6666 1.0000
1.5720 1938.1666 1.0000
1.5780 2064.3333 1.0000
1.5840 1940.0000 1.0000
1.5900 1920.0000 1.0000
1.5960 1898.6666 1.0000
1.6020 1896.8334 1.0000
1.6080 1903.0000 1.0000
1.6140 1815.3334 1.0000
1.6200 1844.6666 1.0000
1.6260 1819.8334 1.0000
1.6320 1723.8334 1.0000
1.6380 1797.6666 1.0000
1.6440 1846.0000 1.0000
1.6500 1795.8334 1.0000
1.6560 1801.5000 1.0000
1.6620 1768.1666 1.0000
1.6680 1743.5000 1.0000
1.6740 1821.3334 1.0000
1.6800 1761.3334 1.0000
1.6860 1675.6666 1.0000
1.6920 1618.5000 1.0000
1.6980 1708.3334 1.0000
1.7040 1728.6666 1.0000
1.7100 1582.3334 1.0000
1.7160 1647.1666 1.0000
1.7220 1603.3334 1.0000
1.7280 1528.8334 1.0000
1.7340 1580.5000 1.0000
1.7400 1498.1666 1.0000
1.7460 1533.6666 1.0000
1.7520 1446.1666 1.0000
1.7580 1473.3334 1.0000
1.7640 1388.3334 1.0000
1.7700 1480.1666 1.0000
1.7760 1373.8334 1.0000
1.7820 1291.8334 1.0000
1.7880 1327.5000 1.0000
1.7940 1223.6666 1.0000
1.8000 1224.8334 1.0000
1.8060 1182.1666 1.0000
1.8120 1216.6666 1.0000
1.8180 1196.0000 1.0000
1.8240 1194.5000 1.0000
1.8300 1083.6666 1.0000
1.8360 1029.8334 1.0000
1.8420 1065.0000 1.0000
1.8480 1021.5000 1.0000
1.8540 953.1667 1.0000
1.8600 1012.3333 1.0000
1.8660 1018.3333 1.0000
1.8720 1004.8333 1.0000
1.8780 896.3333 1.0000
1.8840 944.3333 1.0000
1.8900 977.6667 1.0000
1.8960 920.6667 1.0000
1.9020 887.8333 1.0000
1.9080 903.6667 1.0000
1.9140 877.1667 1.0000
1.9200 924.3333 1.0000
1.9260 881.6667 1.0000
1.9320 803.0000 1.0000
1.9380 938.1667 1.0000
1.9440 830.3333 1.0000
1.9500 858.0000 1.0000
1.9560 875.1667 1.0000
1.9620 868.0000 1.0000
1.9680 833.5000 1.0000
1.9740 887.5000 1.0000
1.9800 814.1667 1.0000
1.9860 881.5000 1.0000
1.9920 854.8333 1.0000
1.9980 790.5000 1.0000
2.0040 767.8333 1.0000
2.0100 814.5000 1.0000
2.0160 809.1667 1.0000
2.0220 827.3333 1.0000
2.0280 757.5000 1.0000
2.0340 744.6667 1.0000
2.0400 672.8333 1.0000
2.0460 718.5000 1.0000
2.0520 748.3333 1.0000
2.0580 687.8333 1.0000
2.0640 692.5000 1.0000
2.0700 701.3333 1.0000
2.0760 684.5000 1.0000
2.0820 636.1667 1.0000
2.0880 596.5000 1.0000
2.0940 652.1667 1.0000
2.1000 613.5000 1.0000
2.1060 608.3333 1.0000
2.1120 604.5000 1.0000
2.1180 559.5000 1.0000
2.1240 554.1667 1.0000
2.1300 535.3333 1.0000
2.1360 566.0000 1.0000
2.1420 519.1667 1.0000
2.1480 512.1667 1.0000
2.1540 514.5000 1.0000
2.1600 500.5000 1.0000
2.1660 510.1667 1.0000
2.1720 474.0000 1.0000
2.1780 495.3333 1.0000
2.1840 469.0000 1.0000
2.1900 524.6667 1.0000
2.1960 457.0000 1.0000
2.2020 476.6667 1.0000
2.2080 433.1667 1.0000
2.2140 477.0000 1.0000
2.2200 453.6667 1.0000
2.2260 462.3333 1.0000
2.2320 421.6667 1.0000
2.2380 461.5000 1.0000
2.2440 451.0000 1.0000
2.2500 441.3333 1.0000
2.2560 471.1667 1.0000
2.2620 447.0000 1.0000
2.2680 459.8333 1.0000
2.2740 452.0000 1.0000
2.2800 462.6667 1.0000
2.2860 473.1667 1.0000
2.2920 447.3333 1.0000
2.2980 387.1667 1.0000
2.3040 454.5000 1.0000
2.3100 400.6667 1.0000
2.3160 421.5000 1.0000
2.3220 389.3333 1.0000
2.3280 388.0000 1.0000
2.3340 413.1667 1.0000
2.3400 407.5000 1.0000
2.3460 363.8333 1.0000
2.3520 368.1667 1.0000
2.3580 394.8333 1.0000
2.3640 353.8333 1.0000
2.3700 377.3333 1.0000
2.3760 377.0000 1.0000
2.3820 340.5000 1.0000
2.3880 345.6667 1.0000
2.3940 339.8333 1.0000
2.4000 322.8333 1.0000
2.4060 335.3333 1.0000
2.4120 300.6667 1.0000
2.4180 304.0000 1.0000
2.4240 306.3333 1.0000
2.4300 324.5000 1.0000
2.4360 288.3333 1.0000
2.4420 286.0000 1.0000
2.4480 311.0000 1.0000
2.4540 261.8333 1.0000
2.4600 291.3333 1.0000
2.4660 265.6667 1.0000
2.4720 260.8333 1.0000
2.4780 285.1667 1.0000
2.4840 255.8333 1.0000
2.4900 231.5000 1.0000
2.4960 243.3333 1.0000
2.5020 265.3333 1.0000
2.5080 254.8333 1.0000
2.5140 294.3333 1.0000
2.5200 274.5000 1.0000
2.5260 244.1667 1.0000
2.5320 240.5000 1.0000
2.5380 251.0000 1.0000
2.5440 245.3333 1.0000
2.5500 259.0000 1.0000
2.5560 247.0000 1.0000
2.5620 281.3333 1.0000
2.5680 216.5000 1.0000
2.5740 223.6667 1.0000
2.5800 253.0000 1.0000
2.5860 248.6667 1.0000
2.5920 236.8333 1.0000
2.5980 222.0000 1.0000
2.6040 231.3333 1.0000
2.6100 237.5000 1.0000
2.6160 245.3333 1.0000
2.6220 241.3333 1.0000
2.6280 217.0000 1.0000
2.6340 199.6667 1.0000
2.6400 214.0000 1.0000
2.6460 228.0000 1.0000
2.6520 214.3333 1.0000
2.6580 244.6667 1.0000
2.6640 219.0000 1.0000
2.6700 220.5000 1.0000
2.6760 182.6667 1.0000
2.6820 206.6667 1.0000
2.6880 205.1667 1.0000
2.6940 199.5000 1.0000
2.7000 193.1667 1.0000
2.7060 197.1667 1.0000
2.7120 196.6667 1.0000
2.7180 189.1667 1.0000
2.7240 158.6667 1.0000
2.7300 159.8333 1.0000
2.7360 146.6667 1.0000
2.7420 169.5000 1.0000
2.7480 146.1667 1.0000
2.7540 156.5000 1.0000
2.7600 146.1667 1.0000
2.7660 154.6667 1.0000
2.7720 133.3333 1.0000
2.7780 144.0000 1.0000
2.7840 143.0000 1.0000
2.7900 134.6667 1.0000
2.7960 148.3333 1.0000
2.8020 150.3333 1.0000
2.8080 124.1667 1.0000
2.8140 137.8333 1.0000
2.8200 134.6667 1.0000
2.8260 153.0000 1.0000
2.8320 136.5000 1.0000
2.8380 135.0000 1.0000
2.8440 138.3333 1.0000
2.8500 126.3333 1.0000
2.8560 132.1667 1.0000
2.8620 131.0000 1.0000
2.8680 137.3333 1.0000
2.8740 131.0000 1.0000
2.8800 124.3333 1.0000
2.8860 125.8333 1.0000
2.8920 104.1667 1.0000
2.8980 117.5000 1.0000
2.9040 123.3333 1.0000
2.9100 142.3333 1.0000
2.9160 127.0000 1.0000
2.9220 132.3333 1.0000
2.9280 126.5000 1.0000
2.9340 119.3333 1.0000
2.9400 131.5000 1.0000
2.9460 129.5000 1.0000
2.9520 131.1667 1.0000
2.9580 114.8333 1.0000
2.9640 106.5000 1.0000
2.9700 119.1667 1.0000
2.9760 120.1667 1.0000
2.9820 120.0000 1.0000
2.9880 123.3333 1.0000
2.9940 110.1667 1.0000
3.0000 115.8333 1.0000
3.0060 97.1667 1.0000
3.0120 95.3333 1.0000
3.0180 88.6667 1.0000
3.0240 99.3333 1.0000
3.0300 84.6667 1.0000
3.0360 102.1667 1.0000
3.0420 92.5000 1.0000
3.0480 105.8333 1.0000
3.0540 105.8333 1.0000
3.0600 106.5000 1.0000
3.0660 79.8333 1.0000
3.0720 77.5000 1.0000
3.0780 75.1667 1.0000
3.0840 79.5000 1.0000
3.0900 91.0000 1.0000
3.0960 77.1667 1.0000
3.1020 74.6667 1.0000
3.1080 70.8333 1.0000
3.1140 80.0000 1.0000
3.1200 72.1667 1.0000
3.1260 67.8333 1.0000
3.1320 91.1667 1.0000
3.1380 80.3333 1.0000
3.1440 69.6667 1.0000
3.1500 86.0000 1.0000
3.1560 80.5000 1.0000
3.1620 72.5000 1.0000
3.1680 82.6667 1.0000
3.1740 61.8333 1.0000
3.1800 67.6667 1.0000
3.1860 66.8333 1.0000
3.1920 80.0000 1.0000
3.1980 73.3333 1.0000
3.2040 54.5000 1.0000
3.2100 75.1667 1.0000
3.2160 72.3333 1.0000
3.2220 54.6667 1.0000
3.2280 76.5000 1.0000
3.2340 75.3333 1.0000
3.2400 72.5000 1.0000
3.2460 72.0000 1.0000
3.2520 75.1667 1.0000
3.2580 60.3333 1.0000
3.2640 64.1667 1.0000
3.2700 61.3333 1.0000
3.2760 65.8333 1.0000
3.2820 63.8333 1.0000
3.2880 58.5000 1.0000
3.2940 52.6667 1.0000
3.3000 56.5000 1.0000
3.3060 53.3333 1.0000
3.3120 74.3333 1.0000
3.3180 54.1667 1.0000
3.3240 63.5000 1.0000
3.3300 52.0000 1.0000
3.3360 48.0000 1.0000
3.3420 57.1667 1.0000
3.3480 63.6667 1.0000
3.3540 62.1667 1.0000
3.3600 43.6667 1.0000
3.3660 49.8333 1.0000
3.3720 42.0000 1.0000
3.3780 45.0000 1.0000
3.3840 41.0000 1.0000
3.3900 43.8333 1.0000
3.3960 58.6667 1.0000
3.4020 46.0000 1.0000
3.4080 38.6667 1.0000
3.4140 48.6667 1.0000
3.4200 69.8333 1.0000
3.4260 37.3333 1.0000
3.4320 46.0000 1.0000
3.4380 43.6667 1.0000
3.4440 38.3333 1.0000
3.4500 51.6667 1.0000
3.4560 43.1667 1.0000
3.4620 47.1667 1.0000
3.4680 44.0000 1.0000
3.4740 60.5000 1.0000
3.4800 42.0000 1.0000
3.4860 50.8333 1.0000
3.4920 43.1667 1.0000
3.4980 38.1667 1.0000
3.5040 45.0000 1.0000
3.5100 43.3333 1.0000
3.5160 43.5000 1.0000
3.5220 43.5000 1.0000
3.5280 42.1667 1.0000
3.5340 42.3333 1.0000
3.5400 38.5000 1.0000
3.5460 40.3333 1.0000
3.5520 40.6667 1.0000
3.5580 39.6667 1.0000
3.5640 35.8333 1.0000
3.5700 40.3333 1.0000
3.5760 27.1667 1.0000
3.5820 36.3333 1.0000
3.5880 43.3333 1.0000
3.5940 33.5000 1.0000
3.6000 43.0000 1.0000
3.6060 30.1667 1.0000
3.6120 32.5000 1.0000
3.6180 36.8333 1.0000
3.6240 34.5000 1.0000
3.6300 31.1667 1.0000
3.6360 39.1667 1.0000
3.6420 30.8333 1.0000
3.6480 26.1667 1.0000
3.6540 39.5000 1.0000
3.6600 31.0000 1.0000
3.6660 23.3333 1.0000
3.6720 29.5000 1.0000
3.6780 33.6667 1.0000
3.6840 38.3333 1.0000
3.6900 24.1667 1.0000
3.6960 21.5000 1.0000
3.7020 24.8333 1.0000
3.7080 27.8333 1.0000
3.7140 22.8333 1.0000
3.7200 28.3333 1.0000
3.7260 36.1667 1.0000
3.7320 23.8333 1.0000
3.7380 34.1667 1.0000
3.7440 25.0000 1.0000
3.7500 27.0000 1.0000
3.7560 20.0000 1.0000
3.7620 34.5000 1.0000
3.7680 27.0000 1.0000
3.7740 25.0000 1.0000
3.7800 27.6667 1.0000
3.7860 20.0000 1.0000
3.7920 18.5000 1.0000
3.7980 23.5000 1.0000
3.8040 25.6667 1.0000
3.8100 25.8333 1.0000
3.8160 17.3333 1.0000
3.8220 19.1667 1.0000
3.8280 24.6667 1.0000
3.8340 15.3333 1.0000
3.8400 18.6667 1.0000
3.8460 25.1667 1.0000
3.8520 19.1667 1.0000
3.8580 25.1667 1.0000
3.8640 22.5000 1.0000
3.8700 20.5000 1.0000
3.8760 20.6667 1.0000
3.8820 16.6667 1.0000
3.8880 14.3333 1.0000
3.8940 21.3333 1.0000
3.9000 23.5000 1.0000
3.9060 30.1667 1.0000
3.9120 21.8333 1.0000
3.9180 24.1667 1.0000
3.9240 11.8333 1.0000
3.9300 27.6667 1.0000
3.9360 17.0000 1.0000
3.9420 20.6667 1.0000
3.9480 18.8333 1.0000
3.9540 11.8333 1.0000
3.9600 17.1667 1.0000
3.9660 20.3333 1.0000
3.9720 15.5000 1.0000
3.9780 11.5000 1.0000
3.9840 17.6667 1.0000
3.9900 17.1667 1.0000
3.9960 10.8333 1.0000
4.0020 18.8333 1.0000
4.0080 9.6667 1.0000
4.0140 18.3333 1.0000
4.0200 11.3333 1.0000
4.0260 12.6667 1.0000
4.0320 19.8333 1.0000
4.0380 15.5000 1.0000
4.0440 10.3333 1.0000
4.0500 14.6667 1.0000
4.0560 11.0000 1.0000
4.0620 11.0000 1.0000
4.0680 11.1667 1.0000
4.0740 13.5000 1.0000
4.0800 13.3333 1.0000
4.0860 7.3333 1.0000
4.0920 10.5000 1.0000
4.0980 12.3333 1.0000
4.1040 11.3333 1.0000
4.1100 10.8333 1.0000
4.1160 7.3333 1.0000
4.1220 13.5000 1.0000
4.1280 13.8333 1.0000
4.1340 12.0000 1.0000
4.1400 12.5000 1.0000
4.1460 11.6667 1.0000
4.1520 8.8333 1.0000
4.1580 10.0000 1.0000
4.1640 14.5000 1.0000
4.1700 9.3333 1.0000
4.1760 15.0000 1.0000
4.1820 15.8333 1.0000
4.1880 20.5000 1.0000
4.1940 15.1667 1.0000
4.2000 8.5000 1.0000
4.2060 10.5000 1.0000
4.2120 15.0000 1.0000
4.2180 13.1667 1.0000
4.2240 9.3333 1.0000
4.2300 8.0000 1.0000
4.2360 11.0000 1.0000
4.2420 9.8333 1.0000
4.2480 12.5000 1.0000
4.2540 12.8333 1.0000
4.2600 18.6667 1.0000
4.2660 13.0000 1.0000
4.2720 1.5000 1.0000
4.2780 8.1667 1.0000
4.2840 10.6667 1.0000
4.2900 11.5000 1.0000
4.2960 11.0000 1.0000
4.3020 6.8333 1.0000
4.3080 8.8333 1.0000
4.3140 4.1667 1.0000
4.3200 8.0000 1.0000
4.3260 6.3333 1.0000
4.3320 10.3333 1.0000
4.3380 6.1667 1.0000
4.3440 11.6667 1.0000
4.3500 12.8333 1.0000
4.3560 7.8333 1.0000
4.3620 7.3333 1.0000
4.3680 4.3333 1.0000
4.3740 8.6667 1.0000
4.3800 9.5000 1.0000
4.3860 8.5000 1.0000
4.3920 6.3333 1.0000
4.3980 8.0000 1.0000
4.4040 4.5000 1.0000
4.4100 12.6667 1.0000
4.4160 7.5000 1.0000
4.4220 12.8333 1.0000
4.4280 7.3333 1.0000
4.4340 8.0000 1.0000
4.4400 8.3333 1.0000
4.4460 3.3333 1.0000
4.4520 8.0000 1.0000
4.4580 5.8333 1.0000
4.4640 10.6667 1.0000
4.4700 7.1667 1.0000
4.4760 8.1667 1.0000
4.4820 3.5000 1.0000
4.4880 2.6667 1.0000
4.4940 7.8333 1.0000
4.5000 6.5000 1.0000
4.5060 7.8333 1.0000
4.5120 5.5000 1.0000
4.5180 9.1667 1.0000
4.5240 5.6667 1.0000
4.5300 7.8333 1.0000
4.5360 5.3333 1.0000
4.5420 7.6667 1.0000
4.5480 6.5000 1.0000
4.5540 5.3333 1.0000
4.5600 6.1667 1.0000
4.5660 6.5000 1.0000
4.5720 6.1667 1.0000
4.5780 4.5000 1.0000
4.5840 3.6667 1.0000
4.5900 8.5000 1.0000
4.5960 5.5000 1.0000
4.6020 5.5000 1.0000
4.6080 11.6667 1.0000
4.6140 8.6667 1.0000
4.6200 9.3333 1.0000
4.6260 0.0000 1.0000
4.6320 0.6667 1.0000
4.6380 5.1667 1.0000
4.6440 4.6667 1.0000
4.6500 4.5000 1.0000
4.6560 4.6667 1.0000
4.6620 3.6667 1.0000
4.6680 2.3333 1.0000
4.6740 6.5000 1.0000
4.6800 3.1667 1.0000
4.6860 0.3333 1.0000
4.6920 6.5000 1.0000
4.6980 0.5000 1.0000
4.7040 3.6667 1.0000
4.7100 6.5000 1.0000
4.7160 3.5000 1.0000
4.7220 3.3333 1.0000
4.7280 0.1667 1.0000
4.7340 4.1667 1.0000
4.7400 1.1667 1.0000
4.7460 7.3333 1.0000
4.7520 5.6667 1.0000
4.7580 4.0000 1.0000
4.7640 2.5000 1.0000
4.7700 2.0000 1.0000
4.7760 2.1667 1.0000
4.7820 3.8333 1.0000
4.7880 0.1667 1.0000
4.7940 3.3333 1.0000
4.8000 1.6667 1.0000
4.8060 2.3333 1.0000
4.8120 8.3333 1.0000
4.8180 5.1667 1.0000
4.8240 5.5000 1.0000
4.8300 4.1667 1.0000
4.8360 4.3333 1.0000
4.8420 0.3333 1.0000
4.8480 4.3333 1.0000
4.8540 3.0000 1.0000
4.8600 3.5000 1.0000
4.8660 7.6667 1.0000
4.8720 1.5000 1.0000
4.8780 7.5000 1.0000
4.8840 4.1667 1.0000
4.8900 1.3333 1.0000
4.8960 0.3333 1.0000
4.9020 2.3333 1.0000
4.9080 0.3333 1.0000
4.9140 4.0000 1.0000
4.9200 4.3333 1.0000
4.9260 1.1667 1.0000
4.9320 2.1667 1.0000
4.9380 3.6667 1.0000
4.9440 3.1667 1.0000
4.9500 2.5000 1.0000
4.9560 5.3333 1.0000
4.9620 0.0000 1.0000
4.9680 4.1667 1.0000
4.9740 0.0000 1.0000
4.9800 4.1667 1.0000
4.9860 3.3333 1.0000
4.9920 3.0000 1.0000
4.9980 0.0000 1.0000
5.0040 6.3333 1.0000
5.0100 2.5000 1.0000
5.0160 2.0000 1.0000
5.0220 0.0000 1.0000
5.0280 0.1667 1.0000
5.0340 3.0000 1.0000
5.0400 2.1667 1.0000
5.0460 1.3333 1.0000
5.0520 2.1667 1.0000
5.0580 5.5000 1.0000
5.0640 3.5000 1.0000
5.0700 4.3333 1.0000
5.0760 0.0000 1.0000
5.0820 3.0000 1.0000
5.0880 3.1667 1.0000
5.0940 4.1667 1.0000
5.1000 3.3333 1.0000
5.1060 0.0000 1.0000
5.1120 0.3333 1.0000
5.1180 0.0000 1.0000
5.1240 3.5000 1.0000
5.1300 3.0000 1.0000
5.1360 0.1667 1.0000
5.1420 3.0000 1.0000
5.1480 0.1667 1.0000
5.1540 2.3333 1.0000
5.1600 2.0000 1.0000
5.1660 1.3333 1.0000
5.1720 2.0000 1.0000
5.1780 0.3333 1.0000
5.1840 1.1667 1.0000
5.1900 0.0000 1.0000
5.1960 0.1667 1.0000
5.2020 1.1667 1.0000
5.2080 0.0000 1.0000
5.2140 2.1667 1.0000
5.2200 0.0000 1.0000
5.2260 0.5000 1.0000
5.2320 0.0000 1.0000
5.2380 0.0000 1.0000
5.2440 2.1667 1.0000
5.2500 0.0000 1.0000
5.2560 0.0000 1.0000
5.2620 3.0000 1.0000
5.2680 3.0000 1.0000
5.2740 0.0000 1.0000
5.2800 0.0000 1.0000
5.2860 0.1667 1.0000
5.2920 0.0000 1.0000
5.2980 0.0000 1.0000
5.3040 0.0000 1.0000
5.3100 0.0000 1.0000
5.3160 0.1667 1.0000
5.3220 0.0000 1.0000
5.3280 0.0000 1.0000
5.3340 2.3333 1.0000
5.3400 1.1667 1.0000
5.3460 0.0000 1.0000
5.3520 0.0000 1.0000
5.3580 0.0000 1.0000
5.3640 2.1667 1.0000
5.3700 0.0000 1.0000
5.3760 0.1667 1.0000
5.3820 0.0000 1.0000
5.3880 3.0000 1.0000
5.3940 0.0000 1.0000
5.4000 6.1667 1.0000
5.4060 3.0000 1.0000
5.4120 0.0000 1.0000
5.4180 0.0000 1.0000
5.4240 0.0000 1.0000
5.4300 1.3333 1.0000
5.4360 3.0000 1.0000
5.4420 2.0000 1.0000
5.4480 0.0000 1.0000
5.4540 0.1667 1.0000
5.4600 1.1667 1.0000
5.4660 0.0000 1.0000
5.4720 3.0000 1.0000
5.4780 0.0000 1.0000
5.4840 1.1667 1.0000
5.4900 0.0000 1.0000
5.4960 0.0000 1.0000
5.5020 1.1667 1.0000
5.5080 0.0000 1.0000
5.5140 0.0000 1.0000
5.5200 1.1667 1.0000
5.5260 2.1667 1.0000
5.5320 0.0000 1.0000
5.5380 3.1667 1.0000
5.5440 2.0000 1.0000
5.5500 2.3333 1.0000
5.5560 0.0000 1.0000
5.5620 0.0000 1.0000
5.5680 0.0000 1.0000
5.5740 0.1667 1.0000
5.5800 0.0000 1.0000
5.5860 0.0000 1.0000
5.5920 2.0000 1.0000
5.5980 2.0000 1.0000
5.6040 0.0000 1.0000
5.6100 0.0000 1.0000
5.6160 0.0000 1.0000
5.6220 0.0000 1.0000
5.6280 0.0000 1.0000
5.6340 2.0000 1.0000
5.6400 0.0000 1.0000
5.6460 0.0000 1.0000
5.6520 0.0000 1.0000
5.6580 0.0000 1.0000
5.6640 0.0000 1.0000
5.6700 0.1667 1.0000
5.6760 0.0000 1.0000
5.6820 0.0000 1.0000
5.6880 0.0000 1.0000
5.6940 0.0000 1.0000
5.7000 0.0000 1.0000
5.7060 2.5000 1.0000
5.7120 0.0000 1.0000
5.7180 2.0000 1.0000
5.7240 0.0000 1.0000
5.7300 1.3333 1.0000
5.7360 0.0000 1.0000
5.7420 0.0000 1.0000
5.7480 0.0000 1.0000
5.7540 0.0000 1.0000
5.7600 1.1667 1.0000
5.7660 0.0000 1.0000
5.7720 2.1667 1.0000
5.7780 0.0000 1.0000
5.7840 0.0000 1.0000
5.7900 0.0000 1.0000
5.7960 0.0000 1.0000
5.8020 0.1667 1.0000
5.8080 0.0000 1.0000
5.8140 0.0000 1.0000
5.8200 0.0000 1.0000
5.8260 0.0000 1.0000
5.8320 0.0000 1.0000
5.8380 0.0000 1.0000
5.8440 0.0000 1.0000
5.8500 0.0000 1.0000
5.8560 1.1667 1.0000
5.8620 0.0000 1.0000
5.8680 0.0000 1.0000
5.8740 0.0000 1.0000
5.8800 0.0000 1.0000
5.8860 0.0000 1.0000
5.8920 0.0000 1.0000
5.8980 0.3333 1.0000
5.9040 0.1667 1.0000
5.9100 1.1667 1.0000
5.9160 0.0000 1.0000
5.9220 0.0000 1.0000
5.9280 0.0000 1.0000
5.9340 0.0000 1.0000
5.9400 0.0000 1.0000
5.9460 0.0000 1.0000
5.9520 0.0000 1.0000
5.9580 0.0000 1.0000
5.9640 0.1667 1.0000
5.9700 2.0000 1.0000
5.9760 1.3333 1.0000
5.9820 0.0000 1.0000
5.9880 0.0000 1.0000
5.9940 0.0000 1.0000
6.0000 0.0000 1.0000
*RAS_INT_END
*RAS_DATA_END