File: XRR/CWOI4anneal3hrs_reflectivity.ras
*RAS_DATA_START
*RAS_HEADER_START
*DISP_FMT_X "%.4f"
*DISP_FMT_Y "%.0f"
*DISP_FULLSCALE "33790277.5000000000"
*DISP_LINE_COLOR "255.0000000000"
*DISP_LINE_STYLE "0.0000000000"
*DISP_LINE_WIDTH "0.2500000000"
*DISP_NOTE "Collected Data-4"
*DISP_OFFSET_Y "0.0000000000"
*DISP_PEAKSEARCH_UNIT_Y "cps"
*DISP_RANGE_BOTTOM "0.0100000000"
*DISP_RANGE_LEFT "-0.0006000000"
*DISP_RANGE_LOGCUTOFF "0.0100000000"
*DISP_RANGE_RIGHT "6.0006000000"
*DISP_RANGE_TOP "33790277.5000000000"
*DISP_SCALE_MODE_Y "2.0000000000"
*DISP_TAB_NAME "2-Theta/Omega"
*DISP_TITLE_Y "Intensity"
*DISP_UNIT_Y "cps"
*DISP_WINDOW_NAME "MSG_MACROENGINE"
*FILE_COMMENT " "
*FILE_MD5 ""
*FILE_MEMO " "
*FILE_OPERATOR "Administrator"
*FILE_PART_ID "MEAS_KHP2_00055"
*FILE_SAMPLE "CWOI4-2"
*FILE_TYPE "RAS_RAW"
*FILE_USERGROUP "System Manager"
*FILE_VERSION "1.0000000000"
*HW_ATTACHMENT_ID "ATT0025"
*HW_ATTACHMENT_NAME "標準|Standard"
*HW_COUNTER_ID-0 "CUT0025"
*HW_COUNTER_ID-1 "CUT0020"
*HW_COUNTER_ID-2 "CUT0020"
*HW_COUNTER_ID-3 "CSL0021"
*HW_COUNTER_ID-4 "CMC0021"
*HW_COUNTER_NAME-0 "D/teX Ultra|D/teX Ultra"
*HW_COUNTER_NAME-1 "None|None"
*HW_COUNTER_NAME-2 "None|None"
*HW_COUNTER_NAME-3 "BBM|BBM"
*HW_COUNTER_NAME-4 "検出器モノクロメータ|Detector monochromator"
*HW_COUNTER_SELECT_NAME "D/teX Ultra|D/teX Ultra"
*HW_GONIOMETER_ID "GON0023"
*HW_GONIOMETER_NAME "SmartLab|SmartLab"
*HW_GONIOMETER_RADIUS-0 "90.0"
*HW_GONIOMETER_RADIUS-1 "114.0"
*HW_GONIOMETER_RADIUS-2 "190.0"
*HW_GONIOMETER_RADIUS-3 "300.0"
*HW_GONIOMETER_RADIUS-4 "187.0"
*HW_GONIOMETER_RADIUS-5 "300.0"
*HW_GONIOMETER_RADIUS-6 "113.0"
*HW_GONIOMETER_RADIUS-7 "331.0"
*HW_I_OPT_ID-0 "CBO0021"
*HW_I_OPT_ID-1 "ICR0021"
*HW_I_OPT_ID-2 "ISL0021"
*HW_I_OPT_ID-3 "ISO0021"
*HW_I_OPT_ID-4 "IAD0021"
*HW_I_OPT_ID-5 "IPR0001"
*HW_I_OPT_NAME-0 "CBOユニット|CBO unit"
*HW_I_OPT_NAME-1 "標準入射光学ユニット|Standard incident optical unit"
*HW_I_OPT_NAME-2 "標準入射スリットボックス|Standard incident slit box"
*HW_I_OPT_NAME-3 "入射平行スリット|Incident parallel slit"
*HW_I_OPT_NAME-4 "長手制限スリット|Length limiting slit"
*HW_I_OPT_NAME-5 "None|None"
*HW_R_ATTENUATER_AUTOMODE "1"
*HW_R_OPT_ID-0 "RSS0021"
*HW_R_OPT_ID-1 "RCR0023"
*HW_R_OPT_ID-2 "RSO0021"
*HW_R_OPT_ID-3 "RRS0021"
*HW_R_OPT_ID-4 "ATN0021"
*HW_R_OPT_ID-5 "RFL0021"
*HW_R_OPT_ID-6 "RAD0021"
*HW_R_OPT_NAME-0 "標準受光スリットボックス1|Standard receiving slit box # 1"
*HW_R_OPT_NAME-1 "標準受光光学ユニット1|Standard receiving unit # 1"
*HW_R_OPT_NAME-2 "標準受光光学ユニット2|Standard receiving optical unit # 2"
*HW_R_OPT_NAME-3 "標準受光スリットボックス2|Standard receiving slit box # 2"
*HW_R_OPT_NAME-4 "標準アッテネータ|Standard Attenuator"
*HW_R_OPT_NAME-5 "Cu Kβ|Cu K-beta"
*HW_R_OPT_NAME-6 "調整用受光スリット|Alignment receiving slit"
*HW_SAMPLE_HOLDER_ID "SMP0021"
*HW_SAMPLE_HOLDER_NAME "χφZクレードル|Chi phi Z cradle"
*HW_XG_CURRENT_MAX "200"
*HW_XG_CURRENT_MIN "10"
*HW_XG_CURRENT_RESOLUTION "1"
*HW_XG_CURRENT_UNIT "mA"
*HW_XG_FOCUS "0.4mm x 8mm"
*HW_XG_FOCUS_TYPE "Normal"
*HW_XG_ID "1700"
*HW_XG_NAME "9kW 開放管(45kV 200mA ID:1700)|9kW Rotating anode(45kV 200mA ID:1700)"
*HW_XG_TARGET_ATOMIC_NUMBER "29.0000000000"
*HW_XG_TARGET_NAME "Cu"
*HW_XG_TYPE "Rota"
*HW_XG_VOLTAGE_MAX "45"
*HW_XG_VOLTAGE_MIN "20"
*HW_XG_VOLTAGE_RESOLUTION "1"
*HW_XG_VOLTAGE_UNIT "kV"
*HW_XG_WATT_MAX "9.00"
*HW_XG_WATT_UNIT "kW"
*HW_XG_WAVE_LENGTH_ALPHA1 "1.540593"
*HW_XG_WAVE_LENGTH_ALPHA2 "1.544414"
*HW_XG_WAVE_LENGTH_BETA "1.392250"
*MEAS_COND_AXIS_NAME-0 "Theta/2-Theta"
*MEAS_COND_AXIS_NAME-1 "2-Theta"
*MEAS_COND_AXIS_NAME-2 "Omega"
*MEAS_COND_AXIS_NAME-3 "Chi"
*MEAS_COND_AXIS_NAME-4 "Phi"
*MEAS_COND_AXIS_NAME-5 "Z"
*MEAS_COND_AXIS_NAME-6 "2-Theta/Omega"
*MEAS_COND_AXIS_NAME-7 "Theta_s"
*MEAS_COND_AXIS_NAME-8 "Theta_d"
*MEAS_COND_AXIS_NAME-9 "Ts"
*MEAS_COND_AXIS_NAME-10 "CBO selection slit"
*MEAS_COND_AXIS_NAME-11 "M"
*MEAS_COND_AXIS_NAME-12 "Incident parallel slit"
*MEAS_COND_AXIS_NAME-13 "Incident slit"
*MEAS_COND_AXIS_NAME-14 ""
*MEAS_COND_AXIS_NAME-15 "Zs"
*MEAS_COND_AXIS_NAME-16 "Incident optical device"
*MEAS_COND_AXIS_NAME-17 "Omega_m"
*MEAS_COND_AXIS_NAME-18 "Length limiting slit"
*MEAS_COND_AXIS_NAME-19 "Center slit"
*MEAS_COND_AXIS_NAME-20 "Filter"
*MEAS_COND_AXIS_NAME-21 "Receiving slit # 1"
*MEAS_COND_AXIS_NAME-22 "Receiving slit # 2"
*MEAS_COND_AXIS_NAME-23 "Receiving optical device"
*MEAS_COND_AXIS_NAME-24 "Receiving parallel slit"
*MEAS_COND_AXIS_NAME-25 "Alignment receiving slit"
*MEAS_COND_AXIS_NAME-26 ""
*MEAS_COND_AXIS_NAME-27 ""
*MEAS_COND_AXIS_NAME-28 "Zd"
*MEAS_COND_AXIS_NAME-29 "Attenuator"
*MEAS_COND_AXIS_NAME-30 "Diffracted beam monochromator"
*MEAS_COND_AXIS_NAME-31 "Monochromator slit"
*MEAS_COND_AXIS_NAME-32 "Primary beam"
*MEAS_COND_AXIS_NAME-33 ""
*MEAS_COND_AXIS_NAME-34 ""
*MEAS_COND_AXIS_NAME-35 "PHA"
*MEAS_COND_AXIS_NAME_INTERNAL-0 "TwoThetaTheta"
*MEAS_COND_AXIS_NAME_INTERNAL-1 "TwoTheta"
*MEAS_COND_AXIS_NAME_INTERNAL-2 "Omega"
*MEAS_COND_AXIS_NAME_INTERNAL-3 "Chi"
*MEAS_COND_AXIS_NAME_INTERNAL-4 "Phi"
*MEAS_COND_AXIS_NAME_INTERNAL-5 "Z"
*MEAS_COND_AXIS_NAME_INTERNAL-6 "TwoThetaOmega"
*MEAS_COND_AXIS_NAME_INTERNAL-7 "ThetaS"
*MEAS_COND_AXIS_NAME_INTERNAL-8 "ThetaD"
*MEAS_COND_AXIS_NAME_INTERNAL-9 "Ts"
*MEAS_COND_AXIS_NAME_INTERNAL-10 "CBO"
*MEAS_COND_AXIS_NAME_INTERNAL-11 "CBO-M"
*MEAS_COND_AXIS_NAME_INTERNAL-12 "IncidentSollerSlit"
*MEAS_COND_AXIS_NAME_INTERNAL-13 "IncidentSlitBox"
*MEAS_COND_AXIS_NAME_INTERNAL-14 "IncidentSlitBox-_Axis"
*MEAS_COND_AXIS_NAME_INTERNAL-15 "Zs"
*MEAS_COND_AXIS_NAME_INTERNAL-16 "IncidentMonochromator"
*MEAS_COND_AXIS_NAME_INTERNAL-17 "IncidentMonochromator-OmegaM"
*MEAS_COND_AXIS_NAME_INTERNAL-18 "IncidentAxdSlit"
*MEAS_COND_AXIS_NAME_INTERNAL-19 "CenterSlit"
*MEAS_COND_AXIS_NAME_INTERNAL-20 "Filter"
*MEAS_COND_AXIS_NAME_INTERNAL-21 "ReceivingSlitBox1"
*MEAS_COND_AXIS_NAME_INTERNAL-22 "ReceivingSlitBox2"
*MEAS_COND_AXIS_NAME_INTERNAL-23 "ReceivingOptics"
*MEAS_COND_AXIS_NAME_INTERNAL-24 "ReceivingSollerSlit"
*MEAS_COND_AXIS_NAME_INTERNAL-25 "ReceivingAxdSlit"
*MEAS_COND_AXIS_NAME_INTERNAL-26 "ReceivingSlitBox1-_Axis"
*MEAS_COND_AXIS_NAME_INTERNAL-27 "ReceivingSlitBox2-_Axis"
*MEAS_COND_AXIS_NAME_INTERNAL-28 "ReceivingSlitBox2-Zd"
*MEAS_COND_AXIS_NAME_INTERNAL-29 "Attenuator"
*MEAS_COND_AXIS_NAME_INTERNAL-30 "CounterMonochromator"
*MEAS_COND_AXIS_NAME_INTERNAL-31 "CounterSlit"
*MEAS_COND_AXIS_NAME_INTERNAL-32 "IncidentPrimary"
*MEAS_COND_AXIS_NAME_INTERNAL-33 "AlphaR"
*MEAS_COND_AXIS_NAME_INTERNAL-34 "BetaR"
*MEAS_COND_AXIS_NAME_INTERNAL-35 "PHA"
*MEAS_COND_AXIS_NAME_MAGICNO-0 "83951616.0000000000"
*MEAS_COND_AXIS_NAME_MAGICNO-1 "268632064.0000000000"
*MEAS_COND_AXIS_NAME_MAGICNO-2 "268500992.0000000000"
*MEAS_COND_AXIS_NAME_MAGICNO-3 "268500992.0000000000"
*MEAS_COND_AXIS_NAME_MAGICNO-4 "268500992.0000000000"
*MEAS_COND_AXIS_NAME_MAGICNO-5 "285278208.0000000000"
*MEAS_COND_AXIS_NAME_MAGICNO-6 "83951616.0000000000"
*MEAS_COND_AXIS_NAME_MAGICNO-7 "131072.0000000000"
*MEAS_COND_AXIS_NAME_MAGICNO-8 "131072.0000000000"
*MEAS_COND_AXIS_NAME_MAGICNO-9 "318898176.0000000000"
*MEAS_COND_AXIS_NAME_MAGICNO-10 "20971521.0000000000"
*MEAS_COND_AXIS_NAME_MAGICNO-11 "285343744.0000000000"
*MEAS_COND_AXIS_NAME_MAGICNO-12 "20971521.0000000000"
*MEAS_COND_AXIS_NAME_MAGICNO-13 "22020097.0000000000"
*MEAS_COND_AXIS_NAME_MAGICNO-14 "25165824.0000000000"
*MEAS_COND_AXIS_NAME_MAGICNO-15 "318898176.0000000000"
*MEAS_COND_AXIS_NAME_MAGICNO-16 "20971521.0000000000"
*MEAS_COND_AXIS_NAME_MAGICNO-17 "285343744.0000000000"
*MEAS_COND_AXIS_NAME_MAGICNO-18 "20971521.0000000000"
*MEAS_COND_AXIS_NAME_MAGICNO-19 "20971521.0000000000"
*MEAS_COND_AXIS_NAME_MAGICNO-20 "20971521.0000000000"
*MEAS_COND_AXIS_NAME_MAGICNO-21 "23068673.0000000000"
*MEAS_COND_AXIS_NAME_MAGICNO-22 "23068673.0000000000"
*MEAS_COND_AXIS_NAME_MAGICNO-23 "20971521.0000000000"
*MEAS_COND_AXIS_NAME_MAGICNO-24 "20971521.0000000000"
*MEAS_COND_AXIS_NAME_MAGICNO-25 "20971521.0000000000"
*MEAS_COND_AXIS_NAME_MAGICNO-26 "25165824.0000000000"
*MEAS_COND_AXIS_NAME_MAGICNO-27 "25165824.0000000000"
*MEAS_COND_AXIS_NAME_MAGICNO-28 "285343744.0000000000"
*MEAS_COND_AXIS_NAME_MAGICNO-29 "17301505.0000000000"
*MEAS_COND_AXIS_NAME_MAGICNO-30 "20971521.0000000000"
*MEAS_COND_AXIS_NAME_MAGICNO-31 "20971521.0000000000"
*MEAS_COND_AXIS_NAME_MAGICNO-32 "20971521.0000000000"
*MEAS_COND_AXIS_NAME_MAGICNO-33 "8388608.0000000000"
*MEAS_COND_AXIS_NAME_MAGICNO-34 "8388608.0000000000"
*MEAS_COND_AXIS_NAME_MAGICNO-35 "0.0000000000"
*MEAS_COND_AXIS_OFFSET-0 "-"
*MEAS_COND_AXIS_OFFSET-1 "0.8860000000"
*MEAS_COND_AXIS_OFFSET-2 "0.6608000000"
*MEAS_COND_AXIS_OFFSET-3 "0.0000000000"
*MEAS_COND_AXIS_OFFSET-4 "0.0000000000"
*MEAS_COND_AXIS_OFFSET-5 "-"
*MEAS_COND_AXIS_OFFSET-6 "-"
*MEAS_COND_AXIS_OFFSET-7 "0.6608000000"
*MEAS_COND_AXIS_OFFSET-8 "0.2252000000"
*MEAS_COND_AXIS_OFFSET-9 "-"
*MEAS_COND_AXIS_OFFSET-10 "-"
*MEAS_COND_AXIS_OFFSET-11 "-"
*MEAS_COND_AXIS_OFFSET-12 "-"
*MEAS_COND_AXIS_OFFSET-13 "-"
*MEAS_COND_AXIS_OFFSET-14 "-"
*MEAS_COND_AXIS_OFFSET-15 "-"
*MEAS_COND_AXIS_OFFSET-16 "-"
*MEAS_COND_AXIS_OFFSET-17 "-"
*MEAS_COND_AXIS_OFFSET-18 "-"
*MEAS_COND_AXIS_OFFSET-19 "-"
*MEAS_COND_AXIS_OFFSET-20 "-"
*MEAS_COND_AXIS_OFFSET-21 "-"
*MEAS_COND_AXIS_OFFSET-22 "-"
*MEAS_COND_AXIS_OFFSET-23 "-"
*MEAS_COND_AXIS_OFFSET-24 "-"
*MEAS_COND_AXIS_OFFSET-25 "-"
*MEAS_COND_AXIS_OFFSET-26 "-"
*MEAS_COND_AXIS_OFFSET-27 "-"
*MEAS_COND_AXIS_OFFSET-28 "-"
*MEAS_COND_AXIS_OFFSET-29 "-"
*MEAS_COND_AXIS_OFFSET-30 "-"
*MEAS_COND_AXIS_OFFSET-31 "-"
*MEAS_COND_AXIS_OFFSET-32 "-"
*MEAS_COND_AXIS_OFFSET-33 "0.0000000000"
*MEAS_COND_AXIS_OFFSET-34 "0.0000000000"
*MEAS_COND_AXIS_OFFSET-35 "-"
*MEAS_COND_AXIS_POSITION-0 "-0.0008000000"
*MEAS_COND_AXIS_POSITION-1 "-0.0008000000"
*MEAS_COND_AXIS_POSITION-2 "-0.0004000000"
*MEAS_COND_AXIS_POSITION-3 "0.0000000000"
*MEAS_COND_AXIS_POSITION-4 "0.0000000000"
*MEAS_COND_AXIS_POSITION-5 "-1.4158000000"
*MEAS_COND_AXIS_POSITION-6 "-0.0008000000"
*MEAS_COND_AXIS_POSITION-7 "-0.0004000000"
*MEAS_COND_AXIS_POSITION-8 "-0.0004000000"
*MEAS_COND_AXIS_POSITION-9 "-4.7308800000"
*MEAS_COND_AXIS_POSITION-10 "PB"
*MEAS_COND_AXIS_POSITION-11 "0.0000000000"
*MEAS_COND_AXIS_POSITION-12 "Soller_slit_open_s"
*MEAS_COND_AXIS_POSITION-13 "0.250mm"
*MEAS_COND_AXIS_POSITION-14 "0.2500000000"
*MEAS_COND_AXIS_POSITION-15 "-1.7590600000"
*MEAS_COND_AXIS_POSITION-16 "Ge(220)x2"
*MEAS_COND_AXIS_POSITION-17 "0.0000000000"
*MEAS_COND_AXIS_POSITION-18 "2.0mm"
*MEAS_COND_AXIS_POSITION-19 "None"
*MEAS_COND_AXIS_POSITION-20 "None"
*MEAS_COND_AXIS_POSITION-21 "0.250mm"
*MEAS_COND_AXIS_POSITION-22 "0.250mm"
*MEAS_COND_AXIS_POSITION-23 "No_unit"
*MEAS_COND_AXIS_POSITION-24 "Soller_slit_5.0deg"
*MEAS_COND_AXIS_POSITION-25 "None"
*MEAS_COND_AXIS_POSITION-26 "0.2500000000"
*MEAS_COND_AXIS_POSITION-27 "0.2500000000"
*MEAS_COND_AXIS_POSITION-28 "0.0865600000"
*MEAS_COND_AXIS_POSITION-29 "1/10000"
*MEAS_COND_AXIS_POSITION-30 "None"
*MEAS_COND_AXIS_POSITION-31 "None"
*MEAS_COND_AXIS_POSITION-32 "None"
*MEAS_COND_AXIS_POSITION-33 "0.0000000000"
*MEAS_COND_AXIS_POSITION-34 "0.0000000000"
*MEAS_COND_AXIS_POSITION-35 "34.0000000000"
*MEAS_COND_AXIS_UNIT-0 "deg"
*MEAS_COND_AXIS_UNIT-1 "deg"
*MEAS_COND_AXIS_UNIT-2 "deg"
*MEAS_COND_AXIS_UNIT-3 "deg"
*MEAS_COND_AXIS_UNIT-4 "deg"
*MEAS_COND_AXIS_UNIT-5 "mm"
*MEAS_COND_AXIS_UNIT-6 "deg"
*MEAS_COND_AXIS_UNIT-7 "deg"
*MEAS_COND_AXIS_UNIT-8 "deg"
*MEAS_COND_AXIS_UNIT-9 "mm"
*MEAS_COND_AXIS_UNIT-10 ""
*MEAS_COND_AXIS_UNIT-11 "pulse"
*MEAS_COND_AXIS_UNIT-12 ""
*MEAS_COND_AXIS_UNIT-13 ""
*MEAS_COND_AXIS_UNIT-14 "mm"
*MEAS_COND_AXIS_UNIT-15 "mm"
*MEAS_COND_AXIS_UNIT-16 ""
*MEAS_COND_AXIS_UNIT-17 "pulse"
*MEAS_COND_AXIS_UNIT-18 ""
*MEAS_COND_AXIS_UNIT-19 ""
*MEAS_COND_AXIS_UNIT-20 ""
*MEAS_COND_AXIS_UNIT-21 ""
*MEAS_COND_AXIS_UNIT-22 ""
*MEAS_COND_AXIS_UNIT-23 ""
*MEAS_COND_AXIS_UNIT-24 ""
*MEAS_COND_AXIS_UNIT-25 ""
*MEAS_COND_AXIS_UNIT-26 "mm"
*MEAS_COND_AXIS_UNIT-27 "mm"
*MEAS_COND_AXIS_UNIT-28 "mm"
*MEAS_COND_AXIS_UNIT-29 ""
*MEAS_COND_AXIS_UNIT-30 ""
*MEAS_COND_AXIS_UNIT-31 ""
*MEAS_COND_AXIS_UNIT-32 ""
*MEAS_COND_AXIS_UNIT-33 "deg"
*MEAS_COND_AXIS_UNIT-34 "deg"
*MEAS_COND_AXIS_UNIT-35 "div"
*MEAS_COND_COUNTER_CNTLOSS_CORR "0.0000000000"
*MEAS_COND_COUNTER_PHABASE "34.0000000000"
*MEAS_COND_COUNTER_PHAWINDOW "19.0000000000"
*MEAS_COND_COUNTER_PHA_UNIT "div"
*MEAS_COND_COUNTER_TAUDIFF "2.0000000000"
*MEAS_COND_COUNTER_TAUINT "0.1000000000"
*MEAS_COND_IRRADIATION_MODE "OFF"
*MEAS_COND_IRRADIATION_WIDTH ""
*MEAS_COND_OPT_ATTR "High resolution parallel beam Ge(220)x2/RS"
*MEAS_COND_OPT_NAME "@High resolution PB-Ge(220)x2"
*MEAS_COND_UNSYMMETRIC_MODE "OFF"
*MEAS_COND_XG_CURRENT "200.0000000000"
*MEAS_COND_XG_VOLTAGE "45.0000000000"
*MEAS_COND_XG_WAVE_TYPE "Ka1"
*MEAS_DATA_COUNT "3001.0000000000"
*MEAS_SCAN_AXIS_X "2-Theta/Omega"
*MEAS_SCAN_AXIS_X_INTERNAL "TwoThetaOmega"
*MEAS_SCAN_END_TIME "11/12/23 14:30:40"
*MEAS_SCAN_MODE "CONTINUOUS"
*MEAS_SCAN_MONITOR "0"
*MEAS_SCAN_RESOLUTION_X "0.0002"
*MEAS_SCAN_SPEED "0.500000"
*MEAS_SCAN_SPEED_UNIT "deg/min"
*MEAS_SCAN_SPEED_USER "0.500000"
*MEAS_SCAN_START "0.0000000000"
*MEAS_SCAN_START_TIME "11/12/23 14:17:50"
*MEAS_SCAN_STEP "0.0020000000"
*MEAS_SCAN_STOP "6.0000000000"
*MEAS_SCAN_UNIT_X "deg"
*MEAS_SCAN_UNIT_Y "counts"
*RAS_HEADER_END
*RAS_INT_START
0.0000 6452564.0000 1.0000
0.0060 6428290.0000 1.0000
0.0120 6345400.5000 1.0000
0.0180 5902265.0000 1.0000
0.0240 5723797.0000 1.0000
0.0300 5135156.5000 1.0000
0.0360 4568031.5000 1.0000
0.0420 3578597.2500 1.0000
0.0480 2635779.5000 1.0000
0.0540 1823985.3750 1.0000
0.0600 1081464.6250 1.0000
0.0660 552925.9375 1.0000
0.0720 257616.5156 1.0000
0.0780 139823.4375 1.0000
0.0840 82915.4297 1.0000
0.0900 59065.6680 1.0000
0.0960 50916.6680 1.0000
0.1020 47359.3320 1.0000
0.1080 47526.0000 1.0000
0.1140 49926.5000 1.0000
0.1200 52062.8320 1.0000
0.1260 54542.0000 1.0000
0.1320 56600.5000 1.0000
0.1380 59191.6680 1.0000
0.1440 61815.6680 1.0000
0.1500 64286.5000 1.0000
0.1560 66873.8359 1.0000
0.1620 69621.8359 1.0000
0.1680 72513.6641 1.0000
0.1740 75156.3359 1.0000
0.1800 77209.8359 1.0000
0.1860 80249.0000 1.0000
0.1920 82741.5000 1.0000
0.1980 85262.5000 1.0000
0.2040 87913.0000 1.0000
0.2100 90995.8359 1.0000
0.2160 92802.1641 1.0000
0.2220 90343.9063 1.0000
0.2280 94101.8984 1.0000
0.2340 91666.5000 1.0000
0.2400 101691.1250 1.0000
0.2460 103135.9766 1.0000
0.2520 102547.6094 1.0000
0.2580 106867.2891 1.0000
0.2640 113816.0000 1.0000
0.2700 114396.9297 1.0000
0.2760 115409.8203 1.0000
0.2820 112415.8359 1.0000
0.2880 117845.2188 1.0000
0.2940 124883.3125 1.0000
0.3000 123080.9688 1.0000
0.3060 125583.3984 1.0000
0.3120 131087.2656 1.0000
0.3180 132375.7188 1.0000
0.3240 135846.3438 1.0000
0.3300 135250.5313 1.0000
0.3360 137596.5625 1.0000
0.3420 142504.6094 1.0000
0.3480 145267.7188 1.0000
0.3540 146064.6250 1.0000
0.3600 148231.9063 1.0000
0.3660 153787.9063 1.0000
0.3720 151784.4688 1.0000
0.3780 151397.1875 1.0000
0.3840 152164.2969 1.0000
0.3900 160617.4531 1.0000
0.3960 164371.1094 1.0000
0.4020 157876.7031 1.0000
0.4080 166143.6719 1.0000
0.4140 165838.3125 1.0000
0.4200 169517.4844 1.0000
0.4260 168407.7656 1.0000
0.4320 173770.1250 1.0000
0.4380 172854.0625 1.0000
0.4440 175572.4688 1.0000
0.4500 173755.2344 1.0000
0.4560 183005.2969 1.0000
0.4620 182186.0469 1.0000
0.4680 179750.6406 1.0000
0.4740 181970.0625 1.0000
0.4800 185120.4531 1.0000
0.4860 184599.1094 1.0000
0.4920 179758.0938 1.0000
0.4980 192985.2344 1.0000
0.5040 188851.7500 1.0000
0.5100 187950.5781 1.0000
0.5160 193610.8438 1.0000
0.5220 195398.2969 1.0000
0.5280 187593.0938 1.0000
0.5340 194147.0781 1.0000
0.5400 189849.7500 1.0000
0.5460 194497.1250 1.0000
0.5520 190497.7031 1.0000
0.5580 190326.4063 1.0000
0.5640 193968.3281 1.0000
0.5700 182610.5625 1.0000
0.5760 189849.7500 1.0000
0.5820 190192.3438 1.0000
0.5880 186639.7813 1.0000
0.5940 184666.1406 1.0000
0.6000 182543.5313 1.0000
0.6060 174090.3750 1.0000
0.6120 174306.3594 1.0000
0.6180 169204.6719 1.0000
0.6240 160386.5781 1.0000
0.6300 155374.2656 1.0000
0.6360 149423.5313 1.0000
0.6420 133820.5781 1.0000
0.6480 127028.2500 1.0000
0.6540 115469.3984 1.0000
0.6600 104953.2266 1.0000
0.6660 92329.3438 1.0000
0.6720 84226.2266 1.0000
0.6780 71751.3047 1.0000
0.6840 62717.2227 1.0000
0.6900 53518.8320 1.0000
0.6960 46202.8320 1.0000
0.7020 39230.8320 1.0000
0.7080 34178.1680 1.0000
0.7140 29193.1660 1.0000
0.7200 25388.1660 1.0000
0.7260 21873.5000 1.0000
0.7320 19103.1660 1.0000
0.7380 17097.3340 1.0000
0.7440 14902.6670 1.0000
0.7500 13336.3330 1.0000
0.7560 11911.5000 1.0000
0.7620 10639.3330 1.0000
0.7680 9568.6670 1.0000
0.7740 8783.5000 1.0000
0.7800 7954.5000 1.0000
0.7860 7409.6665 1.0000
0.7920 6727.6665 1.0000
0.7980 6058.0000 1.0000
0.8040 5675.8335 1.0000
0.8100 5316.0000 1.0000
0.8160 4954.1665 1.0000
0.8220 4575.1665 1.0000
0.8280 4161.6665 1.0000
0.8340 3937.8333 1.0000
0.8400 3610.5000 1.0000
0.8460 3444.3333 1.0000
0.8520 3181.6667 1.0000
0.8580 2951.1667 1.0000
0.8640 2759.3333 1.0000
0.8700 2735.1667 1.0000
0.8760 2377.0000 1.0000
0.8820 2314.8333 1.0000
0.8880 2168.8333 1.0000
0.8940 2120.5000 1.0000
0.9000 1893.0000 1.0000
0.9060 1789.1666 1.0000
0.9120 1708.6666 1.0000
0.9180 1534.1666 1.0000
0.9240 1463.3334 1.0000
0.9300 1437.0000 1.0000
0.9360 1364.6666 1.0000
0.9420 1285.3334 1.0000
0.9480 1206.0000 1.0000
0.9540 1140.1666 1.0000
0.9600 1064.3334 1.0000
0.9660 1036.0000 1.0000
0.9720 986.8333 1.0000
0.9780 962.3333 1.0000
0.9840 914.8333 1.0000
0.9900 824.0000 1.0000
0.9960 808.6667 1.0000
1.0020 790.0000 1.0000
1.0080 665.0000 1.0000
1.0140 718.8333 1.0000
1.0200 702.1667 1.0000
1.0260 610.8333 1.0000
1.0320 583.5000 1.0000
1.0380 604.1667 1.0000
1.0440 616.8333 1.0000
1.0500 544.0000 1.0000
1.0560 524.8333 1.0000
1.0620 534.1667 1.0000
1.0680 511.8333 1.0000
1.0740 473.0000 1.0000
1.0800 511.5000 1.0000
1.0860 455.8333 1.0000
1.0920 456.5000 1.0000
1.0980 429.0000 1.0000
1.1040 412.1667 1.0000
1.1100 395.3333 1.0000
1.1160 392.6667 1.0000
1.1220 350.1667 1.0000
1.1280 362.5000 1.0000
1.1340 357.0000 1.0000
1.1400 333.8333 1.0000
1.1460 333.6667 1.0000
1.1520 334.6667 1.0000
1.1580 352.8333 1.0000
1.1640 274.1667 1.0000
1.1700 285.3333 1.0000
1.1760 310.8333 1.0000
1.1820 276.1667 1.0000
1.1880 262.6667 1.0000
1.1940 257.5000 1.0000
1.2000 225.1667 1.0000
1.2060 240.3333 1.0000
1.2120 247.6667 1.0000
1.2180 237.8333 1.0000
1.2240 213.5000 1.0000
1.2300 227.3333 1.0000
1.2360 216.3333 1.0000
1.2420 211.5000 1.0000
1.2480 200.1667 1.0000
1.2540 157.1667 1.0000
1.2600 185.8333 1.0000
1.2660 182.8333 1.0000
1.2720 171.5000 1.0000
1.2780 170.3333 1.0000
1.2840 167.8333 1.0000
1.2900 140.0000 1.0000
1.2960 139.5000 1.0000
1.3020 152.8333 1.0000
1.3080 168.5000 1.0000
1.3140 156.5000 1.0000
1.3200 163.6667 1.0000
1.3260 120.3333 1.0000
1.3320 139.1667 1.0000
1.3380 115.6667 1.0000
1.3440 118.0000 1.0000
1.3500 120.8333 1.0000
1.3560 131.0000 1.0000
1.3620 120.5000 1.0000
1.3680 110.1667 1.0000
1.3740 130.3333 1.0000
1.3800 108.1667 1.0000
1.3860 97.5000 1.0000
1.3920 95.8333 1.0000
1.3980 98.6667 1.0000
1.4040 122.8333 1.0000
1.4100 98.6667 1.0000
1.4160 103.1667 1.0000
1.4220 79.5000 1.0000
1.4280 96.6667 1.0000
1.4340 101.3333 1.0000
1.4400 92.3333 1.0000
1.4460 83.0000 1.0000
1.4520 85.0000 1.0000
1.4580 96.8333 1.0000
1.4640 81.0000 1.0000
1.4700 70.3333 1.0000
1.4760 64.6667 1.0000
1.4820 62.1667 1.0000
1.4880 78.6667 1.0000
1.4940 86.5000 1.0000
1.5000 68.3333 1.0000
1.5060 81.5000 1.0000
1.5120 67.0000 1.0000
1.5180 76.3333 1.0000
1.5240 73.1667 1.0000
1.5300 57.0000 1.0000
1.5360 62.8333 1.0000
1.5420 68.1667 1.0000
1.5480 47.1667 1.0000
1.5540 57.8333 1.0000
1.5600 46.8333 1.0000
1.5660 48.6667 1.0000
1.5720 58.8333 1.0000
1.5780 58.8333 1.0000
1.5840 50.0000 1.0000
1.5900 54.6667 1.0000
1.5960 52.8333 1.0000
1.6020 48.6667 1.0000
1.6080 52.3333 1.0000
1.6140 44.0000 1.0000
1.6200 45.5000 1.0000
1.6260 46.8333 1.0000
1.6320 42.3333 1.0000
1.6380 35.0000 1.0000
1.6440 34.8333 1.0000
1.6500 35.6667 1.0000
1.6560 41.5000 1.0000
1.6620 34.0000 1.0000
1.6680 31.5000 1.0000
1.6740 41.3333 1.0000
1.6800 40.6667 1.0000
1.6860 25.1667 1.0000
1.6920 38.0000 1.0000
1.6980 44.1667 1.0000
1.7040 26.3333 1.0000
1.7100 42.1667 1.0000
1.7160 32.5000 1.0000
1.7220 44.3333 1.0000
1.7280 39.1667 1.0000
1.7340 28.1667 1.0000
1.7400 30.6667 1.0000
1.7460 32.1667 1.0000
1.7520 31.6667 1.0000
1.7580 32.5000 1.0000
1.7640 22.1667 1.0000
1.7700 23.8333 1.0000
1.7760 37.8333 1.0000
1.7820 37.8333 1.0000
1.7880 30.5000 1.0000
1.7940 24.1667 1.0000
1.8000 26.1667 1.0000
1.8060 25.0000 1.0000
1.8120 30.0000 1.0000
1.8180 24.8333 1.0000
1.8240 22.5000 1.0000
1.8300 16.3333 1.0000
1.8360 29.1667 1.0000
1.8420 27.6667 1.0000
1.8480 18.5000 1.0000
1.8540 20.5000 1.0000
1.8600 15.3333 1.0000
1.8660 23.8333 1.0000
1.8720 17.3333 1.0000
1.8780 31.3333 1.0000
1.8840 22.8333 1.0000
1.8900 16.3333 1.0000
1.8960 22.3333 1.0000
1.9020 19.6667 1.0000
1.9080 17.6667 1.0000
1.9140 15.8333 1.0000
1.9200 16.5000 1.0000
1.9260 18.5000 1.0000
1.9320 21.3333 1.0000
1.9380 22.8333 1.0000
1.9440 18.1667 1.0000
1.9500 15.1667 1.0000
1.9560 13.3333 1.0000
1.9620 14.6667 1.0000
1.9680 11.1667 1.0000
1.9740 22.3333 1.0000
1.9800 13.8333 1.0000
1.9860 16.8333 1.0000
1.9920 18.0000 1.0000
1.9980 11.6667 1.0000
2.0040 13.8333 1.0000
2.0100 10.8333 1.0000
2.0160 18.1667 1.0000
2.0220 13.3333 1.0000
2.0280 23.0000 1.0000
2.0340 22.1667 1.0000
2.0400 15.6667 1.0000
2.0460 12.3333 1.0000
2.0520 17.0000 1.0000
2.0580 14.0000 1.0000
2.0640 14.5000 1.0000
2.0700 13.8333 1.0000
2.0760 7.6667 1.0000
2.0820 18.3333 1.0000
2.0880 14.6667 1.0000
2.0940 10.6667 1.0000
2.1000 13.3333 1.0000
2.1060 8.0000 1.0000
2.1120 9.0000 1.0000
2.1180 16.3333 1.0000
2.1240 7.8333 1.0000
2.1300 13.6667 1.0000
2.1360 9.6667 1.0000
2.1420 7.3333 1.0000
2.1480 11.5000 1.0000
2.1540 5.5000 1.0000
2.1600 16.0000 1.0000
2.1660 7.6667 1.0000
2.1720 11.3333 1.0000
2.1780 11.0000 1.0000
2.1840 6.0000 1.0000
2.1900 10.1667 1.0000
2.1960 8.3333 1.0000
2.2020 13.3333 1.0000
2.2080 10.8333 1.0000
2.2140 7.8333 1.0000
2.2200 13.5000 1.0000
2.2260 11.1667 1.0000
2.2320 7.8333 1.0000
2.2380 14.6667 1.0000
2.2440 10.8333 1.0000
2.2500 11.5000 1.0000
2.2560 11.5000 1.0000
2.2620 8.5000 1.0000
2.2680 15.8333 1.0000
2.2740 2.3333 1.0000
2.2800 11.8333 1.0000
2.2860 8.3333 1.0000
2.2920 8.5000 1.0000
2.2980 4.0000 1.0000
2.3040 3.6667 1.0000
2.3100 6.8333 1.0000
2.3160 3.6667 1.0000
2.3220 4.8333 1.0000
2.3280 10.0000 1.0000
2.3340 7.5000 1.0000
2.3400 6.6667 1.0000
2.3460 6.0000 1.0000
2.3520 10.3333 1.0000
2.3580 3.1667 1.0000
2.3640 5.3333 1.0000
2.3700 5.1667 1.0000
2.3760 10.3333 1.0000
2.3820 5.5000 1.0000
2.3880 10.6667 1.0000
2.3940 7.8333 1.0000
2.4000 4.5000 1.0000
2.4060 12.5000 1.0000
2.4120 3.6667 1.0000
2.4180 7.8333 1.0000
2.4240 6.3333 1.0000
2.4300 8.5000 1.0000
2.4360 6.0000 1.0000
2.4420 8.5000 1.0000
2.4480 5.8333 1.0000
2.4540 2.1667 1.0000
2.4600 6.6667 1.0000
2.4660 3.6667 1.0000
2.4720 9.0000 1.0000
2.4780 4.6667 1.0000
2.4840 6.3333 1.0000
2.4900 8.1667 1.0000
2.4960 4.3333 1.0000
2.5020 4.5000 1.0000
2.5080 6.5000 1.0000
2.5140 5.6667 1.0000
2.5200 11.3333 1.0000
2.5260 2.8333 1.0000
2.5320 3.3333 1.0000
2.5380 6.5000 1.0000
2.5440 0.3333 1.0000
2.5500 2.5000 1.0000
2.5560 3.3333 1.0000
2.5620 1.5000 1.0000
2.5680 4.6667 1.0000
2.5740 0.3333 1.0000
2.5800 4.6667 1.0000
2.5860 4.0000 1.0000
2.5920 6.1667 1.0000
2.5980 3.0000 1.0000
2.6040 3.1667 1.0000
2.6100 5.1667 1.0000
2.6160 7.6667 1.0000
2.6220 4.8333 1.0000
2.6280 1.5000 1.0000
2.6340 1.3333 1.0000
2.6400 3.6667 1.0000
2.6460 4.3333 1.0000
2.6520 4.0000 1.0000
2.6580 1.3333 1.0000
2.6640 2.1667 1.0000
2.6700 6.8333 1.0000
2.6760 4.3333 1.0000
2.6820 3.0000 1.0000
2.6880 2.5000 1.0000
2.6940 4.3333 1.0000
2.7000 4.6667 1.0000
2.7060 3.1667 1.0000
2.7120 0.3333 1.0000
2.7180 4.3333 1.0000
2.7240 3.1667 1.0000
2.7300 0.5000 1.0000
2.7360 0.0000 1.0000
2.7420 0.0000 1.0000
2.7480 4.3333 1.0000
2.7540 5.0000 1.0000
2.7600 0.1667 1.0000
2.7660 1.1667 1.0000
2.7720 0.0000 1.0000
2.7780 10.1667 1.0000
2.7840 0.0000 1.0000
2.7900 2.1667 1.0000
2.7960 3.1667 1.0000
2.8020 1.1667 1.0000
2.8080 0.1667 1.0000
2.8140 5.1667 1.0000
2.8200 4.3333 1.0000
2.8260 3.0000 1.0000
2.8320 2.1667 1.0000
2.8380 0.0000 1.0000
2.8440 4.1667 1.0000
2.8500 0.0000 1.0000
2.8560 1.1667 1.0000
2.8620 6.3333 1.0000
2.8680 2.3333 1.0000
2.8740 3.6667 1.0000
2.8800 2.5000 1.0000
2.8860 3.0000 1.0000
2.8920 0.1667 1.0000
2.8980 0.0000 1.0000
2.9040 5.0000 1.0000
2.9100 3.3333 1.0000
2.9160 3.1667 1.0000
2.9220 3.5000 1.0000
2.9280 2.6667 1.0000
2.9340 3.1667 1.0000
2.9400 0.3333 1.0000
2.9460 0.3333 1.0000
2.9520 2.1667 1.0000
2.9580 0.1667 1.0000
2.9640 3.0000 1.0000
2.9700 5.3333 1.0000
2.9760 0.0000 1.0000
2.9820 2.3333 1.0000
2.9880 0.0000 1.0000
2.9940 0.0000 1.0000
3.0000 2.1667 1.0000
3.0060 3.1667 1.0000
3.0120 2.3333 1.0000
3.0180 0.0000 1.0000
3.0240 0.0000 1.0000
3.0300 5.6667 1.0000
3.0360 0.3333 1.0000
3.0420 0.3333 1.0000
3.0480 3.0000 1.0000
3.0540 0.0000 1.0000
3.0600 2.3333 1.0000
3.0660 4.5000 1.0000
3.0720 2.0000 1.0000
3.0780 0.0000 1.0000
3.0840 0.1667 1.0000
3.0900 2.0000 1.0000
3.0960 1.1667 1.0000
3.1020 0.0000 1.0000
3.1080 0.1667 1.0000
3.1140 4.1667 1.0000
3.1200 0.5000 1.0000
3.1260 0.0000 1.0000
3.1320 4.1667 1.0000
3.1380 0.0000 1.0000
3.1440 1.1667 1.0000
3.1500 1.1667 1.0000
3.1560 0.0000 1.0000
3.1620 2.1667 1.0000
3.1680 0.3333 1.0000
3.1740 2.0000 1.0000
3.1800 0.0000 1.0000
3.1860 0.0000 1.0000
3.1920 0.0000 1.0000
3.1980 3.5000 1.0000
3.2040 1.1667 1.0000
3.2100 1.3333 1.0000
3.2160 0.3333 1.0000
3.2220 0.0000 1.0000
3.2280 3.0000 1.0000
3.2340 2.3333 1.0000
3.2400 1.1667 1.0000
3.2460 2.1667 1.0000
3.2520 0.1667 1.0000
3.2580 1.3333 1.0000
3.2640 0.5000 1.0000
3.2700 2.5000 1.0000
3.2760 2.0000 1.0000
3.2820 0.0000 1.0000
3.2880 2.1667 1.0000
3.2940 3.0000 1.0000
3.3000 0.0000 1.0000
3.3060 5.1667 1.0000
3.3120 0.0000 1.0000
3.3180 0.0000 1.0000
3.3240 0.1667 1.0000
3.3300 0.1667 1.0000
3.3360 0.0000 1.0000
3.3420 3.1667 1.0000
3.3480 0.0000 1.0000
3.3540 1.1667 1.0000
3.3600 0.0000 1.0000
3.3660 3.0000 1.0000
3.3720 0.0000 1.0000
3.3780 1.1667 1.0000
3.3840 0.0000 1.0000
3.3900 0.0000 1.0000
3.3960 2.3333 1.0000
3.4020 0.0000 1.0000
3.4080 5.3333 1.0000
3.4140 3.0000 1.0000
3.4200 0.0000 1.0000
3.4260 2.0000 1.0000
3.4320 2.3333 1.0000
3.4380 0.0000 1.0000
3.4440 0.0000 1.0000
3.4500 2.1667 1.0000
3.4560 0.1667 1.0000
3.4620 0.0000 1.0000
3.4680 0.0000 1.0000
3.4740 4.0000 1.0000
3.4800 0.0000 1.0000
3.4860 0.0000 1.0000
3.4920 1.3333 1.0000
3.4980 0.1667 1.0000
3.5040 2.0000 1.0000
3.5100 0.0000 1.0000
3.5160 0.0000 1.0000
3.5220 0.0000 1.0000
3.5280 2.0000 1.0000
3.5340 0.0000 1.0000
3.5400 4.0000 1.0000
3.5460 2.0000 1.0000
3.5520 1.1667 1.0000
3.5580 3.0000 1.0000
3.5640 0.0000 1.0000
3.5700 0.0000 1.0000
3.5760 2.1667 1.0000
3.5820 2.3333 1.0000
3.5880 5.0000 1.0000
3.5940 0.0000 1.0000
3.6000 1.1667 1.0000
3.6060 0.0000 1.0000
3.6120 0.3333 1.0000
3.6180 3.1667 1.0000
3.6240 0.1667 1.0000
3.6300 2.3333 1.0000
3.6360 3.1667 1.0000
3.6420 0.0000 1.0000
3.6480 3.1667 1.0000
3.6540 0.0000 1.0000
3.6600 0.1667 1.0000
3.6660 2.3333 1.0000
3.6720 2.1667 1.0000
3.6780 2.1667 1.0000
3.6840 2.3333 1.0000
3.6900 0.0000 1.0000
3.6960 0.0000 1.0000
3.7020 3.0000 1.0000
3.7080 1.1667 1.0000
3.7140 0.3333 1.0000
3.7200 0.0000 1.0000
3.7260 0.0000 1.0000
3.7320 0.0000 1.0000
3.7380 2.5000 1.0000
3.7440 0.0000 1.0000
3.7500 3.1667 1.0000
3.7560 0.0000 1.0000
3.7620 0.1667 1.0000
3.7680 1.3333 1.0000
3.7740 1.1667 1.0000
3.7800 0.0000 1.0000
3.7860 2.0000 1.0000
3.7920 0.0000 1.0000
3.7980 2.5000 1.0000
3.8040 0.0000 1.0000
3.8100 0.0000 1.0000
3.8160 0.0000 1.0000
3.8220 0.0000 1.0000
3.8280 0.0000 1.0000
3.8340 4.0000 1.0000
3.8400 0.0000 1.0000
3.8460 0.0000 1.0000
3.8520 0.0000 1.0000
3.8580 0.0000 1.0000
3.8640 0.0000 1.0000
3.8700 0.0000 1.0000
3.8760 2.1667 1.0000
3.8820 4.0000 1.0000
3.8880 0.0000 1.0000
3.8940 2.0000 1.0000
3.9000 0.1667 1.0000
3.9060 1.3333 1.0000
3.9120 4.1667 1.0000
3.9180 0.0000 1.0000
3.9240 0.6667 1.0000
3.9300 0.0000 1.0000
3.9360 0.1667 1.0000
3.9420 0.0000 1.0000
3.9480 0.0000 1.0000
3.9540 0.0000 1.0000
3.9600 0.0000 1.0000
3.9660 0.0000 1.0000
3.9720 0.0000 1.0000
3.9780 0.0000 1.0000
3.9840 0.0000 1.0000
3.9900 0.0000 1.0000
3.9960 2.3333 1.0000
4.0020 1.1667 1.0000
4.0080 0.0000 1.0000
4.0140 0.3333 1.0000
4.0200 0.0000 1.0000
4.0260 0.0000 1.0000
4.0320 0.0000 1.0000
4.0380 0.0000 1.0000
4.0440 0.0000 1.0000
4.0500 0.0000 1.0000
4.0560 0.0000 1.0000
4.0620 0.0000 1.0000
4.0680 0.0000 1.0000
4.0740 0.0000 1.0000
4.0800 0.0000 1.0000
4.0860 0.0000 1.0000
4.0920 1.1667 1.0000
4.0980 0.0000 1.0000
4.1040 0.0000 1.0000
4.1100 0.1667 1.0000
4.1160 3.1667 1.0000
4.1220 0.0000 1.0000
4.1280 0.0000 1.0000
4.1340 0.0000 1.0000
4.1400 0.0000 1.0000
4.1460 0.0000 1.0000
4.1520 0.0000 1.0000
4.1580 0.0000 1.0000
4.1640 0.0000 1.0000
4.1700 2.1667 1.0000
4.1760 0.0000 1.0000
4.1820 2.1667 1.0000
4.1880 0.3333 1.0000
4.1940 0.0000 1.0000
4.2000 0.0000 1.0000
4.2060 1.1667 1.0000
4.2120 0.0000 1.0000
4.2180 0.1667 1.0000
4.2240 0.0000 1.0000
4.2300 0.1667 1.0000
4.2360 0.0000 1.0000
4.2420 0.0000 1.0000
4.2480 2.0000 1.0000
4.2540 0.0000 1.0000
4.2600 0.0000 1.0000
4.2660 0.0000 1.0000
4.2720 0.0000 1.0000
4.2780 0.0000 1.0000
4.2840 3.0000 1.0000
4.2900 0.0000 1.0000
4.2960 0.0000 1.0000
4.3020 0.0000 1.0000
4.3080 0.0000 1.0000
4.3140 0.0000 1.0000
4.3200 0.0000 1.0000
4.3260 1.3333 1.0000
4.3320 0.0000 1.0000
4.3380 0.0000 1.0000
4.3440 2.1667 1.0000
4.3500 0.0000 1.0000
4.3560 0.0000 1.0000
4.3620 0.0000 1.0000
4.3680 1.5000 1.0000
4.3740 0.0000 1.0000
4.3800 2.3333 1.0000
4.3860 1.3333 1.0000
4.3920 0.0000 1.0000
4.3980 0.1667 1.0000
4.4040 0.1667 1.0000
4.4100 0.0000 1.0000
4.4160 0.0000 1.0000
4.4220 0.0000 1.0000
4.4280 0.1667 1.0000
4.4340 1.1667 1.0000
4.4400 0.0000 1.0000
4.4460 0.0000 1.0000
4.4520 0.0000 1.0000
4.4580 0.0000 1.0000
4.4640 0.0000 1.0000
4.4700 0.0000 1.0000
4.4760 2.0000 1.0000
4.4820 0.0000 1.0000
4.4880 2.0000 1.0000
4.4940 1.3333 1.0000
4.5000 0.0000 1.0000
4.5060 0.0000 1.0000
4.5120 0.0000 1.0000
4.5180 0.0000 1.0000
4.5240 0.0000 1.0000
4.5300 0.0000 1.0000
4.5360 0.0000 1.0000
4.5420 0.0000 1.0000
4.5480 2.0000 1.0000
4.5540 0.0000 1.0000
4.5600 0.0000 1.0000
4.5660 0.0000 1.0000
4.5720 1.1667 1.0000
4.5780 2.3333 1.0000
4.5840 0.0000 1.0000
4.5900 0.0000 1.0000
4.5960 0.0000 1.0000
4.6020 1.1667 1.0000
4.6080 0.0000 1.0000
4.6140 0.0000 1.0000
4.6200 0.0000 1.0000
4.6260 0.0000 1.0000
4.6320 0.0000 1.0000
4.6380 0.0000 1.0000
4.6440 1.3333 1.0000
4.6500 2.3333 1.0000
4.6560 4.1667 1.0000
4.6620 0.0000 1.0000
4.6680 0.0000 1.0000
4.6740 0.0000 1.0000
4.6800 3.3333 1.0000
4.6860 0.0000 1.0000
4.6920 0.0000 1.0000
4.6980 1.1667 1.0000
4.7040 0.0000 1.0000
4.7100 0.0000 1.0000
4.7160 0.0000 1.0000
4.7220 2.0000 1.0000
4.7280 2.0000 1.0000
4.7340 0.0000 1.0000
4.7400 0.0000 1.0000
4.7460 0.0000 1.0000
4.7520 0.0000 1.0000
4.7580 0.0000 1.0000
4.7640 0.0000 1.0000
4.7700 0.0000 1.0000
4.7760 0.1667 1.0000
4.7820 0.0000 1.0000
4.7880 1.3333 1.0000
4.7940 0.0000 1.0000
4.8000 0.1667 1.0000
4.8060 0.0000 1.0000
4.8120 0.0000 1.0000
4.8180 0.0000 1.0000
4.8240 2.1667 1.0000
4.8300 0.0000 1.0000
4.8360 0.0000 1.0000
4.8420 0.0000 1.0000
4.8480 0.0000 1.0000
4.8540 0.0000 1.0000
4.8600 0.0000 1.0000
4.8660 3.0000 1.0000
4.8720 0.0000 1.0000
4.8780 2.1667 1.0000
4.8840 0.0000 1.0000
4.8900 0.0000 1.0000
4.8960 2.1667 1.0000
4.9020 0.0000 1.0000
4.9080 0.0000 1.0000
4.9140 0.0000 1.0000
4.9200 0.0000 1.0000
4.9260 0.0000 1.0000
4.9320 4.0000 1.0000
4.9380 0.0000 1.0000
4.9440 2.0000 1.0000
4.9500 0.0000 1.0000
4.9560 0.1667 1.0000
4.9620 0.0000 1.0000
4.9680 1.1667 1.0000
4.9740 0.0000 1.0000
4.9800 0.0000 1.0000
4.9860 0.0000 1.0000
4.9920 0.0000 1.0000
4.9980 0.0000 1.0000
5.0040 0.0000 1.0000
5.0100 0.0000 1.0000
5.0160 0.0000 1.0000
5.0220 0.0000 1.0000
5.0280 0.0000 1.0000
5.0340 0.0000 1.0000
5.0400 2.3333 1.0000
5.0460 0.0000 1.0000
5.0520 0.0000 1.0000
5.0580 0.0000 1.0000
5.0640 0.0000 1.0000
5.0700 0.0000 1.0000
5.0760 0.0000 1.0000
5.0820 0.0000 1.0000
5.0880 1.1667 1.0000
5.0940 0.3333 1.0000
5.1000 0.0000 1.0000
5.1060 0.0000 1.0000
5.1120 0.0000 1.0000
5.1180 0.0000 1.0000
5.1240 0.0000 1.0000
5.1300 0.1667 1.0000
5.1360 0.0000 1.0000
5.1420 0.1667 1.0000
5.1480 0.0000 1.0000
5.1540 0.0000 1.0000
5.1600 0.3333 1.0000
5.1660 0.0000 1.0000
5.1720 0.0000 1.0000
5.1780 0.1667 1.0000
5.1840 0.0000 1.0000
5.1900 0.0000 1.0000
5.1960 0.0000 1.0000
5.2020 3.0000 1.0000
5.2080 0.0000 1.0000
5.2140 0.1667 1.0000
5.2200 0.3333 1.0000
5.2260 3.1667 1.0000
5.2320 0.0000 1.0000
5.2380 0.0000 1.0000
5.2440 0.0000 1.0000
5.2500 0.0000 1.0000
5.2560 0.0000 1.0000
5.2620 0.0000 1.0000
5.2680 0.0000 1.0000
5.2740 0.0000 1.0000
5.2800 0.0000 1.0000
5.2860 0.0000 1.0000
5.2920 0.0000 1.0000
5.2980 0.0000 1.0000
5.3040 0.1667 1.0000
5.3100 0.3333 1.0000
5.3160 0.0000 1.0000
5.3220 0.0000 1.0000
5.3280 0.0000 1.0000
5.3340 1.1667 1.0000
5.3400 0.0000 1.0000
5.3460 0.0000 1.0000
5.3520 2.0000 1.0000
5.3580 0.0000 1.0000
5.3640 0.0000 1.0000
5.3700 2.0000 1.0000
5.3760 0.0000 1.0000
5.3820 1.1667 1.0000
5.3880 0.0000 1.0000
5.3940 2.1667 1.0000
5.4000 0.0000 1.0000
5.4060 0.0000 1.0000
5.4120 1.1667 1.0000
5.4180 0.0000 1.0000
5.4240 2.1667 1.0000
5.4300 0.1667 1.0000
5.4360 0.1667 1.0000
5.4420 0.0000 1.0000
5.4480 0.0000 1.0000
5.4540 0.0000 1.0000
5.4600 0.0000 1.0000
5.4660 0.0000 1.0000
5.4720 0.0000 1.0000
5.4780 0.0000 1.0000
5.4840 0.0000 1.0000
5.4900 0.0000 1.0000
5.4960 1.1667 1.0000
5.5020 0.0000 1.0000
5.5080 0.0000 1.0000
5.5140 0.1667 1.0000
5.5200 2.1667 1.0000
5.5260 0.0000 1.0000
5.5320 2.0000 1.0000
5.5380 2.1667 1.0000
5.5440 0.0000 1.0000
5.5500 0.0000 1.0000
5.5560 0.0000 1.0000
5.5620 0.0000 1.0000
5.5680 0.0000 1.0000
5.5740 1.1667 1.0000
5.5800 0.0000 1.0000
5.5860 0.0000 1.0000
5.5920 0.0000 1.0000
5.5980 0.0000 1.0000
5.6040 0.0000 1.0000
5.6100 0.0000 1.0000
5.6160 0.0000 1.0000
5.6220 0.0000 1.0000
5.6280 0.0000 1.0000
5.6340 0.0000 1.0000
5.6400 0.0000 1.0000
5.6460 0.0000 1.0000
5.6520 0.0000 1.0000
5.6580 0.0000 1.0000
5.6640 0.0000 1.0000
5.6700 0.0000 1.0000
5.6760 0.0000 1.0000
5.6820 1.1667 1.0000
5.6880 0.0000 1.0000
5.6940 0.0000 1.0000
5.7000 0.0000 1.0000
5.7060 1.1667 1.0000
5.7120 2.0000 1.0000
5.7180 0.0000 1.0000
5.7240 2.0000 1.0000
5.7300 0.0000 1.0000
5.7360 0.0000 1.0000
5.7420 0.0000 1.0000
5.7480 0.0000 1.0000
5.7540 0.0000 1.0000
5.7600 0.0000 1.0000
5.7660 0.0000 1.0000
5.7720 0.0000 1.0000
5.7780 0.0000 1.0000
5.7840 0.0000 1.0000
5.7900 0.0000 1.0000
5.7960 0.0000 1.0000
5.8020 0.0000 1.0000
5.8080 0.0000 1.0000
5.8140 0.0000 1.0000
5.8200 0.1667 1.0000
5.8260 0.0000 1.0000
5.8320 0.0000 1.0000
5.8380 2.1667 1.0000
5.8440 0.1667 1.0000
5.8500 0.0000 1.0000
5.8560 0.0000 1.0000
5.8620 1.1667 1.0000
5.8680 0.0000 1.0000
5.8740 0.0000 1.0000
5.8800 0.0000 1.0000
5.8860 0.0000 1.0000
5.8920 0.0000 1.0000
5.8980 0.0000 1.0000
5.9040 0.0000 1.0000
5.9100 0.0000 1.0000
5.9160 1.1667 1.0000
5.9220 2.0000 1.0000
5.9280 0.0000 1.0000
5.9340 0.0000 1.0000
5.9400 0.0000 1.0000
5.9460 0.0000 1.0000
5.9520 0.0000 1.0000
5.9580 0.0000 1.0000
5.9640 0.0000 1.0000
5.9700 0.0000 1.0000
5.9760 0.1667 1.0000
5.9820 0.0000 1.0000
5.9880 0.0000 1.0000
5.9940 0.0000 1.0000
6.0000 0.0000 1.0000
*RAS_INT_END
*RAS_DATA_END