File: XRR/CWOI3_reflectivity.ras
*RAS_DATA_START
*RAS_HEADER_START
*DISP_FMT_X "%.4f"
*DISP_FMT_Y "%.0f"
*DISP_FULLSCALE "2118875.3916666666"
*DISP_LINE_COLOR "255.0000000000"
*DISP_LINE_STYLE "0.0000000000"
*DISP_LINE_WIDTH "0.2500000000"
*DISP_NOTE "Collected Data-21"
*DISP_OFFSET_Y "0.0000000000"
*DISP_PEAKSEARCH_UNIT_Y "cps"
*DISP_RANGE_BOTTOM "0.0100000000"
*DISP_RANGE_LEFT "-0.0006000000"
*DISP_RANGE_LOGCUTOFF "0.0100000000"
*DISP_RANGE_RIGHT "6.0006000000"
*DISP_RANGE_TOP "2118875.3916666666"
*DISP_SCALE_MODE_Y "2.0000000000"
*DISP_TAB_NAME "2-Theta/Omega"
*DISP_TITLE_Y "Intensity"
*DISP_UNIT_Y "cps"
*DISP_WINDOW_NAME "MSG_MACROENGINE"
*FILE_COMMENT " "
*FILE_MD5 ""
*FILE_MEMO " "
*FILE_OPERATOR "Administrator"
*FILE_PART_ID "MEAS_KHP2_00055"
*FILE_SAMPLE "CWO I3"
*FILE_TYPE "RAS_RAW"
*FILE_USERGROUP "System Manager"
*FILE_VERSION "1.0000000000"
*HW_ATTACHMENT_ID "ATT0025"
*HW_ATTACHMENT_NAME "標準|Standard"
*HW_COUNTER_ID-0 "CUT0025"
*HW_COUNTER_ID-1 "CUT0020"
*HW_COUNTER_ID-2 "CUT0020"
*HW_COUNTER_ID-3 "CSL0021"
*HW_COUNTER_ID-4 "CMC0021"
*HW_COUNTER_NAME-0 "D/teX Ultra|D/teX Ultra"
*HW_COUNTER_NAME-1 "None|None"
*HW_COUNTER_NAME-2 "None|None"
*HW_COUNTER_NAME-3 "BBM|BBM"
*HW_COUNTER_NAME-4 "検出器モノクロメータ|Detector monochromator"
*HW_COUNTER_SELECT_NAME "D/teX Ultra|D/teX Ultra"
*HW_GONIOMETER_ID "GON0023"
*HW_GONIOMETER_NAME "SmartLab|SmartLab"
*HW_GONIOMETER_RADIUS-0 "90.0"
*HW_GONIOMETER_RADIUS-1 "114.0"
*HW_GONIOMETER_RADIUS-2 "190.0"
*HW_GONIOMETER_RADIUS-3 "300.0"
*HW_GONIOMETER_RADIUS-4 "187.0"
*HW_GONIOMETER_RADIUS-5 "300.0"
*HW_GONIOMETER_RADIUS-6 "113.0"
*HW_GONIOMETER_RADIUS-7 "331.0"
*HW_I_OPT_ID-0 "CBO0021"
*HW_I_OPT_ID-1 "ICR0021"
*HW_I_OPT_ID-2 "ISL0021"
*HW_I_OPT_ID-3 "ISO0021"
*HW_I_OPT_ID-4 "IAD0021"
*HW_I_OPT_ID-5 "IPR0001"
*HW_I_OPT_NAME-0 "CBOユニット|CBO unit"
*HW_I_OPT_NAME-1 "標準入射光学ユニット|Standard incident optical unit"
*HW_I_OPT_NAME-2 "標準入射スリットボックス|Standard incident slit box"
*HW_I_OPT_NAME-3 "入射平行スリット|Incident parallel slit"
*HW_I_OPT_NAME-4 "長手制限スリット|Length limiting slit"
*HW_I_OPT_NAME-5 "None|None"
*HW_R_ATTENUATER_AUTOMODE "1"
*HW_R_OPT_ID-0 "RSS0021"
*HW_R_OPT_ID-1 "RCR0023"
*HW_R_OPT_ID-2 "RSO0021"
*HW_R_OPT_ID-3 "RRS0021"
*HW_R_OPT_ID-4 "ATN0021"
*HW_R_OPT_ID-5 "RFL0021"
*HW_R_OPT_ID-6 "RAD0021"
*HW_R_OPT_NAME-0 "標準受光スリットボックス1|Standard receiving slit box # 1"
*HW_R_OPT_NAME-1 "標準受光光学ユニット1|Standard receiving unit # 1"
*HW_R_OPT_NAME-2 "標準受光光学ユニット2|Standard receiving optical unit # 2"
*HW_R_OPT_NAME-3 "標準受光スリットボックス2|Standard receiving slit box # 2"
*HW_R_OPT_NAME-4 "標準アッテネータ|Standard Attenuator"
*HW_R_OPT_NAME-5 "Cu Kβ|Cu K-beta"
*HW_R_OPT_NAME-6 "調整用受光スリット|Alignment receiving slit"
*HW_SAMPLE_HOLDER_ID "SMP0021"
*HW_SAMPLE_HOLDER_NAME "χφZクレードル|Chi phi Z cradle"
*HW_XG_CURRENT_MAX "200"
*HW_XG_CURRENT_MIN "10"
*HW_XG_CURRENT_RESOLUTION "1"
*HW_XG_CURRENT_UNIT "mA"
*HW_XG_FOCUS "0.4mm x 8mm"
*HW_XG_FOCUS_TYPE "Normal"
*HW_XG_ID "1700"
*HW_XG_NAME "9kW 開放管(45kV 200mA ID:1700)|9kW Rotating anode(45kV 200mA ID:1700)"
*HW_XG_TARGET_ATOMIC_NUMBER "29.0000000000"
*HW_XG_TARGET_NAME "Cu"
*HW_XG_TYPE "Rota"
*HW_XG_VOLTAGE_MAX "45"
*HW_XG_VOLTAGE_MIN "20"
*HW_XG_VOLTAGE_RESOLUTION "1"
*HW_XG_VOLTAGE_UNIT "kV"
*HW_XG_WATT_MAX "9.00"
*HW_XG_WATT_UNIT "kW"
*HW_XG_WAVE_LENGTH_ALPHA1 "1.540593"
*HW_XG_WAVE_LENGTH_ALPHA2 "1.544414"
*HW_XG_WAVE_LENGTH_BETA "1.392250"
*MEAS_COND_AXIS_NAME-0 "Theta/2-Theta"
*MEAS_COND_AXIS_NAME-1 "2-Theta"
*MEAS_COND_AXIS_NAME-2 "Omega"
*MEAS_COND_AXIS_NAME-3 "Chi"
*MEAS_COND_AXIS_NAME-4 "Phi"
*MEAS_COND_AXIS_NAME-5 "Z"
*MEAS_COND_AXIS_NAME-6 "2-Theta/Omega"
*MEAS_COND_AXIS_NAME-7 "Theta_s"
*MEAS_COND_AXIS_NAME-8 "Theta_d"
*MEAS_COND_AXIS_NAME-9 "Ts"
*MEAS_COND_AXIS_NAME-10 "CBO selection slit"
*MEAS_COND_AXIS_NAME-11 "M"
*MEAS_COND_AXIS_NAME-12 "Incident parallel slit"
*MEAS_COND_AXIS_NAME-13 "Incident slit"
*MEAS_COND_AXIS_NAME-14 ""
*MEAS_COND_AXIS_NAME-15 "Zs"
*MEAS_COND_AXIS_NAME-16 "Incident optical device"
*MEAS_COND_AXIS_NAME-17 "Omega_m"
*MEAS_COND_AXIS_NAME-18 "Length limiting slit"
*MEAS_COND_AXIS_NAME-19 "Center slit"
*MEAS_COND_AXIS_NAME-20 "Filter"
*MEAS_COND_AXIS_NAME-21 "Receiving slit # 1"
*MEAS_COND_AXIS_NAME-22 "Receiving slit # 2"
*MEAS_COND_AXIS_NAME-23 "Receiving optical device"
*MEAS_COND_AXIS_NAME-24 "Receiving parallel slit"
*MEAS_COND_AXIS_NAME-25 "Alignment receiving slit"
*MEAS_COND_AXIS_NAME-26 ""
*MEAS_COND_AXIS_NAME-27 ""
*MEAS_COND_AXIS_NAME-28 "Zd"
*MEAS_COND_AXIS_NAME-29 "Attenuator"
*MEAS_COND_AXIS_NAME-30 "Diffracted beam monochromator"
*MEAS_COND_AXIS_NAME-31 "Monochromator slit"
*MEAS_COND_AXIS_NAME-32 ""
*MEAS_COND_AXIS_NAME-33 ""
*MEAS_COND_AXIS_NAME-34 "Primary beam"
*MEAS_COND_AXIS_NAME-35 "PHA"
*MEAS_COND_AXIS_NAME_INTERNAL-0 "TwoThetaTheta"
*MEAS_COND_AXIS_NAME_INTERNAL-1 "TwoTheta"
*MEAS_COND_AXIS_NAME_INTERNAL-2 "Omega"
*MEAS_COND_AXIS_NAME_INTERNAL-3 "Chi"
*MEAS_COND_AXIS_NAME_INTERNAL-4 "Phi"
*MEAS_COND_AXIS_NAME_INTERNAL-5 "Z"
*MEAS_COND_AXIS_NAME_INTERNAL-6 "TwoThetaOmega"
*MEAS_COND_AXIS_NAME_INTERNAL-7 "ThetaS"
*MEAS_COND_AXIS_NAME_INTERNAL-8 "ThetaD"
*MEAS_COND_AXIS_NAME_INTERNAL-9 "Ts"
*MEAS_COND_AXIS_NAME_INTERNAL-10 "CBO"
*MEAS_COND_AXIS_NAME_INTERNAL-11 "CBO-M"
*MEAS_COND_AXIS_NAME_INTERNAL-12 "IncidentSollerSlit"
*MEAS_COND_AXIS_NAME_INTERNAL-13 "IncidentSlitBox"
*MEAS_COND_AXIS_NAME_INTERNAL-14 "IncidentSlitBox-_Axis"
*MEAS_COND_AXIS_NAME_INTERNAL-15 "Zs"
*MEAS_COND_AXIS_NAME_INTERNAL-16 "IncidentMonochromator"
*MEAS_COND_AXIS_NAME_INTERNAL-17 "IncidentMonochromator-OmegaM"
*MEAS_COND_AXIS_NAME_INTERNAL-18 "IncidentAxdSlit"
*MEAS_COND_AXIS_NAME_INTERNAL-19 "CenterSlit"
*MEAS_COND_AXIS_NAME_INTERNAL-20 "Filter"
*MEAS_COND_AXIS_NAME_INTERNAL-21 "ReceivingSlitBox1"
*MEAS_COND_AXIS_NAME_INTERNAL-22 "ReceivingSlitBox2"
*MEAS_COND_AXIS_NAME_INTERNAL-23 "ReceivingOptics"
*MEAS_COND_AXIS_NAME_INTERNAL-24 "ReceivingSollerSlit"
*MEAS_COND_AXIS_NAME_INTERNAL-25 "ReceivingAxdSlit"
*MEAS_COND_AXIS_NAME_INTERNAL-26 "ReceivingSlitBox1-_Axis"
*MEAS_COND_AXIS_NAME_INTERNAL-27 "ReceivingSlitBox2-_Axis"
*MEAS_COND_AXIS_NAME_INTERNAL-28 "ReceivingSlitBox2-Zd"
*MEAS_COND_AXIS_NAME_INTERNAL-29 "Attenuator"
*MEAS_COND_AXIS_NAME_INTERNAL-30 "CounterMonochromator"
*MEAS_COND_AXIS_NAME_INTERNAL-31 "CounterSlit"
*MEAS_COND_AXIS_NAME_INTERNAL-32 "AlphaR"
*MEAS_COND_AXIS_NAME_INTERNAL-33 "BetaR"
*MEAS_COND_AXIS_NAME_INTERNAL-34 "IncidentPrimary"
*MEAS_COND_AXIS_NAME_INTERNAL-35 "PHA"
*MEAS_COND_AXIS_NAME_MAGICNO-0 "83951616.0000000000"
*MEAS_COND_AXIS_NAME_MAGICNO-1 "268632064.0000000000"
*MEAS_COND_AXIS_NAME_MAGICNO-2 "268500992.0000000000"
*MEAS_COND_AXIS_NAME_MAGICNO-3 "268500992.0000000000"
*MEAS_COND_AXIS_NAME_MAGICNO-4 "268500992.0000000000"
*MEAS_COND_AXIS_NAME_MAGICNO-5 "285278208.0000000000"
*MEAS_COND_AXIS_NAME_MAGICNO-6 "83951616.0000000000"
*MEAS_COND_AXIS_NAME_MAGICNO-7 "131072.0000000000"
*MEAS_COND_AXIS_NAME_MAGICNO-8 "131072.0000000000"
*MEAS_COND_AXIS_NAME_MAGICNO-9 "318898176.0000000000"
*MEAS_COND_AXIS_NAME_MAGICNO-10 "20971521.0000000000"
*MEAS_COND_AXIS_NAME_MAGICNO-11 "285343744.0000000000"
*MEAS_COND_AXIS_NAME_MAGICNO-12 "20971521.0000000000"
*MEAS_COND_AXIS_NAME_MAGICNO-13 "22020097.0000000000"
*MEAS_COND_AXIS_NAME_MAGICNO-14 "25165824.0000000000"
*MEAS_COND_AXIS_NAME_MAGICNO-15 "318898176.0000000000"
*MEAS_COND_AXIS_NAME_MAGICNO-16 "20971521.0000000000"
*MEAS_COND_AXIS_NAME_MAGICNO-17 "285343744.0000000000"
*MEAS_COND_AXIS_NAME_MAGICNO-18 "20971521.0000000000"
*MEAS_COND_AXIS_NAME_MAGICNO-19 "20971521.0000000000"
*MEAS_COND_AXIS_NAME_MAGICNO-20 "20971521.0000000000"
*MEAS_COND_AXIS_NAME_MAGICNO-21 "23068673.0000000000"
*MEAS_COND_AXIS_NAME_MAGICNO-22 "23068673.0000000000"
*MEAS_COND_AXIS_NAME_MAGICNO-23 "20971521.0000000000"
*MEAS_COND_AXIS_NAME_MAGICNO-24 "20971521.0000000000"
*MEAS_COND_AXIS_NAME_MAGICNO-25 "20971521.0000000000"
*MEAS_COND_AXIS_NAME_MAGICNO-26 "25165824.0000000000"
*MEAS_COND_AXIS_NAME_MAGICNO-27 "25165824.0000000000"
*MEAS_COND_AXIS_NAME_MAGICNO-28 "285343744.0000000000"
*MEAS_COND_AXIS_NAME_MAGICNO-29 "17301505.0000000000"
*MEAS_COND_AXIS_NAME_MAGICNO-30 "20971521.0000000000"
*MEAS_COND_AXIS_NAME_MAGICNO-31 "20971521.0000000000"
*MEAS_COND_AXIS_NAME_MAGICNO-32 "8388608.0000000000"
*MEAS_COND_AXIS_NAME_MAGICNO-33 "8388608.0000000000"
*MEAS_COND_AXIS_NAME_MAGICNO-34 "20971521.0000000000"
*MEAS_COND_AXIS_NAME_MAGICNO-35 "0.0000000000"
*MEAS_COND_AXIS_OFFSET-0 "-"
*MEAS_COND_AXIS_OFFSET-1 "0.7797000000"
*MEAS_COND_AXIS_OFFSET-2 "0.6148000000"
*MEAS_COND_AXIS_OFFSET-3 "0.0000000000"
*MEAS_COND_AXIS_OFFSET-4 "0.0000000000"
*MEAS_COND_AXIS_OFFSET-5 "-"
*MEAS_COND_AXIS_OFFSET-6 "-"
*MEAS_COND_AXIS_OFFSET-7 "0.6148000000"
*MEAS_COND_AXIS_OFFSET-8 "0.1649000000"
*MEAS_COND_AXIS_OFFSET-9 "-"
*MEAS_COND_AXIS_OFFSET-10 "-"
*MEAS_COND_AXIS_OFFSET-11 "-"
*MEAS_COND_AXIS_OFFSET-12 "-"
*MEAS_COND_AXIS_OFFSET-13 "-"
*MEAS_COND_AXIS_OFFSET-14 "-"
*MEAS_COND_AXIS_OFFSET-15 "-"
*MEAS_COND_AXIS_OFFSET-16 "-"
*MEAS_COND_AXIS_OFFSET-17 "-"
*MEAS_COND_AXIS_OFFSET-18 "-"
*MEAS_COND_AXIS_OFFSET-19 "-"
*MEAS_COND_AXIS_OFFSET-20 "-"
*MEAS_COND_AXIS_OFFSET-21 "-"
*MEAS_COND_AXIS_OFFSET-22 "-"
*MEAS_COND_AXIS_OFFSET-23 "-"
*MEAS_COND_AXIS_OFFSET-24 "-"
*MEAS_COND_AXIS_OFFSET-25 "-"
*MEAS_COND_AXIS_OFFSET-26 "-"
*MEAS_COND_AXIS_OFFSET-27 "-"
*MEAS_COND_AXIS_OFFSET-28 "-"
*MEAS_COND_AXIS_OFFSET-29 "-"
*MEAS_COND_AXIS_OFFSET-30 "-"
*MEAS_COND_AXIS_OFFSET-31 "-"
*MEAS_COND_AXIS_OFFSET-32 "0.0000000000"
*MEAS_COND_AXIS_OFFSET-33 "0.0000000000"
*MEAS_COND_AXIS_OFFSET-34 "-"
*MEAS_COND_AXIS_OFFSET-35 "-"
*MEAS_COND_AXIS_POSITION-0 "-0.0008000000"
*MEAS_COND_AXIS_POSITION-1 "-0.0009000000"
*MEAS_COND_AXIS_POSITION-2 "-0.0004000000"
*MEAS_COND_AXIS_POSITION-3 "0.0000000000"
*MEAS_COND_AXIS_POSITION-4 "0.0000000000"
*MEAS_COND_AXIS_POSITION-5 "-1.4371000000"
*MEAS_COND_AXIS_POSITION-6 "-0.0008000000"
*MEAS_COND_AXIS_POSITION-7 "-0.0004000000"
*MEAS_COND_AXIS_POSITION-8 "-0.0005000000"
*MEAS_COND_AXIS_POSITION-9 "-4.3477500000"
*MEAS_COND_AXIS_POSITION-10 "PB"
*MEAS_COND_AXIS_POSITION-11 "0.0000000000"
*MEAS_COND_AXIS_POSITION-12 "Soller_slit_open_s"
*MEAS_COND_AXIS_POSITION-13 "0.250mm"
*MEAS_COND_AXIS_POSITION-14 "0.2500000000"
*MEAS_COND_AXIS_POSITION-15 "-0.6878100000"
*MEAS_COND_AXIS_POSITION-16 "Ge(220)x2"
*MEAS_COND_AXIS_POSITION-17 "0.0000000000"
*MEAS_COND_AXIS_POSITION-18 "2.0mm"
*MEAS_COND_AXIS_POSITION-19 "None"
*MEAS_COND_AXIS_POSITION-20 "None"
*MEAS_COND_AXIS_POSITION-21 "0.250mm"
*MEAS_COND_AXIS_POSITION-22 "0.250mm"
*MEAS_COND_AXIS_POSITION-23 "No_unit"
*MEAS_COND_AXIS_POSITION-24 "Soller_slit_5.0deg"
*MEAS_COND_AXIS_POSITION-25 "None"
*MEAS_COND_AXIS_POSITION-26 "0.2500000000"
*MEAS_COND_AXIS_POSITION-27 "0.2500000000"
*MEAS_COND_AXIS_POSITION-28 "0.0809400000"
*MEAS_COND_AXIS_POSITION-29 "1/10000"
*MEAS_COND_AXIS_POSITION-30 "None"
*MEAS_COND_AXIS_POSITION-31 "None"
*MEAS_COND_AXIS_POSITION-32 "0.0000000000"
*MEAS_COND_AXIS_POSITION-33 "0.0000000000"
*MEAS_COND_AXIS_POSITION-34 "None"
*MEAS_COND_AXIS_POSITION-35 "34.0000000000"
*MEAS_COND_AXIS_UNIT-0 "deg"
*MEAS_COND_AXIS_UNIT-1 "deg"
*MEAS_COND_AXIS_UNIT-2 "deg"
*MEAS_COND_AXIS_UNIT-3 "deg"
*MEAS_COND_AXIS_UNIT-4 "deg"
*MEAS_COND_AXIS_UNIT-5 "mm"
*MEAS_COND_AXIS_UNIT-6 "deg"
*MEAS_COND_AXIS_UNIT-7 "deg"
*MEAS_COND_AXIS_UNIT-8 "deg"
*MEAS_COND_AXIS_UNIT-9 "mm"
*MEAS_COND_AXIS_UNIT-10 ""
*MEAS_COND_AXIS_UNIT-11 "pulse"
*MEAS_COND_AXIS_UNIT-12 ""
*MEAS_COND_AXIS_UNIT-13 ""
*MEAS_COND_AXIS_UNIT-14 "mm"
*MEAS_COND_AXIS_UNIT-15 "mm"
*MEAS_COND_AXIS_UNIT-16 ""
*MEAS_COND_AXIS_UNIT-17 "pulse"
*MEAS_COND_AXIS_UNIT-18 ""
*MEAS_COND_AXIS_UNIT-19 ""
*MEAS_COND_AXIS_UNIT-20 ""
*MEAS_COND_AXIS_UNIT-21 ""
*MEAS_COND_AXIS_UNIT-22 ""
*MEAS_COND_AXIS_UNIT-23 ""
*MEAS_COND_AXIS_UNIT-24 ""
*MEAS_COND_AXIS_UNIT-25 ""
*MEAS_COND_AXIS_UNIT-26 "mm"
*MEAS_COND_AXIS_UNIT-27 "mm"
*MEAS_COND_AXIS_UNIT-28 "mm"
*MEAS_COND_AXIS_UNIT-29 ""
*MEAS_COND_AXIS_UNIT-30 ""
*MEAS_COND_AXIS_UNIT-31 ""
*MEAS_COND_AXIS_UNIT-32 "deg"
*MEAS_COND_AXIS_UNIT-33 "deg"
*MEAS_COND_AXIS_UNIT-34 ""
*MEAS_COND_AXIS_UNIT-35 "div"
*MEAS_COND_COUNTER_CNTLOSS_CORR "0.0000000000"
*MEAS_COND_COUNTER_PHABASE "34.0000000000"
*MEAS_COND_COUNTER_PHAWINDOW "19.0000000000"
*MEAS_COND_COUNTER_PHA_UNIT "div"
*MEAS_COND_COUNTER_TAUDIFF "2.0000000000"
*MEAS_COND_COUNTER_TAUINT "0.1000000000"
*MEAS_COND_IRRADIATION_MODE "OFF"
*MEAS_COND_IRRADIATION_WIDTH ""
*MEAS_COND_OPT_ATTR "High resolution parallel beam Ge(220)x2/RS"
*MEAS_COND_OPT_NAME "@High resolution PB-Ge(220)x2"
*MEAS_COND_UNSYMMETRIC_MODE "OFF"
*MEAS_COND_XG_CURRENT "200.0000000000"
*MEAS_COND_XG_VOLTAGE "45.0000000000"
*MEAS_COND_XG_WAVE_TYPE "Ka1"
*MEAS_DATA_COUNT "3001.0000000000"
*MEAS_SCAN_AXIS_X "2-Theta/Omega"
*MEAS_SCAN_AXIS_X_INTERNAL "TwoThetaOmega"
*MEAS_SCAN_END_TIME "10/20/23 15:58:50"
*MEAS_SCAN_MODE "CONTINUOUS"
*MEAS_SCAN_MONITOR "0"
*MEAS_SCAN_RESOLUTION_X "0.0002"
*MEAS_SCAN_SPEED "0.500000"
*MEAS_SCAN_SPEED_UNIT "deg/min"
*MEAS_SCAN_SPEED_USER "0.500000"
*MEAS_SCAN_START "0.0000000000"
*MEAS_SCAN_START_TIME "10/20/23 15:46:33"
*MEAS_SCAN_STEP "0.0020000000"
*MEAS_SCAN_STOP "6.0000000000"
*MEAS_SCAN_UNIT_X "deg"
*MEAS_SCAN_UNIT_Y "counts"
*RAS_HEADER_END
*RAS_INT_START
0.0000 386372.6250 1.0000
0.0060 398333.6875 1.0000
0.0120 403740.7188 1.0000
0.0180 397871.9063 1.0000
0.0240 396069.5625 1.0000
0.0300 373912.6250 1.0000
0.0360 325845.0625 1.0000
0.0420 254414.0000 1.0000
0.0480 192597.9531 1.0000
0.0540 130573.3672 1.0000
0.0600 82170.6563 1.0000
0.0660 44354.3320 1.0000
0.0720 22005.0000 1.0000
0.0780 13434.6670 1.0000
0.0840 10026.0000 1.0000
0.0900 8725.6670 1.0000
0.0960 8373.3330 1.0000
0.1020 8207.0000 1.0000
0.1080 8131.6665 1.0000
0.1140 8512.6670 1.0000
0.1200 8695.8330 1.0000
0.1260 8986.1670 1.0000
0.1320 9381.1670 1.0000
0.1380 9660.8330 1.0000
0.1440 10170.0000 1.0000
0.1500 10281.1670 1.0000
0.1560 10646.5000 1.0000
0.1620 10866.0000 1.0000
0.1680 11146.6670 1.0000
0.1740 11267.0000 1.0000
0.1800 11601.3330 1.0000
0.1860 11784.0000 1.0000
0.1920 12376.1670 1.0000
0.1980 12585.8330 1.0000
0.2040 12869.0000 1.0000
0.2100 13030.8330 1.0000
0.2160 13208.1670 1.0000
0.2220 13773.6670 1.0000
0.2280 13935.0000 1.0000
0.2340 14106.8330 1.0000
0.2400 14689.6670 1.0000
0.2460 14926.3330 1.0000
0.2520 15235.0000 1.0000
0.2580 15376.6670 1.0000
0.2640 15863.1670 1.0000
0.2700 16129.1670 1.0000
0.2760 16425.1660 1.0000
0.2820 16846.3340 1.0000
0.2880 17152.5000 1.0000
0.2940 17375.1660 1.0000
0.3000 17699.5000 1.0000
0.3060 18091.0000 1.0000
0.3120 18479.6660 1.0000
0.3180 18716.8340 1.0000
0.3240 18836.1660 1.0000
0.3300 19182.3340 1.0000
0.3360 19553.1660 1.0000
0.3420 19926.6660 1.0000
0.3480 20127.5000 1.0000
0.3540 20406.8340 1.0000
0.3600 20553.8340 1.0000
0.3660 21097.0000 1.0000
0.3720 21615.8340 1.0000
0.3780 22035.5000 1.0000
0.3840 22176.6660 1.0000
0.3900 22122.1660 1.0000
0.3960 22646.1660 1.0000
0.4020 23032.8340 1.0000
0.4080 23420.8340 1.0000
0.4140 23493.5000 1.0000
0.4200 23908.1660 1.0000
0.4260 24061.5000 1.0000
0.4320 24542.5000 1.0000
0.4380 24647.0000 1.0000
0.4440 24822.8340 1.0000
0.4500 25361.0000 1.0000
0.4560 25507.0000 1.0000
0.4620 25809.6660 1.0000
0.4680 25886.0000 1.0000
0.4740 26200.5000 1.0000
0.4800 26341.3340 1.0000
0.4860 26851.5000 1.0000
0.4920 27079.8340 1.0000
0.4980 27507.0000 1.0000
0.5040 27528.5000 1.0000
0.5100 27825.6660 1.0000
0.5160 27997.5000 1.0000
0.5220 28105.3340 1.0000
0.5280 28251.0000 1.0000
0.5340 28231.3340 1.0000
0.5400 28584.6660 1.0000
0.5460 29026.6660 1.0000
0.5520 28756.5000 1.0000
0.5580 29068.5000 1.0000
0.5640 29113.1660 1.0000
0.5700 28619.0000 1.0000
0.5760 28989.1660 1.0000
0.5820 29150.3340 1.0000
0.5880 29219.5000 1.0000
0.5940 29265.5000 1.0000
0.6000 28910.0000 1.0000
0.6060 28706.1660 1.0000
0.6120 28834.0000 1.0000
0.6180 28812.0000 1.0000
0.6240 28019.0000 1.0000
0.6300 28049.3340 1.0000
0.6360 27228.3340 1.0000
0.6420 26406.6660 1.0000
0.6480 26111.5000 1.0000
0.6540 25258.1660 1.0000
0.6600 24215.8340 1.0000
0.6660 22933.8340 1.0000
0.6720 21802.3340 1.0000
0.6780 20547.0000 1.0000
0.6840 19462.6660 1.0000
0.6900 17999.6660 1.0000
0.6960 16936.5000 1.0000
0.7020 15274.3330 1.0000
0.7080 13922.5000 1.0000
0.7140 12889.8330 1.0000
0.7200 11755.8330 1.0000
0.7260 10683.3330 1.0000
0.7320 9850.0000 1.0000
0.7380 8772.6670 1.0000
0.7440 8053.6665 1.0000
0.7500 7357.5000 1.0000
0.7560 6707.5000 1.0000
0.7620 6335.1665 1.0000
0.7680 5854.8335 1.0000
0.7740 5543.1665 1.0000
0.7800 5280.3335 1.0000
0.7860 4919.5000 1.0000
0.7920 4805.6665 1.0000
0.7980 4607.3335 1.0000
0.8040 4512.0000 1.0000
0.8100 4304.3335 1.0000
0.8160 4260.8335 1.0000
0.8220 4076.5000 1.0000
0.8280 3884.6667 1.0000
0.8340 3766.5000 1.0000
0.8400 3658.0000 1.0000
0.8460 3634.3333 1.0000
0.8520 3504.1667 1.0000
0.8580 3361.3333 1.0000
0.8640 3240.5000 1.0000
0.8700 3085.1667 1.0000
0.8760 2890.6667 1.0000
0.8820 2814.1667 1.0000
0.8880 2644.8333 1.0000
0.8940 2460.6667 1.0000
0.9000 2363.3333 1.0000
0.9060 2219.0000 1.0000
0.9120 2091.8333 1.0000
0.9180 2024.1666 1.0000
0.9240 1896.1666 1.0000
0.9300 1812.3334 1.0000
0.9360 1745.8334 1.0000
0.9420 1620.1666 1.0000
0.9480 1575.5000 1.0000
0.9540 1601.3334 1.0000
0.9600 1472.8334 1.0000
0.9660 1417.1666 1.0000
0.9720 1473.5000 1.0000
0.9780 1389.1666 1.0000
0.9840 1340.3334 1.0000
0.9900 1288.5000 1.0000
0.9960 1301.6666 1.0000
1.0020 1275.5000 1.0000
1.0080 1238.6666 1.0000
1.0140 1228.1666 1.0000
1.0200 1266.1666 1.0000
1.0260 1238.1666 1.0000
1.0320 1159.1666 1.0000
1.0380 1226.1666 1.0000
1.0440 1179.3334 1.0000
1.0500 1170.6666 1.0000
1.0560 1120.3334 1.0000
1.0620 1154.3334 1.0000
1.0680 1189.3334 1.0000
1.0740 1086.3334 1.0000
1.0800 1102.6666 1.0000
1.0860 1055.8334 1.0000
1.0920 1058.8334 1.0000
1.0980 981.3333 1.0000
1.1040 974.3333 1.0000
1.1100 991.8333 1.0000
1.1160 978.0000 1.0000
1.1220 885.1667 1.0000
1.1280 892.0000 1.0000
1.1340 846.3333 1.0000
1.1400 835.0000 1.0000
1.1460 784.8333 1.0000
1.1520 805.8333 1.0000
1.1580 726.0000 1.0000
1.1640 676.0000 1.0000
1.1700 656.6667 1.0000
1.1760 630.1667 1.0000
1.1820 664.1667 1.0000
1.1880 531.1667 1.0000
1.1940 568.8333 1.0000
1.2000 586.0000 1.0000
1.2060 520.5000 1.0000
1.2120 493.0000 1.0000
1.2180 505.3333 1.0000
1.2240 441.6667 1.0000
1.2300 454.8333 1.0000
1.2360 481.3333 1.0000
1.2420 465.5000 1.0000
1.2480 452.5000 1.0000
1.2540 471.0000 1.0000
1.2600 448.6667 1.0000
1.2660 410.8333 1.0000
1.2720 417.6667 1.0000
1.2780 463.1667 1.0000
1.2840 411.5000 1.0000
1.2900 419.3333 1.0000
1.2960 431.6667 1.0000
1.3020 477.1667 1.0000
1.3080 441.5000 1.0000
1.3140 468.6667 1.0000
1.3200 467.3333 1.0000
1.3260 477.6667 1.0000
1.3320 472.1667 1.0000
1.3380 493.0000 1.0000
1.3440 482.3333 1.0000
1.3500 426.0000 1.0000
1.3560 413.8333 1.0000
1.3620 435.0000 1.0000
1.3680 452.3333 1.0000
1.3740 460.5000 1.0000
1.3800 487.3333 1.0000
1.3860 464.3333 1.0000
1.3920 434.8333 1.0000
1.3980 439.0000 1.0000
1.4040 433.3333 1.0000
1.4100 415.8333 1.0000
1.4160 382.1667 1.0000
1.4220 401.5000 1.0000
1.4280 372.1667 1.0000
1.4340 353.5000 1.0000
1.4400 353.5000 1.0000
1.4460 373.5000 1.0000
1.4520 318.3333 1.0000
1.4580 323.5000 1.0000
1.4640 276.6667 1.0000
1.4700 256.6667 1.0000
1.4760 254.1667 1.0000
1.4820 240.3333 1.0000
1.4880 229.0000 1.0000
1.4940 200.8333 1.0000
1.5000 214.3333 1.0000
1.5060 181.1667 1.0000
1.5120 168.5000 1.0000
1.5180 184.3333 1.0000
1.5240 153.5000 1.0000
1.5300 160.5000 1.0000
1.5360 157.0000 1.0000
1.5420 176.1667 1.0000
1.5480 145.6667 1.0000
1.5540 159.3333 1.0000
1.5600 156.6667 1.0000
1.5660 159.0000 1.0000
1.5720 143.0000 1.0000
1.5780 147.3333 1.0000
1.5840 142.0000 1.0000
1.5900 158.0000 1.0000
1.5960 260.0000 1.0000
1.6020 148.3333 1.0000
1.6080 165.8333 1.0000
1.6140 169.5000 1.0000
1.6200 156.0000 1.0000
1.6260 179.6667 1.0000
1.6320 178.8333 1.0000
1.6380 162.1667 1.0000
1.6440 186.0000 1.0000
1.6500 149.1667 1.0000
1.6560 201.1667 1.0000
1.6620 191.8333 1.0000
1.6680 181.6667 1.0000
1.6740 191.0000 1.0000
1.6800 191.8333 1.0000
1.6860 207.5000 1.0000
1.6920 192.6667 1.0000
1.6980 169.1667 1.0000
1.7040 203.1667 1.0000
1.7100 180.5000 1.0000
1.7160 205.0000 1.0000
1.7220 174.0000 1.0000
1.7280 199.3333 1.0000
1.7340 166.6667 1.0000
1.7400 172.3333 1.0000
1.7460 165.3333 1.0000
1.7520 189.5000 1.0000
1.7580 166.1667 1.0000
1.7640 134.6667 1.0000
1.7700 146.8333 1.0000
1.7760 129.6667 1.0000
1.7820 145.8333 1.0000
1.7880 128.5000 1.0000
1.7940 121.1667 1.0000
1.8000 143.3333 1.0000
1.8060 124.3333 1.0000
1.8120 120.3333 1.0000
1.8180 109.1667 1.0000
1.8240 105.8333 1.0000
1.8300 93.3333 1.0000
1.8360 99.0000 1.0000
1.8420 84.1667 1.0000
1.8480 79.1667 1.0000
1.8540 95.8333 1.0000
1.8600 81.0000 1.0000
1.8660 66.1667 1.0000
1.8720 83.0000 1.0000
1.8780 64.3333 1.0000
1.8840 69.3333 1.0000
1.8900 80.5000 1.0000
1.8960 64.5000 1.0000
1.9020 70.8333 1.0000
1.9080 72.8333 1.0000
1.9140 59.6667 1.0000
1.9200 73.3333 1.0000
1.9260 76.5000 1.0000
1.9320 70.6667 1.0000
1.9380 72.1667 1.0000
1.9440 72.6667 1.0000
1.9500 71.0000 1.0000
1.9560 79.5000 1.0000
1.9620 77.5000 1.0000
1.9680 74.1667 1.0000
1.9740 94.8333 1.0000
1.9800 74.6667 1.0000
1.9860 92.6667 1.0000
1.9920 96.3333 1.0000
1.9980 82.5000 1.0000
2.0040 93.5000 1.0000
2.0100 101.3333 1.0000
2.0160 86.5000 1.0000
2.0220 92.5000 1.0000
2.0280 103.0000 1.0000
2.0340 89.5000 1.0000
2.0400 93.5000 1.0000
2.0460 92.0000 1.0000
2.0520 84.1667 1.0000
2.0580 101.3333 1.0000
2.0640 98.8333 1.0000
2.0700 101.5000 1.0000
2.0760 101.1667 1.0000
2.0820 88.5000 1.0000
2.0880 77.6667 1.0000
2.0940 102.5000 1.0000
2.1000 85.8333 1.0000
2.1060 87.1667 1.0000
2.1120 91.6667 1.0000
2.1180 67.3333 1.0000
2.1240 77.1667 1.0000
2.1300 71.8333 1.0000
2.1360 58.8333 1.0000
2.1420 56.1667 1.0000
2.1480 66.1667 1.0000
2.1540 48.3333 1.0000
2.1600 71.0000 1.0000
2.1660 57.6667 1.0000
2.1720 41.8333 1.0000
2.1780 39.6667 1.0000
2.1840 57.5000 1.0000
2.1900 39.1667 1.0000
2.1960 52.6667 1.0000
2.2020 41.3333 1.0000
2.2080 45.1667 1.0000
2.2140 51.1667 1.0000
2.2200 40.3333 1.0000
2.2260 38.5000 1.0000
2.2320 48.0000 1.0000
2.2380 34.1667 1.0000
2.2440 42.8333 1.0000
2.2500 34.8333 1.0000
2.2560 36.8333 1.0000
2.2620 54.1667 1.0000
2.2680 37.1667 1.0000
2.2740 26.0000 1.0000
2.2800 30.1667 1.0000
2.2860 33.6667 1.0000
2.2920 50.0000 1.0000
2.2980 51.5000 1.0000
2.3040 36.1667 1.0000
2.3100 35.8333 1.0000
2.3160 53.6667 1.0000
2.3220 36.5000 1.0000
2.3280 57.0000 1.0000
2.3340 52.3333 1.0000
2.3400 50.1667 1.0000
2.3460 45.5000 1.0000
2.3520 55.0000 1.0000
2.3580 55.6667 1.0000
2.3640 50.5000 1.0000
2.3700 45.5000 1.0000
2.3760 50.0000 1.0000
2.3820 44.1667 1.0000
2.3880 39.5000 1.0000
2.3940 40.5000 1.0000
2.4000 39.3333 1.0000
2.4060 38.5000 1.0000
2.4120 45.8333 1.0000
2.4180 41.6667 1.0000
2.4240 48.8333 1.0000
2.4300 34.1667 1.0000
2.4360 43.1667 1.0000
2.4420 30.8333 1.0000
2.4480 48.1667 1.0000
2.4540 38.5000 1.0000
2.4600 39.5000 1.0000
2.4660 31.3333 1.0000
2.4720 36.6667 1.0000
2.4780 32.1667 1.0000
2.4840 23.5000 1.0000
2.4900 41.1667 1.0000
2.4960 24.0000 1.0000
2.5020 43.1667 1.0000
2.5080 22.1667 1.0000
2.5140 32.6667 1.0000
2.5200 30.0000 1.0000
2.5260 24.1667 1.0000
2.5320 24.6667 1.0000
2.5380 18.8333 1.0000
2.5440 17.1667 1.0000
2.5500 23.8333 1.0000
2.5560 25.3333 1.0000
2.5620 26.3333 1.0000
2.5680 14.0000 1.0000
2.5740 23.8333 1.0000
2.5800 22.5000 1.0000
2.5860 21.8333 1.0000
2.5920 29.6667 1.0000
2.5980 27.3333 1.0000
2.6040 16.6667 1.0000
2.6100 24.8333 1.0000
2.6160 20.1667 1.0000
2.6220 24.5000 1.0000
2.6280 18.5000 1.0000
2.6340 21.0000 1.0000
2.6400 24.5000 1.0000
2.6460 20.8333 1.0000
2.6520 24.1667 1.0000
2.6580 19.3333 1.0000
2.6640 23.3333 1.0000
2.6700 24.3333 1.0000
2.6760 18.1667 1.0000
2.6820 23.5000 1.0000
2.6880 14.1667 1.0000
2.6940 36.8333 1.0000
2.7000 22.6667 1.0000
2.7060 29.1667 1.0000
2.7120 28.0000 1.0000
2.7180 26.8333 1.0000
2.7240 27.8333 1.0000
2.7300 25.0000 1.0000
2.7360 25.5000 1.0000
2.7420 26.0000 1.0000
2.7480 25.8333 1.0000
2.7540 13.5000 1.0000
2.7600 28.8333 1.0000
2.7660 23.6667 1.0000
2.7720 21.3333 1.0000
2.7780 28.0000 1.0000
2.7840 20.3333 1.0000
2.7900 22.5000 1.0000
2.7960 20.1667 1.0000
2.8020 21.0000 1.0000
2.8080 15.1667 1.0000
2.8140 21.5000 1.0000
2.8200 20.1667 1.0000
2.8260 20.8333 1.0000
2.8320 12.0000 1.0000
2.8380 17.3333 1.0000
2.8440 15.5000 1.0000
2.8500 14.6667 1.0000
2.8560 16.6667 1.0000
2.8620 14.6667 1.0000
2.8680 15.0000 1.0000
2.8740 8.5000 1.0000
2.8800 19.6667 1.0000
2.8860 14.3333 1.0000
2.8920 6.1667 1.0000
2.8980 18.5000 1.0000
2.9040 5.3333 1.0000
2.9100 9.1667 1.0000
2.9160 16.0000 1.0000
2.9220 14.6667 1.0000
2.9280 13.0000 1.0000
2.9340 11.6667 1.0000
2.9400 15.5000 1.0000
2.9460 22.3333 1.0000
2.9520 11.5000 1.0000
2.9580 15.3333 1.0000
2.9640 14.1667 1.0000
2.9700 12.3333 1.0000
2.9760 12.1667 1.0000
2.9820 12.5000 1.0000
2.9880 16.1667 1.0000
2.9940 14.1667 1.0000
3.0000 18.5000 1.0000
3.0060 16.0000 1.0000
3.0120 16.6667 1.0000
3.0180 17.1667 1.0000
3.0240 16.5000 1.0000
3.0300 16.5000 1.0000
3.0360 9.3333 1.0000
3.0420 15.3333 1.0000
3.0480 7.1667 1.0000
3.0540 13.1667 1.0000
3.0600 14.6667 1.0000
3.0660 12.3333 1.0000
3.0720 9.3333 1.0000
3.0780 8.0000 1.0000
3.0840 19.0000 1.0000
3.0900 11.1667 1.0000
3.0960 14.1667 1.0000
3.1020 11.5000 1.0000
3.1080 9.1667 1.0000
3.1140 11.6667 1.0000
3.1200 18.6667 1.0000
3.1260 17.0000 1.0000
3.1320 11.1667 1.0000
3.1380 16.0000 1.0000
3.1440 8.3333 1.0000
3.1500 12.0000 1.0000
3.1560 18.0000 1.0000
3.1620 7.0000 1.0000
3.1680 12.0000 1.0000
3.1740 11.0000 1.0000
3.1800 12.6667 1.0000
3.1860 15.6667 1.0000
3.1920 14.6667 1.0000
3.1980 12.3333 1.0000
3.2040 10.3333 1.0000
3.2100 4.6667 1.0000
3.2160 13.0000 1.0000
3.2220 9.5000 1.0000
3.2280 10.1667 1.0000
3.2340 7.1667 1.0000
3.2400 9.5000 1.0000
3.2460 9.5000 1.0000
3.2520 10.5000 1.0000
3.2580 9.8333 1.0000
3.2640 3.5000 1.0000
3.2700 11.0000 1.0000
3.2760 9.3333 1.0000
3.2820 8.8333 1.0000
3.2880 9.3333 1.0000
3.2940 9.8333 1.0000
3.3000 8.5000 1.0000
3.3060 8.3333 1.0000
3.3120 9.1667 1.0000
3.3180 5.3333 1.0000
3.3240 2.0000 1.0000
3.3300 7.6667 1.0000
3.3360 12.3333 1.0000
3.3420 9.0000 1.0000
3.3480 6.8333 1.0000
3.3540 9.6667 1.0000
3.3600 10.0000 1.0000
3.3660 11.3333 1.0000
3.3720 7.5000 1.0000
3.3780 8.0000 1.0000
3.3840 7.0000 1.0000
3.3900 6.6667 1.0000
3.3960 5.8333 1.0000
3.4020 12.8333 1.0000
3.4080 9.6667 1.0000
3.4140 11.1667 1.0000
3.4200 11.0000 1.0000
3.4260 5.3333 1.0000
3.4320 2.5000 1.0000
3.4380 10.6667 1.0000
3.4440 7.3333 1.0000
3.4500 6.8333 1.0000
3.4560 8.3333 1.0000
3.4620 9.0000 1.0000
3.4680 8.6667 1.0000
3.4740 9.5000 1.0000
3.4800 2.8333 1.0000
3.4860 4.3333 1.0000
3.4920 9.6667 1.0000
3.4980 6.8333 1.0000
3.5040 9.5000 1.0000
3.5100 5.3333 1.0000
3.5160 7.3333 1.0000
3.5220 6.3333 1.0000
3.5280 3.3333 1.0000
3.5340 9.1667 1.0000
3.5400 5.0000 1.0000
3.5460 10.3333 1.0000
3.5520 5.8333 1.0000
3.5580 3.6667 1.0000
3.5640 5.5000 1.0000
3.5700 7.0000 1.0000
3.5760 7.6667 1.0000
3.5820 6.6667 1.0000
3.5880 1.3333 1.0000
3.5940 8.5000 1.0000
3.6000 5.6667 1.0000
3.6060 2.3333 1.0000
3.6120 5.6667 1.0000
3.6180 6.3333 1.0000
3.6240 4.8333 1.0000
3.6300 9.5000 1.0000
3.6360 2.3333 1.0000
3.6420 4.1667 1.0000
3.6480 1.6667 1.0000
3.6540 2.1667 1.0000
3.6600 9.5000 1.0000
3.6660 3.6667 1.0000
3.6720 3.5000 1.0000
3.6780 9.8333 1.0000
3.6840 6.5000 1.0000
3.6900 4.8333 1.0000
3.6960 5.6667 1.0000
3.7020 5.5000 1.0000
3.7080 0.0000 1.0000
3.7140 8.3333 1.0000
3.7200 1.5000 1.0000
3.7260 0.5000 1.0000
3.7320 4.3333 1.0000
3.7380 9.1667 1.0000
3.7440 6.0000 1.0000
3.7500 5.5000 1.0000
3.7560 3.3333 1.0000
3.7620 2.1667 1.0000
3.7680 3.3333 1.0000
3.7740 8.6667 1.0000
3.7800 8.5000 1.0000
3.7860 8.1667 1.0000
3.7920 2.8333 1.0000
3.7980 3.6667 1.0000
3.8040 7.1667 1.0000
3.8100 4.1667 1.0000
3.8160 2.3333 1.0000
3.8220 6.1667 1.0000
3.8280 10.8333 1.0000
3.8340 6.1667 1.0000
3.8400 1.1667 1.0000
3.8460 4.3333 1.0000
3.8520 5.8333 1.0000
3.8580 2.0000 1.0000
3.8640 0.0000 1.0000
3.8700 4.0000 1.0000
3.8760 0.5000 1.0000
3.8820 3.5000 1.0000
3.8880 9.1667 1.0000
3.8940 2.5000 1.0000
3.9000 9.6667 1.0000
3.9060 2.3333 1.0000
3.9120 0.1667 1.0000
3.9180 4.3333 1.0000
3.9240 4.5000 1.0000
3.9300 4.6667 1.0000
3.9360 1.3333 1.0000
3.9420 0.1667 1.0000
3.9480 1.1667 1.0000
3.9540 3.0000 1.0000
3.9600 2.1667 1.0000
3.9660 1.1667 1.0000
3.9720 4.1667 1.0000
3.9780 1.1667 1.0000
3.9840 3.0000 1.0000
3.9900 4.1667 1.0000
3.9960 0.3333 1.0000
4.0020 5.3333 1.0000
4.0080 2.5000 1.0000
4.0140 0.0000 1.0000
4.0200 1.1667 1.0000
4.0260 8.3333 1.0000
4.0320 3.3333 1.0000
4.0380 1.1667 1.0000
4.0440 1.5000 1.0000
4.0500 2.1667 1.0000
4.0560 0.0000 1.0000
4.0620 5.8333 1.0000
4.0680 3.3333 1.0000
4.0740 3.6667 1.0000
4.0800 1.1667 1.0000
4.0860 3.3333 1.0000
4.0920 4.8333 1.0000
4.0980 2.3333 1.0000
4.1040 1.1667 1.0000
4.1100 2.1667 1.0000
4.1160 0.0000 1.0000
4.1220 3.6667 1.0000
4.1280 2.1667 1.0000
4.1340 2.0000 1.0000
4.1400 5.1667 1.0000
4.1460 5.0000 1.0000
4.1520 0.0000 1.0000
4.1580 3.0000 1.0000
4.1640 4.3333 1.0000
4.1700 0.5000 1.0000
4.1760 0.3333 1.0000
4.1820 0.0000 1.0000
4.1880 0.3333 1.0000
4.1940 3.3333 1.0000
4.2000 6.5000 1.0000
4.2060 1.1667 1.0000
4.2120 2.6667 1.0000
4.2180 3.3333 1.0000
4.2240 1.1667 1.0000
4.2300 4.0000 1.0000
4.2360 4.5000 1.0000
4.2420 0.0000 1.0000
4.2480 2.1667 1.0000
4.2540 2.1667 1.0000
4.2600 2.3333 1.0000
4.2660 1.1667 1.0000
4.2720 0.0000 1.0000
4.2780 0.0000 1.0000
4.2840 0.0000 1.0000
4.2900 3.0000 1.0000
4.2960 2.1667 1.0000
4.3020 0.0000 1.0000
4.3080 1.1667 1.0000
4.3140 2.3333 1.0000
4.3200 0.1667 1.0000
4.3260 0.0000 1.0000
4.3320 2.3333 1.0000
4.3380 0.0000 1.0000
4.3440 1.1667 1.0000
4.3500 1.1667 1.0000
4.3560 2.0000 1.0000
4.3620 1.1667 1.0000
4.3680 2.1667 1.0000
4.3740 1.1667 1.0000
4.3800 0.0000 1.0000
4.3860 4.3333 1.0000
4.3920 0.3333 1.0000
4.3980 0.0000 1.0000
4.4040 2.5000 1.0000
4.4100 1.1667 1.0000
4.4160 2.3333 1.0000
4.4220 3.1667 1.0000
4.4280 0.0000 1.0000
4.4340 1.1667 1.0000
4.4400 3.0000 1.0000
4.4460 4.5000 1.0000
4.4520 4.0000 1.0000
4.4580 0.1667 1.0000
4.4640 2.3333 1.0000
4.4700 0.0000 1.0000
4.4760 3.3333 1.0000
4.4820 3.3333 1.0000
4.4880 3.0000 1.0000
4.4940 0.3333 1.0000
4.5000 3.0000 1.0000
4.5060 1.3333 1.0000
4.5120 3.1667 1.0000
4.5180 0.3333 1.0000
4.5240 0.0000 1.0000
4.5300 2.1667 1.0000
4.5360 0.0000 1.0000
4.5420 0.0000 1.0000
4.5480 1.1667 1.0000
4.5540 0.0000 1.0000
4.5600 0.0000 1.0000
4.5660 0.0000 1.0000
4.5720 1.3333 1.0000
4.5780 0.0000 1.0000
4.5840 0.1667 1.0000
4.5900 0.0000 1.0000
4.5960 0.0000 1.0000
4.6020 0.0000 1.0000
4.6080 4.1667 1.0000
4.6140 0.0000 1.0000
4.6200 0.0000 1.0000
4.6260 2.1667 1.0000
4.6320 0.0000 1.0000
4.6380 2.3333 1.0000
4.6440 0.0000 1.0000
4.6500 2.1667 1.0000
4.6560 0.0000 1.0000
4.6620 0.0000 1.0000
4.6680 0.0000 1.0000
4.6740 2.1667 1.0000
4.6800 0.0000 1.0000
4.6860 0.3333 1.0000
4.6920 0.0000 1.0000
4.6980 3.0000 1.0000
4.7040 3.0000 1.0000
4.7100 0.0000 1.0000
4.7160 0.1667 1.0000
4.7220 0.0000 1.0000
4.7280 0.0000 1.0000
4.7340 2.3333 1.0000
4.7400 2.1667 1.0000
4.7460 0.0000 1.0000
4.7520 0.1667 1.0000
4.7580 0.1667 1.0000
4.7640 0.3333 1.0000
4.7700 4.3333 1.0000
4.7760 0.0000 1.0000
4.7820 0.1667 1.0000
4.7880 0.0000 1.0000
4.7940 0.0000 1.0000
4.8000 0.1667 1.0000
4.8060 1.1667 1.0000
4.8120 0.0000 1.0000
4.8180 0.0000 1.0000
4.8240 2.1667 1.0000
4.8300 0.0000 1.0000
4.8360 0.0000 1.0000
4.8420 0.0000 1.0000
4.8480 0.0000 1.0000
4.8540 2.0000 1.0000
4.8600 0.0000 1.0000
4.8660 0.0000 1.0000
4.8720 2.3333 1.0000
4.8780 0.0000 1.0000
4.8840 0.0000 1.0000
4.8900 2.0000 1.0000
4.8960 0.1667 1.0000
4.9020 0.0000 1.0000
4.9080 0.0000 1.0000
4.9140 0.0000 1.0000
4.9200 3.0000 1.0000
4.9260 2.1667 1.0000
4.9320 1.1667 1.0000
4.9380 0.1667 1.0000
4.9440 3.1667 1.0000
4.9500 0.0000 1.0000
4.9560 1.1667 1.0000
4.9620 0.0000 1.0000
4.9680 0.0000 1.0000
4.9740 2.0000 1.0000
4.9800 0.0000 1.0000
4.9860 3.0000 1.0000
4.9920 0.0000 1.0000
4.9980 0.0000 1.0000
5.0040 0.1667 1.0000
5.0100 2.0000 1.0000
5.0160 0.0000 1.0000
5.0220 1.1667 1.0000
5.0280 2.1667 1.0000
5.0340 0.0000 1.0000
5.0400 0.0000 1.0000
5.0460 0.0000 1.0000
5.0520 0.0000 1.0000
5.0580 1.1667 1.0000
5.0640 0.0000 1.0000
5.0700 0.0000 1.0000
5.0760 0.0000 1.0000
5.0820 0.0000 1.0000
5.0880 0.0000 1.0000
5.0940 5.0000 1.0000
5.1000 0.0000 1.0000
5.1060 0.0000 1.0000
5.1120 0.3333 1.0000
5.1180 0.0000 1.0000
5.1240 0.0000 1.0000
5.1300 0.1667 1.0000
5.1360 0.0000 1.0000
5.1420 0.0000 1.0000
5.1480 5.0000 1.0000
5.1540 2.0000 1.0000
5.1600 1.1667 1.0000
5.1660 2.3333 1.0000
5.1720 0.0000 1.0000
5.1780 0.0000 1.0000
5.1840 0.0000 1.0000
5.1900 0.0000 1.0000
5.1960 0.0000 1.0000
5.2020 0.0000 1.0000
5.2080 0.3333 1.0000
5.2140 0.0000 1.0000
5.2200 2.0000 1.0000
5.2260 0.0000 1.0000
5.2320 0.0000 1.0000
5.2380 0.0000 1.0000
5.2440 0.0000 1.0000
5.2500 0.0000 1.0000
5.2560 0.0000 1.0000
5.2620 0.1667 1.0000
5.2680 2.0000 1.0000
5.2740 0.0000 1.0000
5.2800 3.0000 1.0000
5.2860 0.0000 1.0000
5.2920 0.0000 1.0000
5.2980 0.0000 1.0000
5.3040 0.0000 1.0000
5.3100 0.0000 1.0000
5.3160 0.0000 1.0000
5.3220 0.0000 1.0000
5.3280 0.0000 1.0000
5.3340 0.0000 1.0000
5.3400 0.0000 1.0000
5.3460 0.0000 1.0000
5.3520 0.0000 1.0000
5.3580 0.0000 1.0000
5.3640 0.0000 1.0000
5.3700 0.0000 1.0000
5.3760 0.0000 1.0000
5.3820 0.0000 1.0000
5.3880 0.0000 1.0000
5.3940 0.1667 1.0000
5.4000 0.0000 1.0000
5.4060 0.0000 1.0000
5.4120 0.0000 1.0000
5.4180 0.0000 1.0000
5.4240 3.0000 1.0000
5.4300 0.3333 1.0000
5.4360 1.1667 1.0000
5.4420 0.0000 1.0000
5.4480 0.0000 1.0000
5.4540 0.0000 1.0000
5.4600 1.1667 1.0000
5.4660 0.0000 1.0000
5.4720 0.0000 1.0000
5.4780 2.0000 1.0000
5.4840 0.0000 1.0000
5.4900 2.0000 1.0000
5.4960 0.0000 1.0000
5.5020 0.0000 1.0000
5.5080 0.0000 1.0000
5.5140 2.0000 1.0000
5.5200 0.0000 1.0000
5.5260 0.0000 1.0000
5.5320 0.0000 1.0000
5.5380 0.0000 1.0000
5.5440 0.0000 1.0000
5.5500 1.1667 1.0000
5.5560 0.0000 1.0000
5.5620 0.0000 1.0000
5.5680 0.0000 1.0000
5.5740 0.0000 1.0000
5.5800 0.0000 1.0000
5.5860 0.0000 1.0000
5.5920 1.1667 1.0000
5.5980 0.0000 1.0000
5.6040 0.0000 1.0000
5.6100 0.0000 1.0000
5.6160 0.3333 1.0000
5.6220 0.0000 1.0000
5.6280 0.0000 1.0000
5.6340 0.0000 1.0000
5.6400 0.0000 1.0000
5.6460 0.0000 1.0000
5.6520 0.0000 1.0000
5.6580 0.0000 1.0000
5.6640 0.0000 1.0000
5.6700 0.0000 1.0000
5.6760 0.0000 1.0000
5.6820 0.1667 1.0000
5.6880 0.0000 1.0000
5.6940 0.0000 1.0000
5.7000 1.1667 1.0000
5.7060 0.0000 1.0000
5.7120 0.0000 1.0000
5.7180 0.0000 1.0000
5.7240 0.0000 1.0000
5.7300 0.0000 1.0000
5.7360 0.0000 1.0000
5.7420 0.0000 1.0000
5.7480 0.0000 1.0000
5.7540 0.0000 1.0000
5.7600 0.0000 1.0000
5.7660 0.0000 1.0000
5.7720 0.1667 1.0000
5.7780 0.0000 1.0000
5.7840 0.0000 1.0000
5.7900 0.0000 1.0000
5.7960 2.0000 1.0000
5.8020 0.0000 1.0000
5.8080 0.0000 1.0000
5.8140 0.0000 1.0000
5.8200 0.1667 1.0000
5.8260 0.0000 1.0000
5.8320 0.0000 1.0000
5.8380 0.0000 1.0000
5.8440 0.0000 1.0000
5.8500 0.0000 1.0000
5.8560 2.3333 1.0000
5.8620 0.0000 1.0000
5.8680 0.0000 1.0000
5.8740 0.0000 1.0000
5.8800 0.0000 1.0000
5.8860 0.0000 1.0000
5.8920 0.0000 1.0000
5.8980 0.0000 1.0000
5.9040 0.0000 1.0000
5.9100 0.0000 1.0000
5.9160 0.0000 1.0000
5.9220 0.0000 1.0000
5.9280 0.0000 1.0000
5.9340 0.0000 1.0000
5.9400 0.0000 1.0000
5.9460 0.0000 1.0000
5.9520 0.0000 1.0000
5.9580 0.0000 1.0000
5.9640 0.0000 1.0000
5.9700 0.0000 1.0000
5.9760 0.0000 1.0000
5.9820 0.0000 1.0000
5.9880 0.0000 1.0000
5.9940 0.0000 1.0000
6.0000 0.0000 1.0000
*RAS_INT_END
*RAS_DATA_END