File: XRR/CWOI1_reflectivity.ras
*RAS_DATA_START
*RAS_HEADER_START
*DISP_FMT_X "%.4f"
*DISP_FMT_Y "%.0f"
*DISP_FULLSCALE "29666484.4499999990"
*DISP_LINE_COLOR "255.0000000000"
*DISP_LINE_STYLE "0.0000000000"
*DISP_LINE_WIDTH "0.2500000000"
*DISP_NOTE "Collected Data-3"
*DISP_OFFSET_Y "0.0000000000"
*DISP_PEAKSEARCH_UNIT_Y "cps"
*DISP_RANGE_BOTTOM "0.0100000000"
*DISP_RANGE_LEFT "-0.0006000000"
*DISP_RANGE_LOGCUTOFF "0.0100000000"
*DISP_RANGE_RIGHT "6.0006000000"
*DISP_RANGE_TOP "29666484.4499999990"
*DISP_SCALE_MODE_Y "2.0000000000"
*DISP_TAB_NAME "2-Theta/Omega"
*DISP_TITLE_Y "Intensity"
*DISP_UNIT_Y "cps"
*DISP_WINDOW_NAME "MSG_MACROENGINE"
*FILE_COMMENT " "
*FILE_MD5 ""
*FILE_MEMO " "
*FILE_OPERATOR "Administrator"
*FILE_PART_ID "MEAS_KHP2_00055"
*FILE_SAMPLE "CWO I1"
*FILE_TYPE "RAS_RAW"
*FILE_USERGROUP "System Manager"
*FILE_VERSION "1.0000000000"
*HW_ATTACHMENT_ID "ATT0025"
*HW_ATTACHMENT_NAME "標準|Standard"
*HW_COUNTER_ID-0 "CUT0025"
*HW_COUNTER_ID-1 "CUT0020"
*HW_COUNTER_ID-2 "CUT0020"
*HW_COUNTER_ID-3 "CSL0021"
*HW_COUNTER_ID-4 "CMC0021"
*HW_COUNTER_NAME-0 "D/teX Ultra|D/teX Ultra"
*HW_COUNTER_NAME-1 "None|None"
*HW_COUNTER_NAME-2 "None|None"
*HW_COUNTER_NAME-3 "BBM|BBM"
*HW_COUNTER_NAME-4 "検出器モノクロメータ|Detector monochromator"
*HW_COUNTER_SELECT_NAME "D/teX Ultra|D/teX Ultra"
*HW_GONIOMETER_ID "GON0023"
*HW_GONIOMETER_NAME "SmartLab|SmartLab"
*HW_GONIOMETER_RADIUS-0 "90.0"
*HW_GONIOMETER_RADIUS-1 "114.0"
*HW_GONIOMETER_RADIUS-2 "190.0"
*HW_GONIOMETER_RADIUS-3 "300.0"
*HW_GONIOMETER_RADIUS-4 "187.0"
*HW_GONIOMETER_RADIUS-5 "300.0"
*HW_GONIOMETER_RADIUS-6 "113.0"
*HW_GONIOMETER_RADIUS-7 "331.0"
*HW_I_OPT_ID-0 "CBO0021"
*HW_I_OPT_ID-1 "ICR0021"
*HW_I_OPT_ID-2 "ISL0021"
*HW_I_OPT_ID-3 "ISO0021"
*HW_I_OPT_ID-4 "IAD0021"
*HW_I_OPT_ID-5 "IPR0001"
*HW_I_OPT_NAME-0 "CBOユニット|CBO unit"
*HW_I_OPT_NAME-1 "標準入射光学ユニット|Standard incident optical unit"
*HW_I_OPT_NAME-2 "標準入射スリットボックス|Standard incident slit box"
*HW_I_OPT_NAME-3 "入射平行スリット|Incident parallel slit"
*HW_I_OPT_NAME-4 "長手制限スリット|Length limiting slit"
*HW_I_OPT_NAME-5 "None|None"
*HW_R_ATTENUATER_AUTOMODE "1"
*HW_R_OPT_ID-0 "RSS0021"
*HW_R_OPT_ID-1 "RCR0023"
*HW_R_OPT_ID-2 "RSO0021"
*HW_R_OPT_ID-3 "RRS0021"
*HW_R_OPT_ID-4 "ATN0021"
*HW_R_OPT_ID-5 "RFL0021"
*HW_R_OPT_ID-6 "RAD0021"
*HW_R_OPT_NAME-0 "標準受光スリットボックス1|Standard receiving slit box # 1"
*HW_R_OPT_NAME-1 "標準受光光学ユニット1|Standard receiving unit # 1"
*HW_R_OPT_NAME-2 "標準受光光学ユニット2|Standard receiving optical unit # 2"
*HW_R_OPT_NAME-3 "標準受光スリットボックス2|Standard receiving slit box # 2"
*HW_R_OPT_NAME-4 "標準アッテネータ|Standard Attenuator"
*HW_R_OPT_NAME-5 "Cu Kβ|Cu K-beta"
*HW_R_OPT_NAME-6 "調整用受光スリット|Alignment receiving slit"
*HW_SAMPLE_HOLDER_ID "SMP0021"
*HW_SAMPLE_HOLDER_NAME "χφZクレードル|Chi phi Z cradle"
*HW_XG_CURRENT_MAX "200"
*HW_XG_CURRENT_MIN "10"
*HW_XG_CURRENT_RESOLUTION "1"
*HW_XG_CURRENT_UNIT "mA"
*HW_XG_FOCUS "0.4mm x 8mm"
*HW_XG_FOCUS_TYPE "Normal"
*HW_XG_ID "1700"
*HW_XG_NAME "9kW 開放管(45kV 200mA ID:1700)|9kW Rotating anode(45kV 200mA ID:1700)"
*HW_XG_TARGET_ATOMIC_NUMBER "29.0000000000"
*HW_XG_TARGET_NAME "Cu"
*HW_XG_TYPE "Rota"
*HW_XG_VOLTAGE_MAX "45"
*HW_XG_VOLTAGE_MIN "20"
*HW_XG_VOLTAGE_RESOLUTION "1"
*HW_XG_VOLTAGE_UNIT "kV"
*HW_XG_WATT_MAX "9.00"
*HW_XG_WATT_UNIT "kW"
*HW_XG_WAVE_LENGTH_ALPHA1 "1.540593"
*HW_XG_WAVE_LENGTH_ALPHA2 "1.544414"
*HW_XG_WAVE_LENGTH_BETA "1.392250"
*MEAS_COND_AXIS_NAME-0 "Theta/2-Theta"
*MEAS_COND_AXIS_NAME-1 "2-Theta"
*MEAS_COND_AXIS_NAME-2 "Omega"
*MEAS_COND_AXIS_NAME-3 "Chi"
*MEAS_COND_AXIS_NAME-4 "Phi"
*MEAS_COND_AXIS_NAME-5 "Z"
*MEAS_COND_AXIS_NAME-6 "2-Theta/Omega"
*MEAS_COND_AXIS_NAME-7 "Theta_s"
*MEAS_COND_AXIS_NAME-8 "Theta_d"
*MEAS_COND_AXIS_NAME-9 "Ts"
*MEAS_COND_AXIS_NAME-10 "CBO selection slit"
*MEAS_COND_AXIS_NAME-11 "M"
*MEAS_COND_AXIS_NAME-12 "Incident parallel slit"
*MEAS_COND_AXIS_NAME-13 "Incident slit"
*MEAS_COND_AXIS_NAME-14 ""
*MEAS_COND_AXIS_NAME-15 "Zs"
*MEAS_COND_AXIS_NAME-16 "Incident optical device"
*MEAS_COND_AXIS_NAME-17 "Omega_m"
*MEAS_COND_AXIS_NAME-18 "Length limiting slit"
*MEAS_COND_AXIS_NAME-19 "Center slit"
*MEAS_COND_AXIS_NAME-20 "Filter"
*MEAS_COND_AXIS_NAME-21 "Receiving slit # 1"
*MEAS_COND_AXIS_NAME-22 "Receiving slit # 2"
*MEAS_COND_AXIS_NAME-23 "Receiving optical device"
*MEAS_COND_AXIS_NAME-24 "Receiving parallel slit"
*MEAS_COND_AXIS_NAME-25 "Alignment receiving slit"
*MEAS_COND_AXIS_NAME-26 ""
*MEAS_COND_AXIS_NAME-27 ""
*MEAS_COND_AXIS_NAME-28 "Zd"
*MEAS_COND_AXIS_NAME-29 "Attenuator"
*MEAS_COND_AXIS_NAME-30 "Diffracted beam monochromator"
*MEAS_COND_AXIS_NAME-31 "Monochromator slit"
*MEAS_COND_AXIS_NAME-32 "Primary beam"
*MEAS_COND_AXIS_NAME-33 ""
*MEAS_COND_AXIS_NAME-34 ""
*MEAS_COND_AXIS_NAME-35 "PHA"
*MEAS_COND_AXIS_NAME_INTERNAL-0 "TwoThetaTheta"
*MEAS_COND_AXIS_NAME_INTERNAL-1 "TwoTheta"
*MEAS_COND_AXIS_NAME_INTERNAL-2 "Omega"
*MEAS_COND_AXIS_NAME_INTERNAL-3 "Chi"
*MEAS_COND_AXIS_NAME_INTERNAL-4 "Phi"
*MEAS_COND_AXIS_NAME_INTERNAL-5 "Z"
*MEAS_COND_AXIS_NAME_INTERNAL-6 "TwoThetaOmega"
*MEAS_COND_AXIS_NAME_INTERNAL-7 "ThetaS"
*MEAS_COND_AXIS_NAME_INTERNAL-8 "ThetaD"
*MEAS_COND_AXIS_NAME_INTERNAL-9 "Ts"
*MEAS_COND_AXIS_NAME_INTERNAL-10 "CBO"
*MEAS_COND_AXIS_NAME_INTERNAL-11 "CBO-M"
*MEAS_COND_AXIS_NAME_INTERNAL-12 "IncidentSollerSlit"
*MEAS_COND_AXIS_NAME_INTERNAL-13 "IncidentSlitBox"
*MEAS_COND_AXIS_NAME_INTERNAL-14 "IncidentSlitBox-_Axis"
*MEAS_COND_AXIS_NAME_INTERNAL-15 "Zs"
*MEAS_COND_AXIS_NAME_INTERNAL-16 "IncidentMonochromator"
*MEAS_COND_AXIS_NAME_INTERNAL-17 "IncidentMonochromator-OmegaM"
*MEAS_COND_AXIS_NAME_INTERNAL-18 "IncidentAxdSlit"
*MEAS_COND_AXIS_NAME_INTERNAL-19 "CenterSlit"
*MEAS_COND_AXIS_NAME_INTERNAL-20 "Filter"
*MEAS_COND_AXIS_NAME_INTERNAL-21 "ReceivingSlitBox1"
*MEAS_COND_AXIS_NAME_INTERNAL-22 "ReceivingSlitBox2"
*MEAS_COND_AXIS_NAME_INTERNAL-23 "ReceivingOptics"
*MEAS_COND_AXIS_NAME_INTERNAL-24 "ReceivingSollerSlit"
*MEAS_COND_AXIS_NAME_INTERNAL-25 "ReceivingAxdSlit"
*MEAS_COND_AXIS_NAME_INTERNAL-26 "ReceivingSlitBox1-_Axis"
*MEAS_COND_AXIS_NAME_INTERNAL-27 "ReceivingSlitBox2-_Axis"
*MEAS_COND_AXIS_NAME_INTERNAL-28 "ReceivingSlitBox2-Zd"
*MEAS_COND_AXIS_NAME_INTERNAL-29 "Attenuator"
*MEAS_COND_AXIS_NAME_INTERNAL-30 "CounterMonochromator"
*MEAS_COND_AXIS_NAME_INTERNAL-31 "CounterSlit"
*MEAS_COND_AXIS_NAME_INTERNAL-32 "IncidentPrimary"
*MEAS_COND_AXIS_NAME_INTERNAL-33 "AlphaR"
*MEAS_COND_AXIS_NAME_INTERNAL-34 "BetaR"
*MEAS_COND_AXIS_NAME_INTERNAL-35 "PHA"
*MEAS_COND_AXIS_NAME_MAGICNO-0 "83951616.0000000000"
*MEAS_COND_AXIS_NAME_MAGICNO-1 "268632064.0000000000"
*MEAS_COND_AXIS_NAME_MAGICNO-2 "268500992.0000000000"
*MEAS_COND_AXIS_NAME_MAGICNO-3 "268500992.0000000000"
*MEAS_COND_AXIS_NAME_MAGICNO-4 "268500992.0000000000"
*MEAS_COND_AXIS_NAME_MAGICNO-5 "285278208.0000000000"
*MEAS_COND_AXIS_NAME_MAGICNO-6 "83951616.0000000000"
*MEAS_COND_AXIS_NAME_MAGICNO-7 "131072.0000000000"
*MEAS_COND_AXIS_NAME_MAGICNO-8 "131072.0000000000"
*MEAS_COND_AXIS_NAME_MAGICNO-9 "318898176.0000000000"
*MEAS_COND_AXIS_NAME_MAGICNO-10 "20971521.0000000000"
*MEAS_COND_AXIS_NAME_MAGICNO-11 "285343744.0000000000"
*MEAS_COND_AXIS_NAME_MAGICNO-12 "20971521.0000000000"
*MEAS_COND_AXIS_NAME_MAGICNO-13 "22020097.0000000000"
*MEAS_COND_AXIS_NAME_MAGICNO-14 "25165824.0000000000"
*MEAS_COND_AXIS_NAME_MAGICNO-15 "318898176.0000000000"
*MEAS_COND_AXIS_NAME_MAGICNO-16 "20971521.0000000000"
*MEAS_COND_AXIS_NAME_MAGICNO-17 "285343744.0000000000"
*MEAS_COND_AXIS_NAME_MAGICNO-18 "20971521.0000000000"
*MEAS_COND_AXIS_NAME_MAGICNO-19 "20971521.0000000000"
*MEAS_COND_AXIS_NAME_MAGICNO-20 "20971521.0000000000"
*MEAS_COND_AXIS_NAME_MAGICNO-21 "23068673.0000000000"
*MEAS_COND_AXIS_NAME_MAGICNO-22 "23068673.0000000000"
*MEAS_COND_AXIS_NAME_MAGICNO-23 "20971521.0000000000"
*MEAS_COND_AXIS_NAME_MAGICNO-24 "20971521.0000000000"
*MEAS_COND_AXIS_NAME_MAGICNO-25 "20971521.0000000000"
*MEAS_COND_AXIS_NAME_MAGICNO-26 "25165824.0000000000"
*MEAS_COND_AXIS_NAME_MAGICNO-27 "25165824.0000000000"
*MEAS_COND_AXIS_NAME_MAGICNO-28 "285343744.0000000000"
*MEAS_COND_AXIS_NAME_MAGICNO-29 "17301505.0000000000"
*MEAS_COND_AXIS_NAME_MAGICNO-30 "20971521.0000000000"
*MEAS_COND_AXIS_NAME_MAGICNO-31 "20971521.0000000000"
*MEAS_COND_AXIS_NAME_MAGICNO-32 "20971521.0000000000"
*MEAS_COND_AXIS_NAME_MAGICNO-33 "8388608.0000000000"
*MEAS_COND_AXIS_NAME_MAGICNO-34 "8388608.0000000000"
*MEAS_COND_AXIS_NAME_MAGICNO-35 "0.0000000000"
*MEAS_COND_AXIS_OFFSET-0 "-"
*MEAS_COND_AXIS_OFFSET-1 "0.9237000000"
*MEAS_COND_AXIS_OFFSET-2 "0.8516000000"
*MEAS_COND_AXIS_OFFSET-3 "0.0000000000"
*MEAS_COND_AXIS_OFFSET-4 "0.0000000000"
*MEAS_COND_AXIS_OFFSET-5 "-"
*MEAS_COND_AXIS_OFFSET-6 "-"
*MEAS_COND_AXIS_OFFSET-7 "0.8516000000"
*MEAS_COND_AXIS_OFFSET-8 "0.0721000000"
*MEAS_COND_AXIS_OFFSET-9 "-"
*MEAS_COND_AXIS_OFFSET-10 "-"
*MEAS_COND_AXIS_OFFSET-11 "-"
*MEAS_COND_AXIS_OFFSET-12 "-"
*MEAS_COND_AXIS_OFFSET-13 "-"
*MEAS_COND_AXIS_OFFSET-14 "-"
*MEAS_COND_AXIS_OFFSET-15 "-"
*MEAS_COND_AXIS_OFFSET-16 "-"
*MEAS_COND_AXIS_OFFSET-17 "-"
*MEAS_COND_AXIS_OFFSET-18 "-"
*MEAS_COND_AXIS_OFFSET-19 "-"
*MEAS_COND_AXIS_OFFSET-20 "-"
*MEAS_COND_AXIS_OFFSET-21 "-"
*MEAS_COND_AXIS_OFFSET-22 "-"
*MEAS_COND_AXIS_OFFSET-23 "-"
*MEAS_COND_AXIS_OFFSET-24 "-"
*MEAS_COND_AXIS_OFFSET-25 "-"
*MEAS_COND_AXIS_OFFSET-26 "-"
*MEAS_COND_AXIS_OFFSET-27 "-"
*MEAS_COND_AXIS_OFFSET-28 "-"
*MEAS_COND_AXIS_OFFSET-29 "-"
*MEAS_COND_AXIS_OFFSET-30 "-"
*MEAS_COND_AXIS_OFFSET-31 "-"
*MEAS_COND_AXIS_OFFSET-32 "-"
*MEAS_COND_AXIS_OFFSET-33 "0.0000000000"
*MEAS_COND_AXIS_OFFSET-34 "0.0000000000"
*MEAS_COND_AXIS_OFFSET-35 "-"
*MEAS_COND_AXIS_POSITION-0 "-0.0008000000"
*MEAS_COND_AXIS_POSITION-1 "-0.0009000000"
*MEAS_COND_AXIS_POSITION-2 "-0.0004000000"
*MEAS_COND_AXIS_POSITION-3 "0.0000000000"
*MEAS_COND_AXIS_POSITION-4 "0.0000000000"
*MEAS_COND_AXIS_POSITION-5 "-1.4599000000"
*MEAS_COND_AXIS_POSITION-6 "-0.0008000000"
*MEAS_COND_AXIS_POSITION-7 "-0.0004000000"
*MEAS_COND_AXIS_POSITION-8 "-0.0005000000"
*MEAS_COND_AXIS_POSITION-9 "-4.9359400000"
*MEAS_COND_AXIS_POSITION-10 "PB"
*MEAS_COND_AXIS_POSITION-11 "0.0000000000"
*MEAS_COND_AXIS_POSITION-12 "Soller_slit_open_s"
*MEAS_COND_AXIS_POSITION-13 "0.250mm"
*MEAS_COND_AXIS_POSITION-14 "0.2500000000"
*MEAS_COND_AXIS_POSITION-15 "-0.8884400000"
*MEAS_COND_AXIS_POSITION-16 "Ge(220)x2"
*MEAS_COND_AXIS_POSITION-17 "0.0000000000"
*MEAS_COND_AXIS_POSITION-18 "2.0mm"
*MEAS_COND_AXIS_POSITION-19 "None"
*MEAS_COND_AXIS_POSITION-20 "None"
*MEAS_COND_AXIS_POSITION-21 "0.250mm"
*MEAS_COND_AXIS_POSITION-22 "0.250mm"
*MEAS_COND_AXIS_POSITION-23 "No_unit"
*MEAS_COND_AXIS_POSITION-24 "Soller_slit_5.0deg"
*MEAS_COND_AXIS_POSITION-25 "None"
*MEAS_COND_AXIS_POSITION-26 "0.2500000000"
*MEAS_COND_AXIS_POSITION-27 "0.2500000000"
*MEAS_COND_AXIS_POSITION-28 "0.0887500000"
*MEAS_COND_AXIS_POSITION-29 "1/10000"
*MEAS_COND_AXIS_POSITION-30 "None"
*MEAS_COND_AXIS_POSITION-31 "None"
*MEAS_COND_AXIS_POSITION-32 "None"
*MEAS_COND_AXIS_POSITION-33 "0.0000000000"
*MEAS_COND_AXIS_POSITION-34 "0.0000000000"
*MEAS_COND_AXIS_POSITION-35 "34.0000000000"
*MEAS_COND_AXIS_UNIT-0 "deg"
*MEAS_COND_AXIS_UNIT-1 "deg"
*MEAS_COND_AXIS_UNIT-2 "deg"
*MEAS_COND_AXIS_UNIT-3 "deg"
*MEAS_COND_AXIS_UNIT-4 "deg"
*MEAS_COND_AXIS_UNIT-5 "mm"
*MEAS_COND_AXIS_UNIT-6 "deg"
*MEAS_COND_AXIS_UNIT-7 "deg"
*MEAS_COND_AXIS_UNIT-8 "deg"
*MEAS_COND_AXIS_UNIT-9 "mm"
*MEAS_COND_AXIS_UNIT-10 ""
*MEAS_COND_AXIS_UNIT-11 "pulse"
*MEAS_COND_AXIS_UNIT-12 ""
*MEAS_COND_AXIS_UNIT-13 ""
*MEAS_COND_AXIS_UNIT-14 "mm"
*MEAS_COND_AXIS_UNIT-15 "mm"
*MEAS_COND_AXIS_UNIT-16 ""
*MEAS_COND_AXIS_UNIT-17 "pulse"
*MEAS_COND_AXIS_UNIT-18 ""
*MEAS_COND_AXIS_UNIT-19 ""
*MEAS_COND_AXIS_UNIT-20 ""
*MEAS_COND_AXIS_UNIT-21 ""
*MEAS_COND_AXIS_UNIT-22 ""
*MEAS_COND_AXIS_UNIT-23 ""
*MEAS_COND_AXIS_UNIT-24 ""
*MEAS_COND_AXIS_UNIT-25 ""
*MEAS_COND_AXIS_UNIT-26 "mm"
*MEAS_COND_AXIS_UNIT-27 "mm"
*MEAS_COND_AXIS_UNIT-28 "mm"
*MEAS_COND_AXIS_UNIT-29 ""
*MEAS_COND_AXIS_UNIT-30 ""
*MEAS_COND_AXIS_UNIT-31 ""
*MEAS_COND_AXIS_UNIT-32 ""
*MEAS_COND_AXIS_UNIT-33 "deg"
*MEAS_COND_AXIS_UNIT-34 "deg"
*MEAS_COND_AXIS_UNIT-35 "div"
*MEAS_COND_COUNTER_CNTLOSS_CORR "0.0000000000"
*MEAS_COND_COUNTER_PHABASE "34.0000000000"
*MEAS_COND_COUNTER_PHAWINDOW "19.0000000000"
*MEAS_COND_COUNTER_PHA_UNIT "div"
*MEAS_COND_COUNTER_TAUDIFF "2.0000000000"
*MEAS_COND_COUNTER_TAUINT "0.1000000000"
*MEAS_COND_IRRADIATION_MODE "OFF"
*MEAS_COND_IRRADIATION_WIDTH ""
*MEAS_COND_OPT_ATTR "High resolution parallel beam Ge(220)x2/RS"
*MEAS_COND_OPT_NAME "@High resolution PB-Ge(220)x2"
*MEAS_COND_UNSYMMETRIC_MODE "OFF"
*MEAS_COND_XG_CURRENT "200.0000000000"
*MEAS_COND_XG_VOLTAGE "45.0000000000"
*MEAS_COND_XG_WAVE_TYPE "Ka1"
*MEAS_DATA_COUNT "3001.0000000000"
*MEAS_SCAN_AXIS_X "2-Theta/Omega"
*MEAS_SCAN_AXIS_X_INTERNAL "TwoThetaOmega"
*MEAS_SCAN_END_TIME "10/27/23 14:00:46"
*MEAS_SCAN_MODE "CONTINUOUS"
*MEAS_SCAN_MONITOR "0"
*MEAS_SCAN_RESOLUTION_X "0.0002"
*MEAS_SCAN_SPEED "0.500000"
*MEAS_SCAN_SPEED_UNIT "deg/min"
*MEAS_SCAN_SPEED_USER "0.500000"
*MEAS_SCAN_START "0.0000000000"
*MEAS_SCAN_START_TIME "10/27/23 13:48:18"
*MEAS_SCAN_STEP "0.0020000000"
*MEAS_SCAN_STOP "6.0000000000"
*MEAS_SCAN_UNIT_X "deg"
*MEAS_SCAN_UNIT_Y "counts"
*RAS_HEADER_END
*RAS_INT_START
0.0000 5432373.5000 1.0000
0.0060 5583809.0000 1.0000
0.0120 5518986.5000 1.0000
0.0180 5486575.5000 1.0000
0.0240 5299419.0000 1.0000
0.0300 5135708.5000 1.0000
0.0360 4435077.5000 1.0000
0.0420 3653487.5000 1.0000
0.0480 2618953.5000 1.0000
0.0540 1767024.6250 1.0000
0.0600 1006456.1250 1.0000
0.0660 518994.1563 1.0000
0.0720 251159.3438 1.0000
0.0780 143748.3750 1.0000
0.0840 95293.5391 1.0000
0.0900 76480.6016 1.0000
0.0960 67453.9688 1.0000
0.1020 67990.2031 1.0000
0.1080 68399.8281 1.0000
0.1140 71810.8828 1.0000
0.1200 68824.3516 1.0000
0.1260 75542.1875 1.0000
0.1320 76249.7188 1.0000
0.1380 83622.9609 1.0000
0.1440 84643.2969 1.0000
0.1500 87823.4766 1.0000
0.1560 92843.2344 1.0000
0.1620 97304.4219 1.0000
0.1680 101676.2266 1.0000
0.1740 105370.2969 1.0000
0.1800 108207.8750 1.0000
0.1860 110784.7891 1.0000
0.1920 112378.5938 1.0000
0.1980 114583.1250 1.0000
0.2040 119952.9297 1.0000
0.2100 124257.7031 1.0000
0.2160 130595.7109 1.0000
0.2220 130714.8750 1.0000
0.2280 131005.3359 1.0000
0.2340 136337.9063 1.0000
0.2400 138862.6719 1.0000
0.2460 143919.6719 1.0000
0.2520 145342.1875 1.0000
0.2580 148864.9688 1.0000
0.2640 151851.5000 1.0000
0.2700 157884.1406 1.0000
0.2760 156335.0156 1.0000
0.2820 159485.4063 1.0000
0.2880 162866.6719 1.0000
0.2940 169554.7188 1.0000
0.3000 171245.3438 1.0000
0.3060 171200.6719 1.0000
0.3120 175594.8125 1.0000
0.3180 179110.1406 1.0000
0.3240 182714.8281 1.0000
0.3300 186282.2813 1.0000
0.3360 183988.3906 1.0000
0.3420 193998.1250 1.0000
0.3480 195137.6250 1.0000
0.3540 193759.7969 1.0000
0.3600 199241.3125 1.0000
0.3660 202786.4375 1.0000
0.3720 210047.9531 1.0000
0.3780 208171.1250 1.0000
0.3840 209660.6719 1.0000
0.3900 210785.2656 1.0000
0.3960 211425.7813 1.0000
0.4020 225002.9688 1.0000
0.4080 221502.5469 1.0000
0.4140 221472.7500 1.0000
0.4200 226246.7344 1.0000
0.4260 233143.3281 1.0000
0.4320 234469.0156 1.0000
0.4380 234655.2031 1.0000
0.4440 236993.7969 1.0000
0.4500 238907.8594 1.0000
0.4560 238274.7969 1.0000
0.4620 249342.1094 1.0000
0.4680 252261.6094 1.0000
0.4740 244486.1875 1.0000
0.4800 253147.8906 1.0000
0.4860 256320.6094 1.0000
0.4920 255717.3594 1.0000
0.4980 260811.5938 1.0000
0.5040 263038.4688 1.0000
0.5100 260900.9688 1.0000
0.5160 266255.8750 1.0000
0.5220 270493.6250 1.0000
0.5280 267008.0938 1.0000
0.5340 269026.4375 1.0000
0.5400 272660.9063 1.0000
0.5460 274046.1875 1.0000
0.5520 281285.3750 1.0000
0.5580 275073.9688 1.0000
0.5640 279028.7188 1.0000
0.5700 275215.4688 1.0000
0.5760 272288.5313 1.0000
0.5820 278075.4063 1.0000
0.5880 281836.5000 1.0000
0.5940 282439.7500 1.0000
0.6000 279892.6250 1.0000
0.6060 273696.1563 1.0000
0.6120 275751.7188 1.0000
0.6180 277524.2813 1.0000
0.6240 269964.8438 1.0000
0.6300 265913.2813 1.0000
0.6360 257921.8750 1.0000
0.6420 251621.1094 1.0000
0.6480 244426.6250 1.0000
0.6540 234625.4063 1.0000
0.6600 226462.7188 1.0000
0.6660 209102.0938 1.0000
0.6720 200879.8125 1.0000
0.6780 189052.8438 1.0000
0.6840 182111.5625 1.0000
0.6900 159358.7969 1.0000
0.6960 147248.7969 1.0000
0.7020 138683.9375 1.0000
0.7080 125300.3828 1.0000
0.7140 116698.2734 1.0000
0.7200 107053.4766 1.0000
0.7260 96097.8906 1.0000
0.7320 87503.2188 1.0000
0.7380 85038.0313 1.0000
0.7440 75676.2500 1.0000
0.7500 68883.9297 1.0000
0.7560 64638.7344 1.0000
0.7620 59008.2617 1.0000
0.7680 57943.2383 1.0000
0.7740 56036.3320 1.0000
0.7800 53028.8320 1.0000
0.7860 50759.8320 1.0000
0.7920 48160.6680 1.0000
0.7980 45767.6680 1.0000
0.8040 43763.3320 1.0000
0.8100 42231.6680 1.0000
0.8160 40292.0000 1.0000
0.8220 38329.0000 1.0000
0.8280 37121.1680 1.0000
0.8340 34869.0000 1.0000
0.8400 33512.0000 1.0000
0.8460 31791.1660 1.0000
0.8520 30080.0000 1.0000
0.8580 28334.5000 1.0000
0.8640 27012.8340 1.0000
0.8700 26015.5000 1.0000
0.8760 24771.6660 1.0000
0.8820 23432.6660 1.0000
0.8880 22125.5000 1.0000
0.8940 21333.1660 1.0000
0.9000 20230.8340 1.0000
0.9060 19170.5000 1.0000
0.9120 18548.3340 1.0000
0.9180 17833.0000 1.0000
0.9240 17553.1660 1.0000
0.9300 17123.0000 1.0000
0.9360 16374.6670 1.0000
0.9420 15934.5000 1.0000
0.9480 15525.5000 1.0000
0.9540 15455.0000 1.0000
0.9600 15079.0000 1.0000
0.9660 14806.3330 1.0000
0.9720 14702.5000 1.0000
0.9780 14392.5000 1.0000
0.9840 14128.8330 1.0000
0.9900 13874.3330 1.0000
0.9960 13680.1670 1.0000
1.0020 13504.3330 1.0000
1.0080 13126.3330 1.0000
1.0140 12958.0000 1.0000
1.0200 12705.6670 1.0000
1.0260 12372.8330 1.0000
1.0320 11971.3330 1.0000
1.0380 11521.6670 1.0000
1.0440 10904.1670 1.0000
1.0500 10671.6670 1.0000
1.0560 10427.8330 1.0000
1.0620 10224.3330 1.0000
1.0680 9807.6670 1.0000
1.0740 9334.8330 1.0000
1.0800 9196.8330 1.0000
1.0860 8775.1670 1.0000
1.0920 8480.0000 1.0000
1.0980 8129.8335 1.0000
1.1040 7705.5000 1.0000
1.1100 7597.0000 1.0000
1.1160 7163.8335 1.0000
1.1220 6969.8335 1.0000
1.1280 6793.5000 1.0000
1.1340 6539.3335 1.0000
1.1400 6424.0000 1.0000
1.1460 6298.8335 1.0000
1.1520 6228.6665 1.0000
1.1580 6038.8335 1.0000
1.1640 6155.5000 1.0000
1.1700 5850.3335 1.0000
1.1760 5682.1665 1.0000
1.1820 5807.1665 1.0000
1.1880 5693.6665 1.0000
1.1940 5610.5000 1.0000
1.2000 5591.5000 1.0000
1.2060 5616.8335 1.0000
1.2120 5593.0000 1.0000
1.2180 5433.6665 1.0000
1.2240 5484.0000 1.0000
1.2300 5575.3335 1.0000
1.2360 5411.5000 1.0000
1.2420 5325.3335 1.0000
1.2480 5169.3335 1.0000
1.2540 5109.6665 1.0000
1.2600 4993.5000 1.0000
1.2660 4905.5000 1.0000
1.2720 4866.6665 1.0000
1.2780 4721.8335 1.0000
1.2840 4625.5000 1.0000
1.2900 4422.5000 1.0000
1.2960 4419.5000 1.0000
1.3020 4073.6667 1.0000
1.3080 4010.3333 1.0000
1.3140 3973.8333 1.0000
1.3200 3767.0000 1.0000
1.3260 3606.0000 1.0000
1.3320 3521.5000 1.0000
1.3380 3339.3333 1.0000
1.3440 3206.3333 1.0000
1.3500 3124.6667 1.0000
1.3560 2950.1667 1.0000
1.3620 2775.3333 1.0000
1.3680 2755.8333 1.0000
1.3740 2631.0000 1.0000
1.3800 2545.6667 1.0000
1.3860 2487.3333 1.0000
1.3920 2462.1667 1.0000
1.3980 2327.0000 1.0000
1.4040 2278.5000 1.0000
1.4100 2311.5000 1.0000
1.4160 2210.8333 1.0000
1.4220 2270.0000 1.0000
1.4280 2227.6667 1.0000
1.4340 2266.1667 1.0000
1.4400 2196.6667 1.0000
1.4460 2257.3333 1.0000
1.4520 2162.0000 1.0000
1.4580 2234.0000 1.0000
1.4640 2245.3333 1.0000
1.4700 2237.3333 1.0000
1.4760 2303.0000 1.0000
1.4820 2278.1667 1.0000
1.4880 2289.8333 1.0000
1.4940 2267.3333 1.0000
1.5000 2238.3333 1.0000
1.5060 2215.3333 1.0000
1.5120 2144.8333 1.0000
1.5180 2228.1667 1.0000
1.5240 2153.8333 1.0000
1.5300 2174.3333 1.0000
1.5360 2147.8333 1.0000
1.5420 2128.5000 1.0000
1.5480 2073.3333 1.0000
1.5540 2081.8333 1.0000
1.5600 1942.6666 1.0000
1.5660 1949.0000 1.0000
1.5720 1944.8334 1.0000
1.5780 1842.8334 1.0000
1.5840 1759.0000 1.0000
1.5900 1729.3334 1.0000
1.5960 1669.6666 1.0000
1.6020 1603.3334 1.0000
1.6080 1551.0000 1.0000
1.6140 1497.3334 1.0000
1.6200 1436.6666 1.0000
1.6260 1445.8334 1.0000
1.6320 1398.1666 1.0000
1.6380 1329.3334 1.0000
1.6440 1267.5000 1.0000
1.6500 1230.8334 1.0000
1.6560 1148.3334 1.0000
1.6620 1149.6666 1.0000
1.6680 1174.3334 1.0000
1.6740 1132.3334 1.0000
1.6800 1065.5000 1.0000
1.6860 1061.1666 1.0000
1.6920 1001.3333 1.0000
1.6980 1020.3333 1.0000
1.7040 1035.3334 1.0000
1.7100 1066.8334 1.0000
1.7160 1034.1666 1.0000
1.7220 1044.0000 1.0000
1.7280 1026.1666 1.0000
1.7340 1046.1666 1.0000
1.7400 1013.1667 1.0000
1.7460 1051.3334 1.0000
1.7520 1026.5000 1.0000
1.7580 1053.8334 1.0000
1.7640 1062.1666 1.0000
1.7700 978.1667 1.0000
1.7760 986.6667 1.0000
1.7820 1051.5000 1.0000
1.7880 1117.5000 1.0000
1.7940 1003.0000 1.0000
1.8000 1040.5000 1.0000
1.8060 972.0000 1.0000
1.8120 1008.3333 1.0000
1.8180 976.0000 1.0000
1.8240 933.6667 1.0000
1.8300 965.8333 1.0000
1.8360 902.8333 1.0000
1.8420 896.5000 1.0000
1.8480 925.0000 1.0000
1.8540 895.3333 1.0000
1.8600 850.1667 1.0000
1.8660 826.0000 1.0000
1.8720 796.1667 1.0000
1.8780 754.8333 1.0000
1.8840 779.6667 1.0000
1.8900 723.3333 1.0000
1.8960 732.8333 1.0000
1.9020 660.0000 1.0000
1.9080 681.0000 1.0000
1.9140 607.0000 1.0000
1.9200 566.6667 1.0000
1.9260 587.3333 1.0000
1.9320 572.1667 1.0000
1.9380 552.8333 1.0000
1.9440 558.6667 1.0000
1.9500 527.0000 1.0000
1.9560 511.3333 1.0000
1.9620 515.1667 1.0000
1.9680 494.0000 1.0000
1.9740 495.5000 1.0000
1.9800 483.3333 1.0000
1.9860 499.3333 1.0000
1.9920 517.1667 1.0000
1.9980 490.0000 1.0000
2.0040 520.0000 1.0000
2.0100 458.5000 1.0000
2.0160 515.5000 1.0000
2.0220 492.5000 1.0000
2.0280 501.8333 1.0000
2.0340 516.5000 1.0000
2.0400 515.0000 1.0000
2.0460 507.0000 1.0000
2.0520 560.0000 1.0000
2.0580 497.0000 1.0000
2.0640 502.5000 1.0000
2.0700 519.0000 1.0000
2.0760 528.5000 1.0000
2.0820 529.5000 1.0000
2.0880 539.8333 1.0000
2.0940 522.6667 1.0000
2.1000 515.8333 1.0000
2.1060 504.6667 1.0000
2.1120 528.5000 1.0000
2.1180 499.8333 1.0000
2.1240 440.5000 1.0000
2.1300 505.0000 1.0000
2.1360 442.8333 1.0000
2.1420 470.5000 1.0000
2.1480 478.5000 1.0000
2.1540 511.0000 1.0000
2.1600 466.0000 1.0000
2.1660 430.8333 1.0000
2.1720 462.1667 1.0000
2.1780 412.5000 1.0000
2.1840 410.8333 1.0000
2.1900 431.6667 1.0000
2.1960 459.0000 1.0000
2.2020 429.1667 1.0000
2.2080 431.3333 1.0000
2.2140 397.6667 1.0000
2.2200 409.0000 1.0000
2.2260 417.3333 1.0000
2.2320 405.1667 1.0000
2.2380 345.1667 1.0000
2.2440 362.0000 1.0000
2.2500 377.1667 1.0000
2.2560 358.6667 1.0000
2.2620 358.5000 1.0000
2.2680 359.8333 1.0000
2.2740 356.1667 1.0000
2.2800 367.8333 1.0000
2.2860 370.8333 1.0000
2.2920 369.0000 1.0000
2.2980 346.5000 1.0000
2.3040 351.5000 1.0000
2.3100 336.0000 1.0000
2.3160 334.0000 1.0000
2.3220 337.5000 1.0000
2.3280 322.1667 1.0000
2.3340 339.3333 1.0000
2.3400 328.1667 1.0000
2.3460 334.8333 1.0000
2.3520 319.1667 1.0000
2.3580 312.6667 1.0000
2.3640 322.1667 1.0000
2.3700 323.6667 1.0000
2.3760 304.8333 1.0000
2.3820 301.0000 1.0000
2.3880 313.3333 1.0000
2.3940 290.6667 1.0000
2.4000 302.5000 1.0000
2.4060 283.1667 1.0000
2.4120 283.1667 1.0000
2.4180 252.8333 1.0000
2.4240 232.3333 1.0000
2.4300 274.8333 1.0000
2.4360 258.0000 1.0000
2.4420 255.6667 1.0000
2.4480 254.8333 1.0000
2.4540 240.3333 1.0000
2.4600 238.0000 1.0000
2.4660 250.6667 1.0000
2.4720 245.6667 1.0000
2.4780 249.1667 1.0000
2.4840 256.3333 1.0000
2.4900 233.5000 1.0000
2.4960 237.3333 1.0000
2.5020 225.8333 1.0000
2.5080 200.1667 1.0000
2.5140 256.8333 1.0000
2.5200 243.6667 1.0000
2.5260 197.5000 1.0000
2.5320 197.0000 1.0000
2.5380 217.5000 1.0000
2.5440 213.8333 1.0000
2.5500 217.1667 1.0000
2.5560 191.3333 1.0000
2.5620 206.0000 1.0000
2.5680 204.0000 1.0000
2.5740 218.6667 1.0000
2.5800 190.5000 1.0000
2.5860 197.8333 1.0000
2.5920 197.1667 1.0000
2.5980 199.6667 1.0000
2.6040 218.1667 1.0000
2.6100 196.1667 1.0000
2.6160 196.1667 1.0000
2.6220 175.8333 1.0000
2.6280 190.1667 1.0000
2.6340 179.5000 1.0000
2.6400 177.6667 1.0000
2.6460 186.1667 1.0000
2.6520 165.5000 1.0000
2.6580 171.3333 1.0000
2.6640 153.5000 1.0000
2.6700 162.3333 1.0000
2.6760 163.1667 1.0000
2.6820 178.0000 1.0000
2.6880 150.6667 1.0000
2.6940 144.3333 1.0000
2.7000 166.6667 1.0000
2.7060 177.1667 1.0000
2.7120 159.3333 1.0000
2.7180 138.3333 1.0000
2.7240 156.3333 1.0000
2.7300 153.5000 1.0000
2.7360 156.3333 1.0000
2.7420 149.6667 1.0000
2.7480 130.1667 1.0000
2.7540 164.0000 1.0000
2.7600 135.6667 1.0000
2.7660 144.6667 1.0000
2.7720 115.6667 1.0000
2.7780 151.1667 1.0000
2.7840 114.8333 1.0000
2.7900 144.1667 1.0000
2.7960 127.0000 1.0000
2.8020 130.8333 1.0000
2.8080 119.0000 1.0000
2.8140 143.1667 1.0000
2.8200 131.3333 1.0000
2.8260 124.6667 1.0000
2.8320 130.3333 1.0000
2.8380 123.5000 1.0000
2.8440 113.8333 1.0000
2.8500 124.5000 1.0000
2.8560 141.5000 1.0000
2.8620 113.0000 1.0000
2.8680 120.3333 1.0000
2.8740 122.8333 1.0000
2.8800 108.8333 1.0000
2.8860 123.0000 1.0000
2.8920 129.3333 1.0000
2.8980 122.6667 1.0000
2.9040 138.3333 1.0000
2.9100 111.5000 1.0000
2.9160 125.6667 1.0000
2.9220 132.5000 1.0000
2.9280 106.5000 1.0000
2.9340 100.5000 1.0000
2.9400 105.8333 1.0000
2.9460 116.6667 1.0000
2.9520 106.1667 1.0000
2.9580 97.3333 1.0000
2.9640 99.3333 1.0000
2.9700 103.6667 1.0000
2.9760 85.1667 1.0000
2.9820 98.8333 1.0000
2.9880 93.8333 1.0000
2.9940 102.8333 1.0000
3.0000 77.0000 1.0000
3.0060 104.3333 1.0000
3.0120 93.0000 1.0000
3.0180 98.1667 1.0000
3.0240 98.8333 1.0000
3.0300 99.6667 1.0000
3.0360 95.3333 1.0000
3.0420 92.1667 1.0000
3.0480 86.8333 1.0000
3.0540 109.1667 1.0000
3.0600 91.1667 1.0000
3.0660 95.8333 1.0000
3.0720 100.1667 1.0000
3.0780 88.1667 1.0000
3.0840 93.5000 1.0000
3.0900 85.1667 1.0000
3.0960 88.3333 1.0000
3.1020 76.3333 1.0000
3.1080 103.1667 1.0000
3.1140 78.6667 1.0000
3.1200 91.0000 1.0000
3.1260 76.5000 1.0000
3.1320 73.5000 1.0000
3.1380 75.3333 1.0000
3.1440 78.8333 1.0000
3.1500 72.8333 1.0000
3.1560 79.3333 1.0000
3.1620 72.8333 1.0000
3.1680 96.1667 1.0000
3.1740 68.0000 1.0000
3.1800 81.6667 1.0000
3.1860 88.5000 1.0000
3.1920 86.8333 1.0000
3.1980 63.0000 1.0000
3.2040 79.1667 1.0000
3.2100 66.6667 1.0000
3.2160 66.8333 1.0000
3.2220 78.3333 1.0000
3.2280 61.5000 1.0000
3.2340 66.8333 1.0000
3.2400 66.8333 1.0000
3.2460 58.0000 1.0000
3.2520 67.3333 1.0000
3.2580 58.5000 1.0000
3.2640 60.6667 1.0000
3.2700 49.3333 1.0000
3.2760 50.6667 1.0000
3.2820 52.3333 1.0000
3.2880 78.3333 1.0000
3.2940 49.0000 1.0000
3.3000 47.6667 1.0000
3.3060 53.1667 1.0000
3.3120 57.1667 1.0000
3.3180 50.5000 1.0000
3.3240 49.5000 1.0000
3.3300 57.0000 1.0000
3.3360 54.5000 1.0000
3.3420 52.0000 1.0000
3.3480 43.8333 1.0000
3.3540 59.1667 1.0000
3.3600 62.3333 1.0000
3.3660 54.6667 1.0000
3.3720 57.8333 1.0000
3.3780 54.5000 1.0000
3.3840 46.0000 1.0000
3.3900 42.5000 1.0000
3.3960 48.1667 1.0000
3.4020 53.3333 1.0000
3.4080 53.6667 1.0000
3.4140 54.6667 1.0000
3.4200 54.1667 1.0000
3.4260 47.3333 1.0000
3.4320 53.3333 1.0000
3.4380 47.8333 1.0000
3.4440 54.1667 1.0000
3.4500 49.0000 1.0000
3.4560 48.8333 1.0000
3.4620 45.8333 1.0000
3.4680 41.3333 1.0000
3.4740 51.3333 1.0000
3.4800 37.1667 1.0000
3.4860 36.1667 1.0000
3.4920 63.6667 1.0000
3.4980 34.6667 1.0000
3.5040 46.0000 1.0000
3.5100 40.0000 1.0000
3.5160 45.3333 1.0000
3.5220 37.6667 1.0000
3.5280 42.0000 1.0000
3.5340 47.3333 1.0000
3.5400 35.8333 1.0000
3.5460 39.6667 1.0000
3.5520 44.1667 1.0000
3.5580 34.3333 1.0000
3.5640 35.0000 1.0000
3.5700 29.8333 1.0000
3.5760 36.1667 1.0000
3.5820 40.1667 1.0000
3.5880 31.8333 1.0000
3.5940 33.0000 1.0000
3.6000 39.6667 1.0000
3.6060 35.8333 1.0000
3.6120 39.6667 1.0000
3.6180 37.3333 1.0000
3.6240 28.8333 1.0000
3.6300 39.3333 1.0000
3.6360 29.1667 1.0000
3.6420 31.8333 1.0000
3.6480 33.6667 1.0000
3.6540 35.1667 1.0000
3.6600 39.6667 1.0000
3.6660 41.0000 1.0000
3.6720 33.3333 1.0000
3.6780 32.5000 1.0000
3.6840 46.0000 1.0000
3.6900 44.5000 1.0000
3.6960 21.8333 1.0000
3.7020 42.5000 1.0000
3.7080 32.1667 1.0000
3.7140 29.5000 1.0000
3.7200 37.0000 1.0000
3.7260 41.5000 1.0000
3.7320 28.8333 1.0000
3.7380 31.3333 1.0000
3.7440 26.0000 1.0000
3.7500 33.0000 1.0000
3.7560 23.8333 1.0000
3.7620 30.5000 1.0000
3.7680 34.0000 1.0000
3.7740 32.3333 1.0000
3.7800 28.0000 1.0000
3.7860 34.8333 1.0000
3.7920 28.5000 1.0000
3.7980 31.3333 1.0000
3.8040 28.6667 1.0000
3.8100 33.0000 1.0000
3.8160 21.0000 1.0000
3.8220 27.1667 1.0000
3.8280 18.5000 1.0000
3.8340 21.3333 1.0000
3.8400 24.8333 1.0000
3.8460 22.1667 1.0000
3.8520 24.5000 1.0000
3.8580 25.5000 1.0000
3.8640 26.8333 1.0000
3.8700 32.3333 1.0000
3.8760 24.5000 1.0000
3.8820 24.6667 1.0000
3.8880 23.1667 1.0000
3.8940 26.0000 1.0000
3.9000 25.8333 1.0000
3.9060 27.3333 1.0000
3.9120 26.5000 1.0000
3.9180 30.0000 1.0000
3.9240 19.1667 1.0000
3.9300 15.0000 1.0000
3.9360 21.3333 1.0000
3.9420 23.6667 1.0000
3.9480 16.0000 1.0000
3.9540 25.8333 1.0000
3.9600 18.3333 1.0000
3.9660 30.0000 1.0000
3.9720 15.8333 1.0000
3.9780 18.0000 1.0000
3.9840 22.0000 1.0000
3.9900 26.5000 1.0000
3.9960 29.1667 1.0000
4.0020 22.0000 1.0000
4.0080 29.3333 1.0000
4.0140 23.0000 1.0000
4.0200 22.0000 1.0000
4.0260 22.3333 1.0000
4.0320 14.3333 1.0000
4.0380 18.6667 1.0000
4.0440 33.5000 1.0000
4.0500 17.8333 1.0000
4.0560 15.3333 1.0000
4.0620 18.6667 1.0000
4.0680 17.8333 1.0000
4.0740 17.3333 1.0000
4.0800 23.3333 1.0000
4.0860 19.6667 1.0000
4.0920 21.6667 1.0000
4.0980 19.8333 1.0000
4.1040 26.3333 1.0000
4.1100 12.8333 1.0000
4.1160 20.3333 1.0000
4.1220 14.0000 1.0000
4.1280 18.1667 1.0000
4.1340 13.6667 1.0000
4.1400 17.0000 1.0000
4.1460 13.1667 1.0000
4.1520 15.5000 1.0000
4.1580 12.0000 1.0000
4.1640 15.6667 1.0000
4.1700 16.1667 1.0000
4.1760 15.0000 1.0000
4.1820 17.8333 1.0000
4.1880 16.1667 1.0000
4.1940 16.1667 1.0000
4.2000 17.0000 1.0000
4.2060 14.5000 1.0000
4.2120 17.6667 1.0000
4.2180 21.8333 1.0000
4.2240 14.1667 1.0000
4.2300 8.8333 1.0000
4.2360 16.8333 1.0000
4.2420 23.6667 1.0000
4.2480 12.3333 1.0000
4.2540 18.0000 1.0000
4.2600 13.1667 1.0000
4.2660 8.1667 1.0000
4.2720 10.5000 1.0000
4.2780 19.0000 1.0000
4.2840 12.5000 1.0000
4.2900 13.5000 1.0000
4.2960 15.1667 1.0000
4.3020 17.8333 1.0000
4.3080 9.0000 1.0000
4.3140 14.5000 1.0000
4.3200 11.6667 1.0000
4.3260 6.5000 1.0000
4.3320 19.0000 1.0000
4.3380 18.0000 1.0000
4.3440 16.0000 1.0000
4.3500 16.6667 1.0000
4.3560 10.1667 1.0000
4.3620 12.1667 1.0000
4.3680 5.0000 1.0000
4.3740 9.3333 1.0000
4.3800 7.8333 1.0000
4.3860 19.6667 1.0000
4.3920 11.1667 1.0000
4.3980 8.0000 1.0000
4.4040 12.5000 1.0000
4.4100 10.6667 1.0000
4.4160 10.6667 1.0000
4.4220 7.3333 1.0000
4.4280 15.0000 1.0000
4.4340 8.0000 1.0000
4.4400 14.8333 1.0000
4.4460 18.5000 1.0000
4.4520 14.6667 1.0000
4.4580 17.3333 1.0000
4.4640 10.8333 1.0000
4.4700 12.1667 1.0000
4.4760 7.5000 1.0000
4.4820 8.3333 1.0000
4.4880 2.1667 1.0000
4.4940 13.8333 1.0000
4.5000 11.6667 1.0000
4.5060 7.8333 1.0000
4.5120 8.6667 1.0000
4.5180 12.6667 1.0000
4.5240 9.6667 1.0000
4.5300 7.5000 1.0000
4.5360 5.8333 1.0000
4.5420 8.5000 1.0000
4.5480 13.3333 1.0000
4.5540 8.0000 1.0000
4.5600 14.5000 1.0000
4.5660 8.0000 1.0000
4.5720 13.1667 1.0000
4.5780 8.5000 1.0000
4.5840 8.6667 1.0000
4.5900 6.5000 1.0000
4.5960 5.1667 1.0000
4.6020 12.3333 1.0000
4.6080 10.8333 1.0000
4.6140 13.8333 1.0000
4.6200 12.0000 1.0000
4.6260 12.1667 1.0000
4.6320 4.0000 1.0000
4.6380 6.8333 1.0000
4.6440 6.5000 1.0000
4.6500 6.3333 1.0000
4.6560 9.5000 1.0000
4.6620 14.0000 1.0000
4.6680 8.0000 1.0000
4.6740 8.6667 1.0000
4.6800 7.8333 1.0000
4.6860 5.6667 1.0000
4.6920 9.6667 1.0000
4.6980 10.8333 1.0000
4.7040 5.8333 1.0000
4.7100 6.1667 1.0000
4.7160 7.5000 1.0000
4.7220 8.5000 1.0000
4.7280 9.0000 1.0000
4.7340 2.5000 1.0000
4.7400 6.5000 1.0000
4.7460 6.6667 1.0000
4.7520 7.6667 1.0000
4.7580 6.8333 1.0000
4.7640 13.1667 1.0000
4.7700 3.3333 1.0000
4.7760 6.0000 1.0000
4.7820 10.5000 1.0000
4.7880 11.3333 1.0000
4.7940 7.6667 1.0000
4.8000 2.5000 1.0000
4.8060 4.8333 1.0000
4.8120 7.8333 1.0000
4.8180 6.6667 1.0000
4.8240 3.8333 1.0000
4.8300 9.5000 1.0000
4.8360 12.0000 1.0000
4.8420 5.5000 1.0000
4.8480 9.3333 1.0000
4.8540 4.5000 1.0000
4.8600 7.5000 1.0000
4.8660 3.5000 1.0000
4.8720 5.6667 1.0000
4.8780 5.0000 1.0000
4.8840 7.3333 1.0000
4.8900 2.6667 1.0000
4.8960 1.5000 1.0000
4.9020 3.5000 1.0000
4.9080 3.5000 1.0000
4.9140 5.3333 1.0000
4.9200 0.0000 1.0000
4.9260 13.1667 1.0000
4.9320 5.3333 1.0000
4.9380 4.1667 1.0000
4.9440 5.3333 1.0000
4.9500 10.5000 1.0000
4.9560 3.6667 1.0000
4.9620 3.3333 1.0000
4.9680 4.3333 1.0000
4.9740 3.8333 1.0000
4.9800 4.6667 1.0000
4.9860 4.5000 1.0000
4.9920 1.3333 1.0000
4.9980 3.3333 1.0000
5.0040 6.0000 1.0000
5.0100 3.5000 1.0000
5.0160 5.5000 1.0000
5.0220 2.6667 1.0000
5.0280 4.5000 1.0000
5.0340 3.3333 1.0000
5.0400 3.3333 1.0000
5.0460 0.1667 1.0000
5.0520 5.1667 1.0000
5.0580 5.5000 1.0000
5.0640 6.1667 1.0000
5.0700 5.1667 1.0000
5.0760 7.0000 1.0000
5.0820 3.8333 1.0000
5.0880 6.3333 1.0000
5.0940 3.3333 1.0000
5.1000 0.1667 1.0000
5.1060 3.1667 1.0000
5.1120 2.5000 1.0000
5.1180 3.3333 1.0000
5.1240 2.0000 1.0000
5.1300 5.1667 1.0000
5.1360 7.1667 1.0000
5.1420 5.3333 1.0000
5.1480 2.1667 1.0000
5.1540 3.3333 1.0000
5.1600 3.3333 1.0000
5.1660 4.5000 1.0000
5.1720 2.1667 1.0000
5.1780 2.5000 1.0000
5.1840 3.1667 1.0000
5.1900 4.3333 1.0000
5.1960 7.3333 1.0000
5.2020 6.1667 1.0000
5.2080 4.8333 1.0000
5.2140 3.6667 1.0000
5.2200 5.1667 1.0000
5.2260 4.6667 1.0000
5.2320 0.3333 1.0000
5.2380 0.0000 1.0000
5.2440 4.3333 1.0000
5.2500 2.5000 1.0000
5.2560 3.1667 1.0000
5.2620 6.3333 1.0000
5.2680 4.6667 1.0000
5.2740 3.1667 1.0000
5.2800 0.1667 1.0000
5.2860 6.0000 1.0000
5.2920 2.1667 1.0000
5.2980 2.6667 1.0000
5.3040 5.1667 1.0000
5.3100 3.1667 1.0000
5.3160 6.5000 1.0000
5.3220 0.1667 1.0000
5.3280 5.8333 1.0000
5.3340 2.1667 1.0000
5.3400 3.3333 1.0000
5.3460 0.1667 1.0000
5.3520 3.3333 1.0000
5.3580 0.0000 1.0000
5.3640 5.1667 1.0000
5.3700 3.5000 1.0000
5.3760 3.1667 1.0000
5.3820 3.3333 1.0000
5.3880 2.0000 1.0000
5.3940 3.5000 1.0000
5.4000 4.3333 1.0000
5.4060 2.1667 1.0000
5.4120 0.0000 1.0000
5.4180 1.1667 1.0000
5.4240 6.3333 1.0000
5.4300 5.0000 1.0000
5.4360 0.1667 1.0000
5.4420 2.5000 1.0000
5.4480 2.3333 1.0000
5.4540 3.5000 1.0000
5.4600 2.3333 1.0000
5.4660 4.0000 1.0000
5.4720 2.5000 1.0000
5.4780 4.5000 1.0000
5.4840 3.1667 1.0000
5.4900 4.5000 1.0000
5.4960 0.5000 1.0000
5.5020 1.5000 1.0000
5.5080 1.1667 1.0000
5.5140 4.1667 1.0000
5.5200 2.6667 1.0000
5.5260 2.1667 1.0000
5.5320 5.3333 1.0000
5.5380 0.0000 1.0000
5.5440 3.1667 1.0000
5.5500 0.1667 1.0000
5.5560 0.1667 1.0000
5.5620 0.0000 1.0000
5.5680 1.1667 1.0000
5.5740 0.1667 1.0000
5.5800 2.3333 1.0000
5.5860 2.5000 1.0000
5.5920 1.1667 1.0000
5.5980 3.3333 1.0000
5.6040 2.0000 1.0000
5.6100 2.5000 1.0000
5.6160 2.5000 1.0000
5.6220 2.0000 1.0000
5.6280 0.0000 1.0000
5.6340 4.1667 1.0000
5.6400 2.1667 1.0000
5.6460 2.1667 1.0000
5.6520 0.0000 1.0000
5.6580 4.6667 1.0000
5.6640 2.1667 1.0000
5.6700 1.1667 1.0000
5.6760 0.0000 1.0000
5.6820 0.3333 1.0000
5.6880 0.6667 1.0000
5.6940 1.1667 1.0000
5.7000 2.1667 1.0000
5.7060 3.1667 1.0000
5.7120 1.1667 1.0000
5.7180 0.3333 1.0000
5.7240 0.1667 1.0000
5.7300 0.1667 1.0000
5.7360 3.3333 1.0000
5.7420 2.3333 1.0000
5.7480 4.3333 1.0000
5.7540 4.0000 1.0000
5.7600 6.1667 1.0000
5.7660 0.3333 1.0000
5.7720 0.0000 1.0000
5.7780 1.1667 1.0000
5.7840 0.3333 1.0000
5.7900 2.1667 1.0000
5.7960 0.0000 1.0000
5.8020 2.0000 1.0000
5.8080 0.0000 1.0000
5.8140 1.5000 1.0000
5.8200 2.0000 1.0000
5.8260 0.0000 1.0000
5.8320 2.0000 1.0000
5.8380 0.0000 1.0000
5.8440 5.0000 1.0000
5.8500 5.1667 1.0000
5.8560 0.0000 1.0000
5.8620 3.0000 1.0000
5.8680 0.1667 1.0000
5.8740 1.1667 1.0000
5.8800 0.0000 1.0000
5.8860 1.1667 1.0000
5.8920 0.0000 1.0000
5.8980 1.1667 1.0000
5.9040 0.3333 1.0000
5.9100 2.0000 1.0000
5.9160 4.1667 1.0000
5.9220 5.1667 1.0000
5.9280 1.3333 1.0000
5.9340 3.1667 1.0000
5.9400 3.0000 1.0000
5.9460 2.0000 1.0000
5.9520 4.0000 1.0000
5.9580 0.1667 1.0000
5.9640 0.1667 1.0000
5.9700 3.0000 1.0000
5.9760 5.1667 1.0000
5.9820 2.3333 1.0000
5.9880 0.1667 1.0000
5.9940 0.0000 1.0000
6.0000 0.1667 1.0000
*RAS_INT_END
*RAS_DATA_END