File: XRR/CWOI9anneal_reflectivity.ras
*RAS_DATA_START
*RAS_HEADER_START
*DISP_FMT_X "%.4f"
*DISP_FMT_Y "%.0f"
*DISP_FULLSCALE "30797424.3500000010"
*DISP_LINE_COLOR "255.0000000000"
*DISP_LINE_STYLE "0.0000000000"
*DISP_LINE_WIDTH "0.2500000000"
*DISP_NOTE "Collected Data-19"
*DISP_OFFSET_Y "0.0000000000"
*DISP_PEAKSEARCH_UNIT_Y "cps"
*DISP_RANGE_BOTTOM "0.0100000000"
*DISP_RANGE_LEFT "-0.0006000000"
*DISP_RANGE_LOGCUTOFF "0.0100000000"
*DISP_RANGE_RIGHT "6.0006000000"
*DISP_RANGE_TOP "30797424.3500000010"
*DISP_SCALE_MODE_Y "2.0000000000"
*DISP_TAB_NAME "2-Theta/Omega"
*DISP_TITLE_Y "Intensity"
*DISP_UNIT_Y "cps"
*DISP_WINDOW_NAME "MSG_MACROENGINE"
*FILE_COMMENT " "
*FILE_MD5 ""
*FILE_MEMO " "
*FILE_OPERATOR "administrator"
*FILE_PART_ID "MEAS_KHP2_00055"
*FILE_SAMPLE "CWOI9anneal"
*FILE_TYPE "RAS_RAW"
*FILE_USERGROUP "System Manager"
*FILE_VERSION "1.0000000000"
*HW_ATTACHMENT_ID "ATT0025"
*HW_ATTACHMENT_NAME "標準|Standard"
*HW_COUNTER_ID-0 "CUT0025"
*HW_COUNTER_ID-1 "CUT0020"
*HW_COUNTER_ID-2 "CUT0020"
*HW_COUNTER_ID-3 "CSL0021"
*HW_COUNTER_ID-4 "CMC0021"
*HW_COUNTER_NAME-0 "D/teX Ultra|D/teX Ultra"
*HW_COUNTER_NAME-1 "None|None"
*HW_COUNTER_NAME-2 "None|None"
*HW_COUNTER_NAME-3 "BBM|BBM"
*HW_COUNTER_NAME-4 "検出器モノクロメータ|Detector monochromator"
*HW_COUNTER_SELECT_NAME "D/teX Ultra|D/teX Ultra"
*HW_GONIOMETER_ID "GON0023"
*HW_GONIOMETER_NAME "SmartLab|SmartLab"
*HW_GONIOMETER_RADIUS-0 "90.0"
*HW_GONIOMETER_RADIUS-1 "114.0"
*HW_GONIOMETER_RADIUS-2 "190.0"
*HW_GONIOMETER_RADIUS-3 "300.0"
*HW_GONIOMETER_RADIUS-4 "187.0"
*HW_GONIOMETER_RADIUS-5 "300.0"
*HW_GONIOMETER_RADIUS-6 "113.0"
*HW_GONIOMETER_RADIUS-7 "331.0"
*HW_I_OPT_ID-0 "CBO0021"
*HW_I_OPT_ID-1 "ICR0021"
*HW_I_OPT_ID-2 "ISL0021"
*HW_I_OPT_ID-3 "ISO0021"
*HW_I_OPT_ID-4 "IAD0021"
*HW_I_OPT_ID-5 "IPR0001"
*HW_I_OPT_NAME-0 "CBOユニット|CBO unit"
*HW_I_OPT_NAME-1 "標準入射光学ユニット|Standard incident optical unit"
*HW_I_OPT_NAME-2 "標準入射スリットボックス|Standard incident slit box"
*HW_I_OPT_NAME-3 "入射平行スリット|Incident parallel slit"
*HW_I_OPT_NAME-4 "長手制限スリット|Length limiting slit"
*HW_I_OPT_NAME-5 "None|None"
*HW_R_ATTENUATER_AUTOMODE "1"
*HW_R_OPT_ID-0 "RSS0021"
*HW_R_OPT_ID-1 "RCR0023"
*HW_R_OPT_ID-2 "RSO0021"
*HW_R_OPT_ID-3 "RRS0021"
*HW_R_OPT_ID-4 "ATN0021"
*HW_R_OPT_ID-5 "RFL0021"
*HW_R_OPT_ID-6 "RAD0021"
*HW_R_OPT_NAME-0 "標準受光スリットボックス1|Standard receiving slit box # 1"
*HW_R_OPT_NAME-1 "標準受光光学ユニット1|Standard receiving unit # 1"
*HW_R_OPT_NAME-2 "標準受光光学ユニット2|Standard receiving optical unit # 2"
*HW_R_OPT_NAME-3 "標準受光スリットボックス2|Standard receiving slit box # 2"
*HW_R_OPT_NAME-4 "標準アッテネータ|Standard Attenuator"
*HW_R_OPT_NAME-5 "Cu Kβ|Cu K-beta"
*HW_R_OPT_NAME-6 "調整用受光スリット|Alignment receiving slit"
*HW_SAMPLE_HOLDER_ID "SMP0021"
*HW_SAMPLE_HOLDER_NAME "χφZクレードル|Chi phi Z cradle"
*HW_XG_CURRENT_MAX "200"
*HW_XG_CURRENT_MIN "10"
*HW_XG_CURRENT_RESOLUTION "1"
*HW_XG_CURRENT_UNIT "mA"
*HW_XG_FOCUS "0.4mm x 8mm"
*HW_XG_FOCUS_TYPE "Normal"
*HW_XG_ID "1700"
*HW_XG_NAME "9kW 開放管(45kV 200mA ID:1700)|9kW Rotating anode(45kV 200mA ID:1700)"
*HW_XG_TARGET_ATOMIC_NUMBER "29.0000000000"
*HW_XG_TARGET_NAME "Cu"
*HW_XG_TYPE "Rota"
*HW_XG_VOLTAGE_MAX "45"
*HW_XG_VOLTAGE_MIN "20"
*HW_XG_VOLTAGE_RESOLUTION "1"
*HW_XG_VOLTAGE_UNIT "kV"
*HW_XG_WATT_MAX "9.00"
*HW_XG_WATT_UNIT "kW"
*HW_XG_WAVE_LENGTH_ALPHA1 "1.540593"
*HW_XG_WAVE_LENGTH_ALPHA2 "1.544414"
*HW_XG_WAVE_LENGTH_BETA "1.392250"
*MEAS_COND_AXIS_NAME-0 "Theta/2-Theta"
*MEAS_COND_AXIS_NAME-1 "2-Theta"
*MEAS_COND_AXIS_NAME-2 "Omega"
*MEAS_COND_AXIS_NAME-3 "Chi"
*MEAS_COND_AXIS_NAME-4 "Phi"
*MEAS_COND_AXIS_NAME-5 "Z"
*MEAS_COND_AXIS_NAME-6 "2-Theta/Omega"
*MEAS_COND_AXIS_NAME-7 "Theta_s"
*MEAS_COND_AXIS_NAME-8 "Theta_d"
*MEAS_COND_AXIS_NAME-9 "Ts"
*MEAS_COND_AXIS_NAME-10 "CBO selection slit"
*MEAS_COND_AXIS_NAME-11 "M"
*MEAS_COND_AXIS_NAME-12 "Incident parallel slit"
*MEAS_COND_AXIS_NAME-13 "Incident slit"
*MEAS_COND_AXIS_NAME-14 ""
*MEAS_COND_AXIS_NAME-15 "Zs"
*MEAS_COND_AXIS_NAME-16 "Incident optical device"
*MEAS_COND_AXIS_NAME-17 "Omega_m"
*MEAS_COND_AXIS_NAME-18 "Length limiting slit"
*MEAS_COND_AXIS_NAME-19 "Center slit"
*MEAS_COND_AXIS_NAME-20 "Filter"
*MEAS_COND_AXIS_NAME-21 "Receiving slit # 1"
*MEAS_COND_AXIS_NAME-22 "Receiving slit # 2"
*MEAS_COND_AXIS_NAME-23 "Receiving optical device"
*MEAS_COND_AXIS_NAME-24 "Receiving parallel slit"
*MEAS_COND_AXIS_NAME-25 "Alignment receiving slit"
*MEAS_COND_AXIS_NAME-26 ""
*MEAS_COND_AXIS_NAME-27 ""
*MEAS_COND_AXIS_NAME-28 "Zd"
*MEAS_COND_AXIS_NAME-29 "Attenuator"
*MEAS_COND_AXIS_NAME-30 "Diffracted beam monochromator"
*MEAS_COND_AXIS_NAME-31 "Monochromator slit"
*MEAS_COND_AXIS_NAME-32 "Primary beam"
*MEAS_COND_AXIS_NAME-33 ""
*MEAS_COND_AXIS_NAME-34 ""
*MEAS_COND_AXIS_NAME-35 "PHA"
*MEAS_COND_AXIS_NAME_INTERNAL-0 "TwoThetaTheta"
*MEAS_COND_AXIS_NAME_INTERNAL-1 "TwoTheta"
*MEAS_COND_AXIS_NAME_INTERNAL-2 "Omega"
*MEAS_COND_AXIS_NAME_INTERNAL-3 "Chi"
*MEAS_COND_AXIS_NAME_INTERNAL-4 "Phi"
*MEAS_COND_AXIS_NAME_INTERNAL-5 "Z"
*MEAS_COND_AXIS_NAME_INTERNAL-6 "TwoThetaOmega"
*MEAS_COND_AXIS_NAME_INTERNAL-7 "ThetaS"
*MEAS_COND_AXIS_NAME_INTERNAL-8 "ThetaD"
*MEAS_COND_AXIS_NAME_INTERNAL-9 "Ts"
*MEAS_COND_AXIS_NAME_INTERNAL-10 "CBO"
*MEAS_COND_AXIS_NAME_INTERNAL-11 "CBO-M"
*MEAS_COND_AXIS_NAME_INTERNAL-12 "IncidentSollerSlit"
*MEAS_COND_AXIS_NAME_INTERNAL-13 "IncidentSlitBox"
*MEAS_COND_AXIS_NAME_INTERNAL-14 "IncidentSlitBox-_Axis"
*MEAS_COND_AXIS_NAME_INTERNAL-15 "Zs"
*MEAS_COND_AXIS_NAME_INTERNAL-16 "IncidentMonochromator"
*MEAS_COND_AXIS_NAME_INTERNAL-17 "IncidentMonochromator-OmegaM"
*MEAS_COND_AXIS_NAME_INTERNAL-18 "IncidentAxdSlit"
*MEAS_COND_AXIS_NAME_INTERNAL-19 "CenterSlit"
*MEAS_COND_AXIS_NAME_INTERNAL-20 "Filter"
*MEAS_COND_AXIS_NAME_INTERNAL-21 "ReceivingSlitBox1"
*MEAS_COND_AXIS_NAME_INTERNAL-22 "ReceivingSlitBox2"
*MEAS_COND_AXIS_NAME_INTERNAL-23 "ReceivingOptics"
*MEAS_COND_AXIS_NAME_INTERNAL-24 "ReceivingSollerSlit"
*MEAS_COND_AXIS_NAME_INTERNAL-25 "ReceivingAxdSlit"
*MEAS_COND_AXIS_NAME_INTERNAL-26 "ReceivingSlitBox1-_Axis"
*MEAS_COND_AXIS_NAME_INTERNAL-27 "ReceivingSlitBox2-_Axis"
*MEAS_COND_AXIS_NAME_INTERNAL-28 "ReceivingSlitBox2-Zd"
*MEAS_COND_AXIS_NAME_INTERNAL-29 "Attenuator"
*MEAS_COND_AXIS_NAME_INTERNAL-30 "CounterMonochromator"
*MEAS_COND_AXIS_NAME_INTERNAL-31 "CounterSlit"
*MEAS_COND_AXIS_NAME_INTERNAL-32 "IncidentPrimary"
*MEAS_COND_AXIS_NAME_INTERNAL-33 "AlphaR"
*MEAS_COND_AXIS_NAME_INTERNAL-34 "BetaR"
*MEAS_COND_AXIS_NAME_INTERNAL-35 "PHA"
*MEAS_COND_AXIS_NAME_MAGICNO-0 "83951616.0000000000"
*MEAS_COND_AXIS_NAME_MAGICNO-1 "268632064.0000000000"
*MEAS_COND_AXIS_NAME_MAGICNO-2 "268500992.0000000000"
*MEAS_COND_AXIS_NAME_MAGICNO-3 "268500992.0000000000"
*MEAS_COND_AXIS_NAME_MAGICNO-4 "268500992.0000000000"
*MEAS_COND_AXIS_NAME_MAGICNO-5 "285278208.0000000000"
*MEAS_COND_AXIS_NAME_MAGICNO-6 "83951616.0000000000"
*MEAS_COND_AXIS_NAME_MAGICNO-7 "131072.0000000000"
*MEAS_COND_AXIS_NAME_MAGICNO-8 "131072.0000000000"
*MEAS_COND_AXIS_NAME_MAGICNO-9 "318898176.0000000000"
*MEAS_COND_AXIS_NAME_MAGICNO-10 "20971521.0000000000"
*MEAS_COND_AXIS_NAME_MAGICNO-11 "285343744.0000000000"
*MEAS_COND_AXIS_NAME_MAGICNO-12 "20971521.0000000000"
*MEAS_COND_AXIS_NAME_MAGICNO-13 "22020097.0000000000"
*MEAS_COND_AXIS_NAME_MAGICNO-14 "25165824.0000000000"
*MEAS_COND_AXIS_NAME_MAGICNO-15 "318898176.0000000000"
*MEAS_COND_AXIS_NAME_MAGICNO-16 "20971521.0000000000"
*MEAS_COND_AXIS_NAME_MAGICNO-17 "285343744.0000000000"
*MEAS_COND_AXIS_NAME_MAGICNO-18 "20971521.0000000000"
*MEAS_COND_AXIS_NAME_MAGICNO-19 "20971521.0000000000"
*MEAS_COND_AXIS_NAME_MAGICNO-20 "20971521.0000000000"
*MEAS_COND_AXIS_NAME_MAGICNO-21 "23068673.0000000000"
*MEAS_COND_AXIS_NAME_MAGICNO-22 "23068673.0000000000"
*MEAS_COND_AXIS_NAME_MAGICNO-23 "20971521.0000000000"
*MEAS_COND_AXIS_NAME_MAGICNO-24 "20971521.0000000000"
*MEAS_COND_AXIS_NAME_MAGICNO-25 "20971521.0000000000"
*MEAS_COND_AXIS_NAME_MAGICNO-26 "25165824.0000000000"
*MEAS_COND_AXIS_NAME_MAGICNO-27 "25165824.0000000000"
*MEAS_COND_AXIS_NAME_MAGICNO-28 "285343744.0000000000"
*MEAS_COND_AXIS_NAME_MAGICNO-29 "17301505.0000000000"
*MEAS_COND_AXIS_NAME_MAGICNO-30 "20971521.0000000000"
*MEAS_COND_AXIS_NAME_MAGICNO-31 "20971521.0000000000"
*MEAS_COND_AXIS_NAME_MAGICNO-32 "20971521.0000000000"
*MEAS_COND_AXIS_NAME_MAGICNO-33 "8388608.0000000000"
*MEAS_COND_AXIS_NAME_MAGICNO-34 "8388608.0000000000"
*MEAS_COND_AXIS_NAME_MAGICNO-35 "0.0000000000"
*MEAS_COND_AXIS_OFFSET-0 "-"
*MEAS_COND_AXIS_OFFSET-1 "0.8835000000"
*MEAS_COND_AXIS_OFFSET-2 "0.6952000000"
*MEAS_COND_AXIS_OFFSET-3 "0.0000000000"
*MEAS_COND_AXIS_OFFSET-4 "0.0000000000"
*MEAS_COND_AXIS_OFFSET-5 "-"
*MEAS_COND_AXIS_OFFSET-6 "-"
*MEAS_COND_AXIS_OFFSET-7 "0.6952000000"
*MEAS_COND_AXIS_OFFSET-8 "0.1883000000"
*MEAS_COND_AXIS_OFFSET-9 "-"
*MEAS_COND_AXIS_OFFSET-10 "-"
*MEAS_COND_AXIS_OFFSET-11 "-"
*MEAS_COND_AXIS_OFFSET-12 "-"
*MEAS_COND_AXIS_OFFSET-13 "-"
*MEAS_COND_AXIS_OFFSET-14 "-"
*MEAS_COND_AXIS_OFFSET-15 "-"
*MEAS_COND_AXIS_OFFSET-16 "-"
*MEAS_COND_AXIS_OFFSET-17 "-"
*MEAS_COND_AXIS_OFFSET-18 "-"
*MEAS_COND_AXIS_OFFSET-19 "-"
*MEAS_COND_AXIS_OFFSET-20 "-"
*MEAS_COND_AXIS_OFFSET-21 "-"
*MEAS_COND_AXIS_OFFSET-22 "-"
*MEAS_COND_AXIS_OFFSET-23 "-"
*MEAS_COND_AXIS_OFFSET-24 "-"
*MEAS_COND_AXIS_OFFSET-25 "-"
*MEAS_COND_AXIS_OFFSET-26 "-"
*MEAS_COND_AXIS_OFFSET-27 "-"
*MEAS_COND_AXIS_OFFSET-28 "-"
*MEAS_COND_AXIS_OFFSET-29 "-"
*MEAS_COND_AXIS_OFFSET-30 "-"
*MEAS_COND_AXIS_OFFSET-31 "-"
*MEAS_COND_AXIS_OFFSET-32 "-"
*MEAS_COND_AXIS_OFFSET-33 "0.0000000000"
*MEAS_COND_AXIS_OFFSET-34 "0.0000000000"
*MEAS_COND_AXIS_OFFSET-35 "-"
*MEAS_COND_AXIS_POSITION-0 "-0.0008000000"
*MEAS_COND_AXIS_POSITION-1 "-0.0009000000"
*MEAS_COND_AXIS_POSITION-2 "-0.0004000000"
*MEAS_COND_AXIS_POSITION-3 "0.0000000000"
*MEAS_COND_AXIS_POSITION-4 "0.0000000000"
*MEAS_COND_AXIS_POSITION-5 "-1.4106000000"
*MEAS_COND_AXIS_POSITION-6 "-0.0008000000"
*MEAS_COND_AXIS_POSITION-7 "-0.0004000000"
*MEAS_COND_AXIS_POSITION-8 "-0.0005000000"
*MEAS_COND_AXIS_POSITION-9 "-4.7109400000"
*MEAS_COND_AXIS_POSITION-10 "PB"
*MEAS_COND_AXIS_POSITION-11 "0.0000000000"
*MEAS_COND_AXIS_POSITION-12 "Soller_slit_open_s"
*MEAS_COND_AXIS_POSITION-13 "0.250mm"
*MEAS_COND_AXIS_POSITION-14 "0.2500000000"
*MEAS_COND_AXIS_POSITION-15 "-1.7440600000"
*MEAS_COND_AXIS_POSITION-16 "Ge(220)x2"
*MEAS_COND_AXIS_POSITION-17 "0.0000000000"
*MEAS_COND_AXIS_POSITION-18 "2.0mm"
*MEAS_COND_AXIS_POSITION-19 "None"
*MEAS_COND_AXIS_POSITION-20 "None"
*MEAS_COND_AXIS_POSITION-21 "0.250mm"
*MEAS_COND_AXIS_POSITION-22 "0.250mm"
*MEAS_COND_AXIS_POSITION-23 "No_unit"
*MEAS_COND_AXIS_POSITION-24 "Soller_slit_5.0deg"
*MEAS_COND_AXIS_POSITION-25 "None"
*MEAS_COND_AXIS_POSITION-26 "0.2500000000"
*MEAS_COND_AXIS_POSITION-27 "0.2500000000"
*MEAS_COND_AXIS_POSITION-28 "0.0890600000"
*MEAS_COND_AXIS_POSITION-29 "1/10000"
*MEAS_COND_AXIS_POSITION-30 "None"
*MEAS_COND_AXIS_POSITION-31 "None"
*MEAS_COND_AXIS_POSITION-32 "None"
*MEAS_COND_AXIS_POSITION-33 "0.0000000000"
*MEAS_COND_AXIS_POSITION-34 "0.0000000000"
*MEAS_COND_AXIS_POSITION-35 "34.0000000000"
*MEAS_COND_AXIS_UNIT-0 "deg"
*MEAS_COND_AXIS_UNIT-1 "deg"
*MEAS_COND_AXIS_UNIT-2 "deg"
*MEAS_COND_AXIS_UNIT-3 "deg"
*MEAS_COND_AXIS_UNIT-4 "deg"
*MEAS_COND_AXIS_UNIT-5 "mm"
*MEAS_COND_AXIS_UNIT-6 "deg"
*MEAS_COND_AXIS_UNIT-7 "deg"
*MEAS_COND_AXIS_UNIT-8 "deg"
*MEAS_COND_AXIS_UNIT-9 "mm"
*MEAS_COND_AXIS_UNIT-10 ""
*MEAS_COND_AXIS_UNIT-11 "pulse"
*MEAS_COND_AXIS_UNIT-12 ""
*MEAS_COND_AXIS_UNIT-13 ""
*MEAS_COND_AXIS_UNIT-14 "mm"
*MEAS_COND_AXIS_UNIT-15 "mm"
*MEAS_COND_AXIS_UNIT-16 ""
*MEAS_COND_AXIS_UNIT-17 "pulse"
*MEAS_COND_AXIS_UNIT-18 ""
*MEAS_COND_AXIS_UNIT-19 ""
*MEAS_COND_AXIS_UNIT-20 ""
*MEAS_COND_AXIS_UNIT-21 ""
*MEAS_COND_AXIS_UNIT-22 ""
*MEAS_COND_AXIS_UNIT-23 ""
*MEAS_COND_AXIS_UNIT-24 ""
*MEAS_COND_AXIS_UNIT-25 ""
*MEAS_COND_AXIS_UNIT-26 "mm"
*MEAS_COND_AXIS_UNIT-27 "mm"
*MEAS_COND_AXIS_UNIT-28 "mm"
*MEAS_COND_AXIS_UNIT-29 ""
*MEAS_COND_AXIS_UNIT-30 ""
*MEAS_COND_AXIS_UNIT-31 ""
*MEAS_COND_AXIS_UNIT-32 ""
*MEAS_COND_AXIS_UNIT-33 "deg"
*MEAS_COND_AXIS_UNIT-34 "deg"
*MEAS_COND_AXIS_UNIT-35 "div"
*MEAS_COND_COUNTER_CNTLOSS_CORR "0.0000000000"
*MEAS_COND_COUNTER_PHABASE "34.0000000000"
*MEAS_COND_COUNTER_PHAWINDOW "19.0000000000"
*MEAS_COND_COUNTER_PHA_UNIT "div"
*MEAS_COND_COUNTER_TAUDIFF "2.0000000000"
*MEAS_COND_COUNTER_TAUINT "0.1000000000"
*MEAS_COND_IRRADIATION_MODE "OFF"
*MEAS_COND_IRRADIATION_WIDTH ""
*MEAS_COND_OPT_ATTR "High resolution parallel beam Ge(220)x2/RS"
*MEAS_COND_OPT_NAME "@High resolution PB-Ge(220)x2"
*MEAS_COND_UNSYMMETRIC_MODE "OFF"
*MEAS_COND_XG_CURRENT "200.0000000000"
*MEAS_COND_XG_VOLTAGE "45.0000000000"
*MEAS_COND_XG_WAVE_TYPE "Ka1"
*MEAS_DATA_COUNT "3001.0000000000"
*MEAS_SCAN_AXIS_X "2-Theta/Omega"
*MEAS_SCAN_AXIS_X_INTERNAL "TwoThetaOmega"
*MEAS_SCAN_END_TIME "11/09/23 21:15:50"
*MEAS_SCAN_MODE "CONTINUOUS"
*MEAS_SCAN_MONITOR "0"
*MEAS_SCAN_RESOLUTION_X "0.0002"
*MEAS_SCAN_SPEED "0.500000"
*MEAS_SCAN_SPEED_UNIT "deg/min"
*MEAS_SCAN_SPEED_USER "0.500000"
*MEAS_SCAN_START "0.0000000000"
*MEAS_SCAN_START_TIME "11/09/23 21:03:22"
*MEAS_SCAN_STEP "0.0020000000"
*MEAS_SCAN_STOP "6.0000000000"
*MEAS_SCAN_UNIT_X "deg"
*MEAS_SCAN_UNIT_Y "counts"
*RAS_HEADER_END
*RAS_INT_START
0.0000 5613185.5000 1.0000
0.0060 5863647.5000 1.0000
0.0120 5603531.5000 1.0000
0.0180 5443545.0000 1.0000
0.0240 5104952.5000 1.0000
0.0300 5013787.5000 1.0000
0.0360 4537000.0000 1.0000
0.0420 3669624.0000 1.0000
0.0480 2751494.0000 1.0000
0.0540 1939286.0000 1.0000
0.0600 1211898.6250 1.0000
0.0660 585822.5000 1.0000
0.0720 282998.3438 1.0000
0.0780 160386.5781 1.0000
0.0840 104111.6328 1.0000
0.0900 86140.2891 1.0000
0.0960 78618.0938 1.0000
0.1020 77620.1016 1.0000
0.1080 78685.1250 1.0000
0.1140 81232.2500 1.0000
0.1200 82982.4609 1.0000
0.1260 89484.3125 1.0000
0.1320 90102.4766 1.0000
0.1380 96276.6328 1.0000
0.1440 96552.1953 1.0000
0.1500 99747.2656 1.0000
0.1560 107016.2422 1.0000
0.1620 111857.2578 1.0000
0.1680 111574.2422 1.0000
0.1740 119319.8672 1.0000
0.1800 119982.7188 1.0000
0.1860 123021.3828 1.0000
0.1920 121621.2109 1.0000
0.1980 130848.9375 1.0000
0.2040 133343.9219 1.0000
0.2100 133016.2188 1.0000
0.2160 135608.0313 1.0000
0.2220 142973.8125 1.0000
0.2280 144470.8125 1.0000
0.2340 151300.3594 1.0000
0.2400 151449.3125 1.0000
0.2460 158420.3750 1.0000
0.2520 160215.2813 1.0000
0.2580 168355.6406 1.0000
0.2640 161392.0156 1.0000
0.2700 167782.1563 1.0000
0.2760 171535.8125 1.0000
0.2820 177553.5625 1.0000
0.2880 180108.1250 1.0000
0.2940 182349.8906 1.0000
0.3000 188941.1250 1.0000
0.3060 190601.9688 1.0000
0.3120 189328.4063 1.0000
0.3180 189663.5469 1.0000
0.3240 193797.0313 1.0000
0.3300 197088.9219 1.0000
0.3360 202116.1406 1.0000
0.3420 196954.8594 1.0000
0.3480 210204.3594 1.0000
0.3540 208781.8438 1.0000
0.3600 212781.2656 1.0000
0.3660 213079.1719 1.0000
0.3720 220139.6094 1.0000
0.3780 218545.7969 1.0000
0.3840 225978.6250 1.0000
0.3900 225099.7969 1.0000
0.3960 224302.8906 1.0000
0.4020 225472.1719 1.0000
0.4080 230112.0938 1.0000
0.4140 233351.8594 1.0000
0.4200 240077.1563 1.0000
0.4260 234312.6094 1.0000
0.4320 241283.6875 1.0000
0.4380 240382.5000 1.0000
0.4440 249714.4844 1.0000
0.4500 249945.3750 1.0000
0.4560 246906.7031 1.0000
0.4620 250258.1875 1.0000
0.4680 251777.5000 1.0000
0.4740 254481.0313 1.0000
0.4800 256186.5469 1.0000
0.4860 250317.7500 1.0000
0.4920 256246.1250 1.0000
0.4980 252894.6719 1.0000
0.5040 258621.9531 1.0000
0.5100 264200.3125 1.0000
0.5160 261757.4531 1.0000
0.5220 263515.0938 1.0000
0.5280 261079.7031 1.0000
0.5340 262680.9688 1.0000
0.5400 266382.4688 1.0000
0.5460 266613.3750 1.0000
0.5520 268304.0000 1.0000
0.5580 260543.4688 1.0000
0.5640 266144.1563 1.0000
0.5700 257296.2656 1.0000
0.5760 257713.3438 1.0000
0.5820 258904.9688 1.0000
0.5880 256506.7969 1.0000
0.5940 255426.8906 1.0000
0.6000 245230.9688 1.0000
0.6060 243808.4531 1.0000
0.6120 240941.0781 1.0000
0.6180 231728.2500 1.0000
0.6240 223692.1719 1.0000
0.6300 214263.3594 1.0000
0.6360 198854.0313 1.0000
0.6420 183109.5625 1.0000
0.6480 172794.4688 1.0000
0.6540 158844.9063 1.0000
0.6600 143428.1250 1.0000
0.6660 126991.0156 1.0000
0.6720 112616.9219 1.0000
0.6780 100596.3125 1.0000
0.6840 88471.4297 1.0000
0.6900 75832.6484 1.0000
0.6960 65390.9531 1.0000
0.7020 57256.9453 1.0000
0.7080 50499.3320 1.0000
0.7140 43739.0000 1.0000
0.7200 38315.1680 1.0000
0.7260 33885.6680 1.0000
0.7320 30012.0000 1.0000
0.7380 26451.1660 1.0000
0.7440 24002.3340 1.0000
0.7500 21341.1660 1.0000
0.7560 18981.0000 1.0000
0.7620 17131.5000 1.0000
0.7680 15517.3330 1.0000
0.7740 14142.8330 1.0000
0.7800 12878.6670 1.0000
0.7860 11439.5000 1.0000
0.7920 10658.1670 1.0000
0.7980 9740.1670 1.0000
0.8040 8864.6670 1.0000
0.8100 8173.1665 1.0000
0.8160 7451.6665 1.0000
0.8220 6938.3335 1.0000
0.8280 6356.8335 1.0000
0.8340 5845.6665 1.0000
0.8400 5499.8335 1.0000
0.8460 5179.5000 1.0000
0.8520 4809.3335 1.0000
0.8580 4417.5000 1.0000
0.8640 4139.8335 1.0000
0.8700 3772.8333 1.0000
0.8760 3650.3333 1.0000
0.8820 3375.0000 1.0000
0.8880 3168.1667 1.0000
0.8940 2937.5000 1.0000
0.9000 2841.3333 1.0000
0.9060 2726.6667 1.0000
0.9120 2554.1667 1.0000
0.9180 2369.8333 1.0000
0.9240 2333.6667 1.0000
0.9300 2179.3333 1.0000
0.9360 2113.0000 1.0000
0.9420 1952.3334 1.0000
0.9480 1796.8334 1.0000
0.9540 1787.0000 1.0000
0.9600 1696.5000 1.0000
0.9660 1597.0000 1.0000
0.9720 1539.5000 1.0000
0.9780 1432.5000 1.0000
0.9840 1431.6666 1.0000
0.9900 1361.8334 1.0000
0.9960 1237.8334 1.0000
1.0020 1173.3334 1.0000
1.0080 1171.1666 1.0000
1.0140 1124.1666 1.0000
1.0200 1156.8334 1.0000
1.0260 1074.3334 1.0000
1.0320 991.6667 1.0000
1.0380 973.5000 1.0000
1.0440 947.0000 1.0000
1.0500 953.0000 1.0000
1.0560 866.0000 1.0000
1.0620 792.1667 1.0000
1.0680 787.8333 1.0000
1.0740 748.8333 1.0000
1.0800 708.3333 1.0000
1.0860 655.6667 1.0000
1.0920 627.3333 1.0000
1.0980 637.5000 1.0000
1.1040 609.1667 1.0000
1.1100 607.8333 1.0000
1.1160 576.8333 1.0000
1.1220 512.5000 1.0000
1.1280 480.6667 1.0000
1.1340 525.6667 1.0000
1.1400 505.3333 1.0000
1.1460 502.1667 1.0000
1.1520 446.3333 1.0000
1.1580 473.8333 1.0000
1.1640 425.5000 1.0000
1.1700 411.5000 1.0000
1.1760 405.3333 1.0000
1.1820 389.3333 1.0000
1.1880 372.6667 1.0000
1.1940 357.0000 1.0000
1.2000 375.0000 1.0000
1.2060 337.0000 1.0000
1.2120 327.0000 1.0000
1.2180 300.5000 1.0000
1.2240 332.8333 1.0000
1.2300 286.0000 1.0000
1.2360 279.3333 1.0000
1.2420 293.1667 1.0000
1.2480 269.5000 1.0000
1.2540 269.8333 1.0000
1.2600 282.6667 1.0000
1.2660 292.8333 1.0000
1.2720 275.6667 1.0000
1.2780 258.1667 1.0000
1.2840 248.5000 1.0000
1.2900 219.0000 1.0000
1.2960 241.8333 1.0000
1.3020 239.3333 1.0000
1.3080 236.0000 1.0000
1.3140 224.5000 1.0000
1.3200 211.3333 1.0000
1.3260 203.6667 1.0000
1.3320 182.3333 1.0000
1.3380 184.6667 1.0000
1.3440 223.0000 1.0000
1.3500 191.6667 1.0000
1.3560 156.5000 1.0000
1.3620 178.0000 1.0000
1.3680 169.3333 1.0000
1.3740 162.8333 1.0000
1.3800 162.3333 1.0000
1.3860 160.1667 1.0000
1.3920 158.5000 1.0000
1.3980 168.3333 1.0000
1.4040 165.8333 1.0000
1.4100 145.1667 1.0000
1.4160 145.1667 1.0000
1.4220 117.6667 1.0000
1.4280 123.3333 1.0000
1.4340 137.1667 1.0000
1.4400 137.5000 1.0000
1.4460 136.0000 1.0000
1.4520 132.3333 1.0000
1.4580 126.6667 1.0000
1.4640 115.1667 1.0000
1.4700 122.5000 1.0000
1.4760 126.1667 1.0000
1.4820 106.5000 1.0000
1.4880 110.6667 1.0000
1.4940 111.3333 1.0000
1.5000 119.1667 1.0000
1.5060 93.8333 1.0000
1.5120 107.3333 1.0000
1.5180 98.3333 1.0000
1.5240 100.1667 1.0000
1.5300 109.3333 1.0000
1.5360 89.6667 1.0000
1.5420 97.6667 1.0000
1.5480 93.0000 1.0000
1.5540 93.0000 1.0000
1.5600 79.1667 1.0000
1.5660 75.3333 1.0000
1.5720 102.1667 1.0000
1.5780 82.6667 1.0000
1.5840 70.3333 1.0000
1.5900 65.1667 1.0000
1.5960 73.5000 1.0000
1.6020 83.6667 1.0000
1.6080 67.3333 1.0000
1.6140 81.8333 1.0000
1.6200 81.6667 1.0000
1.6260 72.1667 1.0000
1.6320 72.1667 1.0000
1.6380 68.0000 1.0000
1.6440 66.3333 1.0000
1.6500 62.8333 1.0000
1.6560 67.5000 1.0000
1.6620 60.1667 1.0000
1.6680 52.6667 1.0000
1.6740 71.0000 1.0000
1.6800 78.3333 1.0000
1.6860 63.0000 1.0000
1.6920 66.8333 1.0000
1.6980 63.1667 1.0000
1.7040 45.6667 1.0000
1.7100 53.1667 1.0000
1.7160 59.1667 1.0000
1.7220 46.6667 1.0000
1.7280 56.5000 1.0000
1.7340 49.5000 1.0000
1.7400 43.8333 1.0000
1.7460 57.5000 1.0000
1.7520 54.0000 1.0000
1.7580 50.5000 1.0000
1.7640 56.5000 1.0000
1.7700 43.3333 1.0000
1.7760 49.5000 1.0000
1.7820 40.6667 1.0000
1.7880 46.1667 1.0000
1.7940 42.8333 1.0000
1.8000 36.6667 1.0000
1.8060 28.3333 1.0000
1.8120 36.5000 1.0000
1.8180 36.5000 1.0000
1.8240 36.0000 1.0000
1.8300 35.3333 1.0000
1.8360 37.8333 1.0000
1.8420 43.1667 1.0000
1.8480 38.5000 1.0000
1.8540 29.6667 1.0000
1.8600 27.5000 1.0000
1.8660 34.0000 1.0000
1.8720 36.1667 1.0000
1.8780 26.0000 1.0000
1.8840 29.5000 1.0000
1.8900 39.6667 1.0000
1.8960 27.3333 1.0000
1.9020 33.1667 1.0000
1.9080 42.6667 1.0000
1.9140 22.8333 1.0000
1.9200 30.8333 1.0000
1.9260 36.5000 1.0000
1.9320 37.0000 1.0000
1.9380 28.5000 1.0000
1.9440 22.0000 1.0000
1.9500 31.6667 1.0000
1.9560 31.8333 1.0000
1.9620 31.6667 1.0000
1.9680 30.6667 1.0000
1.9740 21.8333 1.0000
1.9800 27.8333 1.0000
1.9860 20.8333 1.0000
1.9920 26.1667 1.0000
1.9980 19.6667 1.0000
2.0040 30.1667 1.0000
2.0100 18.8333 1.0000
2.0160 16.6667 1.0000
2.0220 11.8333 1.0000
2.0280 19.3333 1.0000
2.0340 27.5000 1.0000
2.0400 17.6667 1.0000
2.0460 18.5000 1.0000
2.0520 25.0000 1.0000
2.0580 16.3333 1.0000
2.0640 19.6667 1.0000
2.0700 19.5000 1.0000
2.0760 10.6667 1.0000
2.0820 18.3333 1.0000
2.0880 14.8333 1.0000
2.0940 16.5000 1.0000
2.1000 29.5000 1.0000
2.1060 36.3333 1.0000
2.1120 24.1667 1.0000
2.1180 19.0000 1.0000
2.1240 10.0000 1.0000
2.1300 21.1667 1.0000
2.1360 13.1667 1.0000
2.1420 11.1667 1.0000
2.1480 13.3333 1.0000
2.1540 15.6667 1.0000
2.1600 17.6667 1.0000
2.1660 23.6667 1.0000
2.1720 17.5000 1.0000
2.1780 10.3333 1.0000
2.1840 12.8333 1.0000
2.1900 19.1667 1.0000
2.1960 6.8333 1.0000
2.2020 21.1667 1.0000
2.2080 15.0000 1.0000
2.2140 13.6667 1.0000
2.2200 10.5000 1.0000
2.2260 14.3333 1.0000
2.2320 10.8333 1.0000
2.2380 10.6667 1.0000
2.2440 17.8333 1.0000
2.2500 13.5000 1.0000
2.2560 13.3333 1.0000
2.2620 9.0000 1.0000
2.2680 13.3333 1.0000
2.2740 13.1667 1.0000
2.2800 13.6667 1.0000
2.2860 8.0000 1.0000
2.2920 10.0000 1.0000
2.2980 6.1667 1.0000
2.3040 11.1667 1.0000
2.3100 9.8333 1.0000
2.3160 10.5000 1.0000
2.3220 11.1667 1.0000
2.3280 4.6667 1.0000
2.3340 12.8333 1.0000
2.3400 6.8333 1.0000
2.3460 10.6667 1.0000
2.3520 7.8333 1.0000
2.3580 9.1667 1.0000
2.3640 6.5000 1.0000
2.3700 7.0000 1.0000
2.3760 11.6667 1.0000
2.3820 11.8333 1.0000
2.3880 12.1667 1.0000
2.3940 16.0000 1.0000
2.4000 6.5000 1.0000
2.4060 11.5000 1.0000
2.4120 15.1667 1.0000
2.4180 5.6667 1.0000
2.4240 3.3333 1.0000
2.4300 9.1667 1.0000
2.4360 8.3333 1.0000
2.4420 13.5000 1.0000
2.4480 7.3333 1.0000
2.4540 10.5000 1.0000
2.4600 8.6667 1.0000
2.4660 4.0000 1.0000
2.4720 12.1667 1.0000
2.4780 2.6667 1.0000
2.4840 7.6667 1.0000
2.4900 8.6667 1.0000
2.4960 5.5000 1.0000
2.5020 6.0000 1.0000
2.5080 7.3333 1.0000
2.5140 13.5000 1.0000
2.5200 10.5000 1.0000
2.5260 8.6667 1.0000
2.5320 5.3333 1.0000
2.5380 5.6667 1.0000
2.5440 9.0000 1.0000
2.5500 7.8333 1.0000
2.5560 4.0000 1.0000
2.5620 12.8333 1.0000
2.5680 8.8333 1.0000
2.5740 4.3333 1.0000
2.5800 10.8333 1.0000
2.5860 2.6667 1.0000
2.5920 5.8333 1.0000
2.5980 8.3333 1.0000
2.6040 5.8333 1.0000
2.6100 5.1667 1.0000
2.6160 6.5000 1.0000
2.6220 7.5000 1.0000
2.6280 0.1667 1.0000
2.6340 5.8333 1.0000
2.6400 7.8333 1.0000
2.6460 5.1667 1.0000
2.6520 2.6667 1.0000
2.6580 10.5000 1.0000
2.6640 4.5000 1.0000
2.6700 3.0000 1.0000
2.6760 5.5000 1.0000
2.6820 3.3333 1.0000
2.6880 4.0000 1.0000
2.6940 3.6667 1.0000
2.7000 8.3333 1.0000
2.7060 1.3333 1.0000
2.7120 4.1667 1.0000
2.7180 4.8333 1.0000
2.7240 5.1667 1.0000
2.7300 7.0000 1.0000
2.7360 4.8333 1.0000
2.7420 0.1667 1.0000
2.7480 2.3333 1.0000
2.7540 3.1667 1.0000
2.7600 6.3333 1.0000
2.7660 5.0000 1.0000
2.7720 1.1667 1.0000
2.7780 3.0000 1.0000
2.7840 0.3333 1.0000
2.7900 7.6667 1.0000
2.7960 2.3333 1.0000
2.8020 0.0000 1.0000
2.8080 4.0000 1.0000
2.8140 2.5000 1.0000
2.8200 2.3333 1.0000
2.8260 0.1667 1.0000
2.8320 5.5000 1.0000
2.8380 1.5000 1.0000
2.8440 2.1667 1.0000
2.8500 0.1667 1.0000
2.8560 2.3333 1.0000
2.8620 5.1667 1.0000
2.8680 0.1667 1.0000
2.8740 1.6667 1.0000
2.8800 7.6667 1.0000
2.8860 2.0000 1.0000
2.8920 3.3333 1.0000
2.8980 0.5000 1.0000
2.9040 1.3333 1.0000
2.9100 1.1667 1.0000
2.9160 0.3333 1.0000
2.9220 0.3333 1.0000
2.9280 3.0000 1.0000
2.9340 3.0000 1.0000
2.9400 0.1667 1.0000
2.9460 8.5000 1.0000
2.9520 8.5000 1.0000
2.9580 5.1667 1.0000
2.9640 2.3333 1.0000
2.9700 4.6667 1.0000
2.9760 2.5000 1.0000
2.9820 2.6667 1.0000
2.9880 3.0000 1.0000
2.9940 6.1667 1.0000
3.0000 1.3333 1.0000
3.0060 3.1667 1.0000
3.0120 3.1667 1.0000
3.0180 0.3333 1.0000
3.0240 1.5000 1.0000
3.0300 0.1667 1.0000
3.0360 0.0000 1.0000
3.0420 3.3333 1.0000
3.0480 1.5000 1.0000
3.0540 2.0000 1.0000
3.0600 0.1667 1.0000
3.0660 4.1667 1.0000
3.0720 3.5000 1.0000
3.0780 0.0000 1.0000
3.0840 5.6667 1.0000
3.0900 0.0000 1.0000
3.0960 0.0000 1.0000
3.1020 0.0000 1.0000
3.1080 4.3333 1.0000
3.1140 5.3333 1.0000
3.1200 3.5000 1.0000
3.1260 1.6667 1.0000
3.1320 0.1667 1.0000
3.1380 6.3333 1.0000
3.1440 0.0000 1.0000
3.1500 1.3333 1.0000
3.1560 2.1667 1.0000
3.1620 1.3333 1.0000
3.1680 4.3333 1.0000
3.1740 2.1667 1.0000
3.1800 1.3333 1.0000
3.1860 0.0000 1.0000
3.1920 2.3333 1.0000
3.1980 2.1667 1.0000
3.2040 3.0000 1.0000
3.2100 3.1667 1.0000
3.2160 4.0000 1.0000
3.2220 2.1667 1.0000
3.2280 0.0000 1.0000
3.2340 3.1667 1.0000
3.2400 0.1667 1.0000
3.2460 0.0000 1.0000
3.2520 0.1667 1.0000
3.2580 1.1667 1.0000
3.2640 3.5000 1.0000
3.2700 0.0000 1.0000
3.2760 2.1667 1.0000
3.2820 0.0000 1.0000
3.2880 3.1667 1.0000
3.2940 4.1667 1.0000
3.3000 0.0000 1.0000
3.3060 3.1667 1.0000
3.3120 4.0000 1.0000
3.3180 0.0000 1.0000
3.3240 5.5000 1.0000
3.3300 0.3333 1.0000
3.3360 0.0000 1.0000
3.3420 1.3333 1.0000
3.3480 5.1667 1.0000
3.3540 1.1667 1.0000
3.3600 1.3333 1.0000
3.3660 0.0000 1.0000
3.3720 0.0000 1.0000
3.3780 0.1667 1.0000
3.3840 0.1667 1.0000
3.3900 3.0000 1.0000
3.3960 2.1667 1.0000
3.4020 0.0000 1.0000
3.4080 3.3333 1.0000
3.4140 3.0000 1.0000
3.4200 0.1667 1.0000
3.4260 0.0000 1.0000
3.4320 3.3333 1.0000
3.4380 0.0000 1.0000
3.4440 2.1667 1.0000
3.4500 0.0000 1.0000
3.4560 0.0000 1.0000
3.4620 3.5000 1.0000
3.4680 2.1667 1.0000
3.4740 0.0000 1.0000
3.4800 3.1667 1.0000
3.4860 0.3333 1.0000
3.4920 0.1667 1.0000
3.4980 2.3333 1.0000
3.5040 0.0000 1.0000
3.5100 0.5000 1.0000
3.5160 1.1667 1.0000
3.5220 0.0000 1.0000
3.5280 1.1667 1.0000
3.5340 0.0000 1.0000
3.5400 0.3333 1.0000
3.5460 0.0000 1.0000
3.5520 1.1667 1.0000
3.5580 2.3333 1.0000
3.5640 7.0000 1.0000
3.5700 2.0000 1.0000
3.5760 0.1667 1.0000
3.5820 4.1667 1.0000
3.5880 5.1667 1.0000
3.5940 3.3333 1.0000
3.6000 2.5000 1.0000
3.6060 0.3333 1.0000
3.6120 3.1667 1.0000
3.6180 1.3333 1.0000
3.6240 2.1667 1.0000
3.6300 1.1667 1.0000
3.6360 1.3333 1.0000
3.6420 0.0000 1.0000
3.6480 3.3333 1.0000
3.6540 2.5000 1.0000
3.6600 0.0000 1.0000
3.6660 4.1667 1.0000
3.6720 0.0000 1.0000
3.6780 1.1667 1.0000
3.6840 0.0000 1.0000
3.6900 0.0000 1.0000
3.6960 0.1667 1.0000
3.7020 0.1667 1.0000
3.7080 0.0000 1.0000
3.7140 0.1667 1.0000
3.7200 0.0000 1.0000
3.7260 0.0000 1.0000
3.7320 1.1667 1.0000
3.7380 2.5000 1.0000
3.7440 0.1667 1.0000
3.7500 0.3333 1.0000
3.7560 3.1667 1.0000
3.7620 0.3333 1.0000
3.7680 0.0000 1.0000
3.7740 1.1667 1.0000
3.7800 0.0000 1.0000
3.7860 0.0000 1.0000
3.7920 0.0000 1.0000
3.7980 0.5000 1.0000
3.8040 0.0000 1.0000
3.8100 0.0000 1.0000
3.8160 1.1667 1.0000
3.8220 1.1667 1.0000
3.8280 4.3333 1.0000
3.8340 0.0000 1.0000
3.8400 0.0000 1.0000
3.8460 0.0000 1.0000
3.8520 1.1667 1.0000
3.8580 1.6667 1.0000
3.8640 2.1667 1.0000
3.8700 0.0000 1.0000
3.8760 2.3333 1.0000
3.8820 3.6667 1.0000
3.8880 3.1667 1.0000
3.8940 0.0000 1.0000
3.9000 0.0000 1.0000
3.9060 0.0000 1.0000
3.9120 2.1667 1.0000
3.9180 1.3333 1.0000
3.9240 0.3333 1.0000
3.9300 1.1667 1.0000
3.9360 3.0000 1.0000
3.9420 1.1667 1.0000
3.9480 2.0000 1.0000
3.9540 3.1667 1.0000
3.9600 0.0000 1.0000
3.9660 2.3333 1.0000
3.9720 1.1667 1.0000
3.9780 0.3333 1.0000
3.9840 0.0000 1.0000
3.9900 4.0000 1.0000
3.9960 3.1667 1.0000
4.0020 6.1667 1.0000
4.0080 0.0000 1.0000
4.0140 0.0000 1.0000
4.0200 2.0000 1.0000
4.0260 3.3333 1.0000
4.0320 3.3333 1.0000
4.0380 0.0000 1.0000
4.0440 0.0000 1.0000
4.0500 2.1667 1.0000
4.0560 0.0000 1.0000
4.0620 0.1667 1.0000
4.0680 0.0000 1.0000
4.0740 2.0000 1.0000
4.0800 0.0000 1.0000
4.0860 0.1667 1.0000
4.0920 0.3333 1.0000
4.0980 2.1667 1.0000
4.1040 2.0000 1.0000
4.1100 4.3333 1.0000
4.1160 0.0000 1.0000
4.1220 0.0000 1.0000
4.1280 1.1667 1.0000
4.1340 0.0000 1.0000
4.1400 2.3333 1.0000
4.1460 2.1667 1.0000
4.1520 0.0000 1.0000
4.1580 1.5000 1.0000
4.1640 0.1667 1.0000
4.1700 0.0000 1.0000
4.1760 0.0000 1.0000
4.1820 0.0000 1.0000
4.1880 0.0000 1.0000
4.1940 5.1667 1.0000
4.2000 0.0000 1.0000
4.2060 0.0000 1.0000
4.2120 0.3333 1.0000
4.2180 1.1667 1.0000
4.2240 1.1667 1.0000
4.2300 0.1667 1.0000
4.2360 1.1667 1.0000
4.2420 1.1667 1.0000
4.2480 3.0000 1.0000
4.2540 2.1667 1.0000
4.2600 0.0000 1.0000
4.2660 0.0000 1.0000
4.2720 0.0000 1.0000
4.2780 0.0000 1.0000
4.2840 0.1667 1.0000
4.2900 0.0000 1.0000
4.2960 0.3333 1.0000
4.3020 0.0000 1.0000
4.3080 0.1667 1.0000
4.3140 0.0000 1.0000
4.3200 0.0000 1.0000
4.3260 0.1667 1.0000
4.3320 0.0000 1.0000
4.3380 0.0000 1.0000
4.3440 2.0000 1.0000
4.3500 3.1667 1.0000
4.3560 3.3333 1.0000
4.3620 0.0000 1.0000
4.3680 0.0000 1.0000
4.3740 2.1667 1.0000
4.3800 0.0000 1.0000
4.3860 3.3333 1.0000
4.3920 0.0000 1.0000
4.3980 3.0000 1.0000
4.4040 0.0000 1.0000
4.4100 1.1667 1.0000
4.4160 0.0000 1.0000
4.4220 0.0000 1.0000
4.4280 0.0000 1.0000
4.4340 0.0000 1.0000
4.4400 0.0000 1.0000
4.4460 0.0000 1.0000
4.4520 1.1667 1.0000
4.4580 3.0000 1.0000
4.4640 1.1667 1.0000
4.4700 0.1667 1.0000
4.4760 1.1667 1.0000
4.4820 0.1667 1.0000
4.4880 0.0000 1.0000
4.4940 0.0000 1.0000
4.5000 0.0000 1.0000
4.5060 1.1667 1.0000
4.5120 1.1667 1.0000
4.5180 0.0000 1.0000
4.5240 0.0000 1.0000
4.5300 0.1667 1.0000
4.5360 0.0000 1.0000
4.5420 2.0000 1.0000
4.5480 0.1667 1.0000
4.5540 0.0000 1.0000
4.5600 0.1667 1.0000
4.5660 0.5000 1.0000
4.5720 0.0000 1.0000
4.5780 3.0000 1.0000
4.5840 0.1667 1.0000
4.5900 0.0000 1.0000
4.5960 3.0000 1.0000
4.6020 2.0000 1.0000
4.6080 0.0000 1.0000
4.6140 0.0000 1.0000
4.6200 3.0000 1.0000
4.6260 0.0000 1.0000
4.6320 0.0000 1.0000
4.6380 1.3333 1.0000
4.6440 2.0000 1.0000
4.6500 2.0000 1.0000
4.6560 0.1667 1.0000
4.6620 2.3333 1.0000
4.6680 0.3333 1.0000
4.6740 2.0000 1.0000
4.6800 0.0000 1.0000
4.6860 0.0000 1.0000
4.6920 0.0000 1.0000
4.6980 1.1667 1.0000
4.7040 1.3333 1.0000
4.7100 0.0000 1.0000
4.7160 0.0000 1.0000
4.7220 0.0000 1.0000
4.7280 0.0000 1.0000
4.7340 0.0000 1.0000
4.7400 0.1667 1.0000
4.7460 3.5000 1.0000
4.7520 0.1667 1.0000
4.7580 1.1667 1.0000
4.7640 0.0000 1.0000
4.7700 0.1667 1.0000
4.7760 0.0000 1.0000
4.7820 0.0000 1.0000
4.7880 2.0000 1.0000
4.7940 3.1667 1.0000
4.8000 0.0000 1.0000
4.8060 3.0000 1.0000
4.8120 0.0000 1.0000
4.8180 2.1667 1.0000
4.8240 0.0000 1.0000
4.8300 0.0000 1.0000
4.8360 0.0000 1.0000
4.8420 0.1667 1.0000
4.8480 2.3333 1.0000
4.8540 0.1667 1.0000
4.8600 1.5000 1.0000
4.8660 1.1667 1.0000
4.8720 0.1667 1.0000
4.8780 2.0000 1.0000
4.8840 0.1667 1.0000
4.8900 0.0000 1.0000
4.8960 0.1667 1.0000
4.9020 2.1667 1.0000
4.9080 0.1667 1.0000
4.9140 1.3333 1.0000
4.9200 0.0000 1.0000
4.9260 0.1667 1.0000
4.9320 0.0000 1.0000
4.9380 0.0000 1.0000
4.9440 0.0000 1.0000
4.9500 4.1667 1.0000
4.9560 2.0000 1.0000
4.9620 0.0000 1.0000
4.9680 1.1667 1.0000
4.9740 2.3333 1.0000
4.9800 0.0000 1.0000
4.9860 0.1667 1.0000
4.9920 2.0000 1.0000
4.9980 0.1667 1.0000
5.0040 5.0000 1.0000
5.0100 0.3333 1.0000
5.0160 0.0000 1.0000
5.0220 3.0000 1.0000
5.0280 2.3333 1.0000
5.0340 0.0000 1.0000
5.0400 2.1667 1.0000
5.0460 0.0000 1.0000
5.0520 0.0000 1.0000
5.0580 3.0000 1.0000
5.0640 0.0000 1.0000
5.0700 0.0000 1.0000
5.0760 4.1667 1.0000
5.0820 3.1667 1.0000
5.0880 0.0000 1.0000
5.0940 1.1667 1.0000
5.1000 0.0000 1.0000
5.1060 3.3333 1.0000
5.1120 0.3333 1.0000
5.1180 0.0000 1.0000
5.1240 4.3333 1.0000
5.1300 1.1667 1.0000
5.1360 3.1667 1.0000
5.1420 3.3333 1.0000
5.1480 1.1667 1.0000
5.1540 0.0000 1.0000
5.1600 3.0000 1.0000
5.1660 3.0000 1.0000
5.1720 3.1667 1.0000
5.1780 1.1667 1.0000
5.1840 0.0000 1.0000
5.1900 0.0000 1.0000
5.1960 0.3333 1.0000
5.2020 1.1667 1.0000
5.2080 2.1667 1.0000
5.2140 0.3333 1.0000
5.2200 0.0000 1.0000
5.2260 1.3333 1.0000
5.2320 2.1667 1.0000
5.2380 3.1667 1.0000
5.2440 0.1667 1.0000
5.2500 3.3333 1.0000
5.2560 0.0000 1.0000
5.2620 0.1667 1.0000
5.2680 0.0000 1.0000
5.2740 0.0000 1.0000
5.2800 1.1667 1.0000
5.2860 0.0000 1.0000
5.2920 1.1667 1.0000
5.2980 0.0000 1.0000
5.3040 0.0000 1.0000
5.3100 0.0000 1.0000
5.3160 2.1667 1.0000
5.3220 0.0000 1.0000
5.3280 0.0000 1.0000
5.3340 0.0000 1.0000
5.3400 0.0000 1.0000
5.3460 1.1667 1.0000
5.3520 0.0000 1.0000
5.3580 3.0000 1.0000
5.3640 0.0000 1.0000
5.3700 2.1667 1.0000
5.3760 2.1667 1.0000
5.3820 0.1667 1.0000
5.3880 0.0000 1.0000
5.3940 0.0000 1.0000
5.4000 0.0000 1.0000
5.4060 0.0000 1.0000
5.4120 0.0000 1.0000
5.4180 0.0000 1.0000
5.4240 3.1667 1.0000
5.4300 1.1667 1.0000
5.4360 0.0000 1.0000
5.4420 0.1667 1.0000
5.4480 1.1667 1.0000
5.4540 2.0000 1.0000
5.4600 1.3333 1.0000
5.4660 0.0000 1.0000
5.4720 0.0000 1.0000
5.4780 0.0000 1.0000
5.4840 0.0000 1.0000
5.4900 0.0000 1.0000
5.4960 0.0000 1.0000
5.5020 2.1667 1.0000
5.5080 0.1667 1.0000
5.5140 2.0000 1.0000
5.5200 0.0000 1.0000
5.5260 2.0000 1.0000
5.5320 0.0000 1.0000
5.5380 0.0000 1.0000
5.5440 0.3333 1.0000
5.5500 0.0000 1.0000
5.5560 0.0000 1.0000
5.5620 0.0000 1.0000
5.5680 0.1667 1.0000
5.5740 0.0000 1.0000
5.5800 0.0000 1.0000
5.5860 0.0000 1.0000
5.5920 0.0000 1.0000
5.5980 3.0000 1.0000
5.6040 2.1667 1.0000
5.6100 2.0000 1.0000
5.6160 0.0000 1.0000
5.6220 0.0000 1.0000
5.6280 1.3333 1.0000
5.6340 0.1667 1.0000
5.6400 3.0000 1.0000
5.6460 0.0000 1.0000
5.6520 2.3333 1.0000
5.6580 0.0000 1.0000
5.6640 0.0000 1.0000
5.6700 0.0000 1.0000
5.6760 0.0000 1.0000
5.6820 0.0000 1.0000
5.6880 0.0000 1.0000
5.6940 0.1667 1.0000
5.7000 0.0000 1.0000
5.7060 0.0000 1.0000
5.7120 2.0000 1.0000
5.7180 0.0000 1.0000
5.7240 0.0000 1.0000
5.7300 0.1667 1.0000
5.7360 2.0000 1.0000
5.7420 0.1667 1.0000
5.7480 1.1667 1.0000
5.7540 0.0000 1.0000
5.7600 1.1667 1.0000
5.7660 2.1667 1.0000
5.7720 0.0000 1.0000
5.7780 0.0000 1.0000
5.7840 0.0000 1.0000
5.7900 1.1667 1.0000
5.7960 0.0000 1.0000
5.8020 0.0000 1.0000
5.8080 0.1667 1.0000
5.8140 0.0000 1.0000
5.8200 3.0000 1.0000
5.8260 0.0000 1.0000
5.8320 0.0000 1.0000
5.8380 0.0000 1.0000
5.8440 0.1667 1.0000
5.8500 0.0000 1.0000
5.8560 0.0000 1.0000
5.8620 0.0000 1.0000
5.8680 0.1667 1.0000
5.8740 2.0000 1.0000
5.8800 0.0000 1.0000
5.8860 0.0000 1.0000
5.8920 0.0000 1.0000
5.8980 0.0000 1.0000
5.9040 1.1667 1.0000
5.9100 0.0000 1.0000
5.9160 1.1667 1.0000
5.9220 0.0000 1.0000
5.9280 1.1667 1.0000
5.9340 2.1667 1.0000
5.9400 0.3333 1.0000
5.9460 0.1667 1.0000
5.9520 0.0000 1.0000
5.9580 0.0000 1.0000
5.9640 1.1667 1.0000
5.9700 0.1667 1.0000
5.9760 0.0000 1.0000
5.9820 0.0000 1.0000
5.9880 0.0000 1.0000
5.9940 0.0000 1.0000
6.0000 0.0000 1.0000
*RAS_INT_END
*RAS_DATA_END