File: XRR/CWOI4anneal2hrs_reflectivity.ras
*RAS_DATA_START
*RAS_HEADER_START
*DISP_FMT_X "%.4f"
*DISP_FMT_Y "%.0f"
*DISP_FULLSCALE "939941024.7197289500"
*DISP_LINE_COLOR "255.0000000000"
*DISP_LINE_STYLE "0.0000000000"
*DISP_LINE_WIDTH "0.2500000000"
*DISP_NOTE "Collected Data-1"
*DISP_OFFSET_Y "0.0000000000"
*DISP_PEAKSEARCH_UNIT_Y "cps"
*DISP_RANGE_BOTTOM "0.0100000000"
*DISP_RANGE_LEFT "-0.0006000000"
*DISP_RANGE_LOGCUTOFF "0.0100000000"
*DISP_RANGE_RIGHT "6.0006000000"
*DISP_RANGE_TOP "939941024.7197289500"
*DISP_SCALE_MODE_Y "2.0000000000"
*DISP_TAB_NAME "2-Theta/Omega"
*DISP_TITLE_Y "Intensity"
*DISP_UNIT_Y "cps"
*DISP_WINDOW_NAME "MSG_MACROENGINE"
*FILE_COMMENT " "
*FILE_MD5 ""
*FILE_MEMO " "
*FILE_OPERATOR "Administrator"
*FILE_PART_ID "MEAS_KHP2_00055"
*FILE_SAMPLE "CWOI4ann"
*FILE_TYPE "RAS_RAW"
*FILE_USERGROUP "System Manager"
*FILE_VERSION "1.0000000000"
*HW_ATTACHMENT_ID "ATT0025"
*HW_ATTACHMENT_NAME "標準|Standard"
*HW_COUNTER_ID-0 "CUT0025"
*HW_COUNTER_ID-1 "CUT0020"
*HW_COUNTER_ID-2 "CUT0020"
*HW_COUNTER_ID-3 "CSL0021"
*HW_COUNTER_ID-4 "CMC0021"
*HW_COUNTER_NAME-0 "D/teX Ultra|D/teX Ultra"
*HW_COUNTER_NAME-1 "None|None"
*HW_COUNTER_NAME-2 "None|None"
*HW_COUNTER_NAME-3 "BBM|BBM"
*HW_COUNTER_NAME-4 "検出器モノクロメータ|Detector monochromator"
*HW_COUNTER_SELECT_NAME "D/teX Ultra|D/teX Ultra"
*HW_GONIOMETER_ID "GON0023"
*HW_GONIOMETER_NAME "SmartLab|SmartLab"
*HW_GONIOMETER_RADIUS-0 "90.0"
*HW_GONIOMETER_RADIUS-1 "114.0"
*HW_GONIOMETER_RADIUS-2 "190.0"
*HW_GONIOMETER_RADIUS-3 "300.0"
*HW_GONIOMETER_RADIUS-4 "187.0"
*HW_GONIOMETER_RADIUS-5 "300.0"
*HW_GONIOMETER_RADIUS-6 "113.0"
*HW_GONIOMETER_RADIUS-7 "331.0"
*HW_I_OPT_ID-0 "CBO0021"
*HW_I_OPT_ID-1 "ICR0021"
*HW_I_OPT_ID-2 "ISL0021"
*HW_I_OPT_ID-3 "ISO0021"
*HW_I_OPT_ID-4 "IAD0021"
*HW_I_OPT_ID-5 "IPR0001"
*HW_I_OPT_NAME-0 "CBOユニット|CBO unit"
*HW_I_OPT_NAME-1 "標準入射光学ユニット|Standard incident optical unit"
*HW_I_OPT_NAME-2 "標準入射スリットボックス|Standard incident slit box"
*HW_I_OPT_NAME-3 "入射平行スリット|Incident parallel slit"
*HW_I_OPT_NAME-4 "長手制限スリット|Length limiting slit"
*HW_I_OPT_NAME-5 "None|None"
*HW_R_ATTENUATER_AUTOMODE "1"
*HW_R_OPT_ID-0 "RSS0021"
*HW_R_OPT_ID-1 "RCR0023"
*HW_R_OPT_ID-2 "RSO0021"
*HW_R_OPT_ID-3 "RRS0021"
*HW_R_OPT_ID-4 "ATN0021"
*HW_R_OPT_ID-5 "RFL0021"
*HW_R_OPT_ID-6 "RAD0021"
*HW_R_OPT_NAME-0 "標準受光スリットボックス1|Standard receiving slit box # 1"
*HW_R_OPT_NAME-1 "標準受光光学ユニット1|Standard receiving unit # 1"
*HW_R_OPT_NAME-2 "標準受光光学ユニット2|Standard receiving optical unit # 2"
*HW_R_OPT_NAME-3 "標準受光スリットボックス2|Standard receiving slit box # 2"
*HW_R_OPT_NAME-4 "標準アッテネータ|Standard Attenuator"
*HW_R_OPT_NAME-5 "Cu Kβ|Cu K-beta"
*HW_R_OPT_NAME-6 "調整用受光スリット|Alignment receiving slit"
*HW_SAMPLE_HOLDER_ID "SMP0021"
*HW_SAMPLE_HOLDER_NAME "χφZクレードル|Chi phi Z cradle"
*HW_XG_CURRENT_MAX "200"
*HW_XG_CURRENT_MIN "10"
*HW_XG_CURRENT_RESOLUTION "1"
*HW_XG_CURRENT_UNIT "mA"
*HW_XG_FOCUS "0.4mm x 8mm"
*HW_XG_FOCUS_TYPE "Normal"
*HW_XG_ID "1700"
*HW_XG_NAME "9kW 開放管(45kV 200mA ID:1700)|9kW Rotating anode(45kV 200mA ID:1700)"
*HW_XG_TARGET_ATOMIC_NUMBER "29.0000000000"
*HW_XG_TARGET_NAME "Cu"
*HW_XG_TYPE "Rota"
*HW_XG_VOLTAGE_MAX "45"
*HW_XG_VOLTAGE_MIN "20"
*HW_XG_VOLTAGE_RESOLUTION "1"
*HW_XG_VOLTAGE_UNIT "kV"
*HW_XG_WATT_MAX "9.00"
*HW_XG_WATT_UNIT "kW"
*HW_XG_WAVE_LENGTH_ALPHA1 "1.540593"
*HW_XG_WAVE_LENGTH_ALPHA2 "1.544414"
*HW_XG_WAVE_LENGTH_BETA "1.392250"
*MEAS_COND_AXIS_NAME-0 "Theta/2-Theta"
*MEAS_COND_AXIS_NAME-1 "2-Theta"
*MEAS_COND_AXIS_NAME-2 "Omega"
*MEAS_COND_AXIS_NAME-3 "Chi"
*MEAS_COND_AXIS_NAME-4 "Phi"
*MEAS_COND_AXIS_NAME-5 "Z"
*MEAS_COND_AXIS_NAME-6 "2-Theta/Omega"
*MEAS_COND_AXIS_NAME-7 "Theta_s"
*MEAS_COND_AXIS_NAME-8 "Theta_d"
*MEAS_COND_AXIS_NAME-9 "Ts"
*MEAS_COND_AXIS_NAME-10 "CBO selection slit"
*MEAS_COND_AXIS_NAME-11 "M"
*MEAS_COND_AXIS_NAME-12 "Incident parallel slit"
*MEAS_COND_AXIS_NAME-13 "Incident slit"
*MEAS_COND_AXIS_NAME-14 ""
*MEAS_COND_AXIS_NAME-15 "Zs"
*MEAS_COND_AXIS_NAME-16 "Incident optical device"
*MEAS_COND_AXIS_NAME-17 "Omega_m"
*MEAS_COND_AXIS_NAME-18 "Length limiting slit"
*MEAS_COND_AXIS_NAME-19 "Center slit"
*MEAS_COND_AXIS_NAME-20 "Filter"
*MEAS_COND_AXIS_NAME-21 "Receiving slit # 1"
*MEAS_COND_AXIS_NAME-22 "Receiving slit # 2"
*MEAS_COND_AXIS_NAME-23 "Receiving optical device"
*MEAS_COND_AXIS_NAME-24 "Receiving parallel slit"
*MEAS_COND_AXIS_NAME-25 "Alignment receiving slit"
*MEAS_COND_AXIS_NAME-26 ""
*MEAS_COND_AXIS_NAME-27 ""
*MEAS_COND_AXIS_NAME-28 "Zd"
*MEAS_COND_AXIS_NAME-29 "Attenuator"
*MEAS_COND_AXIS_NAME-30 "Diffracted beam monochromator"
*MEAS_COND_AXIS_NAME-31 "Monochromator slit"
*MEAS_COND_AXIS_NAME-32 "Primary beam"
*MEAS_COND_AXIS_NAME-33 ""
*MEAS_COND_AXIS_NAME-34 ""
*MEAS_COND_AXIS_NAME-35 "PHA"
*MEAS_COND_AXIS_NAME_INTERNAL-0 "TwoThetaTheta"
*MEAS_COND_AXIS_NAME_INTERNAL-1 "TwoTheta"
*MEAS_COND_AXIS_NAME_INTERNAL-2 "Omega"
*MEAS_COND_AXIS_NAME_INTERNAL-3 "Chi"
*MEAS_COND_AXIS_NAME_INTERNAL-4 "Phi"
*MEAS_COND_AXIS_NAME_INTERNAL-5 "Z"
*MEAS_COND_AXIS_NAME_INTERNAL-6 "TwoThetaOmega"
*MEAS_COND_AXIS_NAME_INTERNAL-7 "ThetaS"
*MEAS_COND_AXIS_NAME_INTERNAL-8 "ThetaD"
*MEAS_COND_AXIS_NAME_INTERNAL-9 "Ts"
*MEAS_COND_AXIS_NAME_INTERNAL-10 "CBO"
*MEAS_COND_AXIS_NAME_INTERNAL-11 "CBO-M"
*MEAS_COND_AXIS_NAME_INTERNAL-12 "IncidentSollerSlit"
*MEAS_COND_AXIS_NAME_INTERNAL-13 "IncidentSlitBox"
*MEAS_COND_AXIS_NAME_INTERNAL-14 "IncidentSlitBox-_Axis"
*MEAS_COND_AXIS_NAME_INTERNAL-15 "Zs"
*MEAS_COND_AXIS_NAME_INTERNAL-16 "IncidentMonochromator"
*MEAS_COND_AXIS_NAME_INTERNAL-17 "IncidentMonochromator-OmegaM"
*MEAS_COND_AXIS_NAME_INTERNAL-18 "IncidentAxdSlit"
*MEAS_COND_AXIS_NAME_INTERNAL-19 "CenterSlit"
*MEAS_COND_AXIS_NAME_INTERNAL-20 "Filter"
*MEAS_COND_AXIS_NAME_INTERNAL-21 "ReceivingSlitBox1"
*MEAS_COND_AXIS_NAME_INTERNAL-22 "ReceivingSlitBox2"
*MEAS_COND_AXIS_NAME_INTERNAL-23 "ReceivingOptics"
*MEAS_COND_AXIS_NAME_INTERNAL-24 "ReceivingSollerSlit"
*MEAS_COND_AXIS_NAME_INTERNAL-25 "ReceivingAxdSlit"
*MEAS_COND_AXIS_NAME_INTERNAL-26 "ReceivingSlitBox1-_Axis"
*MEAS_COND_AXIS_NAME_INTERNAL-27 "ReceivingSlitBox2-_Axis"
*MEAS_COND_AXIS_NAME_INTERNAL-28 "ReceivingSlitBox2-Zd"
*MEAS_COND_AXIS_NAME_INTERNAL-29 "Attenuator"
*MEAS_COND_AXIS_NAME_INTERNAL-30 "CounterMonochromator"
*MEAS_COND_AXIS_NAME_INTERNAL-31 "CounterSlit"
*MEAS_COND_AXIS_NAME_INTERNAL-32 "IncidentPrimary"
*MEAS_COND_AXIS_NAME_INTERNAL-33 "AlphaR"
*MEAS_COND_AXIS_NAME_INTERNAL-34 "BetaR"
*MEAS_COND_AXIS_NAME_INTERNAL-35 "PHA"
*MEAS_COND_AXIS_NAME_MAGICNO-0 "83951616.0000000000"
*MEAS_COND_AXIS_NAME_MAGICNO-1 "268632064.0000000000"
*MEAS_COND_AXIS_NAME_MAGICNO-2 "268500992.0000000000"
*MEAS_COND_AXIS_NAME_MAGICNO-3 "268500992.0000000000"
*MEAS_COND_AXIS_NAME_MAGICNO-4 "268500992.0000000000"
*MEAS_COND_AXIS_NAME_MAGICNO-5 "285278208.0000000000"
*MEAS_COND_AXIS_NAME_MAGICNO-6 "83951616.0000000000"
*MEAS_COND_AXIS_NAME_MAGICNO-7 "131072.0000000000"
*MEAS_COND_AXIS_NAME_MAGICNO-8 "131072.0000000000"
*MEAS_COND_AXIS_NAME_MAGICNO-9 "318898176.0000000000"
*MEAS_COND_AXIS_NAME_MAGICNO-10 "20971521.0000000000"
*MEAS_COND_AXIS_NAME_MAGICNO-11 "285343744.0000000000"
*MEAS_COND_AXIS_NAME_MAGICNO-12 "20971521.0000000000"
*MEAS_COND_AXIS_NAME_MAGICNO-13 "22020097.0000000000"
*MEAS_COND_AXIS_NAME_MAGICNO-14 "25165824.0000000000"
*MEAS_COND_AXIS_NAME_MAGICNO-15 "318898176.0000000000"
*MEAS_COND_AXIS_NAME_MAGICNO-16 "20971521.0000000000"
*MEAS_COND_AXIS_NAME_MAGICNO-17 "285343744.0000000000"
*MEAS_COND_AXIS_NAME_MAGICNO-18 "20971521.0000000000"
*MEAS_COND_AXIS_NAME_MAGICNO-19 "20971521.0000000000"
*MEAS_COND_AXIS_NAME_MAGICNO-20 "20971521.0000000000"
*MEAS_COND_AXIS_NAME_MAGICNO-21 "23068673.0000000000"
*MEAS_COND_AXIS_NAME_MAGICNO-22 "23068673.0000000000"
*MEAS_COND_AXIS_NAME_MAGICNO-23 "20971521.0000000000"
*MEAS_COND_AXIS_NAME_MAGICNO-24 "20971521.0000000000"
*MEAS_COND_AXIS_NAME_MAGICNO-25 "20971521.0000000000"
*MEAS_COND_AXIS_NAME_MAGICNO-26 "25165824.0000000000"
*MEAS_COND_AXIS_NAME_MAGICNO-27 "25165824.0000000000"
*MEAS_COND_AXIS_NAME_MAGICNO-28 "285343744.0000000000"
*MEAS_COND_AXIS_NAME_MAGICNO-29 "17301505.0000000000"
*MEAS_COND_AXIS_NAME_MAGICNO-30 "20971521.0000000000"
*MEAS_COND_AXIS_NAME_MAGICNO-31 "20971521.0000000000"
*MEAS_COND_AXIS_NAME_MAGICNO-32 "20971521.0000000000"
*MEAS_COND_AXIS_NAME_MAGICNO-33 "8388608.0000000000"
*MEAS_COND_AXIS_NAME_MAGICNO-34 "8388608.0000000000"
*MEAS_COND_AXIS_NAME_MAGICNO-35 "0.0000000000"
*MEAS_COND_AXIS_OFFSET-0 "-"
*MEAS_COND_AXIS_OFFSET-1 "0.8833000000"
*MEAS_COND_AXIS_OFFSET-2 "0.7236000000"
*MEAS_COND_AXIS_OFFSET-3 "0.0000000000"
*MEAS_COND_AXIS_OFFSET-4 "0.0000000000"
*MEAS_COND_AXIS_OFFSET-5 "-"
*MEAS_COND_AXIS_OFFSET-6 "-"
*MEAS_COND_AXIS_OFFSET-7 "0.7236000000"
*MEAS_COND_AXIS_OFFSET-8 "0.1597000000"
*MEAS_COND_AXIS_OFFSET-9 "-"
*MEAS_COND_AXIS_OFFSET-10 "-"
*MEAS_COND_AXIS_OFFSET-11 "-"
*MEAS_COND_AXIS_OFFSET-12 "-"
*MEAS_COND_AXIS_OFFSET-13 "-"
*MEAS_COND_AXIS_OFFSET-14 "-"
*MEAS_COND_AXIS_OFFSET-15 "-"
*MEAS_COND_AXIS_OFFSET-16 "-"
*MEAS_COND_AXIS_OFFSET-17 "-"
*MEAS_COND_AXIS_OFFSET-18 "-"
*MEAS_COND_AXIS_OFFSET-19 "-"
*MEAS_COND_AXIS_OFFSET-20 "-"
*MEAS_COND_AXIS_OFFSET-21 "-"
*MEAS_COND_AXIS_OFFSET-22 "-"
*MEAS_COND_AXIS_OFFSET-23 "-"
*MEAS_COND_AXIS_OFFSET-24 "-"
*MEAS_COND_AXIS_OFFSET-25 "-"
*MEAS_COND_AXIS_OFFSET-26 "-"
*MEAS_COND_AXIS_OFFSET-27 "-"
*MEAS_COND_AXIS_OFFSET-28 "-"
*MEAS_COND_AXIS_OFFSET-29 "-"
*MEAS_COND_AXIS_OFFSET-30 "-"
*MEAS_COND_AXIS_OFFSET-31 "-"
*MEAS_COND_AXIS_OFFSET-32 "-"
*MEAS_COND_AXIS_OFFSET-33 "0.0000000000"
*MEAS_COND_AXIS_OFFSET-34 "0.0000000000"
*MEAS_COND_AXIS_OFFSET-35 "-"
*MEAS_COND_AXIS_POSITION-0 "-0.0008000000"
*MEAS_COND_AXIS_POSITION-1 "-0.0008000000"
*MEAS_COND_AXIS_POSITION-2 "-0.0004000000"
*MEAS_COND_AXIS_POSITION-3 "0.0000000000"
*MEAS_COND_AXIS_POSITION-4 "0.0000000000"
*MEAS_COND_AXIS_POSITION-5 "-1.4094000000"
*MEAS_COND_AXIS_POSITION-6 "-0.0008000000"
*MEAS_COND_AXIS_POSITION-7 "-0.0004000000"
*MEAS_COND_AXIS_POSITION-8 "-0.0004000000"
*MEAS_COND_AXIS_POSITION-9 "-4.7170000000"
*MEAS_COND_AXIS_POSITION-10 "PB"
*MEAS_COND_AXIS_POSITION-11 "0.0000000000"
*MEAS_COND_AXIS_POSITION-12 "Soller_slit_open_s"
*MEAS_COND_AXIS_POSITION-13 "0.250mm"
*MEAS_COND_AXIS_POSITION-14 "0.2500000000"
*MEAS_COND_AXIS_POSITION-15 "-1.7465600000"
*MEAS_COND_AXIS_POSITION-16 "Ge(220)x2"
*MEAS_COND_AXIS_POSITION-17 "0.0000000000"
*MEAS_COND_AXIS_POSITION-18 "2.0mm"
*MEAS_COND_AXIS_POSITION-19 "None"
*MEAS_COND_AXIS_POSITION-20 "None"
*MEAS_COND_AXIS_POSITION-21 "0.250mm"
*MEAS_COND_AXIS_POSITION-22 "0.250mm"
*MEAS_COND_AXIS_POSITION-23 "No_unit"
*MEAS_COND_AXIS_POSITION-24 "Soller_slit_5.0deg"
*MEAS_COND_AXIS_POSITION-25 "None"
*MEAS_COND_AXIS_POSITION-26 "0.2500000000"
*MEAS_COND_AXIS_POSITION-27 "0.2500000000"
*MEAS_COND_AXIS_POSITION-28 "0.0859400000"
*MEAS_COND_AXIS_POSITION-29 "1/10000"
*MEAS_COND_AXIS_POSITION-30 "None"
*MEAS_COND_AXIS_POSITION-31 "None"
*MEAS_COND_AXIS_POSITION-32 "None"
*MEAS_COND_AXIS_POSITION-33 "0.0000000000"
*MEAS_COND_AXIS_POSITION-34 "0.0000000000"
*MEAS_COND_AXIS_POSITION-35 "34.0000000000"
*MEAS_COND_AXIS_UNIT-0 "deg"
*MEAS_COND_AXIS_UNIT-1 "deg"
*MEAS_COND_AXIS_UNIT-2 "deg"
*MEAS_COND_AXIS_UNIT-3 "deg"
*MEAS_COND_AXIS_UNIT-4 "deg"
*MEAS_COND_AXIS_UNIT-5 "mm"
*MEAS_COND_AXIS_UNIT-6 "deg"
*MEAS_COND_AXIS_UNIT-7 "deg"
*MEAS_COND_AXIS_UNIT-8 "deg"
*MEAS_COND_AXIS_UNIT-9 "mm"
*MEAS_COND_AXIS_UNIT-10 ""
*MEAS_COND_AXIS_UNIT-11 "pulse"
*MEAS_COND_AXIS_UNIT-12 ""
*MEAS_COND_AXIS_UNIT-13 ""
*MEAS_COND_AXIS_UNIT-14 "mm"
*MEAS_COND_AXIS_UNIT-15 "mm"
*MEAS_COND_AXIS_UNIT-16 ""
*MEAS_COND_AXIS_UNIT-17 "pulse"
*MEAS_COND_AXIS_UNIT-18 ""
*MEAS_COND_AXIS_UNIT-19 ""
*MEAS_COND_AXIS_UNIT-20 ""
*MEAS_COND_AXIS_UNIT-21 ""
*MEAS_COND_AXIS_UNIT-22 ""
*MEAS_COND_AXIS_UNIT-23 ""
*MEAS_COND_AXIS_UNIT-24 ""
*MEAS_COND_AXIS_UNIT-25 ""
*MEAS_COND_AXIS_UNIT-26 "mm"
*MEAS_COND_AXIS_UNIT-27 "mm"
*MEAS_COND_AXIS_UNIT-28 "mm"
*MEAS_COND_AXIS_UNIT-29 ""
*MEAS_COND_AXIS_UNIT-30 ""
*MEAS_COND_AXIS_UNIT-31 ""
*MEAS_COND_AXIS_UNIT-32 ""
*MEAS_COND_AXIS_UNIT-33 "deg"
*MEAS_COND_AXIS_UNIT-34 "deg"
*MEAS_COND_AXIS_UNIT-35 "div"
*MEAS_COND_COUNTER_CNTLOSS_CORR "0.0000000000"
*MEAS_COND_COUNTER_PHABASE "34.0000000000"
*MEAS_COND_COUNTER_PHAWINDOW "19.0000000000"
*MEAS_COND_COUNTER_PHA_UNIT "div"
*MEAS_COND_COUNTER_TAUDIFF "2.0000000000"
*MEAS_COND_COUNTER_TAUINT "0.1000000000"
*MEAS_COND_IRRADIATION_MODE "OFF"
*MEAS_COND_IRRADIATION_WIDTH ""
*MEAS_COND_OPT_ATTR "High resolution parallel beam Ge(220)x2/RS"
*MEAS_COND_OPT_NAME "@High resolution PB-Ge(220)x2"
*MEAS_COND_UNSYMMETRIC_MODE "OFF"
*MEAS_COND_XG_CURRENT "200.0000000000"
*MEAS_COND_XG_VOLTAGE "45.0000000000"
*MEAS_COND_XG_WAVE_TYPE "Ka1"
*MEAS_DATA_COUNT "3001.0000000000"
*MEAS_SCAN_AXIS_X "2-Theta/Omega"
*MEAS_SCAN_AXIS_X_INTERNAL "TwoThetaOmega"
*MEAS_SCAN_END_TIME "11/11/23 14:26:22"
*MEAS_SCAN_MODE "CONTINUOUS"
*MEAS_SCAN_MONITOR "0"
*MEAS_SCAN_RESOLUTION_X "0.0002"
*MEAS_SCAN_SPEED "0.500000"
*MEAS_SCAN_SPEED_UNIT "deg/min"
*MEAS_SCAN_SPEED_USER "0.500000"
*MEAS_SCAN_START "0.0000000000"
*MEAS_SCAN_START_TIME "11/11/23 14:13:33"
*MEAS_SCAN_STEP "0.0020000000"
*MEAS_SCAN_STOP "6.0000000000"
*MEAS_SCAN_UNIT_X "deg"
*MEAS_SCAN_UNIT_Y "counts"
*RAS_HEADER_END
*RAS_INT_START
0.0000 6664132.5000 1.0000
0.0060 6762606.5000 1.0000
0.0120 6663994.5000 1.0000
0.0180 6116040.0000 1.0000
0.0240 5757311.5000 1.0000
0.0300 5198324.0000 1.0000
0.0360 4544861.0000 1.0000
0.0420 3746721.0000 1.0000
0.0480 2769009.7500 1.0000
0.0540 1858189.3750 1.0000
0.0600 1107143.8750 1.0000
0.0660 575902.1250 1.0000
0.0720 269748.8438 1.0000
0.0780 140076.6563 1.0000
0.0840 81269.4844 1.0000
0.0900 54682.1602 1.0000
0.0960 42216.0000 1.0000
0.1020 37970.6680 1.0000
0.1080 37388.1680 1.0000
0.1140 38366.5000 1.0000
0.1200 40590.8320 1.0000
0.1260 42709.0000 1.0000
0.1320 44645.1680 1.0000
0.1380 47292.5000 1.0000
0.1440 49017.8320 1.0000
0.1500 51445.1680 1.0000
0.1560 54011.6680 1.0000
0.1620 55550.1680 1.0000
0.1680 58639.5000 1.0000
0.1740 60885.8320 1.0000
0.1800 63487.5000 1.0000
0.1860 65408.5000 1.0000
0.1920 68021.5000 1.0000
0.1980 70491.0000 1.0000
0.2040 72811.8359 1.0000
0.2100 75354.8359 1.0000
0.2160 77500.0000 1.0000
0.2220 80459.1641 1.0000
0.2280 82616.6641 1.0000
0.2340 84940.8359 1.0000
0.2400 87455.5000 1.0000
0.2460 89935.5000 1.0000
0.2520 91842.3359 1.0000
0.2580 94833.5156 1.0000
0.2640 92418.7188 1.0000
0.2700 95382.9063 1.0000
0.2760 100350.5313 1.0000
0.2820 103821.1719 1.0000
0.2880 104975.5703 1.0000
0.2940 107567.3672 1.0000
0.3000 107336.4922 1.0000
0.3060 109824.0313 1.0000
0.3120 112840.3594 1.0000
0.3180 114389.4766 1.0000
0.3240 119766.7344 1.0000
0.3300 118277.1875 1.0000
0.3360 122775.6094 1.0000
0.3420 122775.6094 1.0000
0.3480 124652.4375 1.0000
0.3540 127445.3281 1.0000
0.3600 130886.1719 1.0000
0.3660 135667.6094 1.0000
0.3720 138162.5938 1.0000
0.3780 138475.3906 1.0000
0.3840 137820.0000 1.0000
0.3900 142035.4063 1.0000
0.3960 139964.9375 1.0000
0.4020 142489.7188 1.0000
0.4080 148931.9844 1.0000
0.4140 152365.3906 1.0000
0.4200 153624.0469 1.0000
0.4260 152253.6719 1.0000
0.4320 159045.9844 1.0000
0.4380 157846.9063 1.0000
0.4440 162352.7813 1.0000
0.4500 161243.0625 1.0000
0.4560 165071.2031 1.0000
0.4620 165048.8438 1.0000
0.4680 165056.2969 1.0000
0.4740 164631.7813 1.0000
0.4800 172042.2500 1.0000
0.4860 167797.0625 1.0000
0.4920 173137.0781 1.0000
0.4980 171900.7500 1.0000
0.5040 179192.0625 1.0000
0.5100 186587.6406 1.0000
0.5160 175713.9844 1.0000
0.5220 177210.9688 1.0000
0.5280 185872.6563 1.0000
0.5340 183087.2188 1.0000
0.5400 182342.4531 1.0000
0.5460 186081.2031 1.0000
0.5520 181731.7344 1.0000
0.5580 185731.1563 1.0000
0.5640 188807.0625 1.0000
0.5700 186818.5313 1.0000
0.5760 194891.8438 1.0000
0.5820 185530.0781 1.0000
0.5880 187123.8906 1.0000
0.5940 189693.3438 1.0000
0.6000 181351.9063 1.0000
0.6060 186900.4531 1.0000
0.6120 178290.8906 1.0000
0.6180 181843.4531 1.0000
0.6240 168162.0000 1.0000
0.6300 168236.4688 1.0000
0.6360 160282.3125 1.0000
0.6420 155106.1406 1.0000
0.6480 149870.4063 1.0000
0.6540 144582.5313 1.0000
0.6600 129270.0156 1.0000
0.6660 118679.3672 1.0000
0.6720 106852.3906 1.0000
0.6780 103545.6094 1.0000
0.6840 89819.4609 1.0000
0.6900 83429.3203 1.0000
0.6960 73278.0859 1.0000
0.7020 64899.4063 1.0000
0.7080 61339.3945 1.0000
0.7140 56351.6680 1.0000
0.7200 51597.8320 1.0000
0.7260 47233.1680 1.0000
0.7320 42970.1680 1.0000
0.7380 40044.6680 1.0000
0.7440 36995.8320 1.0000
0.7500 34557.8320 1.0000
0.7560 32123.5000 1.0000
0.7620 29937.0000 1.0000
0.7680 27823.1660 1.0000
0.7740 26309.6660 1.0000
0.7800 24691.0000 1.0000
0.7860 23461.0000 1.0000
0.7920 22254.1660 1.0000
0.7980 21212.6660 1.0000
0.8040 20041.5000 1.0000
0.8100 19265.5000 1.0000
0.8160 18341.0000 1.0000
0.8220 17675.0000 1.0000
0.8280 16764.5000 1.0000
0.8340 15824.8330 1.0000
0.8400 15309.3330 1.0000
0.8460 14776.3330 1.0000
0.8520 13921.8330 1.0000
0.8580 13392.5000 1.0000
0.8640 13024.6670 1.0000
0.8700 12238.6670 1.0000
0.8760 11803.1670 1.0000
0.8820 11145.6670 1.0000
0.8880 10569.6670 1.0000
0.8940 9998.8330 1.0000
0.9000 9813.3330 1.0000
0.9060 9258.5000 1.0000
0.9120 9174.1670 1.0000
0.9180 8748.1670 1.0000
0.9240 8351.5000 1.0000
0.9300 7904.3335 1.0000
0.9360 7731.6665 1.0000
0.9420 7326.3335 1.0000
0.9480 7222.1665 1.0000
0.9540 6793.5000 1.0000
0.9600 6605.5000 1.0000
0.9660 6546.3335 1.0000
0.9720 6237.5000 1.0000
0.9780 5986.0000 1.0000
0.9840 5695.1665 1.0000
0.9900 5599.3335 1.0000
0.9960 5436.3335 1.0000
1.0020 5302.6665 1.0000
1.0080 5166.0000 1.0000
1.0140 4974.3335 1.0000
1.0200 4833.0000 1.0000
1.0260 4693.8335 1.0000
1.0320 4644.3335 1.0000
1.0380 4427.5000 1.0000
1.0440 4260.5000 1.0000
1.0500 4343.6665 1.0000
1.0560 4062.3333 1.0000
1.0620 4033.6667 1.0000
1.0680 3882.8333 1.0000
1.0740 3789.6667 1.0000
1.0800 3586.0000 1.0000
1.0860 3508.5000 1.0000
1.0920 3439.0000 1.0000
1.0980 3393.1667 1.0000
1.1040 3312.6667 1.0000
1.1100 3163.0000 1.0000
1.1160 3151.0000 1.0000
1.1220 3005.6667 1.0000
1.1280 2873.0000 1.0000
1.1340 2879.0000 1.0000
1.1400 2661.3333 1.0000
1.1460 2570.0000 1.0000
1.1520 2554.5000 1.0000
1.1580 2444.0000 1.0000
1.1640 2443.1667 1.0000
1.1700 2216.0000 1.0000
1.1760 2224.3333 1.0000
1.1820 2160.8333 1.0000
1.1880 2103.0000 1.0000
1.1940 2068.0000 1.0000
1.2000 2024.0000 1.0000
1.2060 1976.1666 1.0000
1.2120 1979.6666 1.0000
1.2180 1807.6666 1.0000
1.2240 1823.8334 1.0000
1.2300 1780.0000 1.0000
1.2360 1762.5000 1.0000
1.2420 1731.6666 1.0000
1.2480 1651.5000 1.0000
1.2540 1599.6666 1.0000
1.2600 1516.6666 1.0000
1.2660 1548.6666 1.0000
1.2720 1483.0000 1.0000
1.2780 1498.1666 1.0000
1.2840 1416.6666 1.0000
1.2900 1432.3334 1.0000
1.2960 1411.6666 1.0000
1.3020 1331.5000 1.0000
1.3080 1358.0000 1.0000
1.3140 1325.6666 1.0000
1.3200 1270.5000 1.0000
1.3260 1205.3334 1.0000
1.3320 1221.5000 1.0000
1.3380 1256.3334 1.0000
1.3440 1230.8334 1.0000
1.3500 1162.0000 1.0000
1.3560 1141.8334 1.0000
1.3620 1066.5000 1.0000
1.3680 1110.5000 1.0000
1.3740 1150.6666 1.0000
1.3800 1060.0000 1.0000
1.3860 1026.6666 1.0000
1.3920 1035.8334 1.0000
1.3980 964.3333 1.0000
1.4040 999.3333 1.0000
1.4100 930.0000 1.0000
1.4160 933.3333 1.0000
1.4220 914.8333 1.0000
1.4280 890.8333 1.0000
1.4340 792.8333 1.0000
1.4400 824.5000 1.0000
1.4460 825.1667 1.0000
1.4520 733.8333 1.0000
1.4580 749.3333 1.0000
1.4640 735.1667 1.0000
1.4700 757.3333 1.0000
1.4760 756.3333 1.0000
1.4820 632.1667 1.0000
1.4880 653.6667 1.0000
1.4940 616.3333 1.0000
1.5000 609.8333 1.0000
1.5060 568.5000 1.0000
1.5120 597.0000 1.0000
1.5180 572.8333 1.0000
1.5240 578.1667 1.0000
1.5300 552.0000 1.0000
1.5360 527.8333 1.0000
1.5420 541.3333 1.0000
1.5480 505.6667 1.0000
1.5540 513.8333 1.0000
1.5600 493.6667 1.0000
1.5660 496.0000 1.0000
1.5720 482.0000 1.0000
1.5780 489.8333 1.0000
1.5840 477.1667 1.0000
1.5900 493.3333 1.0000
1.5960 480.6667 1.0000
1.6020 415.1667 1.0000
1.6080 451.6667 1.0000
1.6140 444.0000 1.0000
1.6200 417.8333 1.0000
1.6260 450.3333 1.0000
1.6320 439.8333 1.0000
1.6380 449.3333 1.0000
1.6440 413.1667 1.0000
1.6500 408.1667 1.0000
1.6560 407.3333 1.0000
1.6620 383.6667 1.0000
1.6680 404.1667 1.0000
1.6740 381.1667 1.0000
1.6800 375.1667 1.0000
1.6860 428.6667 1.0000
1.6920 351.5000 1.0000
1.6980 367.5000 1.0000
1.7040 370.5000 1.0000
1.7100 365.6667 1.0000
1.7160 392.0000 1.0000
1.7220 366.1667 1.0000
1.7280 334.0000 1.0000
1.7340 317.6667 1.0000
1.7400 333.0000 1.0000
1.7460 314.6667 1.0000
1.7520 305.3333 1.0000
1.7580 296.3333 1.0000
1.7640 284.8333 1.0000
1.7700 288.0000 1.0000
1.7760 284.6667 1.0000
1.7820 277.5000 1.0000
1.7880 264.5000 1.0000
1.7940 253.5000 1.0000
1.8000 272.0000 1.0000
1.8060 261.0000 1.0000
1.8120 231.6667 1.0000
1.8180 229.8333 1.0000
1.8240 256.5000 1.0000
1.8300 219.5000 1.0000
1.8360 206.3333 1.0000
1.8420 211.6667 1.0000
1.8480 220.8333 1.0000
1.8540 185.0000 1.0000
1.8600 193.0000 1.0000
1.8660 196.0000 1.0000
1.8720 211.8333 1.0000
1.8780 195.5000 1.0000
1.8840 182.0000 1.0000
1.8900 180.6667 1.0000
1.8960 169.3333 1.0000
1.9020 186.1667 1.0000
1.9080 160.1667 1.0000
1.9140 178.5000 1.0000
1.9200 170.3333 1.0000
1.9260 170.3333 1.0000
1.9320 169.3333 1.0000
1.9380 161.1667 1.0000
1.9440 150.3333 1.0000
1.9500 182.8333 1.0000
1.9560 163.8333 1.0000
1.9620 152.0000 1.0000
1.9680 172.6667 1.0000
1.9740 158.0000 1.0000
1.9800 162.1667 1.0000
1.9860 150.5000 1.0000
1.9920 141.3333 1.0000
1.9980 154.0000 1.0000
2.0040 199.6667 1.0000
2.0100 151.0000 1.0000
2.0160 142.5000 1.0000
2.0220 121.1667 1.0000
2.0280 138.3333 1.0000
2.0340 140.0000 1.0000
2.0400 154.0000 1.0000
2.0460 144.6667 1.0000
2.0520 136.1667 1.0000
2.0580 130.5000 1.0000
2.0640 131.1667 1.0000
2.0700 118.5000 1.0000
2.0760 131.8333 1.0000
2.0820 120.5000 1.0000
2.0880 130.0000 1.0000
2.0940 113.5000 1.0000
2.1000 101.8333 1.0000
2.1060 93.0000 1.0000
2.1120 103.0000 1.0000
2.1180 105.8333 1.0000
2.1240 104.6667 1.0000
2.1300 118.3333 1.0000
2.1360 129.6667 1.0000
2.1420 88.5000 1.0000
2.1480 101.8333 1.0000
2.1540 83.8333 1.0000
2.1600 97.1667 1.0000
2.1660 94.5000 1.0000
2.1720 83.0000 1.0000
2.1780 85.8333 1.0000
2.1840 86.8333 1.0000
2.1900 93.3333 1.0000
2.1960 95.0000 1.0000
2.2020 96.5000 1.0000
2.2080 88.6667 1.0000
2.2140 77.5000 1.0000
2.2200 82.3333 1.0000
2.2260 90.3333 1.0000
2.2320 78.6667 1.0000
2.2380 87.5000 1.0000
2.2440 73.5000 1.0000
2.2500 72.0000 1.0000
2.2560 72.5000 1.0000
2.2620 73.1667 1.0000
2.2680 72.1667 1.0000
2.2740 62.0000 1.0000
2.2800 68.6667 1.0000
2.2860 72.3333 1.0000
2.2920 63.8333 1.0000
2.2980 77.8333 1.0000
2.3040 76.3333 1.0000
2.3100 62.8333 1.0000
2.3160 61.1667 1.0000
2.3220 63.3333 1.0000
2.3280 62.1667 1.0000
2.3340 61.3333 1.0000
2.3400 63.3333 1.0000
2.3460 69.1667 1.0000
2.3520 46.5000 1.0000
2.3580 79.1667 1.0000
2.3640 77.3333 1.0000
2.3700 62.3333 1.0000
2.3760 56.5000 1.0000
2.3820 56.1667 1.0000
2.3880 48.3333 1.0000
2.3940 57.8333 1.0000
2.4000 52.5000 1.0000
2.4060 39.0000 1.0000
2.4120 52.1667 1.0000
2.4180 50.5000 1.0000
2.4240 52.8333 1.0000
2.4300 46.0000 1.0000
2.4360 47.1667 1.0000
2.4420 59.8333 1.0000
2.4480 52.5000 1.0000
2.4540 45.1667 1.0000
2.4600 47.3333 1.0000
2.4660 40.5000 1.0000
2.4720 34.6667 1.0000
2.4780 54.6667 1.0000
2.4840 38.0000 1.0000
2.4900 33.1667 1.0000
2.4960 44.6667 1.0000
2.5020 33.3333 1.0000
2.5080 32.8333 1.0000
2.5140 40.8333 1.0000
2.5200 37.8333 1.0000
2.5260 30.3333 1.0000
2.5320 46.5000 1.0000
2.5380 43.3333 1.0000
2.5440 32.8333 1.0000
2.5500 34.1667 1.0000
2.5560 35.5000 1.0000
2.5620 34.5000 1.0000
2.5680 25.5000 1.0000
2.5740 30.8333 1.0000
2.5800 33.3333 1.0000
2.5860 32.1667 1.0000
2.5920 30.0000 1.0000
2.5980 26.0000 1.0000
2.6040 48.3333 1.0000
2.6100 31.1667 1.0000
2.6160 32.6667 1.0000
2.6220 27.1667 1.0000
2.6280 32.8333 1.0000
2.6340 24.6667 1.0000
2.6400 35.1667 1.0000
2.6460 39.3333 1.0000
2.6520 37.3333 1.0000
2.6580 24.8333 1.0000
2.6640 32.1667 1.0000
2.6700 28.3333 1.0000
2.6760 27.5000 1.0000
2.6820 32.0000 1.0000
2.6880 22.8333 1.0000
2.6940 21.8333 1.0000
2.7000 17.1667 1.0000
2.7060 29.3333 1.0000
2.7120 18.3333 1.0000
2.7180 31.0000 1.0000
2.7240 23.0000 1.0000
2.7300 29.3333 1.0000
2.7360 24.3333 1.0000
2.7420 25.0000 1.0000
2.7480 26.6667 1.0000
2.7540 21.3333 1.0000
2.7600 29.5000 1.0000
2.7660 21.3333 1.0000
2.7720 17.8333 1.0000
2.7780 20.5000 1.0000
2.7840 13.6667 1.0000
2.7900 18.0000 1.0000
2.7960 11.6667 1.0000
2.8020 12.5000 1.0000
2.8080 20.6667 1.0000
2.8140 13.8333 1.0000
2.8200 18.3333 1.0000
2.8260 18.0000 1.0000
2.8320 13.1667 1.0000
2.8380 17.3333 1.0000
2.8440 13.8333 1.0000
2.8500 12.3333 1.0000
2.8560 18.8333 1.0000
2.8620 13.5000 1.0000
2.8680 13.0000 1.0000
2.8740 10.6667 1.0000
2.8800 13.5000 1.0000
2.8860 16.0000 1.0000
2.8920 27.1667 1.0000
2.8980 12.1667 1.0000
2.9040 13.5000 1.0000
2.9100 14.6667 1.0000
2.9160 13.1667 1.0000
2.9220 14.1667 1.0000
2.9280 10.0000 1.0000
2.9340 14.6667 1.0000
2.9400 14.0000 1.0000
2.9460 17.6667 1.0000
2.9520 17.8333 1.0000
2.9580 14.6667 1.0000
2.9640 23.3333 1.0000
2.9700 21.3333 1.0000
2.9760 13.1667 1.0000
2.9820 13.1667 1.0000
2.9880 10.8333 1.0000
2.9940 10.6667 1.0000
3.0000 15.6667 1.0000
3.0060 10.3333 1.0000
3.0120 12.3333 1.0000
3.0180 9.8333 1.0000
3.0240 12.8333 1.0000
3.0300 9.8333 1.0000
3.0360 12.0000 1.0000
3.0420 3.8333 1.0000
3.0480 12.1667 1.0000
3.0540 7.3333 1.0000
3.0600 9.5000 1.0000
3.0660 11.0000 1.0000
3.0720 9.6667 1.0000
3.0780 9.5000 1.0000
3.0840 7.8333 1.0000
3.0900 13.0000 1.0000
3.0960 11.3333 1.0000
3.1020 12.6667 1.0000
3.1080 8.0000 1.0000
3.1140 6.3333 1.0000
3.1200 5.8333 1.0000
3.1260 7.5000 1.0000
3.1320 13.0000 1.0000
3.1380 5.5000 1.0000
3.1440 6.5000 1.0000
3.1500 6.5000 1.0000
3.1560 6.8333 1.0000
3.1620 12.3333 1.0000
3.1680 6.6667 1.0000
3.1740 7.3333 1.0000
3.1800 8.5000 1.0000
3.1860 6.5000 1.0000
3.1920 7.8333 1.0000
3.1980 11.6667 1.0000
3.2040 5.5000 1.0000
3.2100 9.1667 1.0000
3.2160 7.1667 1.0000
3.2220 6.1667 1.0000
3.2280 9.0000 1.0000
3.2340 4.6667 1.0000
3.2400 6.3333 1.0000
3.2460 6.1667 1.0000
3.2520 9.8333 1.0000
3.2580 7.3333 1.0000
3.2640 3.5000 1.0000
3.2700 10.6667 1.0000
3.2760 5.6667 1.0000
3.2820 7.0000 1.0000
3.2880 3.3333 1.0000
3.2940 8.8333 1.0000
3.3000 6.8333 1.0000
3.3060 2.1667 1.0000
3.3120 1.8333 1.0000
3.3180 3.5000 1.0000
3.3240 4.0000 1.0000
3.3300 2.0000 1.0000
3.3360 1.3333 1.0000
3.3420 5.0000 1.0000
3.3480 4.8333 1.0000
3.3540 1.1667 1.0000
3.3600 2.3333 1.0000
3.3660 4.8333 1.0000
3.3720 3.6667 1.0000
3.3780 3.3333 1.0000
3.3840 9.3333 1.0000
3.3900 1.1667 1.0000
3.3960 4.5000 1.0000
3.4020 7.6667 1.0000
3.4080 4.6667 1.0000
3.4140 5.5000 1.0000
3.4200 4.1667 1.0000
3.4260 7.5000 1.0000
3.4320 2.5000 1.0000
3.4380 7.1667 1.0000
3.4440 2.6667 1.0000
3.4500 3.3333 1.0000
3.4560 4.5000 1.0000
3.4620 0.0000 1.0000
3.4680 2.6667 1.0000
3.4740 4.3333 1.0000
3.4800 6.3333 1.0000
3.4860 7.3333 1.0000
3.4920 0.3333 1.0000
3.4980 6.3333 1.0000
3.5040 3.5000 1.0000
3.5100 4.5000 1.0000
3.5160 6.5000 1.0000
3.5220 5.6667 1.0000
3.5280 4.0000 1.0000
3.5340 4.0000 1.0000
3.5400 4.5000 1.0000
3.5460 2.6667 1.0000
3.5520 0.0000 1.0000
3.5580 0.0000 1.0000
3.5640 0.3333 1.0000
3.5700 1.1667 1.0000
3.5760 3.3333 1.0000
3.5820 2.6667 1.0000
3.5880 4.5000 1.0000
3.5940 1.1667 1.0000
3.6000 0.0000 1.0000
3.6060 3.3333 1.0000
3.6120 3.3333 1.0000
3.6180 6.5000 1.0000
3.6240 4.6667 1.0000
3.6300 0.1667 1.0000
3.6360 2.6667 1.0000
3.6420 0.1667 1.0000
3.6480 2.5000 1.0000
3.6540 0.0000 1.0000
3.6600 3.3333 1.0000
3.6660 0.3333 1.0000
3.6720 0.0000 1.0000
3.6780 0.1667 1.0000
3.6840 0.1667 1.0000
3.6900 0.0000 1.0000
3.6960 1.3333 1.0000
3.7020 2.5000 1.0000
3.7080 2.0000 1.0000
3.7140 2.1667 1.0000
3.7200 0.0000 1.0000
3.7260 0.0000 1.0000
3.7320 0.1667 1.0000
3.7380 2.1667 1.0000
3.7440 2.0000 1.0000
3.7500 1.5000 1.0000
3.7560 1.1667 1.0000
3.7620 0.1667 1.0000
3.7680 3.0000 1.0000
3.7740 0.0000 1.0000
3.7800 0.3333 1.0000
3.7860 2.0000 1.0000
3.7920 6.5000 1.0000
3.7980 2.3333 1.0000
3.8040 2.0000 1.0000
3.8100 0.3333 1.0000
3.8160 5.0000 1.0000
3.8220 3.1667 1.0000
3.8280 5.3333 1.0000
3.8340 3.3333 1.0000
3.8400 2.1667 1.0000
3.8460 1.3333 1.0000
3.8520 6.5000 1.0000
3.8580 0.0000 1.0000
3.8640 0.1667 1.0000
3.8700 3.0000 1.0000
3.8760 0.0000 1.0000
3.8820 5.1667 1.0000
3.8880 0.0000 1.0000
3.8940 2.0000 1.0000
3.9000 3.1667 1.0000
3.9060 0.0000 1.0000
3.9120 3.1667 1.0000
3.9180 0.0000 1.0000
3.9240 3.0000 1.0000
3.9300 0.0000 1.0000
3.9360 2.1667 1.0000
3.9420 2.1667 1.0000
3.9480 0.1667 1.0000
3.9540 1.1667 1.0000
3.9600 0.0000 1.0000
3.9660 0.1667 1.0000
3.9720 5.1667 1.0000
3.9780 0.0000 1.0000
3.9840 4.3333 1.0000
3.9900 0.1667 1.0000
3.9960 5.3333 1.0000
4.0020 3.0000 1.0000
4.0080 0.0000 1.0000
4.0140 0.0000 1.0000
4.0200 2.3333 1.0000
4.0260 1.1667 1.0000
4.0320 3.3333 1.0000
4.0380 4.0000 1.0000
4.0440 0.3333 1.0000
4.0500 0.0000 1.0000
4.0560 3.0000 1.0000
4.0620 2.1667 1.0000
4.0680 3.0000 1.0000
4.0740 0.0000 1.0000
4.0800 0.1667 1.0000
4.0860 3.0000 1.0000
4.0920 0.3333 1.0000
4.0980 0.0000 1.0000
4.1040 0.0000 1.0000
4.1100 3.0000 1.0000
4.1160 5.3333 1.0000
4.1220 3.3333 1.0000
4.1280 1.1667 1.0000
4.1340 0.0000 1.0000
4.1400 4.0000 1.0000
4.1460 0.0000 1.0000
4.1520 2.3333 1.0000
4.1580 0.0000 1.0000
4.1640 0.1667 1.0000
4.1700 2.0000 1.0000
4.1760 0.0000 1.0000
4.1820 0.0000 1.0000
4.1880 2.0000 1.0000
4.1940 0.0000 1.0000
4.2000 0.0000 1.0000
4.2060 0.0000 1.0000
4.2120 0.1667 1.0000
4.2180 2.3333 1.0000
4.2240 1.1667 1.0000
4.2300 0.0000 1.0000
4.2360 0.0000 1.0000
4.2420 2.5000 1.0000
4.2480 0.0000 1.0000
4.2540 2.1667 1.0000
4.2600 1.1667 1.0000
4.2660 0.0000 1.0000
4.2720 1.1667 1.0000
4.2780 0.0000 1.0000
4.2840 0.0000 1.0000
4.2900 2.0000 1.0000
4.2960 0.1667 1.0000
4.3020 2.3333 1.0000
4.3080 0.1667 1.0000
4.3140 1.1667 1.0000
4.3200 2.3333 1.0000
4.3260 0.0000 1.0000
4.3320 2.1667 1.0000
4.3380 0.0000 1.0000
4.3440 0.0000 1.0000
4.3500 0.0000 1.0000
4.3560 1.1667 1.0000
4.3620 2.1667 1.0000
4.3680 3.3333 1.0000
4.3740 1.1667 1.0000
4.3800 2.1667 1.0000
4.3860 0.0000 1.0000
4.3920 0.1667 1.0000
4.3980 0.0000 1.0000
4.4040 0.0000 1.0000
4.4100 0.1667 1.0000
4.4160 0.1667 1.0000
4.4220 0.0000 1.0000
4.4280 2.1667 1.0000
4.4340 0.0000 1.0000
4.4400 0.0000 1.0000
4.4460 0.0000 1.0000
4.4520 0.0000 1.0000
4.4580 0.0000 1.0000
4.4640 2.5000 1.0000
4.4700 0.0000 1.0000
4.4760 0.0000 1.0000
4.4820 0.0000 1.0000
4.4880 3.0000 1.0000
4.4940 5.1667 1.0000
4.5000 0.3333 1.0000
4.5060 0.0000 1.0000
4.5120 6.1667 1.0000
4.5180 3.1667 1.0000
4.5240 2.3333 1.0000
4.5300 0.0000 1.0000
4.5360 3.3333 1.0000
4.5420 0.1667 1.0000
4.5480 0.0000 1.0000
4.5540 4.3333 1.0000
4.5600 0.0000 1.0000
4.5660 3.1667 1.0000
4.5720 1.1667 1.0000
4.5780 0.0000 1.0000
4.5840 2.0000 1.0000
4.5900 2.3333 1.0000
4.5960 0.0000 1.0000
4.6020 1.1667 1.0000
4.6080 3.0000 1.0000
4.6140 4.6667 1.0000
4.6200 0.1667 1.0000
4.6260 3.3333 1.0000
4.6320 1.1667 1.0000
4.6380 3.6667 1.0000
4.6440 2.0000 1.0000
4.6500 2.3333 1.0000
4.6560 0.0000 1.0000
4.6620 4.0000 1.0000
4.6680 3.0000 1.0000
4.6740 0.3333 1.0000
4.6800 3.0000 1.0000
4.6860 6.5000 1.0000
4.6920 1.1667 1.0000
4.6980 2.0000 1.0000
4.7040 1.1667 1.0000
4.7100 0.0000 1.0000
4.7160 0.0000 1.0000
4.7220 0.0000 1.0000
4.7280 1.1667 1.0000
4.7340 2.0000 1.0000
4.7400 3.0000 1.0000
4.7460 0.5000 1.0000
4.7520 7.8333 1.0000
4.7580 1.1667 1.0000
4.7640 6.5000 1.0000
4.7700 3.3333 1.0000
4.7760 5.3333 1.0000
4.7820 5.8333 1.0000
4.7880 0.3333 1.0000
4.7940 9.5000 1.0000
4.8000 10.3333 1.0000
4.8060 12.6667 1.0000
4.8120 12.3333 1.0000
4.8180 15.0000 1.0000
4.8240 12.3333 1.0000
4.8300 10.8333 1.0000
4.8360 16.1667 1.0000
4.8420 10.0000 1.0000
4.8480 13.5000 1.0000
4.8540 13.8333 1.0000
4.8600 11.8333 1.0000
4.8660 11.0000 1.0000
4.8720 6.3333 1.0000
4.8780 8.1667 1.0000
4.8840 14.6667 1.0000
4.8900 9.5000 1.0000
4.8960 2.5000 1.0000
4.9020 6.5000 1.0000
4.9080 6.1667 1.0000
4.9140 0.1667 1.0000
4.9200 3.5000 1.0000
4.9260 4.0000 1.0000
4.9320 2.0000 1.0000
4.9380 1.1667 1.0000
4.9440 2.1667 1.0000
4.9500 1.3333 1.0000
4.9560 0.0000 1.0000
4.9620 0.0000 1.0000
4.9680 3.1667 1.0000
4.9740 0.0000 1.0000
4.9800 0.5000 1.0000
4.9860 6.1667 1.0000
4.9920 0.0000 1.0000
4.9980 0.5000 1.0000
5.0040 0.0000 1.0000
5.0100 0.1667 1.0000
5.0160 0.0000 1.0000
5.0220 0.0000 1.0000
5.0280 1.1667 1.0000
5.0340 0.1667 1.0000
5.0400 0.1667 1.0000
5.0460 0.0000 1.0000
5.0520 0.0000 1.0000
5.0580 6.5000 1.0000
5.0640 0.0000 1.0000
5.0700 2.1667 1.0000
5.0760 0.0000 1.0000
5.0820 0.0000 1.0000
5.0880 0.0000 1.0000
5.0940 6.0000 1.0000
5.1000 3.3333 1.0000
5.1060 0.1667 1.0000
5.1120 2.3333 1.0000
5.1180 2.1667 1.0000
5.1240 0.1667 1.0000
5.1300 1.1667 1.0000
5.1360 0.0000 1.0000
5.1420 3.1667 1.0000
5.1480 1.1667 1.0000
5.1540 0.3333 1.0000
5.1600 0.0000 1.0000
5.1660 0.1667 1.0000
5.1720 2.1667 1.0000
5.1780 0.5000 1.0000
5.1840 2.1667 1.0000
5.1900 0.0000 1.0000
5.1960 0.0000 1.0000
5.2020 0.1667 1.0000
5.2080 0.0000 1.0000
5.2140 2.1667 1.0000
5.2200 1.1667 1.0000
5.2260 3.0000 1.0000
5.2320 0.0000 1.0000
5.2380 0.0000 1.0000
5.2440 0.1667 1.0000
5.2500 0.0000 1.0000
5.2560 3.0000 1.0000
5.2620 2.5000 1.0000
5.2680 1.1667 1.0000
5.2740 0.0000 1.0000
5.2800 1.8333 1.0000
5.2860 0.0000 1.0000
5.2920 0.0000 1.0000
5.2980 1.1667 1.0000
5.3040 0.1667 1.0000
5.3100 0.0000 1.0000
5.3160 3.5000 1.0000
5.3220 0.0000 1.0000
5.3280 0.1667 1.0000
5.3340 1.1667 1.0000
5.3400 0.0000 1.0000
5.3460 0.3333 1.0000
5.3520 2.3333 1.0000
5.3580 0.0000 1.0000
5.3640 3.0000 1.0000
5.3700 0.0000 1.0000
5.3760 2.0000 1.0000
5.3820 2.1667 1.0000
5.3880 1.1667 1.0000
5.3940 0.0000 1.0000
5.4000 2.3333 1.0000
5.4060 0.3333 1.0000
5.4120 2.1667 1.0000
5.4180 0.3333 1.0000
5.4240 0.0000 1.0000
5.4300 1.1667 1.0000
5.4360 0.0000 1.0000
5.4420 0.0000 1.0000
5.4480 0.0000 1.0000
5.4540 2.1667 1.0000
5.4600 0.3333 1.0000
5.4660 3.3333 1.0000
5.4720 0.0000 1.0000
5.4780 0.0000 1.0000
5.4840 5.1667 1.0000
5.4900 0.0000 1.0000
5.4960 0.0000 1.0000
5.5020 0.0000 1.0000
5.5080 0.3333 1.0000
5.5140 0.0000 1.0000
5.5200 2.0000 1.0000
5.5260 0.0000 1.0000
5.5320 0.0000 1.0000
5.5380 0.0000 1.0000
5.5440 2.3333 1.0000
5.5500 0.0000 1.0000
5.5560 0.0000 1.0000
5.5620 0.0000 1.0000
5.5680 0.0000 1.0000
5.5740 5.1667 1.0000
5.5800 0.0000 1.0000
5.5860 0.0000 1.0000
5.5920 3.0000 1.0000
5.5980 0.0000 1.0000
5.6040 3.0000 1.0000
5.6100 3.3333 1.0000
5.6160 0.0000 1.0000
5.6220 0.0000 1.0000
5.6280 0.0000 1.0000
5.6340 0.0000 1.0000
5.6400 0.1667 1.0000
5.6460 0.0000 1.0000
5.6520 1.3333 1.0000
5.6580 1.1667 1.0000
5.6640 0.0000 1.0000
5.6700 0.0000 1.0000
5.6760 0.0000 1.0000
5.6820 1.3333 1.0000
5.6880 0.0000 1.0000
5.6940 0.0000 1.0000
5.7000 0.0000 1.0000
5.7060 0.0000 1.0000
5.7120 0.1667 1.0000
5.7180 0.0000 1.0000
5.7240 2.0000 1.0000
5.7300 1.3333 1.0000
5.7360 0.0000 1.0000
5.7420 0.0000 1.0000
5.7480 0.0000 1.0000
5.7540 0.0000 1.0000
5.7600 2.3333 1.0000
5.7660 3.1667 1.0000
5.7720 2.0000 1.0000
5.7780 3.1667 1.0000
5.7840 1.1667 1.0000
5.7900 0.0000 1.0000
5.7960 0.1667 1.0000
5.8020 0.0000 1.0000
5.8080 1.1667 1.0000
5.8140 3.0000 1.0000
5.8200 0.0000 1.0000
5.8260 0.0000 1.0000
5.8320 3.3333 1.0000
5.8380 2.0000 1.0000
5.8440 0.0000 1.0000
5.8500 2.3333 1.0000
5.8560 0.0000 1.0000
5.8620 3.1667 1.0000
5.8680 0.0000 1.0000
5.8740 5.5000 1.0000
5.8800 0.0000 1.0000
5.8860 0.0000 1.0000
5.8920 4.0000 1.0000
5.8980 3.1667 1.0000
5.9040 0.0000 1.0000
5.9100 0.1667 1.0000
5.9160 0.0000 1.0000
5.9220 0.0000 1.0000
5.9280 1.3333 1.0000
5.9340 0.0000 1.0000
5.9400 2.0000 1.0000
5.9460 2.1667 1.0000
5.9520 0.1667 1.0000
5.9580 0.0000 1.0000
5.9640 2.0000 1.0000
5.9700 0.0000 1.0000
5.9760 2.3333 1.0000
5.9820 0.3333 1.0000
5.9880 0.0000 1.0000
5.9940 0.1667 1.0000
6.0000 2.1667 1.0000
*RAS_INT_END
*RAS_DATA_END