File: XRR/sub_reflectivity.ras
*RAS_DATA_START
*RAS_HEADER_START
*DISP_FMT_X "%.4f"
*DISP_FMT_Y "%.0f"
*DISP_FULLSCALE "28204537.7500000040"
*DISP_LINE_COLOR "255.0000000000"
*DISP_LINE_STYLE "0.0000000000"
*DISP_LINE_WIDTH "0.2500000000"
*DISP_NOTE "Collected Data-7"
*DISP_OFFSET_Y "0.0000000000"
*DISP_PEAKSEARCH_UNIT_Y "cps"
*DISP_RANGE_BOTTOM "0.0100000000"
*DISP_RANGE_LEFT "-0.0006000000"
*DISP_RANGE_LOGCUTOFF "0.0100000000"
*DISP_RANGE_RIGHT "6.0006000000"
*DISP_RANGE_TOP "28204537.7500000040"
*DISP_SCALE_MODE_Y "2.0000000000"
*DISP_TAB_NAME "2-Theta/Omega"
*DISP_TITLE_Y "Intensity"
*DISP_UNIT_Y "cps"
*DISP_WINDOW_NAME "MSG_MACROENGINE"
*FILE_COMMENT " "
*FILE_MD5 ""
*FILE_MEMO " "
*FILE_OPERATOR "administrator"
*FILE_PART_ID "MEAS_KHP2_00055"
*FILE_SAMPLE "CWO sub"
*FILE_TYPE "RAS_RAW"
*FILE_USERGROUP "System Manager"
*FILE_VERSION "1.0000000000"
*HW_ATTACHMENT_ID "ATT0025"
*HW_ATTACHMENT_NAME "標準|Standard"
*HW_COUNTER_ID-0 "CUT0025"
*HW_COUNTER_ID-1 "CUT0020"
*HW_COUNTER_ID-2 "CUT0020"
*HW_COUNTER_ID-3 "CSL0021"
*HW_COUNTER_ID-4 "CMC0021"
*HW_COUNTER_NAME-0 "D/teX Ultra|D/teX Ultra"
*HW_COUNTER_NAME-1 "None|None"
*HW_COUNTER_NAME-2 "None|None"
*HW_COUNTER_NAME-3 "BBM|BBM"
*HW_COUNTER_NAME-4 "検出器モノクロメータ|Detector monochromator"
*HW_COUNTER_SELECT_NAME "D/teX Ultra|D/teX Ultra"
*HW_GONIOMETER_ID "GON0023"
*HW_GONIOMETER_NAME "SmartLab|SmartLab"
*HW_GONIOMETER_RADIUS-0 "90.0"
*HW_GONIOMETER_RADIUS-1 "114.0"
*HW_GONIOMETER_RADIUS-2 "190.0"
*HW_GONIOMETER_RADIUS-3 "300.0"
*HW_GONIOMETER_RADIUS-4 "187.0"
*HW_GONIOMETER_RADIUS-5 "300.0"
*HW_GONIOMETER_RADIUS-6 "113.0"
*HW_GONIOMETER_RADIUS-7 "331.0"
*HW_I_OPT_ID-0 "CBO0021"
*HW_I_OPT_ID-1 "ICR0021"
*HW_I_OPT_ID-2 "ISL0021"
*HW_I_OPT_ID-3 "ISO0021"
*HW_I_OPT_ID-4 "IAD0021"
*HW_I_OPT_ID-5 "IPR0001"
*HW_I_OPT_NAME-0 "CBOユニット|CBO unit"
*HW_I_OPT_NAME-1 "標準入射光学ユニット|Standard incident optical unit"
*HW_I_OPT_NAME-2 "標準入射スリットボックス|Standard incident slit box"
*HW_I_OPT_NAME-3 "入射平行スリット|Incident parallel slit"
*HW_I_OPT_NAME-4 "長手制限スリット|Length limiting slit"
*HW_I_OPT_NAME-5 "None|None"
*HW_R_ATTENUATER_AUTOMODE "1"
*HW_R_OPT_ID-0 "RSS0021"
*HW_R_OPT_ID-1 "RCR0023"
*HW_R_OPT_ID-2 "RSO0021"
*HW_R_OPT_ID-3 "RRS0021"
*HW_R_OPT_ID-4 "ATN0021"
*HW_R_OPT_ID-5 "RFL0021"
*HW_R_OPT_ID-6 "RAD0021"
*HW_R_OPT_NAME-0 "標準受光スリットボックス1|Standard receiving slit box # 1"
*HW_R_OPT_NAME-1 "標準受光光学ユニット1|Standard receiving unit # 1"
*HW_R_OPT_NAME-2 "標準受光光学ユニット2|Standard receiving optical unit # 2"
*HW_R_OPT_NAME-3 "標準受光スリットボックス2|Standard receiving slit box # 2"
*HW_R_OPT_NAME-4 "標準アッテネータ|Standard Attenuator"
*HW_R_OPT_NAME-5 "Cu Kβ|Cu K-beta"
*HW_R_OPT_NAME-6 "調整用受光スリット|Alignment receiving slit"
*HW_SAMPLE_HOLDER_ID "SMP0021"
*HW_SAMPLE_HOLDER_NAME "χφZクレードル|Chi phi Z cradle"
*HW_XG_CURRENT_MAX "200"
*HW_XG_CURRENT_MIN "10"
*HW_XG_CURRENT_RESOLUTION "1"
*HW_XG_CURRENT_UNIT "mA"
*HW_XG_FOCUS "0.4mm x 8mm"
*HW_XG_FOCUS_TYPE "Normal"
*HW_XG_ID "1700"
*HW_XG_NAME "9kW 開放管(45kV 200mA ID:1700)|9kW Rotating anode(45kV 200mA ID:1700)"
*HW_XG_TARGET_ATOMIC_NUMBER "29.0000000000"
*HW_XG_TARGET_NAME "Cu"
*HW_XG_TYPE "Rota"
*HW_XG_VOLTAGE_MAX "45"
*HW_XG_VOLTAGE_MIN "20"
*HW_XG_VOLTAGE_RESOLUTION "1"
*HW_XG_VOLTAGE_UNIT "kV"
*HW_XG_WATT_MAX "9.00"
*HW_XG_WATT_UNIT "kW"
*HW_XG_WAVE_LENGTH_ALPHA1 "1.540593"
*HW_XG_WAVE_LENGTH_ALPHA2 "1.544414"
*HW_XG_WAVE_LENGTH_BETA "1.392250"
*MEAS_COND_AXIS_NAME-0 "Theta/2-Theta"
*MEAS_COND_AXIS_NAME-1 "2-Theta"
*MEAS_COND_AXIS_NAME-2 "Omega"
*MEAS_COND_AXIS_NAME-3 "Chi"
*MEAS_COND_AXIS_NAME-4 "Phi"
*MEAS_COND_AXIS_NAME-5 "Z"
*MEAS_COND_AXIS_NAME-6 "2-Theta/Omega"
*MEAS_COND_AXIS_NAME-7 "Theta_s"
*MEAS_COND_AXIS_NAME-8 "Theta_d"
*MEAS_COND_AXIS_NAME-9 "Ts"
*MEAS_COND_AXIS_NAME-10 "CBO selection slit"
*MEAS_COND_AXIS_NAME-11 "M"
*MEAS_COND_AXIS_NAME-12 "Incident parallel slit"
*MEAS_COND_AXIS_NAME-13 "Incident slit"
*MEAS_COND_AXIS_NAME-14 ""
*MEAS_COND_AXIS_NAME-15 "Zs"
*MEAS_COND_AXIS_NAME-16 "Incident optical device"
*MEAS_COND_AXIS_NAME-17 "Omega_m"
*MEAS_COND_AXIS_NAME-18 "Length limiting slit"
*MEAS_COND_AXIS_NAME-19 "Center slit"
*MEAS_COND_AXIS_NAME-20 "Filter"
*MEAS_COND_AXIS_NAME-21 "Receiving slit # 1"
*MEAS_COND_AXIS_NAME-22 "Receiving slit # 2"
*MEAS_COND_AXIS_NAME-23 "Receiving optical device"
*MEAS_COND_AXIS_NAME-24 "Receiving parallel slit"
*MEAS_COND_AXIS_NAME-25 "Alignment receiving slit"
*MEAS_COND_AXIS_NAME-26 ""
*MEAS_COND_AXIS_NAME-27 ""
*MEAS_COND_AXIS_NAME-28 "Zd"
*MEAS_COND_AXIS_NAME-29 "Attenuator"
*MEAS_COND_AXIS_NAME-30 "Diffracted beam monochromator"
*MEAS_COND_AXIS_NAME-31 "Monochromator slit"
*MEAS_COND_AXIS_NAME-32 "Primary beam"
*MEAS_COND_AXIS_NAME-33 ""
*MEAS_COND_AXIS_NAME-34 ""
*MEAS_COND_AXIS_NAME-35 "PHA"
*MEAS_COND_AXIS_NAME_INTERNAL-0 "TwoThetaTheta"
*MEAS_COND_AXIS_NAME_INTERNAL-1 "TwoTheta"
*MEAS_COND_AXIS_NAME_INTERNAL-2 "Omega"
*MEAS_COND_AXIS_NAME_INTERNAL-3 "Chi"
*MEAS_COND_AXIS_NAME_INTERNAL-4 "Phi"
*MEAS_COND_AXIS_NAME_INTERNAL-5 "Z"
*MEAS_COND_AXIS_NAME_INTERNAL-6 "TwoThetaOmega"
*MEAS_COND_AXIS_NAME_INTERNAL-7 "ThetaS"
*MEAS_COND_AXIS_NAME_INTERNAL-8 "ThetaD"
*MEAS_COND_AXIS_NAME_INTERNAL-9 "Ts"
*MEAS_COND_AXIS_NAME_INTERNAL-10 "CBO"
*MEAS_COND_AXIS_NAME_INTERNAL-11 "CBO-M"
*MEAS_COND_AXIS_NAME_INTERNAL-12 "IncidentSollerSlit"
*MEAS_COND_AXIS_NAME_INTERNAL-13 "IncidentSlitBox"
*MEAS_COND_AXIS_NAME_INTERNAL-14 "IncidentSlitBox-_Axis"
*MEAS_COND_AXIS_NAME_INTERNAL-15 "Zs"
*MEAS_COND_AXIS_NAME_INTERNAL-16 "IncidentMonochromator"
*MEAS_COND_AXIS_NAME_INTERNAL-17 "IncidentMonochromator-OmegaM"
*MEAS_COND_AXIS_NAME_INTERNAL-18 "IncidentAxdSlit"
*MEAS_COND_AXIS_NAME_INTERNAL-19 "CenterSlit"
*MEAS_COND_AXIS_NAME_INTERNAL-20 "Filter"
*MEAS_COND_AXIS_NAME_INTERNAL-21 "ReceivingSlitBox1"
*MEAS_COND_AXIS_NAME_INTERNAL-22 "ReceivingSlitBox2"
*MEAS_COND_AXIS_NAME_INTERNAL-23 "ReceivingOptics"
*MEAS_COND_AXIS_NAME_INTERNAL-24 "ReceivingSollerSlit"
*MEAS_COND_AXIS_NAME_INTERNAL-25 "ReceivingAxdSlit"
*MEAS_COND_AXIS_NAME_INTERNAL-26 "ReceivingSlitBox1-_Axis"
*MEAS_COND_AXIS_NAME_INTERNAL-27 "ReceivingSlitBox2-_Axis"
*MEAS_COND_AXIS_NAME_INTERNAL-28 "ReceivingSlitBox2-Zd"
*MEAS_COND_AXIS_NAME_INTERNAL-29 "Attenuator"
*MEAS_COND_AXIS_NAME_INTERNAL-30 "CounterMonochromator"
*MEAS_COND_AXIS_NAME_INTERNAL-31 "CounterSlit"
*MEAS_COND_AXIS_NAME_INTERNAL-32 "IncidentPrimary"
*MEAS_COND_AXIS_NAME_INTERNAL-33 "AlphaR"
*MEAS_COND_AXIS_NAME_INTERNAL-34 "BetaR"
*MEAS_COND_AXIS_NAME_INTERNAL-35 "PHA"
*MEAS_COND_AXIS_NAME_MAGICNO-0 "83951616.0000000000"
*MEAS_COND_AXIS_NAME_MAGICNO-1 "268632064.0000000000"
*MEAS_COND_AXIS_NAME_MAGICNO-2 "268500992.0000000000"
*MEAS_COND_AXIS_NAME_MAGICNO-3 "268500992.0000000000"
*MEAS_COND_AXIS_NAME_MAGICNO-4 "268500992.0000000000"
*MEAS_COND_AXIS_NAME_MAGICNO-5 "285278208.0000000000"
*MEAS_COND_AXIS_NAME_MAGICNO-6 "83951616.0000000000"
*MEAS_COND_AXIS_NAME_MAGICNO-7 "131072.0000000000"
*MEAS_COND_AXIS_NAME_MAGICNO-8 "131072.0000000000"
*MEAS_COND_AXIS_NAME_MAGICNO-9 "318898176.0000000000"
*MEAS_COND_AXIS_NAME_MAGICNO-10 "20971521.0000000000"
*MEAS_COND_AXIS_NAME_MAGICNO-11 "285343744.0000000000"
*MEAS_COND_AXIS_NAME_MAGICNO-12 "20971521.0000000000"
*MEAS_COND_AXIS_NAME_MAGICNO-13 "22020097.0000000000"
*MEAS_COND_AXIS_NAME_MAGICNO-14 "25165824.0000000000"
*MEAS_COND_AXIS_NAME_MAGICNO-15 "318898176.0000000000"
*MEAS_COND_AXIS_NAME_MAGICNO-16 "20971521.0000000000"
*MEAS_COND_AXIS_NAME_MAGICNO-17 "285343744.0000000000"
*MEAS_COND_AXIS_NAME_MAGICNO-18 "20971521.0000000000"
*MEAS_COND_AXIS_NAME_MAGICNO-19 "20971521.0000000000"
*MEAS_COND_AXIS_NAME_MAGICNO-20 "20971521.0000000000"
*MEAS_COND_AXIS_NAME_MAGICNO-21 "23068673.0000000000"
*MEAS_COND_AXIS_NAME_MAGICNO-22 "23068673.0000000000"
*MEAS_COND_AXIS_NAME_MAGICNO-23 "20971521.0000000000"
*MEAS_COND_AXIS_NAME_MAGICNO-24 "20971521.0000000000"
*MEAS_COND_AXIS_NAME_MAGICNO-25 "20971521.0000000000"
*MEAS_COND_AXIS_NAME_MAGICNO-26 "25165824.0000000000"
*MEAS_COND_AXIS_NAME_MAGICNO-27 "25165824.0000000000"
*MEAS_COND_AXIS_NAME_MAGICNO-28 "285343744.0000000000"
*MEAS_COND_AXIS_NAME_MAGICNO-29 "17301505.0000000000"
*MEAS_COND_AXIS_NAME_MAGICNO-30 "20971521.0000000000"
*MEAS_COND_AXIS_NAME_MAGICNO-31 "20971521.0000000000"
*MEAS_COND_AXIS_NAME_MAGICNO-32 "20971521.0000000000"
*MEAS_COND_AXIS_NAME_MAGICNO-33 "8388608.0000000000"
*MEAS_COND_AXIS_NAME_MAGICNO-34 "8388608.0000000000"
*MEAS_COND_AXIS_NAME_MAGICNO-35 "0.0000000000"
*MEAS_COND_AXIS_OFFSET-0 "-"
*MEAS_COND_AXIS_OFFSET-1 "0.9117000000"
*MEAS_COND_AXIS_OFFSET-2 "0.8116000000"
*MEAS_COND_AXIS_OFFSET-3 "0.0000000000"
*MEAS_COND_AXIS_OFFSET-4 "0.0000000000"
*MEAS_COND_AXIS_OFFSET-5 "-"
*MEAS_COND_AXIS_OFFSET-6 "-"
*MEAS_COND_AXIS_OFFSET-7 "0.8116000000"
*MEAS_COND_AXIS_OFFSET-8 "0.1001000000"
*MEAS_COND_AXIS_OFFSET-9 "-"
*MEAS_COND_AXIS_OFFSET-10 "-"
*MEAS_COND_AXIS_OFFSET-11 "-"
*MEAS_COND_AXIS_OFFSET-12 "-"
*MEAS_COND_AXIS_OFFSET-13 "-"
*MEAS_COND_AXIS_OFFSET-14 "-"
*MEAS_COND_AXIS_OFFSET-15 "-"
*MEAS_COND_AXIS_OFFSET-16 "-"
*MEAS_COND_AXIS_OFFSET-17 "-"
*MEAS_COND_AXIS_OFFSET-18 "-"
*MEAS_COND_AXIS_OFFSET-19 "-"
*MEAS_COND_AXIS_OFFSET-20 "-"
*MEAS_COND_AXIS_OFFSET-21 "-"
*MEAS_COND_AXIS_OFFSET-22 "-"
*MEAS_COND_AXIS_OFFSET-23 "-"
*MEAS_COND_AXIS_OFFSET-24 "-"
*MEAS_COND_AXIS_OFFSET-25 "-"
*MEAS_COND_AXIS_OFFSET-26 "-"
*MEAS_COND_AXIS_OFFSET-27 "-"
*MEAS_COND_AXIS_OFFSET-28 "-"
*MEAS_COND_AXIS_OFFSET-29 "-"
*MEAS_COND_AXIS_OFFSET-30 "-"
*MEAS_COND_AXIS_OFFSET-31 "-"
*MEAS_COND_AXIS_OFFSET-32 "-"
*MEAS_COND_AXIS_OFFSET-33 "0.0000000000"
*MEAS_COND_AXIS_OFFSET-34 "0.0000000000"
*MEAS_COND_AXIS_OFFSET-35 "-"
*MEAS_COND_AXIS_POSITION-0 "-0.0008000000"
*MEAS_COND_AXIS_POSITION-1 "-0.0009000000"
*MEAS_COND_AXIS_POSITION-2 "-0.0004000000"
*MEAS_COND_AXIS_POSITION-3 "0.0000000000"
*MEAS_COND_AXIS_POSITION-4 "0.0000000000"
*MEAS_COND_AXIS_POSITION-5 "-1.4282000000"
*MEAS_COND_AXIS_POSITION-6 "-0.0008000000"
*MEAS_COND_AXIS_POSITION-7 "-0.0004000000"
*MEAS_COND_AXIS_POSITION-8 "-0.0005000000"
*MEAS_COND_AXIS_POSITION-9 "-4.8858800000"
*MEAS_COND_AXIS_POSITION-10 "PB"
*MEAS_COND_AXIS_POSITION-11 "0.0000000000"
*MEAS_COND_AXIS_POSITION-12 "Soller_slit_open_s"
*MEAS_COND_AXIS_POSITION-13 "0.250mm"
*MEAS_COND_AXIS_POSITION-14 "0.2500000000"
*MEAS_COND_AXIS_POSITION-15 "-1.8040600000"
*MEAS_COND_AXIS_POSITION-16 "Ge(220)x2"
*MEAS_COND_AXIS_POSITION-17 "0.0000000000"
*MEAS_COND_AXIS_POSITION-18 "2.0mm"
*MEAS_COND_AXIS_POSITION-19 "None"
*MEAS_COND_AXIS_POSITION-20 "None"
*MEAS_COND_AXIS_POSITION-21 "0.250mm"
*MEAS_COND_AXIS_POSITION-22 "0.250mm"
*MEAS_COND_AXIS_POSITION-23 "No_unit"
*MEAS_COND_AXIS_POSITION-24 "Soller_slit_5.0deg"
*MEAS_COND_AXIS_POSITION-25 "None"
*MEAS_COND_AXIS_POSITION-26 "0.2500000000"
*MEAS_COND_AXIS_POSITION-27 "0.2500000000"
*MEAS_COND_AXIS_POSITION-28 "0.0928100000"
*MEAS_COND_AXIS_POSITION-29 "1/10000"
*MEAS_COND_AXIS_POSITION-30 "None"
*MEAS_COND_AXIS_POSITION-31 "None"
*MEAS_COND_AXIS_POSITION-32 "None"
*MEAS_COND_AXIS_POSITION-33 "0.0000000000"
*MEAS_COND_AXIS_POSITION-34 "0.0000000000"
*MEAS_COND_AXIS_POSITION-35 "34.0000000000"
*MEAS_COND_AXIS_UNIT-0 "deg"
*MEAS_COND_AXIS_UNIT-1 "deg"
*MEAS_COND_AXIS_UNIT-2 "deg"
*MEAS_COND_AXIS_UNIT-3 "deg"
*MEAS_COND_AXIS_UNIT-4 "deg"
*MEAS_COND_AXIS_UNIT-5 "mm"
*MEAS_COND_AXIS_UNIT-6 "deg"
*MEAS_COND_AXIS_UNIT-7 "deg"
*MEAS_COND_AXIS_UNIT-8 "deg"
*MEAS_COND_AXIS_UNIT-9 "mm"
*MEAS_COND_AXIS_UNIT-10 ""
*MEAS_COND_AXIS_UNIT-11 "pulse"
*MEAS_COND_AXIS_UNIT-12 ""
*MEAS_COND_AXIS_UNIT-13 ""
*MEAS_COND_AXIS_UNIT-14 "mm"
*MEAS_COND_AXIS_UNIT-15 "mm"
*MEAS_COND_AXIS_UNIT-16 ""
*MEAS_COND_AXIS_UNIT-17 "pulse"
*MEAS_COND_AXIS_UNIT-18 ""
*MEAS_COND_AXIS_UNIT-19 ""
*MEAS_COND_AXIS_UNIT-20 ""
*MEAS_COND_AXIS_UNIT-21 ""
*MEAS_COND_AXIS_UNIT-22 ""
*MEAS_COND_AXIS_UNIT-23 ""
*MEAS_COND_AXIS_UNIT-24 ""
*MEAS_COND_AXIS_UNIT-25 ""
*MEAS_COND_AXIS_UNIT-26 "mm"
*MEAS_COND_AXIS_UNIT-27 "mm"
*MEAS_COND_AXIS_UNIT-28 "mm"
*MEAS_COND_AXIS_UNIT-29 ""
*MEAS_COND_AXIS_UNIT-30 ""
*MEAS_COND_AXIS_UNIT-31 ""
*MEAS_COND_AXIS_UNIT-32 ""
*MEAS_COND_AXIS_UNIT-33 "deg"
*MEAS_COND_AXIS_UNIT-34 "deg"
*MEAS_COND_AXIS_UNIT-35 "div"
*MEAS_COND_COUNTER_CNTLOSS_CORR "0.0000000000"
*MEAS_COND_COUNTER_PHABASE "34.0000000000"
*MEAS_COND_COUNTER_PHAWINDOW "19.0000000000"
*MEAS_COND_COUNTER_PHA_UNIT "div"
*MEAS_COND_COUNTER_TAUDIFF "2.0000000000"
*MEAS_COND_COUNTER_TAUINT "0.1000000000"
*MEAS_COND_IRRADIATION_MODE "OFF"
*MEAS_COND_IRRADIATION_WIDTH ""
*MEAS_COND_OPT_ATTR "High resolution parallel beam Ge(220)x2/RS"
*MEAS_COND_OPT_NAME "@High resolution PB-Ge(220)x2"
*MEAS_COND_UNSYMMETRIC_MODE "OFF"
*MEAS_COND_XG_CURRENT "200.0000000000"
*MEAS_COND_XG_VOLTAGE "45.0000000000"
*MEAS_COND_XG_WAVE_TYPE "Ka1"
*MEAS_DATA_COUNT "3001.0000000000"
*MEAS_SCAN_AXIS_X "2-Theta/Omega"
*MEAS_SCAN_AXIS_X_INTERNAL "TwoThetaOmega"
*MEAS_SCAN_END_TIME "11/07/23 13:38:51"
*MEAS_SCAN_MODE "CONTINUOUS"
*MEAS_SCAN_MONITOR "0"
*MEAS_SCAN_RESOLUTION_X "0.0002"
*MEAS_SCAN_SPEED "0.500000"
*MEAS_SCAN_SPEED_UNIT "deg/min"
*MEAS_SCAN_SPEED_USER "0.500000"
*MEAS_SCAN_START "0.0000000000"
*MEAS_SCAN_START_TIME "11/07/23 13:26:21"
*MEAS_SCAN_STEP "0.0020000000"
*MEAS_SCAN_STOP "6.0000000000"
*MEAS_SCAN_UNIT_X "deg"
*MEAS_SCAN_UNIT_Y "counts"
*RAS_HEADER_END
*RAS_INT_START
0.0000 5331002.5000 1.0000
0.0060 5505470.5000 1.0000
0.0120 5570155.0000 1.0000
0.0180 5447544.5000 1.0000
0.0240 5331002.5000 1.0000
0.0300 4973377.0000 1.0000
0.0360 4424733.5000 1.0000
0.0420 3561357.2500 1.0000
0.0480 2532340.0000 1.0000
0.0540 1617795.7500 1.0000
0.0600 911004.6875 1.0000
0.0660 478322.1250 1.0000
0.0720 238274.7969 1.0000
0.0780 151255.6719 1.0000
0.0840 113525.5391 1.0000
0.0900 95785.0859 1.0000
0.0960 88106.4844 1.0000
0.1020 87376.6094 1.0000
0.1080 97170.3594 1.0000
0.1140 99881.3281 1.0000
0.1200 99806.8516 1.0000
0.1260 109347.3750 1.0000
0.1320 111916.8359 1.0000
0.1380 115394.9219 1.0000
0.1440 118597.4453 1.0000
0.1500 126931.4375 1.0000
0.1560 135131.3750 1.0000
0.1620 133969.5313 1.0000
0.1680 142757.8281 1.0000
0.1740 145789.0625 1.0000
0.1800 147621.1875 1.0000
0.1860 154056.0156 1.0000
0.1920 159284.3125 1.0000
0.1980 160997.2969 1.0000
0.2040 164989.2656 1.0000
0.2100 170195.2188 1.0000
0.2160 175661.8438 1.0000
0.2220 181672.1563 1.0000
0.2280 182320.1094 1.0000
0.2340 189939.1250 1.0000
0.2400 198116.7031 1.0000
0.2460 200730.8594 1.0000
0.2520 204253.6250 1.0000
0.2580 209295.7344 1.0000
0.2640 212274.8125 1.0000
0.2700 210695.9063 1.0000
0.2760 219096.9219 1.0000
0.2820 222679.2813 1.0000
0.2880 225896.7031 1.0000
0.2940 236137.2969 1.0000
0.3000 240084.5938 1.0000
0.3060 245886.3594 1.0000
0.3120 242646.6094 1.0000
0.3180 250883.7813 1.0000
0.3240 255918.4375 1.0000
0.3300 262777.7813 1.0000
0.3360 260163.6406 1.0000
0.3420 269324.3125 1.0000
0.3480 276086.8438 1.0000
0.3540 277129.5313 1.0000
0.3600 280756.5938 1.0000
0.3660 284681.5313 1.0000
0.3720 289529.9688 1.0000
0.3780 295398.7813 1.0000
0.3840 299107.7500 1.0000
0.3900 302556.0313 1.0000
0.3960 309497.3125 1.0000
0.4020 312118.9063 1.0000
0.4080 311984.8438 1.0000
0.4140 322471.2500 1.0000
0.4200 314487.2813 1.0000
0.4260 315842.7813 1.0000
0.4320 326515.3438 1.0000
0.4380 330507.3125 1.0000
0.4440 332205.4063 1.0000
0.4500 336100.5625 1.0000
0.4560 345745.3438 1.0000
0.4620 349551.1250 1.0000
0.4680 340256.3750 1.0000
0.4740 347093.3750 1.0000
0.4800 353185.6250 1.0000
0.4860 358339.4375 1.0000
0.4920 362986.8125 1.0000
0.4980 358339.4375 1.0000
0.5040 374232.8750 1.0000
0.5100 369086.5000 1.0000
0.5160 367105.4063 1.0000
0.5220 374225.4063 1.0000
0.5280 379006.8438 1.0000
0.5340 372140.0625 1.0000
0.5400 379453.7188 1.0000
0.5460 380302.7500 1.0000
0.5520 385493.8125 1.0000
0.5580 385970.4688 1.0000
0.5640 385374.6563 1.0000
0.5700 378344.0000 1.0000
0.5760 382969.0313 1.0000
0.5820 380570.8750 1.0000
0.5880 380719.8438 1.0000
0.5940 376675.7188 1.0000
0.6000 374858.4688 1.0000
0.6060 368855.6250 1.0000
0.6120 354824.1250 1.0000
0.6180 359426.8125 1.0000
0.6240 349268.1250 1.0000
0.6300 337024.0625 1.0000
0.6360 314740.5000 1.0000
0.6420 308022.6563 1.0000
0.6480 289373.5938 1.0000
0.6540 273755.7188 1.0000
0.6600 258026.1563 1.0000
0.6660 235548.9375 1.0000
0.6720 208848.8750 1.0000
0.6780 195696.2031 1.0000
0.6840 176205.5313 1.0000
0.6900 165086.0781 1.0000
0.6960 149259.6875 1.0000
0.7020 133336.4688 1.0000
0.7080 124667.3281 1.0000
0.7140 111566.7969 1.0000
0.7200 106077.8281 1.0000
0.7260 96135.1250 1.0000
0.7320 90601.4766 1.0000
0.7380 84315.6016 1.0000
0.7440 77523.2813 1.0000
0.7500 73114.2344 1.0000
0.7560 66649.6172 1.0000
0.7620 65033.4609 1.0000
0.7680 61600.0625 1.0000
0.7740 60482.9063 1.0000
0.7800 57302.0313 1.0000
0.7860 54866.8320 1.0000
0.7920 51887.8320 1.0000
0.7980 49996.3320 1.0000
0.8040 47137.3320 1.0000
0.8100 45219.8320 1.0000
0.8160 43328.8320 1.0000
0.8220 41294.8320 1.0000
0.8280 39660.5000 1.0000
0.8340 37909.3320 1.0000
0.8400 36324.1680 1.0000
0.8460 35218.5000 1.0000
0.8520 33609.0000 1.0000
0.8580 32245.8340 1.0000
0.8640 31213.5000 1.0000
0.8700 30021.0000 1.0000
0.8760 28842.0000 1.0000
0.8820 27734.5000 1.0000
0.8880 26684.5000 1.0000
0.8940 26011.5000 1.0000
0.9000 25179.5000 1.0000
0.9060 24121.5000 1.0000
0.9120 23096.5000 1.0000
0.9180 22700.6660 1.0000
0.9240 21710.0000 1.0000
0.9300 21137.3340 1.0000
0.9360 20261.8340 1.0000
0.9420 19964.3340 1.0000
0.9480 19421.6660 1.0000
0.9540 18612.0000 1.0000
0.9600 18074.3340 1.0000
0.9660 17782.1660 1.0000
0.9720 17058.0000 1.0000
0.9780 16519.5000 1.0000
0.9840 16153.0000 1.0000
0.9900 15550.8330 1.0000
0.9960 15114.5000 1.0000
1.0020 14732.0000 1.0000
1.0080 14552.5000 1.0000
1.0140 14005.8330 1.0000
1.0200 13603.8330 1.0000
1.0260 13201.8330 1.0000
1.0320 12889.1670 1.0000
1.0380 12571.8330 1.0000
1.0440 12208.1670 1.0000
1.0500 11874.6670 1.0000
1.0560 11849.0000 1.0000
1.0620 11374.8330 1.0000
1.0680 11062.0000 1.0000
1.0740 10534.1670 1.0000
1.0800 10363.8330 1.0000
1.0860 10207.8330 1.0000
1.0920 9984.8330 1.0000
1.0980 9772.8330 1.0000
1.1040 9437.0000 1.0000
1.1100 9249.5000 1.0000
1.1160 9070.3330 1.0000
1.1220 8961.0000 1.0000
1.1280 8586.1670 1.0000
1.1340 8551.1670 1.0000
1.1400 8412.3330 1.0000
1.1460 8020.1665 1.0000
1.1520 8037.6665 1.0000
1.1580 7679.3335 1.0000
1.1640 7657.1665 1.0000
1.1700 7546.8335 1.0000
1.1760 7229.6665 1.0000
1.1820 7002.6665 1.0000
1.1880 6883.5000 1.0000
1.1940 6783.1665 1.0000
1.2000 6494.6665 1.0000
1.2060 6457.0000 1.0000
1.2120 6412.6665 1.0000
1.2180 6162.6665 1.0000
1.2240 6023.5000 1.0000
1.2300 5992.1665 1.0000
1.2360 5958.6665 1.0000
1.2420 5642.0000 1.0000
1.2480 5695.1665 1.0000
1.2540 5462.8335 1.0000
1.2600 5408.1665 1.0000
1.2660 5348.0000 1.0000
1.2720 5191.0000 1.0000
1.2780 5094.5000 1.0000
1.2840 4932.0000 1.0000
1.2900 4945.1665 1.0000
1.2960 4730.8335 1.0000
1.3020 4718.5000 1.0000
1.3080 4632.3335 1.0000
1.3140 4479.8335 1.0000
1.3200 4376.3335 1.0000
1.3260 4388.6665 1.0000
1.3320 4277.1665 1.0000
1.3380 4133.5000 1.0000
1.3440 4100.8335 1.0000
1.3500 4029.1667 1.0000
1.3560 3918.3333 1.0000
1.3620 4035.1667 1.0000
1.3680 3848.0000 1.0000
1.3740 3853.5000 1.0000
1.3800 3656.8333 1.0000
1.3860 3581.6667 1.0000
1.3920 3572.1667 1.0000
1.3980 3473.1667 1.0000
1.4040 3506.5000 1.0000
1.4100 3303.8333 1.0000
1.4160 3317.1667 1.0000
1.4220 3154.8333 1.0000
1.4280 3259.5000 1.0000
1.4340 3083.8333 1.0000
1.4400 3100.1667 1.0000
1.4460 3058.0000 1.0000
1.4520 3035.8333 1.0000
1.4580 2952.6667 1.0000
1.4640 2927.1667 1.0000
1.4700 2826.8333 1.0000
1.4760 2697.8333 1.0000
1.4820 2694.6667 1.0000
1.4880 2671.0000 1.0000
1.4940 2689.8333 1.0000
1.5000 2559.0000 1.0000
1.5060 2561.1667 1.0000
1.5120 2506.0000 1.0000
1.5180 2564.6667 1.0000
1.5240 2359.5000 1.0000
1.5300 2500.6667 1.0000
1.5360 2440.6667 1.0000
1.5420 2296.8333 1.0000
1.5480 2231.3333 1.0000
1.5540 2268.3333 1.0000
1.5600 2242.0000 1.0000
1.5660 2164.3333 1.0000
1.5720 2075.5000 1.0000
1.5780 2096.8333 1.0000
1.5840 2013.1666 1.0000
1.5900 2022.1666 1.0000
1.5960 2002.5000 1.0000
1.6020 1983.3334 1.0000
1.6080 1946.0000 1.0000
1.6140 1860.5000 1.0000
1.6200 1869.0000 1.0000
1.6260 1864.8334 1.0000
1.6320 1903.1666 1.0000
1.6380 1840.8334 1.0000
1.6440 1784.6666 1.0000
1.6500 1730.5000 1.0000
1.6560 1775.5000 1.0000
1.6620 1663.6666 1.0000
1.6680 1722.3334 1.0000
1.6740 1607.6666 1.0000
1.6800 1596.5000 1.0000
1.6860 1563.8334 1.0000
1.6920 1589.0000 1.0000
1.6980 1504.1666 1.0000
1.7040 1502.6666 1.0000
1.7100 1482.5000 1.0000
1.7160 1463.6666 1.0000
1.7220 1407.3334 1.0000
1.7280 1404.5000 1.0000
1.7340 1329.3334 1.0000
1.7400 1335.6666 1.0000
1.7460 1383.6666 1.0000
1.7520 1339.8334 1.0000
1.7580 1304.5000 1.0000
1.7640 1285.5000 1.0000
1.7700 1290.1666 1.0000
1.7760 1216.1666 1.0000
1.7820 1286.0000 1.0000
1.7880 1218.8334 1.0000
1.7940 1249.6666 1.0000
1.8000 1257.3334 1.0000
1.8060 1128.5000 1.0000
1.8120 1191.8334 1.0000
1.8180 1177.5000 1.0000
1.8240 1113.6666 1.0000
1.8300 1137.3334 1.0000
1.8360 1133.1666 1.0000
1.8420 1134.0000 1.0000
1.8480 1074.8334 1.0000
1.8540 1107.6666 1.0000
1.8600 1033.5000 1.0000
1.8660 1062.3334 1.0000
1.8720 1041.1666 1.0000
1.8780 989.0000 1.0000
1.8840 1011.0000 1.0000
1.8900 1022.0000 1.0000
1.8960 913.3333 1.0000
1.9020 913.1667 1.0000
1.9080 935.8333 1.0000
1.9140 974.1667 1.0000
1.9200 947.5000 1.0000
1.9260 940.8333 1.0000
1.9320 890.0000 1.0000
1.9380 899.1667 1.0000
1.9440 803.5000 1.0000
1.9500 843.3333 1.0000
1.9560 927.8333 1.0000
1.9620 883.8333 1.0000
1.9680 840.1667 1.0000
1.9740 837.5000 1.0000
1.9800 778.0000 1.0000
1.9860 795.6667 1.0000
1.9920 810.1667 1.0000
1.9980 812.3333 1.0000
2.0040 719.8333 1.0000
2.0100 766.6667 1.0000
2.0160 767.3333 1.0000
2.0220 731.8333 1.0000
2.0280 724.6667 1.0000
2.0340 696.1667 1.0000
2.0400 704.8333 1.0000
2.0460 714.0000 1.0000
2.0520 668.8333 1.0000
2.0580 673.3333 1.0000
2.0640 665.5000 1.0000
2.0700 690.8333 1.0000
2.0760 658.3333 1.0000
2.0820 644.0000 1.0000
2.0880 638.1667 1.0000
2.0940 684.8333 1.0000
2.1000 635.3333 1.0000
2.1060 605.6667 1.0000
2.1120 588.6667 1.0000
2.1180 574.0000 1.0000
2.1240 610.0000 1.0000
2.1300 575.6667 1.0000
2.1360 585.3333 1.0000
2.1420 595.1667 1.0000
2.1480 535.0000 1.0000
2.1540 542.6667 1.0000
2.1600 538.8333 1.0000
2.1660 528.0000 1.0000
2.1720 528.6667 1.0000
2.1780 541.8333 1.0000
2.1840 536.5000 1.0000
2.1900 524.8333 1.0000
2.1960 525.3333 1.0000
2.2020 490.6667 1.0000
2.2080 501.5000 1.0000
2.2140 544.0000 1.0000
2.2200 482.6667 1.0000
2.2260 532.8333 1.0000
2.2320 492.3333 1.0000
2.2380 502.6667 1.0000
2.2440 447.6667 1.0000
2.2500 487.3333 1.0000
2.2560 453.0000 1.0000
2.2620 416.6667 1.0000
2.2680 479.6667 1.0000
2.2740 444.8333 1.0000
2.2800 448.3333 1.0000
2.2860 422.8333 1.0000
2.2920 431.6667 1.0000
2.2980 438.3333 1.0000
2.3040 402.3333 1.0000
2.3100 365.8333 1.0000
2.3160 407.8333 1.0000
2.3220 435.0000 1.0000
2.3280 396.6667 1.0000
2.3340 384.8333 1.0000
2.3400 359.5000 1.0000
2.3460 366.1667 1.0000
2.3520 349.0000 1.0000
2.3580 387.8333 1.0000
2.3640 385.5000 1.0000
2.3700 394.6667 1.0000
2.3760 326.3333 1.0000
2.3820 353.1667 1.0000
2.3880 384.5000 1.0000
2.3940 318.8333 1.0000
2.4000 355.8333 1.0000
2.4060 331.1667 1.0000
2.4120 327.0000 1.0000
2.4180 325.3333 1.0000
2.4240 324.0000 1.0000
2.4300 325.8333 1.0000
2.4360 298.0000 1.0000
2.4420 347.0000 1.0000
2.4480 329.8333 1.0000
2.4540 334.0000 1.0000
2.4600 321.6667 1.0000
2.4660 291.8333 1.0000
2.4720 298.5000 1.0000
2.4780 298.5000 1.0000
2.4840 305.1667 1.0000
2.4900 280.5000 1.0000
2.4960 290.8333 1.0000
2.5020 262.6667 1.0000
2.5080 264.0000 1.0000
2.5140 276.1667 1.0000
2.5200 268.3333 1.0000
2.5260 277.1667 1.0000
2.5320 245.6667 1.0000
2.5380 273.5000 1.0000
2.5440 270.0000 1.0000
2.5500 263.0000 1.0000
2.5560 257.5000 1.0000
2.5620 260.1667 1.0000
2.5680 247.1667 1.0000
2.5740 269.3333 1.0000
2.5800 238.1667 1.0000
2.5860 229.8333 1.0000
2.5920 243.1667 1.0000
2.5980 226.6667 1.0000
2.6040 207.1667 1.0000
2.6100 248.5000 1.0000
2.6160 213.5000 1.0000
2.6220 226.5000 1.0000
2.6280 222.1667 1.0000
2.6340 219.5000 1.0000
2.6400 189.6667 1.0000
2.6460 230.5000 1.0000
2.6520 188.1667 1.0000
2.6580 245.5000 1.0000
2.6640 196.1667 1.0000
2.6700 201.5000 1.0000
2.6760 185.5000 1.0000
2.6820 194.8333 1.0000
2.6880 222.6667 1.0000
2.6940 197.1667 1.0000
2.7000 185.0000 1.0000
2.7060 202.5000 1.0000
2.7120 196.5000 1.0000
2.7180 181.0000 1.0000
2.7240 171.1667 1.0000
2.7300 202.8333 1.0000
2.7360 201.8333 1.0000
2.7420 188.3333 1.0000
2.7480 184.3333 1.0000
2.7540 171.6667 1.0000
2.7600 189.5000 1.0000
2.7660 147.6667 1.0000
2.7720 155.1667 1.0000
2.7780 177.5000 1.0000
2.7840 150.1667 1.0000
2.7900 185.3333 1.0000
2.7960 161.1667 1.0000
2.8020 166.8333 1.0000
2.8080 152.5000 1.0000
2.8140 171.1667 1.0000
2.8200 146.6667 1.0000
2.8260 132.5000 1.0000
2.8320 155.0000 1.0000
2.8380 154.0000 1.0000
2.8440 197.0000 1.0000
2.8500 156.8333 1.0000
2.8560 141.3333 1.0000
2.8620 171.5000 1.0000
2.8680 155.8333 1.0000
2.8740 138.5000 1.0000
2.8800 138.3333 1.0000
2.8860 138.8333 1.0000
2.8920 134.0000 1.0000
2.8980 146.5000 1.0000
2.9040 122.3333 1.0000
2.9100 146.3333 1.0000
2.9160 126.3333 1.0000
2.9220 129.5000 1.0000
2.9280 130.1667 1.0000
2.9340 118.0000 1.0000
2.9400 124.6667 1.0000
2.9460 128.1667 1.0000
2.9520 116.1667 1.0000
2.9580 126.3333 1.0000
2.9640 112.3333 1.0000
2.9700 118.3333 1.0000
2.9760 129.6667 1.0000
2.9820 125.1667 1.0000
2.9880 102.8333 1.0000
2.9940 106.1667 1.0000
3.0000 107.8333 1.0000
3.0060 109.8333 1.0000
3.0120 111.8333 1.0000
3.0180 96.8333 1.0000
3.0240 122.3333 1.0000
3.0300 101.5000 1.0000
3.0360 108.3333 1.0000
3.0420 112.5000 1.0000
3.0480 117.6667 1.0000
3.0540 113.8333 1.0000
3.0600 111.5000 1.0000
3.0660 104.6667 1.0000
3.0720 104.1667 1.0000
3.0780 101.6667 1.0000
3.0840 104.5000 1.0000
3.0900 90.6667 1.0000
3.0960 110.5000 1.0000
3.1020 106.6667 1.0000
3.1080 105.6667 1.0000
3.1140 97.0000 1.0000
3.1200 89.3333 1.0000
3.1260 87.1667 1.0000
3.1320 88.6667 1.0000
3.1380 88.0000 1.0000
3.1440 88.0000 1.0000
3.1500 90.5000 1.0000
3.1560 90.0000 1.0000
3.1620 75.5000 1.0000
3.1680 101.3333 1.0000
3.1740 87.3333 1.0000
3.1800 99.6667 1.0000
3.1860 93.6667 1.0000
3.1920 95.5000 1.0000
3.1980 92.3333 1.0000
3.2040 86.3333 1.0000
3.2100 79.8333 1.0000
3.2160 96.6667 1.0000
3.2220 91.5000 1.0000
3.2280 88.5000 1.0000
3.2340 73.8333 1.0000
3.2400 71.0000 1.0000
3.2460 79.8333 1.0000
3.2520 75.8333 1.0000
3.2580 81.0000 1.0000
3.2640 80.1667 1.0000
3.2700 90.1667 1.0000
3.2760 82.3333 1.0000
3.2820 71.3333 1.0000
3.2880 66.0000 1.0000
3.2940 80.1667 1.0000
3.3000 66.8333 1.0000
3.3060 64.6667 1.0000
3.3120 62.5000 1.0000
3.3180 82.6667 1.0000
3.3240 61.0000 1.0000
3.3300 59.3333 1.0000
3.3360 74.6667 1.0000
3.3420 75.3333 1.0000
3.3480 64.6667 1.0000
3.3540 80.5000 1.0000
3.3600 56.5000 1.0000
3.3660 65.5000 1.0000
3.3720 65.8333 1.0000
3.3780 76.1667 1.0000
3.3840 65.1667 1.0000
3.3900 61.6667 1.0000
3.3960 71.3333 1.0000
3.4020 70.5000 1.0000
3.4080 54.3333 1.0000
3.4140 62.0000 1.0000
3.4200 51.1667 1.0000
3.4260 70.6667 1.0000
3.4320 67.6667 1.0000
3.4380 66.6667 1.0000
3.4440 62.6667 1.0000
3.4500 45.5000 1.0000
3.4560 53.3333 1.0000
3.4620 65.6667 1.0000
3.4680 55.6667 1.0000
3.4740 50.3333 1.0000
3.4800 63.0000 1.0000
3.4860 63.3333 1.0000
3.4920 72.5000 1.0000
3.4980 62.5000 1.0000
3.5040 63.0000 1.0000
3.5100 51.5000 1.0000
3.5160 55.8333 1.0000
3.5220 52.8333 1.0000
3.5280 46.1667 1.0000
3.5340 46.8333 1.0000
3.5400 54.3333 1.0000
3.5460 72.6667 1.0000
3.5520 55.6667 1.0000
3.5580 47.3333 1.0000
3.5640 50.3333 1.0000
3.5700 51.6667 1.0000
3.5760 57.3333 1.0000
3.5820 52.0000 1.0000
3.5880 45.5000 1.0000
3.5940 43.6667 1.0000
3.6000 44.0000 1.0000
3.6060 52.8333 1.0000
3.6120 38.8333 1.0000
3.6180 39.0000 1.0000
3.6240 49.5000 1.0000
3.6300 56.3333 1.0000
3.6360 52.3333 1.0000
3.6420 51.0000 1.0000
3.6480 41.1667 1.0000
3.6540 53.3333 1.0000
3.6600 46.6667 1.0000
3.6660 44.0000 1.0000
3.6720 56.6667 1.0000
3.6780 33.0000 1.0000
3.6840 36.3333 1.0000
3.6900 52.5000 1.0000
3.6960 45.1667 1.0000
3.7020 43.3333 1.0000
3.7080 45.3333 1.0000
3.7140 41.8333 1.0000
3.7200 33.8333 1.0000
3.7260 38.1667 1.0000
3.7320 49.8333 1.0000
3.7380 42.0000 1.0000
3.7440 41.8333 1.0000
3.7500 51.6667 1.0000
3.7560 42.0000 1.0000
3.7620 29.6667 1.0000
3.7680 43.8333 1.0000
3.7740 44.6667 1.0000
3.7800 38.8333 1.0000
3.7860 35.8333 1.0000
3.7920 42.3333 1.0000
3.7980 46.1667 1.0000
3.8040 34.0000 1.0000
3.8100 41.5000 1.0000
3.8160 29.5000 1.0000
3.8220 33.8333 1.0000
3.8280 32.6667 1.0000
3.8340 39.0000 1.0000
3.8400 34.0000 1.0000
3.8460 40.3333 1.0000
3.8520 36.8333 1.0000
3.8580 42.6667 1.0000
3.8640 40.8333 1.0000
3.8700 48.3333 1.0000
3.8760 41.8333 1.0000
3.8820 30.6667 1.0000
3.8880 41.5000 1.0000
3.8940 36.6667 1.0000
3.9000 19.1667 1.0000
3.9060 37.3333 1.0000
3.9120 39.3333 1.0000
3.9180 38.5000 1.0000
3.9240 30.6667 1.0000
3.9300 29.8333 1.0000
3.9360 33.1667 1.0000
3.9420 27.0000 1.0000
3.9480 40.5000 1.0000
3.9540 34.3333 1.0000
3.9600 16.5000 1.0000
3.9660 43.3333 1.0000
3.9720 39.8333 1.0000
3.9780 41.3333 1.0000
3.9840 33.8333 1.0000
3.9900 37.1667 1.0000
3.9960 21.5000 1.0000
4.0020 28.3333 1.0000
4.0080 23.0000 1.0000
4.0140 22.8333 1.0000
4.0200 39.5000 1.0000
4.0260 34.6667 1.0000
4.0320 35.3333 1.0000
4.0380 29.1667 1.0000
4.0440 22.5000 1.0000
4.0500 35.3333 1.0000
4.0560 36.0000 1.0000
4.0620 29.3333 1.0000
4.0680 24.1667 1.0000
4.0740 16.6667 1.0000
4.0800 29.3333 1.0000
4.0860 30.3333 1.0000
4.0920 28.3333 1.0000
4.0980 29.6667 1.0000
4.1040 25.1667 1.0000
4.1100 25.1667 1.0000
4.1160 35.1667 1.0000
4.1220 29.6667 1.0000
4.1280 18.3333 1.0000
4.1340 29.6667 1.0000
4.1400 36.6667 1.0000
4.1460 28.5000 1.0000
4.1520 30.1667 1.0000
4.1580 21.1667 1.0000
4.1640 34.6667 1.0000
4.1700 18.5000 1.0000
4.1760 37.5000 1.0000
4.1820 23.0000 1.0000
4.1880 29.5000 1.0000
4.1940 18.6667 1.0000
4.2000 30.1667 1.0000
4.2060 29.1667 1.0000
4.2120 27.0000 1.0000
4.2180 21.6667 1.0000
4.2240 30.6667 1.0000
4.2300 27.0000 1.0000
4.2360 32.0000 1.0000
4.2420 23.5000 1.0000
4.2480 24.8333 1.0000
4.2540 19.5000 1.0000
4.2600 18.3333 1.0000
4.2660 18.0000 1.0000
4.2720 26.3333 1.0000
4.2780 29.0000 1.0000
4.2840 25.1667 1.0000
4.2900 19.8333 1.0000
4.2960 20.1667 1.0000
4.3020 25.5000 1.0000
4.3080 13.3333 1.0000
4.3140 23.1667 1.0000
4.3200 16.8333 1.0000
4.3260 17.1667 1.0000
4.3320 24.5000 1.0000
4.3380 22.0000 1.0000
4.3440 18.8333 1.0000
4.3500 19.0000 1.0000
4.3560 21.0000 1.0000
4.3620 27.1667 1.0000
4.3680 27.1667 1.0000
4.3740 13.3333 1.0000
4.3800 20.6667 1.0000
4.3860 29.5000 1.0000
4.3920 24.5000 1.0000
4.3980 33.1667 1.0000
4.4040 19.3333 1.0000
4.4100 26.0000 1.0000
4.4160 23.6667 1.0000
4.4220 17.0000 1.0000
4.4280 14.3333 1.0000
4.4340 24.8333 1.0000
4.4400 22.3333 1.0000
4.4460 26.8333 1.0000
4.4520 16.5000 1.0000
4.4580 17.0000 1.0000
4.4640 13.5000 1.0000
4.4700 21.1667 1.0000
4.4760 18.1667 1.0000
4.4820 23.8333 1.0000
4.4880 22.1667 1.0000
4.4940 19.0000 1.0000
4.5000 20.8333 1.0000
4.5060 23.5000 1.0000
4.5120 26.0000 1.0000
4.5180 24.3333 1.0000
4.5240 23.8333 1.0000
4.5300 14.3333 1.0000
4.5360 21.3333 1.0000
4.5420 29.3333 1.0000
4.5480 16.8333 1.0000
4.5540 18.5000 1.0000
4.5600 24.0000 1.0000
4.5660 23.5000 1.0000
4.5720 23.1667 1.0000
4.5780 17.5000 1.0000
4.5840 17.5000 1.0000
4.5900 27.5000 1.0000
4.5960 21.8333 1.0000
4.6020 23.0000 1.0000
4.6080 13.6667 1.0000
4.6140 19.3333 1.0000
4.6200 10.3333 1.0000
4.6260 19.8333 1.0000
4.6320 23.0000 1.0000
4.6380 20.5000 1.0000
4.6440 30.0000 1.0000
4.6500 14.0000 1.0000
4.6560 10.8333 1.0000
4.6620 17.0000 1.0000
4.6680 16.0000 1.0000
4.6740 7.5000 1.0000
4.6800 11.1667 1.0000
4.6860 16.0000 1.0000
4.6920 22.0000 1.0000
4.6980 17.5000 1.0000
4.7040 12.5000 1.0000
4.7100 17.0000 1.0000
4.7160 18.3333 1.0000
4.7220 21.1667 1.0000
4.7280 14.5000 1.0000
4.7340 24.1667 1.0000
4.7400 16.5000 1.0000
4.7460 11.0000 1.0000
4.7520 14.8333 1.0000
4.7580 24.8333 1.0000
4.7640 16.5000 1.0000
4.7700 15.1667 1.0000
4.7760 12.5000 1.0000
4.7820 19.8333 1.0000
4.7880 16.6667 1.0000
4.7940 20.8333 1.0000
4.8000 21.0000 1.0000
4.8060 12.1667 1.0000
4.8120 15.1667 1.0000
4.8180 13.3333 1.0000
4.8240 16.1667 1.0000
4.8300 18.8333 1.0000
4.8360 20.3333 1.0000
4.8420 17.0000 1.0000
4.8480 15.5000 1.0000
4.8540 19.1667 1.0000
4.8600 12.6667 1.0000
4.8660 16.8333 1.0000
4.8720 16.5000 1.0000
4.8780 14.6667 1.0000
4.8840 14.3333 1.0000
4.8900 26.1667 1.0000
4.8960 20.1667 1.0000
4.9020 21.5000 1.0000
4.9080 24.8333 1.0000
4.9140 22.5000 1.0000
4.9200 19.5000 1.0000
4.9260 12.1667 1.0000
4.9320 13.6667 1.0000
4.9380 15.1667 1.0000
4.9440 9.0000 1.0000
4.9500 11.3333 1.0000
4.9560 22.1667 1.0000
4.9620 12.3333 1.0000
4.9680 18.1667 1.0000
4.9740 13.0000 1.0000
4.9800 14.8333 1.0000
4.9860 11.8333 1.0000
4.9920 9.6667 1.0000
4.9980 13.6667 1.0000
5.0040 17.6667 1.0000
5.0100 14.6667 1.0000
5.0160 18.6667 1.0000
5.0220 14.8333 1.0000
5.0280 12.0000 1.0000
5.0340 22.0000 1.0000
5.0400 12.8333 1.0000
5.0460 7.8333 1.0000
5.0520 14.6667 1.0000
5.0580 9.0000 1.0000
5.0640 11.3333 1.0000
5.0700 11.5000 1.0000
5.0760 18.0000 1.0000
5.0820 14.8333 1.0000
5.0880 4.6667 1.0000
5.0940 13.6667 1.0000
5.1000 13.6667 1.0000
5.1060 14.5000 1.0000
5.1120 8.1667 1.0000
5.1180 15.6667 1.0000
5.1240 12.0000 1.0000
5.1300 9.3333 1.0000
5.1360 17.6667 1.0000
5.1420 20.3333 1.0000
5.1480 15.1667 1.0000
5.1540 18.5000 1.0000
5.1600 13.0000 1.0000
5.1660 9.3333 1.0000
5.1720 14.8333 1.0000
5.1780 15.0000 1.0000
5.1840 14.3333 1.0000
5.1900 16.0000 1.0000
5.1960 13.6667 1.0000
5.2020 9.8333 1.0000
5.2080 6.3333 1.0000
5.2140 6.6667 1.0000
5.2200 11.8333 1.0000
5.2260 12.8333 1.0000
5.2320 17.8333 1.0000
5.2380 10.3333 1.0000
5.2440 5.0000 1.0000
5.2500 9.6667 1.0000
5.2560 17.1667 1.0000
5.2620 18.0000 1.0000
5.2680 15.3333 1.0000
5.2740 14.3333 1.0000
5.2800 15.3333 1.0000
5.2860 12.6667 1.0000
5.2920 11.1667 1.0000
5.2980 13.8333 1.0000
5.3040 13.8333 1.0000
5.3100 9.8333 1.0000
5.3160 13.8333 1.0000
5.3220 11.3333 1.0000
5.3280 11.0000 1.0000
5.3340 15.5000 1.0000
5.3400 7.5000 1.0000
5.3460 14.0000 1.0000
5.3520 24.0000 1.0000
5.3580 8.1667 1.0000
5.3640 9.8333 1.0000
5.3700 7.5000 1.0000
5.3760 10.0000 1.0000
5.3820 9.3333 1.0000
5.3880 11.1667 1.0000
5.3940 9.3333 1.0000
5.4000 12.8333 1.0000
5.4060 9.0000 1.0000
5.4120 12.0000 1.0000
5.4180 6.8333 1.0000
5.4240 11.6667 1.0000
5.4300 16.1667 1.0000
5.4360 9.5000 1.0000
5.4420 13.6667 1.0000
5.4480 12.5000 1.0000
5.4540 12.6667 1.0000
5.4600 7.6667 1.0000
5.4660 11.8333 1.0000
5.4720 14.8333 1.0000
5.4780 17.8333 1.0000
5.4840 18.5000 1.0000
5.4900 9.0000 1.0000
5.4960 11.0000 1.0000
5.5020 14.8333 1.0000
5.5080 12.3333 1.0000
5.5140 12.5000 1.0000
5.5200 7.6667 1.0000
5.5260 9.8333 1.0000
5.5320 12.1667 1.0000
5.5380 10.0000 1.0000
5.5440 14.6667 1.0000
5.5500 10.6667 1.0000
5.5560 6.8333 1.0000
5.5620 8.6667 1.0000
5.5680 18.1667 1.0000
5.5740 12.5000 1.0000
5.5800 8.8333 1.0000
5.5860 2.3333 1.0000
5.5920 6.0000 1.0000
5.5980 10.1667 1.0000
5.6040 11.3333 1.0000
5.6100 5.0000 1.0000
5.6160 6.6667 1.0000
5.6220 14.8333 1.0000
5.6280 10.0000 1.0000
5.6340 18.6667 1.0000
5.6400 11.8333 1.0000
5.6460 11.5000 1.0000
5.6520 7.1667 1.0000
5.6580 12.0000 1.0000
5.6640 12.6667 1.0000
5.6700 6.5000 1.0000
5.6760 12.6667 1.0000
5.6820 6.6667 1.0000
5.6880 11.1667 1.0000
5.6940 11.1667 1.0000
5.7000 8.0000 1.0000
5.7060 10.0000 1.0000
5.7120 12.6667 1.0000
5.7180 7.3333 1.0000
5.7240 9.3333 1.0000
5.7300 9.8333 1.0000
5.7360 10.6667 1.0000
5.7420 13.0000 1.0000
5.7480 7.6667 1.0000
5.7540 8.8333 1.0000
5.7600 11.8333 1.0000
5.7660 6.8333 1.0000
5.7720 9.3333 1.0000
5.7780 7.3333 1.0000
5.7840 3.8333 1.0000
5.7900 13.8333 1.0000
5.7960 13.8333 1.0000
5.8020 6.6667 1.0000
5.8080 6.6667 1.0000
5.8140 8.8333 1.0000
5.8200 11.5000 1.0000
5.8260 8.6667 1.0000
5.8320 9.0000 1.0000
5.8380 13.3333 1.0000
5.8440 9.5000 1.0000
5.8500 10.1667 1.0000
5.8560 11.6667 1.0000
5.8620 9.0000 1.0000
5.8680 12.3333 1.0000
5.8740 7.6667 1.0000
5.8800 11.3333 1.0000
5.8860 9.0000 1.0000
5.8920 9.6667 1.0000
5.8980 10.3333 1.0000
5.9040 8.0000 1.0000
5.9100 12.1667 1.0000
5.9160 7.8333 1.0000
5.9220 6.5000 1.0000
5.9280 11.1667 1.0000
5.9340 9.1667 1.0000
5.9400 10.1667 1.0000
5.9460 8.0000 1.0000
5.9520 14.3333 1.0000
5.9580 13.1667 1.0000
5.9640 5.5000 1.0000
5.9700 5.6667 1.0000
5.9760 15.0000 1.0000
5.9820 6.6667 1.0000
5.9880 6.6667 1.0000
5.9940 5.8333 1.0000
6.0000 5.3333 1.0000
*RAS_INT_END
*RAS_DATA_END