File: xrr_temp/CWO016_reflectivity.ras
*RAS_DATA_START
*RAS_HEADER_START
*DISP_FMT_X "%.4f"
*DISP_FMT_Y "%.0f"
*DISP_FULLSCALE "26908094.4499999990"
*DISP_LINE_COLOR "255.0000000000"
*DISP_LINE_STYLE "0.0000000000"
*DISP_LINE_WIDTH "0.2500000000"
*DISP_NOTE "Collected Data-49"
*DISP_OFFSET_Y "0.0000000000"
*DISP_PEAKSEARCH_UNIT_Y "cps"
*DISP_RANGE_BOTTOM "0.0100000000"
*DISP_RANGE_LEFT "-0.0006000000"
*DISP_RANGE_LOGCUTOFF "0.0100000000"
*DISP_RANGE_RIGHT "6.0006000000"
*DISP_RANGE_TOP "26908094.4499999990"
*DISP_SCALE_MODE_Y "2.0000000000"
*DISP_TAB_NAME "2-Theta/Omega"
*DISP_TITLE_Y "Intensity"
*DISP_UNIT_Y "cps"
*DISP_WINDOW_NAME "MSG_MACROENGINE"
*FILE_COMMENT " "
*FILE_MD5 ""
*FILE_MEMO " "
*FILE_OPERATOR "administrator"
*FILE_PART_ID "MEAS_KHP2_00055"
*FILE_SAMPLE "CWO 016"
*FILE_TYPE "RAS_RAW"
*FILE_USERGROUP "System Manager"
*FILE_VERSION "1.0000000000"
*HW_ATTACHMENT_ID "ATT0025"
*HW_ATTACHMENT_NAME "標準|Standard"
*HW_COUNTER_ID-0 "CUT0025"
*HW_COUNTER_ID-1 "CUT0020"
*HW_COUNTER_ID-2 "CUT0020"
*HW_COUNTER_ID-3 "CSL0021"
*HW_COUNTER_ID-4 "CMC0021"
*HW_COUNTER_NAME-0 "D/teX Ultra|D/teX Ultra"
*HW_COUNTER_NAME-1 "None|None"
*HW_COUNTER_NAME-2 "None|None"
*HW_COUNTER_NAME-3 "BBM|BBM"
*HW_COUNTER_NAME-4 "検出器モノクロメータ|Detector monochromator"
*HW_COUNTER_SELECT_NAME "D/teX Ultra|D/teX Ultra"
*HW_GONIOMETER_ID "GON0023"
*HW_GONIOMETER_NAME "SmartLab|SmartLab"
*HW_GONIOMETER_RADIUS-0 "90.0"
*HW_GONIOMETER_RADIUS-1 "114.0"
*HW_GONIOMETER_RADIUS-2 "190.0"
*HW_GONIOMETER_RADIUS-3 "300.0"
*HW_GONIOMETER_RADIUS-4 "187.0"
*HW_GONIOMETER_RADIUS-5 "300.0"
*HW_GONIOMETER_RADIUS-6 "113.0"
*HW_GONIOMETER_RADIUS-7 "331.0"
*HW_I_OPT_ID-0 "CBO0021"
*HW_I_OPT_ID-1 "ICR0021"
*HW_I_OPT_ID-2 "ISL0021"
*HW_I_OPT_ID-3 "ISO0021"
*HW_I_OPT_ID-4 "IAD0021"
*HW_I_OPT_ID-5 "IPR0001"
*HW_I_OPT_NAME-0 "CBOユニット|CBO unit"
*HW_I_OPT_NAME-1 "標準入射光学ユニット|Standard incident optical unit"
*HW_I_OPT_NAME-2 "標準入射スリットボックス|Standard incident slit box"
*HW_I_OPT_NAME-3 "入射平行スリット|Incident parallel slit"
*HW_I_OPT_NAME-4 "長手制限スリット|Length limiting slit"
*HW_I_OPT_NAME-5 "None|None"
*HW_R_ATTENUATER_AUTOMODE "1"
*HW_R_OPT_ID-0 "RSS0021"
*HW_R_OPT_ID-1 "RCR0023"
*HW_R_OPT_ID-2 "RSO0021"
*HW_R_OPT_ID-3 "RRS0021"
*HW_R_OPT_ID-4 "ATN0021"
*HW_R_OPT_ID-5 "RFL0021"
*HW_R_OPT_ID-6 "RAD0021"
*HW_R_OPT_NAME-0 "標準受光スリットボックス1|Standard receiving slit box # 1"
*HW_R_OPT_NAME-1 "標準受光光学ユニット1|Standard receiving unit # 1"
*HW_R_OPT_NAME-2 "標準受光光学ユニット2|Standard receiving optical unit # 2"
*HW_R_OPT_NAME-3 "標準受光スリットボックス2|Standard receiving slit box # 2"
*HW_R_OPT_NAME-4 "標準アッテネータ|Standard Attenuator"
*HW_R_OPT_NAME-5 "Cu Kβ|Cu K-beta"
*HW_R_OPT_NAME-6 "調整用受光スリット|Alignment receiving slit"
*HW_SAMPLE_HOLDER_ID "SMP0021"
*HW_SAMPLE_HOLDER_NAME "χφZクレードル|Chi phi Z cradle"
*HW_XG_CURRENT_MAX "200"
*HW_XG_CURRENT_MIN "10"
*HW_XG_CURRENT_RESOLUTION "1"
*HW_XG_CURRENT_UNIT "mA"
*HW_XG_FOCUS "0.4mm x 8mm"
*HW_XG_FOCUS_TYPE "Normal"
*HW_XG_ID "1700"
*HW_XG_NAME "9kW 開放管(45kV 200mA ID:1700)|9kW Rotating anode(45kV 200mA ID:1700)"
*HW_XG_TARGET_ATOMIC_NUMBER "29.0000000000"
*HW_XG_TARGET_NAME "Cu"
*HW_XG_TYPE "Rota"
*HW_XG_VOLTAGE_MAX "45"
*HW_XG_VOLTAGE_MIN "20"
*HW_XG_VOLTAGE_RESOLUTION "1"
*HW_XG_VOLTAGE_UNIT "kV"
*HW_XG_WATT_MAX "9.00"
*HW_XG_WATT_UNIT "kW"
*HW_XG_WAVE_LENGTH_ALPHA1 "1.540593"
*HW_XG_WAVE_LENGTH_ALPHA2 "1.544414"
*HW_XG_WAVE_LENGTH_BETA "1.392250"
*MEAS_COND_AXIS_NAME-0 "Theta/2-Theta"
*MEAS_COND_AXIS_NAME-1 "2-Theta"
*MEAS_COND_AXIS_NAME-2 "Omega"
*MEAS_COND_AXIS_NAME-3 "Chi"
*MEAS_COND_AXIS_NAME-4 "Phi"
*MEAS_COND_AXIS_NAME-5 "Z"
*MEAS_COND_AXIS_NAME-6 "2-Theta/Omega"
*MEAS_COND_AXIS_NAME-7 "Theta_s"
*MEAS_COND_AXIS_NAME-8 "Theta_d"
*MEAS_COND_AXIS_NAME-9 "Ts"
*MEAS_COND_AXIS_NAME-10 "CBO selection slit"
*MEAS_COND_AXIS_NAME-11 "M"
*MEAS_COND_AXIS_NAME-12 "Incident parallel slit"
*MEAS_COND_AXIS_NAME-13 "Incident slit"
*MEAS_COND_AXIS_NAME-14 ""
*MEAS_COND_AXIS_NAME-15 "Zs"
*MEAS_COND_AXIS_NAME-16 "Incident optical device"
*MEAS_COND_AXIS_NAME-17 "Omega_m"
*MEAS_COND_AXIS_NAME-18 "Length limiting slit"
*MEAS_COND_AXIS_NAME-19 "Center slit"
*MEAS_COND_AXIS_NAME-20 "Filter"
*MEAS_COND_AXIS_NAME-21 "Receiving slit # 1"
*MEAS_COND_AXIS_NAME-22 "Receiving slit # 2"
*MEAS_COND_AXIS_NAME-23 "Receiving optical device"
*MEAS_COND_AXIS_NAME-24 "Receiving parallel slit"
*MEAS_COND_AXIS_NAME-25 "Alignment receiving slit"
*MEAS_COND_AXIS_NAME-26 ""
*MEAS_COND_AXIS_NAME-27 ""
*MEAS_COND_AXIS_NAME-28 "Zd"
*MEAS_COND_AXIS_NAME-29 "Attenuator"
*MEAS_COND_AXIS_NAME-30 "Diffracted beam monochromator"
*MEAS_COND_AXIS_NAME-31 "Monochromator slit"
*MEAS_COND_AXIS_NAME-32 "Primary beam"
*MEAS_COND_AXIS_NAME-33 ""
*MEAS_COND_AXIS_NAME-34 ""
*MEAS_COND_AXIS_NAME-35 "PHA"
*MEAS_COND_AXIS_NAME_INTERNAL-0 "TwoThetaTheta"
*MEAS_COND_AXIS_NAME_INTERNAL-1 "TwoTheta"
*MEAS_COND_AXIS_NAME_INTERNAL-2 "Omega"
*MEAS_COND_AXIS_NAME_INTERNAL-3 "Chi"
*MEAS_COND_AXIS_NAME_INTERNAL-4 "Phi"
*MEAS_COND_AXIS_NAME_INTERNAL-5 "Z"
*MEAS_COND_AXIS_NAME_INTERNAL-6 "TwoThetaOmega"
*MEAS_COND_AXIS_NAME_INTERNAL-7 "ThetaS"
*MEAS_COND_AXIS_NAME_INTERNAL-8 "ThetaD"
*MEAS_COND_AXIS_NAME_INTERNAL-9 "Ts"
*MEAS_COND_AXIS_NAME_INTERNAL-10 "CBO"
*MEAS_COND_AXIS_NAME_INTERNAL-11 "CBO-M"
*MEAS_COND_AXIS_NAME_INTERNAL-12 "IncidentSollerSlit"
*MEAS_COND_AXIS_NAME_INTERNAL-13 "IncidentSlitBox"
*MEAS_COND_AXIS_NAME_INTERNAL-14 "IncidentSlitBox-_Axis"
*MEAS_COND_AXIS_NAME_INTERNAL-15 "Zs"
*MEAS_COND_AXIS_NAME_INTERNAL-16 "IncidentMonochromator"
*MEAS_COND_AXIS_NAME_INTERNAL-17 "IncidentMonochromator-OmegaM"
*MEAS_COND_AXIS_NAME_INTERNAL-18 "IncidentAxdSlit"
*MEAS_COND_AXIS_NAME_INTERNAL-19 "CenterSlit"
*MEAS_COND_AXIS_NAME_INTERNAL-20 "Filter"
*MEAS_COND_AXIS_NAME_INTERNAL-21 "ReceivingSlitBox1"
*MEAS_COND_AXIS_NAME_INTERNAL-22 "ReceivingSlitBox2"
*MEAS_COND_AXIS_NAME_INTERNAL-23 "ReceivingOptics"
*MEAS_COND_AXIS_NAME_INTERNAL-24 "ReceivingSollerSlit"
*MEAS_COND_AXIS_NAME_INTERNAL-25 "ReceivingAxdSlit"
*MEAS_COND_AXIS_NAME_INTERNAL-26 "ReceivingSlitBox1-_Axis"
*MEAS_COND_AXIS_NAME_INTERNAL-27 "ReceivingSlitBox2-_Axis"
*MEAS_COND_AXIS_NAME_INTERNAL-28 "ReceivingSlitBox2-Zd"
*MEAS_COND_AXIS_NAME_INTERNAL-29 "Attenuator"
*MEAS_COND_AXIS_NAME_INTERNAL-30 "CounterMonochromator"
*MEAS_COND_AXIS_NAME_INTERNAL-31 "CounterSlit"
*MEAS_COND_AXIS_NAME_INTERNAL-32 "IncidentPrimary"
*MEAS_COND_AXIS_NAME_INTERNAL-33 "AlphaR"
*MEAS_COND_AXIS_NAME_INTERNAL-34 "BetaR"
*MEAS_COND_AXIS_NAME_INTERNAL-35 "PHA"
*MEAS_COND_AXIS_NAME_MAGICNO-0 "83951616.0000000000"
*MEAS_COND_AXIS_NAME_MAGICNO-1 "268632064.0000000000"
*MEAS_COND_AXIS_NAME_MAGICNO-2 "268500992.0000000000"
*MEAS_COND_AXIS_NAME_MAGICNO-3 "268500992.0000000000"
*MEAS_COND_AXIS_NAME_MAGICNO-4 "268500992.0000000000"
*MEAS_COND_AXIS_NAME_MAGICNO-5 "285278208.0000000000"
*MEAS_COND_AXIS_NAME_MAGICNO-6 "83951616.0000000000"
*MEAS_COND_AXIS_NAME_MAGICNO-7 "131072.0000000000"
*MEAS_COND_AXIS_NAME_MAGICNO-8 "131072.0000000000"
*MEAS_COND_AXIS_NAME_MAGICNO-9 "318898176.0000000000"
*MEAS_COND_AXIS_NAME_MAGICNO-10 "20971521.0000000000"
*MEAS_COND_AXIS_NAME_MAGICNO-11 "285343744.0000000000"
*MEAS_COND_AXIS_NAME_MAGICNO-12 "20971521.0000000000"
*MEAS_COND_AXIS_NAME_MAGICNO-13 "22020097.0000000000"
*MEAS_COND_AXIS_NAME_MAGICNO-14 "25165824.0000000000"
*MEAS_COND_AXIS_NAME_MAGICNO-15 "318898176.0000000000"
*MEAS_COND_AXIS_NAME_MAGICNO-16 "20971521.0000000000"
*MEAS_COND_AXIS_NAME_MAGICNO-17 "285343744.0000000000"
*MEAS_COND_AXIS_NAME_MAGICNO-18 "20971521.0000000000"
*MEAS_COND_AXIS_NAME_MAGICNO-19 "20971521.0000000000"
*MEAS_COND_AXIS_NAME_MAGICNO-20 "20971521.0000000000"
*MEAS_COND_AXIS_NAME_MAGICNO-21 "23068673.0000000000"
*MEAS_COND_AXIS_NAME_MAGICNO-22 "23068673.0000000000"
*MEAS_COND_AXIS_NAME_MAGICNO-23 "20971521.0000000000"
*MEAS_COND_AXIS_NAME_MAGICNO-24 "20971521.0000000000"
*MEAS_COND_AXIS_NAME_MAGICNO-25 "20971521.0000000000"
*MEAS_COND_AXIS_NAME_MAGICNO-26 "25165824.0000000000"
*MEAS_COND_AXIS_NAME_MAGICNO-27 "25165824.0000000000"
*MEAS_COND_AXIS_NAME_MAGICNO-28 "285343744.0000000000"
*MEAS_COND_AXIS_NAME_MAGICNO-29 "17301505.0000000000"
*MEAS_COND_AXIS_NAME_MAGICNO-30 "20971521.0000000000"
*MEAS_COND_AXIS_NAME_MAGICNO-31 "20971521.0000000000"
*MEAS_COND_AXIS_NAME_MAGICNO-32 "20971521.0000000000"
*MEAS_COND_AXIS_NAME_MAGICNO-33 "8388608.0000000000"
*MEAS_COND_AXIS_NAME_MAGICNO-34 "8388608.0000000000"
*MEAS_COND_AXIS_NAME_MAGICNO-35 "0.0000000000"
*MEAS_COND_AXIS_OFFSET-0 "-"
*MEAS_COND_AXIS_OFFSET-1 "0.8920000000"
*MEAS_COND_AXIS_OFFSET-2 "1.7652000000"
*MEAS_COND_AXIS_OFFSET-3 "0.0000000000"
*MEAS_COND_AXIS_OFFSET-4 "0.0000000000"
*MEAS_COND_AXIS_OFFSET-5 "-"
*MEAS_COND_AXIS_OFFSET-6 "-"
*MEAS_COND_AXIS_OFFSET-7 "1.7652000000"
*MEAS_COND_AXIS_OFFSET-8 "-0.8732000000"
*MEAS_COND_AXIS_OFFSET-9 "-"
*MEAS_COND_AXIS_OFFSET-10 "-"
*MEAS_COND_AXIS_OFFSET-11 "-"
*MEAS_COND_AXIS_OFFSET-12 "-"
*MEAS_COND_AXIS_OFFSET-13 "-"
*MEAS_COND_AXIS_OFFSET-14 "-"
*MEAS_COND_AXIS_OFFSET-15 "-"
*MEAS_COND_AXIS_OFFSET-16 "-"
*MEAS_COND_AXIS_OFFSET-17 "-"
*MEAS_COND_AXIS_OFFSET-18 "-"
*MEAS_COND_AXIS_OFFSET-19 "-"
*MEAS_COND_AXIS_OFFSET-20 "-"
*MEAS_COND_AXIS_OFFSET-21 "-"
*MEAS_COND_AXIS_OFFSET-22 "-"
*MEAS_COND_AXIS_OFFSET-23 "-"
*MEAS_COND_AXIS_OFFSET-24 "-"
*MEAS_COND_AXIS_OFFSET-25 "-"
*MEAS_COND_AXIS_OFFSET-26 "-"
*MEAS_COND_AXIS_OFFSET-27 "-"
*MEAS_COND_AXIS_OFFSET-28 "-"
*MEAS_COND_AXIS_OFFSET-29 "-"
*MEAS_COND_AXIS_OFFSET-30 "-"
*MEAS_COND_AXIS_OFFSET-31 "-"
*MEAS_COND_AXIS_OFFSET-32 "-"
*MEAS_COND_AXIS_OFFSET-33 "0.0000000000"
*MEAS_COND_AXIS_OFFSET-34 "0.0000000000"
*MEAS_COND_AXIS_OFFSET-35 "-"
*MEAS_COND_AXIS_POSITION-0 "-0.0008000000"
*MEAS_COND_AXIS_POSITION-1 "-0.0008000000"
*MEAS_COND_AXIS_POSITION-2 "-0.0004000000"
*MEAS_COND_AXIS_POSITION-3 "0.0000000000"
*MEAS_COND_AXIS_POSITION-4 "0.0000000000"
*MEAS_COND_AXIS_POSITION-5 "-2.0226000000"
*MEAS_COND_AXIS_POSITION-6 "-0.0008000000"
*MEAS_COND_AXIS_POSITION-7 "-0.0004000000"
*MEAS_COND_AXIS_POSITION-8 "-0.0004000000"
*MEAS_COND_AXIS_POSITION-9 "-4.7599400000"
*MEAS_COND_AXIS_POSITION-10 "PB"
*MEAS_COND_AXIS_POSITION-11 "0.0000000000"
*MEAS_COND_AXIS_POSITION-12 "Soller_slit_open_s"
*MEAS_COND_AXIS_POSITION-13 "0.250mm"
*MEAS_COND_AXIS_POSITION-14 "0.2500000000"
*MEAS_COND_AXIS_POSITION-15 "-0.8975000000"
*MEAS_COND_AXIS_POSITION-16 "Ge(220)x2"
*MEAS_COND_AXIS_POSITION-17 "0.0000000000"
*MEAS_COND_AXIS_POSITION-18 "2.0mm"
*MEAS_COND_AXIS_POSITION-19 "None"
*MEAS_COND_AXIS_POSITION-20 "None"
*MEAS_COND_AXIS_POSITION-21 "0.250mm"
*MEAS_COND_AXIS_POSITION-22 "0.250mm"
*MEAS_COND_AXIS_POSITION-23 "No_unit"
*MEAS_COND_AXIS_POSITION-24 "Soller_slit_5.0deg"
*MEAS_COND_AXIS_POSITION-25 "None"
*MEAS_COND_AXIS_POSITION-26 "0.2500000000"
*MEAS_COND_AXIS_POSITION-27 "0.2500000000"
*MEAS_COND_AXIS_POSITION-28 "0.0915600000"
*MEAS_COND_AXIS_POSITION-29 "1/10000"
*MEAS_COND_AXIS_POSITION-30 "None"
*MEAS_COND_AXIS_POSITION-31 "None"
*MEAS_COND_AXIS_POSITION-32 "None"
*MEAS_COND_AXIS_POSITION-33 "0.0000000000"
*MEAS_COND_AXIS_POSITION-34 "43.1000000000"
*MEAS_COND_AXIS_POSITION-35 "34.0000000000"
*MEAS_COND_AXIS_UNIT-0 "deg"
*MEAS_COND_AXIS_UNIT-1 "deg"
*MEAS_COND_AXIS_UNIT-2 "deg"
*MEAS_COND_AXIS_UNIT-3 "deg"
*MEAS_COND_AXIS_UNIT-4 "deg"
*MEAS_COND_AXIS_UNIT-5 "mm"
*MEAS_COND_AXIS_UNIT-6 "deg"
*MEAS_COND_AXIS_UNIT-7 "deg"
*MEAS_COND_AXIS_UNIT-8 "deg"
*MEAS_COND_AXIS_UNIT-9 "mm"
*MEAS_COND_AXIS_UNIT-10 ""
*MEAS_COND_AXIS_UNIT-11 "pulse"
*MEAS_COND_AXIS_UNIT-12 ""
*MEAS_COND_AXIS_UNIT-13 ""
*MEAS_COND_AXIS_UNIT-14 "mm"
*MEAS_COND_AXIS_UNIT-15 "mm"
*MEAS_COND_AXIS_UNIT-16 ""
*MEAS_COND_AXIS_UNIT-17 "pulse"
*MEAS_COND_AXIS_UNIT-18 ""
*MEAS_COND_AXIS_UNIT-19 ""
*MEAS_COND_AXIS_UNIT-20 ""
*MEAS_COND_AXIS_UNIT-21 ""
*MEAS_COND_AXIS_UNIT-22 ""
*MEAS_COND_AXIS_UNIT-23 ""
*MEAS_COND_AXIS_UNIT-24 ""
*MEAS_COND_AXIS_UNIT-25 ""
*MEAS_COND_AXIS_UNIT-26 "mm"
*MEAS_COND_AXIS_UNIT-27 "mm"
*MEAS_COND_AXIS_UNIT-28 "mm"
*MEAS_COND_AXIS_UNIT-29 ""
*MEAS_COND_AXIS_UNIT-30 ""
*MEAS_COND_AXIS_UNIT-31 ""
*MEAS_COND_AXIS_UNIT-32 ""
*MEAS_COND_AXIS_UNIT-33 "deg"
*MEAS_COND_AXIS_UNIT-34 "deg"
*MEAS_COND_AXIS_UNIT-35 "div"
*MEAS_COND_COUNTER_CNTLOSS_CORR "0.0000000000"
*MEAS_COND_COUNTER_PHABASE "34.0000000000"
*MEAS_COND_COUNTER_PHAWINDOW "19.0000000000"
*MEAS_COND_COUNTER_PHA_UNIT "div"
*MEAS_COND_COUNTER_TAUDIFF "2.0000000000"
*MEAS_COND_COUNTER_TAUINT "0.1000000000"
*MEAS_COND_IRRADIATION_MODE "OFF"
*MEAS_COND_IRRADIATION_WIDTH ""
*MEAS_COND_OPT_ATTR "High resolution parallel beam Ge(220)x2/RS"
*MEAS_COND_OPT_NAME "@High resolution PB-Ge(220)x2"
*MEAS_COND_UNSYMMETRIC_MODE "OFF"
*MEAS_COND_XG_CURRENT "200.0000000000"
*MEAS_COND_XG_VOLTAGE "45.0000000000"
*MEAS_COND_XG_WAVE_TYPE "Ka1"
*MEAS_DATA_COUNT "3001.0000000000"
*MEAS_SCAN_AXIS_X "2-Theta/Omega"
*MEAS_SCAN_AXIS_X_INTERNAL "TwoThetaOmega"
*MEAS_SCAN_END_TIME "07/25/23 15:56:55"
*MEAS_SCAN_MODE "CONTINUOUS"
*MEAS_SCAN_MONITOR "0"
*MEAS_SCAN_RESOLUTION_X "0.0002"
*MEAS_SCAN_SPEED "0.500000"
*MEAS_SCAN_SPEED_UNIT "deg/min"
*MEAS_SCAN_SPEED_USER "0.500000"
*MEAS_SCAN_START "0.0000000000"
*MEAS_SCAN_START_TIME "07/25/23 15:44:24"
*MEAS_SCAN_STEP "0.0020000000"
*MEAS_SCAN_STOP "6.0000000000"
*MEAS_SCAN_UNIT_X "deg"
*MEAS_SCAN_UNIT_Y "counts"
*RAS_HEADER_END
*RAS_INT_START
0.0000 5011719.0000 1.0000
0.0060 5076127.0000 1.0000
0.0120 5301487.5000 1.0000
0.0180 5210323.0000 1.0000
0.0240 5067162.5000 1.0000
0.0300 4889522.0000 1.0000
0.0360 4558239.5000 1.0000
0.0420 3728515.5000 1.0000
0.0480 2808868.5000 1.0000
0.0540 1888118.0000 1.0000
0.0600 1182659.7500 1.0000
0.0660 638023.5000 1.0000
0.0720 323968.2188 1.0000
0.0780 189462.4688 1.0000
0.0840 124473.6953 1.0000
0.0900 96634.1250 1.0000
0.0960 79675.6719 1.0000
0.1020 74804.8672 1.0000
0.1080 77821.1875 1.0000
0.1140 82937.7734 1.0000
0.1200 82483.4609 1.0000
0.1260 88061.7969 1.0000
0.1320 88225.6484 1.0000
0.1380 92575.1172 1.0000
0.1440 98592.8750 1.0000
0.1500 100328.1875 1.0000
0.1560 106919.4219 1.0000
0.1620 109958.0938 1.0000
0.1680 113823.4531 1.0000
0.1740 118187.8125 1.0000
0.1800 123557.6250 1.0000
0.1860 121799.9609 1.0000
0.1920 131943.7500 1.0000
0.1980 133857.8125 1.0000
0.2040 135704.8438 1.0000
0.2100 135682.5000 1.0000
0.2160 142608.8750 1.0000
0.2220 150689.6563 1.0000
0.2280 150391.7500 1.0000
0.2340 154242.2188 1.0000
0.2400 158487.4063 1.0000
0.2460 163425.2500 1.0000
0.2520 167260.8125 1.0000
0.2580 171357.0625 1.0000
0.2640 175833.1406 1.0000
0.2700 178074.9063 1.0000
0.2760 181940.2656 1.0000
0.2820 189097.5156 1.0000
0.2880 193640.6250 1.0000
0.2940 196560.1406 1.0000
0.3000 189842.2969 1.0000
0.3060 204648.3594 1.0000
0.3120 209980.9219 1.0000
0.3180 207910.4531 1.0000
0.3240 215924.2031 1.0000
0.3300 217063.7031 1.0000
0.3360 216892.4063 1.0000
0.3420 221927.0625 1.0000
0.3480 227788.4219 1.0000
0.3540 232540.0469 1.0000
0.3600 233925.3281 1.0000
0.3660 233240.1563 1.0000
0.3720 240337.8125 1.0000
0.3780 247189.7188 1.0000
0.3840 245908.7188 1.0000
0.3900 241313.4688 1.0000
0.3960 251025.2969 1.0000
0.4020 260111.5000 1.0000
0.4080 261444.6406 1.0000
0.4140 258800.7188 1.0000
0.4200 266501.6563 1.0000
0.4260 269361.5625 1.0000
0.4320 270076.5625 1.0000
0.4380 268914.7188 1.0000
0.4440 280697.0000 1.0000
0.4500 280324.5938 1.0000
0.4560 282454.6563 1.0000
0.4620 286439.1875 1.0000
0.4680 286185.9688 1.0000
0.4740 289850.2500 1.0000
0.4800 293670.9063 1.0000
0.4860 298951.3438 1.0000
0.4920 294222.0625 1.0000
0.4980 299547.1563 1.0000
0.5040 302459.2188 1.0000
0.5100 303576.3750 1.0000
0.5160 308908.9375 1.0000
0.5220 307344.9063 1.0000
0.5280 316393.9063 1.0000
0.5340 312297.6563 1.0000
0.5400 315179.9375 1.0000
0.5460 313668.0313 1.0000
0.5520 315708.7188 1.0000
0.5580 326865.3750 1.0000
0.5640 315485.2813 1.0000
0.5700 321257.2500 1.0000
0.5760 323625.6250 1.0000
0.5820 321138.0938 1.0000
0.5880 326396.1875 1.0000
0.5940 315045.8750 1.0000
0.6000 325517.3438 1.0000
0.6060 320311.4063 1.0000
0.6120 314167.0313 1.0000
0.6180 314718.1563 1.0000
0.6240 309825.0000 1.0000
0.6300 296590.4063 1.0000
0.6360 283825.0313 1.0000
0.6420 278671.2188 1.0000
0.6480 267730.5000 1.0000
0.6540 257914.4375 1.0000
0.6600 240382.5000 1.0000
0.6660 233173.1094 1.0000
0.6720 211127.8750 1.0000
0.6780 196731.4375 1.0000
0.6840 182483.9531 1.0000
0.6900 172064.5938 1.0000
0.6960 155739.2031 1.0000
0.7020 142497.1563 1.0000
0.7080 131198.9688 1.0000
0.7140 124414.1016 1.0000
0.7200 113041.4453 1.0000
0.7260 109928.2969 1.0000
0.7320 102286.9375 1.0000
0.7380 95211.6094 1.0000
0.7440 92485.7422 1.0000
0.7500 87421.2969 1.0000
0.7560 82237.6875 1.0000
0.7620 75907.1250 1.0000
0.7680 74730.3906 1.0000
0.7740 68087.0234 1.0000
0.7800 65212.2070 1.0000
0.7860 62091.6133 1.0000
0.7920 61720.3320 1.0000
0.7980 59044.5000 1.0000
0.8040 56634.6680 1.0000
0.8100 54500.3320 1.0000
0.8160 51948.5000 1.0000
0.8220 49762.0000 1.0000
0.8280 48013.3320 1.0000
0.8340 45940.6680 1.0000
0.8400 44206.0000 1.0000
0.8460 42173.0000 1.0000
0.8520 40279.5000 1.0000
0.8580 39048.3320 1.0000
0.8640 37399.6680 1.0000
0.8700 36254.1680 1.0000
0.8760 35000.0000 1.0000
0.8820 33471.8320 1.0000
0.8880 32126.8340 1.0000
0.8940 31253.5000 1.0000
0.9000 30295.8340 1.0000
0.9060 29004.3340 1.0000
0.9120 27844.3340 1.0000
0.9180 26790.1660 1.0000
0.9240 25803.0000 1.0000
0.9300 25030.5000 1.0000
0.9360 24091.6660 1.0000
0.9420 23385.5000 1.0000
0.9480 22369.6660 1.0000
0.9540 21457.5000 1.0000
0.9600 20793.3340 1.0000
0.9660 20148.0000 1.0000
0.9720 19601.5000 1.0000
0.9780 18768.3340 1.0000
0.9840 18092.0000 1.0000
0.9900 17525.6660 1.0000
0.9960 16818.1660 1.0000
1.0020 16106.6670 1.0000
1.0080 15880.1670 1.0000
1.0140 15379.0000 1.0000
1.0200 15067.0000 1.0000
1.0260 14419.0000 1.0000
1.0320 13915.5000 1.0000
1.0380 13431.3330 1.0000
1.0440 13181.8330 1.0000
1.0500 12726.5000 1.0000
1.0560 12346.6670 1.0000
1.0620 11785.6670 1.0000
1.0680 11404.0000 1.0000
1.0740 11207.6670 1.0000
1.0800 10614.5000 1.0000
1.0860 10258.8330 1.0000
1.0920 10122.3330 1.0000
1.0980 9808.1670 1.0000
1.1040 9471.1670 1.0000
1.1100 9520.6670 1.0000
1.1160 8928.0000 1.0000
1.1220 8680.5000 1.0000
1.1280 8389.8330 1.0000
1.1340 8210.6670 1.0000
1.1400 8053.6665 1.0000
1.1460 7837.0000 1.0000
1.1520 7520.5000 1.0000
1.1580 7373.5000 1.0000
1.1640 7099.3335 1.0000
1.1700 6970.5000 1.0000
1.1760 6758.0000 1.0000
1.1820 6643.6665 1.0000
1.1880 6402.1665 1.0000
1.1940 6143.5000 1.0000
1.2000 6070.5000 1.0000
1.2060 6002.0000 1.0000
1.2120 5640.8335 1.0000
1.2180 5715.6665 1.0000
1.2240 5517.1665 1.0000
1.2300 5168.8335 1.0000
1.2360 5342.5000 1.0000
1.2420 5114.1665 1.0000
1.2480 4977.6665 1.0000
1.2540 4767.6665 1.0000
1.2600 4631.0000 1.0000
1.2660 4566.0000 1.0000
1.2720 4493.1665 1.0000
1.2780 4439.6665 1.0000
1.2840 4343.3335 1.0000
1.2900 4236.0000 1.0000
1.2960 4061.1667 1.0000
1.3020 4001.0000 1.0000
1.3080 3919.0000 1.0000
1.3140 3720.5000 1.0000
1.3200 3757.6667 1.0000
1.3260 3596.0000 1.0000
1.3320 3632.0000 1.0000
1.3380 3528.1667 1.0000
1.3440 3450.0000 1.0000
1.3500 3403.3333 1.0000
1.3560 3320.0000 1.0000
1.3620 3337.3333 1.0000
1.3680 3141.8333 1.0000
1.3740 3195.8333 1.0000
1.3800 3115.3333 1.0000
1.3860 3085.6667 1.0000
1.3920 3026.8333 1.0000
1.3980 3045.5000 1.0000
1.4040 2944.8333 1.0000
1.4100 2850.0000 1.0000
1.4160 2829.8333 1.0000
1.4220 2739.8333 1.0000
1.4280 2752.0000 1.0000
1.4340 2712.8333 1.0000
1.4400 2723.5000 1.0000
1.4460 2647.5000 1.0000
1.4520 2587.6667 1.0000
1.4580 2545.5000 1.0000
1.4640 2601.1667 1.0000
1.4700 2529.8333 1.0000
1.4760 2497.0000 1.0000
1.4820 2440.1667 1.0000
1.4880 2457.5000 1.0000
1.4940 2449.3333 1.0000
1.5000 2365.0000 1.0000
1.5060 2364.3333 1.0000
1.5120 2381.3333 1.0000
1.5180 2299.6667 1.0000
1.5240 2316.3333 1.0000
1.5300 2271.5000 1.0000
1.5360 2232.1667 1.0000
1.5420 2227.0000 1.0000
1.5480 2230.6667 1.0000
1.5540 2235.1667 1.0000
1.5600 2228.8333 1.0000
1.5660 2120.6667 1.0000
1.5720 2139.6667 1.0000
1.5780 2099.0000 1.0000
1.5840 2118.1667 1.0000
1.5900 2061.6667 1.0000
1.5960 1987.6666 1.0000
1.6020 1928.8334 1.0000
1.6080 2055.8333 1.0000
1.6140 2008.6666 1.0000
1.6200 2017.8334 1.0000
1.6260 1929.8334 1.0000
1.6320 1971.8334 1.0000
1.6380 1926.1666 1.0000
1.6440 1840.0000 1.0000
1.6500 1927.6666 1.0000
1.6560 1832.5000 1.0000
1.6620 1864.5000 1.0000
1.6680 1769.5000 1.0000
1.6740 1826.6666 1.0000
1.6800 1819.5000 1.0000
1.6860 1751.3334 1.0000
1.6920 1779.6666 1.0000
1.6980 1817.3334 1.0000
1.7040 1710.0000 1.0000
1.7100 1706.5000 1.0000
1.7160 1711.0000 1.0000
1.7220 1627.3334 1.0000
1.7280 1654.3334 1.0000
1.7340 1618.1666 1.0000
1.7400 1590.3334 1.0000
1.7460 1568.6666 1.0000
1.7520 1544.8334 1.0000
1.7580 1561.5000 1.0000
1.7640 1612.8334 1.0000
1.7700 1494.1666 1.0000
1.7760 1477.0000 1.0000
1.7820 1555.0000 1.0000
1.7880 1473.0000 1.0000
1.7940 1429.0000 1.0000
1.8000 1499.3334 1.0000
1.8060 1466.1666 1.0000
1.8120 1393.5000 1.0000
1.8180 1397.8334 1.0000
1.8240 1452.8334 1.0000
1.8300 1292.5000 1.0000
1.8360 1402.5000 1.0000
1.8420 1341.0000 1.0000
1.8480 1350.3334 1.0000
1.8540 1337.8334 1.0000
1.8600 1301.0000 1.0000
1.8660 1353.8334 1.0000
1.8720 1261.3334 1.0000
1.8780 1241.0000 1.0000
1.8840 1294.3334 1.0000
1.8900 1288.6666 1.0000
1.8960 1305.3334 1.0000
1.9020 1183.5000 1.0000
1.9080 1225.1666 1.0000
1.9140 1166.0000 1.0000
1.9200 1113.1666 1.0000
1.9260 1191.5000 1.0000
1.9320 1096.0000 1.0000
1.9380 1108.6666 1.0000
1.9440 1143.8334 1.0000
1.9500 1126.6666 1.0000
1.9560 1120.3334 1.0000
1.9620 1105.8334 1.0000
1.9680 1048.1666 1.0000
1.9740 1005.1667 1.0000
1.9800 1029.3334 1.0000
1.9860 996.6667 1.0000
1.9920 958.0000 1.0000
1.9980 1008.1667 1.0000
2.0040 935.6667 1.0000
2.0100 941.6667 1.0000
2.0160 954.6667 1.0000
2.0220 885.5000 1.0000
2.0280 889.8333 1.0000
2.0340 886.5000 1.0000
2.0400 848.8333 1.0000
2.0460 891.0000 1.0000
2.0520 870.1667 1.0000
2.0580 885.1667 1.0000
2.0640 865.6667 1.0000
2.0700 806.6667 1.0000
2.0760 844.3333 1.0000
2.0820 751.3333 1.0000
2.0880 791.3333 1.0000
2.0940 789.1667 1.0000
2.1000 749.1667 1.0000
2.1060 813.6667 1.0000
2.1120 746.1667 1.0000
2.1180 741.8333 1.0000
2.1240 764.5000 1.0000
2.1300 784.1667 1.0000
2.1360 719.0000 1.0000
2.1420 714.3333 1.0000
2.1480 697.5000 1.0000
2.1540 662.0000 1.0000
2.1600 656.1667 1.0000
2.1660 668.6667 1.0000
2.1720 629.5000 1.0000
2.1780 642.0000 1.0000
2.1840 621.3333 1.0000
2.1900 638.8333 1.0000
2.1960 590.5000 1.0000
2.2020 620.1667 1.0000
2.2080 585.8333 1.0000
2.2140 580.5000 1.0000
2.2200 559.5000 1.0000
2.2260 635.3333 1.0000
2.2320 563.8333 1.0000
2.2380 544.5000 1.0000
2.2440 533.0000 1.0000
2.2500 528.3333 1.0000
2.2560 529.8333 1.0000
2.2620 507.0000 1.0000
2.2680 524.0000 1.0000
2.2740 497.3333 1.0000
2.2800 519.5000 1.0000
2.2860 485.8333 1.0000
2.2920 521.6667 1.0000
2.2980 485.8333 1.0000
2.3040 473.5000 1.0000
2.3100 446.8333 1.0000
2.3160 468.8333 1.0000
2.3220 435.8333 1.0000
2.3280 444.1667 1.0000
2.3340 455.5000 1.0000
2.3400 506.0000 1.0000
2.3460 461.1667 1.0000
2.3520 417.3333 1.0000
2.3580 418.0000 1.0000
2.3640 425.5000 1.0000
2.3700 434.0000 1.0000
2.3760 426.0000 1.0000
2.3820 388.3333 1.0000
2.3880 405.5000 1.0000
2.3940 411.1667 1.0000
2.4000 390.3333 1.0000
2.4060 402.3333 1.0000
2.4120 400.3333 1.0000
2.4180 381.8333 1.0000
2.4240 394.0000 1.0000
2.4300 374.0000 1.0000
2.4360 411.1667 1.0000
2.4420 397.6667 1.0000
2.4480 359.0000 1.0000
2.4540 339.6667 1.0000
2.4600 362.5000 1.0000
2.4660 390.3333 1.0000
2.4720 340.0000 1.0000
2.4780 347.3333 1.0000
2.4840 335.0000 1.0000
2.4900 353.6667 1.0000
2.4960 343.8333 1.0000
2.5020 338.5000 1.0000
2.5080 361.0000 1.0000
2.5140 334.8333 1.0000
2.5200 339.5000 1.0000
2.5260 346.5000 1.0000
2.5320 324.3333 1.0000
2.5380 309.0000 1.0000
2.5440 332.6667 1.0000
2.5500 327.6667 1.0000
2.5560 346.5000 1.0000
2.5620 297.3333 1.0000
2.5680 324.0000 1.0000
2.5740 317.5000 1.0000
2.5800 301.1667 1.0000
2.5860 273.1667 1.0000
2.5920 333.5000 1.0000
2.5980 299.0000 1.0000
2.6040 297.6667 1.0000
2.6100 271.3333 1.0000
2.6160 316.6667 1.0000
2.6220 286.3333 1.0000
2.6280 294.8333 1.0000
2.6340 288.5000 1.0000
2.6400 264.3333 1.0000
2.6460 293.5000 1.0000
2.6520 301.3333 1.0000
2.6580 292.5000 1.0000
2.6640 280.5000 1.0000
2.6700 268.1667 1.0000
2.6760 278.0000 1.0000
2.6820 300.0000 1.0000
2.6880 274.3333 1.0000
2.6940 279.1667 1.0000
2.7000 266.8333 1.0000
2.7060 295.3333 1.0000
2.7120 285.8333 1.0000
2.7180 290.8333 1.0000
2.7240 291.8333 1.0000
2.7300 273.1667 1.0000
2.7360 251.0000 1.0000
2.7420 281.5000 1.0000
2.7480 237.1667 1.0000
2.7540 231.3333 1.0000
2.7600 270.5000 1.0000
2.7660 239.6667 1.0000
2.7720 255.6667 1.0000
2.7780 264.6667 1.0000
2.7840 237.6667 1.0000
2.7900 229.8333 1.0000
2.7960 232.0000 1.0000
2.8020 238.5000 1.0000
2.8080 244.5000 1.0000
2.8140 229.3333 1.0000
2.8200 233.1667 1.0000
2.8260 209.6667 1.0000
2.8320 231.0000 1.0000
2.8380 223.0000 1.0000
2.8440 244.6667 1.0000
2.8500 200.1667 1.0000
2.8560 228.5000 1.0000
2.8620 213.5000 1.0000
2.8680 221.1667 1.0000
2.8740 217.5000 1.0000
2.8800 240.3333 1.0000
2.8860 224.3333 1.0000
2.8920 233.6667 1.0000
2.8980 195.8333 1.0000
2.9040 237.6667 1.0000
2.9100 211.3333 1.0000
2.9160 200.5000 1.0000
2.9220 212.8333 1.0000
2.9280 181.6667 1.0000
2.9340 203.3333 1.0000
2.9400 207.8333 1.0000
2.9460 197.3333 1.0000
2.9520 194.5000 1.0000
2.9580 204.0000 1.0000
2.9640 192.1667 1.0000
2.9700 196.5000 1.0000
2.9760 203.6667 1.0000
2.9820 192.3333 1.0000
2.9880 203.8333 1.0000
2.9940 172.0000 1.0000
3.0000 161.0000 1.0000
3.0060 204.5000 1.0000
3.0120 178.6667 1.0000
3.0180 164.8333 1.0000
3.0240 163.5000 1.0000
3.0300 166.0000 1.0000
3.0360 179.6667 1.0000
3.0420 160.0000 1.0000
3.0480 170.8333 1.0000
3.0540 170.5000 1.0000
3.0600 152.6667 1.0000
3.0660 159.6667 1.0000
3.0720 177.0000 1.0000
3.0780 160.6667 1.0000
3.0840 161.5000 1.0000
3.0900 141.5000 1.0000
3.0960 164.5000 1.0000
3.1020 160.8333 1.0000
3.1080 141.3333 1.0000
3.1140 157.6667 1.0000
3.1200 145.3333 1.0000
3.1260 153.5000 1.0000
3.1320 144.6667 1.0000
3.1380 141.6667 1.0000
3.1440 143.8333 1.0000
3.1500 177.6667 1.0000
3.1560 144.8333 1.0000
3.1620 149.3333 1.0000
3.1680 131.1667 1.0000
3.1740 154.0000 1.0000
3.1800 149.3333 1.0000
3.1860 136.8333 1.0000
3.1920 113.5000 1.0000
3.1980 125.5000 1.0000
3.2040 102.5000 1.0000
3.2100 119.0000 1.0000
3.2160 134.0000 1.0000
3.2220 115.5000 1.0000
3.2280 130.3333 1.0000
3.2340 122.8333 1.0000
3.2400 108.6667 1.0000
3.2460 129.0000 1.0000
3.2520 121.8333 1.0000
3.2580 106.3333 1.0000
3.2640 123.1667 1.0000
3.2700 128.8333 1.0000
3.2760 123.1667 1.0000
3.2820 124.6667 1.0000
3.2880 103.0000 1.0000
3.2940 106.6667 1.0000
3.3000 100.5000 1.0000
3.3060 112.3333 1.0000
3.3120 93.6667 1.0000
3.3180 127.1667 1.0000
3.3240 99.5000 1.0000
3.3300 112.0000 1.0000
3.3360 98.0000 1.0000
3.3420 94.1667 1.0000
3.3480 104.8333 1.0000
3.3540 89.0000 1.0000
3.3600 97.5000 1.0000
3.3660 94.1667 1.0000
3.3720 99.6667 1.0000
3.3780 99.0000 1.0000
3.3840 96.1667 1.0000
3.3900 120.5000 1.0000
3.3960 82.0000 1.0000
3.4020 96.0000 1.0000
3.4080 80.1667 1.0000
3.4140 98.8333 1.0000
3.4200 89.6667 1.0000
3.4260 89.5000 1.0000
3.4320 94.3333 1.0000
3.4380 91.6667 1.0000
3.4440 90.6667 1.0000
3.4500 75.0000 1.0000
3.4560 86.0000 1.0000
3.4620 81.8333 1.0000
3.4680 94.3333 1.0000
3.4740 105.0000 1.0000
3.4800 78.5000 1.0000
3.4860 81.8333 1.0000
3.4920 91.1667 1.0000
3.4980 82.8333 1.0000
3.5040 75.6667 1.0000
3.5100 102.5000 1.0000
3.5160 71.1667 1.0000
3.5220 74.3333 1.0000
3.5280 97.6667 1.0000
3.5340 85.3333 1.0000
3.5400 63.5000 1.0000
3.5460 81.6667 1.0000
3.5520 72.0000 1.0000
3.5580 83.3333 1.0000
3.5640 82.0000 1.0000
3.5700 74.0000 1.0000
3.5760 81.6667 1.0000
3.5820 79.5000 1.0000
3.5880 86.8333 1.0000
3.5940 70.6667 1.0000
3.6000 73.1667 1.0000
3.6060 68.0000 1.0000
3.6120 81.0000 1.0000
3.6180 73.8333 1.0000
3.6240 76.0000 1.0000
3.6300 66.8333 1.0000
3.6360 73.3333 1.0000
3.6420 76.5000 1.0000
3.6480 56.8333 1.0000
3.6540 71.1667 1.0000
3.6600 63.8333 1.0000
3.6660 65.1667 1.0000
3.6720 68.1667 1.0000
3.6780 70.6667 1.0000
3.6840 55.8333 1.0000
3.6900 73.6667 1.0000
3.6960 79.6667 1.0000
3.7020 71.8333 1.0000
3.7080 66.3333 1.0000
3.7140 63.3333 1.0000
3.7200 59.6667 1.0000
3.7260 66.0000 1.0000
3.7320 77.0000 1.0000
3.7380 65.6667 1.0000
3.7440 56.8333 1.0000
3.7500 65.1667 1.0000
3.7560 80.1667 1.0000
3.7620 67.3333 1.0000
3.7680 67.5000 1.0000
3.7740 66.5000 1.0000
3.7800 65.0000 1.0000
3.7860 77.5000 1.0000
3.7920 72.0000 1.0000
3.7980 76.0000 1.0000
3.8040 63.3333 1.0000
3.8100 67.5000 1.0000
3.8160 66.1667 1.0000
3.8220 64.8333 1.0000
3.8280 53.5000 1.0000
3.8340 57.8333 1.0000
3.8400 80.3333 1.0000
3.8460 74.8333 1.0000
3.8520 56.8333 1.0000
3.8580 71.1667 1.0000
3.8640 69.6667 1.0000
3.8700 65.6667 1.0000
3.8760 52.8333 1.0000
3.8820 56.0000 1.0000
3.8880 65.3333 1.0000
3.8940 71.5000 1.0000
3.9000 64.1667 1.0000
3.9060 57.8333 1.0000
3.9120 49.8333 1.0000
3.9180 67.6667 1.0000
3.9240 68.1667 1.0000
3.9300 53.5000 1.0000
3.9360 63.6667 1.0000
3.9420 60.5000 1.0000
3.9480 48.6667 1.0000
3.9540 48.6667 1.0000
3.9600 56.3333 1.0000
3.9660 41.3333 1.0000
3.9720 56.0000 1.0000
3.9780 54.6667 1.0000
3.9840 51.0000 1.0000
3.9900 60.8333 1.0000
3.9960 46.3333 1.0000
4.0020 49.8333 1.0000
4.0080 60.3333 1.0000
4.0140 49.3333 1.0000
4.0200 53.3333 1.0000
4.0260 65.5000 1.0000
4.0320 49.0000 1.0000
4.0380 59.8333 1.0000
4.0440 42.8333 1.0000
4.0500 57.5000 1.0000
4.0560 44.8333 1.0000
4.0620 36.5000 1.0000
4.0680 52.8333 1.0000
4.0740 48.6667 1.0000
4.0800 49.8333 1.0000
4.0860 46.8333 1.0000
4.0920 51.0000 1.0000
4.0980 49.1667 1.0000
4.1040 49.0000 1.0000
4.1100 33.0000 1.0000
4.1160 45.0000 1.0000
4.1220 36.3333 1.0000
4.1280 44.3333 1.0000
4.1340 36.6667 1.0000
4.1400 38.3333 1.0000
4.1460 41.8333 1.0000
4.1520 35.3333 1.0000
4.1580 45.3333 1.0000
4.1640 41.1667 1.0000
4.1700 45.6667 1.0000
4.1760 46.6667 1.0000
4.1820 45.0000 1.0000
4.1880 32.8333 1.0000
4.1940 44.6667 1.0000
4.2000 40.0000 1.0000
4.2060 48.5000 1.0000
4.2120 45.3333 1.0000
4.2180 34.1667 1.0000
4.2240 42.3333 1.0000
4.2300 33.1667 1.0000
4.2360 46.8333 1.0000
4.2420 31.5000 1.0000
4.2480 28.3333 1.0000
4.2540 27.0000 1.0000
4.2600 39.3333 1.0000
4.2660 31.8333 1.0000
4.2720 38.3333 1.0000
4.2780 30.0000 1.0000
4.2840 35.5000 1.0000
4.2900 37.1667 1.0000
4.2960 35.8333 1.0000
4.3020 33.0000 1.0000
4.3080 33.8333 1.0000
4.3140 31.8333 1.0000
4.3200 33.0000 1.0000
4.3260 31.6667 1.0000
4.3320 38.1667 1.0000
4.3380 40.6667 1.0000
4.3440 34.8333 1.0000
4.3500 39.3333 1.0000
4.3560 25.6667 1.0000
4.3620 28.3333 1.0000
4.3680 32.5000 1.0000
4.3740 33.5000 1.0000
4.3800 34.3333 1.0000
4.3860 29.3333 1.0000
4.3920 31.1667 1.0000
4.3980 25.3333 1.0000
4.4040 33.5000 1.0000
4.4100 33.3333 1.0000
4.4160 39.1667 1.0000
4.4220 24.5000 1.0000
4.4280 35.3333 1.0000
4.4340 22.1667 1.0000
4.4400 35.3333 1.0000
4.4460 27.8333 1.0000
4.4520 28.0000 1.0000
4.4580 35.3333 1.0000
4.4640 30.8333 1.0000
4.4700 23.5000 1.0000
4.4760 30.1667 1.0000
4.4820 27.0000 1.0000
4.4880 40.6667 1.0000
4.4940 21.3333 1.0000
4.5000 19.8333 1.0000
4.5060 20.0000 1.0000
4.5120 31.1667 1.0000
4.5180 27.6667 1.0000
4.5240 22.1667 1.0000
4.5300 28.6667 1.0000
4.5360 26.1667 1.0000
4.5420 21.5000 1.0000
4.5480 28.5000 1.0000
4.5540 30.8333 1.0000
4.5600 31.1667 1.0000
4.5660 18.6667 1.0000
4.5720 25.6667 1.0000
4.5780 24.6667 1.0000
4.5840 19.0000 1.0000
4.5900 21.8333 1.0000
4.5960 27.3333 1.0000
4.6020 27.0000 1.0000
4.6080 19.8333 1.0000
4.6140 20.5000 1.0000
4.6200 27.8333 1.0000
4.6260 21.8333 1.0000
4.6320 24.8333 1.0000
4.6380 26.1667 1.0000
4.6440 24.0000 1.0000
4.6500 14.3333 1.0000
4.6560 27.6667 1.0000
4.6620 23.6667 1.0000
4.6680 21.3333 1.0000
4.6740 18.8333 1.0000
4.6800 21.6667 1.0000
4.6860 23.0000 1.0000
4.6920 20.8333 1.0000
4.6980 28.3333 1.0000
4.7040 26.3333 1.0000
4.7100 19.1667 1.0000
4.7160 21.1667 1.0000
4.7220 26.1667 1.0000
4.7280 26.5000 1.0000
4.7340 15.3333 1.0000
4.7400 18.1667 1.0000
4.7460 20.0000 1.0000
4.7520 15.8333 1.0000
4.7580 27.5000 1.0000
4.7640 18.8333 1.0000
4.7700 16.0000 1.0000
4.7760 18.6667 1.0000
4.7820 19.5000 1.0000
4.7880 27.0000 1.0000
4.7940 16.3333 1.0000
4.8000 26.0000 1.0000
4.8060 16.8333 1.0000
4.8120 22.6667 1.0000
4.8180 20.5000 1.0000
4.8240 28.3333 1.0000
4.8300 4.6667 1.0000
4.8360 19.0000 1.0000
4.8420 19.5000 1.0000
4.8480 23.1667 1.0000
4.8540 10.3333 1.0000
4.8600 21.1667 1.0000
4.8660 25.8333 1.0000
4.8720 18.8333 1.0000
4.8780 10.8333 1.0000
4.8840 16.1667 1.0000
4.8900 15.5000 1.0000
4.8960 17.0000 1.0000
4.9020 15.3333 1.0000
4.9080 16.0000 1.0000
4.9140 30.1667 1.0000
4.9200 23.8333 1.0000
4.9260 23.3333 1.0000
4.9320 26.5000 1.0000
4.9380 21.3333 1.0000
4.9440 19.8333 1.0000
4.9500 13.1667 1.0000
4.9560 24.3333 1.0000
4.9620 16.8333 1.0000
4.9680 17.3333 1.0000
4.9740 18.8333 1.0000
4.9800 17.0000 1.0000
4.9860 20.0000 1.0000
4.9920 22.8333 1.0000
4.9980 17.3333 1.0000
5.0040 15.6667 1.0000
5.0100 17.5000 1.0000
5.0160 12.3333 1.0000
5.0220 20.3333 1.0000
5.0280 10.1667 1.0000
5.0340 22.1667 1.0000
5.0400 13.1667 1.0000
5.0460 13.1667 1.0000
5.0520 18.6667 1.0000
5.0580 9.1667 1.0000
5.0640 18.3333 1.0000
5.0700 15.0000 1.0000
5.0760 13.1667 1.0000
5.0820 11.6667 1.0000
5.0880 12.3333 1.0000
5.0940 9.6667 1.0000
5.1000 17.0000 1.0000
5.1060 18.0000 1.0000
5.1120 16.0000 1.0000
5.1180 10.6667 1.0000
5.1240 19.1667 1.0000
5.1300 21.6667 1.0000
5.1360 7.5000 1.0000
5.1420 12.1667 1.0000
5.1480 14.0000 1.0000
5.1540 15.8333 1.0000
5.1600 18.3333 1.0000
5.1660 19.1667 1.0000
5.1720 15.6667 1.0000
5.1780 9.3333 1.0000
5.1840 12.3333 1.0000
5.1900 16.8333 1.0000
5.1960 15.6667 1.0000
5.2020 7.0000 1.0000
5.2080 7.6667 1.0000
5.2140 14.3333 1.0000
5.2200 7.6667 1.0000
5.2260 13.5000 1.0000
5.2320 9.8333 1.0000
5.2380 8.0000 1.0000
5.2440 14.3333 1.0000
5.2500 12.8333 1.0000
5.2560 16.0000 1.0000
5.2620 5.6667 1.0000
5.2680 9.1667 1.0000
5.2740 14.0000 1.0000
5.2800 19.8333 1.0000
5.2860 5.6667 1.0000
5.2920 15.8333 1.0000
5.2980 16.8333 1.0000
5.3040 21.6667 1.0000
5.3100 15.3333 1.0000
5.3160 15.5000 1.0000
5.3220 12.1667 1.0000
5.3280 18.6667 1.0000
5.3340 11.1667 1.0000
5.3400 12.0000 1.0000
5.3460 6.5000 1.0000
5.3520 6.1667 1.0000
5.3580 12.1667 1.0000
5.3640 14.6667 1.0000
5.3700 6.6667 1.0000
5.3760 11.1667 1.0000
5.3820 13.6667 1.0000
5.3880 2.3333 1.0000
5.3940 8.6667 1.0000
5.4000 9.0000 1.0000
5.4060 10.6667 1.0000
5.4120 12.1667 1.0000
5.4180 5.3333 1.0000
5.4240 10.8333 1.0000
5.4300 8.3333 1.0000
5.4360 10.0000 1.0000
5.4420 14.1667 1.0000
5.4480 11.6667 1.0000
5.4540 14.6667 1.0000
5.4600 10.0000 1.0000
5.4660 12.8333 1.0000
5.4720 6.6667 1.0000
5.4780 9.1667 1.0000
5.4840 14.0000 1.0000
5.4900 6.3333 1.0000
5.4960 13.6667 1.0000
5.5020 17.3333 1.0000
5.5080 15.6667 1.0000
5.5140 12.8333 1.0000
5.5200 16.1667 1.0000
5.5260 7.1667 1.0000
5.5320 15.3333 1.0000
5.5380 9.8333 1.0000
5.5440 14.1667 1.0000
5.5500 13.6667 1.0000
5.5560 18.0000 1.0000
5.5620 5.3333 1.0000
5.5680 12.6667 1.0000
5.5740 15.1667 1.0000
5.5800 14.6667 1.0000
5.5860 8.8333 1.0000
5.5920 12.0000 1.0000
5.5980 11.3333 1.0000
5.6040 9.5000 1.0000
5.6100 11.0000 1.0000
5.6160 6.1667 1.0000
5.6220 10.5000 1.0000
5.6280 10.0000 1.0000
5.6340 12.8333 1.0000
5.6400 15.3333 1.0000
5.6460 9.3333 1.0000
5.6520 9.6667 1.0000
5.6580 10.0000 1.0000
5.6640 12.0000 1.0000
5.6700 10.0000 1.0000
5.6760 10.1667 1.0000
5.6820 7.3333 1.0000
5.6880 3.8333 1.0000
5.6940 7.6667 1.0000
5.7000 10.3333 1.0000
5.7060 11.1667 1.0000
5.7120 7.0000 1.0000
5.7180 6.0000 1.0000
5.7240 8.0000 1.0000
5.7300 3.3333 1.0000
5.7360 16.1667 1.0000
5.7420 10.8333 1.0000
5.7480 10.3333 1.0000
5.7540 4.0000 1.0000
5.7600 8.5000 1.0000
5.7660 5.0000 1.0000
5.7720 5.8333 1.0000
5.7780 5.1667 1.0000
5.7840 6.3333 1.0000
5.7900 6.8333 1.0000
5.7960 5.0000 1.0000
5.8020 8.5000 1.0000
5.8080 7.5000 1.0000
5.8140 7.1667 1.0000
5.8200 8.1667 1.0000
5.8260 3.1667 1.0000
5.8320 2.5000 1.0000
5.8380 5.5000 1.0000
5.8440 5.0000 1.0000
5.8500 8.5000 1.0000
5.8560 7.5000 1.0000
5.8620 6.1667 1.0000
5.8680 7.1667 1.0000
5.8740 8.1667 1.0000
5.8800 11.8333 1.0000
5.8860 11.5000 1.0000
5.8920 3.5000 1.0000
5.8980 6.0000 1.0000
5.9040 5.0000 1.0000
5.9100 10.6667 1.0000
5.9160 12.3333 1.0000
5.9220 7.6667 1.0000
5.9280 5.1667 1.0000
5.9340 7.6667 1.0000
5.9400 11.5000 1.0000
5.9460 6.8333 1.0000
5.9520 9.0000 1.0000
5.9580 5.6667 1.0000
5.9640 3.5000 1.0000
5.9700 6.1667 1.0000
5.9760 9.1667 1.0000
5.9820 11.3333 1.0000
5.9880 3.5000 1.0000
5.9940 8.5000 1.0000
6.0000 2.3333 1.0000
*RAS_INT_END
*RAS_DATA_END