File: xrr_temp/CWOI6anneal_reflectivity.ras
*RAS_DATA_START
*RAS_HEADER_START
*DISP_FMT_X "%.4f"
*DISP_FMT_Y "%.0f"
*DISP_FULLSCALE "31169807.0000000000"
*DISP_LINE_COLOR "255.0000000000"
*DISP_LINE_STYLE "0.0000000000"
*DISP_LINE_WIDTH "0.2500000000"
*DISP_NOTE "Collected Data-16"
*DISP_OFFSET_Y "0.0000000000"
*DISP_PEAKSEARCH_UNIT_Y "cps"
*DISP_RANGE_BOTTOM "0.0100000000"
*DISP_RANGE_LEFT "-0.0006000000"
*DISP_RANGE_LOGCUTOFF "0.0100000000"
*DISP_RANGE_RIGHT "6.0006000000"
*DISP_RANGE_TOP "31169807.0000000000"
*DISP_SCALE_MODE_Y "2.0000000000"
*DISP_TAB_NAME "2-Theta/Omega"
*DISP_TITLE_Y "Intensity"
*DISP_UNIT_Y "cps"
*DISP_WINDOW_NAME "MSG_MACROENGINE"
*FILE_COMMENT " "
*FILE_MD5 ""
*FILE_MEMO " "
*FILE_OPERATOR "administrator"
*FILE_PART_ID "MEAS_KHP2_00055"
*FILE_SAMPLE "CWOI6"
*FILE_TYPE "RAS_RAW"
*FILE_USERGROUP "System Manager"
*FILE_VERSION "1.0000000000"
*HW_ATTACHMENT_ID "ATT0025"
*HW_ATTACHMENT_NAME "標準|Standard"
*HW_COUNTER_ID-0 "CUT0025"
*HW_COUNTER_ID-1 "CUT0020"
*HW_COUNTER_ID-2 "CUT0020"
*HW_COUNTER_ID-3 "CSL0021"
*HW_COUNTER_ID-4 "CMC0021"
*HW_COUNTER_NAME-0 "D/teX Ultra|D/teX Ultra"
*HW_COUNTER_NAME-1 "None|None"
*HW_COUNTER_NAME-2 "None|None"
*HW_COUNTER_NAME-3 "BBM|BBM"
*HW_COUNTER_NAME-4 "検出器モノクロメータ|Detector monochromator"
*HW_COUNTER_SELECT_NAME "D/teX Ultra|D/teX Ultra"
*HW_GONIOMETER_ID "GON0023"
*HW_GONIOMETER_NAME "SmartLab|SmartLab"
*HW_GONIOMETER_RADIUS-0 "90.0"
*HW_GONIOMETER_RADIUS-1 "114.0"
*HW_GONIOMETER_RADIUS-2 "190.0"
*HW_GONIOMETER_RADIUS-3 "300.0"
*HW_GONIOMETER_RADIUS-4 "187.0"
*HW_GONIOMETER_RADIUS-5 "300.0"
*HW_GONIOMETER_RADIUS-6 "113.0"
*HW_GONIOMETER_RADIUS-7 "331.0"
*HW_I_OPT_ID-0 "CBO0021"
*HW_I_OPT_ID-1 "ICR0021"
*HW_I_OPT_ID-2 "ISL0021"
*HW_I_OPT_ID-3 "ISO0021"
*HW_I_OPT_ID-4 "IAD0021"
*HW_I_OPT_ID-5 "IPR0001"
*HW_I_OPT_NAME-0 "CBOユニット|CBO unit"
*HW_I_OPT_NAME-1 "標準入射光学ユニット|Standard incident optical unit"
*HW_I_OPT_NAME-2 "標準入射スリットボックス|Standard incident slit box"
*HW_I_OPT_NAME-3 "入射平行スリット|Incident parallel slit"
*HW_I_OPT_NAME-4 "長手制限スリット|Length limiting slit"
*HW_I_OPT_NAME-5 "None|None"
*HW_R_ATTENUATER_AUTOMODE "1"
*HW_R_OPT_ID-0 "RSS0021"
*HW_R_OPT_ID-1 "RCR0023"
*HW_R_OPT_ID-2 "RSO0021"
*HW_R_OPT_ID-3 "RRS0021"
*HW_R_OPT_ID-4 "ATN0021"
*HW_R_OPT_ID-5 "RFL0021"
*HW_R_OPT_ID-6 "RAD0021"
*HW_R_OPT_NAME-0 "標準受光スリットボックス1|Standard receiving slit box # 1"
*HW_R_OPT_NAME-1 "標準受光光学ユニット1|Standard receiving unit # 1"
*HW_R_OPT_NAME-2 "標準受光光学ユニット2|Standard receiving optical unit # 2"
*HW_R_OPT_NAME-3 "標準受光スリットボックス2|Standard receiving slit box # 2"
*HW_R_OPT_NAME-4 "標準アッテネータ|Standard Attenuator"
*HW_R_OPT_NAME-5 "Cu Kβ|Cu K-beta"
*HW_R_OPT_NAME-6 "調整用受光スリット|Alignment receiving slit"
*HW_SAMPLE_HOLDER_ID "SMP0021"
*HW_SAMPLE_HOLDER_NAME "χφZクレードル|Chi phi Z cradle"
*HW_XG_CURRENT_MAX "200"
*HW_XG_CURRENT_MIN "10"
*HW_XG_CURRENT_RESOLUTION "1"
*HW_XG_CURRENT_UNIT "mA"
*HW_XG_FOCUS "0.4mm x 8mm"
*HW_XG_FOCUS_TYPE "Normal"
*HW_XG_ID "1700"
*HW_XG_NAME "9kW 開放管(45kV 200mA ID:1700)|9kW Rotating anode(45kV 200mA ID:1700)"
*HW_XG_TARGET_ATOMIC_NUMBER "29.0000000000"
*HW_XG_TARGET_NAME "Cu"
*HW_XG_TYPE "Rota"
*HW_XG_VOLTAGE_MAX "45"
*HW_XG_VOLTAGE_MIN "20"
*HW_XG_VOLTAGE_RESOLUTION "1"
*HW_XG_VOLTAGE_UNIT "kV"
*HW_XG_WATT_MAX "9.00"
*HW_XG_WATT_UNIT "kW"
*HW_XG_WAVE_LENGTH_ALPHA1 "1.540593"
*HW_XG_WAVE_LENGTH_ALPHA2 "1.544414"
*HW_XG_WAVE_LENGTH_BETA "1.392250"
*MEAS_COND_AXIS_NAME-0 "Theta/2-Theta"
*MEAS_COND_AXIS_NAME-1 "2-Theta"
*MEAS_COND_AXIS_NAME-2 "Omega"
*MEAS_COND_AXIS_NAME-3 "Chi"
*MEAS_COND_AXIS_NAME-4 "Phi"
*MEAS_COND_AXIS_NAME-5 "Z"
*MEAS_COND_AXIS_NAME-6 "2-Theta/Omega"
*MEAS_COND_AXIS_NAME-7 "Theta_s"
*MEAS_COND_AXIS_NAME-8 "Theta_d"
*MEAS_COND_AXIS_NAME-9 "Ts"
*MEAS_COND_AXIS_NAME-10 "CBO selection slit"
*MEAS_COND_AXIS_NAME-11 "M"
*MEAS_COND_AXIS_NAME-12 "Incident parallel slit"
*MEAS_COND_AXIS_NAME-13 "Incident slit"
*MEAS_COND_AXIS_NAME-14 ""
*MEAS_COND_AXIS_NAME-15 "Zs"
*MEAS_COND_AXIS_NAME-16 "Incident optical device"
*MEAS_COND_AXIS_NAME-17 "Omega_m"
*MEAS_COND_AXIS_NAME-18 "Length limiting slit"
*MEAS_COND_AXIS_NAME-19 "Center slit"
*MEAS_COND_AXIS_NAME-20 "Filter"
*MEAS_COND_AXIS_NAME-21 "Receiving slit # 1"
*MEAS_COND_AXIS_NAME-22 "Receiving slit # 2"
*MEAS_COND_AXIS_NAME-23 "Receiving optical device"
*MEAS_COND_AXIS_NAME-24 "Receiving parallel slit"
*MEAS_COND_AXIS_NAME-25 "Alignment receiving slit"
*MEAS_COND_AXIS_NAME-26 ""
*MEAS_COND_AXIS_NAME-27 ""
*MEAS_COND_AXIS_NAME-28 "Zd"
*MEAS_COND_AXIS_NAME-29 "Attenuator"
*MEAS_COND_AXIS_NAME-30 "Diffracted beam monochromator"
*MEAS_COND_AXIS_NAME-31 "Monochromator slit"
*MEAS_COND_AXIS_NAME-32 "Primary beam"
*MEAS_COND_AXIS_NAME-33 ""
*MEAS_COND_AXIS_NAME-34 ""
*MEAS_COND_AXIS_NAME-35 "PHA"
*MEAS_COND_AXIS_NAME_INTERNAL-0 "TwoThetaTheta"
*MEAS_COND_AXIS_NAME_INTERNAL-1 "TwoTheta"
*MEAS_COND_AXIS_NAME_INTERNAL-2 "Omega"
*MEAS_COND_AXIS_NAME_INTERNAL-3 "Chi"
*MEAS_COND_AXIS_NAME_INTERNAL-4 "Phi"
*MEAS_COND_AXIS_NAME_INTERNAL-5 "Z"
*MEAS_COND_AXIS_NAME_INTERNAL-6 "TwoThetaOmega"
*MEAS_COND_AXIS_NAME_INTERNAL-7 "ThetaS"
*MEAS_COND_AXIS_NAME_INTERNAL-8 "ThetaD"
*MEAS_COND_AXIS_NAME_INTERNAL-9 "Ts"
*MEAS_COND_AXIS_NAME_INTERNAL-10 "CBO"
*MEAS_COND_AXIS_NAME_INTERNAL-11 "CBO-M"
*MEAS_COND_AXIS_NAME_INTERNAL-12 "IncidentSollerSlit"
*MEAS_COND_AXIS_NAME_INTERNAL-13 "IncidentSlitBox"
*MEAS_COND_AXIS_NAME_INTERNAL-14 "IncidentSlitBox-_Axis"
*MEAS_COND_AXIS_NAME_INTERNAL-15 "Zs"
*MEAS_COND_AXIS_NAME_INTERNAL-16 "IncidentMonochromator"
*MEAS_COND_AXIS_NAME_INTERNAL-17 "IncidentMonochromator-OmegaM"
*MEAS_COND_AXIS_NAME_INTERNAL-18 "IncidentAxdSlit"
*MEAS_COND_AXIS_NAME_INTERNAL-19 "CenterSlit"
*MEAS_COND_AXIS_NAME_INTERNAL-20 "Filter"
*MEAS_COND_AXIS_NAME_INTERNAL-21 "ReceivingSlitBox1"
*MEAS_COND_AXIS_NAME_INTERNAL-22 "ReceivingSlitBox2"
*MEAS_COND_AXIS_NAME_INTERNAL-23 "ReceivingOptics"
*MEAS_COND_AXIS_NAME_INTERNAL-24 "ReceivingSollerSlit"
*MEAS_COND_AXIS_NAME_INTERNAL-25 "ReceivingAxdSlit"
*MEAS_COND_AXIS_NAME_INTERNAL-26 "ReceivingSlitBox1-_Axis"
*MEAS_COND_AXIS_NAME_INTERNAL-27 "ReceivingSlitBox2-_Axis"
*MEAS_COND_AXIS_NAME_INTERNAL-28 "ReceivingSlitBox2-Zd"
*MEAS_COND_AXIS_NAME_INTERNAL-29 "Attenuator"
*MEAS_COND_AXIS_NAME_INTERNAL-30 "CounterMonochromator"
*MEAS_COND_AXIS_NAME_INTERNAL-31 "CounterSlit"
*MEAS_COND_AXIS_NAME_INTERNAL-32 "IncidentPrimary"
*MEAS_COND_AXIS_NAME_INTERNAL-33 "AlphaR"
*MEAS_COND_AXIS_NAME_INTERNAL-34 "BetaR"
*MEAS_COND_AXIS_NAME_INTERNAL-35 "PHA"
*MEAS_COND_AXIS_NAME_MAGICNO-0 "83951616.0000000000"
*MEAS_COND_AXIS_NAME_MAGICNO-1 "268632064.0000000000"
*MEAS_COND_AXIS_NAME_MAGICNO-2 "268500992.0000000000"
*MEAS_COND_AXIS_NAME_MAGICNO-3 "268500992.0000000000"
*MEAS_COND_AXIS_NAME_MAGICNO-4 "268500992.0000000000"
*MEAS_COND_AXIS_NAME_MAGICNO-5 "285278208.0000000000"
*MEAS_COND_AXIS_NAME_MAGICNO-6 "83951616.0000000000"
*MEAS_COND_AXIS_NAME_MAGICNO-7 "131072.0000000000"
*MEAS_COND_AXIS_NAME_MAGICNO-8 "131072.0000000000"
*MEAS_COND_AXIS_NAME_MAGICNO-9 "318898176.0000000000"
*MEAS_COND_AXIS_NAME_MAGICNO-10 "20971521.0000000000"
*MEAS_COND_AXIS_NAME_MAGICNO-11 "285343744.0000000000"
*MEAS_COND_AXIS_NAME_MAGICNO-12 "20971521.0000000000"
*MEAS_COND_AXIS_NAME_MAGICNO-13 "22020097.0000000000"
*MEAS_COND_AXIS_NAME_MAGICNO-14 "25165824.0000000000"
*MEAS_COND_AXIS_NAME_MAGICNO-15 "318898176.0000000000"
*MEAS_COND_AXIS_NAME_MAGICNO-16 "20971521.0000000000"
*MEAS_COND_AXIS_NAME_MAGICNO-17 "285343744.0000000000"
*MEAS_COND_AXIS_NAME_MAGICNO-18 "20971521.0000000000"
*MEAS_COND_AXIS_NAME_MAGICNO-19 "20971521.0000000000"
*MEAS_COND_AXIS_NAME_MAGICNO-20 "20971521.0000000000"
*MEAS_COND_AXIS_NAME_MAGICNO-21 "23068673.0000000000"
*MEAS_COND_AXIS_NAME_MAGICNO-22 "23068673.0000000000"
*MEAS_COND_AXIS_NAME_MAGICNO-23 "20971521.0000000000"
*MEAS_COND_AXIS_NAME_MAGICNO-24 "20971521.0000000000"
*MEAS_COND_AXIS_NAME_MAGICNO-25 "20971521.0000000000"
*MEAS_COND_AXIS_NAME_MAGICNO-26 "25165824.0000000000"
*MEAS_COND_AXIS_NAME_MAGICNO-27 "25165824.0000000000"
*MEAS_COND_AXIS_NAME_MAGICNO-28 "285343744.0000000000"
*MEAS_COND_AXIS_NAME_MAGICNO-29 "17301505.0000000000"
*MEAS_COND_AXIS_NAME_MAGICNO-30 "20971521.0000000000"
*MEAS_COND_AXIS_NAME_MAGICNO-31 "20971521.0000000000"
*MEAS_COND_AXIS_NAME_MAGICNO-32 "20971521.0000000000"
*MEAS_COND_AXIS_NAME_MAGICNO-33 "8388608.0000000000"
*MEAS_COND_AXIS_NAME_MAGICNO-34 "8388608.0000000000"
*MEAS_COND_AXIS_NAME_MAGICNO-35 "0.0000000000"
*MEAS_COND_AXIS_OFFSET-0 "-"
*MEAS_COND_AXIS_OFFSET-1 "0.8835000000"
*MEAS_COND_AXIS_OFFSET-2 "0.1866000000"
*MEAS_COND_AXIS_OFFSET-3 "0.0000000000"
*MEAS_COND_AXIS_OFFSET-4 "0.0000000000"
*MEAS_COND_AXIS_OFFSET-5 "-"
*MEAS_COND_AXIS_OFFSET-6 "-"
*MEAS_COND_AXIS_OFFSET-7 "0.1866000000"
*MEAS_COND_AXIS_OFFSET-8 "0.6969000000"
*MEAS_COND_AXIS_OFFSET-9 "-"
*MEAS_COND_AXIS_OFFSET-10 "-"
*MEAS_COND_AXIS_OFFSET-11 "-"
*MEAS_COND_AXIS_OFFSET-12 "-"
*MEAS_COND_AXIS_OFFSET-13 "-"
*MEAS_COND_AXIS_OFFSET-14 "-"
*MEAS_COND_AXIS_OFFSET-15 "-"
*MEAS_COND_AXIS_OFFSET-16 "-"
*MEAS_COND_AXIS_OFFSET-17 "-"
*MEAS_COND_AXIS_OFFSET-18 "-"
*MEAS_COND_AXIS_OFFSET-19 "-"
*MEAS_COND_AXIS_OFFSET-20 "-"
*MEAS_COND_AXIS_OFFSET-21 "-"
*MEAS_COND_AXIS_OFFSET-22 "-"
*MEAS_COND_AXIS_OFFSET-23 "-"
*MEAS_COND_AXIS_OFFSET-24 "-"
*MEAS_COND_AXIS_OFFSET-25 "-"
*MEAS_COND_AXIS_OFFSET-26 "-"
*MEAS_COND_AXIS_OFFSET-27 "-"
*MEAS_COND_AXIS_OFFSET-28 "-"
*MEAS_COND_AXIS_OFFSET-29 "-"
*MEAS_COND_AXIS_OFFSET-30 "-"
*MEAS_COND_AXIS_OFFSET-31 "-"
*MEAS_COND_AXIS_OFFSET-32 "-"
*MEAS_COND_AXIS_OFFSET-33 "0.0000000000"
*MEAS_COND_AXIS_OFFSET-34 "0.0000000000"
*MEAS_COND_AXIS_OFFSET-35 "-"
*MEAS_COND_AXIS_POSITION-0 "-0.0008000000"
*MEAS_COND_AXIS_POSITION-1 "-0.0009000000"
*MEAS_COND_AXIS_POSITION-2 "-0.0005000000"
*MEAS_COND_AXIS_POSITION-3 "0.0000000000"
*MEAS_COND_AXIS_POSITION-4 "0.0000000000"
*MEAS_COND_AXIS_POSITION-5 "-1.4565000000"
*MEAS_COND_AXIS_POSITION-6 "-0.0008000000"
*MEAS_COND_AXIS_POSITION-7 "-0.0005000000"
*MEAS_COND_AXIS_POSITION-8 "-0.0004000000"
*MEAS_COND_AXIS_POSITION-9 "-4.7109400000"
*MEAS_COND_AXIS_POSITION-10 "PB"
*MEAS_COND_AXIS_POSITION-11 "0.0000000000"
*MEAS_COND_AXIS_POSITION-12 "Soller_slit_open_s"
*MEAS_COND_AXIS_POSITION-13 "0.250mm"
*MEAS_COND_AXIS_POSITION-14 "0.2500000000"
*MEAS_COND_AXIS_POSITION-15 "-1.7440600000"
*MEAS_COND_AXIS_POSITION-16 "Ge(220)x2"
*MEAS_COND_AXIS_POSITION-17 "0.0000000000"
*MEAS_COND_AXIS_POSITION-18 "2.0mm"
*MEAS_COND_AXIS_POSITION-19 "None"
*MEAS_COND_AXIS_POSITION-20 "None"
*MEAS_COND_AXIS_POSITION-21 "0.250mm"
*MEAS_COND_AXIS_POSITION-22 "0.250mm"
*MEAS_COND_AXIS_POSITION-23 "No_unit"
*MEAS_COND_AXIS_POSITION-24 "Soller_slit_5.0deg"
*MEAS_COND_AXIS_POSITION-25 "None"
*MEAS_COND_AXIS_POSITION-26 "0.2500000000"
*MEAS_COND_AXIS_POSITION-27 "0.2500000000"
*MEAS_COND_AXIS_POSITION-28 "0.0890600000"
*MEAS_COND_AXIS_POSITION-29 "1/10000"
*MEAS_COND_AXIS_POSITION-30 "None"
*MEAS_COND_AXIS_POSITION-31 "None"
*MEAS_COND_AXIS_POSITION-32 "None"
*MEAS_COND_AXIS_POSITION-33 "0.0000000000"
*MEAS_COND_AXIS_POSITION-34 "0.0000000000"
*MEAS_COND_AXIS_POSITION-35 "34.0000000000"
*MEAS_COND_AXIS_UNIT-0 "deg"
*MEAS_COND_AXIS_UNIT-1 "deg"
*MEAS_COND_AXIS_UNIT-2 "deg"
*MEAS_COND_AXIS_UNIT-3 "deg"
*MEAS_COND_AXIS_UNIT-4 "deg"
*MEAS_COND_AXIS_UNIT-5 "mm"
*MEAS_COND_AXIS_UNIT-6 "deg"
*MEAS_COND_AXIS_UNIT-7 "deg"
*MEAS_COND_AXIS_UNIT-8 "deg"
*MEAS_COND_AXIS_UNIT-9 "mm"
*MEAS_COND_AXIS_UNIT-10 ""
*MEAS_COND_AXIS_UNIT-11 "pulse"
*MEAS_COND_AXIS_UNIT-12 ""
*MEAS_COND_AXIS_UNIT-13 ""
*MEAS_COND_AXIS_UNIT-14 "mm"
*MEAS_COND_AXIS_UNIT-15 "mm"
*MEAS_COND_AXIS_UNIT-16 ""
*MEAS_COND_AXIS_UNIT-17 "pulse"
*MEAS_COND_AXIS_UNIT-18 ""
*MEAS_COND_AXIS_UNIT-19 ""
*MEAS_COND_AXIS_UNIT-20 ""
*MEAS_COND_AXIS_UNIT-21 ""
*MEAS_COND_AXIS_UNIT-22 ""
*MEAS_COND_AXIS_UNIT-23 ""
*MEAS_COND_AXIS_UNIT-24 ""
*MEAS_COND_AXIS_UNIT-25 ""
*MEAS_COND_AXIS_UNIT-26 "mm"
*MEAS_COND_AXIS_UNIT-27 "mm"
*MEAS_COND_AXIS_UNIT-28 "mm"
*MEAS_COND_AXIS_UNIT-29 ""
*MEAS_COND_AXIS_UNIT-30 ""
*MEAS_COND_AXIS_UNIT-31 ""
*MEAS_COND_AXIS_UNIT-32 ""
*MEAS_COND_AXIS_UNIT-33 "deg"
*MEAS_COND_AXIS_UNIT-34 "deg"
*MEAS_COND_AXIS_UNIT-35 "div"
*MEAS_COND_COUNTER_CNTLOSS_CORR "0.0000000000"
*MEAS_COND_COUNTER_PHABASE "34.0000000000"
*MEAS_COND_COUNTER_PHAWINDOW "19.0000000000"
*MEAS_COND_COUNTER_PHA_UNIT "div"
*MEAS_COND_COUNTER_TAUDIFF "2.0000000000"
*MEAS_COND_COUNTER_TAUINT "0.1000000000"
*MEAS_COND_IRRADIATION_MODE "OFF"
*MEAS_COND_IRRADIATION_WIDTH ""
*MEAS_COND_OPT_ATTR "High resolution parallel beam Ge(220)x2/RS"
*MEAS_COND_OPT_NAME "@High resolution PB-Ge(220)x2"
*MEAS_COND_UNSYMMETRIC_MODE "OFF"
*MEAS_COND_XG_CURRENT "200.0000000000"
*MEAS_COND_XG_VOLTAGE "45.0000000000"
*MEAS_COND_XG_WAVE_TYPE "Ka1"
*MEAS_DATA_COUNT "3001.0000000000"
*MEAS_SCAN_AXIS_X "2-Theta/Omega"
*MEAS_SCAN_AXIS_X_INTERNAL "TwoThetaOmega"
*MEAS_SCAN_END_TIME "11/09/23 18:31:57"
*MEAS_SCAN_MODE "CONTINUOUS"
*MEAS_SCAN_MONITOR "0"
*MEAS_SCAN_RESOLUTION_X "0.0002"
*MEAS_SCAN_SPEED "0.500000"
*MEAS_SCAN_SPEED_UNIT "deg/min"
*MEAS_SCAN_SPEED_USER "0.500000"
*MEAS_SCAN_START "0.0000000000"
*MEAS_SCAN_START_TIME "11/09/23 18:19:12"
*MEAS_SCAN_STEP "0.0020000000"
*MEAS_SCAN_STOP "6.0000000000"
*MEAS_SCAN_UNIT_X "deg"
*MEAS_SCAN_UNIT_Y "counts"
*RAS_HEADER_END
*RAS_INT_START
0.0000 5896748.5000 1.0000
0.0060 6131487.0000 1.0000
0.0120 5849442.0000 1.0000
0.0180 5693179.0000 1.0000
0.0240 5435959.0000 1.0000
0.0300 5107159.0000 1.0000
0.0360 4634647.0000 1.0000
0.0420 3856367.0000 1.0000
0.0480 2835211.2500 1.0000
0.0540 1930459.2500 1.0000
0.0600 1118796.5000 1.0000
0.0660 605633.4375 1.0000
0.0720 294750.8125 1.0000
0.0780 156007.3125 1.0000
0.0840 96917.1406 1.0000
0.0900 69911.7188 1.0000
0.0960 62337.3906 1.0000
0.1020 60342.1680 1.0000
0.1080 61484.8320 1.0000
0.1140 63814.1680 1.0000
0.1200 66078.6641 1.0000
0.1260 68662.0000 1.0000
0.1320 71859.3359 1.0000
0.1380 74818.5000 1.0000
0.1440 77319.1641 1.0000
0.1500 80665.5000 1.0000
0.1560 84144.8359 1.0000
0.1620 86507.8359 1.0000
0.1680 89534.6641 1.0000
0.1740 92652.3359 1.0000
0.1800 87763.8906 1.0000
0.1860 97401.2422 1.0000
0.1920 98577.9766 1.0000
0.1980 100149.4453 1.0000
0.2040 104484.0156 1.0000
0.2100 107977.0000 1.0000
0.2160 111812.5703 1.0000
0.2220 111968.9688 1.0000
0.2280 115476.8438 1.0000
0.2340 117644.1328 1.0000
0.2400 125196.1172 1.0000
0.2460 126380.3047 1.0000
0.2520 126722.9063 1.0000
0.2580 131921.4063 1.0000
0.2640 131891.6094 1.0000
0.2700 130297.8047 1.0000
0.2760 140486.2813 1.0000
0.2820 144247.3750 1.0000
0.2880 144053.7344 1.0000
0.2940 142400.3438 1.0000
0.3000 148365.9688 1.0000
0.3060 148976.6875 1.0000
0.3120 150875.8438 1.0000
0.3180 159813.1094 1.0000
0.3240 163216.7188 1.0000
0.3300 156826.5781 1.0000
0.3360 163246.5000 1.0000
0.3420 169055.7188 1.0000
0.3480 165227.5938 1.0000
0.3540 167849.1875 1.0000
0.3600 171632.6250 1.0000
0.3660 176793.9063 1.0000
0.3720 175259.6719 1.0000
0.3780 186036.5156 1.0000
0.3840 180547.5469 1.0000
0.3900 183146.7969 1.0000
0.3960 185790.7344 1.0000
0.4020 188270.8281 1.0000
0.4080 187377.1094 1.0000
0.4140 191778.7031 1.0000
0.4200 199598.7969 1.0000
0.4260 196656.9531 1.0000
0.4320 201043.6719 1.0000
0.4380 206324.0938 1.0000
0.4440 202994.9688 1.0000
0.4500 205892.1250 1.0000
0.4560 204968.6094 1.0000
0.4620 210390.5469 1.0000
0.4680 210591.6406 1.0000
0.4740 209697.9063 1.0000
0.4800 211314.0625 1.0000
0.4860 216832.8125 1.0000
0.4920 215864.6250 1.0000
0.4980 211507.7031 1.0000
0.5040 215745.4531 1.0000
0.5100 217734.0000 1.0000
0.5160 214985.7969 1.0000
0.5220 215335.8281 1.0000
0.5280 219759.7813 1.0000
0.5340 219365.0469 1.0000
0.5400 223230.4063 1.0000
0.5460 215261.3594 1.0000
0.5520 220906.7188 1.0000
0.5580 224079.4531 1.0000
0.5640 226388.2500 1.0000
0.5700 221941.9531 1.0000
0.5760 213742.0156 1.0000
0.5820 222150.5000 1.0000
0.5880 207679.5781 1.0000
0.5940 214389.9688 1.0000
0.6000 211753.4844 1.0000
0.6060 203300.3281 1.0000
0.6120 201386.2656 1.0000
0.6180 198086.9219 1.0000
0.6240 190237.0313 1.0000
0.6300 178834.5781 1.0000
0.6360 172973.2188 1.0000
0.6420 163142.2344 1.0000
0.6480 150145.9688 1.0000
0.6540 134967.5156 1.0000
0.6600 126410.0938 1.0000
0.6660 112184.9609 1.0000
0.6720 102927.4453 1.0000
0.6780 88746.9922 1.0000
0.6840 75773.0703 1.0000
0.6900 68749.8750 1.0000
0.6960 57571.0117 1.0000
0.7020 52287.3320 1.0000
0.7080 45621.3320 1.0000
0.7140 40405.5000 1.0000
0.7200 35469.5000 1.0000
0.7260 31527.1660 1.0000
0.7320 28046.3340 1.0000
0.7380 25072.6660 1.0000
0.7440 22565.1660 1.0000
0.7500 20456.8340 1.0000
0.7560 18516.5000 1.0000
0.7620 16860.0000 1.0000
0.7680 15186.5000 1.0000
0.7740 13626.5000 1.0000
0.7800 12974.0000 1.0000
0.7860 11713.8330 1.0000
0.7920 10661.8330 1.0000
0.7980 9889.0000 1.0000
0.8040 9284.5000 1.0000
0.8100 8455.1670 1.0000
0.8160 8196.3330 1.0000
0.8220 7552.0000 1.0000
0.8280 6806.3335 1.0000
0.8340 6498.8335 1.0000
0.8400 6056.3335 1.0000
0.8460 5650.0000 1.0000
0.8520 5261.5000 1.0000
0.8580 5010.3335 1.0000
0.8640 4790.8335 1.0000
0.8700 4431.5000 1.0000
0.8760 4163.3335 1.0000
0.8820 3902.3333 1.0000
0.8880 3829.1667 1.0000
0.8940 3643.5000 1.0000
0.9000 3380.8333 1.0000
0.9060 3242.1667 1.0000
0.9120 3074.6667 1.0000
0.9180 3003.8333 1.0000
0.9240 2799.5000 1.0000
0.9300 2654.1667 1.0000
0.9360 2590.0000 1.0000
0.9420 2420.0000 1.0000
0.9480 2373.5000 1.0000
0.9540 2302.6667 1.0000
0.9600 2154.8333 1.0000
0.9660 2141.3333 1.0000
0.9720 2093.5000 1.0000
0.9780 2048.1667 1.0000
0.9840 1793.0000 1.0000
0.9900 1784.1666 1.0000
0.9960 1757.6666 1.0000
1.0020 1742.6666 1.0000
1.0080 1655.6666 1.0000
1.0140 1667.6666 1.0000
1.0200 1496.8334 1.0000
1.0260 1510.0000 1.0000
1.0320 1488.6666 1.0000
1.0380 1468.0000 1.0000
1.0440 1330.8334 1.0000
1.0500 1290.3334 1.0000
1.0560 1318.6666 1.0000
1.0620 1284.8334 1.0000
1.0680 1242.5000 1.0000
1.0740 1198.1666 1.0000
1.0800 1182.0000 1.0000
1.0860 1114.1666 1.0000
1.0920 1050.1666 1.0000
1.0980 1087.1666 1.0000
1.1040 1091.5000 1.0000
1.1100 1006.0000 1.0000
1.1160 1041.5000 1.0000
1.1220 1020.1667 1.0000
1.1280 898.3333 1.0000
1.1340 917.8333 1.0000
1.1400 921.1667 1.0000
1.1460 868.5000 1.0000
1.1520 891.6667 1.0000
1.1580 860.3333 1.0000
1.1640 776.1667 1.0000
1.1700 800.6667 1.0000
1.1760 795.5000 1.0000
1.1820 751.3333 1.0000
1.1880 790.3333 1.0000
1.1940 740.3333 1.0000
1.2000 770.5000 1.0000
1.2060 718.5000 1.0000
1.2120 696.8333 1.0000
1.2180 668.6667 1.0000
1.2240 666.3333 1.0000
1.2300 626.5000 1.0000
1.2360 628.1667 1.0000
1.2420 688.6667 1.0000
1.2480 605.3333 1.0000
1.2540 592.0000 1.0000
1.2600 566.3333 1.0000
1.2660 566.3333 1.0000
1.2720 555.8333 1.0000
1.2780 545.5000 1.0000
1.2840 537.5000 1.0000
1.2900 496.6667 1.0000
1.2960 497.0000 1.0000
1.3020 509.6667 1.0000
1.3080 490.0000 1.0000
1.3140 520.3333 1.0000
1.3200 479.3333 1.0000
1.3260 496.0000 1.0000
1.3320 473.3333 1.0000
1.3380 484.0000 1.0000
1.3440 451.6667 1.0000
1.3500 427.8333 1.0000
1.3560 414.3333 1.0000
1.3620 408.6667 1.0000
1.3680 438.1667 1.0000
1.3740 404.0000 1.0000
1.3800 404.8333 1.0000
1.3860 368.1667 1.0000
1.3920 387.0000 1.0000
1.3980 391.0000 1.0000
1.4040 390.1667 1.0000
1.4100 367.3333 1.0000
1.4160 363.3333 1.0000
1.4220 368.8333 1.0000
1.4280 366.3333 1.0000
1.4340 368.3333 1.0000
1.4400 350.0000 1.0000
1.4460 378.5000 1.0000
1.4520 335.6667 1.0000
1.4580 321.0000 1.0000
1.4640 331.8333 1.0000
1.4700 354.6667 1.0000
1.4760 348.5000 1.0000
1.4820 301.3333 1.0000
1.4880 319.8333 1.0000
1.4940 311.1667 1.0000
1.5000 313.5000 1.0000
1.5060 315.1667 1.0000
1.5120 276.1667 1.0000
1.5180 280.6667 1.0000
1.5240 282.6667 1.0000
1.5300 274.6667 1.0000
1.5360 282.5000 1.0000
1.5420 288.3333 1.0000
1.5480 288.5000 1.0000
1.5540 263.6667 1.0000
1.5600 275.0000 1.0000
1.5660 256.6667 1.0000
1.5720 216.3333 1.0000
1.5780 246.8333 1.0000
1.5840 245.6667 1.0000
1.5900 254.0000 1.0000
1.5960 226.6667 1.0000
1.6020 266.6667 1.0000
1.6080 223.5000 1.0000
1.6140 230.1667 1.0000
1.6200 225.6667 1.0000
1.6260 279.8333 1.0000
1.6320 226.6667 1.0000
1.6380 239.0000 1.0000
1.6440 200.8333 1.0000
1.6500 227.1667 1.0000
1.6560 209.8333 1.0000
1.6620 212.6667 1.0000
1.6680 194.0000 1.0000
1.6740 206.8333 1.0000
1.6800 218.3333 1.0000
1.6860 192.3333 1.0000
1.6920 212.3333 1.0000
1.6980 191.3333 1.0000
1.7040 209.0000 1.0000
1.7100 178.0000 1.0000
1.7160 189.8333 1.0000
1.7220 180.0000 1.0000
1.7280 177.6667 1.0000
1.7340 179.3333 1.0000
1.7400 192.8333 1.0000
1.7460 183.3333 1.0000
1.7520 163.8333 1.0000
1.7580 147.3333 1.0000
1.7640 164.6667 1.0000
1.7700 167.3333 1.0000
1.7760 143.1667 1.0000
1.7820 171.5000 1.0000
1.7880 162.3333 1.0000
1.7940 174.5000 1.0000
1.8000 171.5000 1.0000
1.8060 151.1667 1.0000
1.8120 144.1667 1.0000
1.8180 149.5000 1.0000
1.8240 155.3333 1.0000
1.8300 150.1667 1.0000
1.8360 140.6667 1.0000
1.8420 139.6667 1.0000
1.8480 143.1667 1.0000
1.8540 125.5000 1.0000
1.8600 141.1667 1.0000
1.8660 142.8333 1.0000
1.8720 118.3333 1.0000
1.8780 134.6667 1.0000
1.8840 110.5000 1.0000
1.8900 115.8333 1.0000
1.8960 139.5000 1.0000
1.9020 138.0000 1.0000
1.9080 146.8333 1.0000
1.9140 118.6667 1.0000
1.9200 133.5000 1.0000
1.9260 115.5000 1.0000
1.9320 121.1667 1.0000
1.9380 130.0000 1.0000
1.9440 131.6667 1.0000
1.9500 131.3333 1.0000
1.9560 104.0000 1.0000
1.9620 115.3333 1.0000
1.9680 106.6667 1.0000
1.9740 113.6667 1.0000
1.9800 121.6667 1.0000
1.9860 102.6667 1.0000
1.9920 104.1667 1.0000
1.9980 115.0000 1.0000
2.0040 84.1667 1.0000
2.0100 101.6667 1.0000
2.0160 107.1667 1.0000
2.0220 101.5000 1.0000
2.0280 102.0000 1.0000
2.0340 103.8333 1.0000
2.0400 95.3333 1.0000
2.0460 101.3333 1.0000
2.0520 105.3333 1.0000
2.0580 101.3333 1.0000
2.0640 115.6667 1.0000
2.0700 92.8333 1.0000
2.0760 108.0000 1.0000
2.0820 100.0000 1.0000
2.0880 89.1667 1.0000
2.0940 78.3333 1.0000
2.1000 82.0000 1.0000
2.1060 91.8333 1.0000
2.1120 78.8333 1.0000
2.1180 85.3333 1.0000
2.1240 113.6667 1.0000
2.1300 77.8333 1.0000
2.1360 77.1667 1.0000
2.1420 93.8333 1.0000
2.1480 68.0000 1.0000
2.1540 74.3333 1.0000
2.1600 71.8333 1.0000
2.1660 72.8333 1.0000
2.1720 104.3333 1.0000
2.1780 84.1667 1.0000
2.1840 67.5000 1.0000
2.1900 82.5000 1.0000
2.1960 73.1667 1.0000
2.2020 87.0000 1.0000
2.2080 61.8333 1.0000
2.2140 84.0000 1.0000
2.2200 87.0000 1.0000
2.2260 75.3333 1.0000
2.2320 84.0000 1.0000
2.2380 73.0000 1.0000
2.2440 67.8333 1.0000
2.2500 68.3333 1.0000
2.2560 60.8333 1.0000
2.2620 76.1667 1.0000
2.2680 74.3333 1.0000
2.2740 67.0000 1.0000
2.2800 63.6667 1.0000
2.2860 79.0000 1.0000
2.2920 74.8333 1.0000
2.2980 71.3333 1.0000
2.3040 70.0000 1.0000
2.3100 61.0000 1.0000
2.3160 72.8333 1.0000
2.3220 75.8333 1.0000
2.3280 72.8333 1.0000
2.3340 56.1667 1.0000
2.3400 56.0000 1.0000
2.3460 64.8333 1.0000
2.3520 47.1667 1.0000
2.3580 63.8333 1.0000
2.3640 65.3333 1.0000
2.3700 59.1667 1.0000
2.3760 46.8333 1.0000
2.3820 65.0000 1.0000
2.3880 60.6667 1.0000
2.3940 48.1667 1.0000
2.4000 54.6667 1.0000
2.4060 54.0000 1.0000
2.4120 44.0000 1.0000
2.4180 49.1667 1.0000
2.4240 43.1667 1.0000
2.4300 67.0000 1.0000
2.4360 54.3333 1.0000
2.4420 49.1667 1.0000
2.4480 57.5000 1.0000
2.4540 39.3333 1.0000
2.4600 55.8333 1.0000
2.4660 47.6667 1.0000
2.4720 37.1667 1.0000
2.4780 53.0000 1.0000
2.4840 48.6667 1.0000
2.4900 44.5000 1.0000
2.4960 45.3333 1.0000
2.5020 51.6667 1.0000
2.5080 45.1667 1.0000
2.5140 52.3333 1.0000
2.5200 45.0000 1.0000
2.5260 48.1667 1.0000
2.5320 48.5000 1.0000
2.5380 40.1667 1.0000
2.5440 42.5000 1.0000
2.5500 39.0000 1.0000
2.5560 58.5000 1.0000
2.5620 58.6667 1.0000
2.5680 37.3333 1.0000
2.5740 49.5000 1.0000
2.5800 45.0000 1.0000
2.5860 75.5000 1.0000
2.5920 36.8333 1.0000
2.5980 44.6667 1.0000
2.6040 47.5000 1.0000
2.6100 39.5000 1.0000
2.6160 48.1667 1.0000
2.6220 39.0000 1.0000
2.6280 36.5000 1.0000
2.6340 33.8333 1.0000
2.6400 35.6667 1.0000
2.6460 61.1667 1.0000
2.6520 44.1667 1.0000
2.6580 37.1667 1.0000
2.6640 37.3333 1.0000
2.6700 35.6667 1.0000
2.6760 39.8333 1.0000
2.6820 45.8333 1.0000
2.6880 33.1667 1.0000
2.6940 40.0000 1.0000
2.7000 49.6667 1.0000
2.7060 44.8333 1.0000
2.7120 39.3333 1.0000
2.7180 42.8333 1.0000
2.7240 39.0000 1.0000
2.7300 38.0000 1.0000
2.7360 48.8333 1.0000
2.7420 38.1667 1.0000
2.7480 36.8333 1.0000
2.7540 41.3333 1.0000
2.7600 47.0000 1.0000
2.7660 30.8333 1.0000
2.7720 35.1667 1.0000
2.7780 37.1667 1.0000
2.7840 35.0000 1.0000
2.7900 35.5000 1.0000
2.7960 30.5000 1.0000
2.8020 37.6667 1.0000
2.8080 25.8333 1.0000
2.8140 30.5000 1.0000
2.8200 31.6667 1.0000
2.8260 31.3333 1.0000
2.8320 28.0000 1.0000
2.8380 40.8333 1.0000
2.8440 39.3333 1.0000
2.8500 35.5000 1.0000
2.8560 39.6667 1.0000
2.8620 21.1667 1.0000
2.8680 37.5000 1.0000
2.8740 32.0000 1.0000
2.8800 29.1667 1.0000
2.8860 30.1667 1.0000
2.8920 25.0000 1.0000
2.8980 27.1667 1.0000
2.9040 20.0000 1.0000
2.9100 25.3333 1.0000
2.9160 32.0000 1.0000
2.9220 32.3333 1.0000
2.9280 18.5000 1.0000
2.9340 25.0000 1.0000
2.9400 26.0000 1.0000
2.9460 22.6667 1.0000
2.9520 25.0000 1.0000
2.9580 30.1667 1.0000
2.9640 31.6667 1.0000
2.9700 21.6667 1.0000
2.9760 22.3333 1.0000
2.9820 19.0000 1.0000
2.9880 23.1667 1.0000
2.9940 15.1667 1.0000
3.0000 27.8333 1.0000
3.0060 24.1667 1.0000
3.0120 19.5000 1.0000
3.0180 31.1667 1.0000
3.0240 24.1667 1.0000
3.0300 15.8333 1.0000
3.0360 30.6667 1.0000
3.0420 18.6667 1.0000
3.0480 21.3333 1.0000
3.0540 21.8333 1.0000
3.0600 17.0000 1.0000
3.0660 25.5000 1.0000
3.0720 33.8333 1.0000
3.0780 18.8333 1.0000
3.0840 18.1667 1.0000
3.0900 25.8333 1.0000
3.0960 22.3333 1.0000
3.1020 18.8333 1.0000
3.1080 19.8333 1.0000
3.1140 25.6667 1.0000
3.1200 26.5000 1.0000
3.1260 20.3333 1.0000
3.1320 24.0000 1.0000
3.1380 17.5000 1.0000
3.1440 20.1667 1.0000
3.1500 23.5000 1.0000
3.1560 22.0000 1.0000
3.1620 26.3333 1.0000
3.1680 24.0000 1.0000
3.1740 10.0000 1.0000
3.1800 23.3333 1.0000
3.1860 18.8333 1.0000
3.1920 19.8333 1.0000
3.1980 14.6667 1.0000
3.2040 13.5000 1.0000
3.2100 20.5000 1.0000
3.2160 25.1667 1.0000
3.2220 20.6667 1.0000
3.2280 12.6667 1.0000
3.2340 14.5000 1.0000
3.2400 13.5000 1.0000
3.2460 19.1667 1.0000
3.2520 22.3333 1.0000
3.2580 11.6667 1.0000
3.2640 21.6667 1.0000
3.2700 15.5000 1.0000
3.2760 16.1667 1.0000
3.2820 16.6667 1.0000
3.2880 18.3333 1.0000
3.2940 15.1667 1.0000
3.3000 19.1667 1.0000
3.3060 17.5000 1.0000
3.3120 16.0000 1.0000
3.3180 14.3333 1.0000
3.3240 20.0000 1.0000
3.3300 21.6667 1.0000
3.3360 15.6667 1.0000
3.3420 13.6667 1.0000
3.3480 19.3333 1.0000
3.3540 19.8333 1.0000
3.3600 17.6667 1.0000
3.3660 8.6667 1.0000
3.3720 20.0000 1.0000
3.3780 11.5000 1.0000
3.3840 16.0000 1.0000
3.3900 11.8333 1.0000
3.3960 16.6667 1.0000
3.4020 20.5000 1.0000
3.4080 17.3333 1.0000
3.4140 24.3333 1.0000
3.4200 15.8333 1.0000
3.4260 8.5000 1.0000
3.4320 8.8333 1.0000
3.4380 13.3333 1.0000
3.4440 17.1667 1.0000
3.4500 18.3333 1.0000
3.4560 16.0000 1.0000
3.4620 8.5000 1.0000
3.4680 10.3333 1.0000
3.4740 20.5000 1.0000
3.4800 16.5000 1.0000
3.4860 20.5000 1.0000
3.4920 9.8333 1.0000
3.4980 19.6667 1.0000
3.5040 14.1667 1.0000
3.5100 12.6667 1.0000
3.5160 13.6667 1.0000
3.5220 17.8333 1.0000
3.5280 13.1667 1.0000
3.5340 21.0000 1.0000
3.5400 10.5000 1.0000
3.5460 7.1667 1.0000
3.5520 9.6667 1.0000
3.5580 16.1667 1.0000
3.5640 11.0000 1.0000
3.5700 17.1667 1.0000
3.5760 13.1667 1.0000
3.5820 17.0000 1.0000
3.5880 17.3333 1.0000
3.5940 13.6667 1.0000
3.6000 14.0000 1.0000
3.6060 9.1667 1.0000
3.6120 12.0000 1.0000
3.6180 15.3333 1.0000
3.6240 11.1667 1.0000
3.6300 16.6667 1.0000
3.6360 22.5000 1.0000
3.6420 16.5000 1.0000
3.6480 14.5000 1.0000
3.6540 15.6667 1.0000
3.6600 5.3333 1.0000
3.6660 14.8333 1.0000
3.6720 9.3333 1.0000
3.6780 13.8333 1.0000
3.6840 12.6667 1.0000
3.6900 8.6667 1.0000
3.6960 10.6667 1.0000
3.7020 17.8333 1.0000
3.7080 7.0000 1.0000
3.7140 6.8333 1.0000
3.7200 10.6667 1.0000
3.7260 11.3333 1.0000
3.7320 12.6667 1.0000
3.7380 13.0000 1.0000
3.7440 15.8333 1.0000
3.7500 14.5000 1.0000
3.7560 14.3333 1.0000
3.7620 11.8333 1.0000
3.7680 17.5000 1.0000
3.7740 15.5000 1.0000
3.7800 13.3333 1.0000
3.7860 7.5000 1.0000
3.7920 11.3333 1.0000
3.7980 9.8333 1.0000
3.8040 10.1667 1.0000
3.8100 10.3333 1.0000
3.8160 7.5000 1.0000
3.8220 14.1667 1.0000
3.8280 11.6667 1.0000
3.8340 14.1667 1.0000
3.8400 16.8333 1.0000
3.8460 9.0000 1.0000
3.8520 11.3333 1.0000
3.8580 12.8333 1.0000
3.8640 11.0000 1.0000
3.8700 12.1667 1.0000
3.8760 8.6667 1.0000
3.8820 9.8333 1.0000
3.8880 9.5000 1.0000
3.8940 4.6667 1.0000
3.9000 13.1667 1.0000
3.9060 14.1667 1.0000
3.9120 9.8333 1.0000
3.9180 10.0000 1.0000
3.9240 6.0000 1.0000
3.9300 6.5000 1.0000
3.9360 3.5000 1.0000
3.9420 7.6667 1.0000
3.9480 6.8333 1.0000
3.9540 4.6667 1.0000
3.9600 10.3333 1.0000
3.9660 8.6667 1.0000
3.9720 9.6667 1.0000
3.9780 14.6667 1.0000
3.9840 4.8333 1.0000
3.9900 8.6667 1.0000
3.9960 10.6667 1.0000
4.0020 2.5000 1.0000
4.0080 8.6667 1.0000
4.0140 7.1667 1.0000
4.0200 13.0000 1.0000
4.0260 7.6667 1.0000
4.0320 6.6667 1.0000
4.0380 11.1667 1.0000
4.0440 10.8333 1.0000
4.0500 14.6667 1.0000
4.0560 9.8333 1.0000
4.0620 7.6667 1.0000
4.0680 8.6667 1.0000
4.0740 6.5000 1.0000
4.0800 6.8333 1.0000
4.0860 6.8333 1.0000
4.0920 8.5000 1.0000
4.0980 6.6667 1.0000
4.1040 8.8333 1.0000
4.1100 8.5000 1.0000
4.1160 5.1667 1.0000
4.1220 3.8333 1.0000
4.1280 10.5000 1.0000
4.1340 2.5000 1.0000
4.1400 11.6667 1.0000
4.1460 10.1667 1.0000
4.1520 1.0000 1.0000
4.1580 10.6667 1.0000
4.1640 9.3333 1.0000
4.1700 12.1667 1.0000
4.1760 2.8333 1.0000
4.1820 8.8333 1.0000
4.1880 8.0000 1.0000
4.1940 5.8333 1.0000
4.2000 3.8333 1.0000
4.2060 6.8333 1.0000
4.2120 8.5000 1.0000
4.2180 10.0000 1.0000
4.2240 7.5000 1.0000
4.2300 7.1667 1.0000
4.2360 4.6667 1.0000
4.2420 6.5000 1.0000
4.2480 23.1667 1.0000
4.2540 2.5000 1.0000
4.2600 7.8333 1.0000
4.2660 10.6667 1.0000
4.2720 9.1667 1.0000
4.2780 12.1667 1.0000
4.2840 3.1667 1.0000
4.2900 5.6667 1.0000
4.2960 5.8333 1.0000
4.3020 7.0000 1.0000
4.3080 8.5000 1.0000
4.3140 6.8333 1.0000
4.3200 6.8333 1.0000
4.3260 3.5000 1.0000
4.3320 9.1667 1.0000
4.3380 3.5000 1.0000
4.3440 6.3333 1.0000
4.3500 7.5000 1.0000
4.3560 8.5000 1.0000
4.3620 5.0000 1.0000
4.3680 5.5000 1.0000
4.3740 2.5000 1.0000
4.3800 10.0000 1.0000
4.3860 2.3333 1.0000
4.3920 5.3333 1.0000
4.3980 6.1667 1.0000
4.4040 5.3333 1.0000
4.4100 2.8333 1.0000
4.4160 6.1667 1.0000
4.4220 3.8333 1.0000
4.4280 5.5000 1.0000
4.4340 7.0000 1.0000
4.4400 2.3333 1.0000
4.4460 6.3333 1.0000
4.4520 9.1667 1.0000
4.4580 2.0000 1.0000
4.4640 5.3333 1.0000
4.4700 8.5000 1.0000
4.4760 8.5000 1.0000
4.4820 7.5000 1.0000
4.4880 3.5000 1.0000
4.4940 4.1667 1.0000
4.5000 5.6667 1.0000
4.5060 4.8333 1.0000
4.5120 6.8333 1.0000
4.5180 5.3333 1.0000
4.5240 1.5000 1.0000
4.5300 3.8333 1.0000
4.5360 3.3333 1.0000
4.5420 5.1667 1.0000
4.5480 2.6667 1.0000
4.5540 5.1667 1.0000
4.5600 6.0000 1.0000
4.5660 7.6667 1.0000
4.5720 6.8333 1.0000
4.5780 2.3333 1.0000
4.5840 2.5000 1.0000
4.5900 5.5000 1.0000
4.5960 6.3333 1.0000
4.6020 2.6667 1.0000
4.6080 5.1667 1.0000
4.6140 4.8333 1.0000
4.6200 3.6667 1.0000
4.6260 1.8333 1.0000
4.6320 4.8333 1.0000
4.6380 4.6667 1.0000
4.6440 2.1667 1.0000
4.6500 5.5000 1.0000
4.6560 3.6667 1.0000
4.6620 3.0000 1.0000
4.6680 8.1667 1.0000
4.6740 6.5000 1.0000
4.6800 1.0000 1.0000
4.6860 7.5000 1.0000
4.6920 4.3333 1.0000
4.6980 3.5000 1.0000
4.7040 1.5000 1.0000
4.7100 4.3333 1.0000
4.7160 4.6667 1.0000
4.7220 6.0000 1.0000
4.7280 0.0000 1.0000
4.7340 2.1667 1.0000
4.7400 0.3333 1.0000
4.7460 2.6667 1.0000
4.7520 6.5000 1.0000
4.7580 4.0000 1.0000
4.7640 3.1667 1.0000
4.7700 3.3333 1.0000
4.7760 0.0000 1.0000
4.7820 4.6667 1.0000
4.7880 5.3333 1.0000
4.7940 5.0000 1.0000
4.8000 4.6667 1.0000
4.8060 7.3333 1.0000
4.8120 6.3333 1.0000
4.8180 2.5000 1.0000
4.8240 6.1667 1.0000
4.8300 3.5000 1.0000
4.8360 7.3333 1.0000
4.8420 3.0000 1.0000
4.8480 5.3333 1.0000
4.8540 0.3333 1.0000
4.8600 0.0000 1.0000
4.8660 1.8333 1.0000
4.8720 3.5000 1.0000
4.8780 4.5000 1.0000
4.8840 0.1667 1.0000
4.8900 2.1667 1.0000
4.8960 0.5000 1.0000
4.9020 3.5000 1.0000
4.9080 5.5000 1.0000
4.9140 3.0000 1.0000
4.9200 4.5000 1.0000
4.9260 7.3333 1.0000
4.9320 4.3333 1.0000
4.9380 0.1667 1.0000
4.9440 6.0000 1.0000
4.9500 1.1667 1.0000
4.9560 3.5000 1.0000
4.9620 6.5000 1.0000
4.9680 3.5000 1.0000
4.9740 3.5000 1.0000
4.9800 4.6667 1.0000
4.9860 1.1667 1.0000
4.9920 3.3333 1.0000
4.9980 0.0000 1.0000
5.0040 0.0000 1.0000
5.0100 1.3333 1.0000
5.0160 4.1667 1.0000
5.0220 6.1667 1.0000
5.0280 3.6667 1.0000
5.0340 0.5000 1.0000
5.0400 3.1667 1.0000
5.0460 0.0000 1.0000
5.0520 3.1667 1.0000
5.0580 5.5000 1.0000
5.0640 2.1667 1.0000
5.0700 7.1667 1.0000
5.0760 5.6667 1.0000
5.0820 7.5000 1.0000
5.0880 6.0000 1.0000
5.0940 2.5000 1.0000
5.1000 0.5000 1.0000
5.1060 4.3333 1.0000
5.1120 0.3333 1.0000
5.1180 4.5000 1.0000
5.1240 3.3333 1.0000
5.1300 2.1667 1.0000
5.1360 0.0000 1.0000
5.1420 5.3333 1.0000
5.1480 3.0000 1.0000
5.1540 0.1667 1.0000
5.1600 0.0000 1.0000
5.1660 3.8333 1.0000
5.1720 3.3333 1.0000
5.1780 4.1667 1.0000
5.1840 0.0000 1.0000
5.1900 4.5000 1.0000
5.1960 1.1667 1.0000
5.2020 3.0000 1.0000
5.2080 3.1667 1.0000
5.2140 0.0000 1.0000
5.2200 0.1667 1.0000
5.2260 5.5000 1.0000
5.2320 2.1667 1.0000
5.2380 8.8333 1.0000
5.2440 3.1667 1.0000
5.2500 2.1667 1.0000
5.2560 2.1667 1.0000
5.2620 3.3333 1.0000
5.2680 2.5000 1.0000
5.2740 1.5000 1.0000
5.2800 0.1667 1.0000
5.2860 7.3333 1.0000
5.2920 2.1667 1.0000
5.2980 0.0000 1.0000
5.3040 3.0000 1.0000
5.3100 3.5000 1.0000
5.3160 2.6667 1.0000
5.3220 6.5000 1.0000
5.3280 0.0000 1.0000
5.3340 2.1667 1.0000
5.3400 0.1667 1.0000
5.3460 0.1667 1.0000
5.3520 6.0000 1.0000
5.3580 7.1667 1.0000
5.3640 4.1667 1.0000
5.3700 1.3333 1.0000
5.3760 0.0000 1.0000
5.3820 4.3333 1.0000
5.3880 5.5000 1.0000
5.3940 0.1667 1.0000
5.4000 4.1667 1.0000
5.4060 1.1667 1.0000
5.4120 2.1667 1.0000
5.4180 2.0000 1.0000
5.4240 6.1667 1.0000
5.4300 3.1667 1.0000
5.4360 2.3333 1.0000
5.4420 0.6667 1.0000
5.4480 2.1667 1.0000
5.4540 2.3333 1.0000
5.4600 2.5000 1.0000
5.4660 0.5000 1.0000
5.4720 0.0000 1.0000
5.4780 0.1667 1.0000
5.4840 4.3333 1.0000
5.4900 2.3333 1.0000
5.4960 0.0000 1.0000
5.5020 3.3333 1.0000
5.5080 0.3333 1.0000
5.5140 3.5000 1.0000
5.5200 5.1667 1.0000
5.5260 4.6667 1.0000
5.5320 2.3333 1.0000
5.5380 3.0000 1.0000
5.5440 0.0000 1.0000
5.5500 6.8333 1.0000
5.5560 0.0000 1.0000
5.5620 0.0000 1.0000
5.5680 0.0000 1.0000
5.5740 0.3333 1.0000
5.5800 3.3333 1.0000
5.5860 3.1667 1.0000
5.5920 2.1667 1.0000
5.5980 4.1667 1.0000
5.6040 0.1667 1.0000
5.6100 3.1667 1.0000
5.6160 2.1667 1.0000
5.6220 2.1667 1.0000
5.6280 0.0000 1.0000
5.6340 3.1667 1.0000
5.6400 0.3333 1.0000
5.6460 0.0000 1.0000
5.6520 3.5000 1.0000
5.6580 2.3333 1.0000
5.6640 4.1667 1.0000
5.6700 0.0000 1.0000
5.6760 2.1667 1.0000
5.6820 8.0000 1.0000
5.6880 0.0000 1.0000
5.6940 3.3333 1.0000
5.7000 4.1667 1.0000
5.7060 0.0000 1.0000
5.7120 0.0000 1.0000
5.7180 0.0000 1.0000
5.7240 4.0000 1.0000
5.7300 0.0000 1.0000
5.7360 0.1667 1.0000
5.7420 0.3333 1.0000
5.7480 1.3333 1.0000
5.7540 4.1667 1.0000
5.7600 2.0000 1.0000
5.7660 5.3333 1.0000
5.7720 0.0000 1.0000
5.7780 7.1667 1.0000
5.7840 2.1667 1.0000
5.7900 5.0000 1.0000
5.7960 4.5000 1.0000
5.8020 3.1667 1.0000
5.8080 3.0000 1.0000
5.8140 2.3333 1.0000
5.8200 0.0000 1.0000
5.8260 4.1667 1.0000
5.8320 3.0000 1.0000
5.8380 4.3333 1.0000
5.8440 2.5000 1.0000
5.8500 5.1667 1.0000
5.8560 0.3333 1.0000
5.8620 3.0000 1.0000
5.8680 2.0000 1.0000
5.8740 4.5000 1.0000
5.8800 4.0000 1.0000
5.8860 0.0000 1.0000
5.8920 0.0000 1.0000
5.8980 2.5000 1.0000
5.9040 0.0000 1.0000
5.9100 3.0000 1.0000
5.9160 2.3333 1.0000
5.9220 4.1667 1.0000
5.9280 2.0000 1.0000
5.9340 0.1667 1.0000
5.9400 1.1667 1.0000
5.9460 0.0000 1.0000
5.9520 2.1667 1.0000
5.9580 6.0000 1.0000
5.9640 0.0000 1.0000
5.9700 0.0000 1.0000
5.9760 2.1667 1.0000
5.9820 3.3333 1.0000
5.9880 3.0000 1.0000
5.9940 0.0000 1.0000
6.0000 1.3333 1.0000
*RAS_INT_END
*RAS_DATA_END