File: xrr_temp/CWOI5_reflectivity.ras
*RAS_DATA_START
*RAS_HEADER_START
*DISP_FMT_X "%.4f"
*DISP_FMT_Y "%.0f"
*DISP_FULLSCALE "2831687.2281189766"
*DISP_LINE_COLOR "255.0000000000"
*DISP_LINE_STYLE "0.0000000000"
*DISP_LINE_WIDTH "0.2500000000"
*DISP_NOTE "Collected Data-31"
*DISP_OFFSET_Y "0.0000000000"
*DISP_PEAKSEARCH_UNIT_Y "cps"
*DISP_RANGE_BOTTOM "0.0593494474"
*DISP_RANGE_LEFT "-1.0242122597"
*DISP_RANGE_LOGCUTOFF "0.0100000000"
*DISP_RANGE_RIGHT "7.0461871694"
*DISP_RANGE_TOP "2831687.2281189766"
*DISP_SCALE_MODE_Y "2.0000000000"
*DISP_TAB_NAME "2-Theta/Omega"
*DISP_TITLE_Y "Intensity"
*DISP_UNIT_Y "cps"
*DISP_WINDOW_NAME "MSG_MACROENGINE"
*FILE_COMMENT " "
*FILE_MD5 ""
*FILE_MEMO " "
*FILE_OPERATOR "Administrator"
*FILE_PART_ID "MEAS_KHP2_00055"
*FILE_SAMPLE "CWOI5"
*FILE_TYPE "RAS_RAW"
*FILE_USERGROUP "System Manager"
*FILE_VERSION "1.0000000000"
*HW_ATTACHMENT_ID "ATT0025"
*HW_ATTACHMENT_NAME "標準|Standard"
*HW_COUNTER_ID-0 "CUT0025"
*HW_COUNTER_ID-1 "CUT0020"
*HW_COUNTER_ID-2 "CUT0020"
*HW_COUNTER_ID-3 "CSL0021"
*HW_COUNTER_ID-4 "CMC0021"
*HW_COUNTER_NAME-0 "D/teX Ultra|D/teX Ultra"
*HW_COUNTER_NAME-1 "None|None"
*HW_COUNTER_NAME-2 "None|None"
*HW_COUNTER_NAME-3 "BBM|BBM"
*HW_COUNTER_NAME-4 "検出器モノクロメータ|Detector monochromator"
*HW_COUNTER_SELECT_NAME "D/teX Ultra|D/teX Ultra"
*HW_GONIOMETER_ID "GON0023"
*HW_GONIOMETER_NAME "SmartLab|SmartLab"
*HW_GONIOMETER_RADIUS-0 "90.0"
*HW_GONIOMETER_RADIUS-1 "114.0"
*HW_GONIOMETER_RADIUS-2 "190.0"
*HW_GONIOMETER_RADIUS-3 "300.0"
*HW_GONIOMETER_RADIUS-4 "187.0"
*HW_GONIOMETER_RADIUS-5 "300.0"
*HW_GONIOMETER_RADIUS-6 "113.0"
*HW_GONIOMETER_RADIUS-7 "331.0"
*HW_I_OPT_ID-0 "CBO0021"
*HW_I_OPT_ID-1 "ICR0021"
*HW_I_OPT_ID-2 "ISL0021"
*HW_I_OPT_ID-3 "ISO0021"
*HW_I_OPT_ID-4 "IAD0021"
*HW_I_OPT_ID-5 "IPR0001"
*HW_I_OPT_NAME-0 "CBOユニット|CBO unit"
*HW_I_OPT_NAME-1 "標準入射光学ユニット|Standard incident optical unit"
*HW_I_OPT_NAME-2 "標準入射スリットボックス|Standard incident slit box"
*HW_I_OPT_NAME-3 "入射平行スリット|Incident parallel slit"
*HW_I_OPT_NAME-4 "長手制限スリット|Length limiting slit"
*HW_I_OPT_NAME-5 "None|None"
*HW_R_ATTENUATER_AUTOMODE "1"
*HW_R_OPT_ID-0 "RSS0021"
*HW_R_OPT_ID-1 "RCR0023"
*HW_R_OPT_ID-2 "RSO0021"
*HW_R_OPT_ID-3 "RRS0021"
*HW_R_OPT_ID-4 "ATN0021"
*HW_R_OPT_ID-5 "RFL0021"
*HW_R_OPT_ID-6 "RAD0021"
*HW_R_OPT_NAME-0 "標準受光スリットボックス1|Standard receiving slit box # 1"
*HW_R_OPT_NAME-1 "標準受光光学ユニット1|Standard receiving unit # 1"
*HW_R_OPT_NAME-2 "標準受光光学ユニット2|Standard receiving optical unit # 2"
*HW_R_OPT_NAME-3 "標準受光スリットボックス2|Standard receiving slit box # 2"
*HW_R_OPT_NAME-4 "標準アッテネータ|Standard Attenuator"
*HW_R_OPT_NAME-5 "Cu Kβ|Cu K-beta"
*HW_R_OPT_NAME-6 "調整用受光スリット|Alignment receiving slit"
*HW_SAMPLE_HOLDER_ID "SMP0021"
*HW_SAMPLE_HOLDER_NAME "χφZクレードル|Chi phi Z cradle"
*HW_XG_CURRENT_MAX "200"
*HW_XG_CURRENT_MIN "10"
*HW_XG_CURRENT_RESOLUTION "1"
*HW_XG_CURRENT_UNIT "mA"
*HW_XG_FOCUS "0.4mm x 8mm"
*HW_XG_FOCUS_TYPE "Normal"
*HW_XG_ID "1700"
*HW_XG_NAME "9kW 開放管(45kV 200mA ID:1700)|9kW Rotating anode(45kV 200mA ID:1700)"
*HW_XG_TARGET_ATOMIC_NUMBER "29.0000000000"
*HW_XG_TARGET_NAME "Cu"
*HW_XG_TYPE "Rota"
*HW_XG_VOLTAGE_MAX "45"
*HW_XG_VOLTAGE_MIN "20"
*HW_XG_VOLTAGE_RESOLUTION "1"
*HW_XG_VOLTAGE_UNIT "kV"
*HW_XG_WATT_MAX "9.00"
*HW_XG_WATT_UNIT "kW"
*HW_XG_WAVE_LENGTH_ALPHA1 "1.540593"
*HW_XG_WAVE_LENGTH_ALPHA2 "1.544414"
*HW_XG_WAVE_LENGTH_BETA "1.392250"
*MEAS_COND_AXIS_NAME-0 "Theta/2-Theta"
*MEAS_COND_AXIS_NAME-1 "2-Theta"
*MEAS_COND_AXIS_NAME-2 "Omega"
*MEAS_COND_AXIS_NAME-3 "Chi"
*MEAS_COND_AXIS_NAME-4 "Phi"
*MEAS_COND_AXIS_NAME-5 "Z"
*MEAS_COND_AXIS_NAME-6 "2-Theta/Omega"
*MEAS_COND_AXIS_NAME-7 "Theta_s"
*MEAS_COND_AXIS_NAME-8 "Theta_d"
*MEAS_COND_AXIS_NAME-9 "Ts"
*MEAS_COND_AXIS_NAME-10 "CBO selection slit"
*MEAS_COND_AXIS_NAME-11 "M"
*MEAS_COND_AXIS_NAME-12 "Incident parallel slit"
*MEAS_COND_AXIS_NAME-13 "Incident slit"
*MEAS_COND_AXIS_NAME-14 ""
*MEAS_COND_AXIS_NAME-15 "Zs"
*MEAS_COND_AXIS_NAME-16 "Incident optical device"
*MEAS_COND_AXIS_NAME-17 "Omega_m"
*MEAS_COND_AXIS_NAME-18 "Length limiting slit"
*MEAS_COND_AXIS_NAME-19 "Center slit"
*MEAS_COND_AXIS_NAME-20 "Filter"
*MEAS_COND_AXIS_NAME-21 "Receiving slit # 1"
*MEAS_COND_AXIS_NAME-22 "Receiving slit # 2"
*MEAS_COND_AXIS_NAME-23 "Receiving optical device"
*MEAS_COND_AXIS_NAME-24 "Receiving parallel slit"
*MEAS_COND_AXIS_NAME-25 "Alignment receiving slit"
*MEAS_COND_AXIS_NAME-26 ""
*MEAS_COND_AXIS_NAME-27 ""
*MEAS_COND_AXIS_NAME-28 "Zd"
*MEAS_COND_AXIS_NAME-29 "Attenuator"
*MEAS_COND_AXIS_NAME-30 "Diffracted beam monochromator"
*MEAS_COND_AXIS_NAME-31 "Monochromator slit"
*MEAS_COND_AXIS_NAME-32 ""
*MEAS_COND_AXIS_NAME-33 ""
*MEAS_COND_AXIS_NAME-34 "Primary beam"
*MEAS_COND_AXIS_NAME-35 "PHA"
*MEAS_COND_AXIS_NAME_INTERNAL-0 "TwoThetaTheta"
*MEAS_COND_AXIS_NAME_INTERNAL-1 "TwoTheta"
*MEAS_COND_AXIS_NAME_INTERNAL-2 "Omega"
*MEAS_COND_AXIS_NAME_INTERNAL-3 "Chi"
*MEAS_COND_AXIS_NAME_INTERNAL-4 "Phi"
*MEAS_COND_AXIS_NAME_INTERNAL-5 "Z"
*MEAS_COND_AXIS_NAME_INTERNAL-6 "TwoThetaOmega"
*MEAS_COND_AXIS_NAME_INTERNAL-7 "ThetaS"
*MEAS_COND_AXIS_NAME_INTERNAL-8 "ThetaD"
*MEAS_COND_AXIS_NAME_INTERNAL-9 "Ts"
*MEAS_COND_AXIS_NAME_INTERNAL-10 "CBO"
*MEAS_COND_AXIS_NAME_INTERNAL-11 "CBO-M"
*MEAS_COND_AXIS_NAME_INTERNAL-12 "IncidentSollerSlit"
*MEAS_COND_AXIS_NAME_INTERNAL-13 "IncidentSlitBox"
*MEAS_COND_AXIS_NAME_INTERNAL-14 "IncidentSlitBox-_Axis"
*MEAS_COND_AXIS_NAME_INTERNAL-15 "Zs"
*MEAS_COND_AXIS_NAME_INTERNAL-16 "IncidentMonochromator"
*MEAS_COND_AXIS_NAME_INTERNAL-17 "IncidentMonochromator-OmegaM"
*MEAS_COND_AXIS_NAME_INTERNAL-18 "IncidentAxdSlit"
*MEAS_COND_AXIS_NAME_INTERNAL-19 "CenterSlit"
*MEAS_COND_AXIS_NAME_INTERNAL-20 "Filter"
*MEAS_COND_AXIS_NAME_INTERNAL-21 "ReceivingSlitBox1"
*MEAS_COND_AXIS_NAME_INTERNAL-22 "ReceivingSlitBox2"
*MEAS_COND_AXIS_NAME_INTERNAL-23 "ReceivingOptics"
*MEAS_COND_AXIS_NAME_INTERNAL-24 "ReceivingSollerSlit"
*MEAS_COND_AXIS_NAME_INTERNAL-25 "ReceivingAxdSlit"
*MEAS_COND_AXIS_NAME_INTERNAL-26 "ReceivingSlitBox1-_Axis"
*MEAS_COND_AXIS_NAME_INTERNAL-27 "ReceivingSlitBox2-_Axis"
*MEAS_COND_AXIS_NAME_INTERNAL-28 "ReceivingSlitBox2-Zd"
*MEAS_COND_AXIS_NAME_INTERNAL-29 "Attenuator"
*MEAS_COND_AXIS_NAME_INTERNAL-30 "CounterMonochromator"
*MEAS_COND_AXIS_NAME_INTERNAL-31 "CounterSlit"
*MEAS_COND_AXIS_NAME_INTERNAL-32 "AlphaR"
*MEAS_COND_AXIS_NAME_INTERNAL-33 "BetaR"
*MEAS_COND_AXIS_NAME_INTERNAL-34 "IncidentPrimary"
*MEAS_COND_AXIS_NAME_INTERNAL-35 "PHA"
*MEAS_COND_AXIS_NAME_MAGICNO-0 "83951616.0000000000"
*MEAS_COND_AXIS_NAME_MAGICNO-1 "268632064.0000000000"
*MEAS_COND_AXIS_NAME_MAGICNO-2 "268500992.0000000000"
*MEAS_COND_AXIS_NAME_MAGICNO-3 "268500992.0000000000"
*MEAS_COND_AXIS_NAME_MAGICNO-4 "268500992.0000000000"
*MEAS_COND_AXIS_NAME_MAGICNO-5 "285278208.0000000000"
*MEAS_COND_AXIS_NAME_MAGICNO-6 "83951616.0000000000"
*MEAS_COND_AXIS_NAME_MAGICNO-7 "131072.0000000000"
*MEAS_COND_AXIS_NAME_MAGICNO-8 "131072.0000000000"
*MEAS_COND_AXIS_NAME_MAGICNO-9 "318898176.0000000000"
*MEAS_COND_AXIS_NAME_MAGICNO-10 "20971521.0000000000"
*MEAS_COND_AXIS_NAME_MAGICNO-11 "285343744.0000000000"
*MEAS_COND_AXIS_NAME_MAGICNO-12 "20971521.0000000000"
*MEAS_COND_AXIS_NAME_MAGICNO-13 "22020097.0000000000"
*MEAS_COND_AXIS_NAME_MAGICNO-14 "25165824.0000000000"
*MEAS_COND_AXIS_NAME_MAGICNO-15 "318898176.0000000000"
*MEAS_COND_AXIS_NAME_MAGICNO-16 "20971521.0000000000"
*MEAS_COND_AXIS_NAME_MAGICNO-17 "285343744.0000000000"
*MEAS_COND_AXIS_NAME_MAGICNO-18 "20971521.0000000000"
*MEAS_COND_AXIS_NAME_MAGICNO-19 "20971521.0000000000"
*MEAS_COND_AXIS_NAME_MAGICNO-20 "20971521.0000000000"
*MEAS_COND_AXIS_NAME_MAGICNO-21 "23068673.0000000000"
*MEAS_COND_AXIS_NAME_MAGICNO-22 "23068673.0000000000"
*MEAS_COND_AXIS_NAME_MAGICNO-23 "20971521.0000000000"
*MEAS_COND_AXIS_NAME_MAGICNO-24 "20971521.0000000000"
*MEAS_COND_AXIS_NAME_MAGICNO-25 "20971521.0000000000"
*MEAS_COND_AXIS_NAME_MAGICNO-26 "25165824.0000000000"
*MEAS_COND_AXIS_NAME_MAGICNO-27 "25165824.0000000000"
*MEAS_COND_AXIS_NAME_MAGICNO-28 "285343744.0000000000"
*MEAS_COND_AXIS_NAME_MAGICNO-29 "17301505.0000000000"
*MEAS_COND_AXIS_NAME_MAGICNO-30 "20971521.0000000000"
*MEAS_COND_AXIS_NAME_MAGICNO-31 "20971521.0000000000"
*MEAS_COND_AXIS_NAME_MAGICNO-32 "8388608.0000000000"
*MEAS_COND_AXIS_NAME_MAGICNO-33 "8388608.0000000000"
*MEAS_COND_AXIS_NAME_MAGICNO-34 "20971521.0000000000"
*MEAS_COND_AXIS_NAME_MAGICNO-35 "0.0000000000"
*MEAS_COND_AXIS_OFFSET-0 "-"
*MEAS_COND_AXIS_OFFSET-1 "0.7797000000"
*MEAS_COND_AXIS_OFFSET-2 "0.7287000000"
*MEAS_COND_AXIS_OFFSET-3 "0.0000000000"
*MEAS_COND_AXIS_OFFSET-4 "0.0000000000"
*MEAS_COND_AXIS_OFFSET-5 "-"
*MEAS_COND_AXIS_OFFSET-6 "-"
*MEAS_COND_AXIS_OFFSET-7 "0.7287000000"
*MEAS_COND_AXIS_OFFSET-8 "0.0510000000"
*MEAS_COND_AXIS_OFFSET-9 "-"
*MEAS_COND_AXIS_OFFSET-10 "-"
*MEAS_COND_AXIS_OFFSET-11 "-"
*MEAS_COND_AXIS_OFFSET-12 "-"
*MEAS_COND_AXIS_OFFSET-13 "-"
*MEAS_COND_AXIS_OFFSET-14 "-"
*MEAS_COND_AXIS_OFFSET-15 "-"
*MEAS_COND_AXIS_OFFSET-16 "-"
*MEAS_COND_AXIS_OFFSET-17 "-"
*MEAS_COND_AXIS_OFFSET-18 "-"
*MEAS_COND_AXIS_OFFSET-19 "-"
*MEAS_COND_AXIS_OFFSET-20 "-"
*MEAS_COND_AXIS_OFFSET-21 "-"
*MEAS_COND_AXIS_OFFSET-22 "-"
*MEAS_COND_AXIS_OFFSET-23 "-"
*MEAS_COND_AXIS_OFFSET-24 "-"
*MEAS_COND_AXIS_OFFSET-25 "-"
*MEAS_COND_AXIS_OFFSET-26 "-"
*MEAS_COND_AXIS_OFFSET-27 "-"
*MEAS_COND_AXIS_OFFSET-28 "-"
*MEAS_COND_AXIS_OFFSET-29 "-"
*MEAS_COND_AXIS_OFFSET-30 "-"
*MEAS_COND_AXIS_OFFSET-31 "-"
*MEAS_COND_AXIS_OFFSET-32 "0.0000000000"
*MEAS_COND_AXIS_OFFSET-33 "0.0000000000"
*MEAS_COND_AXIS_OFFSET-34 "-"
*MEAS_COND_AXIS_OFFSET-35 "-"
*MEAS_COND_AXIS_POSITION-0 "-0.0008000000"
*MEAS_COND_AXIS_POSITION-1 "-0.0009000000"
*MEAS_COND_AXIS_POSITION-2 "-0.0004000000"
*MEAS_COND_AXIS_POSITION-3 "0.0000000000"
*MEAS_COND_AXIS_POSITION-4 "0.0000000000"
*MEAS_COND_AXIS_POSITION-5 "-1.4302000000"
*MEAS_COND_AXIS_POSITION-6 "-0.0008000000"
*MEAS_COND_AXIS_POSITION-7 "-0.0004000000"
*MEAS_COND_AXIS_POSITION-8 "-0.0005000000"
*MEAS_COND_AXIS_POSITION-9 "-4.3477500000"
*MEAS_COND_AXIS_POSITION-10 "PB"
*MEAS_COND_AXIS_POSITION-11 "0.0000000000"
*MEAS_COND_AXIS_POSITION-12 "Soller_slit_open_s"
*MEAS_COND_AXIS_POSITION-13 "0.250mm"
*MEAS_COND_AXIS_POSITION-14 "0.2500000000"
*MEAS_COND_AXIS_POSITION-15 "-0.6878100000"
*MEAS_COND_AXIS_POSITION-16 "Ge(220)x2"
*MEAS_COND_AXIS_POSITION-17 "0.0000000000"
*MEAS_COND_AXIS_POSITION-18 "2.0mm"
*MEAS_COND_AXIS_POSITION-19 "None"
*MEAS_COND_AXIS_POSITION-20 "None"
*MEAS_COND_AXIS_POSITION-21 "0.250mm"
*MEAS_COND_AXIS_POSITION-22 "0.250mm"
*MEAS_COND_AXIS_POSITION-23 "No_unit"
*MEAS_COND_AXIS_POSITION-24 "Soller_slit_5.0deg"
*MEAS_COND_AXIS_POSITION-25 "None"
*MEAS_COND_AXIS_POSITION-26 "0.2500000000"
*MEAS_COND_AXIS_POSITION-27 "0.2500000000"
*MEAS_COND_AXIS_POSITION-28 "0.0809400000"
*MEAS_COND_AXIS_POSITION-29 "1/10000"
*MEAS_COND_AXIS_POSITION-30 "None"
*MEAS_COND_AXIS_POSITION-31 "None"
*MEAS_COND_AXIS_POSITION-32 "0.0000000000"
*MEAS_COND_AXIS_POSITION-33 "0.0000000000"
*MEAS_COND_AXIS_POSITION-34 "None"
*MEAS_COND_AXIS_POSITION-35 "34.0000000000"
*MEAS_COND_AXIS_UNIT-0 "deg"
*MEAS_COND_AXIS_UNIT-1 "deg"
*MEAS_COND_AXIS_UNIT-2 "deg"
*MEAS_COND_AXIS_UNIT-3 "deg"
*MEAS_COND_AXIS_UNIT-4 "deg"
*MEAS_COND_AXIS_UNIT-5 "mm"
*MEAS_COND_AXIS_UNIT-6 "deg"
*MEAS_COND_AXIS_UNIT-7 "deg"
*MEAS_COND_AXIS_UNIT-8 "deg"
*MEAS_COND_AXIS_UNIT-9 "mm"
*MEAS_COND_AXIS_UNIT-10 ""
*MEAS_COND_AXIS_UNIT-11 "pulse"
*MEAS_COND_AXIS_UNIT-12 ""
*MEAS_COND_AXIS_UNIT-13 ""
*MEAS_COND_AXIS_UNIT-14 "mm"
*MEAS_COND_AXIS_UNIT-15 "mm"
*MEAS_COND_AXIS_UNIT-16 ""
*MEAS_COND_AXIS_UNIT-17 "pulse"
*MEAS_COND_AXIS_UNIT-18 ""
*MEAS_COND_AXIS_UNIT-19 ""
*MEAS_COND_AXIS_UNIT-20 ""
*MEAS_COND_AXIS_UNIT-21 ""
*MEAS_COND_AXIS_UNIT-22 ""
*MEAS_COND_AXIS_UNIT-23 ""
*MEAS_COND_AXIS_UNIT-24 ""
*MEAS_COND_AXIS_UNIT-25 ""
*MEAS_COND_AXIS_UNIT-26 "mm"
*MEAS_COND_AXIS_UNIT-27 "mm"
*MEAS_COND_AXIS_UNIT-28 "mm"
*MEAS_COND_AXIS_UNIT-29 ""
*MEAS_COND_AXIS_UNIT-30 ""
*MEAS_COND_AXIS_UNIT-31 ""
*MEAS_COND_AXIS_UNIT-32 "deg"
*MEAS_COND_AXIS_UNIT-33 "deg"
*MEAS_COND_AXIS_UNIT-34 ""
*MEAS_COND_AXIS_UNIT-35 "div"
*MEAS_COND_COUNTER_CNTLOSS_CORR "0.0000000000"
*MEAS_COND_COUNTER_PHABASE "34.0000000000"
*MEAS_COND_COUNTER_PHAWINDOW "19.0000000000"
*MEAS_COND_COUNTER_PHA_UNIT "div"
*MEAS_COND_COUNTER_TAUDIFF "2.0000000000"
*MEAS_COND_COUNTER_TAUINT "0.1000000000"
*MEAS_COND_IRRADIATION_MODE "OFF"
*MEAS_COND_IRRADIATION_WIDTH ""
*MEAS_COND_OPT_ATTR "High resolution parallel beam Ge(220)x2/RS"
*MEAS_COND_OPT_NAME "@High resolution PB-Ge(220)x2"
*MEAS_COND_UNSYMMETRIC_MODE "OFF"
*MEAS_COND_XG_CURRENT "200.0000000000"
*MEAS_COND_XG_VOLTAGE "45.0000000000"
*MEAS_COND_XG_WAVE_TYPE "Ka1"
*MEAS_DATA_COUNT "4001.0000000000"
*MEAS_SCAN_AXIS_X "2-Theta/Omega"
*MEAS_SCAN_AXIS_X_INTERNAL "TwoThetaOmega"
*MEAS_SCAN_END_TIME "10/25/23 00:27:21"
*MEAS_SCAN_MODE "CONTINUOUS"
*MEAS_SCAN_MONITOR "0"
*MEAS_SCAN_RESOLUTION_X "0.0002"
*MEAS_SCAN_SPEED "0.500000"
*MEAS_SCAN_SPEED_UNIT "deg/min"
*MEAS_SCAN_SPEED_USER "0.500000"
*MEAS_SCAN_START "0.0000000000"
*MEAS_SCAN_START_TIME "10/25/23 00:11:02"
*MEAS_SCAN_STEP "0.0020000000"
*MEAS_SCAN_STOP "8.0000000000"
*MEAS_SCAN_UNIT_X "deg"
*MEAS_SCAN_UNIT_Y "counts"
*RAS_HEADER_END
*RAS_INT_START
0.0000 402266.0625 1.0000
0.0060 404485.5000 1.0000
0.0120 411650.1875 1.0000
0.0180 397425.0625 1.0000
0.0240 372475.1875 1.0000
0.0300 360767.4063 1.0000
0.0360 312930.7188 1.0000
0.0420 244642.5938 1.0000
0.0480 176220.4219 1.0000
0.0540 126343.0625 1.0000
0.0600 77985.0391 1.0000
0.0660 42285.5000 1.0000
0.0720 21180.8340 1.0000
0.0780 12767.1670 1.0000
0.0840 9563.8330 1.0000
0.0900 7875.8335 1.0000
0.0960 7342.1665 1.0000
0.1020 7117.0000 1.0000
0.1080 6979.1665 1.0000
0.1140 7158.6665 1.0000
0.1200 7230.8335 1.0000
0.1260 7854.8335 1.0000
0.1320 7854.0000 1.0000
0.1380 8020.3335 1.0000
0.1440 8573.0000 1.0000
0.1500 8762.5000 1.0000
0.1560 8866.3330 1.0000
0.1620 9148.8330 1.0000
0.1680 9523.1670 1.0000
0.1740 9608.8330 1.0000
0.1800 9900.6670 1.0000
0.1860 10138.3330 1.0000
0.1920 10402.0000 1.0000
0.1980 10596.5000 1.0000
0.2040 11030.5000 1.0000
0.2100 11267.3330 1.0000
0.2160 11349.3330 1.0000
0.2220 11665.5000 1.0000
0.2280 11961.5000 1.0000
0.2340 12354.8330 1.0000
0.2400 12582.8330 1.0000
0.2460 12686.0000 1.0000
0.2520 13049.8330 1.0000
0.2580 13382.1670 1.0000
0.2640 13664.5000 1.0000
0.2700 13920.5000 1.0000
0.2760 14222.3330 1.0000
0.2820 14275.8330 1.0000
0.2880 14686.0000 1.0000
0.2940 15023.5000 1.0000
0.3000 15156.8330 1.0000
0.3060 15525.6670 1.0000
0.3120 15989.8330 1.0000
0.3180 16208.5000 1.0000
0.3240 16223.8330 1.0000
0.3300 16642.3340 1.0000
0.3360 16690.0000 1.0000
0.3420 17169.1660 1.0000
0.3480 17399.6660 1.0000
0.3540 17837.8340 1.0000
0.3600 17973.1660 1.0000
0.3660 18234.3340 1.0000
0.3720 18414.0000 1.0000
0.3780 18958.0000 1.0000
0.3840 18908.5000 1.0000
0.3900 19029.6660 1.0000
0.3960 19369.5000 1.0000
0.4020 19806.5000 1.0000
0.4080 20064.3340 1.0000
0.4140 20331.6660 1.0000
0.4200 20724.0000 1.0000
0.4260 20681.3340 1.0000
0.4320 20999.1660 1.0000
0.4380 21446.3340 1.0000
0.4440 21722.0000 1.0000
0.4500 21673.5000 1.0000
0.4560 22248.3340 1.0000
0.4620 22511.6660 1.0000
0.4680 22659.6660 1.0000
0.4740 22924.6660 1.0000
0.4800 23065.1660 1.0000
0.4860 23403.5000 1.0000
0.4920 23345.1660 1.0000
0.4980 23703.1660 1.0000
0.5040 23936.1660 1.0000
0.5100 24069.3340 1.0000
0.5160 23947.8340 1.0000
0.5220 24604.8340 1.0000
0.5280 24959.5000 1.0000
0.5340 24854.6660 1.0000
0.5400 24929.3340 1.0000
0.5460 24905.8340 1.0000
0.5520 25106.8340 1.0000
0.5580 25473.6660 1.0000
0.5640 25511.0000 1.0000
0.5700 25204.6660 1.0000
0.5760 25496.0000 1.0000
0.5820 25541.5000 1.0000
0.5880 25424.1660 1.0000
0.5940 25484.1660 1.0000
0.6000 25174.0000 1.0000
0.6060 24932.3340 1.0000
0.6120 24686.0000 1.0000
0.6180 24052.3340 1.0000
0.6240 23941.5000 1.0000
0.6300 23090.6660 1.0000
0.6360 22442.6660 1.0000
0.6420 21715.0000 1.0000
0.6480 20382.6660 1.0000
0.6540 19795.6660 1.0000
0.6600 18476.0000 1.0000
0.6660 17124.8340 1.0000
0.6720 16155.3330 1.0000
0.6780 14770.1670 1.0000
0.6840 13796.3330 1.0000
0.6900 12529.0000 1.0000
0.6960 11848.6670 1.0000
0.7020 10979.6670 1.0000
0.7080 10065.6670 1.0000
0.7140 9328.1670 1.0000
0.7200 8602.3330 1.0000
0.7260 8091.3335 1.0000
0.7320 7632.6665 1.0000
0.7380 7052.3335 1.0000
0.7440 6566.6665 1.0000
0.7500 6267.8335 1.0000
0.7560 5846.5000 1.0000
0.7620 5407.5000 1.0000
0.7680 5203.0000 1.0000
0.7740 5027.8335 1.0000
0.7800 4581.8335 1.0000
0.7860 4347.0000 1.0000
0.7920 4130.3335 1.0000
0.7980 3912.8333 1.0000
0.8040 3714.8333 1.0000
0.8100 3530.5000 1.0000
0.8160 3365.3333 1.0000
0.8220 3192.6667 1.0000
0.8280 2913.5000 1.0000
0.8340 2789.6667 1.0000
0.8400 2667.1667 1.0000
0.8460 2505.8333 1.0000
0.8520 2411.3333 1.0000
0.8580 2345.1667 1.0000
0.8640 2221.8333 1.0000
0.8700 2195.8333 1.0000
0.8760 2001.6666 1.0000
0.8820 1941.5000 1.0000
0.8880 1910.6666 1.0000
0.8940 1764.1666 1.0000
0.9000 1757.0000 1.0000
0.9060 1610.6666 1.0000
0.9120 1570.3334 1.0000
0.9180 1453.5000 1.0000
0.9240 1454.0000 1.0000
0.9300 1264.0000 1.0000
0.9360 1306.1666 1.0000
0.9420 1243.8334 1.0000
0.9480 1254.8334 1.0000
0.9540 1191.6666 1.0000
0.9600 1218.5000 1.0000
0.9660 1133.0000 1.0000
0.9720 1171.0000 1.0000
0.9780 1081.3334 1.0000
0.9840 1024.3334 1.0000
0.9900 1014.8333 1.0000
0.9960 996.5000 1.0000
1.0020 912.3333 1.0000
1.0080 983.5000 1.0000
1.0140 923.6667 1.0000
1.0200 859.1667 1.0000
1.0260 860.0000 1.0000
1.0320 866.6667 1.0000
1.0380 801.1667 1.0000
1.0440 794.3333 1.0000
1.0500 828.6667 1.0000
1.0560 775.3333 1.0000
1.0620 743.3333 1.0000
1.0680 735.1667 1.0000
1.0740 783.3333 1.0000
1.0800 709.0000 1.0000
1.0860 702.0000 1.0000
1.0920 736.3333 1.0000
1.0980 674.6667 1.0000
1.1040 682.0000 1.0000
1.1100 681.1667 1.0000
1.1160 674.3333 1.0000
1.1220 637.5000 1.0000
1.1280 640.1667 1.0000
1.1340 632.0000 1.0000
1.1400 638.3333 1.0000
1.1460 583.6667 1.0000
1.1520 591.1667 1.0000
1.1580 526.0000 1.0000
1.1640 553.3333 1.0000
1.1700 548.8333 1.0000
1.1760 519.3333 1.0000
1.1820 575.1667 1.0000
1.1880 498.8333 1.0000
1.1940 490.0000 1.0000
1.2000 466.6667 1.0000
1.2060 518.3333 1.0000
1.2120 495.1667 1.0000
1.2180 468.3333 1.0000
1.2240 436.1667 1.0000
1.2300 442.3333 1.0000
1.2360 467.3333 1.0000
1.2420 424.8333 1.0000
1.2480 440.1667 1.0000
1.2540 413.1667 1.0000
1.2600 398.8333 1.0000
1.2660 383.8333 1.0000
1.2720 391.5000 1.0000
1.2780 383.5000 1.0000
1.2840 343.3333 1.0000
1.2900 325.6667 1.0000
1.2960 322.5000 1.0000
1.3020 351.6667 1.0000
1.3080 346.8333 1.0000
1.3140 326.1667 1.0000
1.3200 324.8333 1.0000
1.3260 309.6667 1.0000
1.3320 302.5000 1.0000
1.3380 320.3333 1.0000
1.3440 303.5000 1.0000
1.3500 303.0000 1.0000
1.3560 282.5000 1.0000
1.3620 281.6667 1.0000
1.3680 286.6667 1.0000
1.3740 246.0000 1.0000
1.3800 243.1667 1.0000
1.3860 252.5000 1.0000
1.3920 258.6667 1.0000
1.3980 240.5000 1.0000
1.4040 233.6667 1.0000
1.4100 275.3333 1.0000
1.4160 251.6667 1.0000
1.4220 231.6667 1.0000
1.4280 240.0000 1.0000
1.4340 221.3333 1.0000
1.4400 219.6667 1.0000
1.4460 200.8333 1.0000
1.4520 186.1667 1.0000
1.4580 210.1667 1.0000
1.4640 201.3333 1.0000
1.4700 201.6667 1.0000
1.4760 177.6667 1.0000
1.4820 210.6667 1.0000
1.4880 194.0000 1.0000
1.4940 195.8333 1.0000
1.5000 173.1667 1.0000
1.5060 172.0000 1.0000
1.5120 189.0000 1.0000
1.5180 167.5000 1.0000
1.5240 164.6667 1.0000
1.5300 186.5000 1.0000
1.5360 172.0000 1.0000
1.5420 156.8333 1.0000
1.5480 163.0000 1.0000
1.5540 145.3333 1.0000
1.5600 143.3333 1.0000
1.5660 174.1667 1.0000
1.5720 138.1667 1.0000
1.5780 139.0000 1.0000
1.5840 139.8333 1.0000
1.5900 135.8333 1.0000
1.5960 154.0000 1.0000
1.6020 145.8333 1.0000
1.6080 155.3333 1.0000
1.6140 167.6667 1.0000
1.6200 159.0000 1.0000
1.6260 142.6667 1.0000
1.6320 136.3333 1.0000
1.6380 138.3333 1.0000
1.6440 125.5000 1.0000
1.6500 138.5000 1.0000
1.6560 128.3333 1.0000
1.6620 156.8333 1.0000
1.6680 92.1667 1.0000
1.6740 128.6667 1.0000
1.6800 145.8333 1.0000
1.6860 157.3333 1.0000
1.6920 120.1667 1.0000
1.6980 133.3333 1.0000
1.7040 136.6667 1.0000
1.7100 114.6667 1.0000
1.7160 127.3333 1.0000
1.7220 124.1667 1.0000
1.7280 116.8333 1.0000
1.7340 122.0000 1.0000
1.7400 148.5000 1.0000
1.7460 116.3333 1.0000
1.7520 107.3333 1.0000
1.7580 138.0000 1.0000
1.7640 126.1667 1.0000
1.7700 113.3333 1.0000
1.7760 108.6667 1.0000
1.7820 121.3333 1.0000
1.7880 105.5000 1.0000
1.7940 110.0000 1.0000
1.8000 104.0000 1.0000
1.8060 106.0000 1.0000
1.8120 102.6667 1.0000
1.8180 106.5000 1.0000
1.8240 90.0000 1.0000
1.8300 89.1667 1.0000
1.8360 111.6667 1.0000
1.8420 108.6667 1.0000
1.8480 102.1667 1.0000
1.8540 92.8333 1.0000
1.8600 97.8333 1.0000
1.8660 88.0000 1.0000
1.8720 74.0000 1.0000
1.8780 96.0000 1.0000
1.8840 85.6667 1.0000
1.8900 84.5000 1.0000
1.8960 91.0000 1.0000
1.9020 96.6667 1.0000
1.9080 67.3333 1.0000
1.9140 80.3333 1.0000
1.9200 83.1667 1.0000
1.9260 86.5000 1.0000
1.9320 79.1667 1.0000
1.9380 68.3333 1.0000
1.9440 77.3333 1.0000
1.9500 62.6667 1.0000
1.9560 68.6667 1.0000
1.9620 67.8333 1.0000
1.9680 47.0000 1.0000
1.9740 62.6667 1.0000
1.9800 78.1667 1.0000
1.9860 63.1667 1.0000
1.9920 70.0000 1.0000
1.9980 61.5000 1.0000
2.0040 58.3333 1.0000
2.0100 56.1667 1.0000
2.0160 55.3333 1.0000
2.0220 74.3333 1.0000
2.0280 58.6667 1.0000
2.0340 47.8333 1.0000
2.0400 48.0000 1.0000
2.0460 54.6667 1.0000
2.0520 44.5000 1.0000
2.0580 50.5000 1.0000
2.0640 34.8333 1.0000
2.0700 48.8333 1.0000
2.0760 54.3333 1.0000
2.0820 52.8333 1.0000
2.0880 51.0000 1.0000
2.0940 42.1667 1.0000
2.1000 33.0000 1.0000
2.1060 43.8333 1.0000
2.1120 45.8333 1.0000
2.1180 42.3333 1.0000
2.1240 37.3333 1.0000
2.1300 37.6667 1.0000
2.1360 38.0000 1.0000
2.1420 39.6667 1.0000
2.1480 42.0000 1.0000
2.1540 43.3333 1.0000
2.1600 36.8333 1.0000
2.1660 35.3333 1.0000
2.1720 43.0000 1.0000
2.1780 32.5000 1.0000
2.1840 32.3333 1.0000
2.1900 32.6667 1.0000
2.1960 25.3333 1.0000
2.2020 37.5000 1.0000
2.2080 31.8333 1.0000
2.2140 30.5000 1.0000
2.2200 31.5000 1.0000
2.2260 32.3333 1.0000
2.2320 38.3333 1.0000
2.2380 27.0000 1.0000
2.2440 40.8333 1.0000
2.2500 33.8333 1.0000
2.2560 37.1667 1.0000
2.2620 34.6667 1.0000
2.2680 30.8333 1.0000
2.2740 32.3333 1.0000
2.2800 34.6667 1.0000
2.2860 36.6667 1.0000
2.2920 36.6667 1.0000
2.2980 30.8333 1.0000
2.3040 26.6667 1.0000
2.3100 29.6667 1.0000
2.3160 45.0000 1.0000
2.3220 30.8333 1.0000
2.3280 25.3333 1.0000
2.3340 32.1667 1.0000
2.3400 41.5000 1.0000
2.3460 39.0000 1.0000
2.3520 23.6667 1.0000
2.3580 35.8333 1.0000
2.3640 27.3333 1.0000
2.3700 57.8333 1.0000
2.3760 32.6667 1.0000
2.3820 34.1667 1.0000
2.3880 31.6667 1.0000
2.3940 30.1667 1.0000
2.4000 27.3333 1.0000
2.4060 35.8333 1.0000
2.4120 47.5000 1.0000
2.4180 44.8333 1.0000
2.4240 31.5000 1.0000
2.4300 27.3333 1.0000
2.4360 31.0000 1.0000
2.4420 37.8333 1.0000
2.4480 33.5000 1.0000
2.4540 44.8333 1.0000
2.4600 35.5000 1.0000
2.4660 31.8333 1.0000
2.4720 35.8333 1.0000
2.4780 23.5000 1.0000
2.4840 30.3333 1.0000
2.4900 25.8333 1.0000
2.4960 25.6667 1.0000
2.5020 24.8333 1.0000
2.5080 33.3333 1.0000
2.5140 22.5000 1.0000
2.5200 19.8333 1.0000
2.5260 27.5000 1.0000
2.5320 22.0000 1.0000
2.5380 24.5000 1.0000
2.5440 31.3333 1.0000
2.5500 29.1667 1.0000
2.5560 24.3333 1.0000
2.5620 21.1667 1.0000
2.5680 16.3333 1.0000
2.5740 28.1667 1.0000
2.5800 16.5000 1.0000
2.5860 23.8333 1.0000
2.5920 18.6667 1.0000
2.5980 15.0000 1.0000
2.6040 26.5000 1.0000
2.6100 16.6667 1.0000
2.6160 13.6667 1.0000
2.6220 13.1667 1.0000
2.6280 10.5000 1.0000
2.6340 19.5000 1.0000
2.6400 15.8333 1.0000
2.6460 19.5000 1.0000
2.6520 22.5000 1.0000
2.6580 24.5000 1.0000
2.6640 16.6667 1.0000
2.6700 16.5000 1.0000
2.6760 23.0000 1.0000
2.6820 20.8333 1.0000
2.6880 19.5000 1.0000
2.6940 15.6667 1.0000
2.7000 23.8333 1.0000
2.7060 12.3333 1.0000
2.7120 18.6667 1.0000
2.7180 13.5000 1.0000
2.7240 20.0000 1.0000
2.7300 13.0000 1.0000
2.7360 14.1667 1.0000
2.7420 14.6667 1.0000
2.7480 14.5000 1.0000
2.7540 10.5000 1.0000
2.7600 13.5000 1.0000
2.7660 4.6667 1.0000
2.7720 17.8333 1.0000
2.7780 12.5000 1.0000
2.7840 11.0000 1.0000
2.7900 13.5000 1.0000
2.7960 8.1667 1.0000
2.8020 12.3333 1.0000
2.8080 4.6667 1.0000
2.8140 13.8333 1.0000
2.8200 10.3333 1.0000
2.8260 10.5000 1.0000
2.8320 12.1667 1.0000
2.8380 10.6667 1.0000
2.8440 14.1667 1.0000
2.8500 4.5000 1.0000
2.8560 11.8333 1.0000
2.8620 8.5000 1.0000
2.8680 9.5000 1.0000
2.8740 13.3333 1.0000
2.8800 11.6667 1.0000
2.8860 12.0000 1.0000
2.8920 12.3333 1.0000
2.8980 9.0000 1.0000
2.9040 17.0000 1.0000
2.9100 7.8333 1.0000
2.9160 11.0000 1.0000
2.9220 8.0000 1.0000
2.9280 10.1667 1.0000
2.9340 16.0000 1.0000
2.9400 10.8333 1.0000
2.9460 9.6667 1.0000
2.9520 12.0000 1.0000
2.9580 12.0000 1.0000
2.9640 10.5000 1.0000
2.9700 9.6667 1.0000
2.9760 7.5000 1.0000
2.9820 7.5000 1.0000
2.9880 11.6667 1.0000
2.9940 8.6667 1.0000
3.0000 8.8333 1.0000
3.0060 3.3333 1.0000
3.0120 9.1667 1.0000
3.0180 6.8333 1.0000
3.0240 8.8333 1.0000
3.0300 9.6667 1.0000
3.0360 10.5000 1.0000
3.0420 13.8333 1.0000
3.0480 5.8333 1.0000
3.0540 13.0000 1.0000
3.0600 3.0000 1.0000
3.0660 8.6667 1.0000
3.0720 12.8333 1.0000
3.0780 16.5000 1.0000
3.0840 12.6667 1.0000
3.0900 11.5000 1.0000
3.0960 3.8333 1.0000
3.1020 11.0000 1.0000
3.1080 14.5000 1.0000
3.1140 17.5000 1.0000
3.1200 12.1667 1.0000
3.1260 13.5000 1.0000
3.1320 4.0000 1.0000
3.1380 13.8333 1.0000
3.1440 13.8333 1.0000
3.1500 8.0000 1.0000
3.1560 10.6667 1.0000
3.1620 8.3333 1.0000
3.1680 2.8333 1.0000
3.1740 7.6667 1.0000
3.1800 7.6667 1.0000
3.1860 8.8333 1.0000
3.1920 6.5000 1.0000
3.1980 5.1667 1.0000
3.2040 6.0000 1.0000
3.2100 10.5000 1.0000
3.2160 8.1667 1.0000
3.2220 2.3333 1.0000
3.2280 3.3333 1.0000
3.2340 7.5000 1.0000
3.2400 6.6667 1.0000
3.2460 6.5000 1.0000
3.2520 7.6667 1.0000
3.2580 6.0000 1.0000
3.2640 3.8333 1.0000
3.2700 12.5000 1.0000
3.2760 8.5000 1.0000
3.2820 2.1667 1.0000
3.2880 3.6667 1.0000
3.2940 13.0000 1.0000
3.3000 2.1667 1.0000
3.3060 4.6667 1.0000
3.3120 4.5000 1.0000
3.3180 5.1667 1.0000
3.3240 6.0000 1.0000
3.3300 4.3333 1.0000
3.3360 3.1667 1.0000
3.3420 7.6667 1.0000
3.3480 0.5000 1.0000
3.3540 7.6667 1.0000
3.3600 7.5000 1.0000
3.3660 7.6667 1.0000
3.3720 2.1667 1.0000
3.3780 5.8333 1.0000
3.3840 4.1667 1.0000
3.3900 2.8333 1.0000
3.3960 4.3333 1.0000
3.4020 0.1667 1.0000
3.4080 3.3333 1.0000
3.4140 2.5000 1.0000
3.4200 4.0000 1.0000
3.4260 3.1667 1.0000
3.4320 4.6667 1.0000
3.4380 1.1667 1.0000
3.4440 6.5000 1.0000
3.4500 4.8333 1.0000
3.4560 5.3333 1.0000
3.4620 3.1667 1.0000
3.4680 0.0000 1.0000
3.4740 2.1667 1.0000
3.4800 4.0000 1.0000
3.4860 2.5000 1.0000
3.4920 2.3333 1.0000
3.4980 7.3333 1.0000
3.5040 3.1667 1.0000
3.5100 6.5000 1.0000
3.5160 3.5000 1.0000
3.5220 4.1667 1.0000
3.5280 1.1667 1.0000
3.5340 5.8333 1.0000
3.5400 0.1667 1.0000
3.5460 5.5000 1.0000
3.5520 4.1667 1.0000
3.5580 4.3333 1.0000
3.5640 0.1667 1.0000
3.5700 3.3333 1.0000
3.5760 3.5000 1.0000
3.5820 1.3333 1.0000
3.5880 2.6667 1.0000
3.5940 3.0000 1.0000
3.6000 1.5000 1.0000
3.6060 2.5000 1.0000
3.6120 4.3333 1.0000
3.6180 5.5000 1.0000
3.6240 1.6667 1.0000
3.6300 4.3333 1.0000
3.6360 0.1667 1.0000
3.6420 3.3333 1.0000
3.6480 3.1667 1.0000
3.6540 4.5000 1.0000
3.6600 5.1667 1.0000
3.6660 0.5000 1.0000
3.6720 0.0000 1.0000
3.6780 0.3333 1.0000
3.6840 5.5000 1.0000
3.6900 3.3333 1.0000
3.6960 2.1667 1.0000
3.7020 4.1667 1.0000
3.7080 3.0000 1.0000
3.7140 0.3333 1.0000
3.7200 2.3333 1.0000
3.7260 4.5000 1.0000
3.7320 4.0000 1.0000
3.7380 1.3333 1.0000
3.7440 0.0000 1.0000
3.7500 2.1667 1.0000
3.7560 4.5000 1.0000
3.7620 0.0000 1.0000
3.7680 2.1667 1.0000
3.7740 2.6667 1.0000
3.7800 3.3333 1.0000
3.7860 4.3333 1.0000
3.7920 4.3333 1.0000
3.7980 4.3333 1.0000
3.8040 2.0000 1.0000
3.8100 0.0000 1.0000
3.8160 2.0000 1.0000
3.8220 3.1667 1.0000
3.8280 0.0000 1.0000
3.8340 4.3333 1.0000
3.8400 1.3333 1.0000
3.8460 3.0000 1.0000
3.8520 0.0000 1.0000
3.8580 5.3333 1.0000
3.8640 3.1667 1.0000
3.8700 3.0000 1.0000
3.8760 0.6667 1.0000
3.8820 0.0000 1.0000
3.8880 2.3333 1.0000
3.8940 2.3333 1.0000
3.9000 2.1667 1.0000
3.9060 0.0000 1.0000
3.9120 2.1667 1.0000
3.9180 1.1667 1.0000
3.9240 0.0000 1.0000
3.9300 1.1667 1.0000
3.9360 0.0000 1.0000
3.9420 0.1667 1.0000
3.9480 4.3333 1.0000
3.9540 0.0000 1.0000
3.9600 1.1667 1.0000
3.9660 3.3333 1.0000
3.9720 4.3333 1.0000
3.9780 0.0000 1.0000
3.9840 0.1667 1.0000
3.9900 2.3333 1.0000
3.9960 4.3333 1.0000
4.0020 3.3333 1.0000
4.0080 2.0000 1.0000
4.0140 0.5000 1.0000
4.0200 3.3333 1.0000
4.0260 1.1667 1.0000
4.0320 5.0000 1.0000
4.0380 0.1667 1.0000
4.0440 0.0000 1.0000
4.0500 0.0000 1.0000
4.0560 0.1667 1.0000
4.0620 2.0000 1.0000
4.0680 0.0000 1.0000
4.0740 1.1667 1.0000
4.0800 0.3333 1.0000
4.0860 0.0000 1.0000
4.0920 0.3333 1.0000
4.0980 2.0000 1.0000
4.1040 0.1667 1.0000
4.1100 0.0000 1.0000
4.1160 0.0000 1.0000
4.1220 0.1667 1.0000
4.1280 0.1667 1.0000
4.1340 1.1667 1.0000
4.1400 1.1667 1.0000
4.1460 1.3333 1.0000
4.1520 0.0000 1.0000
4.1580 2.1667 1.0000
4.1640 0.0000 1.0000
4.1700 4.0000 1.0000
4.1760 0.0000 1.0000
4.1820 0.1667 1.0000
4.1880 2.0000 1.0000
4.1940 0.0000 1.0000
4.2000 0.5000 1.0000
4.2060 0.0000 1.0000
4.2120 0.0000 1.0000
4.2180 2.0000 1.0000
4.2240 0.0000 1.0000
4.2300 0.0000 1.0000
4.2360 3.0000 1.0000
4.2420 2.0000 1.0000
4.2480 0.3333 1.0000
4.2540 2.0000 1.0000
4.2600 2.1667 1.0000
4.2660 4.1667 1.0000
4.2720 0.0000 1.0000
4.2780 0.1667 1.0000
4.2840 0.0000 1.0000
4.2900 2.0000 1.0000
4.2960 2.0000 1.0000
4.3020 1.1667 1.0000
4.3080 3.1667 1.0000
4.3140 0.3333 1.0000
4.3200 0.1667 1.0000
4.3260 0.0000 1.0000
4.3320 0.0000 1.0000
4.3380 3.1667 1.0000
4.3440 0.0000 1.0000
4.3500 0.0000 1.0000
4.3560 0.0000 1.0000
4.3620 0.0000 1.0000
4.3680 0.0000 1.0000
4.3740 1.1667 1.0000
4.3800 1.3333 1.0000
4.3860 0.0000 1.0000
4.3920 0.0000 1.0000
4.3980 0.0000 1.0000
4.4040 0.0000 1.0000
4.4100 0.0000 1.0000
4.4160 0.0000 1.0000
4.4220 1.1667 1.0000
4.4280 2.1667 1.0000
4.4340 0.0000 1.0000
4.4400 0.0000 1.0000
4.4460 0.0000 1.0000
4.4520 0.0000 1.0000
4.4580 2.0000 1.0000
4.4640 0.0000 1.0000
4.4700 0.1667 1.0000
4.4760 0.0000 1.0000
4.4820 0.0000 1.0000
4.4880 0.0000 1.0000
4.4940 0.0000 1.0000
4.5000 0.0000 1.0000
4.5060 0.0000 1.0000
4.5120 0.0000 1.0000
4.5180 1.5000 1.0000
4.5240 2.0000 1.0000
4.5300 0.1667 1.0000
4.5360 0.0000 1.0000
4.5420 0.0000 1.0000
4.5480 0.0000 1.0000
4.5540 1.3333 1.0000
4.5600 0.0000 1.0000
4.5660 0.0000 1.0000
4.5720 0.0000 1.0000
4.5780 0.0000 1.0000
4.5840 0.0000 1.0000
4.5900 0.0000 1.0000
4.5960 0.0000 1.0000
4.6020 0.0000 1.0000
4.6080 0.0000 1.0000
4.6140 0.0000 1.0000
4.6200 0.0000 1.0000
4.6260 0.0000 1.0000
4.6320 0.0000 1.0000
4.6380 0.0000 1.0000
4.6440 0.0000 1.0000
4.6500 0.0000 1.0000
4.6560 0.0000 1.0000
4.6620 0.0000 1.0000
4.6680 1.1667 1.0000
4.6740 0.0000 1.0000
4.6800 0.0000 1.0000
4.6860 0.0000 1.0000
4.6920 0.1667 1.0000
4.6980 0.0000 1.0000
4.7040 0.0000 1.0000
4.7100 0.0000 1.0000
4.7160 0.0000 1.0000
4.7220 0.0000 1.0000
4.7280 0.0000 1.0000
4.7340 0.0000 1.0000
4.7400 0.0000 1.0000
4.7460 0.0000 1.0000
4.7520 0.0000 1.0000
4.7580 0.0000 1.0000
4.7640 0.0000 1.0000
4.7700 0.0000 1.0000
4.7760 0.0000 1.0000
4.7820 0.0000 1.0000
4.7880 0.0000 1.0000
4.7940 0.0000 1.0000
4.8000 0.0000 1.0000
4.8060 0.0000 1.0000
4.8120 0.0000 1.0000
4.8180 1.1667 1.0000
4.8240 0.0000 1.0000
4.8300 0.0000 1.0000
4.8360 0.0000 1.0000
4.8420 0.0000 1.0000
4.8480 0.0000 1.0000
4.8540 0.0000 1.0000
4.8600 0.0000 1.0000
4.8660 0.0000 1.0000
4.8720 0.0000 1.0000
4.8780 0.0000 1.0000
4.8840 0.0000 1.0000
4.8900 0.0000 1.0000
4.8960 0.0000 1.0000
4.9020 0.0000 1.0000
4.9080 0.0000 1.0000
4.9140 0.0000 1.0000
4.9200 0.0000 1.0000
4.9260 2.0000 1.0000
4.9320 0.0000 1.0000
4.9380 2.0000 1.0000
4.9440 2.0000 1.0000
4.9500 0.0000 1.0000
4.9560 0.0000 1.0000
4.9620 0.0000 1.0000
4.9680 0.0000 1.0000
4.9740 0.0000 1.0000
4.9800 0.0000 1.0000
4.9860 0.0000 1.0000
4.9920 2.1667 1.0000
4.9980 0.0000 1.0000
5.0040 0.0000 1.0000
5.0100 0.0000 1.0000
5.0160 0.0000 1.0000
5.0220 1.1667 1.0000
5.0280 0.0000 1.0000
5.0340 0.0000 1.0000
5.0400 0.0000 1.0000
5.0460 0.0000 1.0000
5.0520 0.0000 1.0000
5.0580 0.0000 1.0000
5.0640 0.0000 1.0000
5.0700 0.0000 1.0000
5.0760 0.0000 1.0000
5.0820 0.0000 1.0000
5.0880 0.0000 1.0000
5.0940 0.0000 1.0000
5.1000 0.0000 1.0000
5.1060 0.0000 1.0000
5.1120 0.0000 1.0000
5.1180 0.0000 1.0000
5.1240 0.0000 1.0000
5.1300 0.0000 1.0000
5.1360 0.0000 1.0000
5.1420 0.0000 1.0000
5.1480 0.0000 1.0000
5.1540 0.0000 1.0000
5.1600 0.0000 1.0000
5.1660 0.0000 1.0000
5.1720 0.0000 1.0000
5.1780 0.0000 1.0000
5.1840 1.1667 1.0000
5.1900 0.0000 1.0000
5.1960 1.1667 1.0000
5.2020 0.0000 1.0000
5.2080 0.0000 1.0000
5.2140 0.0000 1.0000
5.2200 0.0000 1.0000
5.2260 0.0000 1.0000
5.2320 0.0000 1.0000
5.2380 0.0000 1.0000
5.2440 0.0000 1.0000
5.2500 0.0000 1.0000
5.2560 0.0000 1.0000
5.2620 0.0000 1.0000
5.2680 0.0000 1.0000
5.2740 0.0000 1.0000
5.2800 0.0000 1.0000
5.2860 0.0000 1.0000
5.2920 0.0000 1.0000
5.2980 3.0000 1.0000
5.3040 0.0000 1.0000
5.3100 0.0000 1.0000
5.3160 0.0000 1.0000
5.3220 0.0000 1.0000
5.3280 0.0000 1.0000
5.3340 0.0000 1.0000
5.3400 0.0000 1.0000
5.3460 0.0000 1.0000
5.3520 0.0000 1.0000
5.3580 0.0000 1.0000
5.3640 0.0000 1.0000
5.3700 0.0000 1.0000
5.3760 0.0000 1.0000
5.3820 0.0000 1.0000
5.3880 0.0000 1.0000
5.3940 0.0000 1.0000
5.4000 0.0000 1.0000
5.4060 0.0000 1.0000
5.4120 0.0000 1.0000
5.4180 0.0000 1.0000
5.4240 0.0000 1.0000
5.4300 0.0000 1.0000
5.4360 0.0000 1.0000
5.4420 0.0000 1.0000
5.4480 0.0000 1.0000
5.4540 0.0000 1.0000
5.4600 0.0000 1.0000
5.4660 0.0000 1.0000
5.4720 0.0000 1.0000
5.4780 0.0000 1.0000
5.4840 0.0000 1.0000
5.4900 0.0000 1.0000
5.4960 0.0000 1.0000
5.5020 0.0000 1.0000
5.5080 0.0000 1.0000
5.5140 0.0000 1.0000
5.5200 0.0000 1.0000
5.5260 0.0000 1.0000
5.5320 2.1667 1.0000
5.5380 0.0000 1.0000
5.5440 0.0000 1.0000
5.5500 0.0000 1.0000
5.5560 0.0000 1.0000
5.5620 0.0000 1.0000
5.5680 0.0000 1.0000
5.5740 0.0000 1.0000
5.5800 0.0000 1.0000
5.5860 0.0000 1.0000
5.5920 0.0000 1.0000
5.5980 0.0000 1.0000
5.6040 0.0000 1.0000
5.6100 0.0000 1.0000
5.6160 0.0000 1.0000
5.6220 0.0000 1.0000
5.6280 0.0000 1.0000
5.6340 0.0000 1.0000
5.6400 0.0000 1.0000
5.6460 0.0000 1.0000
5.6520 0.0000 1.0000
5.6580 0.0000 1.0000
5.6640 0.0000 1.0000
5.6700 2.0000 1.0000
5.6760 0.0000 1.0000
5.6820 0.0000 1.0000
5.6880 0.0000 1.0000
5.6940 0.0000 1.0000
5.7000 0.0000 1.0000
5.7060 0.0000 1.0000
5.7120 0.0000 1.0000
5.7180 0.0000 1.0000
5.7240 0.0000 1.0000
5.7300 0.0000 1.0000
5.7360 0.0000 1.0000
5.7420 0.0000 1.0000
5.7480 0.0000 1.0000
5.7540 0.0000 1.0000
5.7600 0.0000 1.0000
5.7660 0.0000 1.0000
5.7720 0.0000 1.0000
5.7780 0.0000 1.0000
5.7840 0.0000 1.0000
5.7900 0.0000 1.0000
5.7960 0.0000 1.0000
5.8020 0.0000 1.0000
5.8080 0.0000 1.0000
5.8140 0.0000 1.0000
5.8200 0.0000 1.0000
5.8260 0.0000 1.0000
5.8320 0.0000 1.0000
5.8380 0.0000 1.0000
5.8440 0.0000 1.0000
5.8500 0.0000 1.0000
5.8560 0.0000 1.0000
5.8620 0.0000 1.0000
5.8680 0.0000 1.0000
5.8740 0.0000 1.0000
5.8800 0.0000 1.0000
5.8860 0.0000 1.0000
5.8920 0.0000 1.0000
5.8980 0.0000 1.0000
5.9040 0.0000 1.0000
5.9100 0.0000 1.0000
5.9160 0.0000 1.0000
5.9220 0.0000 1.0000
5.9280 0.0000 1.0000
5.9340 0.0000 1.0000
5.9400 0.0000 1.0000
5.9460 0.0000 1.0000
5.9520 0.0000 1.0000
5.9580 0.0000 1.0000
5.9640 0.0000 1.0000
5.9700 0.0000 1.0000
5.9760 0.0000 1.0000
5.9820 0.0000 1.0000
5.9880 0.0000 1.0000
5.9940 0.0000 1.0000
6.0000 0.0000 1.0000
6.0060 0.0000 1.0000
6.0120 0.0000 1.0000
6.0180 0.0000 1.0000
6.0240 0.0000 1.0000
6.0300 0.0000 1.0000
6.0360 0.0000 1.0000
6.0420 0.0000 1.0000
6.0480 0.0000 1.0000
6.0540 0.0000 1.0000
6.0600 0.0000 1.0000
6.0660 0.0000 1.0000
6.0720 0.0000 1.0000
6.0780 0.0000 1.0000
6.0840 0.0000 1.0000
6.0900 0.0000 1.0000
6.0960 0.0000 1.0000
6.1020 0.0000 1.0000
6.1080 0.0000 1.0000
6.1140 0.0000 1.0000
6.1200 0.0000 1.0000
6.1260 0.0000 1.0000
6.1320 0.0000 1.0000
6.1380 0.0000 1.0000
6.1440 0.0000 1.0000
6.1500 0.0000 1.0000
6.1560 0.0000 1.0000
6.1620 0.0000 1.0000
6.1680 0.0000 1.0000
6.1740 0.3333 1.0000
6.1800 0.0000 1.0000
6.1860 0.0000 1.0000
6.1920 0.0000 1.0000
6.1980 0.0000 1.0000
6.2040 0.0000 1.0000
6.2100 0.0000 1.0000
6.2160 0.0000 1.0000
6.2220 0.0000 1.0000
6.2280 0.0000 1.0000
6.2340 0.0000 1.0000
6.2400 0.0000 1.0000
6.2460 0.0000 1.0000
6.2520 0.0000 1.0000
6.2580 0.0000 1.0000
6.2640 0.0000 1.0000
6.2700 0.0000 1.0000
6.2760 0.0000 1.0000
6.2820 0.0000 1.0000
6.2880 0.0000 1.0000
6.2940 0.0000 1.0000
6.3000 0.0000 1.0000
6.3060 0.0000 1.0000
6.3120 0.0000 1.0000
6.3180 0.0000 1.0000
6.3240 0.0000 1.0000
6.3300 0.0000 1.0000
6.3360 0.0000 1.0000
6.3420 0.0000 1.0000
6.3480 0.0000 1.0000
6.3540 0.0000 1.0000
6.3600 0.0000 1.0000
6.3660 0.0000 1.0000
6.3720 0.0000 1.0000
6.3780 0.0000 1.0000
6.3840 0.0000 1.0000
6.3900 0.0000 1.0000
6.3960 0.0000 1.0000
6.4020 0.0000 1.0000
6.4080 0.0000 1.0000
6.4140 0.0000 1.0000
6.4200 0.0000 1.0000
6.4260 0.0000 1.0000
6.4320 0.0000 1.0000
6.4380 0.0000 1.0000
6.4440 0.0000 1.0000
6.4500 0.0000 1.0000
6.4560 0.0000 1.0000
6.4620 0.0000 1.0000
6.4680 0.0000 1.0000
6.4740 0.0000 1.0000
6.4800 0.0000 1.0000
6.4860 0.0000 1.0000
6.4920 0.0000 1.0000
6.4980 0.0000 1.0000
6.5040 0.0000 1.0000
6.5100 0.0000 1.0000
6.5160 0.0000 1.0000
6.5220 0.0000 1.0000
6.5280 0.0000 1.0000
6.5340 0.0000 1.0000
6.5400 0.0000 1.0000
6.5460 0.0000 1.0000
6.5520 0.0000 1.0000
6.5580 0.0000 1.0000
6.5640 0.0000 1.0000
6.5700 0.0000 1.0000
6.5760 0.0000 1.0000
6.5820 0.0000 1.0000
6.5880 0.0000 1.0000
6.5940 0.0000 1.0000
6.6000 0.0000 1.0000
6.6060 0.0000 1.0000
6.6120 0.0000 1.0000
6.6180 0.0000 1.0000
6.6240 0.0000 1.0000
6.6300 0.0000 1.0000
6.6360 0.0000 1.0000
6.6420 0.0000 1.0000
6.6480 0.0000 1.0000
6.6540 0.0000 1.0000
6.6600 0.0000 1.0000
6.6660 0.0000 1.0000
6.6720 0.0000 1.0000
6.6780 0.0000 1.0000
6.6840 0.0000 1.0000
6.6900 0.0000 1.0000
6.6960 0.0000 1.0000
6.7020 0.0000 1.0000
6.7080 0.0000 1.0000
6.7140 0.0000 1.0000
6.7200 0.0000 1.0000
6.7260 0.0000 1.0000
6.7320 0.0000 1.0000
6.7380 0.0000 1.0000
6.7440 0.0000 1.0000
6.7500 0.0000 1.0000
6.7560 0.0000 1.0000
6.7620 0.0000 1.0000
6.7680 0.0000 1.0000
6.7740 0.0000 1.0000
6.7800 0.0000 1.0000
6.7860 0.0000 1.0000
6.7920 0.0000 1.0000
6.7980 0.0000 1.0000
6.8040 0.0000 1.0000
6.8100 0.0000 1.0000
6.8160 0.0000 1.0000
6.8220 0.0000 1.0000
6.8280 0.0000 1.0000
6.8340 0.0000 1.0000
6.8400 0.0000 1.0000
6.8460 0.0000 1.0000
6.8520 0.0000 1.0000
6.8580 0.0000 1.0000
6.8640 0.0000 1.0000
6.8700 0.0000 1.0000
6.8760 0.0000 1.0000
6.8820 0.0000 1.0000
6.8880 0.0000 1.0000
6.8940 0.0000 1.0000
6.9000 0.0000 1.0000
6.9060 0.0000 1.0000
6.9120 0.0000 1.0000
6.9180 0.0000 1.0000
6.9240 0.0000 1.0000
6.9300 0.0000 1.0000
6.9360 0.0000 1.0000
6.9420 0.0000 1.0000
6.9480 0.0000 1.0000
6.9540 0.0000 1.0000
6.9600 0.0000 1.0000
6.9660 0.0000 1.0000
6.9720 0.0000 1.0000
6.9780 0.0000 1.0000
6.9840 0.0000 1.0000
6.9900 0.0000 1.0000
6.9960 0.0000 1.0000
7.0020 0.0000 1.0000
7.0080 0.0000 1.0000
7.0140 0.0000 1.0000
7.0200 0.0000 1.0000
7.0260 0.0000 1.0000
7.0320 0.0000 1.0000
7.0380 0.0000 1.0000
7.0440 0.0000 1.0000
7.0500 0.0000 1.0000
7.0560 0.0000 1.0000
7.0620 0.0000 1.0000
7.0680 0.0000 1.0000
7.0740 0.0000 1.0000
7.0800 0.0000 1.0000
7.0860 0.0000 1.0000
7.0920 0.0000 1.0000
7.0980 0.0000 1.0000
7.1040 0.0000 1.0000
7.1100 0.0000 1.0000
7.1160 0.0000 1.0000
7.1220 0.0000 1.0000
7.1280 0.0000 1.0000
7.1340 0.0000 1.0000
7.1400 0.0000 1.0000
7.1460 0.0000 1.0000
7.1520 0.0000 1.0000
7.1580 0.0000 1.0000
7.1640 0.0000 1.0000
7.1700 0.0000 1.0000
7.1760 0.0000 1.0000
7.1820 0.0000 1.0000
7.1880 0.0000 1.0000
7.1940 0.0000 1.0000
7.2000 0.0000 1.0000
7.2060 0.0000 1.0000
7.2120 0.0000 1.0000
7.2180 0.0000 1.0000
7.2240 0.0000 1.0000
7.2300 0.0000 1.0000
7.2360 0.0000 1.0000
7.2420 0.0000 1.0000
7.2480 0.0000 1.0000
7.2540 0.0000 1.0000
7.2600 0.0000 1.0000
7.2660 0.0000 1.0000
7.2720 0.0000 1.0000
7.2780 0.0000 1.0000
7.2840 0.0000 1.0000
7.2900 0.0000 1.0000
7.2960 0.0000 1.0000
7.3020 0.0000 1.0000
7.3080 0.0000 1.0000
7.3140 0.0000 1.0000
7.3200 0.0000 1.0000
7.3260 0.0000 1.0000
7.3320 0.0000 1.0000
7.3380 0.0000 1.0000
7.3440 0.0000 1.0000
7.3500 0.0000 1.0000
7.3560 0.0000 1.0000
7.3620 0.0000 1.0000
7.3680 0.0000 1.0000
7.3740 0.0000 1.0000
7.3800 0.0000 1.0000
7.3860 0.0000 1.0000
7.3920 0.0000 1.0000
7.3980 0.0000 1.0000
7.4040 0.0000 1.0000
7.4100 0.0000 1.0000
7.4160 0.0000 1.0000
7.4220 0.0000 1.0000
7.4280 0.0000 1.0000
7.4340 0.0000 1.0000
7.4400 0.0000 1.0000
7.4460 0.0000 1.0000
7.4520 0.0000 1.0000
7.4580 0.0000 1.0000
7.4640 0.0000 1.0000
7.4700 0.0000 1.0000
7.4760 0.0000 1.0000
7.4820 0.0000 1.0000
7.4880 0.0000 1.0000
7.4940 0.0000 1.0000
7.5000 0.0000 1.0000
7.5060 0.0000 1.0000
7.5120 0.0000 1.0000
7.5180 0.0000 1.0000
7.5240 0.0000 1.0000
7.5300 0.0000 1.0000
7.5360 0.0000 1.0000
7.5420 0.0000 1.0000
7.5480 0.0000 1.0000
7.5540 0.0000 1.0000
7.5600 0.0000 1.0000
7.5660 0.0000 1.0000
7.5720 0.0000 1.0000
7.5780 0.0000 1.0000
7.5840 0.0000 1.0000
7.5900 0.0000 1.0000
7.5960 0.0000 1.0000
7.6020 0.0000 1.0000
7.6080 0.0000 1.0000
7.6140 0.0000 1.0000
7.6200 0.0000 1.0000
7.6260 0.0000 1.0000
7.6320 0.0000 1.0000
7.6380 0.0000 1.0000
7.6440 0.0000 1.0000
7.6500 0.0000 1.0000
7.6560 0.0000 1.0000
7.6620 0.0000 1.0000
7.6680 0.0000 1.0000
7.6740 0.0000 1.0000
7.6800 0.0000 1.0000
7.6860 0.0000 1.0000
7.6920 0.0000 1.0000
7.6980 0.0000 1.0000
7.7040 0.0000 1.0000
7.7100 0.0000 1.0000
7.7160 0.0000 1.0000
7.7220 0.0000 1.0000
7.7280 0.0000 1.0000
7.7340 0.0000 1.0000
7.7400 0.0000 1.0000
7.7460 0.0000 1.0000
7.7520 0.0000 1.0000
7.7580 0.0000 1.0000
7.7640 0.0000 1.0000
7.7700 0.0000 1.0000
7.7760 0.0000 1.0000
7.7820 0.0000 1.0000
7.7880 0.0000 1.0000
7.7940 0.0000 1.0000
7.8000 0.0000 1.0000
7.8060 0.0000 1.0000
7.8120 0.0000 1.0000
7.8180 0.0000 1.0000
7.8240 0.0000 1.0000
7.8300 0.0000 1.0000
7.8360 0.0000 1.0000
7.8420 0.0000 1.0000
7.8480 0.0000 1.0000
7.8540 0.0000 1.0000
7.8600 0.0000 1.0000
7.8660 0.0000 1.0000
7.8720 0.0000 1.0000
7.8780 0.0000 1.0000
7.8840 0.0000 1.0000
7.8900 0.0000 1.0000
7.8960 0.0000 1.0000
7.9020 0.0000 1.0000
7.9080 0.0000 1.0000
7.9140 0.0000 1.0000
7.9200 0.0000 1.0000
7.9260 0.0000 1.0000
7.9320 0.0000 1.0000
7.9380 0.0000 1.0000
7.9440 0.0000 1.0000
7.9500 0.0000 1.0000
7.9560 0.0000 1.0000
7.9620 0.0000 1.0000
7.9680 0.0000 1.0000
7.9740 0.0000 1.0000
7.9800 0.0000 1.0000
7.9860 0.0000 1.0000
7.9920 0.0000 1.0000
7.9980 0.0000 1.0000
8.0000 0.0000 1.0000
*RAS_INT_END
*RAS_DATA_END