File: xrr_temp/CWOI9_reflectivity.ras
*RAS_DATA_START
*RAS_HEADER_START
*DISP_FMT_X "%.4f"
*DISP_FMT_Y "%.0f"
*DISP_FULLSCALE "29445813.2500000040"
*DISP_LINE_COLOR "255.0000000000"
*DISP_LINE_STYLE "0.0000000000"
*DISP_LINE_WIDTH "0.2500000000"
*DISP_NOTE "Collected Data-1"
*DISP_OFFSET_Y "0.0000000000"
*DISP_PEAKSEARCH_UNIT_Y "cps"
*DISP_RANGE_BOTTOM "0.0100000000"
*DISP_RANGE_LEFT "-0.0006000000"
*DISP_RANGE_LOGCUTOFF "0.0100000000"
*DISP_RANGE_RIGHT "6.0006000000"
*DISP_RANGE_TOP "29445813.2500000040"
*DISP_SCALE_MODE_Y "2.0000000000"
*DISP_TAB_NAME "2-Theta/Omega"
*DISP_TITLE_Y "Intensity"
*DISP_UNIT_Y "cps"
*DISP_WINDOW_NAME "MSG_MACROENGINE"
*FILE_COMMENT " "
*FILE_MD5 ""
*FILE_MEMO " "
*FILE_OPERATOR "administrator"
*FILE_PART_ID "MEAS_KHP2_00055"
*FILE_SAMPLE "CWO I9"
*FILE_TYPE "RAS_RAW"
*FILE_USERGROUP "System Manager"
*FILE_VERSION "1.0000000000"
*HW_ATTACHMENT_ID "ATT0025"
*HW_ATTACHMENT_NAME "標準|Standard"
*HW_COUNTER_ID-0 "CUT0025"
*HW_COUNTER_ID-1 "CUT0020"
*HW_COUNTER_ID-2 "CUT0020"
*HW_COUNTER_ID-3 "CSL0021"
*HW_COUNTER_ID-4 "CMC0021"
*HW_COUNTER_NAME-0 "D/teX Ultra|D/teX Ultra"
*HW_COUNTER_NAME-1 "None|None"
*HW_COUNTER_NAME-2 "None|None"
*HW_COUNTER_NAME-3 "BBM|BBM"
*HW_COUNTER_NAME-4 "検出器モノクロメータ|Detector monochromator"
*HW_COUNTER_SELECT_NAME "D/teX Ultra|D/teX Ultra"
*HW_GONIOMETER_ID "GON0023"
*HW_GONIOMETER_NAME "SmartLab|SmartLab"
*HW_GONIOMETER_RADIUS-0 "90.0"
*HW_GONIOMETER_RADIUS-1 "114.0"
*HW_GONIOMETER_RADIUS-2 "190.0"
*HW_GONIOMETER_RADIUS-3 "300.0"
*HW_GONIOMETER_RADIUS-4 "187.0"
*HW_GONIOMETER_RADIUS-5 "300.0"
*HW_GONIOMETER_RADIUS-6 "113.0"
*HW_GONIOMETER_RADIUS-7 "331.0"
*HW_I_OPT_ID-0 "CBO0021"
*HW_I_OPT_ID-1 "ICR0021"
*HW_I_OPT_ID-2 "ISL0021"
*HW_I_OPT_ID-3 "ISO0021"
*HW_I_OPT_ID-4 "IAD0021"
*HW_I_OPT_ID-5 "IPR0001"
*HW_I_OPT_NAME-0 "CBOユニット|CBO unit"
*HW_I_OPT_NAME-1 "標準入射光学ユニット|Standard incident optical unit"
*HW_I_OPT_NAME-2 "標準入射スリットボックス|Standard incident slit box"
*HW_I_OPT_NAME-3 "入射平行スリット|Incident parallel slit"
*HW_I_OPT_NAME-4 "長手制限スリット|Length limiting slit"
*HW_I_OPT_NAME-5 "None|None"
*HW_R_ATTENUATER_AUTOMODE "1"
*HW_R_OPT_ID-0 "RSS0021"
*HW_R_OPT_ID-1 "RCR0023"
*HW_R_OPT_ID-2 "RSO0021"
*HW_R_OPT_ID-3 "RRS0021"
*HW_R_OPT_ID-4 "ATN0021"
*HW_R_OPT_ID-5 "RFL0021"
*HW_R_OPT_ID-6 "RAD0021"
*HW_R_OPT_NAME-0 "標準受光スリットボックス1|Standard receiving slit box # 1"
*HW_R_OPT_NAME-1 "標準受光光学ユニット1|Standard receiving unit # 1"
*HW_R_OPT_NAME-2 "標準受光光学ユニット2|Standard receiving optical unit # 2"
*HW_R_OPT_NAME-3 "標準受光スリットボックス2|Standard receiving slit box # 2"
*HW_R_OPT_NAME-4 "標準アッテネータ|Standard Attenuator"
*HW_R_OPT_NAME-5 "Cu Kβ|Cu K-beta"
*HW_R_OPT_NAME-6 "調整用受光スリット|Alignment receiving slit"
*HW_SAMPLE_HOLDER_ID "SMP0021"
*HW_SAMPLE_HOLDER_NAME "χφZクレードル|Chi phi Z cradle"
*HW_XG_CURRENT_MAX "200"
*HW_XG_CURRENT_MIN "10"
*HW_XG_CURRENT_RESOLUTION "1"
*HW_XG_CURRENT_UNIT "mA"
*HW_XG_FOCUS "0.4mm x 8mm"
*HW_XG_FOCUS_TYPE "Normal"
*HW_XG_ID "1700"
*HW_XG_NAME "9kW 開放管(45kV 200mA ID:1700)|9kW Rotating anode(45kV 200mA ID:1700)"
*HW_XG_TARGET_ATOMIC_NUMBER "29.0000000000"
*HW_XG_TARGET_NAME "Cu"
*HW_XG_TYPE "Rota"
*HW_XG_VOLTAGE_MAX "45"
*HW_XG_VOLTAGE_MIN "20"
*HW_XG_VOLTAGE_RESOLUTION "1"
*HW_XG_VOLTAGE_UNIT "kV"
*HW_XG_WATT_MAX "9.00"
*HW_XG_WATT_UNIT "kW"
*HW_XG_WAVE_LENGTH_ALPHA1 "1.540593"
*HW_XG_WAVE_LENGTH_ALPHA2 "1.544414"
*HW_XG_WAVE_LENGTH_BETA "1.392250"
*MEAS_COND_AXIS_NAME-0 "Theta/2-Theta"
*MEAS_COND_AXIS_NAME-1 "2-Theta"
*MEAS_COND_AXIS_NAME-2 "Omega"
*MEAS_COND_AXIS_NAME-3 "Chi"
*MEAS_COND_AXIS_NAME-4 "Phi"
*MEAS_COND_AXIS_NAME-5 "Z"
*MEAS_COND_AXIS_NAME-6 "2-Theta/Omega"
*MEAS_COND_AXIS_NAME-7 "Theta_s"
*MEAS_COND_AXIS_NAME-8 "Theta_d"
*MEAS_COND_AXIS_NAME-9 "Ts"
*MEAS_COND_AXIS_NAME-10 "CBO selection slit"
*MEAS_COND_AXIS_NAME-11 "M"
*MEAS_COND_AXIS_NAME-12 "Incident parallel slit"
*MEAS_COND_AXIS_NAME-13 "Incident slit"
*MEAS_COND_AXIS_NAME-14 ""
*MEAS_COND_AXIS_NAME-15 "Zs"
*MEAS_COND_AXIS_NAME-16 "Incident optical device"
*MEAS_COND_AXIS_NAME-17 "Omega_m"
*MEAS_COND_AXIS_NAME-18 "Length limiting slit"
*MEAS_COND_AXIS_NAME-19 "Center slit"
*MEAS_COND_AXIS_NAME-20 "Filter"
*MEAS_COND_AXIS_NAME-21 "Receiving slit # 1"
*MEAS_COND_AXIS_NAME-22 "Receiving slit # 2"
*MEAS_COND_AXIS_NAME-23 "Receiving optical device"
*MEAS_COND_AXIS_NAME-24 "Receiving parallel slit"
*MEAS_COND_AXIS_NAME-25 "Alignment receiving slit"
*MEAS_COND_AXIS_NAME-26 ""
*MEAS_COND_AXIS_NAME-27 ""
*MEAS_COND_AXIS_NAME-28 "Zd"
*MEAS_COND_AXIS_NAME-29 "Attenuator"
*MEAS_COND_AXIS_NAME-30 "Diffracted beam monochromator"
*MEAS_COND_AXIS_NAME-31 "Monochromator slit"
*MEAS_COND_AXIS_NAME-32 "Primary beam"
*MEAS_COND_AXIS_NAME-33 ""
*MEAS_COND_AXIS_NAME-34 ""
*MEAS_COND_AXIS_NAME-35 "PHA"
*MEAS_COND_AXIS_NAME_INTERNAL-0 "TwoThetaTheta"
*MEAS_COND_AXIS_NAME_INTERNAL-1 "TwoTheta"
*MEAS_COND_AXIS_NAME_INTERNAL-2 "Omega"
*MEAS_COND_AXIS_NAME_INTERNAL-3 "Chi"
*MEAS_COND_AXIS_NAME_INTERNAL-4 "Phi"
*MEAS_COND_AXIS_NAME_INTERNAL-5 "Z"
*MEAS_COND_AXIS_NAME_INTERNAL-6 "TwoThetaOmega"
*MEAS_COND_AXIS_NAME_INTERNAL-7 "ThetaS"
*MEAS_COND_AXIS_NAME_INTERNAL-8 "ThetaD"
*MEAS_COND_AXIS_NAME_INTERNAL-9 "Ts"
*MEAS_COND_AXIS_NAME_INTERNAL-10 "CBO"
*MEAS_COND_AXIS_NAME_INTERNAL-11 "CBO-M"
*MEAS_COND_AXIS_NAME_INTERNAL-12 "IncidentSollerSlit"
*MEAS_COND_AXIS_NAME_INTERNAL-13 "IncidentSlitBox"
*MEAS_COND_AXIS_NAME_INTERNAL-14 "IncidentSlitBox-_Axis"
*MEAS_COND_AXIS_NAME_INTERNAL-15 "Zs"
*MEAS_COND_AXIS_NAME_INTERNAL-16 "IncidentMonochromator"
*MEAS_COND_AXIS_NAME_INTERNAL-17 "IncidentMonochromator-OmegaM"
*MEAS_COND_AXIS_NAME_INTERNAL-18 "IncidentAxdSlit"
*MEAS_COND_AXIS_NAME_INTERNAL-19 "CenterSlit"
*MEAS_COND_AXIS_NAME_INTERNAL-20 "Filter"
*MEAS_COND_AXIS_NAME_INTERNAL-21 "ReceivingSlitBox1"
*MEAS_COND_AXIS_NAME_INTERNAL-22 "ReceivingSlitBox2"
*MEAS_COND_AXIS_NAME_INTERNAL-23 "ReceivingOptics"
*MEAS_COND_AXIS_NAME_INTERNAL-24 "ReceivingSollerSlit"
*MEAS_COND_AXIS_NAME_INTERNAL-25 "ReceivingAxdSlit"
*MEAS_COND_AXIS_NAME_INTERNAL-26 "ReceivingSlitBox1-_Axis"
*MEAS_COND_AXIS_NAME_INTERNAL-27 "ReceivingSlitBox2-_Axis"
*MEAS_COND_AXIS_NAME_INTERNAL-28 "ReceivingSlitBox2-Zd"
*MEAS_COND_AXIS_NAME_INTERNAL-29 "Attenuator"
*MEAS_COND_AXIS_NAME_INTERNAL-30 "CounterMonochromator"
*MEAS_COND_AXIS_NAME_INTERNAL-31 "CounterSlit"
*MEAS_COND_AXIS_NAME_INTERNAL-32 "IncidentPrimary"
*MEAS_COND_AXIS_NAME_INTERNAL-33 "AlphaR"
*MEAS_COND_AXIS_NAME_INTERNAL-34 "BetaR"
*MEAS_COND_AXIS_NAME_INTERNAL-35 "PHA"
*MEAS_COND_AXIS_NAME_MAGICNO-0 "83951616.0000000000"
*MEAS_COND_AXIS_NAME_MAGICNO-1 "268632064.0000000000"
*MEAS_COND_AXIS_NAME_MAGICNO-2 "268500992.0000000000"
*MEAS_COND_AXIS_NAME_MAGICNO-3 "268500992.0000000000"
*MEAS_COND_AXIS_NAME_MAGICNO-4 "268500992.0000000000"
*MEAS_COND_AXIS_NAME_MAGICNO-5 "285278208.0000000000"
*MEAS_COND_AXIS_NAME_MAGICNO-6 "83951616.0000000000"
*MEAS_COND_AXIS_NAME_MAGICNO-7 "131072.0000000000"
*MEAS_COND_AXIS_NAME_MAGICNO-8 "131072.0000000000"
*MEAS_COND_AXIS_NAME_MAGICNO-9 "318898176.0000000000"
*MEAS_COND_AXIS_NAME_MAGICNO-10 "20971521.0000000000"
*MEAS_COND_AXIS_NAME_MAGICNO-11 "285343744.0000000000"
*MEAS_COND_AXIS_NAME_MAGICNO-12 "20971521.0000000000"
*MEAS_COND_AXIS_NAME_MAGICNO-13 "22020097.0000000000"
*MEAS_COND_AXIS_NAME_MAGICNO-14 "25165824.0000000000"
*MEAS_COND_AXIS_NAME_MAGICNO-15 "318898176.0000000000"
*MEAS_COND_AXIS_NAME_MAGICNO-16 "20971521.0000000000"
*MEAS_COND_AXIS_NAME_MAGICNO-17 "285343744.0000000000"
*MEAS_COND_AXIS_NAME_MAGICNO-18 "20971521.0000000000"
*MEAS_COND_AXIS_NAME_MAGICNO-19 "20971521.0000000000"
*MEAS_COND_AXIS_NAME_MAGICNO-20 "20971521.0000000000"
*MEAS_COND_AXIS_NAME_MAGICNO-21 "23068673.0000000000"
*MEAS_COND_AXIS_NAME_MAGICNO-22 "23068673.0000000000"
*MEAS_COND_AXIS_NAME_MAGICNO-23 "20971521.0000000000"
*MEAS_COND_AXIS_NAME_MAGICNO-24 "20971521.0000000000"
*MEAS_COND_AXIS_NAME_MAGICNO-25 "20971521.0000000000"
*MEAS_COND_AXIS_NAME_MAGICNO-26 "25165824.0000000000"
*MEAS_COND_AXIS_NAME_MAGICNO-27 "25165824.0000000000"
*MEAS_COND_AXIS_NAME_MAGICNO-28 "285343744.0000000000"
*MEAS_COND_AXIS_NAME_MAGICNO-29 "17301505.0000000000"
*MEAS_COND_AXIS_NAME_MAGICNO-30 "20971521.0000000000"
*MEAS_COND_AXIS_NAME_MAGICNO-31 "20971521.0000000000"
*MEAS_COND_AXIS_NAME_MAGICNO-32 "20971521.0000000000"
*MEAS_COND_AXIS_NAME_MAGICNO-33 "8388608.0000000000"
*MEAS_COND_AXIS_NAME_MAGICNO-34 "8388608.0000000000"
*MEAS_COND_AXIS_NAME_MAGICNO-35 "0.0000000000"
*MEAS_COND_AXIS_OFFSET-0 "-"
*MEAS_COND_AXIS_OFFSET-1 "0.9127000000"
*MEAS_COND_AXIS_OFFSET-2 "0.6957000000"
*MEAS_COND_AXIS_OFFSET-3 "0.0000000000"
*MEAS_COND_AXIS_OFFSET-4 "0.0000000000"
*MEAS_COND_AXIS_OFFSET-5 "-"
*MEAS_COND_AXIS_OFFSET-6 "-"
*MEAS_COND_AXIS_OFFSET-7 "0.6957000000"
*MEAS_COND_AXIS_OFFSET-8 "0.2170000000"
*MEAS_COND_AXIS_OFFSET-9 "-"
*MEAS_COND_AXIS_OFFSET-10 "-"
*MEAS_COND_AXIS_OFFSET-11 "-"
*MEAS_COND_AXIS_OFFSET-12 "-"
*MEAS_COND_AXIS_OFFSET-13 "-"
*MEAS_COND_AXIS_OFFSET-14 "-"
*MEAS_COND_AXIS_OFFSET-15 "-"
*MEAS_COND_AXIS_OFFSET-16 "-"
*MEAS_COND_AXIS_OFFSET-17 "-"
*MEAS_COND_AXIS_OFFSET-18 "-"
*MEAS_COND_AXIS_OFFSET-19 "-"
*MEAS_COND_AXIS_OFFSET-20 "-"
*MEAS_COND_AXIS_OFFSET-21 "-"
*MEAS_COND_AXIS_OFFSET-22 "-"
*MEAS_COND_AXIS_OFFSET-23 "-"
*MEAS_COND_AXIS_OFFSET-24 "-"
*MEAS_COND_AXIS_OFFSET-25 "-"
*MEAS_COND_AXIS_OFFSET-26 "-"
*MEAS_COND_AXIS_OFFSET-27 "-"
*MEAS_COND_AXIS_OFFSET-28 "-"
*MEAS_COND_AXIS_OFFSET-29 "-"
*MEAS_COND_AXIS_OFFSET-30 "-"
*MEAS_COND_AXIS_OFFSET-31 "-"
*MEAS_COND_AXIS_OFFSET-32 "-"
*MEAS_COND_AXIS_OFFSET-33 "0.0000000000"
*MEAS_COND_AXIS_OFFSET-34 "0.0000000000"
*MEAS_COND_AXIS_OFFSET-35 "-"
*MEAS_COND_AXIS_POSITION-0 "-0.0008000000"
*MEAS_COND_AXIS_POSITION-1 "-0.0008000000"
*MEAS_COND_AXIS_POSITION-2 "-0.0004000000"
*MEAS_COND_AXIS_POSITION-3 "0.0000000000"
*MEAS_COND_AXIS_POSITION-4 "0.0000000000"
*MEAS_COND_AXIS_POSITION-5 "-1.4113000000"
*MEAS_COND_AXIS_POSITION-6 "-0.0008000000"
*MEAS_COND_AXIS_POSITION-7 "-0.0004000000"
*MEAS_COND_AXIS_POSITION-8 "-0.0004000000"
*MEAS_COND_AXIS_POSITION-9 "-4.8793100000"
*MEAS_COND_AXIS_POSITION-10 "PB"
*MEAS_COND_AXIS_POSITION-11 "0.0000000000"
*MEAS_COND_AXIS_POSITION-12 "Soller_slit_open_s"
*MEAS_COND_AXIS_POSITION-13 "0.250mm"
*MEAS_COND_AXIS_POSITION-14 "0.2500000000"
*MEAS_COND_AXIS_POSITION-15 "-1.7884400000"
*MEAS_COND_AXIS_POSITION-16 "Ge(220)x2"
*MEAS_COND_AXIS_POSITION-17 "0.0000000000"
*MEAS_COND_AXIS_POSITION-18 "2.0mm"
*MEAS_COND_AXIS_POSITION-19 "None"
*MEAS_COND_AXIS_POSITION-20 "None"
*MEAS_COND_AXIS_POSITION-21 "0.250mm"
*MEAS_COND_AXIS_POSITION-22 "0.250mm"
*MEAS_COND_AXIS_POSITION-23 "No_unit"
*MEAS_COND_AXIS_POSITION-24 "Soller_slit_5.0deg"
*MEAS_COND_AXIS_POSITION-25 "None"
*MEAS_COND_AXIS_POSITION-26 "0.2500000000"
*MEAS_COND_AXIS_POSITION-27 "0.2500000000"
*MEAS_COND_AXIS_POSITION-28 "0.0868700000"
*MEAS_COND_AXIS_POSITION-29 "1/10000"
*MEAS_COND_AXIS_POSITION-30 "None"
*MEAS_COND_AXIS_POSITION-31 "None"
*MEAS_COND_AXIS_POSITION-32 "None"
*MEAS_COND_AXIS_POSITION-33 "0.0000000000"
*MEAS_COND_AXIS_POSITION-34 "0.0000000000"
*MEAS_COND_AXIS_POSITION-35 "34.0000000000"
*MEAS_COND_AXIS_UNIT-0 "deg"
*MEAS_COND_AXIS_UNIT-1 "deg"
*MEAS_COND_AXIS_UNIT-2 "deg"
*MEAS_COND_AXIS_UNIT-3 "deg"
*MEAS_COND_AXIS_UNIT-4 "deg"
*MEAS_COND_AXIS_UNIT-5 "mm"
*MEAS_COND_AXIS_UNIT-6 "deg"
*MEAS_COND_AXIS_UNIT-7 "deg"
*MEAS_COND_AXIS_UNIT-8 "deg"
*MEAS_COND_AXIS_UNIT-9 "mm"
*MEAS_COND_AXIS_UNIT-10 ""
*MEAS_COND_AXIS_UNIT-11 "pulse"
*MEAS_COND_AXIS_UNIT-12 ""
*MEAS_COND_AXIS_UNIT-13 ""
*MEAS_COND_AXIS_UNIT-14 "mm"
*MEAS_COND_AXIS_UNIT-15 "mm"
*MEAS_COND_AXIS_UNIT-16 ""
*MEAS_COND_AXIS_UNIT-17 "pulse"
*MEAS_COND_AXIS_UNIT-18 ""
*MEAS_COND_AXIS_UNIT-19 ""
*MEAS_COND_AXIS_UNIT-20 ""
*MEAS_COND_AXIS_UNIT-21 ""
*MEAS_COND_AXIS_UNIT-22 ""
*MEAS_COND_AXIS_UNIT-23 ""
*MEAS_COND_AXIS_UNIT-24 ""
*MEAS_COND_AXIS_UNIT-25 ""
*MEAS_COND_AXIS_UNIT-26 "mm"
*MEAS_COND_AXIS_UNIT-27 "mm"
*MEAS_COND_AXIS_UNIT-28 "mm"
*MEAS_COND_AXIS_UNIT-29 ""
*MEAS_COND_AXIS_UNIT-30 ""
*MEAS_COND_AXIS_UNIT-31 ""
*MEAS_COND_AXIS_UNIT-32 ""
*MEAS_COND_AXIS_UNIT-33 "deg"
*MEAS_COND_AXIS_UNIT-34 "deg"
*MEAS_COND_AXIS_UNIT-35 "div"
*MEAS_COND_COUNTER_CNTLOSS_CORR "0.0000000000"
*MEAS_COND_COUNTER_PHABASE "34.0000000000"
*MEAS_COND_COUNTER_PHAWINDOW "19.0000000000"
*MEAS_COND_COUNTER_PHA_UNIT "div"
*MEAS_COND_COUNTER_TAUDIFF "2.0000000000"
*MEAS_COND_COUNTER_TAUINT "0.1000000000"
*MEAS_COND_IRRADIATION_MODE "OFF"
*MEAS_COND_IRRADIATION_WIDTH ""
*MEAS_COND_OPT_ATTR "High resolution parallel beam Ge(220)x2/RS"
*MEAS_COND_OPT_NAME "@High resolution PB-Ge(220)x2"
*MEAS_COND_UNSYMMETRIC_MODE "OFF"
*MEAS_COND_XG_CURRENT "200.0000000000"
*MEAS_COND_XG_VOLTAGE "45.0000000000"
*MEAS_COND_XG_WAVE_TYPE "Ka1"
*MEAS_DATA_COUNT "3001.0000000000"
*MEAS_SCAN_AXIS_X "2-Theta/Omega"
*MEAS_SCAN_AXIS_X_INTERNAL "TwoThetaOmega"
*MEAS_SCAN_END_TIME "11/06/23 13:48:04"
*MEAS_SCAN_MODE "CONTINUOUS"
*MEAS_SCAN_MONITOR "0"
*MEAS_SCAN_RESOLUTION_X "0.0002"
*MEAS_SCAN_SPEED "0.500000"
*MEAS_SCAN_SPEED_UNIT "deg/min"
*MEAS_SCAN_SPEED_USER "0.500000"
*MEAS_SCAN_START "0.0000000000"
*MEAS_SCAN_START_TIME "11/06/23 13:35:33"
*MEAS_SCAN_STEP "0.0020000000"
*MEAS_SCAN_STOP "6.0000000000"
*MEAS_SCAN_UNIT_X "deg"
*MEAS_SCAN_UNIT_Y "counts"
*RAS_HEADER_END
*RAS_INT_START
0.0000 5352104.0000 1.0000
0.0060 5620771.0000 1.0000
0.0120 5501057.5000 1.0000
0.0180 5329899.0000 1.0000
0.0240 5293074.5000 1.0000
0.0300 5046750.5000 1.0000
0.0360 4315639.0000 1.0000
0.0420 3542186.5000 1.0000
0.0480 2577025.7500 1.0000
0.0540 1766748.7500 1.0000
0.0600 1022463.3125 1.0000
0.0660 546290.0625 1.0000
0.0720 280183.0938 1.0000
0.0780 160669.5938 1.0000
0.0840 111805.1250 1.0000
0.0900 87317.0313 1.0000
0.0960 79787.3906 1.0000
0.1020 76651.8984 1.0000
0.1080 79407.5547 1.0000
0.1140 80301.2813 1.0000
0.1200 85738.1172 1.0000
0.1260 85447.6563 1.0000
0.1320 92820.8906 1.0000
0.1380 95405.2500 1.0000
0.1440 98704.5859 1.0000
0.1500 106964.1016 1.0000
0.1560 107761.0156 1.0000
0.1620 112140.2734 1.0000
0.1680 115134.2500 1.0000
0.1740 117651.5781 1.0000
0.1800 124942.8984 1.0000
0.1860 131325.5938 1.0000
0.1920 134446.1875 1.0000
0.1980 136814.5469 1.0000
0.2040 141908.7969 1.0000
0.2100 144321.8594 1.0000
0.2160 151449.3125 1.0000
0.2220 151814.2656 1.0000
0.2280 157720.2969 1.0000
0.2340 157653.2656 1.0000
0.2400 167320.4063 1.0000
0.2460 173546.6875 1.0000
0.2520 171610.2813 1.0000
0.2580 173308.3750 1.0000
0.2640 179050.5469 1.0000
0.2700 186922.7969 1.0000
0.2760 185708.8125 1.0000
0.2820 193491.6719 1.0000
0.2880 195308.9219 1.0000
0.2940 195361.0625 1.0000
0.3000 200589.3594 1.0000
0.3060 202093.7969 1.0000
0.3120 203389.6875 1.0000
0.3180 214077.1719 1.0000
0.3240 220236.4219 1.0000
0.3300 220623.7031 1.0000
0.3360 218374.5000 1.0000
0.3420 223126.1406 1.0000
0.3480 231638.8906 1.0000
0.3540 230827.0781 1.0000
0.3600 227684.1406 1.0000
0.3660 240471.8750 1.0000
0.3720 241119.8281 1.0000
0.3780 239913.2969 1.0000
0.3840 241112.3750 1.0000
0.3900 256030.1563 1.0000
0.3960 250451.8125 1.0000
0.4020 259940.2188 1.0000
0.4080 257139.8594 1.0000
0.4140 267559.2188 1.0000
0.4200 271216.0625 1.0000
0.4260 266941.0625 1.0000
0.4320 275349.5313 1.0000
0.4380 281665.1875 1.0000
0.4440 280369.3125 1.0000
0.4500 281851.3750 1.0000
0.4560 285642.2813 1.0000
0.4620 289224.6250 1.0000
0.4680 287280.7813 1.0000
0.4740 294020.9375 1.0000
0.4800 301528.2500 1.0000
0.4860 298847.0938 1.0000
0.4920 301230.3438 1.0000
0.4980 305058.4688 1.0000
0.5040 300269.5938 1.0000
0.5100 312074.2188 1.0000
0.5160 315634.2500 1.0000
0.5220 313161.5938 1.0000
0.5280 305296.7813 1.0000
0.5340 316624.7813 1.0000
0.5400 318397.3438 1.0000
0.5460 319082.5313 1.0000
0.5520 325703.5313 1.0000
0.5580 323439.4375 1.0000
0.5640 329278.4375 1.0000
0.5700 326262.1250 1.0000
0.5760 326641.9688 1.0000
0.5820 334871.6875 1.0000
0.5880 341403.3438 1.0000
0.5940 326828.1563 1.0000
0.6000 330149.8438 1.0000
0.6060 327893.1875 1.0000
0.6120 335534.5313 1.0000
0.6180 316230.0625 1.0000
0.6240 321637.0938 1.0000
0.6300 311016.6563 1.0000
0.6360 310227.1875 1.0000
0.6420 291324.8750 1.0000
0.6480 284458.0938 1.0000
0.6540 284688.9688 1.0000
0.6600 264081.1250 1.0000
0.6660 250935.9219 1.0000
0.6720 236033.0469 1.0000
0.6780 220147.0469 1.0000
0.6840 207150.7969 1.0000
0.6900 189611.4219 1.0000
0.6960 176160.8438 1.0000
0.7020 158978.9531 1.0000
0.7080 147189.2188 1.0000
0.7140 131072.3750 1.0000
0.7200 116958.9453 1.0000
0.7260 103337.0703 1.0000
0.7320 97252.2891 1.0000
0.7380 86319.0391 1.0000
0.7440 81783.3750 1.0000
0.7500 74134.5703 1.0000
0.7560 63104.5039 1.0000
0.7620 60728.6836 1.0000
0.7680 57779.3867 1.0000
0.7740 57395.1680 1.0000
0.7800 54342.3320 1.0000
0.7860 52745.0000 1.0000
0.7920 50842.6680 1.0000
0.7980 48647.6680 1.0000
0.8040 46555.6680 1.0000
0.8100 45369.6680 1.0000
0.8160 43954.6680 1.0000
0.8220 42542.1680 1.0000
0.8280 40944.6680 1.0000
0.8340 39341.5000 1.0000
0.8400 38215.1680 1.0000
0.8460 36983.5000 1.0000
0.8520 35344.3320 1.0000
0.8580 33610.0000 1.0000
0.8640 32359.5000 1.0000
0.8700 30978.6660 1.0000
0.8760 29600.3340 1.0000
0.8820 28133.6660 1.0000
0.8880 26864.0000 1.0000
0.8940 25446.8340 1.0000
0.9000 24554.6660 1.0000
0.9060 22960.1660 1.0000
0.9120 21783.8340 1.0000
0.9180 20584.3340 1.0000
0.9240 20181.3340 1.0000
0.9300 19004.1660 1.0000
0.9360 18454.3340 1.0000
0.9420 17898.8340 1.0000
0.9480 16770.6660 1.0000
0.9540 16642.3340 1.0000
0.9600 16008.6670 1.0000
0.9660 15777.6670 1.0000
0.9720 15228.8330 1.0000
0.9780 14828.5000 1.0000
0.9840 14678.6670 1.0000
0.9900 14261.3330 1.0000
0.9960 14046.6670 1.0000
1.0020 13813.6670 1.0000
1.0080 13853.8330 1.0000
1.0140 13718.5000 1.0000
1.0200 13323.3330 1.0000
1.0260 13152.5000 1.0000
1.0320 12938.0000 1.0000
1.0380 12973.1670 1.0000
1.0440 12499.0000 1.0000
1.0500 12529.8330 1.0000
1.0560 12236.8330 1.0000
1.0620 12184.3330 1.0000
1.0680 11719.8330 1.0000
1.0740 11514.3330 1.0000
1.0800 11418.5000 1.0000
1.0860 10985.8330 1.0000
1.0920 10672.0000 1.0000
1.0980 10404.3330 1.0000
1.1040 10218.1670 1.0000
1.1100 9665.0000 1.0000
1.1160 9602.0000 1.0000
1.1220 9115.8330 1.0000
1.1280 8904.5000 1.0000
1.1340 8525.1670 1.0000
1.1400 8303.0000 1.0000
1.1460 7833.3335 1.0000
1.1520 7698.6665 1.0000
1.1580 7302.3335 1.0000
1.1640 7034.3335 1.0000
1.1700 6976.6665 1.0000
1.1760 6630.8335 1.0000
1.1820 6425.5000 1.0000
1.1880 6093.8335 1.0000
1.1940 5908.1665 1.0000
1.2000 5936.5000 1.0000
1.2060 5639.8335 1.0000
1.2120 5491.8335 1.0000
1.2180 5405.3335 1.0000
1.2240 5424.3335 1.0000
1.2300 5321.0000 1.0000
1.2360 5287.0000 1.0000
1.2420 5095.5000 1.0000
1.2480 5155.1665 1.0000
1.2540 5019.3335 1.0000
1.2600 4989.0000 1.0000
1.2660 4829.8335 1.0000
1.2720 5002.8335 1.0000
1.2780 4907.6665 1.0000
1.2840 4828.6665 1.0000
1.2900 5000.3335 1.0000
1.2960 4838.3335 1.0000
1.3020 4922.1665 1.0000
1.3080 4969.5000 1.0000
1.3140 4761.5000 1.0000
1.3200 4835.1665 1.0000
1.3260 4742.0000 1.0000
1.3320 4742.5000 1.0000
1.3380 4572.3335 1.0000
1.3440 4653.1665 1.0000
1.3500 4624.6665 1.0000
1.3560 4535.3335 1.0000
1.3620 4427.3335 1.0000
1.3680 4341.0000 1.0000
1.3740 4280.0000 1.0000
1.3800 4044.1667 1.0000
1.3860 4004.5000 1.0000
1.3920 3877.8333 1.0000
1.3980 3835.5000 1.0000
1.4040 3785.5000 1.0000
1.4100 3524.0000 1.0000
1.4160 3385.3333 1.0000
1.4220 3255.8333 1.0000
1.4280 3230.5000 1.0000
1.4340 3113.1667 1.0000
1.4400 3037.3333 1.0000
1.4460 2928.6667 1.0000
1.4520 2773.8333 1.0000
1.4580 2694.8333 1.0000
1.4640 2622.1667 1.0000
1.4700 2567.8333 1.0000
1.4760 2443.1667 1.0000
1.4820 2424.3333 1.0000
1.4880 2266.0000 1.0000
1.4940 2235.3333 1.0000
1.5000 2221.0000 1.0000
1.5060 2117.5000 1.0000
1.5120 2084.5000 1.0000
1.5180 2086.3333 1.0000
1.5240 2121.6667 1.0000
1.5300 2015.0000 1.0000
1.5360 2056.5000 1.0000
1.5420 2008.1666 1.0000
1.5480 2044.6666 1.0000
1.5540 2005.6666 1.0000
1.5600 2116.3333 1.0000
1.5660 2013.3334 1.0000
1.5720 2099.8333 1.0000
1.5780 2063.0000 1.0000
1.5840 2079.3333 1.0000
1.5900 2056.0000 1.0000
1.5960 2204.3333 1.0000
1.6020 2037.6666 1.0000
1.6080 2098.1667 1.0000
1.6140 2160.5000 1.0000
1.6200 2101.1667 1.0000
1.6260 2132.0000 1.0000
1.6320 2146.1667 1.0000
1.6380 2081.0000 1.0000
1.6440 2130.0000 1.0000
1.6500 2044.6666 1.0000
1.6560 2041.5000 1.0000
1.6620 2039.6666 1.0000
1.6680 1952.1666 1.0000
1.6740 1898.0000 1.0000
1.6800 1937.6666 1.0000
1.6860 1918.0000 1.0000
1.6920 1804.0000 1.0000
1.6980 1765.8334 1.0000
1.7040 1716.3334 1.0000
1.7100 1691.3334 1.0000
1.7160 1688.3334 1.0000
1.7220 1581.8334 1.0000
1.7280 1491.6666 1.0000
1.7340 1498.1666 1.0000
1.7400 1419.3334 1.0000
1.7460 1399.8334 1.0000
1.7520 1299.8334 1.0000
1.7580 1248.8334 1.0000
1.7640 1209.3334 1.0000
1.7700 1218.0000 1.0000
1.7760 1188.8334 1.0000
1.7820 1096.3334 1.0000
1.7880 1107.0000 1.0000
1.7940 1048.3334 1.0000
1.8000 983.6667 1.0000
1.8060 921.8333 1.0000
1.8120 915.0000 1.0000
1.8180 910.1667 1.0000
1.8240 944.6667 1.0000
1.8300 916.0000 1.0000
1.8360 913.3333 1.0000
1.8420 900.0000 1.0000
1.8480 918.6667 1.0000
1.8540 875.0000 1.0000
1.8600 897.3333 1.0000
1.8660 922.0000 1.0000
1.8720 1004.6667 1.0000
1.8780 890.5000 1.0000
1.8840 954.1667 1.0000
1.8900 945.1667 1.0000
1.8960 933.8333 1.0000
1.9020 941.3333 1.0000
1.9080 926.5000 1.0000
1.9140 1059.6666 1.0000
1.9200 1005.8333 1.0000
1.9260 999.3333 1.0000
1.9320 1045.0000 1.0000
1.9380 1048.6666 1.0000
1.9440 1058.5000 1.0000
1.9500 1014.1667 1.0000
1.9560 1004.0000 1.0000
1.9620 1016.0000 1.0000
1.9680 1034.1666 1.0000
1.9740 1017.6667 1.0000
1.9800 998.1667 1.0000
1.9860 1010.1667 1.0000
1.9920 984.1667 1.0000
1.9980 922.8333 1.0000
2.0040 1018.6667 1.0000
2.0100 985.0000 1.0000
2.0160 889.8333 1.0000
2.0220 892.8333 1.0000
2.0280 854.0000 1.0000
2.0340 889.6667 1.0000
2.0400 801.1667 1.0000
2.0460 804.1667 1.0000
2.0520 783.6667 1.0000
2.0580 763.8333 1.0000
2.0640 713.1667 1.0000
2.0700 653.6667 1.0000
2.0760 668.8333 1.0000
2.0820 620.3333 1.0000
2.0880 629.3333 1.0000
2.0940 609.0000 1.0000
2.1000 646.5000 1.0000
2.1060 533.0000 1.0000
2.1120 479.8333 1.0000
2.1180 475.5000 1.0000
2.1240 500.8333 1.0000
2.1300 463.0000 1.0000
2.1360 436.6667 1.0000
2.1420 458.1667 1.0000
2.1480 500.3333 1.0000
2.1540 464.3333 1.0000
2.1600 448.1667 1.0000
2.1660 424.5000 1.0000
2.1720 459.3333 1.0000
2.1780 446.6667 1.0000
2.1840 474.5000 1.0000
2.1900 463.1667 1.0000
2.1960 452.6667 1.0000
2.2020 496.8333 1.0000
2.2080 472.6667 1.0000
2.2140 503.6667 1.0000
2.2200 501.1667 1.0000
2.2260 495.0000 1.0000
2.2320 505.3333 1.0000
2.2380 535.5000 1.0000
2.2440 511.8333 1.0000
2.2500 538.1667 1.0000
2.2560 542.3333 1.0000
2.2620 583.8333 1.0000
2.2680 529.8333 1.0000
2.2740 538.1667 1.0000
2.2800 532.5000 1.0000
2.2860 534.8333 1.0000
2.2920 547.0000 1.0000
2.2980 550.5000 1.0000
2.3040 580.5000 1.0000
2.3100 538.8333 1.0000
2.3160 551.1667 1.0000
2.3220 584.3333 1.0000
2.3280 522.8333 1.0000
2.3340 489.3333 1.0000
2.3400 557.1667 1.0000
2.3460 525.8333 1.0000
2.3520 533.1667 1.0000
2.3580 449.6667 1.0000
2.3640 453.5000 1.0000
2.3700 470.8333 1.0000
2.3760 453.5000 1.0000
2.3820 429.5000 1.0000
2.3880 420.3333 1.0000
2.3940 397.0000 1.0000
2.4000 365.0000 1.0000
2.4060 372.3333 1.0000
2.4120 341.5000 1.0000
2.4180 345.6667 1.0000
2.4240 343.0000 1.0000
2.4300 314.8333 1.0000
2.4360 315.5000 1.0000
2.4420 288.3333 1.0000
2.4480 247.8333 1.0000
2.4540 292.0000 1.0000
2.4600 270.5000 1.0000
2.4660 242.1667 1.0000
2.4720 244.3333 1.0000
2.4780 250.3333 1.0000
2.4840 232.8333 1.0000
2.4900 267.5000 1.0000
2.4960 239.3333 1.0000
2.5020 245.1667 1.0000
2.5080 216.3333 1.0000
2.5140 250.8333 1.0000
2.5200 225.5000 1.0000
2.5260 242.1667 1.0000
2.5320 257.3333 1.0000
2.5380 265.3333 1.0000
2.5440 249.3333 1.0000
2.5500 260.6667 1.0000
2.5560 267.8333 1.0000
2.5620 279.8333 1.0000
2.5680 272.3333 1.0000
2.5740 305.5000 1.0000
2.5800 315.1667 1.0000
2.5860 280.8333 1.0000
2.5920 253.0000 1.0000
2.5980 302.3333 1.0000
2.6040 277.1667 1.0000
2.6100 277.1667 1.0000
2.6160 302.3333 1.0000
2.6220 314.8333 1.0000
2.6280 312.1667 1.0000
2.6340 294.6667 1.0000
2.6400 308.1667 1.0000
2.6460 294.0000 1.0000
2.6520 295.1667 1.0000
2.6580 269.0000 1.0000
2.6640 295.8333 1.0000
2.6700 289.5000 1.0000
2.6760 281.5000 1.0000
2.6820 299.0000 1.0000
2.6880 281.8333 1.0000
2.6940 265.8333 1.0000
2.7000 251.1667 1.0000
2.7060 253.5000 1.0000
2.7120 261.6667 1.0000
2.7180 231.5000 1.0000
2.7240 229.5000 1.0000
2.7300 203.1667 1.0000
2.7360 209.6667 1.0000
2.7420 211.5000 1.0000
2.7480 205.6667 1.0000
2.7540 198.1667 1.0000
2.7600 205.1667 1.0000
2.7660 195.6667 1.0000
2.7720 153.6667 1.0000
2.7780 171.6667 1.0000
2.7840 160.0000 1.0000
2.7900 164.1667 1.0000
2.7960 142.6667 1.0000
2.8020 162.3333 1.0000
2.8080 146.3333 1.0000
2.8140 142.5000 1.0000
2.8200 128.6667 1.0000
2.8260 115.5000 1.0000
2.8320 136.6667 1.0000
2.8380 125.8333 1.0000
2.8440 146.5000 1.0000
2.8500 134.5000 1.0000
2.8560 132.3333 1.0000
2.8620 136.6667 1.0000
2.8680 157.3333 1.0000
2.8740 133.0000 1.0000
2.8800 160.6667 1.0000
2.8860 135.3333 1.0000
2.8920 135.1667 1.0000
2.8980 173.1667 1.0000
2.9040 160.0000 1.0000
2.9100 138.8333 1.0000
2.9160 161.1667 1.0000
2.9220 156.8333 1.0000
2.9280 154.8333 1.0000
2.9340 187.1667 1.0000
2.9400 142.0000 1.0000
2.9460 176.6667 1.0000
2.9520 174.1667 1.0000
2.9580 177.1667 1.0000
2.9640 161.1667 1.0000
2.9700 180.3333 1.0000
2.9760 169.5000 1.0000
2.9820 165.8333 1.0000
2.9880 174.3333 1.0000
2.9940 141.5000 1.0000
3.0000 162.5000 1.0000
3.0060 163.3333 1.0000
3.0120 155.3333 1.0000
3.0180 147.1667 1.0000
3.0240 147.3333 1.0000
3.0300 148.0000 1.0000
3.0360 140.3333 1.0000
3.0420 148.8333 1.0000
3.0480 136.0000 1.0000
3.0540 152.6667 1.0000
3.0600 137.1667 1.0000
3.0660 140.1667 1.0000
3.0720 140.1667 1.0000
3.0780 101.3333 1.0000
3.0840 114.1667 1.0000
3.0900 101.6667 1.0000
3.0960 97.8333 1.0000
3.1020 97.3333 1.0000
3.1080 109.5000 1.0000
3.1140 94.5000 1.0000
3.1200 88.5000 1.0000
3.1260 84.6667 1.0000
3.1320 89.8333 1.0000
3.1380 97.1667 1.0000
3.1440 85.8333 1.0000
3.1500 84.8333 1.0000
3.1560 87.1667 1.0000
3.1620 72.8333 1.0000
3.1680 86.1667 1.0000
3.1740 73.8333 1.0000
3.1800 74.3333 1.0000
3.1860 71.6667 1.0000
3.1920 78.3333 1.0000
3.1980 93.0000 1.0000
3.2040 75.0000 1.0000
3.2100 89.5000 1.0000
3.2160 86.5000 1.0000
3.2220 83.0000 1.0000
3.2280 83.5000 1.0000
3.2340 86.5000 1.0000
3.2400 83.6667 1.0000
3.2460 89.0000 1.0000
3.2520 98.1667 1.0000
3.2580 102.5000 1.0000
3.2640 92.0000 1.0000
3.2700 99.1667 1.0000
3.2760 99.1667 1.0000
3.2820 109.5000 1.0000
3.2880 104.3333 1.0000
3.2940 100.0000 1.0000
3.3000 107.3333 1.0000
3.3060 95.0000 1.0000
3.3120 80.6667 1.0000
3.3180 107.5000 1.0000
3.3240 100.0000 1.0000
3.3300 108.0000 1.0000
3.3360 99.1667 1.0000
3.3420 99.0000 1.0000
3.3480 87.3333 1.0000
3.3540 93.5000 1.0000
3.3600 79.5000 1.0000
3.3660 96.8333 1.0000
3.3720 91.1667 1.0000
3.3780 75.3333 1.0000
3.3840 76.1667 1.0000
3.3900 86.0000 1.0000
3.3960 67.6667 1.0000
3.4020 70.0000 1.0000
3.4080 83.1667 1.0000
3.4140 80.5000 1.0000
3.4200 63.1667 1.0000
3.4260 69.0000 1.0000
3.4320 66.6667 1.0000
3.4380 56.6667 1.0000
3.4440 59.3333 1.0000
3.4500 65.0000 1.0000
3.4560 50.3333 1.0000
3.4620 48.6667 1.0000
3.4680 51.1667 1.0000
3.4740 43.0000 1.0000
3.4800 36.0000 1.0000
3.4860 50.1667 1.0000
3.4920 33.6667 1.0000
3.4980 44.6667 1.0000
3.5040 50.5000 1.0000
3.5100 47.1667 1.0000
3.5160 49.1667 1.0000
3.5220 47.5000 1.0000
3.5280 44.0000 1.0000
3.5340 46.1667 1.0000
3.5400 48.6667 1.0000
3.5460 51.3333 1.0000
3.5520 40.3333 1.0000
3.5580 48.5000 1.0000
3.5640 51.8333 1.0000
3.5700 60.6667 1.0000
3.5760 50.0000 1.0000
3.5820 53.6667 1.0000
3.5880 67.5000 1.0000
3.5940 59.0000 1.0000
3.6000 44.0000 1.0000
3.6060 72.8333 1.0000
3.6120 57.3333 1.0000
3.6180 64.1667 1.0000
3.6240 45.6667 1.0000
3.6300 61.3333 1.0000
3.6360 52.3333 1.0000
3.6420 55.3333 1.0000
3.6480 52.6667 1.0000
3.6540 68.5000 1.0000
3.6600 62.1667 1.0000
3.6660 45.8333 1.0000
3.6720 56.1667 1.0000
3.6780 62.3333 1.0000
3.6840 50.0000 1.0000
3.6900 44.0000 1.0000
3.6960 71.8333 1.0000
3.7020 57.0000 1.0000
3.7080 60.6667 1.0000
3.7140 50.0000 1.0000
3.7200 31.1667 1.0000
3.7260 58.3333 1.0000
3.7320 47.6667 1.0000
3.7380 41.0000 1.0000
3.7440 50.8333 1.0000
3.7500 48.1667 1.0000
3.7560 43.1667 1.0000
3.7620 38.6667 1.0000
3.7680 28.6667 1.0000
3.7740 25.0000 1.0000
3.7800 44.6667 1.0000
3.7860 36.6667 1.0000
3.7920 34.0000 1.0000
3.7980 28.0000 1.0000
3.8040 40.5000 1.0000
3.8100 36.8333 1.0000
3.8160 34.5000 1.0000
3.8220 23.6667 1.0000
3.8280 29.6667 1.0000
3.8340 23.8333 1.0000
3.8400 33.1667 1.0000
3.8460 38.5000 1.0000
3.8520 34.1667 1.0000
3.8580 33.3333 1.0000
3.8640 32.8333 1.0000
3.8700 30.5000 1.0000
3.8760 33.8333 1.0000
3.8820 31.6667 1.0000
3.8880 32.6667 1.0000
3.8940 35.1667 1.0000
3.9000 32.8333 1.0000
3.9060 29.3333 1.0000
3.9120 32.6667 1.0000
3.9180 37.0000 1.0000
3.9240 24.0000 1.0000
3.9300 31.0000 1.0000
3.9360 36.6667 1.0000
3.9420 33.0000 1.0000
3.9480 38.5000 1.0000
3.9540 32.3333 1.0000
3.9600 38.1667 1.0000
3.9660 28.1667 1.0000
3.9720 36.8333 1.0000
3.9780 29.6667 1.0000
3.9840 37.1667 1.0000
3.9900 32.6667 1.0000
3.9960 35.5000 1.0000
4.0020 32.3333 1.0000
4.0080 30.1667 1.0000
4.0140 40.5000 1.0000
4.0200 28.3333 1.0000
4.0260 41.3333 1.0000
4.0320 40.5000 1.0000
4.0380 30.0000 1.0000
4.0440 36.3333 1.0000
4.0500 24.1667 1.0000
4.0560 31.3333 1.0000
4.0620 32.3333 1.0000
4.0680 25.1667 1.0000
4.0740 28.5000 1.0000
4.0800 22.8333 1.0000
4.0860 17.0000 1.0000
4.0920 28.1667 1.0000
4.0980 29.6667 1.0000
4.1040 17.6667 1.0000
4.1100 25.5000 1.0000
4.1160 26.3333 1.0000
4.1220 21.3333 1.0000
4.1280 22.8333 1.0000
4.1340 18.0000 1.0000
4.1400 23.1667 1.0000
4.1460 32.6667 1.0000
4.1520 20.1667 1.0000
4.1580 13.6667 1.0000
4.1640 19.0000 1.0000
4.1700 17.3333 1.0000
4.1760 15.0000 1.0000
4.1820 19.3333 1.0000
4.1880 23.0000 1.0000
4.1940 20.5000 1.0000
4.2000 20.6667 1.0000
4.2060 23.1667 1.0000
4.2120 13.6667 1.0000
4.2180 13.5000 1.0000
4.2240 20.5000 1.0000
4.2300 25.1667 1.0000
4.2360 22.3333 1.0000
4.2420 15.3333 1.0000
4.2480 26.6667 1.0000
4.2540 30.0000 1.0000
4.2600 13.6667 1.0000
4.2660 23.3333 1.0000
4.2720 28.6667 1.0000
4.2780 21.5000 1.0000
4.2840 21.6667 1.0000
4.2900 16.0000 1.0000
4.2960 22.3333 1.0000
4.3020 35.3333 1.0000
4.3080 17.8333 1.0000
4.3140 23.8333 1.0000
4.3200 18.1667 1.0000
4.3260 19.8333 1.0000
4.3320 20.1667 1.0000
4.3380 18.8333 1.0000
4.3440 20.1667 1.0000
4.3500 18.5000 1.0000
4.3560 24.5000 1.0000
4.3620 27.0000 1.0000
4.3680 15.6667 1.0000
4.3740 21.3333 1.0000
4.3800 27.8333 1.0000
4.3860 17.0000 1.0000
4.3920 16.1667 1.0000
4.3980 9.8333 1.0000
4.4040 16.0000 1.0000
4.4100 17.8333 1.0000
4.4160 14.1667 1.0000
4.4220 13.5000 1.0000
4.4280 9.8333 1.0000
4.4340 9.6667 1.0000
4.4400 17.5000 1.0000
4.4460 14.5000 1.0000
4.4520 2.3333 1.0000
4.4580 13.5000 1.0000
4.4640 15.3333 1.0000
4.4700 10.1667 1.0000
4.4760 11.3333 1.0000
4.4820 18.5000 1.0000
4.4880 9.5000 1.0000
4.4940 11.5000 1.0000
4.5000 15.0000 1.0000
4.5060 13.0000 1.0000
4.5120 11.8333 1.0000
4.5180 22.6667 1.0000
4.5240 6.1667 1.0000
4.5300 13.0000 1.0000
4.5360 11.6667 1.0000
4.5420 14.5000 1.0000
4.5480 16.6667 1.0000
4.5540 8.6667 1.0000
4.5600 12.5000 1.0000
4.5660 6.3333 1.0000
4.5720 19.0000 1.0000
4.5780 13.6667 1.0000
4.5840 18.8333 1.0000
4.5900 6.3333 1.0000
4.5960 14.5000 1.0000
4.6020 13.3333 1.0000
4.6080 14.3333 1.0000
4.6140 19.3333 1.0000
4.6200 10.6667 1.0000
4.6260 10.5000 1.0000
4.6320 14.3333 1.0000
4.6380 13.5000 1.0000
4.6440 12.5000 1.0000
4.6500 17.0000 1.0000
4.6560 6.6667 1.0000
4.6620 14.6667 1.0000
4.6680 10.5000 1.0000
4.6740 20.6667 1.0000
4.6800 12.5000 1.0000
4.6860 12.8333 1.0000
4.6920 6.3333 1.0000
4.6980 17.6667 1.0000
4.7040 17.3333 1.0000
4.7100 8.8333 1.0000
4.7160 7.3333 1.0000
4.7220 13.3333 1.0000
4.7280 18.1667 1.0000
4.7340 8.5000 1.0000
4.7400 9.8333 1.0000
4.7460 15.0000 1.0000
4.7520 14.5000 1.0000
4.7580 9.6667 1.0000
4.7640 5.5000 1.0000
4.7700 10.1667 1.0000
4.7760 12.1667 1.0000
4.7820 17.0000 1.0000
4.7880 9.5000 1.0000
4.7940 12.5000 1.0000
4.8000 10.6667 1.0000
4.8060 10.5000 1.0000
4.8120 8.6667 1.0000
4.8180 9.3333 1.0000
4.8240 6.8333 1.0000
4.8300 9.1667 1.0000
4.8360 9.6667 1.0000
4.8420 3.8333 1.0000
4.8480 9.3333 1.0000
4.8540 10.0000 1.0000
4.8600 10.8333 1.0000
4.8660 5.0000 1.0000
4.8720 6.3333 1.0000
4.8780 9.3333 1.0000
4.8840 6.0000 1.0000
4.8900 8.3333 1.0000
4.8960 9.5000 1.0000
4.9020 8.0000 1.0000
4.9080 4.3333 1.0000
4.9140 7.1667 1.0000
4.9200 12.5000 1.0000
4.9260 12.5000 1.0000
4.9320 11.0000 1.0000
4.9380 8.3333 1.0000
4.9440 4.5000 1.0000
4.9500 8.8333 1.0000
4.9560 12.5000 1.0000
4.9620 6.0000 1.0000
4.9680 9.5000 1.0000
4.9740 7.3333 1.0000
4.9800 5.6667 1.0000
4.9860 6.8333 1.0000
4.9920 7.5000 1.0000
4.9980 8.1667 1.0000
5.0040 9.3333 1.0000
5.0100 4.1667 1.0000
5.0160 3.5000 1.0000
5.0220 2.3333 1.0000
5.0280 10.0000 1.0000
5.0340 7.3333 1.0000
5.0400 10.3333 1.0000
5.0460 4.6667 1.0000
5.0520 7.0000 1.0000
5.0580 6.0000 1.0000
5.0640 11.3333 1.0000
5.0700 6.6667 1.0000
5.0760 4.1667 1.0000
5.0820 10.8333 1.0000
5.0880 8.8333 1.0000
5.0940 5.6667 1.0000
5.1000 7.0000 1.0000
5.1060 2.5000 1.0000
5.1120 4.5000 1.0000
5.1180 2.6667 1.0000
5.1240 5.8333 1.0000
5.1300 9.8333 1.0000
5.1360 4.3333 1.0000
5.1420 8.1667 1.0000
5.1480 6.0000 1.0000
5.1540 6.5000 1.0000
5.1600 6.3333 1.0000
5.1660 0.5000 1.0000
5.1720 2.1667 1.0000
5.1780 5.3333 1.0000
5.1840 4.3333 1.0000
5.1900 9.3333 1.0000
5.1960 5.6667 1.0000
5.2020 0.6667 1.0000
5.2080 6.3333 1.0000
5.2140 2.0000 1.0000
5.2200 4.0000 1.0000
5.2260 2.0000 1.0000
5.2320 4.3333 1.0000
5.2380 5.5000 1.0000
5.2440 5.5000 1.0000
5.2500 4.5000 1.0000
5.2560 7.1667 1.0000
5.2620 5.3333 1.0000
5.2680 8.3333 1.0000
5.2740 3.6667 1.0000
5.2800 6.1667 1.0000
5.2860 5.3333 1.0000
5.2920 8.1667 1.0000
5.2980 4.1667 1.0000
5.3040 3.5000 1.0000
5.3100 7.6667 1.0000
5.3160 5.3333 1.0000
5.3220 3.6667 1.0000
5.3280 5.6667 1.0000
5.3340 10.3333 1.0000
5.3400 5.3333 1.0000
5.3460 3.8333 1.0000
5.3520 3.5000 1.0000
5.3580 3.1667 1.0000
5.3640 14.5000 1.0000
5.3700 5.6667 1.0000
5.3760 4.3333 1.0000
5.3820 7.6667 1.0000
5.3880 4.5000 1.0000
5.3940 3.1667 1.0000
5.4000 5.5000 1.0000
5.4060 4.5000 1.0000
5.4120 1.1667 1.0000
5.4180 4.1667 1.0000
5.4240 3.0000 1.0000
5.4300 4.3333 1.0000
5.4360 3.3333 1.0000
5.4420 5.0000 1.0000
5.4480 1.3333 1.0000
5.4540 2.5000 1.0000
5.4600 4.3333 1.0000
5.4660 4.8333 1.0000
5.4720 2.3333 1.0000
5.4780 6.1667 1.0000
5.4840 5.0000 1.0000
5.4900 8.6667 1.0000
5.4960 3.1667 1.0000
5.5020 0.1667 1.0000
5.5080 2.1667 1.0000
5.5140 1.1667 1.0000
5.5200 1.3333 1.0000
5.5260 2.3333 1.0000
5.5320 3.0000 1.0000
5.5380 0.0000 1.0000
5.5440 2.5000 1.0000
5.5500 2.1667 1.0000
5.5560 0.1667 1.0000
5.5620 0.1667 1.0000
5.5680 1.8333 1.0000
5.5740 4.3333 1.0000
5.5800 1.1667 1.0000
5.5860 4.1667 1.0000
5.5920 1.5000 1.0000
5.5980 3.1667 1.0000
5.6040 2.1667 1.0000
5.6100 2.0000 1.0000
5.6160 2.3333 1.0000
5.6220 2.0000 1.0000
5.6280 4.6667 1.0000
5.6340 5.3333 1.0000
5.6400 2.1667 1.0000
5.6460 2.3333 1.0000
5.6520 1.3333 1.0000
5.6580 0.0000 1.0000
5.6640 3.3333 1.0000
5.6700 1.1667 1.0000
5.6760 2.3333 1.0000
5.6820 4.6667 1.0000
5.6880 3.1667 1.0000
5.6940 2.6667 1.0000
5.7000 0.1667 1.0000
5.7060 0.3333 1.0000
5.7120 0.0000 1.0000
5.7180 0.0000 1.0000
5.7240 4.0000 1.0000
5.7300 4.3333 1.0000
5.7360 0.1667 1.0000
5.7420 2.3333 1.0000
5.7480 6.1667 1.0000
5.7540 0.0000 1.0000
5.7600 0.0000 1.0000
5.7660 2.1667 1.0000
5.7720 3.1667 1.0000
5.7780 0.0000 1.0000
5.7840 3.3333 1.0000
5.7900 0.1667 1.0000
5.7960 3.3333 1.0000
5.8020 1.1667 1.0000
5.8080 2.3333 1.0000
5.8140 0.0000 1.0000
5.8200 0.0000 1.0000
5.8260 2.1667 1.0000
5.8320 1.1667 1.0000
5.8380 6.3333 1.0000
5.8440 4.1667 1.0000
5.8500 1.1667 1.0000
5.8560 4.3333 1.0000
5.8620 0.0000 1.0000
5.8680 0.3333 1.0000
5.8740 3.0000 1.0000
5.8800 2.3333 1.0000
5.8860 1.3333 1.0000
5.8920 0.0000 1.0000
5.8980 0.0000 1.0000
5.9040 0.0000 1.0000
5.9100 1.1667 1.0000
5.9160 3.3333 1.0000
5.9220 4.5000 1.0000
5.9280 0.1667 1.0000
5.9340 3.5000 1.0000
5.9400 0.1667 1.0000
5.9460 0.0000 1.0000
5.9520 3.1667 1.0000
5.9580 3.3333 1.0000
5.9640 0.0000 1.0000
5.9700 0.0000 1.0000
5.9760 3.0000 1.0000
5.9820 0.1667 1.0000
5.9880 0.0000 1.0000
5.9940 2.5000 1.0000
6.0000 0.0000 1.0000
*RAS_INT_END
*RAS_DATA_END