File: xrr_temp/CWOI12_reflectivity.ras
*RAS_DATA_START
*RAS_HEADER_START
*DISP_FMT_X "%.4f"
*DISP_FMT_Y "%.0f"
*DISP_FULLSCALE "28604504.3000000010"
*DISP_LINE_COLOR "255.0000000000"
*DISP_LINE_STYLE "0.0000000000"
*DISP_LINE_WIDTH "0.2500000000"
*DISP_NOTE "Collected Data-1"
*DISP_OFFSET_Y "0.0000000000"
*DISP_PEAKSEARCH_UNIT_Y "cps"
*DISP_RANGE_BOTTOM "0.0100000000"
*DISP_RANGE_LEFT "-0.0006000000"
*DISP_RANGE_LOGCUTOFF "0.0100000000"
*DISP_RANGE_RIGHT "6.0006000000"
*DISP_RANGE_TOP "28604504.3000000010"
*DISP_SCALE_MODE_Y "2.0000000000"
*DISP_TAB_NAME "2-Theta/Omega"
*DISP_TITLE_Y "Intensity"
*DISP_UNIT_Y "cps"
*DISP_WINDOW_NAME "MSG_MACROENGINE"
*FILE_COMMENT " "
*FILE_MD5 ""
*FILE_MEMO " "
*FILE_OPERATOR "administrator"
*FILE_PART_ID "MEAS_KHP2_00055"
*FILE_SAMPLE "CWOI6"
*FILE_TYPE "RAS_RAW"
*FILE_USERGROUP "System Manager"
*FILE_VERSION "1.0000000000"
*HW_ATTACHMENT_ID "ATT0025"
*HW_ATTACHMENT_NAME "標準|Standard"
*HW_COUNTER_ID-0 "CUT0025"
*HW_COUNTER_ID-1 "CUT0020"
*HW_COUNTER_ID-2 "CUT0020"
*HW_COUNTER_ID-3 "CSL0021"
*HW_COUNTER_ID-4 "CMC0021"
*HW_COUNTER_NAME-0 "D/teX Ultra|D/teX Ultra"
*HW_COUNTER_NAME-1 "None|None"
*HW_COUNTER_NAME-2 "None|None"
*HW_COUNTER_NAME-3 "BBM|BBM"
*HW_COUNTER_NAME-4 "検出器モノクロメータ|Detector monochromator"
*HW_COUNTER_SELECT_NAME "D/teX Ultra|D/teX Ultra"
*HW_GONIOMETER_ID "GON0023"
*HW_GONIOMETER_NAME "SmartLab|SmartLab"
*HW_GONIOMETER_RADIUS-0 "90.0"
*HW_GONIOMETER_RADIUS-1 "114.0"
*HW_GONIOMETER_RADIUS-2 "190.0"
*HW_GONIOMETER_RADIUS-3 "300.0"
*HW_GONIOMETER_RADIUS-4 "187.0"
*HW_GONIOMETER_RADIUS-5 "300.0"
*HW_GONIOMETER_RADIUS-6 "113.0"
*HW_GONIOMETER_RADIUS-7 "331.0"
*HW_I_OPT_ID-0 "CBO0021"
*HW_I_OPT_ID-1 "ICR0021"
*HW_I_OPT_ID-2 "ISL0021"
*HW_I_OPT_ID-3 "ISO0021"
*HW_I_OPT_ID-4 "IAD0021"
*HW_I_OPT_ID-5 "IPR0001"
*HW_I_OPT_NAME-0 "CBOユニット|CBO unit"
*HW_I_OPT_NAME-1 "標準入射光学ユニット|Standard incident optical unit"
*HW_I_OPT_NAME-2 "標準入射スリットボックス|Standard incident slit box"
*HW_I_OPT_NAME-3 "入射平行スリット|Incident parallel slit"
*HW_I_OPT_NAME-4 "長手制限スリット|Length limiting slit"
*HW_I_OPT_NAME-5 "None|None"
*HW_R_ATTENUATER_AUTOMODE "1"
*HW_R_OPT_ID-0 "RSS0021"
*HW_R_OPT_ID-1 "RCR0023"
*HW_R_OPT_ID-2 "RSO0021"
*HW_R_OPT_ID-3 "RRS0021"
*HW_R_OPT_ID-4 "ATN0021"
*HW_R_OPT_ID-5 "RFL0021"
*HW_R_OPT_ID-6 "RAD0021"
*HW_R_OPT_NAME-0 "標準受光スリットボックス1|Standard receiving slit box # 1"
*HW_R_OPT_NAME-1 "標準受光光学ユニット1|Standard receiving unit # 1"
*HW_R_OPT_NAME-2 "標準受光光学ユニット2|Standard receiving optical unit # 2"
*HW_R_OPT_NAME-3 "標準受光スリットボックス2|Standard receiving slit box # 2"
*HW_R_OPT_NAME-4 "標準アッテネータ|Standard Attenuator"
*HW_R_OPT_NAME-5 "Cu Kβ|Cu K-beta"
*HW_R_OPT_NAME-6 "調整用受光スリット|Alignment receiving slit"
*HW_SAMPLE_HOLDER_ID "SMP0021"
*HW_SAMPLE_HOLDER_NAME "χφZクレードル|Chi phi Z cradle"
*HW_XG_CURRENT_MAX "200"
*HW_XG_CURRENT_MIN "10"
*HW_XG_CURRENT_RESOLUTION "1"
*HW_XG_CURRENT_UNIT "mA"
*HW_XG_FOCUS "0.4mm x 8mm"
*HW_XG_FOCUS_TYPE "Normal"
*HW_XG_ID "1700"
*HW_XG_NAME "9kW 開放管(45kV 200mA ID:1700)|9kW Rotating anode(45kV 200mA ID:1700)"
*HW_XG_TARGET_ATOMIC_NUMBER "29.0000000000"
*HW_XG_TARGET_NAME "Cu"
*HW_XG_TYPE "Rota"
*HW_XG_VOLTAGE_MAX "45"
*HW_XG_VOLTAGE_MIN "20"
*HW_XG_VOLTAGE_RESOLUTION "1"
*HW_XG_VOLTAGE_UNIT "kV"
*HW_XG_WATT_MAX "9.00"
*HW_XG_WATT_UNIT "kW"
*HW_XG_WAVE_LENGTH_ALPHA1 "1.540593"
*HW_XG_WAVE_LENGTH_ALPHA2 "1.544414"
*HW_XG_WAVE_LENGTH_BETA "1.392250"
*MEAS_COND_AXIS_NAME-0 "Theta/2-Theta"
*MEAS_COND_AXIS_NAME-1 "2-Theta"
*MEAS_COND_AXIS_NAME-2 "Omega"
*MEAS_COND_AXIS_NAME-3 "Chi"
*MEAS_COND_AXIS_NAME-4 "Phi"
*MEAS_COND_AXIS_NAME-5 "Z"
*MEAS_COND_AXIS_NAME-6 "2-Theta/Omega"
*MEAS_COND_AXIS_NAME-7 "Theta_s"
*MEAS_COND_AXIS_NAME-8 "Theta_d"
*MEAS_COND_AXIS_NAME-9 "Ts"
*MEAS_COND_AXIS_NAME-10 "CBO selection slit"
*MEAS_COND_AXIS_NAME-11 "M"
*MEAS_COND_AXIS_NAME-12 "Incident parallel slit"
*MEAS_COND_AXIS_NAME-13 "Incident slit"
*MEAS_COND_AXIS_NAME-14 ""
*MEAS_COND_AXIS_NAME-15 "Zs"
*MEAS_COND_AXIS_NAME-16 "Incident optical device"
*MEAS_COND_AXIS_NAME-17 "Omega_m"
*MEAS_COND_AXIS_NAME-18 "Length limiting slit"
*MEAS_COND_AXIS_NAME-19 "Center slit"
*MEAS_COND_AXIS_NAME-20 "Filter"
*MEAS_COND_AXIS_NAME-21 "Receiving slit # 1"
*MEAS_COND_AXIS_NAME-22 "Receiving slit # 2"
*MEAS_COND_AXIS_NAME-23 "Receiving optical device"
*MEAS_COND_AXIS_NAME-24 "Receiving parallel slit"
*MEAS_COND_AXIS_NAME-25 "Alignment receiving slit"
*MEAS_COND_AXIS_NAME-26 ""
*MEAS_COND_AXIS_NAME-27 ""
*MEAS_COND_AXIS_NAME-28 "Zd"
*MEAS_COND_AXIS_NAME-29 "Attenuator"
*MEAS_COND_AXIS_NAME-30 "Diffracted beam monochromator"
*MEAS_COND_AXIS_NAME-31 "Monochromator slit"
*MEAS_COND_AXIS_NAME-32 ""
*MEAS_COND_AXIS_NAME-33 ""
*MEAS_COND_AXIS_NAME-34 "Primary beam"
*MEAS_COND_AXIS_NAME-35 "PHA"
*MEAS_COND_AXIS_NAME_INTERNAL-0 "TwoThetaTheta"
*MEAS_COND_AXIS_NAME_INTERNAL-1 "TwoTheta"
*MEAS_COND_AXIS_NAME_INTERNAL-2 "Omega"
*MEAS_COND_AXIS_NAME_INTERNAL-3 "Chi"
*MEAS_COND_AXIS_NAME_INTERNAL-4 "Phi"
*MEAS_COND_AXIS_NAME_INTERNAL-5 "Z"
*MEAS_COND_AXIS_NAME_INTERNAL-6 "TwoThetaOmega"
*MEAS_COND_AXIS_NAME_INTERNAL-7 "ThetaS"
*MEAS_COND_AXIS_NAME_INTERNAL-8 "ThetaD"
*MEAS_COND_AXIS_NAME_INTERNAL-9 "Ts"
*MEAS_COND_AXIS_NAME_INTERNAL-10 "CBO"
*MEAS_COND_AXIS_NAME_INTERNAL-11 "CBO-M"
*MEAS_COND_AXIS_NAME_INTERNAL-12 "IncidentSollerSlit"
*MEAS_COND_AXIS_NAME_INTERNAL-13 "IncidentSlitBox"
*MEAS_COND_AXIS_NAME_INTERNAL-14 "IncidentSlitBox-_Axis"
*MEAS_COND_AXIS_NAME_INTERNAL-15 "Zs"
*MEAS_COND_AXIS_NAME_INTERNAL-16 "IncidentMonochromator"
*MEAS_COND_AXIS_NAME_INTERNAL-17 "IncidentMonochromator-OmegaM"
*MEAS_COND_AXIS_NAME_INTERNAL-18 "IncidentAxdSlit"
*MEAS_COND_AXIS_NAME_INTERNAL-19 "CenterSlit"
*MEAS_COND_AXIS_NAME_INTERNAL-20 "Filter"
*MEAS_COND_AXIS_NAME_INTERNAL-21 "ReceivingSlitBox1"
*MEAS_COND_AXIS_NAME_INTERNAL-22 "ReceivingSlitBox2"
*MEAS_COND_AXIS_NAME_INTERNAL-23 "ReceivingOptics"
*MEAS_COND_AXIS_NAME_INTERNAL-24 "ReceivingSollerSlit"
*MEAS_COND_AXIS_NAME_INTERNAL-25 "ReceivingAxdSlit"
*MEAS_COND_AXIS_NAME_INTERNAL-26 "ReceivingSlitBox1-_Axis"
*MEAS_COND_AXIS_NAME_INTERNAL-27 "ReceivingSlitBox2-_Axis"
*MEAS_COND_AXIS_NAME_INTERNAL-28 "ReceivingSlitBox2-Zd"
*MEAS_COND_AXIS_NAME_INTERNAL-29 "Attenuator"
*MEAS_COND_AXIS_NAME_INTERNAL-30 "CounterMonochromator"
*MEAS_COND_AXIS_NAME_INTERNAL-31 "CounterSlit"
*MEAS_COND_AXIS_NAME_INTERNAL-32 "AlphaR"
*MEAS_COND_AXIS_NAME_INTERNAL-33 "BetaR"
*MEAS_COND_AXIS_NAME_INTERNAL-34 "IncidentPrimary"
*MEAS_COND_AXIS_NAME_INTERNAL-35 "PHA"
*MEAS_COND_AXIS_NAME_MAGICNO-0 "83951616.0000000000"
*MEAS_COND_AXIS_NAME_MAGICNO-1 "268632064.0000000000"
*MEAS_COND_AXIS_NAME_MAGICNO-2 "268500992.0000000000"
*MEAS_COND_AXIS_NAME_MAGICNO-3 "268500992.0000000000"
*MEAS_COND_AXIS_NAME_MAGICNO-4 "268500992.0000000000"
*MEAS_COND_AXIS_NAME_MAGICNO-5 "285278208.0000000000"
*MEAS_COND_AXIS_NAME_MAGICNO-6 "83951616.0000000000"
*MEAS_COND_AXIS_NAME_MAGICNO-7 "131072.0000000000"
*MEAS_COND_AXIS_NAME_MAGICNO-8 "131072.0000000000"
*MEAS_COND_AXIS_NAME_MAGICNO-9 "318898176.0000000000"
*MEAS_COND_AXIS_NAME_MAGICNO-10 "20971521.0000000000"
*MEAS_COND_AXIS_NAME_MAGICNO-11 "285343744.0000000000"
*MEAS_COND_AXIS_NAME_MAGICNO-12 "20971521.0000000000"
*MEAS_COND_AXIS_NAME_MAGICNO-13 "22020097.0000000000"
*MEAS_COND_AXIS_NAME_MAGICNO-14 "25165824.0000000000"
*MEAS_COND_AXIS_NAME_MAGICNO-15 "318898176.0000000000"
*MEAS_COND_AXIS_NAME_MAGICNO-16 "20971521.0000000000"
*MEAS_COND_AXIS_NAME_MAGICNO-17 "285343744.0000000000"
*MEAS_COND_AXIS_NAME_MAGICNO-18 "20971521.0000000000"
*MEAS_COND_AXIS_NAME_MAGICNO-19 "20971521.0000000000"
*MEAS_COND_AXIS_NAME_MAGICNO-20 "20971521.0000000000"
*MEAS_COND_AXIS_NAME_MAGICNO-21 "23068673.0000000000"
*MEAS_COND_AXIS_NAME_MAGICNO-22 "23068673.0000000000"
*MEAS_COND_AXIS_NAME_MAGICNO-23 "20971521.0000000000"
*MEAS_COND_AXIS_NAME_MAGICNO-24 "20971521.0000000000"
*MEAS_COND_AXIS_NAME_MAGICNO-25 "20971521.0000000000"
*MEAS_COND_AXIS_NAME_MAGICNO-26 "25165824.0000000000"
*MEAS_COND_AXIS_NAME_MAGICNO-27 "25165824.0000000000"
*MEAS_COND_AXIS_NAME_MAGICNO-28 "285343744.0000000000"
*MEAS_COND_AXIS_NAME_MAGICNO-29 "17301505.0000000000"
*MEAS_COND_AXIS_NAME_MAGICNO-30 "20971521.0000000000"
*MEAS_COND_AXIS_NAME_MAGICNO-31 "20971521.0000000000"
*MEAS_COND_AXIS_NAME_MAGICNO-32 "8388608.0000000000"
*MEAS_COND_AXIS_NAME_MAGICNO-33 "8388608.0000000000"
*MEAS_COND_AXIS_NAME_MAGICNO-34 "20971521.0000000000"
*MEAS_COND_AXIS_NAME_MAGICNO-35 "0.0000000000"
*MEAS_COND_AXIS_OFFSET-0 "-"
*MEAS_COND_AXIS_OFFSET-1 "0.8904000000"
*MEAS_COND_AXIS_OFFSET-2 "0.7143000000"
*MEAS_COND_AXIS_OFFSET-3 "0.0000000000"
*MEAS_COND_AXIS_OFFSET-4 "0.0000000000"
*MEAS_COND_AXIS_OFFSET-5 "-"
*MEAS_COND_AXIS_OFFSET-6 "-"
*MEAS_COND_AXIS_OFFSET-7 "0.7143000000"
*MEAS_COND_AXIS_OFFSET-8 "0.1761000000"
*MEAS_COND_AXIS_OFFSET-9 "-"
*MEAS_COND_AXIS_OFFSET-10 "-"
*MEAS_COND_AXIS_OFFSET-11 "-"
*MEAS_COND_AXIS_OFFSET-12 "-"
*MEAS_COND_AXIS_OFFSET-13 "-"
*MEAS_COND_AXIS_OFFSET-14 "-"
*MEAS_COND_AXIS_OFFSET-15 "-"
*MEAS_COND_AXIS_OFFSET-16 "-"
*MEAS_COND_AXIS_OFFSET-17 "-"
*MEAS_COND_AXIS_OFFSET-18 "-"
*MEAS_COND_AXIS_OFFSET-19 "-"
*MEAS_COND_AXIS_OFFSET-20 "-"
*MEAS_COND_AXIS_OFFSET-21 "-"
*MEAS_COND_AXIS_OFFSET-22 "-"
*MEAS_COND_AXIS_OFFSET-23 "-"
*MEAS_COND_AXIS_OFFSET-24 "-"
*MEAS_COND_AXIS_OFFSET-25 "-"
*MEAS_COND_AXIS_OFFSET-26 "-"
*MEAS_COND_AXIS_OFFSET-27 "-"
*MEAS_COND_AXIS_OFFSET-28 "-"
*MEAS_COND_AXIS_OFFSET-29 "-"
*MEAS_COND_AXIS_OFFSET-30 "-"
*MEAS_COND_AXIS_OFFSET-31 "-"
*MEAS_COND_AXIS_OFFSET-32 "0.0000000000"
*MEAS_COND_AXIS_OFFSET-33 "0.0000000000"
*MEAS_COND_AXIS_OFFSET-34 "-"
*MEAS_COND_AXIS_OFFSET-35 "-"
*MEAS_COND_AXIS_POSITION-0 "-0.0008000000"
*MEAS_COND_AXIS_POSITION-1 "-0.0008000000"
*MEAS_COND_AXIS_POSITION-2 "-0.0004000000"
*MEAS_COND_AXIS_POSITION-3 "0.0000000000"
*MEAS_COND_AXIS_POSITION-4 "0.0000000000"
*MEAS_COND_AXIS_POSITION-5 "-1.4085000000"
*MEAS_COND_AXIS_POSITION-6 "-0.0008000000"
*MEAS_COND_AXIS_POSITION-7 "-0.0004000000"
*MEAS_COND_AXIS_POSITION-8 "-0.0004000000"
*MEAS_COND_AXIS_POSITION-9 "-4.7391900000"
*MEAS_COND_AXIS_POSITION-10 "PB"
*MEAS_COND_AXIS_POSITION-11 "0.0000000000"
*MEAS_COND_AXIS_POSITION-12 "Soller_slit_open_s"
*MEAS_COND_AXIS_POSITION-13 "0.250mm"
*MEAS_COND_AXIS_POSITION-14 "0.2500000000"
*MEAS_COND_AXIS_POSITION-15 "-1.7675000000"
*MEAS_COND_AXIS_POSITION-16 "Ge(220)x2"
*MEAS_COND_AXIS_POSITION-17 "0.0000000000"
*MEAS_COND_AXIS_POSITION-18 "2.0mm"
*MEAS_COND_AXIS_POSITION-19 "None"
*MEAS_COND_AXIS_POSITION-20 "None"
*MEAS_COND_AXIS_POSITION-21 "0.250mm"
*MEAS_COND_AXIS_POSITION-22 "0.250mm"
*MEAS_COND_AXIS_POSITION-23 "No_unit"
*MEAS_COND_AXIS_POSITION-24 "Soller_slit_5.0deg"
*MEAS_COND_AXIS_POSITION-25 "None"
*MEAS_COND_AXIS_POSITION-26 "0.2500000000"
*MEAS_COND_AXIS_POSITION-27 "0.2500000000"
*MEAS_COND_AXIS_POSITION-28 "0.0862500000"
*MEAS_COND_AXIS_POSITION-29 "1/10000"
*MEAS_COND_AXIS_POSITION-30 "None"
*MEAS_COND_AXIS_POSITION-31 "None"
*MEAS_COND_AXIS_POSITION-32 "0.6500000000"
*MEAS_COND_AXIS_POSITION-33 "0.0000000000"
*MEAS_COND_AXIS_POSITION-34 "None"
*MEAS_COND_AXIS_POSITION-35 "34.0000000000"
*MEAS_COND_AXIS_UNIT-0 "deg"
*MEAS_COND_AXIS_UNIT-1 "deg"
*MEAS_COND_AXIS_UNIT-2 "deg"
*MEAS_COND_AXIS_UNIT-3 "deg"
*MEAS_COND_AXIS_UNIT-4 "deg"
*MEAS_COND_AXIS_UNIT-5 "mm"
*MEAS_COND_AXIS_UNIT-6 "deg"
*MEAS_COND_AXIS_UNIT-7 "deg"
*MEAS_COND_AXIS_UNIT-8 "deg"
*MEAS_COND_AXIS_UNIT-9 "mm"
*MEAS_COND_AXIS_UNIT-10 ""
*MEAS_COND_AXIS_UNIT-11 "pulse"
*MEAS_COND_AXIS_UNIT-12 ""
*MEAS_COND_AXIS_UNIT-13 ""
*MEAS_COND_AXIS_UNIT-14 "mm"
*MEAS_COND_AXIS_UNIT-15 "mm"
*MEAS_COND_AXIS_UNIT-16 ""
*MEAS_COND_AXIS_UNIT-17 "pulse"
*MEAS_COND_AXIS_UNIT-18 ""
*MEAS_COND_AXIS_UNIT-19 ""
*MEAS_COND_AXIS_UNIT-20 ""
*MEAS_COND_AXIS_UNIT-21 ""
*MEAS_COND_AXIS_UNIT-22 ""
*MEAS_COND_AXIS_UNIT-23 ""
*MEAS_COND_AXIS_UNIT-24 ""
*MEAS_COND_AXIS_UNIT-25 ""
*MEAS_COND_AXIS_UNIT-26 "mm"
*MEAS_COND_AXIS_UNIT-27 "mm"
*MEAS_COND_AXIS_UNIT-28 "mm"
*MEAS_COND_AXIS_UNIT-29 ""
*MEAS_COND_AXIS_UNIT-30 ""
*MEAS_COND_AXIS_UNIT-31 ""
*MEAS_COND_AXIS_UNIT-32 "deg"
*MEAS_COND_AXIS_UNIT-33 "deg"
*MEAS_COND_AXIS_UNIT-34 ""
*MEAS_COND_AXIS_UNIT-35 "div"
*MEAS_COND_COUNTER_CNTLOSS_CORR "0.0000000000"
*MEAS_COND_COUNTER_PHABASE "34.0000000000"
*MEAS_COND_COUNTER_PHAWINDOW "19.0000000000"
*MEAS_COND_COUNTER_PHA_UNIT "div"
*MEAS_COND_COUNTER_TAUDIFF "2.0000000000"
*MEAS_COND_COUNTER_TAUINT "0.1000000000"
*MEAS_COND_IRRADIATION_MODE "OFF"
*MEAS_COND_IRRADIATION_WIDTH ""
*MEAS_COND_OPT_ATTR "High resolution parallel beam Ge(220)x2/RS"
*MEAS_COND_OPT_NAME "@High resolution PB-Ge(220)x2"
*MEAS_COND_UNSYMMETRIC_MODE "OFF"
*MEAS_COND_XG_CURRENT "200.0000000000"
*MEAS_COND_XG_VOLTAGE "45.0000000000"
*MEAS_COND_XG_WAVE_TYPE "Ka1"
*MEAS_DATA_COUNT "3001.0000000000"
*MEAS_SCAN_AXIS_X "2-Theta/Omega"
*MEAS_SCAN_AXIS_X_INTERNAL "TwoThetaOmega"
*MEAS_SCAN_END_TIME "11/24/23 21:05:41"
*MEAS_SCAN_MODE "CONTINUOUS"
*MEAS_SCAN_MONITOR "0"
*MEAS_SCAN_RESOLUTION_X "0.0002"
*MEAS_SCAN_SPEED "0.500000"
*MEAS_SCAN_SPEED_UNIT "deg/min"
*MEAS_SCAN_SPEED_USER "0.500000"
*MEAS_SCAN_START "0.0000000000"
*MEAS_SCAN_START_TIME "11/24/23 20:53:11"
*MEAS_SCAN_STEP "0.0020000000"
*MEAS_SCAN_STOP "6.0000000000"
*MEAS_SCAN_UNIT_X "deg"
*MEAS_SCAN_UNIT_Y "counts"
*RAS_HEADER_END
*RAS_INT_START
0.0000 5406582.5000 1.0000
0.0060 5510711.5000 1.0000
0.0120 5632218.5000 1.0000
0.0180 5396652.0000 1.0000
0.0240 5142742.5000 1.0000
0.0300 4850491.0000 1.0000
0.0360 4430112.0000 1.0000
0.0420 3516119.7500 1.0000
0.0480 2592473.0000 1.0000
0.0540 1751301.7500 1.0000
0.0600 1021920.1250 1.0000
0.0660 532005.3125 1.0000
0.0720 249558.0938 1.0000
0.0780 135481.4063 1.0000
0.0840 92455.9531 1.0000
0.0900 67617.8203 1.0000
0.0960 63864.1719 1.0000
0.1020 66470.8750 1.0000
0.1080 69152.0469 1.0000
0.1140 70917.1563 1.0000
0.1200 72659.9219 1.0000
0.1260 76994.4922 1.0000
0.1320 79020.2734 1.0000
0.1380 81664.2109 1.0000
0.1440 84501.7891 1.0000
0.1500 89901.3906 1.0000
0.1560 94839.2266 1.0000
0.1620 93766.7500 1.0000
0.1680 102987.0234 1.0000
0.1740 99777.0625 1.0000
0.1800 108356.8281 1.0000
0.1860 106472.5547 1.0000
0.1920 115633.2500 1.0000
0.1980 115111.9141 1.0000
0.2040 123267.1563 1.0000
0.2100 122112.7578 1.0000
0.2160 123483.1406 1.0000
0.2220 129217.8828 1.0000
0.2280 136799.6563 1.0000
0.2340 138348.7813 1.0000
0.2400 140426.7031 1.0000
0.2460 143078.0938 1.0000
0.2520 145714.5781 1.0000
0.2580 154339.0313 1.0000
0.2640 154413.5156 1.0000
0.2700 160662.1406 1.0000
0.2760 162278.2969 1.0000
0.2820 165324.4063 1.0000
0.2880 167849.1875 1.0000
0.2940 170634.6406 1.0000
0.3000 172600.8438 1.0000
0.3060 177270.5469 1.0000
0.3120 182476.5000 1.0000
0.3180 185068.3125 1.0000
0.3240 184829.9844 1.0000
0.3300 195718.5469 1.0000
0.3360 189663.5469 1.0000
0.3420 196232.4375 1.0000
0.3480 197297.4531 1.0000
0.3540 197513.4531 1.0000
0.3600 209779.8281 1.0000
0.3660 207821.0938 1.0000
0.3720 212490.8125 1.0000
0.3780 212155.6563 1.0000
0.3840 218493.6563 1.0000
0.3900 220363.0313 1.0000
0.3960 220400.2813 1.0000
0.4020 226857.4531 1.0000
0.4080 231110.0938 1.0000
0.4140 236338.3906 1.0000
0.4200 234655.2031 1.0000
0.4260 241104.9375 1.0000
0.4320 243689.2969 1.0000
0.4380 243644.6094 1.0000
0.4440 245379.9219 1.0000
0.4500 242423.1719 1.0000
0.4560 249811.3125 1.0000
0.4620 255203.4688 1.0000
0.4680 254652.3281 1.0000
0.4740 257437.7656 1.0000
0.4800 258279.3594 1.0000
0.4860 271454.3750 1.0000
0.4920 264609.9375 1.0000
0.4980 273457.8125 1.0000
0.5040 270158.4688 1.0000
0.5100 268951.9375 1.0000
0.5160 279609.6250 1.0000
0.5220 276638.0000 1.0000
0.5280 270367.0000 1.0000
0.5340 279713.9063 1.0000
0.5400 278067.9688 1.0000
0.5460 285277.3438 1.0000
0.5520 290967.4063 1.0000
0.5580 284420.8438 1.0000
0.5640 284204.8750 1.0000
0.5700 291898.3438 1.0000
0.5760 279110.6250 1.0000
0.5820 290937.5938 1.0000
0.5880 281724.7813 1.0000
0.5940 290237.5313 1.0000
0.6000 283102.5938 1.0000
0.6060 293752.8438 1.0000
0.6120 283854.8125 1.0000
0.6180 280354.4063 1.0000
0.6240 274731.3750 1.0000
0.6300 270270.1875 1.0000
0.6360 267641.1563 1.0000
0.6420 257914.4219 1.0000
0.6480 248344.1094 1.0000
0.6540 241879.5000 1.0000
0.6600 235750.0313 1.0000
0.6660 214159.0938 1.0000
0.6720 198481.6406 1.0000
0.6780 191622.2969 1.0000
0.6840 178179.1719 1.0000
0.6900 164721.1406 1.0000
0.6960 151203.5469 1.0000
0.7020 137879.5781 1.0000
0.7080 126856.9531 1.0000
0.7140 113078.6797 1.0000
0.7200 103135.9766 1.0000
0.7260 94593.4531 1.0000
0.7320 82282.3750 1.0000
0.7380 76614.6641 1.0000
0.7440 71118.2422 1.0000
0.7500 65405.8438 1.0000
0.7560 59544.4961 1.0000
0.7620 57589.1680 1.0000
0.7680 54185.5000 1.0000
0.7740 51210.6680 1.0000
0.7800 48785.3320 1.0000
0.7860 46099.3320 1.0000
0.7920 44129.0000 1.0000
0.7980 42714.6680 1.0000
0.8040 41207.3320 1.0000
0.8100 39970.5000 1.0000
0.8160 38591.3320 1.0000
0.8220 37472.8320 1.0000
0.8280 36352.8320 1.0000
0.8340 35068.1680 1.0000
0.8400 33952.3320 1.0000
0.8460 32722.1660 1.0000
0.8520 31838.5000 1.0000
0.8580 30269.5000 1.0000
0.8640 29375.6660 1.0000
0.8700 28057.0000 1.0000
0.8760 26965.8340 1.0000
0.8820 25913.3340 1.0000
0.8880 24577.3340 1.0000
0.8940 23690.0000 1.0000
0.9000 22661.6660 1.0000
0.9060 21704.1660 1.0000
0.9120 20614.0000 1.0000
0.9180 19818.0000 1.0000
0.9240 18617.8340 1.0000
0.9300 17788.0000 1.0000
0.9360 17050.1660 1.0000
0.9420 16568.6660 1.0000
0.9480 15780.6670 1.0000
0.9540 15134.5000 1.0000
0.9600 14516.1670 1.0000
0.9660 13946.0000 1.0000
0.9720 13416.8330 1.0000
0.9780 13245.8330 1.0000
0.9840 12951.1670 1.0000
0.9900 12611.0000 1.0000
0.9960 12505.1670 1.0000
1.0020 12183.1670 1.0000
1.0080 11842.3330 1.0000
1.0140 11605.5000 1.0000
1.0200 11444.5000 1.0000
1.0260 11112.3330 1.0000
1.0320 10904.3330 1.0000
1.0380 10844.8330 1.0000
1.0440 10580.6670 1.0000
1.0500 10390.3330 1.0000
1.0560 10231.0000 1.0000
1.0620 10204.8330 1.0000
1.0680 9950.3330 1.0000
1.0740 9919.8330 1.0000
1.0800 9620.5000 1.0000
1.0860 9555.1670 1.0000
1.0920 9449.0000 1.0000
1.0980 9185.6670 1.0000
1.1040 8898.0000 1.0000
1.1100 8559.3330 1.0000
1.1160 8444.0000 1.0000
1.1220 8276.5000 1.0000
1.1280 8062.8335 1.0000
1.1340 7959.5000 1.0000
1.1400 7643.5000 1.0000
1.1460 7588.0000 1.0000
1.1520 7256.8335 1.0000
1.1580 6984.6665 1.0000
1.1640 6852.8335 1.0000
1.1700 6552.6665 1.0000
1.1760 6339.0000 1.0000
1.1820 6184.8335 1.0000
1.1880 5994.1665 1.0000
1.1940 5915.6665 1.0000
1.2000 5562.6665 1.0000
1.2060 5469.8335 1.0000
1.2120 5301.3335 1.0000
1.2180 5107.8335 1.0000
1.2240 5092.3335 1.0000
1.2300 4899.0000 1.0000
1.2360 4859.5000 1.0000
1.2420 4678.8335 1.0000
1.2480 4465.3335 1.0000
1.2540 4589.3335 1.0000
1.2600 4435.1665 1.0000
1.2660 4331.1665 1.0000
1.2720 4282.0000 1.0000
1.2780 4253.0000 1.0000
1.2840 4199.3335 1.0000
1.2900 4151.1665 1.0000
1.2960 4236.6665 1.0000
1.3020 4093.5000 1.0000
1.3080 3998.6667 1.0000
1.3140 3914.5000 1.0000
1.3200 4072.8333 1.0000
1.3260 3981.1667 1.0000
1.3320 3938.6667 1.0000
1.3380 3999.5000 1.0000
1.3440 3873.5000 1.0000
1.3500 3922.6667 1.0000
1.3560 3803.5000 1.0000
1.3620 3763.6667 1.0000
1.3680 3681.5000 1.0000
1.3740 3664.1667 1.0000
1.3800 3722.5000 1.0000
1.3860 3500.1667 1.0000
1.3920 3494.8333 1.0000
1.3980 3486.0000 1.0000
1.4040 3368.0000 1.0000
1.4100 3252.5000 1.0000
1.4160 3247.6667 1.0000
1.4220 3117.6667 1.0000
1.4280 3130.5000 1.0000
1.4340 3010.6667 1.0000
1.4400 2880.1667 1.0000
1.4460 2881.8333 1.0000
1.4520 2788.1667 1.0000
1.4580 2717.1667 1.0000
1.4640 2648.1667 1.0000
1.4700 2561.0000 1.0000
1.4760 2567.6667 1.0000
1.4820 2475.5000 1.0000
1.4880 2405.6667 1.0000
1.4940 2385.8333 1.0000
1.5000 2318.0000 1.0000
1.5060 2262.0000 1.0000
1.5120 2164.3333 1.0000
1.5180 2160.1667 1.0000
1.5240 2028.5000 1.0000
1.5300 1988.3334 1.0000
1.5360 1890.3334 1.0000
1.5420 1824.8334 1.0000
1.5480 1955.0000 1.0000
1.5540 1856.8334 1.0000
1.5600 1865.0000 1.0000
1.5660 1827.0000 1.0000
1.5720 1803.0000 1.0000
1.5780 1752.6666 1.0000
1.5840 1792.5000 1.0000
1.5900 1840.5000 1.0000
1.5960 1788.6666 1.0000
1.6020 1876.6666 1.0000
1.6080 1758.3334 1.0000
1.6140 1776.1666 1.0000
1.6200 1783.8334 1.0000
1.6260 1738.5000 1.0000
1.6320 1761.1666 1.0000
1.6380 1773.6666 1.0000
1.6440 1770.8334 1.0000
1.6500 1799.1666 1.0000
1.6560 1785.5000 1.0000
1.6620 1733.8334 1.0000
1.6680 1756.6666 1.0000
1.6740 1678.1666 1.0000
1.6800 1677.8334 1.0000
1.6860 1710.5000 1.0000
1.6920 1634.3334 1.0000
1.6980 1658.3334 1.0000
1.7040 1623.8334 1.0000
1.7100 1603.5000 1.0000
1.7160 1494.0000 1.0000
1.7220 1531.1666 1.0000
1.7280 1566.6666 1.0000
1.7340 1524.3334 1.0000
1.7400 1508.0000 1.0000
1.7460 1373.5000 1.0000
1.7520 1392.1666 1.0000
1.7580 1424.5000 1.0000
1.7640 1335.1666 1.0000
1.7700 1335.8334 1.0000
1.7760 1313.8334 1.0000
1.7820 1288.1666 1.0000
1.7880 1204.3334 1.0000
1.7940 1185.3334 1.0000
1.8000 1137.1666 1.0000
1.8060 1097.5000 1.0000
1.8120 1108.6666 1.0000
1.8180 1072.1666 1.0000
1.8240 1051.3334 1.0000
1.8300 1043.3334 1.0000
1.8360 1037.1666 1.0000
1.8420 943.3333 1.0000
1.8480 920.8333 1.0000
1.8540 913.1667 1.0000
1.8600 964.8333 1.0000
1.8660 891.5000 1.0000
1.8720 888.5000 1.0000
1.8780 905.3333 1.0000
1.8840 839.0000 1.0000
1.8900 870.0000 1.0000
1.8960 776.8333 1.0000
1.9020 829.3333 1.0000
1.9080 862.5000 1.0000
1.9140 812.3333 1.0000
1.9200 879.5000 1.0000
1.9260 835.6667 1.0000
1.9320 853.0000 1.0000
1.9380 837.8333 1.0000
1.9440 885.1667 1.0000
1.9500 822.6667 1.0000
1.9560 867.3333 1.0000
1.9620 853.8333 1.0000
1.9680 781.8333 1.0000
1.9740 887.8333 1.0000
1.9800 921.1667 1.0000
1.9860 935.3333 1.0000
1.9920 849.8333 1.0000
1.9980 883.3333 1.0000
2.0040 847.5000 1.0000
2.0100 853.1667 1.0000
2.0160 877.0000 1.0000
2.0220 788.8333 1.0000
2.0280 821.0000 1.0000
2.0340 820.8333 1.0000
2.0400 809.6667 1.0000
2.0460 819.6667 1.0000
2.0520 793.5000 1.0000
2.0580 856.1667 1.0000
2.0640 812.5000 1.0000
2.0700 758.8333 1.0000
2.0760 716.8333 1.0000
2.0820 793.1667 1.0000
2.0880 696.8333 1.0000
2.0940 687.8333 1.0000
2.1000 657.6667 1.0000
2.1060 669.1667 1.0000
2.1120 641.5000 1.0000
2.1180 634.6667 1.0000
2.1240 584.1667 1.0000
2.1300 612.5000 1.0000
2.1360 599.1667 1.0000
2.1420 611.0000 1.0000
2.1480 536.1667 1.0000
2.1540 517.1667 1.0000
2.1600 551.1667 1.0000
2.1660 493.0000 1.0000
2.1720 476.3333 1.0000
2.1780 507.5000 1.0000
2.1840 553.3333 1.0000
2.1900 474.3333 1.0000
2.1960 472.1667 1.0000
2.2020 466.3333 1.0000
2.2080 472.3333 1.0000
2.2140 440.8333 1.0000
2.2200 424.1667 1.0000
2.2260 477.5000 1.0000
2.2320 455.6667 1.0000
2.2380 424.8333 1.0000
2.2440 439.5000 1.0000
2.2500 494.1667 1.0000
2.2560 451.1667 1.0000
2.2620 430.5000 1.0000
2.2680 478.6667 1.0000
2.2740 456.5000 1.0000
2.2800 458.6667 1.0000
2.2860 452.8333 1.0000
2.2920 500.6667 1.0000
2.2980 478.6667 1.0000
2.3040 446.8333 1.0000
2.3100 443.1667 1.0000
2.3160 474.6667 1.0000
2.3220 477.6667 1.0000
2.3280 441.1667 1.0000
2.3340 473.8333 1.0000
2.3400 472.1667 1.0000
2.3460 448.6667 1.0000
2.3520 512.5000 1.0000
2.3580 470.5000 1.0000
2.3640 451.0000 1.0000
2.3700 418.6667 1.0000
2.3760 457.5000 1.0000
2.3820 452.1667 1.0000
2.3880 419.5000 1.0000
2.3940 451.8333 1.0000
2.4000 458.0000 1.0000
2.4060 457.0000 1.0000
2.4120 416.0000 1.0000
2.4180 420.5000 1.0000
2.4240 381.5000 1.0000
2.4300 405.0000 1.0000
2.4360 379.5000 1.0000
2.4420 373.6667 1.0000
2.4480 369.0000 1.0000
2.4540 376.8333 1.0000
2.4600 366.6667 1.0000
2.4660 343.3333 1.0000
2.4720 322.5000 1.0000
2.4780 347.1667 1.0000
2.4840 387.6667 1.0000
2.4900 311.5000 1.0000
2.4960 311.5000 1.0000
2.5020 355.6667 1.0000
2.5080 293.0000 1.0000
2.5140 333.3333 1.0000
2.5200 291.1667 1.0000
2.5260 249.1667 1.0000
2.5320 251.5000 1.0000
2.5380 257.3333 1.0000
2.5440 253.5000 1.0000
2.5500 255.1667 1.0000
2.5560 250.3333 1.0000
2.5620 217.0000 1.0000
2.5680 238.3333 1.0000
2.5740 275.3333 1.0000
2.5800 257.5000 1.0000
2.5860 289.8333 1.0000
2.5920 238.6667 1.0000
2.5980 259.3333 1.0000
2.6040 264.3333 1.0000
2.6100 260.3333 1.0000
2.6160 271.8333 1.0000
2.6220 246.6667 1.0000
2.6280 256.5000 1.0000
2.6340 252.0000 1.0000
2.6400 259.1667 1.0000
2.6460 263.6667 1.0000
2.6520 282.6667 1.0000
2.6580 251.0000 1.0000
2.6640 284.1667 1.0000
2.6700 267.5000 1.0000
2.6760 249.5000 1.0000
2.6820 269.1667 1.0000
2.6880 241.5000 1.0000
2.6940 274.1667 1.0000
2.7000 257.6667 1.0000
2.7060 265.3333 1.0000
2.7120 244.6667 1.0000
2.7180 271.3333 1.0000
2.7240 251.1667 1.0000
2.7300 231.5000 1.0000
2.7360 214.3333 1.0000
2.7420 250.6667 1.0000
2.7480 249.8333 1.0000
2.7540 248.0000 1.0000
2.7600 244.0000 1.0000
2.7660 244.1667 1.0000
2.7720 244.8333 1.0000
2.7780 233.6667 1.0000
2.7840 198.0000 1.0000
2.7900 196.6667 1.0000
2.7960 232.6667 1.0000
2.8020 195.0000 1.0000
2.8080 189.0000 1.0000
2.8140 189.6667 1.0000
2.8200 199.0000 1.0000
2.8260 183.6667 1.0000
2.8320 174.6667 1.0000
2.8380 176.5000 1.0000
2.8440 173.6667 1.0000
2.8500 206.1667 1.0000
2.8560 159.1667 1.0000
2.8620 162.3333 1.0000
2.8680 177.8333 1.0000
2.8740 169.8333 1.0000
2.8800 143.6667 1.0000
2.8860 153.6667 1.0000
2.8920 138.6667 1.0000
2.8980 139.0000 1.0000
2.9040 166.6667 1.0000
2.9100 163.3333 1.0000
2.9160 161.1667 1.0000
2.9220 138.3333 1.0000
2.9280 158.1667 1.0000
2.9340 152.6667 1.0000
2.9400 130.3333 1.0000
2.9460 155.3333 1.0000
2.9520 137.0000 1.0000
2.9580 133.3333 1.0000
2.9640 136.1667 1.0000
2.9700 173.5000 1.0000
2.9760 156.6667 1.0000
2.9820 148.8333 1.0000
2.9880 141.8333 1.0000
2.9940 156.1667 1.0000
3.0000 173.1667 1.0000
3.0060 144.6667 1.0000
3.0120 140.0000 1.0000
3.0180 144.5000 1.0000
3.0240 162.0000 1.0000
3.0300 154.3333 1.0000
3.0360 161.5000 1.0000
3.0420 135.8333 1.0000
3.0480 146.3333 1.0000
3.0540 131.0000 1.0000
3.0600 163.8333 1.0000
3.0660 169.8333 1.0000
3.0720 167.5000 1.0000
3.0780 161.6667 1.0000
3.0840 157.0000 1.0000
3.0900 153.0000 1.0000
3.0960 127.3333 1.0000
3.1020 152.6667 1.0000
3.1080 136.6667 1.0000
3.1140 163.3333 1.0000
3.1200 133.6667 1.0000
3.1260 131.0000 1.0000
3.1320 116.6667 1.0000
3.1380 135.6667 1.0000
3.1440 123.0000 1.0000
3.1500 127.0000 1.0000
3.1560 115.8333 1.0000
3.1620 114.3333 1.0000
3.1680 119.6667 1.0000
3.1740 113.6667 1.0000
3.1800 105.3333 1.0000
3.1860 113.3333 1.0000
3.1920 106.3333 1.0000
3.1980 109.3333 1.0000
3.2040 100.1667 1.0000
3.2100 85.0000 1.0000
3.2160 100.1667 1.0000
3.2220 91.3333 1.0000
3.2280 82.1667 1.0000
3.2340 88.6667 1.0000
3.2400 94.6667 1.0000
3.2460 95.3333 1.0000
3.2520 83.6667 1.0000
3.2580 93.8333 1.0000
3.2640 90.8333 1.0000
3.2700 99.0000 1.0000
3.2760 86.8333 1.0000
3.2820 92.1667 1.0000
3.2880 97.1667 1.0000
3.2940 98.8333 1.0000
3.3000 88.3333 1.0000
3.3060 92.5000 1.0000
3.3120 111.5000 1.0000
3.3180 103.8333 1.0000
3.3240 105.0000 1.0000
3.3300 81.3333 1.0000
3.3360 111.5000 1.0000
3.3420 94.5000 1.0000
3.3480 71.1667 1.0000
3.3540 106.5000 1.0000
3.3600 85.6667 1.0000
3.3660 119.3333 1.0000
3.3720 94.8333 1.0000
3.3780 68.8333 1.0000
3.3840 102.6667 1.0000
3.3900 104.5000 1.0000
3.3960 106.1667 1.0000
3.4020 103.3333 1.0000
3.4080 96.0000 1.0000
3.4140 90.3333 1.0000
3.4200 89.0000 1.0000
3.4260 99.0000 1.0000
3.4320 89.3333 1.0000
3.4380 99.6667 1.0000
3.4440 79.3333 1.0000
3.4500 82.6667 1.0000
3.4560 77.6667 1.0000
3.4620 86.3333 1.0000
3.4680 91.5000 1.0000
3.4740 80.0000 1.0000
3.4800 71.1667 1.0000
3.4860 66.1667 1.0000
3.4920 84.3333 1.0000
3.4980 75.1667 1.0000
3.5040 83.5000 1.0000
3.5100 93.5000 1.0000
3.5160 72.6667 1.0000
3.5220 84.0000 1.0000
3.5280 62.6667 1.0000
3.5340 78.0000 1.0000
3.5400 75.5000 1.0000
3.5460 77.6667 1.0000
3.5520 70.0000 1.0000
3.5580 58.6667 1.0000
3.5640 60.0000 1.0000
3.5700 67.3333 1.0000
3.5760 67.3333 1.0000
3.5820 54.3333 1.0000
3.5880 62.8333 1.0000
3.5940 58.3333 1.0000
3.6000 52.8333 1.0000
3.6060 62.1667 1.0000
3.6120 69.8333 1.0000
3.6180 60.8333 1.0000
3.6240 52.3333 1.0000
3.6300 57.5000 1.0000
3.6360 71.8333 1.0000
3.6420 82.3333 1.0000
3.6480 55.5000 1.0000
3.6540 62.1667 1.0000
3.6600 50.5000 1.0000
3.6660 59.6667 1.0000
3.6720 67.3333 1.0000
3.6780 55.3333 1.0000
3.6840 64.6667 1.0000
3.6900 57.8333 1.0000
3.6960 54.0000 1.0000
3.7020 60.1667 1.0000
3.7080 66.0000 1.0000
3.7140 49.5000 1.0000
3.7200 55.6667 1.0000
3.7260 67.6667 1.0000
3.7320 58.1667 1.0000
3.7380 61.0000 1.0000
3.7440 71.3333 1.0000
3.7500 50.8333 1.0000
3.7560 65.6667 1.0000
3.7620 66.1667 1.0000
3.7680 46.6667 1.0000
3.7740 45.5000 1.0000
3.7800 42.6667 1.0000
3.7860 49.3333 1.0000
3.7920 57.3333 1.0000
3.7980 52.5000 1.0000
3.8040 40.1667 1.0000
3.8100 56.3333 1.0000
3.8160 49.8333 1.0000
3.8220 45.1667 1.0000
3.8280 38.0000 1.0000
3.8340 39.8333 1.0000
3.8400 53.6667 1.0000
3.8460 37.0000 1.0000
3.8520 49.0000 1.0000
3.8580 55.6667 1.0000
3.8640 51.3333 1.0000
3.8700 52.8333 1.0000
3.8760 44.1667 1.0000
3.8820 42.5000 1.0000
3.8880 42.1667 1.0000
3.8940 38.1667 1.0000
3.9000 41.6667 1.0000
3.9060 40.3333 1.0000
3.9120 45.8333 1.0000
3.9180 35.0000 1.0000
3.9240 27.3333 1.0000
3.9300 31.3333 1.0000
3.9360 51.3333 1.0000
3.9420 34.1667 1.0000
3.9480 35.8333 1.0000
3.9540 27.6667 1.0000
3.9600 33.6667 1.0000
3.9660 45.8333 1.0000
3.9720 46.8333 1.0000
3.9780 37.8333 1.0000
3.9840 41.0000 1.0000
3.9900 31.3333 1.0000
3.9960 37.1667 1.0000
4.0020 33.6667 1.0000
4.0080 21.3333 1.0000
4.0140 47.0000 1.0000
4.0200 38.8333 1.0000
4.0260 29.8333 1.0000
4.0320 49.3333 1.0000
4.0380 36.1667 1.0000
4.0440 33.0000 1.0000
4.0500 35.6667 1.0000
4.0560 32.1667 1.0000
4.0620 41.3333 1.0000
4.0680 36.5000 1.0000
4.0740 36.0000 1.0000
4.0800 25.8333 1.0000
4.0860 34.0000 1.0000
4.0920 35.3333 1.0000
4.0980 34.0000 1.0000
4.1040 41.8333 1.0000
4.1100 38.0000 1.0000
4.1160 39.6667 1.0000
4.1220 32.3333 1.0000
4.1280 48.5000 1.0000
4.1340 27.1667 1.0000
4.1400 46.5000 1.0000
4.1460 34.3333 1.0000
4.1520 30.5000 1.0000
4.1580 21.5000 1.0000
4.1640 37.5000 1.0000
4.1700 24.3333 1.0000
4.1760 21.6667 1.0000
4.1820 37.0000 1.0000
4.1880 29.8333 1.0000
4.1940 32.3333 1.0000
4.2000 28.6667 1.0000
4.2060 26.8333 1.0000
4.2120 27.5000 1.0000
4.2180 29.1667 1.0000
4.2240 43.5000 1.0000
4.2300 22.5000 1.0000
4.2360 24.5000 1.0000
4.2420 22.0000 1.0000
4.2480 14.0000 1.0000
4.2540 21.6667 1.0000
4.2600 24.6667 1.0000
4.2660 23.6667 1.0000
4.2720 23.3333 1.0000
4.2780 35.0000 1.0000
4.2840 23.5000 1.0000
4.2900 25.1667 1.0000
4.2960 19.8333 1.0000
4.3020 35.5000 1.0000
4.3080 29.5000 1.0000
4.3140 23.6667 1.0000
4.3200 28.5000 1.0000
4.3260 24.5000 1.0000
4.3320 21.0000 1.0000
4.3380 30.6667 1.0000
4.3440 18.5000 1.0000
4.3500 29.1667 1.0000
4.3560 23.1667 1.0000
4.3620 18.6667 1.0000
4.3680 35.0000 1.0000
4.3740 28.3333 1.0000
4.3800 27.3333 1.0000
4.3860 20.5000 1.0000
4.3920 26.6667 1.0000
4.3980 26.6667 1.0000
4.4040 21.3333 1.0000
4.4100 23.5000 1.0000
4.4160 16.8333 1.0000
4.4220 22.6667 1.0000
4.4280 20.3333 1.0000
4.4340 31.1667 1.0000
4.4400 19.3333 1.0000
4.4460 23.3333 1.0000
4.4520 13.5000 1.0000
4.4580 17.1667 1.0000
4.4640 18.8333 1.0000
4.4700 23.0000 1.0000
4.4760 23.8333 1.0000
4.4820 30.5000 1.0000
4.4880 17.8333 1.0000
4.4940 21.1667 1.0000
4.5000 24.5000 1.0000
4.5060 17.3333 1.0000
4.5120 21.6667 1.0000
4.5180 17.0000 1.0000
4.5240 10.8333 1.0000
4.5300 16.3333 1.0000
4.5360 24.0000 1.0000
4.5420 16.5000 1.0000
4.5480 19.0000 1.0000
4.5540 21.3333 1.0000
4.5600 12.0000 1.0000
4.5660 11.0000 1.0000
4.5720 8.3333 1.0000
4.5780 17.8333 1.0000
4.5840 16.1667 1.0000
4.5900 17.0000 1.0000
4.5960 20.5000 1.0000
4.6020 14.1667 1.0000
4.6080 21.0000 1.0000
4.6140 18.8333 1.0000
4.6200 22.8333 1.0000
4.6260 18.5000 1.0000
4.6320 20.3333 1.0000
4.6380 16.5000 1.0000
4.6440 13.8333 1.0000
4.6500 13.1667 1.0000
4.6560 19.3333 1.0000
4.6620 18.8333 1.0000
4.6680 11.3333 1.0000
4.6740 12.5000 1.0000
4.6800 14.8333 1.0000
4.6860 16.0000 1.0000
4.6920 11.1667 1.0000
4.6980 20.3333 1.0000
4.7040 9.1667 1.0000
4.7100 10.6667 1.0000
4.7160 13.3333 1.0000
4.7220 9.5000 1.0000
4.7280 16.5000 1.0000
4.7340 9.3333 1.0000
4.7400 11.0000 1.0000
4.7460 13.5000 1.0000
4.7520 7.5000 1.0000
4.7580 11.0000 1.0000
4.7640 14.3333 1.0000
4.7700 7.8333 1.0000
4.7760 12.6667 1.0000
4.7820 21.3333 1.0000
4.7880 15.5000 1.0000
4.7940 18.8333 1.0000
4.8000 9.0000 1.0000
4.8060 19.1667 1.0000
4.8120 14.5000 1.0000
4.8180 11.6667 1.0000
4.8240 17.6667 1.0000
4.8300 14.3333 1.0000
4.8360 14.5000 1.0000
4.8420 12.5000 1.0000
4.8480 10.8333 1.0000
4.8540 10.5000 1.0000
4.8600 15.1667 1.0000
4.8660 23.5000 1.0000
4.8720 16.6667 1.0000
4.8780 13.5000 1.0000
4.8840 10.8333 1.0000
4.8900 17.3333 1.0000
4.8960 16.6667 1.0000
4.9020 18.5000 1.0000
4.9080 2.5000 1.0000
4.9140 7.8333 1.0000
4.9200 8.0000 1.0000
4.9260 8.1667 1.0000
4.9320 12.1667 1.0000
4.9380 6.6667 1.0000
4.9440 8.8333 1.0000
4.9500 18.8333 1.0000
4.9560 17.3333 1.0000
4.9620 14.1667 1.0000
4.9680 10.8333 1.0000
4.9740 10.8333 1.0000
4.9800 7.8333 1.0000
4.9860 13.0000 1.0000
4.9920 10.1667 1.0000
4.9980 14.6667 1.0000
5.0040 9.1667 1.0000
5.0100 9.8333 1.0000
5.0160 14.3333 1.0000
5.0220 2.3333 1.0000
5.0280 12.3333 1.0000
5.0340 11.1667 1.0000
5.0400 13.3333 1.0000
5.0460 12.0000 1.0000
5.0520 14.5000 1.0000
5.0580 12.0000 1.0000
5.0640 12.1667 1.0000
5.0700 7.5000 1.0000
5.0760 17.0000 1.0000
5.0820 9.1667 1.0000
5.0880 9.8333 1.0000
5.0940 15.1667 1.0000
5.1000 8.1667 1.0000
5.1060 16.0000 1.0000
5.1120 9.3333 1.0000
5.1180 6.1667 1.0000
5.1240 10.6667 1.0000
5.1300 7.6667 1.0000
5.1360 10.8333 1.0000
5.1420 11.6667 1.0000
5.1480 6.5000 1.0000
5.1540 10.5000 1.0000
5.1600 4.6667 1.0000
5.1660 11.1667 1.0000
5.1720 6.5000 1.0000
5.1780 11.8333 1.0000
5.1840 10.0000 1.0000
5.1900 8.6667 1.0000
5.1960 7.3333 1.0000
5.2020 7.0000 1.0000
5.2080 7.1667 1.0000
5.2140 5.8333 1.0000
5.2200 5.1667 1.0000
5.2260 9.6667 1.0000
5.2320 7.5000 1.0000
5.2380 9.5000 1.0000
5.2440 7.5000 1.0000
5.2500 8.8333 1.0000
5.2560 6.5000 1.0000
5.2620 9.5000 1.0000
5.2680 5.8333 1.0000
5.2740 2.3333 1.0000
5.2800 0.3333 1.0000
5.2860 2.5000 1.0000
5.2920 10.6667 1.0000
5.2980 7.1667 1.0000
5.3040 8.5000 1.0000
5.3100 5.5000 1.0000
5.3160 4.6667 1.0000
5.3220 7.3333 1.0000
5.3280 4.5000 1.0000
5.3340 7.1667 1.0000
5.3400 8.5000 1.0000
5.3460 5.6667 1.0000
5.3520 6.8333 1.0000
5.3580 6.3333 1.0000
5.3640 4.3333 1.0000
5.3700 5.8333 1.0000
5.3760 5.3333 1.0000
5.3820 4.3333 1.0000
5.3880 8.1667 1.0000
5.3940 7.3333 1.0000
5.4000 3.6667 1.0000
5.4060 5.6667 1.0000
5.4120 9.5000 1.0000
5.4180 2.8333 1.0000
5.4240 4.5000 1.0000
5.4300 8.5000 1.0000
5.4360 6.8333 1.0000
5.4420 7.1667 1.0000
5.4480 6.5000 1.0000
5.4540 8.3333 1.0000
5.4600 5.3333 1.0000
5.4660 4.1667 1.0000
5.4720 9.0000 1.0000
5.4780 3.5000 1.0000
5.4840 7.5000 1.0000
5.4900 4.6667 1.0000
5.4960 0.5000 1.0000
5.5020 3.5000 1.0000
5.5080 4.6667 1.0000
5.5140 7.1667 1.0000
5.5200 8.5000 1.0000
5.5260 3.5000 1.0000
5.5320 2.5000 1.0000
5.5380 10.5000 1.0000
5.5440 7.3333 1.0000
5.5500 12.3333 1.0000
5.5560 3.6667 1.0000
5.5620 7.6667 1.0000
5.5680 3.8333 1.0000
5.5740 4.6667 1.0000
5.5800 4.5000 1.0000
5.5860 3.5000 1.0000
5.5920 5.5000 1.0000
5.5980 6.0000 1.0000
5.6040 7.0000 1.0000
5.6100 4.1667 1.0000
5.6160 6.6667 1.0000
5.6220 5.8333 1.0000
5.6280 8.0000 1.0000
5.6340 3.3333 1.0000
5.6400 0.0000 1.0000
5.6460 2.3333 1.0000
5.6520 2.6667 1.0000
5.6580 4.5000 1.0000
5.6640 1.1667 1.0000
5.6700 3.3333 1.0000
5.6760 1.5000 1.0000
5.6820 2.3333 1.0000
5.6880 3.3333 1.0000
5.6940 2.1667 1.0000
5.7000 4.6667 1.0000
5.7060 0.3333 1.0000
5.7120 5.3333 1.0000
5.7180 8.3333 1.0000
5.7240 5.6667 1.0000
5.7300 3.3333 1.0000
5.7360 6.5000 1.0000
5.7420 2.3333 1.0000
5.7480 6.1667 1.0000
5.7540 0.1667 1.0000
5.7600 2.1667 1.0000
5.7660 6.5000 1.0000
5.7720 9.5000 1.0000
5.7780 4.1667 1.0000
5.7840 3.6667 1.0000
5.7900 3.3333 1.0000
5.7960 6.5000 1.0000
5.8020 4.3333 1.0000
5.8080 4.3333 1.0000
5.8140 2.1667 1.0000
5.8200 3.1667 1.0000
5.8260 2.1667 1.0000
5.8320 0.1667 1.0000
5.8380 2.0000 1.0000
5.8440 4.8333 1.0000
5.8500 8.0000 1.0000
5.8560 4.3333 1.0000
5.8620 5.1667 1.0000
5.8680 1.1667 1.0000
5.8740 0.1667 1.0000
5.8800 0.0000 1.0000
5.8860 3.0000 1.0000
5.8920 0.0000 1.0000
5.8980 3.1667 1.0000
5.9040 0.3333 1.0000
5.9100 6.0000 1.0000
5.9160 5.1667 1.0000
5.9220 5.3333 1.0000
5.9280 2.5000 1.0000
5.9340 4.0000 1.0000
5.9400 3.1667 1.0000
5.9460 1.3333 1.0000
5.9520 6.0000 1.0000
5.9580 2.6667 1.0000
5.9640 6.5000 1.0000
5.9700 2.5000 1.0000
5.9760 2.3333 1.0000
5.9820 1.3333 1.0000
5.9880 2.1667 1.0000
5.9940 2.1667 1.0000
6.0000 2.5000 1.0000
*RAS_INT_END
*RAS_DATA_END