File: xrr_temp/CWOI10_reflectivity.ras
*RAS_DATA_START
*RAS_HEADER_START
*DISP_FMT_X "%.4f"
*DISP_FMT_Y "%.0f"
*DISP_FULLSCALE "28728631.8500000010"
*DISP_LINE_COLOR "255.0000000000"
*DISP_LINE_STYLE "0.0000000000"
*DISP_LINE_WIDTH "0.2500000000"
*DISP_NOTE "Collected Data-8"
*DISP_OFFSET_Y "0.0000000000"
*DISP_PEAKSEARCH_UNIT_Y "cps"
*DISP_RANGE_BOTTOM "0.0100000000"
*DISP_RANGE_LEFT "-0.0006000000"
*DISP_RANGE_LOGCUTOFF "0.0100000000"
*DISP_RANGE_RIGHT "6.0006000000"
*DISP_RANGE_TOP "28728631.8500000010"
*DISP_SCALE_MODE_Y "2.0000000000"
*DISP_TAB_NAME "2-Theta/Omega"
*DISP_TITLE_Y "Intensity"
*DISP_UNIT_Y "cps"
*DISP_WINDOW_NAME "MSG_MACROENGINE"
*FILE_COMMENT " "
*FILE_MD5 ""
*FILE_MEMO " "
*FILE_OPERATOR "Administrator"
*FILE_PART_ID "MEAS_KHP2_00055"
*FILE_SAMPLE "CWOI10"
*FILE_TYPE "RAS_RAW"
*FILE_USERGROUP "System Manager"
*FILE_VERSION "1.0000000000"
*HW_ATTACHMENT_ID "ATT0025"
*HW_ATTACHMENT_NAME "標準|Standard"
*HW_COUNTER_ID-0 "CUT0025"
*HW_COUNTER_ID-1 "CUT0020"
*HW_COUNTER_ID-2 "CUT0020"
*HW_COUNTER_ID-3 "CSL0021"
*HW_COUNTER_ID-4 "CMC0021"
*HW_COUNTER_NAME-0 "D/teX Ultra|D/teX Ultra"
*HW_COUNTER_NAME-1 "None|None"
*HW_COUNTER_NAME-2 "None|None"
*HW_COUNTER_NAME-3 "BBM|BBM"
*HW_COUNTER_NAME-4 "検出器モノクロメータ|Detector monochromator"
*HW_COUNTER_SELECT_NAME "D/teX Ultra|D/teX Ultra"
*HW_GONIOMETER_ID "GON0023"
*HW_GONIOMETER_NAME "SmartLab|SmartLab"
*HW_GONIOMETER_RADIUS-0 "90.0"
*HW_GONIOMETER_RADIUS-1 "114.0"
*HW_GONIOMETER_RADIUS-2 "190.0"
*HW_GONIOMETER_RADIUS-3 "300.0"
*HW_GONIOMETER_RADIUS-4 "187.0"
*HW_GONIOMETER_RADIUS-5 "300.0"
*HW_GONIOMETER_RADIUS-6 "113.0"
*HW_GONIOMETER_RADIUS-7 "331.0"
*HW_I_OPT_ID-0 "CBO0021"
*HW_I_OPT_ID-1 "ICR0021"
*HW_I_OPT_ID-2 "ISL0021"
*HW_I_OPT_ID-3 "ISO0021"
*HW_I_OPT_ID-4 "IAD0021"
*HW_I_OPT_ID-5 "IPR0001"
*HW_I_OPT_NAME-0 "CBOユニット|CBO unit"
*HW_I_OPT_NAME-1 "標準入射光学ユニット|Standard incident optical unit"
*HW_I_OPT_NAME-2 "標準入射スリットボックス|Standard incident slit box"
*HW_I_OPT_NAME-3 "入射平行スリット|Incident parallel slit"
*HW_I_OPT_NAME-4 "長手制限スリット|Length limiting slit"
*HW_I_OPT_NAME-5 "None|None"
*HW_R_ATTENUATER_AUTOMODE "1"
*HW_R_OPT_ID-0 "RSS0021"
*HW_R_OPT_ID-1 "RCR0023"
*HW_R_OPT_ID-2 "RSO0021"
*HW_R_OPT_ID-3 "RRS0021"
*HW_R_OPT_ID-4 "ATN0021"
*HW_R_OPT_ID-5 "RFL0021"
*HW_R_OPT_ID-6 "RAD0021"
*HW_R_OPT_NAME-0 "標準受光スリットボックス1|Standard receiving slit box # 1"
*HW_R_OPT_NAME-1 "標準受光光学ユニット1|Standard receiving unit # 1"
*HW_R_OPT_NAME-2 "標準受光光学ユニット2|Standard receiving optical unit # 2"
*HW_R_OPT_NAME-3 "標準受光スリットボックス2|Standard receiving slit box # 2"
*HW_R_OPT_NAME-4 "標準アッテネータ|Standard Attenuator"
*HW_R_OPT_NAME-5 "Cu Kβ|Cu K-beta"
*HW_R_OPT_NAME-6 "調整用受光スリット|Alignment receiving slit"
*HW_SAMPLE_HOLDER_ID "SMP0021"
*HW_SAMPLE_HOLDER_NAME "χφZクレードル|Chi phi Z cradle"
*HW_XG_CURRENT_MAX "200"
*HW_XG_CURRENT_MIN "10"
*HW_XG_CURRENT_RESOLUTION "1"
*HW_XG_CURRENT_UNIT "mA"
*HW_XG_FOCUS "0.4mm x 8mm"
*HW_XG_FOCUS_TYPE "Normal"
*HW_XG_ID "1700"
*HW_XG_NAME "9kW 開放管(45kV 200mA ID:1700)|9kW Rotating anode(45kV 200mA ID:1700)"
*HW_XG_TARGET_ATOMIC_NUMBER "29.0000000000"
*HW_XG_TARGET_NAME "Cu"
*HW_XG_TYPE "Rota"
*HW_XG_VOLTAGE_MAX "45"
*HW_XG_VOLTAGE_MIN "20"
*HW_XG_VOLTAGE_RESOLUTION "1"
*HW_XG_VOLTAGE_UNIT "kV"
*HW_XG_WATT_MAX "9.00"
*HW_XG_WATT_UNIT "kW"
*HW_XG_WAVE_LENGTH_ALPHA1 "1.540593"
*HW_XG_WAVE_LENGTH_ALPHA2 "1.544414"
*HW_XG_WAVE_LENGTH_BETA "1.392250"
*MEAS_COND_AXIS_NAME-0 "Theta/2-Theta"
*MEAS_COND_AXIS_NAME-1 "2-Theta"
*MEAS_COND_AXIS_NAME-2 "Omega"
*MEAS_COND_AXIS_NAME-3 "Chi"
*MEAS_COND_AXIS_NAME-4 "Phi"
*MEAS_COND_AXIS_NAME-5 "Z"
*MEAS_COND_AXIS_NAME-6 "2-Theta/Omega"
*MEAS_COND_AXIS_NAME-7 "Theta_s"
*MEAS_COND_AXIS_NAME-8 "Theta_d"
*MEAS_COND_AXIS_NAME-9 "Ts"
*MEAS_COND_AXIS_NAME-10 "CBO selection slit"
*MEAS_COND_AXIS_NAME-11 "M"
*MEAS_COND_AXIS_NAME-12 "Incident parallel slit"
*MEAS_COND_AXIS_NAME-13 "Incident slit"
*MEAS_COND_AXIS_NAME-14 ""
*MEAS_COND_AXIS_NAME-15 "Zs"
*MEAS_COND_AXIS_NAME-16 "Incident optical device"
*MEAS_COND_AXIS_NAME-17 "Omega_m"
*MEAS_COND_AXIS_NAME-18 "Length limiting slit"
*MEAS_COND_AXIS_NAME-19 "Center slit"
*MEAS_COND_AXIS_NAME-20 "Filter"
*MEAS_COND_AXIS_NAME-21 "Receiving slit # 1"
*MEAS_COND_AXIS_NAME-22 "Receiving slit # 2"
*MEAS_COND_AXIS_NAME-23 "Receiving optical device"
*MEAS_COND_AXIS_NAME-24 "Receiving parallel slit"
*MEAS_COND_AXIS_NAME-25 "Alignment receiving slit"
*MEAS_COND_AXIS_NAME-26 ""
*MEAS_COND_AXIS_NAME-27 ""
*MEAS_COND_AXIS_NAME-28 "Zd"
*MEAS_COND_AXIS_NAME-29 "Attenuator"
*MEAS_COND_AXIS_NAME-30 "Diffracted beam monochromator"
*MEAS_COND_AXIS_NAME-31 "Monochromator slit"
*MEAS_COND_AXIS_NAME-32 "Primary beam"
*MEAS_COND_AXIS_NAME-33 ""
*MEAS_COND_AXIS_NAME-34 ""
*MEAS_COND_AXIS_NAME-35 "PHA"
*MEAS_COND_AXIS_NAME_INTERNAL-0 "TwoThetaTheta"
*MEAS_COND_AXIS_NAME_INTERNAL-1 "TwoTheta"
*MEAS_COND_AXIS_NAME_INTERNAL-2 "Omega"
*MEAS_COND_AXIS_NAME_INTERNAL-3 "Chi"
*MEAS_COND_AXIS_NAME_INTERNAL-4 "Phi"
*MEAS_COND_AXIS_NAME_INTERNAL-5 "Z"
*MEAS_COND_AXIS_NAME_INTERNAL-6 "TwoThetaOmega"
*MEAS_COND_AXIS_NAME_INTERNAL-7 "ThetaS"
*MEAS_COND_AXIS_NAME_INTERNAL-8 "ThetaD"
*MEAS_COND_AXIS_NAME_INTERNAL-9 "Ts"
*MEAS_COND_AXIS_NAME_INTERNAL-10 "CBO"
*MEAS_COND_AXIS_NAME_INTERNAL-11 "CBO-M"
*MEAS_COND_AXIS_NAME_INTERNAL-12 "IncidentSollerSlit"
*MEAS_COND_AXIS_NAME_INTERNAL-13 "IncidentSlitBox"
*MEAS_COND_AXIS_NAME_INTERNAL-14 "IncidentSlitBox-_Axis"
*MEAS_COND_AXIS_NAME_INTERNAL-15 "Zs"
*MEAS_COND_AXIS_NAME_INTERNAL-16 "IncidentMonochromator"
*MEAS_COND_AXIS_NAME_INTERNAL-17 "IncidentMonochromator-OmegaM"
*MEAS_COND_AXIS_NAME_INTERNAL-18 "IncidentAxdSlit"
*MEAS_COND_AXIS_NAME_INTERNAL-19 "CenterSlit"
*MEAS_COND_AXIS_NAME_INTERNAL-20 "Filter"
*MEAS_COND_AXIS_NAME_INTERNAL-21 "ReceivingSlitBox1"
*MEAS_COND_AXIS_NAME_INTERNAL-22 "ReceivingSlitBox2"
*MEAS_COND_AXIS_NAME_INTERNAL-23 "ReceivingOptics"
*MEAS_COND_AXIS_NAME_INTERNAL-24 "ReceivingSollerSlit"
*MEAS_COND_AXIS_NAME_INTERNAL-25 "ReceivingAxdSlit"
*MEAS_COND_AXIS_NAME_INTERNAL-26 "ReceivingSlitBox1-_Axis"
*MEAS_COND_AXIS_NAME_INTERNAL-27 "ReceivingSlitBox2-_Axis"
*MEAS_COND_AXIS_NAME_INTERNAL-28 "ReceivingSlitBox2-Zd"
*MEAS_COND_AXIS_NAME_INTERNAL-29 "Attenuator"
*MEAS_COND_AXIS_NAME_INTERNAL-30 "CounterMonochromator"
*MEAS_COND_AXIS_NAME_INTERNAL-31 "CounterSlit"
*MEAS_COND_AXIS_NAME_INTERNAL-32 "IncidentPrimary"
*MEAS_COND_AXIS_NAME_INTERNAL-33 "AlphaR"
*MEAS_COND_AXIS_NAME_INTERNAL-34 "BetaR"
*MEAS_COND_AXIS_NAME_INTERNAL-35 "PHA"
*MEAS_COND_AXIS_NAME_MAGICNO-0 "83951616.0000000000"
*MEAS_COND_AXIS_NAME_MAGICNO-1 "268632064.0000000000"
*MEAS_COND_AXIS_NAME_MAGICNO-2 "268500992.0000000000"
*MEAS_COND_AXIS_NAME_MAGICNO-3 "268500992.0000000000"
*MEAS_COND_AXIS_NAME_MAGICNO-4 "268500992.0000000000"
*MEAS_COND_AXIS_NAME_MAGICNO-5 "285278208.0000000000"
*MEAS_COND_AXIS_NAME_MAGICNO-6 "83951616.0000000000"
*MEAS_COND_AXIS_NAME_MAGICNO-7 "131072.0000000000"
*MEAS_COND_AXIS_NAME_MAGICNO-8 "131072.0000000000"
*MEAS_COND_AXIS_NAME_MAGICNO-9 "318898176.0000000000"
*MEAS_COND_AXIS_NAME_MAGICNO-10 "20971521.0000000000"
*MEAS_COND_AXIS_NAME_MAGICNO-11 "285343744.0000000000"
*MEAS_COND_AXIS_NAME_MAGICNO-12 "20971521.0000000000"
*MEAS_COND_AXIS_NAME_MAGICNO-13 "22020097.0000000000"
*MEAS_COND_AXIS_NAME_MAGICNO-14 "25165824.0000000000"
*MEAS_COND_AXIS_NAME_MAGICNO-15 "318898176.0000000000"
*MEAS_COND_AXIS_NAME_MAGICNO-16 "20971521.0000000000"
*MEAS_COND_AXIS_NAME_MAGICNO-17 "285343744.0000000000"
*MEAS_COND_AXIS_NAME_MAGICNO-18 "20971521.0000000000"
*MEAS_COND_AXIS_NAME_MAGICNO-19 "20971521.0000000000"
*MEAS_COND_AXIS_NAME_MAGICNO-20 "20971521.0000000000"
*MEAS_COND_AXIS_NAME_MAGICNO-21 "23068673.0000000000"
*MEAS_COND_AXIS_NAME_MAGICNO-22 "23068673.0000000000"
*MEAS_COND_AXIS_NAME_MAGICNO-23 "20971521.0000000000"
*MEAS_COND_AXIS_NAME_MAGICNO-24 "20971521.0000000000"
*MEAS_COND_AXIS_NAME_MAGICNO-25 "20971521.0000000000"
*MEAS_COND_AXIS_NAME_MAGICNO-26 "25165824.0000000000"
*MEAS_COND_AXIS_NAME_MAGICNO-27 "25165824.0000000000"
*MEAS_COND_AXIS_NAME_MAGICNO-28 "285343744.0000000000"
*MEAS_COND_AXIS_NAME_MAGICNO-29 "17301505.0000000000"
*MEAS_COND_AXIS_NAME_MAGICNO-30 "20971521.0000000000"
*MEAS_COND_AXIS_NAME_MAGICNO-31 "20971521.0000000000"
*MEAS_COND_AXIS_NAME_MAGICNO-32 "20971521.0000000000"
*MEAS_COND_AXIS_NAME_MAGICNO-33 "8388608.0000000000"
*MEAS_COND_AXIS_NAME_MAGICNO-34 "8388608.0000000000"
*MEAS_COND_AXIS_NAME_MAGICNO-35 "0.0000000000"
*MEAS_COND_AXIS_OFFSET-0 "-"
*MEAS_COND_AXIS_OFFSET-1 "0.8877000000"
*MEAS_COND_AXIS_OFFSET-2 "0.8170000000"
*MEAS_COND_AXIS_OFFSET-3 "0.0000000000"
*MEAS_COND_AXIS_OFFSET-4 "0.0000000000"
*MEAS_COND_AXIS_OFFSET-5 "-"
*MEAS_COND_AXIS_OFFSET-6 "-"
*MEAS_COND_AXIS_OFFSET-7 "0.8170000000"
*MEAS_COND_AXIS_OFFSET-8 "0.0707000000"
*MEAS_COND_AXIS_OFFSET-9 "-"
*MEAS_COND_AXIS_OFFSET-10 "-"
*MEAS_COND_AXIS_OFFSET-11 "-"
*MEAS_COND_AXIS_OFFSET-12 "-"
*MEAS_COND_AXIS_OFFSET-13 "-"
*MEAS_COND_AXIS_OFFSET-14 "-"
*MEAS_COND_AXIS_OFFSET-15 "-"
*MEAS_COND_AXIS_OFFSET-16 "-"
*MEAS_COND_AXIS_OFFSET-17 "-"
*MEAS_COND_AXIS_OFFSET-18 "-"
*MEAS_COND_AXIS_OFFSET-19 "-"
*MEAS_COND_AXIS_OFFSET-20 "-"
*MEAS_COND_AXIS_OFFSET-21 "-"
*MEAS_COND_AXIS_OFFSET-22 "-"
*MEAS_COND_AXIS_OFFSET-23 "-"
*MEAS_COND_AXIS_OFFSET-24 "-"
*MEAS_COND_AXIS_OFFSET-25 "-"
*MEAS_COND_AXIS_OFFSET-26 "-"
*MEAS_COND_AXIS_OFFSET-27 "-"
*MEAS_COND_AXIS_OFFSET-28 "-"
*MEAS_COND_AXIS_OFFSET-29 "-"
*MEAS_COND_AXIS_OFFSET-30 "-"
*MEAS_COND_AXIS_OFFSET-31 "-"
*MEAS_COND_AXIS_OFFSET-32 "-"
*MEAS_COND_AXIS_OFFSET-33 "0.0000000000"
*MEAS_COND_AXIS_OFFSET-34 "0.0000000000"
*MEAS_COND_AXIS_OFFSET-35 "-"
*MEAS_COND_AXIS_POSITION-0 "-0.0008000000"
*MEAS_COND_AXIS_POSITION-1 "-0.0009000000"
*MEAS_COND_AXIS_POSITION-2 "-0.0004000000"
*MEAS_COND_AXIS_POSITION-3 "0.0000000000"
*MEAS_COND_AXIS_POSITION-4 "0.0000000000"
*MEAS_COND_AXIS_POSITION-5 "-1.4197000000"
*MEAS_COND_AXIS_POSITION-6 "-0.0008000000"
*MEAS_COND_AXIS_POSITION-7 "-0.0004000000"
*MEAS_COND_AXIS_POSITION-8 "-0.0005000000"
*MEAS_COND_AXIS_POSITION-9 "-4.7376300000"
*MEAS_COND_AXIS_POSITION-10 "PB"
*MEAS_COND_AXIS_POSITION-11 "0.0000000000"
*MEAS_COND_AXIS_POSITION-12 "Soller_slit_open_s"
*MEAS_COND_AXIS_POSITION-13 "0.250mm"
*MEAS_COND_AXIS_POSITION-14 "0.2500000000"
*MEAS_COND_AXIS_POSITION-15 "-1.7634400000"
*MEAS_COND_AXIS_POSITION-16 "Ge(220)x2"
*MEAS_COND_AXIS_POSITION-17 "0.0000000000"
*MEAS_COND_AXIS_POSITION-18 "2.0mm"
*MEAS_COND_AXIS_POSITION-19 "None"
*MEAS_COND_AXIS_POSITION-20 "None"
*MEAS_COND_AXIS_POSITION-21 "0.250mm"
*MEAS_COND_AXIS_POSITION-22 "0.250mm"
*MEAS_COND_AXIS_POSITION-23 "No_unit"
*MEAS_COND_AXIS_POSITION-24 "Soller_slit_5.0deg"
*MEAS_COND_AXIS_POSITION-25 "None"
*MEAS_COND_AXIS_POSITION-26 "0.2500000000"
*MEAS_COND_AXIS_POSITION-27 "0.2500000000"
*MEAS_COND_AXIS_POSITION-28 "0.0890600000"
*MEAS_COND_AXIS_POSITION-29 "1/10000"
*MEAS_COND_AXIS_POSITION-30 "None"
*MEAS_COND_AXIS_POSITION-31 "None"
*MEAS_COND_AXIS_POSITION-32 "None"
*MEAS_COND_AXIS_POSITION-33 "0.0000000000"
*MEAS_COND_AXIS_POSITION-34 "0.0000000000"
*MEAS_COND_AXIS_POSITION-35 "34.0000000000"
*MEAS_COND_AXIS_UNIT-0 "deg"
*MEAS_COND_AXIS_UNIT-1 "deg"
*MEAS_COND_AXIS_UNIT-2 "deg"
*MEAS_COND_AXIS_UNIT-3 "deg"
*MEAS_COND_AXIS_UNIT-4 "deg"
*MEAS_COND_AXIS_UNIT-5 "mm"
*MEAS_COND_AXIS_UNIT-6 "deg"
*MEAS_COND_AXIS_UNIT-7 "deg"
*MEAS_COND_AXIS_UNIT-8 "deg"
*MEAS_COND_AXIS_UNIT-9 "mm"
*MEAS_COND_AXIS_UNIT-10 ""
*MEAS_COND_AXIS_UNIT-11 "pulse"
*MEAS_COND_AXIS_UNIT-12 ""
*MEAS_COND_AXIS_UNIT-13 ""
*MEAS_COND_AXIS_UNIT-14 "mm"
*MEAS_COND_AXIS_UNIT-15 "mm"
*MEAS_COND_AXIS_UNIT-16 ""
*MEAS_COND_AXIS_UNIT-17 "pulse"
*MEAS_COND_AXIS_UNIT-18 ""
*MEAS_COND_AXIS_UNIT-19 ""
*MEAS_COND_AXIS_UNIT-20 ""
*MEAS_COND_AXIS_UNIT-21 ""
*MEAS_COND_AXIS_UNIT-22 ""
*MEAS_COND_AXIS_UNIT-23 ""
*MEAS_COND_AXIS_UNIT-24 ""
*MEAS_COND_AXIS_UNIT-25 ""
*MEAS_COND_AXIS_UNIT-26 "mm"
*MEAS_COND_AXIS_UNIT-27 "mm"
*MEAS_COND_AXIS_UNIT-28 "mm"
*MEAS_COND_AXIS_UNIT-29 ""
*MEAS_COND_AXIS_UNIT-30 ""
*MEAS_COND_AXIS_UNIT-31 ""
*MEAS_COND_AXIS_UNIT-32 ""
*MEAS_COND_AXIS_UNIT-33 "deg"
*MEAS_COND_AXIS_UNIT-34 "deg"
*MEAS_COND_AXIS_UNIT-35 "div"
*MEAS_COND_COUNTER_CNTLOSS_CORR "0.0000000000"
*MEAS_COND_COUNTER_PHABASE "34.0000000000"
*MEAS_COND_COUNTER_PHAWINDOW "19.0000000000"
*MEAS_COND_COUNTER_PHA_UNIT "div"
*MEAS_COND_COUNTER_TAUDIFF "2.0000000000"
*MEAS_COND_COUNTER_TAUINT "0.1000000000"
*MEAS_COND_IRRADIATION_MODE "OFF"
*MEAS_COND_IRRADIATION_WIDTH ""
*MEAS_COND_OPT_ATTR "High resolution parallel beam Ge(220)x2/RS"
*MEAS_COND_OPT_NAME "@High resolution PB-Ge(220)x2"
*MEAS_COND_UNSYMMETRIC_MODE "OFF"
*MEAS_COND_XG_CURRENT "200.0000000000"
*MEAS_COND_XG_VOLTAGE "45.0000000000"
*MEAS_COND_XG_WAVE_TYPE "Ka1"
*MEAS_DATA_COUNT "3001.0000000000"
*MEAS_SCAN_AXIS_X "2-Theta/Omega"
*MEAS_SCAN_AXIS_X_INTERNAL "TwoThetaOmega"
*MEAS_SCAN_END_TIME "11/15/23 14:16:33"
*MEAS_SCAN_MODE "CONTINUOUS"
*MEAS_SCAN_MONITOR "0"
*MEAS_SCAN_RESOLUTION_X "0.0002"
*MEAS_SCAN_SPEED "0.500000"
*MEAS_SCAN_SPEED_UNIT "deg/min"
*MEAS_SCAN_SPEED_USER "0.500000"
*MEAS_SCAN_START "0.0000000000"
*MEAS_SCAN_START_TIME "11/15/23 14:04:06"
*MEAS_SCAN_STEP "0.0020000000"
*MEAS_SCAN_STOP "6.0000000000"
*MEAS_SCAN_UNIT_X "deg"
*MEAS_SCAN_UNIT_Y "counts"
*RAS_HEADER_END
*RAS_INT_START
0.0000 5465749.5000 1.0000
0.0060 5461750.0000 1.0000
0.0120 5477473.0000 1.0000
0.0180 5373619.5000 1.0000
0.0240 5253078.0000 1.0000
0.0300 4908830.5000 1.0000
0.0360 4550929.5000 1.0000
0.0420 3713620.5000 1.0000
0.0480 2718807.0000 1.0000
0.0540 1866878.3750 1.0000
0.0600 1091579.7500 1.0000
0.0660 568320.3750 1.0000
0.0720 263269.3438 1.0000
0.0780 144552.7344 1.0000
0.0840 95025.4141 1.0000
0.0900 78670.2266 1.0000
0.0960 76257.1719 1.0000
0.1020 75288.9688 1.0000
0.1080 76361.4375 1.0000
0.1140 78022.2813 1.0000
0.1200 81805.7188 1.0000
0.1260 85469.9922 1.0000
0.1320 93118.8047 1.0000
0.1380 95807.4297 1.0000
0.1440 96552.1953 1.0000
0.1500 104670.2109 1.0000
0.1560 106606.6172 1.0000
0.1620 108505.7813 1.0000
0.1680 115744.9688 1.0000
0.1740 117785.6406 1.0000
0.1800 118962.3828 1.0000
0.1860 124131.0938 1.0000
0.1920 129910.5234 1.0000
0.1980 129068.9297 1.0000
0.2040 133113.0469 1.0000
0.2100 142132.2188 1.0000
0.2160 143152.5625 1.0000
0.2220 149438.4375 1.0000
0.2280 152290.9063 1.0000
0.2340 155605.1406 1.0000
0.2400 162628.3438 1.0000
0.2460 164222.1563 1.0000
0.2520 170820.8281 1.0000
0.2580 170068.6094 1.0000
0.2640 172854.0625 1.0000
0.2700 174440.4219 1.0000
0.2760 183727.7188 1.0000
0.2820 182335.0000 1.0000
0.2880 189834.8438 1.0000
0.2940 193096.9531 1.0000
0.3000 194482.2188 1.0000
0.3060 201713.9531 1.0000
0.3120 200298.8906 1.0000
0.3180 205735.7188 1.0000
0.3240 211880.0938 1.0000
0.3300 214062.2656 1.0000
0.3360 218210.6563 1.0000
0.3420 214605.9531 1.0000
0.3480 223126.1406 1.0000
0.3540 226872.3438 1.0000
0.3600 231750.5938 1.0000
0.3660 237872.6250 1.0000
0.3720 240620.8281 1.0000
0.3780 245715.0781 1.0000
0.3840 245394.8125 1.0000
0.3900 248753.7500 1.0000
0.3960 245193.7344 1.0000
0.4020 255560.9531 1.0000
0.4080 254495.9219 1.0000
0.4140 266427.1563 1.0000
0.4200 262822.4688 1.0000
0.4260 262211.7813 1.0000
0.4320 266062.2188 1.0000
0.4380 269927.5938 1.0000
0.4440 279341.5000 1.0000
0.4500 280443.7813 1.0000
0.4560 285046.4688 1.0000
0.4620 287161.5938 1.0000
0.4680 289827.9063 1.0000
0.4740 288651.1563 1.0000
0.4800 294393.3438 1.0000
0.4860 294877.4375 1.0000
0.4920 295532.8438 1.0000
0.4980 300731.3438 1.0000
0.5040 303807.2500 1.0000
0.5100 303710.4375 1.0000
0.5160 304336.0625 1.0000
0.5220 314375.5625 1.0000
0.5280 304023.2500 1.0000
0.5340 319782.6250 1.0000
0.5400 315291.6250 1.0000
0.5460 316043.8438 1.0000
0.5520 314509.6250 1.0000
0.5580 316259.8438 1.0000
0.5640 311932.7188 1.0000
0.5700 304000.9063 1.0000
0.5760 317578.0938 1.0000
0.5820 314271.3125 1.0000
0.5880 317168.4688 1.0000
0.5940 318047.2813 1.0000
0.6000 310726.1875 1.0000
0.6060 309668.5938 1.0000
0.6120 307248.0938 1.0000
0.6180 292538.8438 1.0000
0.6240 290289.6563 1.0000
0.6300 276831.6250 1.0000
0.6360 269793.5313 1.0000
0.6420 253646.8906 1.0000
0.6480 243778.6563 1.0000
0.6540 229948.2500 1.0000
0.6600 212654.6563 1.0000
0.6660 194579.0469 1.0000
0.6720 177359.9219 1.0000
0.6780 161436.7031 1.0000
0.6840 146794.5000 1.0000
0.6900 133887.5938 1.0000
0.6960 118068.6484 1.0000
0.7020 111700.8594 1.0000
0.7080 98101.3203 1.0000
0.7140 92887.9219 1.0000
0.7200 83109.0703 1.0000
0.7260 76748.7188 1.0000
0.7320 71088.4531 1.0000
0.7380 68161.5000 1.0000
0.7440 64489.7773 1.0000
0.7500 55761.0547 1.0000
0.7560 55105.0000 1.0000
0.7620 51037.1680 1.0000
0.7680 48191.1680 1.0000
0.7740 45594.3320 1.0000
0.7800 42894.5000 1.0000
0.7860 40431.5000 1.0000
0.7920 38828.3320 1.0000
0.7980 36946.3320 1.0000
0.8040 35289.6680 1.0000
0.8100 33947.3320 1.0000
0.8160 32831.5000 1.0000
0.8220 31788.8340 1.0000
0.8280 30377.8340 1.0000
0.8340 29320.1660 1.0000
0.8400 28107.5000 1.0000
0.8460 27248.5000 1.0000
0.8520 26306.3340 1.0000
0.8580 25280.8340 1.0000
0.8640 24472.1660 1.0000
0.8700 23712.5000 1.0000
0.8760 22520.0000 1.0000
0.8820 21918.3340 1.0000
0.8880 21040.3340 1.0000
0.8940 20256.0000 1.0000
0.9000 19428.5000 1.0000
0.9060 18725.8340 1.0000
0.9120 17832.6660 1.0000
0.9180 16878.5000 1.0000
0.9240 16393.0000 1.0000
0.9300 15784.5000 1.0000
0.9360 15159.8330 1.0000
0.9420 14306.0000 1.0000
0.9480 13937.0000 1.0000
0.9540 13184.5000 1.0000
0.9600 12832.8330 1.0000
0.9660 12334.5000 1.0000
0.9720 11863.0000 1.0000
0.9780 11528.5000 1.0000
0.9840 10908.8330 1.0000
0.9900 10757.3330 1.0000
0.9960 10509.1670 1.0000
1.0020 10131.3330 1.0000
1.0080 10164.0000 1.0000
1.0140 9699.6670 1.0000
1.0200 9539.8330 1.0000
1.0260 9196.0000 1.0000
1.0320 9130.8330 1.0000
1.0380 8984.3330 1.0000
1.0440 8866.8330 1.0000
1.0500 8562.3330 1.0000
1.0560 8452.5000 1.0000
1.0620 8381.1670 1.0000
1.0680 8058.0000 1.0000
1.0740 7830.8335 1.0000
1.0800 7898.3335 1.0000
1.0860 7595.8335 1.0000
1.0920 7534.0000 1.0000
1.0980 7319.0000 1.0000
1.1040 7179.5000 1.0000
1.1100 6886.8335 1.0000
1.1160 6480.1665 1.0000
1.1220 6456.1665 1.0000
1.1280 6068.3335 1.0000
1.1340 6002.5000 1.0000
1.1400 5857.5000 1.0000
1.1460 5594.8335 1.0000
1.1520 5575.0000 1.0000
1.1580 5296.8335 1.0000
1.1640 5150.0000 1.0000
1.1700 4788.3335 1.0000
1.1760 4711.1665 1.0000
1.1820 4533.0000 1.0000
1.1880 4447.0000 1.0000
1.1940 4336.8335 1.0000
1.2000 4245.6665 1.0000
1.2060 4121.6665 1.0000
1.2120 3955.6667 1.0000
1.2180 3912.8333 1.0000
1.2240 3948.3333 1.0000
1.2300 3831.3333 1.0000
1.2360 3704.1667 1.0000
1.2420 3561.5000 1.0000
1.2480 3535.5000 1.0000
1.2540 3343.0000 1.0000
1.2600 3436.8333 1.0000
1.2660 3377.1667 1.0000
1.2720 3333.0000 1.0000
1.2780 3258.6667 1.0000
1.2840 3283.1667 1.0000
1.2900 3034.8333 1.0000
1.2960 3201.8333 1.0000
1.3020 3079.1667 1.0000
1.3080 3087.6667 1.0000
1.3140 3056.1667 1.0000
1.3200 2972.1667 1.0000
1.3260 2954.5000 1.0000
1.3320 2998.1667 1.0000
1.3380 2869.1667 1.0000
1.3440 2688.8333 1.0000
1.3500 2682.8333 1.0000
1.3560 2653.8333 1.0000
1.3620 2630.8333 1.0000
1.3680 2622.5000 1.0000
1.3740 2431.5000 1.0000
1.3800 2479.3333 1.0000
1.3860 2367.0000 1.0000
1.3920 2291.1667 1.0000
1.3980 2240.5000 1.0000
1.4040 2135.5000 1.0000
1.4100 2044.8334 1.0000
1.4160 2013.8334 1.0000
1.4220 1929.3334 1.0000
1.4280 1970.5000 1.0000
1.4340 1844.6666 1.0000
1.4400 1721.8334 1.0000
1.4460 1757.0000 1.0000
1.4520 1758.3334 1.0000
1.4580 1686.0000 1.0000
1.4640 1597.3334 1.0000
1.4700 1544.8334 1.0000
1.4760 1567.5000 1.0000
1.4820 1547.8334 1.0000
1.4880 1485.1666 1.0000
1.4940 1518.1666 1.0000
1.5000 1437.0000 1.0000
1.5060 1454.3334 1.0000
1.5120 1394.5000 1.0000
1.5180 1325.8334 1.0000
1.5240 1407.0000 1.0000
1.5300 1381.1666 1.0000
1.5360 1367.5000 1.0000
1.5420 1342.5000 1.0000
1.5480 1362.1666 1.0000
1.5540 1267.5000 1.0000
1.5600 1218.0000 1.0000
1.5660 1257.0000 1.0000
1.5720 1311.3334 1.0000
1.5780 1215.6666 1.0000
1.5840 1252.1666 1.0000
1.5900 1194.5000 1.0000
1.5960 1231.6666 1.0000
1.6020 1164.0000 1.0000
1.6080 1201.0000 1.0000
1.6140 1153.0000 1.0000
1.6200 1162.3334 1.0000
1.6260 1156.3334 1.0000
1.6320 1104.8334 1.0000
1.6380 1097.6666 1.0000
1.6440 1042.0000 1.0000
1.6500 1063.5000 1.0000
1.6560 1006.8333 1.0000
1.6620 1003.0000 1.0000
1.6680 951.8333 1.0000
1.6740 884.0000 1.0000
1.6800 864.5000 1.0000
1.6860 855.5000 1.0000
1.6920 843.6667 1.0000
1.6980 867.5000 1.0000
1.7040 775.5000 1.0000
1.7100 812.3333 1.0000
1.7160 770.8333 1.0000
1.7220 724.6667 1.0000
1.7280 763.0000 1.0000
1.7340 694.1667 1.0000
1.7400 690.8333 1.0000
1.7460 666.5000 1.0000
1.7520 649.3333 1.0000
1.7580 686.3333 1.0000
1.7640 626.5000 1.0000
1.7700 654.0000 1.0000
1.7760 602.6667 1.0000
1.7820 615.1667 1.0000
1.7880 642.5000 1.0000
1.7940 609.8333 1.0000
1.8000 595.6667 1.0000
1.8060 581.5000 1.0000
1.8120 597.5000 1.0000
1.8180 596.0000 1.0000
1.8240 592.8333 1.0000
1.8300 561.8333 1.0000
1.8360 554.5000 1.0000
1.8420 537.5000 1.0000
1.8480 555.1667 1.0000
1.8540 565.8333 1.0000
1.8600 582.6667 1.0000
1.8660 584.1667 1.0000
1.8720 577.8333 1.0000
1.8780 524.6667 1.0000
1.8840 578.3333 1.0000
1.8900 537.0000 1.0000
1.8960 534.3333 1.0000
1.9020 485.0000 1.0000
1.9080 540.8333 1.0000
1.9140 527.8333 1.0000
1.9200 506.1667 1.0000
1.9260 454.0000 1.0000
1.9320 471.5000 1.0000
1.9380 485.6667 1.0000
1.9440 471.1667 1.0000
1.9500 440.8333 1.0000
1.9560 418.6667 1.0000
1.9620 398.1667 1.0000
1.9680 378.1667 1.0000
1.9740 404.5000 1.0000
1.9800 385.3333 1.0000
1.9860 352.5000 1.0000
1.9920 368.6667 1.0000
1.9980 338.5000 1.0000
2.0040 330.1667 1.0000
2.0100 337.1667 1.0000
2.0160 307.6667 1.0000
2.0220 348.1667 1.0000
2.0280 316.1667 1.0000
2.0340 322.3333 1.0000
2.0400 298.6667 1.0000
2.0460 307.1667 1.0000
2.0520 281.8333 1.0000
2.0580 263.8333 1.0000
2.0640 295.1667 1.0000
2.0700 268.5000 1.0000
2.0760 257.8333 1.0000
2.0820 260.8333 1.0000
2.0880 269.1667 1.0000
2.0940 265.6667 1.0000
2.1000 271.1667 1.0000
2.1060 261.3333 1.0000
2.1120 289.5000 1.0000
2.1180 261.0000 1.0000
2.1240 242.0000 1.0000
2.1300 243.1667 1.0000
2.1360 249.5000 1.0000
2.1420 295.8333 1.0000
2.1480 266.6667 1.0000
2.1540 260.0000 1.0000
2.1600 288.1667 1.0000
2.1660 248.0000 1.0000
2.1720 262.0000 1.0000
2.1780 240.5000 1.0000
2.1840 261.3333 1.0000
2.1900 254.3333 1.0000
2.1960 229.5000 1.0000
2.2020 238.5000 1.0000
2.2080 225.1667 1.0000
2.2140 222.6667 1.0000
2.2200 233.8333 1.0000
2.2260 212.5000 1.0000
2.2320 210.0000 1.0000
2.2380 216.8333 1.0000
2.2440 241.1667 1.0000
2.2500 214.6667 1.0000
2.2560 207.8333 1.0000
2.2620 177.0000 1.0000
2.2680 159.0000 1.0000
2.2740 166.0000 1.0000
2.2800 174.5000 1.0000
2.2860 186.8333 1.0000
2.2920 159.0000 1.0000
2.2980 150.5000 1.0000
2.3040 152.5000 1.0000
2.3100 120.5000 1.0000
2.3160 149.5000 1.0000
2.3220 146.0000 1.0000
2.3280 139.6667 1.0000
2.3340 123.1667 1.0000
2.3400 122.8333 1.0000
2.3460 117.1667 1.0000
2.3520 121.8333 1.0000
2.3580 140.5000 1.0000
2.3640 120.3333 1.0000
2.3700 129.3333 1.0000
2.3760 123.3333 1.0000
2.3820 108.8333 1.0000
2.3880 111.3333 1.0000
2.3940 123.1667 1.0000
2.4000 128.0000 1.0000
2.4060 146.6667 1.0000
2.4120 130.8333 1.0000
2.4180 115.6667 1.0000
2.4240 152.5000 1.0000
2.4300 129.0000 1.0000
2.4360 137.8333 1.0000
2.4420 129.6667 1.0000
2.4480 147.8333 1.0000
2.4540 134.3333 1.0000
2.4600 126.0000 1.0000
2.4660 128.5000 1.0000
2.4720 136.5000 1.0000
2.4780 106.3333 1.0000
2.4840 119.3333 1.0000
2.4900 117.3333 1.0000
2.4960 143.1667 1.0000
2.5020 101.0000 1.0000
2.5080 120.8333 1.0000
2.5140 113.6667 1.0000
2.5200 97.5000 1.0000
2.5260 109.8333 1.0000
2.5320 109.6667 1.0000
2.5380 101.8333 1.0000
2.5440 113.5000 1.0000
2.5500 80.5000 1.0000
2.5560 78.0000 1.0000
2.5620 83.3333 1.0000
2.5680 103.6667 1.0000
2.5740 91.8333 1.0000
2.5800 73.0000 1.0000
2.5860 60.3333 1.0000
2.5920 67.3333 1.0000
2.5980 65.1667 1.0000
2.6040 64.0000 1.0000
2.6100 59.3333 1.0000
2.6160 59.6667 1.0000
2.6220 59.1667 1.0000
2.6280 56.1667 1.0000
2.6340 79.0000 1.0000
2.6400 51.1667 1.0000
2.6460 65.8333 1.0000
2.6520 98.5000 1.0000
2.6580 68.5000 1.0000
2.6640 71.0000 1.0000
2.6700 65.8333 1.0000
2.6760 65.5000 1.0000
2.6820 54.6667 1.0000
2.6880 59.8333 1.0000
2.6940 93.5000 1.0000
2.7000 61.6667 1.0000
2.7060 57.0000 1.0000
2.7120 66.5000 1.0000
2.7180 70.6667 1.0000
2.7240 54.8333 1.0000
2.7300 48.0000 1.0000
2.7360 64.5000 1.0000
2.7420 60.0000 1.0000
2.7480 58.5000 1.0000
2.7540 66.3333 1.0000
2.7600 70.5000 1.0000
2.7660 70.0000 1.0000
2.7720 55.5000 1.0000
2.7780 62.5000 1.0000
2.7840 68.8333 1.0000
2.7900 58.0000 1.0000
2.7960 74.6667 1.0000
2.8020 62.6667 1.0000
2.8080 54.0000 1.0000
2.8140 47.0000 1.0000
2.8200 47.5000 1.0000
2.8260 53.8333 1.0000
2.8320 44.8333 1.0000
2.8380 46.5000 1.0000
2.8440 47.6667 1.0000
2.8500 62.3333 1.0000
2.8560 50.3333 1.0000
2.8620 43.1667 1.0000
2.8680 46.6667 1.0000
2.8740 40.0000 1.0000
2.8800 44.1667 1.0000
2.8860 43.8333 1.0000
2.8920 26.1667 1.0000
2.8980 36.3333 1.0000
2.9040 31.3333 1.0000
2.9100 28.3333 1.0000
2.9160 26.8333 1.0000
2.9220 36.0000 1.0000
2.9280 40.6667 1.0000
2.9340 35.6667 1.0000
2.9400 34.8333 1.0000
2.9460 22.8333 1.0000
2.9520 33.8333 1.0000
2.9580 33.8333 1.0000
2.9640 37.0000 1.0000
2.9700 27.5000 1.0000
2.9760 25.3333 1.0000
2.9820 29.1667 1.0000
2.9880 26.8333 1.0000
2.9940 29.0000 1.0000
3.0000 24.6667 1.0000
3.0060 22.8333 1.0000
3.0120 35.8333 1.0000
3.0180 30.8333 1.0000
3.0240 36.8333 1.0000
3.0300 27.5000 1.0000
3.0360 30.5000 1.0000
3.0420 29.8333 1.0000
3.0480 25.8333 1.0000
3.0540 27.3333 1.0000
3.0600 41.3333 1.0000
3.0660 33.3333 1.0000
3.0720 31.5000 1.0000
3.0780 33.0000 1.0000
3.0840 22.6667 1.0000
3.0900 32.6667 1.0000
3.0960 37.8333 1.0000
3.1020 31.0000 1.0000
3.1080 26.0000 1.0000
3.1140 37.6667 1.0000
3.1200 17.5000 1.0000
3.1260 25.3333 1.0000
3.1320 33.8333 1.0000
3.1380 18.1667 1.0000
3.1440 21.3333 1.0000
3.1500 25.1667 1.0000
3.1560 24.8333 1.0000
3.1620 24.3333 1.0000
3.1680 13.5000 1.0000
3.1740 14.3333 1.0000
3.1800 20.8333 1.0000
3.1860 28.5000 1.0000
3.1920 26.0000 1.0000
3.1980 19.1667 1.0000
3.2040 16.8333 1.0000
3.2100 12.0000 1.0000
3.2160 7.5000 1.0000
3.2220 18.3333 1.0000
3.2280 16.8333 1.0000
3.2340 23.8333 1.0000
3.2400 13.6667 1.0000
3.2460 14.5000 1.0000
3.2520 17.3333 1.0000
3.2580 11.8333 1.0000
3.2640 12.5000 1.0000
3.2700 23.5000 1.0000
3.2760 21.5000 1.0000
3.2820 18.1667 1.0000
3.2880 18.8333 1.0000
3.2940 11.6667 1.0000
3.3000 11.6667 1.0000
3.3060 19.5000 1.0000
3.3120 12.5000 1.0000
3.3180 17.5000 1.0000
3.3240 16.3333 1.0000
3.3300 21.3333 1.0000
3.3360 24.0000 1.0000
3.3420 18.0000 1.0000
3.3480 10.0000 1.0000
3.3540 16.3333 1.0000
3.3600 16.8333 1.0000
3.3660 19.3333 1.0000
3.3720 18.8333 1.0000
3.3780 9.8333 1.0000
3.3840 18.1667 1.0000
3.3900 15.6667 1.0000
3.3960 22.5000 1.0000
3.4020 19.5000 1.0000
3.4080 17.8333 1.0000
3.4140 9.8333 1.0000
3.4200 13.6667 1.0000
3.4260 15.1667 1.0000
3.4320 16.6667 1.0000
3.4380 19.3333 1.0000
3.4440 10.6667 1.0000
3.4500 10.8333 1.0000
3.4560 11.5000 1.0000
3.4620 7.0000 1.0000
3.4680 14.0000 1.0000
3.4740 6.8333 1.0000
3.4800 9.1667 1.0000
3.4860 7.0000 1.0000
3.4920 10.3333 1.0000
3.4980 14.5000 1.0000
3.5040 7.3333 1.0000
3.5100 13.6667 1.0000
3.5160 10.3333 1.0000
3.5220 5.6667 1.0000
3.5280 18.6667 1.0000
3.5340 6.3333 1.0000
3.5400 8.6667 1.0000
3.5460 4.6667 1.0000
3.5520 6.3333 1.0000
3.5580 14.0000 1.0000
3.5640 3.1667 1.0000
3.5700 7.6667 1.0000
3.5760 7.8333 1.0000
3.5820 6.3333 1.0000
3.5880 7.3333 1.0000
3.5940 8.6667 1.0000
3.6000 5.6667 1.0000
3.6060 8.1667 1.0000
3.6120 8.1667 1.0000
3.6180 9.1667 1.0000
3.6240 4.5000 1.0000
3.6300 6.6667 1.0000
3.6360 10.1667 1.0000
3.6420 7.5000 1.0000
3.6480 3.6667 1.0000
3.6540 8.1667 1.0000
3.6600 17.0000 1.0000
3.6660 11.1667 1.0000
3.6720 10.6667 1.0000
3.6780 6.5000 1.0000
3.6840 7.3333 1.0000
3.6900 11.8333 1.0000
3.6960 8.3333 1.0000
3.7020 11.5000 1.0000
3.7080 11.6667 1.0000
3.7140 6.8333 1.0000
3.7200 4.3333 1.0000
3.7260 8.3333 1.0000
3.7320 6.8333 1.0000
3.7380 5.8333 1.0000
3.7440 6.0000 1.0000
3.7500 9.6667 1.0000
3.7560 15.0000 1.0000
3.7620 5.6667 1.0000
3.7680 8.6667 1.0000
3.7740 3.0000 1.0000
3.7800 4.1667 1.0000
3.7860 9.1667 1.0000
3.7920 3.5000 1.0000
3.7980 3.1667 1.0000
3.8040 3.1667 1.0000
3.8100 4.6667 1.0000
3.8160 1.1667 1.0000
3.8220 3.5000 1.0000
3.8280 7.5000 1.0000
3.8340 6.3333 1.0000
3.8400 0.0000 1.0000
3.8460 5.5000 1.0000
3.8520 0.5000 1.0000
3.8580 3.5000 1.0000
3.8640 0.1667 1.0000
3.8700 5.3333 1.0000
3.8760 3.0000 1.0000
3.8820 0.5000 1.0000
3.8880 3.3333 1.0000
3.8940 2.1667 1.0000
3.9000 5.6667 1.0000
3.9060 4.5000 1.0000
3.9120 7.3333 1.0000
3.9180 0.1667 1.0000
3.9240 2.8333 1.0000
3.9300 5.1667 1.0000
3.9360 2.3333 1.0000
3.9420 0.3333 1.0000
3.9480 4.5000 1.0000
3.9540 1.3333 1.0000
3.9600 1.3333 1.0000
3.9660 2.5000 1.0000
3.9720 0.0000 1.0000
3.9780 3.5000 1.0000
3.9840 6.6667 1.0000
3.9900 0.0000 1.0000
3.9960 4.0000 1.0000
4.0020 6.1667 1.0000
4.0080 2.0000 1.0000
4.0140 2.1667 1.0000
4.0200 0.0000 1.0000
4.0260 2.3333 1.0000
4.0320 0.0000 1.0000
4.0380 1.5000 1.0000
4.0440 1.1667 1.0000
4.0500 2.0000 1.0000
4.0560 5.3333 1.0000
4.0620 1.3333 1.0000
4.0680 0.0000 1.0000
4.0740 4.3333 1.0000
4.0800 1.3333 1.0000
4.0860 4.0000 1.0000
4.0920 1.3333 1.0000
4.0980 1.3333 1.0000
4.1040 2.1667 1.0000
4.1100 4.1667 1.0000
4.1160 2.1667 1.0000
4.1220 3.5000 1.0000
4.1280 0.0000 1.0000
4.1340 0.0000 1.0000
4.1400 0.3333 1.0000
4.1460 2.0000 1.0000
4.1520 0.0000 1.0000
4.1580 0.0000 1.0000
4.1640 0.1667 1.0000
4.1700 0.0000 1.0000
4.1760 7.1667 1.0000
4.1820 0.0000 1.0000
4.1880 0.0000 1.0000
4.1940 0.1667 1.0000
4.2000 1.5000 1.0000
4.2060 3.1667 1.0000
4.2120 3.3333 1.0000
4.2180 1.1667 1.0000
4.2240 2.3333 1.0000
4.2300 3.1667 1.0000
4.2360 4.3333 1.0000
4.2420 3.3333 1.0000
4.2480 0.0000 1.0000
4.2540 2.1667 1.0000
4.2600 1.1667 1.0000
4.2660 0.3333 1.0000
4.2720 0.0000 1.0000
4.2780 0.0000 1.0000
4.2840 1.5000 1.0000
4.2900 2.0000 1.0000
4.2960 3.3333 1.0000
4.3020 1.5000 1.0000
4.3080 2.1667 1.0000
4.3140 0.0000 1.0000
4.3200 3.0000 1.0000
4.3260 2.1667 1.0000
4.3320 0.0000 1.0000
4.3380 0.3333 1.0000
4.3440 2.1667 1.0000
4.3500 0.0000 1.0000
4.3560 2.0000 1.0000
4.3620 0.0000 1.0000
4.3680 0.1667 1.0000
4.3740 1.1667 1.0000
4.3800 0.0000 1.0000
4.3860 1.1667 1.0000
4.3920 1.1667 1.0000
4.3980 0.0000 1.0000
4.4040 0.0000 1.0000
4.4100 0.0000 1.0000
4.4160 0.0000 1.0000
4.4220 1.1667 1.0000
4.4280 0.0000 1.0000
4.4340 0.0000 1.0000
4.4400 0.0000 1.0000
4.4460 0.0000 1.0000
4.4520 0.0000 1.0000
4.4580 2.0000 1.0000
4.4640 0.0000 1.0000
4.4700 0.0000 1.0000
4.4760 0.0000 1.0000
4.4820 0.1667 1.0000
4.4880 0.0000 1.0000
4.4940 0.0000 1.0000
4.5000 0.0000 1.0000
4.5060 1.1667 1.0000
4.5120 0.0000 1.0000
4.5180 0.0000 1.0000
4.5240 0.0000 1.0000
4.5300 2.1667 1.0000
4.5360 0.0000 1.0000
4.5420 0.0000 1.0000
4.5480 0.1667 1.0000
4.5540 0.0000 1.0000
4.5600 0.0000 1.0000
4.5660 0.0000 1.0000
4.5720 0.0000 1.0000
4.5780 0.0000 1.0000
4.5840 0.3333 1.0000
4.5900 1.1667 1.0000
4.5960 0.1667 1.0000
4.6020 0.0000 1.0000
4.6080 0.1667 1.0000
4.6140 0.0000 1.0000
4.6200 0.0000 1.0000
4.6260 6.0000 1.0000
4.6320 1.1667 1.0000
4.6380 2.0000 1.0000
4.6440 0.0000 1.0000
4.6500 2.0000 1.0000
4.6560 0.0000 1.0000
4.6620 0.0000 1.0000
4.6680 3.3333 1.0000
4.6740 0.0000 1.0000
4.6800 0.0000 1.0000
4.6860 0.0000 1.0000
4.6920 0.0000 1.0000
4.6980 0.0000 1.0000
4.7040 0.0000 1.0000
4.7100 0.0000 1.0000
4.7160 2.0000 1.0000
4.7220 1.3333 1.0000
4.7280 2.1667 1.0000
4.7340 0.0000 1.0000
4.7400 0.0000 1.0000
4.7460 0.0000 1.0000
4.7520 2.0000 1.0000
4.7580 0.1667 1.0000
4.7640 0.0000 1.0000
4.7700 0.1667 1.0000
4.7760 2.1667 1.0000
4.7820 0.0000 1.0000
4.7880 0.0000 1.0000
4.7940 0.0000 1.0000
4.8000 0.0000 1.0000
4.8060 4.0000 1.0000
4.8120 3.0000 1.0000
4.8180 0.0000 1.0000
4.8240 0.0000 1.0000
4.8300 0.0000 1.0000
4.8360 0.0000 1.0000
4.8420 0.0000 1.0000
4.8480 0.0000 1.0000
4.8540 0.0000 1.0000
4.8600 0.0000 1.0000
4.8660 3.3333 1.0000
4.8720 3.0000 1.0000
4.8780 0.0000 1.0000
4.8840 0.3333 1.0000
4.8900 0.0000 1.0000
4.8960 0.0000 1.0000
4.9020 2.1667 1.0000
4.9080 0.0000 1.0000
4.9140 0.0000 1.0000
4.9200 0.0000 1.0000
4.9260 0.0000 1.0000
4.9320 0.0000 1.0000
4.9380 0.0000 1.0000
4.9440 0.0000 1.0000
4.9500 0.0000 1.0000
4.9560 1.1667 1.0000
4.9620 0.0000 1.0000
4.9680 0.0000 1.0000
4.9740 0.0000 1.0000
4.9800 2.1667 1.0000
4.9860 0.0000 1.0000
4.9920 0.0000 1.0000
4.9980 0.0000 1.0000
5.0040 0.0000 1.0000
5.0100 0.0000 1.0000
5.0160 0.0000 1.0000
5.0220 0.0000 1.0000
5.0280 0.0000 1.0000
5.0340 0.0000 1.0000
5.0400 1.1667 1.0000
5.0460 0.0000 1.0000
5.0520 0.0000 1.0000
5.0580 0.0000 1.0000
5.0640 0.0000 1.0000
5.0700 0.0000 1.0000
5.0760 0.0000 1.0000
5.0820 0.0000 1.0000
5.0880 0.0000 1.0000
5.0940 0.0000 1.0000
5.1000 0.0000 1.0000
5.1060 0.0000 1.0000
5.1120 0.0000 1.0000
5.1180 0.0000 1.0000
5.1240 0.1667 1.0000
5.1300 0.0000 1.0000
5.1360 0.0000 1.0000
5.1420 0.0000 1.0000
5.1480 0.0000 1.0000
5.1540 0.0000 1.0000
5.1600 0.0000 1.0000
5.1660 0.0000 1.0000
5.1720 0.0000 1.0000
5.1780 0.0000 1.0000
5.1840 0.0000 1.0000
5.1900 0.0000 1.0000
5.1960 0.0000 1.0000
5.2020 0.1667 1.0000
5.2080 0.0000 1.0000
5.2140 0.0000 1.0000
5.2200 0.0000 1.0000
5.2260 0.0000 1.0000
5.2320 0.0000 1.0000
5.2380 0.0000 1.0000
5.2440 0.0000 1.0000
5.2500 0.0000 1.0000
5.2560 0.0000 1.0000
5.2620 0.0000 1.0000
5.2680 0.0000 1.0000
5.2740 0.0000 1.0000
5.2800 0.0000 1.0000
5.2860 0.0000 1.0000
5.2920 0.0000 1.0000
5.2980 0.0000 1.0000
5.3040 0.0000 1.0000
5.3100 0.0000 1.0000
5.3160 0.0000 1.0000
5.3220 0.0000 1.0000
5.3280 0.0000 1.0000
5.3340 0.0000 1.0000
5.3400 0.0000 1.0000
5.3460 0.0000 1.0000
5.3520 0.0000 1.0000
5.3580 0.0000 1.0000
5.3640 0.0000 1.0000
5.3700 0.0000 1.0000
5.3760 0.0000 1.0000
5.3820 0.0000 1.0000
5.3880 0.0000 1.0000
5.3940 0.0000 1.0000
5.4000 1.1667 1.0000
5.4060 0.0000 1.0000
5.4120 0.0000 1.0000
5.4180 0.0000 1.0000
5.4240 0.0000 1.0000
5.4300 0.0000 1.0000
5.4360 0.0000 1.0000
5.4420 0.0000 1.0000
5.4480 0.0000 1.0000
5.4540 0.0000 1.0000
5.4600 0.0000 1.0000
5.4660 0.0000 1.0000
5.4720 0.0000 1.0000
5.4780 0.0000 1.0000
5.4840 0.0000 1.0000
5.4900 0.0000 1.0000
5.4960 0.0000 1.0000
5.5020 0.0000 1.0000
5.5080 0.0000 1.0000
5.5140 0.0000 1.0000
5.5200 0.0000 1.0000
5.5260 0.0000 1.0000
5.5320 0.0000 1.0000
5.5380 0.0000 1.0000
5.5440 0.0000 1.0000
5.5500 0.0000 1.0000
5.5560 0.0000 1.0000
5.5620 0.0000 1.0000
5.5680 0.0000 1.0000
5.5740 0.0000 1.0000
5.5800 0.0000 1.0000
5.5860 0.1667 1.0000
5.5920 0.0000 1.0000
5.5980 0.0000 1.0000
5.6040 0.0000 1.0000
5.6100 0.0000 1.0000
5.6160 0.0000 1.0000
5.6220 0.0000 1.0000
5.6280 0.0000 1.0000
5.6340 0.0000 1.0000
5.6400 0.0000 1.0000
5.6460 0.0000 1.0000
5.6520 0.0000 1.0000
5.6580 0.0000 1.0000
5.6640 0.0000 1.0000
5.6700 0.0000 1.0000
5.6760 0.0000 1.0000
5.6820 0.0000 1.0000
5.6880 0.0000 1.0000
5.6940 0.0000 1.0000
5.7000 0.0000 1.0000
5.7060 0.0000 1.0000
5.7120 0.0000 1.0000
5.7180 0.0000 1.0000
5.7240 0.0000 1.0000
5.7300 0.0000 1.0000
5.7360 0.0000 1.0000
5.7420 0.0000 1.0000
5.7480 0.0000 1.0000
5.7540 0.0000 1.0000
5.7600 0.0000 1.0000
5.7660 0.0000 1.0000
5.7720 0.0000 1.0000
5.7780 0.0000 1.0000
5.7840 0.0000 1.0000
5.7900 0.0000 1.0000
5.7960 0.0000 1.0000
5.8020 0.0000 1.0000
5.8080 0.0000 1.0000
5.8140 0.0000 1.0000
5.8200 0.0000 1.0000
5.8260 0.0000 1.0000
5.8320 0.0000 1.0000
5.8380 0.1667 1.0000
5.8440 0.0000 1.0000
5.8500 0.0000 1.0000
5.8560 0.0000 1.0000
5.8620 0.0000 1.0000
5.8680 0.0000 1.0000
5.8740 0.0000 1.0000
5.8800 0.0000 1.0000
5.8860 0.0000 1.0000
5.8920 0.0000 1.0000
5.8980 0.0000 1.0000
5.9040 0.0000 1.0000
5.9100 0.0000 1.0000
5.9160 0.0000 1.0000
5.9220 0.0000 1.0000
5.9280 0.0000 1.0000
5.9340 0.0000 1.0000
5.9400 0.0000 1.0000
5.9460 0.0000 1.0000
5.9520 3.0000 1.0000
5.9580 0.0000 1.0000
5.9640 0.0000 1.0000
5.9700 0.0000 1.0000
5.9760 0.0000 1.0000
5.9820 0.0000 1.0000
5.9880 0.0000 1.0000
5.9940 0.0000 1.0000
6.0000 0.0000 1.0000
*RAS_INT_END
*RAS_DATA_END