File: xrr_temp/CWOI2_reflectivity.ras
*RAS_DATA_START
*RAS_HEADER_START
*DISP_FMT_X "%.4f"
*DISP_FMT_Y "%.0f"
*DISP_FULLSCALE "2083871.1233333335"
*DISP_LINE_COLOR "255.0000000000"
*DISP_LINE_STYLE "0.0000000000"
*DISP_LINE_WIDTH "0.2500000000"
*DISP_NOTE "Collected Data-11"
*DISP_OFFSET_Y "0.0000000000"
*DISP_PEAKSEARCH_UNIT_Y "cps"
*DISP_RANGE_BOTTOM "0.0100000000"
*DISP_RANGE_LEFT "-0.0006000000"
*DISP_RANGE_LOGCUTOFF "0.0100000000"
*DISP_RANGE_RIGHT "6.0006000000"
*DISP_RANGE_TOP "2083871.1233333335"
*DISP_SCALE_MODE_Y "2.0000000000"
*DISP_TAB_NAME "2-Theta/Omega"
*DISP_TITLE_Y "Intensity"
*DISP_UNIT_Y "cps"
*DISP_WINDOW_NAME "MSG_MACROENGINE"
*FILE_COMMENT " "
*FILE_MD5 ""
*FILE_MEMO " "
*FILE_OPERATOR "Administrator"
*FILE_PART_ID "MEAS_KHP2_00055"
*FILE_SAMPLE "I-2"
*FILE_TYPE "RAS_RAW"
*FILE_USERGROUP "System Manager"
*FILE_VERSION "1.0000000000"
*HW_ATTACHMENT_ID "ATT0025"
*HW_ATTACHMENT_NAME "標準|Standard"
*HW_COUNTER_ID-0 "CUT0025"
*HW_COUNTER_ID-1 "CUT0020"
*HW_COUNTER_ID-2 "CUT0020"
*HW_COUNTER_ID-3 "CSL0021"
*HW_COUNTER_ID-4 "CMC0021"
*HW_COUNTER_NAME-0 "D/teX Ultra|D/teX Ultra"
*HW_COUNTER_NAME-1 "None|None"
*HW_COUNTER_NAME-2 "None|None"
*HW_COUNTER_NAME-3 "BBM|BBM"
*HW_COUNTER_NAME-4 "検出器モノクロメータ|Detector monochromator"
*HW_COUNTER_SELECT_NAME "D/teX Ultra|D/teX Ultra"
*HW_GONIOMETER_ID "GON0023"
*HW_GONIOMETER_NAME "SmartLab|SmartLab"
*HW_GONIOMETER_RADIUS-0 "90.0"
*HW_GONIOMETER_RADIUS-1 "114.0"
*HW_GONIOMETER_RADIUS-2 "190.0"
*HW_GONIOMETER_RADIUS-3 "300.0"
*HW_GONIOMETER_RADIUS-4 "187.0"
*HW_GONIOMETER_RADIUS-5 "300.0"
*HW_GONIOMETER_RADIUS-6 "113.0"
*HW_GONIOMETER_RADIUS-7 "331.0"
*HW_I_OPT_ID-0 "CBO0021"
*HW_I_OPT_ID-1 "ICR0021"
*HW_I_OPT_ID-2 "ISL0021"
*HW_I_OPT_ID-3 "ISO0021"
*HW_I_OPT_ID-4 "IAD0021"
*HW_I_OPT_ID-5 "IPR0001"
*HW_I_OPT_NAME-0 "CBOユニット|CBO unit"
*HW_I_OPT_NAME-1 "標準入射光学ユニット|Standard incident optical unit"
*HW_I_OPT_NAME-2 "標準入射スリットボックス|Standard incident slit box"
*HW_I_OPT_NAME-3 "入射平行スリット|Incident parallel slit"
*HW_I_OPT_NAME-4 "長手制限スリット|Length limiting slit"
*HW_I_OPT_NAME-5 "None|None"
*HW_R_ATTENUATER_AUTOMODE "1"
*HW_R_OPT_ID-0 "RSS0021"
*HW_R_OPT_ID-1 "RCR0023"
*HW_R_OPT_ID-2 "RSO0021"
*HW_R_OPT_ID-3 "RRS0021"
*HW_R_OPT_ID-4 "ATN0021"
*HW_R_OPT_ID-5 "RFL0021"
*HW_R_OPT_ID-6 "RAD0021"
*HW_R_OPT_NAME-0 "標準受光スリットボックス1|Standard receiving slit box # 1"
*HW_R_OPT_NAME-1 "標準受光光学ユニット1|Standard receiving unit # 1"
*HW_R_OPT_NAME-2 "標準受光光学ユニット2|Standard receiving optical unit # 2"
*HW_R_OPT_NAME-3 "標準受光スリットボックス2|Standard receiving slit box # 2"
*HW_R_OPT_NAME-4 "標準アッテネータ|Standard Attenuator"
*HW_R_OPT_NAME-5 "Cu Kβ|Cu K-beta"
*HW_R_OPT_NAME-6 "調整用受光スリット|Alignment receiving slit"
*HW_SAMPLE_HOLDER_ID "SMP0021"
*HW_SAMPLE_HOLDER_NAME "χφZクレードル|Chi phi Z cradle"
*HW_XG_CURRENT_MAX "200"
*HW_XG_CURRENT_MIN "10"
*HW_XG_CURRENT_RESOLUTION "1"
*HW_XG_CURRENT_UNIT "mA"
*HW_XG_FOCUS "0.4mm x 8mm"
*HW_XG_FOCUS_TYPE "Normal"
*HW_XG_ID "1700"
*HW_XG_NAME "9kW 開放管(45kV 200mA ID:1700)|9kW Rotating anode(45kV 200mA ID:1700)"
*HW_XG_TARGET_ATOMIC_NUMBER "29.0000000000"
*HW_XG_TARGET_NAME "Cu"
*HW_XG_TYPE "Rota"
*HW_XG_VOLTAGE_MAX "45"
*HW_XG_VOLTAGE_MIN "20"
*HW_XG_VOLTAGE_RESOLUTION "1"
*HW_XG_VOLTAGE_UNIT "kV"
*HW_XG_WATT_MAX "9.00"
*HW_XG_WATT_UNIT "kW"
*HW_XG_WAVE_LENGTH_ALPHA1 "1.540593"
*HW_XG_WAVE_LENGTH_ALPHA2 "1.544414"
*HW_XG_WAVE_LENGTH_BETA "1.392250"
*MEAS_COND_AXIS_NAME-0 "Theta/2-Theta"
*MEAS_COND_AXIS_NAME-1 "2-Theta"
*MEAS_COND_AXIS_NAME-2 "Omega"
*MEAS_COND_AXIS_NAME-3 "Chi"
*MEAS_COND_AXIS_NAME-4 "Phi"
*MEAS_COND_AXIS_NAME-5 "Z"
*MEAS_COND_AXIS_NAME-6 "2-Theta/Omega"
*MEAS_COND_AXIS_NAME-7 "Theta_s"
*MEAS_COND_AXIS_NAME-8 "Theta_d"
*MEAS_COND_AXIS_NAME-9 "Ts"
*MEAS_COND_AXIS_NAME-10 "CBO selection slit"
*MEAS_COND_AXIS_NAME-11 "M"
*MEAS_COND_AXIS_NAME-12 "Incident parallel slit"
*MEAS_COND_AXIS_NAME-13 "Incident slit"
*MEAS_COND_AXIS_NAME-14 ""
*MEAS_COND_AXIS_NAME-15 "Zs"
*MEAS_COND_AXIS_NAME-16 "Incident optical device"
*MEAS_COND_AXIS_NAME-17 "Omega_m"
*MEAS_COND_AXIS_NAME-18 "Length limiting slit"
*MEAS_COND_AXIS_NAME-19 "Center slit"
*MEAS_COND_AXIS_NAME-20 "Filter"
*MEAS_COND_AXIS_NAME-21 "Receiving slit # 1"
*MEAS_COND_AXIS_NAME-22 "Receiving slit # 2"
*MEAS_COND_AXIS_NAME-23 "Receiving optical device"
*MEAS_COND_AXIS_NAME-24 "Receiving parallel slit"
*MEAS_COND_AXIS_NAME-25 "Alignment receiving slit"
*MEAS_COND_AXIS_NAME-26 ""
*MEAS_COND_AXIS_NAME-27 ""
*MEAS_COND_AXIS_NAME-28 "Zd"
*MEAS_COND_AXIS_NAME-29 "Attenuator"
*MEAS_COND_AXIS_NAME-30 "Diffracted beam monochromator"
*MEAS_COND_AXIS_NAME-31 "Monochromator slit"
*MEAS_COND_AXIS_NAME-32 ""
*MEAS_COND_AXIS_NAME-33 ""
*MEAS_COND_AXIS_NAME-34 "Primary beam"
*MEAS_COND_AXIS_NAME-35 "PHA"
*MEAS_COND_AXIS_NAME_INTERNAL-0 "TwoThetaTheta"
*MEAS_COND_AXIS_NAME_INTERNAL-1 "TwoTheta"
*MEAS_COND_AXIS_NAME_INTERNAL-2 "Omega"
*MEAS_COND_AXIS_NAME_INTERNAL-3 "Chi"
*MEAS_COND_AXIS_NAME_INTERNAL-4 "Phi"
*MEAS_COND_AXIS_NAME_INTERNAL-5 "Z"
*MEAS_COND_AXIS_NAME_INTERNAL-6 "TwoThetaOmega"
*MEAS_COND_AXIS_NAME_INTERNAL-7 "ThetaS"
*MEAS_COND_AXIS_NAME_INTERNAL-8 "ThetaD"
*MEAS_COND_AXIS_NAME_INTERNAL-9 "Ts"
*MEAS_COND_AXIS_NAME_INTERNAL-10 "CBO"
*MEAS_COND_AXIS_NAME_INTERNAL-11 "CBO-M"
*MEAS_COND_AXIS_NAME_INTERNAL-12 "IncidentSollerSlit"
*MEAS_COND_AXIS_NAME_INTERNAL-13 "IncidentSlitBox"
*MEAS_COND_AXIS_NAME_INTERNAL-14 "IncidentSlitBox-_Axis"
*MEAS_COND_AXIS_NAME_INTERNAL-15 "Zs"
*MEAS_COND_AXIS_NAME_INTERNAL-16 "IncidentMonochromator"
*MEAS_COND_AXIS_NAME_INTERNAL-17 "IncidentMonochromator-OmegaM"
*MEAS_COND_AXIS_NAME_INTERNAL-18 "IncidentAxdSlit"
*MEAS_COND_AXIS_NAME_INTERNAL-19 "CenterSlit"
*MEAS_COND_AXIS_NAME_INTERNAL-20 "Filter"
*MEAS_COND_AXIS_NAME_INTERNAL-21 "ReceivingSlitBox1"
*MEAS_COND_AXIS_NAME_INTERNAL-22 "ReceivingSlitBox2"
*MEAS_COND_AXIS_NAME_INTERNAL-23 "ReceivingOptics"
*MEAS_COND_AXIS_NAME_INTERNAL-24 "ReceivingSollerSlit"
*MEAS_COND_AXIS_NAME_INTERNAL-25 "ReceivingAxdSlit"
*MEAS_COND_AXIS_NAME_INTERNAL-26 "ReceivingSlitBox1-_Axis"
*MEAS_COND_AXIS_NAME_INTERNAL-27 "ReceivingSlitBox2-_Axis"
*MEAS_COND_AXIS_NAME_INTERNAL-28 "ReceivingSlitBox2-Zd"
*MEAS_COND_AXIS_NAME_INTERNAL-29 "Attenuator"
*MEAS_COND_AXIS_NAME_INTERNAL-30 "CounterMonochromator"
*MEAS_COND_AXIS_NAME_INTERNAL-31 "CounterSlit"
*MEAS_COND_AXIS_NAME_INTERNAL-32 "AlphaR"
*MEAS_COND_AXIS_NAME_INTERNAL-33 "BetaR"
*MEAS_COND_AXIS_NAME_INTERNAL-34 "IncidentPrimary"
*MEAS_COND_AXIS_NAME_INTERNAL-35 "PHA"
*MEAS_COND_AXIS_NAME_MAGICNO-0 "83951616.0000000000"
*MEAS_COND_AXIS_NAME_MAGICNO-1 "268632064.0000000000"
*MEAS_COND_AXIS_NAME_MAGICNO-2 "268500992.0000000000"
*MEAS_COND_AXIS_NAME_MAGICNO-3 "268500992.0000000000"
*MEAS_COND_AXIS_NAME_MAGICNO-4 "268500992.0000000000"
*MEAS_COND_AXIS_NAME_MAGICNO-5 "285278208.0000000000"
*MEAS_COND_AXIS_NAME_MAGICNO-6 "83951616.0000000000"
*MEAS_COND_AXIS_NAME_MAGICNO-7 "131072.0000000000"
*MEAS_COND_AXIS_NAME_MAGICNO-8 "131072.0000000000"
*MEAS_COND_AXIS_NAME_MAGICNO-9 "318898176.0000000000"
*MEAS_COND_AXIS_NAME_MAGICNO-10 "20971521.0000000000"
*MEAS_COND_AXIS_NAME_MAGICNO-11 "285343744.0000000000"
*MEAS_COND_AXIS_NAME_MAGICNO-12 "20971521.0000000000"
*MEAS_COND_AXIS_NAME_MAGICNO-13 "22020097.0000000000"
*MEAS_COND_AXIS_NAME_MAGICNO-14 "25165824.0000000000"
*MEAS_COND_AXIS_NAME_MAGICNO-15 "318898176.0000000000"
*MEAS_COND_AXIS_NAME_MAGICNO-16 "20971521.0000000000"
*MEAS_COND_AXIS_NAME_MAGICNO-17 "285343744.0000000000"
*MEAS_COND_AXIS_NAME_MAGICNO-18 "20971521.0000000000"
*MEAS_COND_AXIS_NAME_MAGICNO-19 "20971521.0000000000"
*MEAS_COND_AXIS_NAME_MAGICNO-20 "20971521.0000000000"
*MEAS_COND_AXIS_NAME_MAGICNO-21 "23068673.0000000000"
*MEAS_COND_AXIS_NAME_MAGICNO-22 "23068673.0000000000"
*MEAS_COND_AXIS_NAME_MAGICNO-23 "20971521.0000000000"
*MEAS_COND_AXIS_NAME_MAGICNO-24 "20971521.0000000000"
*MEAS_COND_AXIS_NAME_MAGICNO-25 "20971521.0000000000"
*MEAS_COND_AXIS_NAME_MAGICNO-26 "25165824.0000000000"
*MEAS_COND_AXIS_NAME_MAGICNO-27 "25165824.0000000000"
*MEAS_COND_AXIS_NAME_MAGICNO-28 "285343744.0000000000"
*MEAS_COND_AXIS_NAME_MAGICNO-29 "17301505.0000000000"
*MEAS_COND_AXIS_NAME_MAGICNO-30 "20971521.0000000000"
*MEAS_COND_AXIS_NAME_MAGICNO-31 "20971521.0000000000"
*MEAS_COND_AXIS_NAME_MAGICNO-32 "8388608.0000000000"
*MEAS_COND_AXIS_NAME_MAGICNO-33 "8388608.0000000000"
*MEAS_COND_AXIS_NAME_MAGICNO-34 "20971521.0000000000"
*MEAS_COND_AXIS_NAME_MAGICNO-35 "0.0000000000"
*MEAS_COND_AXIS_OFFSET-0 "-"
*MEAS_COND_AXIS_OFFSET-1 "0.7788000000"
*MEAS_COND_AXIS_OFFSET-2 "0.6033000000"
*MEAS_COND_AXIS_OFFSET-3 "0.0000000000"
*MEAS_COND_AXIS_OFFSET-4 "0.0000000000"
*MEAS_COND_AXIS_OFFSET-5 "-"
*MEAS_COND_AXIS_OFFSET-6 "-"
*MEAS_COND_AXIS_OFFSET-7 "0.6033000000"
*MEAS_COND_AXIS_OFFSET-8 "0.1755000000"
*MEAS_COND_AXIS_OFFSET-9 "-"
*MEAS_COND_AXIS_OFFSET-10 "-"
*MEAS_COND_AXIS_OFFSET-11 "-"
*MEAS_COND_AXIS_OFFSET-12 "-"
*MEAS_COND_AXIS_OFFSET-13 "-"
*MEAS_COND_AXIS_OFFSET-14 "-"
*MEAS_COND_AXIS_OFFSET-15 "-"
*MEAS_COND_AXIS_OFFSET-16 "-"
*MEAS_COND_AXIS_OFFSET-17 "-"
*MEAS_COND_AXIS_OFFSET-18 "-"
*MEAS_COND_AXIS_OFFSET-19 "-"
*MEAS_COND_AXIS_OFFSET-20 "-"
*MEAS_COND_AXIS_OFFSET-21 "-"
*MEAS_COND_AXIS_OFFSET-22 "-"
*MEAS_COND_AXIS_OFFSET-23 "-"
*MEAS_COND_AXIS_OFFSET-24 "-"
*MEAS_COND_AXIS_OFFSET-25 "-"
*MEAS_COND_AXIS_OFFSET-26 "-"
*MEAS_COND_AXIS_OFFSET-27 "-"
*MEAS_COND_AXIS_OFFSET-28 "-"
*MEAS_COND_AXIS_OFFSET-29 "-"
*MEAS_COND_AXIS_OFFSET-30 "-"
*MEAS_COND_AXIS_OFFSET-31 "-"
*MEAS_COND_AXIS_OFFSET-32 "0.0000000000"
*MEAS_COND_AXIS_OFFSET-33 "0.0000000000"
*MEAS_COND_AXIS_OFFSET-34 "-"
*MEAS_COND_AXIS_OFFSET-35 "-"
*MEAS_COND_AXIS_POSITION-0 "-0.0008000000"
*MEAS_COND_AXIS_POSITION-1 "-0.0009000000"
*MEAS_COND_AXIS_POSITION-2 "-0.0004000000"
*MEAS_COND_AXIS_POSITION-3 "0.0000000000"
*MEAS_COND_AXIS_POSITION-4 "0.0000000000"
*MEAS_COND_AXIS_POSITION-5 "-1.4286000000"
*MEAS_COND_AXIS_POSITION-6 "-0.0008000000"
*MEAS_COND_AXIS_POSITION-7 "-0.0004000000"
*MEAS_COND_AXIS_POSITION-8 "-0.0005000000"
*MEAS_COND_AXIS_POSITION-9 "-4.3477500000"
*MEAS_COND_AXIS_POSITION-10 "PB"
*MEAS_COND_AXIS_POSITION-11 "0.0000000000"
*MEAS_COND_AXIS_POSITION-12 "Soller_slit_open_s"
*MEAS_COND_AXIS_POSITION-13 "0.250mm"
*MEAS_COND_AXIS_POSITION-14 "0.2500000000"
*MEAS_COND_AXIS_POSITION-15 "-0.6878100000"
*MEAS_COND_AXIS_POSITION-16 "Ge(220)x2"
*MEAS_COND_AXIS_POSITION-17 "0.0000000000"
*MEAS_COND_AXIS_POSITION-18 "2.0mm"
*MEAS_COND_AXIS_POSITION-19 "None"
*MEAS_COND_AXIS_POSITION-20 "None"
*MEAS_COND_AXIS_POSITION-21 "0.250mm"
*MEAS_COND_AXIS_POSITION-22 "0.250mm"
*MEAS_COND_AXIS_POSITION-23 "No_unit"
*MEAS_COND_AXIS_POSITION-24 "Soller_slit_5.0deg"
*MEAS_COND_AXIS_POSITION-25 "None"
*MEAS_COND_AXIS_POSITION-26 "0.2500000000"
*MEAS_COND_AXIS_POSITION-27 "0.2500000000"
*MEAS_COND_AXIS_POSITION-28 "0.0843800000"
*MEAS_COND_AXIS_POSITION-29 "1/10000"
*MEAS_COND_AXIS_POSITION-30 "None"
*MEAS_COND_AXIS_POSITION-31 "None"
*MEAS_COND_AXIS_POSITION-32 "0.0000000000"
*MEAS_COND_AXIS_POSITION-33 "0.0000000000"
*MEAS_COND_AXIS_POSITION-34 "None"
*MEAS_COND_AXIS_POSITION-35 "34.0000000000"
*MEAS_COND_AXIS_UNIT-0 "deg"
*MEAS_COND_AXIS_UNIT-1 "deg"
*MEAS_COND_AXIS_UNIT-2 "deg"
*MEAS_COND_AXIS_UNIT-3 "deg"
*MEAS_COND_AXIS_UNIT-4 "deg"
*MEAS_COND_AXIS_UNIT-5 "mm"
*MEAS_COND_AXIS_UNIT-6 "deg"
*MEAS_COND_AXIS_UNIT-7 "deg"
*MEAS_COND_AXIS_UNIT-8 "deg"
*MEAS_COND_AXIS_UNIT-9 "mm"
*MEAS_COND_AXIS_UNIT-10 ""
*MEAS_COND_AXIS_UNIT-11 "pulse"
*MEAS_COND_AXIS_UNIT-12 ""
*MEAS_COND_AXIS_UNIT-13 ""
*MEAS_COND_AXIS_UNIT-14 "mm"
*MEAS_COND_AXIS_UNIT-15 "mm"
*MEAS_COND_AXIS_UNIT-16 ""
*MEAS_COND_AXIS_UNIT-17 "pulse"
*MEAS_COND_AXIS_UNIT-18 ""
*MEAS_COND_AXIS_UNIT-19 ""
*MEAS_COND_AXIS_UNIT-20 ""
*MEAS_COND_AXIS_UNIT-21 ""
*MEAS_COND_AXIS_UNIT-22 ""
*MEAS_COND_AXIS_UNIT-23 ""
*MEAS_COND_AXIS_UNIT-24 ""
*MEAS_COND_AXIS_UNIT-25 ""
*MEAS_COND_AXIS_UNIT-26 "mm"
*MEAS_COND_AXIS_UNIT-27 "mm"
*MEAS_COND_AXIS_UNIT-28 "mm"
*MEAS_COND_AXIS_UNIT-29 ""
*MEAS_COND_AXIS_UNIT-30 ""
*MEAS_COND_AXIS_UNIT-31 ""
*MEAS_COND_AXIS_UNIT-32 "deg"
*MEAS_COND_AXIS_UNIT-33 "deg"
*MEAS_COND_AXIS_UNIT-34 ""
*MEAS_COND_AXIS_UNIT-35 "div"
*MEAS_COND_COUNTER_CNTLOSS_CORR "0.0000000000"
*MEAS_COND_COUNTER_PHABASE "34.0000000000"
*MEAS_COND_COUNTER_PHAWINDOW "19.0000000000"
*MEAS_COND_COUNTER_PHA_UNIT "div"
*MEAS_COND_COUNTER_TAUDIFF "2.0000000000"
*MEAS_COND_COUNTER_TAUINT "0.1000000000"
*MEAS_COND_IRRADIATION_MODE "OFF"
*MEAS_COND_IRRADIATION_WIDTH ""
*MEAS_COND_OPT_ATTR "High resolution parallel beam Ge(220)x2/RS"
*MEAS_COND_OPT_NAME "@High resolution PB-Ge(220)x2"
*MEAS_COND_UNSYMMETRIC_MODE "OFF"
*MEAS_COND_XG_CURRENT "200.0000000000"
*MEAS_COND_XG_VOLTAGE "45.0000000000"
*MEAS_COND_XG_WAVE_TYPE "Ka1"
*MEAS_DATA_COUNT "3001.0000000000"
*MEAS_SCAN_AXIS_X "2-Theta/Omega"
*MEAS_SCAN_AXIS_X_INTERNAL "TwoThetaOmega"
*MEAS_SCAN_END_TIME "10/17/23 16:22:33"
*MEAS_SCAN_MODE "CONTINUOUS"
*MEAS_SCAN_MONITOR "0"
*MEAS_SCAN_RESOLUTION_X "0.0002"
*MEAS_SCAN_SPEED "0.500000"
*MEAS_SCAN_SPEED_UNIT "deg/min"
*MEAS_SCAN_SPEED_USER "0.500000"
*MEAS_SCAN_START "0.0000000000"
*MEAS_SCAN_START_TIME "10/17/23 16:10:16"
*MEAS_SCAN_STEP "0.0020000000"
*MEAS_SCAN_STOP "6.0000000000"
*MEAS_SCAN_UNIT_X "deg"
*MEAS_SCAN_UNIT_Y "counts"
*RAS_HEADER_END
*RAS_INT_START
0.0000 387109.9688 1.0000
0.0060 384778.8438 1.0000
0.0120 393038.3438 1.0000
0.0180 381643.3438 1.0000
0.0240 376526.7500 1.0000
0.0300 353014.3125 1.0000
0.0360 300001.4688 1.0000
0.0420 232487.9219 1.0000
0.0480 173926.5313 1.0000
0.0540 118023.9609 1.0000
0.0600 69762.7656 1.0000
0.0660 37643.8320 1.0000
0.0720 19226.1660 1.0000
0.0780 12645.5000 1.0000
0.0840 10014.0000 1.0000
0.0900 8998.5000 1.0000
0.0960 8464.5000 1.0000
0.1020 8621.5000 1.0000
0.1080 8776.5000 1.0000
0.1140 9145.5000 1.0000
0.1200 9304.8330 1.0000
0.1260 9628.3330 1.0000
0.1320 10060.3330 1.0000
0.1380 10465.5000 1.0000
0.1440 10772.0000 1.0000
0.1500 10993.1670 1.0000
0.1560 11661.6670 1.0000
0.1620 11834.6670 1.0000
0.1680 12129.6670 1.0000
0.1740 12284.1670 1.0000
0.1800 12696.1670 1.0000
0.1860 13124.1670 1.0000
0.1920 13449.0000 1.0000
0.1980 13775.3330 1.0000
0.2040 14183.0000 1.0000
0.2100 14559.1670 1.0000
0.2160 14660.8330 1.0000
0.2220 14870.6670 1.0000
0.2280 15408.5000 1.0000
0.2340 15525.3330 1.0000
0.2400 16098.6670 1.0000
0.2460 16500.8340 1.0000
0.2520 16542.0000 1.0000
0.2580 17071.5000 1.0000
0.2640 17513.6660 1.0000
0.2700 17883.3340 1.0000
0.2760 18164.8340 1.0000
0.2820 18297.8340 1.0000
0.2880 18598.6660 1.0000
0.2940 19137.6660 1.0000
0.3000 19536.5000 1.0000
0.3060 19859.6660 1.0000
0.3120 20144.6660 1.0000
0.3180 20526.3340 1.0000
0.3240 20861.6660 1.0000
0.3300 21225.0000 1.0000
0.3360 21806.8340 1.0000
0.3420 22044.5000 1.0000
0.3480 22265.3340 1.0000
0.3540 22812.0000 1.0000
0.3600 22923.5000 1.0000
0.3660 23524.6660 1.0000
0.3720 23950.0000 1.0000
0.3780 23993.6660 1.0000
0.3840 24402.6660 1.0000
0.3900 24728.1660 1.0000
0.3960 24735.6660 1.0000
0.4020 25220.1660 1.0000
0.4080 25534.8340 1.0000
0.4140 26292.8340 1.0000
0.4200 26189.0000 1.0000
0.4260 26904.0000 1.0000
0.4320 26989.6660 1.0000
0.4380 27743.0000 1.0000
0.4440 27297.8340 1.0000
0.4500 28120.6660 1.0000
0.4560 28459.5000 1.0000
0.4620 28688.8340 1.0000
0.4680 28901.1660 1.0000
0.4740 29296.6660 1.0000
0.4800 29715.3340 1.0000
0.4860 29774.1660 1.0000
0.4920 29683.5000 1.0000
0.4980 30034.0000 1.0000
0.5040 30379.3340 1.0000
0.5100 30349.6660 1.0000
0.5160 30526.6660 1.0000
0.5220 30833.5000 1.0000
0.5280 31179.8340 1.0000
0.5340 31505.0000 1.0000
0.5400 31552.3340 1.0000
0.5460 31595.3340 1.0000
0.5520 31483.1660 1.0000
0.5580 31919.8340 1.0000
0.5640 31762.3340 1.0000
0.5700 32086.3340 1.0000
0.5760 32172.0000 1.0000
0.5820 32043.3340 1.0000
0.5880 31929.3340 1.0000
0.5940 31841.5000 1.0000
0.6000 31731.1660 1.0000
0.6060 31855.5000 1.0000
0.6120 31240.6660 1.0000
0.6180 31127.6660 1.0000
0.6240 30820.6660 1.0000
0.6300 30195.1660 1.0000
0.6360 29464.5000 1.0000
0.6420 28835.0000 1.0000
0.6480 28134.8340 1.0000
0.6540 27342.8340 1.0000
0.6600 25876.0000 1.0000
0.6660 24836.3340 1.0000
0.6720 23614.0000 1.0000
0.6780 22359.0000 1.0000
0.6840 20726.8340 1.0000
0.6900 19201.5000 1.0000
0.6960 17744.6660 1.0000
0.7020 16389.6660 1.0000
0.7080 14962.5000 1.0000
0.7140 13848.1670 1.0000
0.7200 12449.0000 1.0000
0.7260 11426.0000 1.0000
0.7320 10290.1670 1.0000
0.7380 9213.3330 1.0000
0.7440 8583.8330 1.0000
0.7500 7824.5000 1.0000
0.7560 7059.3335 1.0000
0.7620 6460.5000 1.0000
0.7680 6072.3335 1.0000
0.7740 5529.5000 1.0000
0.7800 5250.3335 1.0000
0.7860 5059.3335 1.0000
0.7920 4782.5000 1.0000
0.7980 4439.6665 1.0000
0.8040 4413.0000 1.0000
0.8100 4257.1665 1.0000
0.8160 4131.1665 1.0000
0.8220 4022.8333 1.0000
0.8280 3823.3333 1.0000
0.8340 3746.5000 1.0000
0.8400 3783.3333 1.0000
0.8460 3614.8333 1.0000
0.8520 3588.5000 1.0000
0.8580 3440.5000 1.0000
0.8640 3301.3333 1.0000
0.8700 3291.8333 1.0000
0.8760 3077.1667 1.0000
0.8820 2901.0000 1.0000
0.8880 2846.6667 1.0000
0.8940 2763.3333 1.0000
0.9000 2673.0000 1.0000
0.9060 2483.3333 1.0000
0.9120 2422.3333 1.0000
0.9180 2291.3333 1.0000
0.9240 2269.1667 1.0000
0.9300 2032.5000 1.0000
0.9360 2028.8334 1.0000
0.9420 1895.5000 1.0000
0.9480 1859.5000 1.0000
0.9540 1745.5000 1.0000
0.9600 1631.6666 1.0000
0.9660 1588.6666 1.0000
0.9720 1489.3334 1.0000
0.9780 1406.3334 1.0000
0.9840 1439.6666 1.0000
0.9900 1329.3334 1.0000
0.9960 1282.1666 1.0000
1.0020 1267.8334 1.0000
1.0080 1173.5000 1.0000
1.0140 1199.6666 1.0000
1.0200 1139.3334 1.0000
1.0260 1107.6666 1.0000
1.0320 1108.0000 1.0000
1.0380 1075.0000 1.0000
1.0440 1080.8334 1.0000
1.0500 1086.1666 1.0000
1.0560 971.3333 1.0000
1.0620 971.3333 1.0000
1.0680 1046.0000 1.0000
1.0740 1003.6667 1.0000
1.0800 984.0000 1.0000
1.0860 1046.5000 1.0000
1.0920 1019.0000 1.0000
1.0980 958.3333 1.0000
1.1040 944.0000 1.0000
1.1100 936.1667 1.0000
1.1160 939.1667 1.0000
1.1220 967.0000 1.0000
1.1280 933.0000 1.0000
1.1340 919.0000 1.0000
1.1400 864.1667 1.0000
1.1460 936.1667 1.0000
1.1520 896.6667 1.0000
1.1580 898.6667 1.0000
1.1640 827.5000 1.0000
1.1700 850.5000 1.0000
1.1760 792.8333 1.0000
1.1820 783.0000 1.0000
1.1880 781.0000 1.0000
1.1940 734.0000 1.0000
1.2000 723.6667 1.0000
1.2060 745.5000 1.0000
1.2120 654.1667 1.0000
1.2180 681.3333 1.0000
1.2240 631.0000 1.0000
1.2300 604.0000 1.0000
1.2360 570.5000 1.0000
1.2420 612.1667 1.0000
1.2480 569.8333 1.0000
1.2540 557.3333 1.0000
1.2600 504.8333 1.0000
1.2660 513.8333 1.0000
1.2720 504.3333 1.0000
1.2780 489.6667 1.0000
1.2840 436.6667 1.0000
1.2900 450.5000 1.0000
1.2960 413.5000 1.0000
1.3020 421.6667 1.0000
1.3080 434.8333 1.0000
1.3140 424.3333 1.0000
1.3200 391.8333 1.0000
1.3260 397.0000 1.0000
1.3320 364.5000 1.0000
1.3380 403.1667 1.0000
1.3440 401.1667 1.0000
1.3500 382.6667 1.0000
1.3560 385.3333 1.0000
1.3620 371.1667 1.0000
1.3680 387.6667 1.0000
1.3740 390.6667 1.0000
1.3800 408.3333 1.0000
1.3860 372.5000 1.0000
1.3920 373.0000 1.0000
1.3980 392.0000 1.0000
1.4040 390.1667 1.0000
1.4100 379.1667 1.0000
1.4160 378.1667 1.0000
1.4220 384.5000 1.0000
1.4280 386.5000 1.0000
1.4340 376.5000 1.0000
1.4400 371.8333 1.0000
1.4460 361.6667 1.0000
1.4520 345.0000 1.0000
1.4580 367.1667 1.0000
1.4640 365.0000 1.0000
1.4700 339.5000 1.0000
1.4760 345.0000 1.0000
1.4820 320.1667 1.0000
1.4880 321.5000 1.0000
1.4940 298.1667 1.0000
1.5000 323.3333 1.0000
1.5060 333.1667 1.0000
1.5120 305.5000 1.0000
1.5180 324.6667 1.0000
1.5240 277.8333 1.0000
1.5300 311.3333 1.0000
1.5360 278.5000 1.0000
1.5420 246.5000 1.0000
1.5480 252.5000 1.0000
1.5540 238.1667 1.0000
1.5600 223.3333 1.0000
1.5660 212.0000 1.0000
1.5720 222.3333 1.0000
1.5780 213.3333 1.0000
1.5840 196.8333 1.0000
1.5900 181.8333 1.0000
1.5960 205.6667 1.0000
1.6020 164.6667 1.0000
1.6080 187.1667 1.0000
1.6140 172.3333 1.0000
1.6200 190.3333 1.0000
1.6260 184.8333 1.0000
1.6320 162.6667 1.0000
1.6380 170.1667 1.0000
1.6440 167.3333 1.0000
1.6500 135.1667 1.0000
1.6560 139.8333 1.0000
1.6620 139.5000 1.0000
1.6680 154.8333 1.0000
1.6740 148.8333 1.0000
1.6800 117.0000 1.0000
1.6860 129.0000 1.0000
1.6920 153.6667 1.0000
1.6980 138.3333 1.0000
1.7040 142.6667 1.0000
1.7100 150.6667 1.0000
1.7160 138.8333 1.0000
1.7220 149.8333 1.0000
1.7280 149.8333 1.0000
1.7340 152.0000 1.0000
1.7400 157.5000 1.0000
1.7460 176.8333 1.0000
1.7520 159.1667 1.0000
1.7580 139.8333 1.0000
1.7640 143.3333 1.0000
1.7700 152.0000 1.0000
1.7760 172.3333 1.0000
1.7820 163.8333 1.0000
1.7880 148.0000 1.0000
1.7940 166.5000 1.0000
1.8000 147.3333 1.0000
1.8060 163.5000 1.0000
1.8120 158.0000 1.0000
1.8180 135.5000 1.0000
1.8240 152.8333 1.0000
1.8300 149.8333 1.0000
1.8360 154.0000 1.0000
1.8420 146.6667 1.0000
1.8480 131.8333 1.0000
1.8540 157.8333 1.0000
1.8600 149.6667 1.0000
1.8660 143.3333 1.0000
1.8720 136.6667 1.0000
1.8780 133.6667 1.0000
1.8840 117.1667 1.0000
1.8900 141.0000 1.0000
1.8960 106.3333 1.0000
1.9020 124.1667 1.0000
1.9080 110.0000 1.0000
1.9140 93.1667 1.0000
1.9200 88.1667 1.0000
1.9260 102.0000 1.0000
1.9320 119.0000 1.0000
1.9380 97.5000 1.0000
1.9440 85.5000 1.0000
1.9500 95.8333 1.0000
1.9560 101.5000 1.0000
1.9620 87.1667 1.0000
1.9680 74.3333 1.0000
1.9740 95.1667 1.0000
1.9800 87.8333 1.0000
1.9860 71.0000 1.0000
1.9920 72.5000 1.0000
1.9980 69.8333 1.0000
2.0040 74.3333 1.0000
2.0100 86.0000 1.0000
2.0160 71.8333 1.0000
2.0220 66.3333 1.0000
2.0280 60.5000 1.0000
2.0340 79.5000 1.0000
2.0400 79.8333 1.0000
2.0460 96.8333 1.0000
2.0520 87.6667 1.0000
2.0580 74.5000 1.0000
2.0640 87.3333 1.0000
2.0700 89.1667 1.0000
2.0760 80.8333 1.0000
2.0820 75.1667 1.0000
2.0880 79.6667 1.0000
2.0940 78.1667 1.0000
2.1000 90.1667 1.0000
2.1060 80.8333 1.0000
2.1120 69.6667 1.0000
2.1180 84.5000 1.0000
2.1240 83.3333 1.0000
2.1300 76.3333 1.0000
2.1360 77.3333 1.0000
2.1420 101.5000 1.0000
2.1480 88.5000 1.0000
2.1540 80.5000 1.0000
2.1600 89.3333 1.0000
2.1660 82.1667 1.0000
2.1720 77.6667 1.0000
2.1780 75.5000 1.0000
2.1840 69.3333 1.0000
2.1900 85.3333 1.0000
2.1960 82.6667 1.0000
2.2020 76.8333 1.0000
2.2080 81.6667 1.0000
2.2140 59.6667 1.0000
2.2200 68.5000 1.0000
2.2260 67.8333 1.0000
2.2320 70.6667 1.0000
2.2380 61.1667 1.0000
2.2440 53.1667 1.0000
2.2500 61.5000 1.0000
2.2560 64.0000 1.0000
2.2620 58.1667 1.0000
2.2680 47.1667 1.0000
2.2740 54.0000 1.0000
2.2800 47.8333 1.0000
2.2860 57.1667 1.0000
2.2920 50.3333 1.0000
2.2980 43.3333 1.0000
2.3040 38.1667 1.0000
2.3100 44.3333 1.0000
2.3160 53.5000 1.0000
2.3220 39.8333 1.0000
2.3280 47.3333 1.0000
2.3340 36.3333 1.0000
2.3400 44.8333 1.0000
2.3460 42.1667 1.0000
2.3520 39.1667 1.0000
2.3580 40.0000 1.0000
2.3640 31.6667 1.0000
2.3700 39.5000 1.0000
2.3760 34.1667 1.0000
2.3820 33.5000 1.0000
2.3880 45.6667 1.0000
2.3940 41.8333 1.0000
2.4000 41.3333 1.0000
2.4060 35.0000 1.0000
2.4120 37.5000 1.0000
2.4180 50.5000 1.0000
2.4240 24.0000 1.0000
2.4300 39.6667 1.0000
2.4360 29.8333 1.0000
2.4420 37.8333 1.0000
2.4480 33.6667 1.0000
2.4540 42.3333 1.0000
2.4600 43.5000 1.0000
2.4660 48.8333 1.0000
2.4720 40.5000 1.0000
2.4780 35.5000 1.0000
2.4840 43.8333 1.0000
2.4900 49.5000 1.0000
2.4960 33.3333 1.0000
2.5020 41.3333 1.0000
2.5080 37.5000 1.0000
2.5140 49.1667 1.0000
2.5200 43.6667 1.0000
2.5260 36.5000 1.0000
2.5320 44.3333 1.0000
2.5380 41.5000 1.0000
2.5440 47.0000 1.0000
2.5500 30.8333 1.0000
2.5560 44.6667 1.0000
2.5620 34.6667 1.0000
2.5680 40.5000 1.0000
2.5740 50.0000 1.0000
2.5800 38.5000 1.0000
2.5860 25.8333 1.0000
2.5920 40.1667 1.0000
2.5980 35.0000 1.0000
2.6040 29.8333 1.0000
2.6100 18.5000 1.0000
2.6160 31.1667 1.0000
2.6220 35.1667 1.0000
2.6280 31.8333 1.0000
2.6340 39.5000 1.0000
2.6400 30.3333 1.0000
2.6460 23.8333 1.0000
2.6520 27.8333 1.0000
2.6580 23.8333 1.0000
2.6640 25.6667 1.0000
2.6700 29.3333 1.0000
2.6760 21.1667 1.0000
2.6820 32.3333 1.0000
2.6880 27.1667 1.0000
2.6940 15.6667 1.0000
2.7000 24.3333 1.0000
2.7060 27.5000 1.0000
2.7120 12.3333 1.0000
2.7180 23.3333 1.0000
2.7240 16.6667 1.0000
2.7300 19.6667 1.0000
2.7360 28.6667 1.0000
2.7420 17.3333 1.0000
2.7480 25.5000 1.0000
2.7540 27.5000 1.0000
2.7600 21.1667 1.0000
2.7660 17.3333 1.0000
2.7720 23.6667 1.0000
2.7780 24.6667 1.0000
2.7840 23.8333 1.0000
2.7900 24.5000 1.0000
2.7960 19.5000 1.0000
2.8020 19.3333 1.0000
2.8080 28.3333 1.0000
2.8140 19.5000 1.0000
2.8200 22.0000 1.0000
2.8260 23.5000 1.0000
2.8320 32.0000 1.0000
2.8380 19.3333 1.0000
2.8440 28.1667 1.0000
2.8500 19.8333 1.0000
2.8560 32.1667 1.0000
2.8620 12.3333 1.0000
2.8680 26.1667 1.0000
2.8740 19.1667 1.0000
2.8800 20.8333 1.0000
2.8860 30.0000 1.0000
2.8920 22.3333 1.0000
2.8980 24.1667 1.0000
2.9040 24.5000 1.0000
2.9100 19.3333 1.0000
2.9160 30.0000 1.0000
2.9220 20.6667 1.0000
2.9280 21.8333 1.0000
2.9340 33.3333 1.0000
2.9400 22.3333 1.0000
2.9460 26.0000 1.0000
2.9520 17.3333 1.0000
2.9580 16.1667 1.0000
2.9640 14.8333 1.0000
2.9700 14.1667 1.0000
2.9760 18.0000 1.0000
2.9820 16.5000 1.0000
2.9880 17.1667 1.0000
2.9940 11.3333 1.0000
3.0000 27.1667 1.0000
3.0060 15.3333 1.0000
3.0120 12.0000 1.0000
3.0180 10.8333 1.0000
3.0240 13.5000 1.0000
3.0300 16.5000 1.0000
3.0360 20.3333 1.0000
3.0420 22.8333 1.0000
3.0480 19.1667 1.0000
3.0540 8.3333 1.0000
3.0600 20.3333 1.0000
3.0660 14.3333 1.0000
3.0720 19.1667 1.0000
3.0780 12.0000 1.0000
3.0840 18.6667 1.0000
3.0900 8.6667 1.0000
3.0960 12.6667 1.0000
3.1020 11.6667 1.0000
3.1080 18.3333 1.0000
3.1140 10.3333 1.0000
3.1200 10.3333 1.0000
3.1260 13.6667 1.0000
3.1320 17.1667 1.0000
3.1380 7.5000 1.0000
3.1440 13.1667 1.0000
3.1500 15.1667 1.0000
3.1560 12.5000 1.0000
3.1620 13.0000 1.0000
3.1680 13.3333 1.0000
3.1740 16.3333 1.0000
3.1800 12.0000 1.0000
3.1860 10.5000 1.0000
3.1920 12.5000 1.0000
3.1980 8.8333 1.0000
3.2040 17.8333 1.0000
3.2100 13.3333 1.0000
3.2160 11.1667 1.0000
3.2220 16.6667 1.0000
3.2280 12.3333 1.0000
3.2340 21.5000 1.0000
3.2400 20.8333 1.0000
3.2460 19.1667 1.0000
3.2520 13.6667 1.0000
3.2580 15.0000 1.0000
3.2640 17.0000 1.0000
3.2700 16.5000 1.0000
3.2760 9.3333 1.0000
3.2820 12.8333 1.0000
3.2880 10.0000 1.0000
3.2940 13.1667 1.0000
3.3000 14.0000 1.0000
3.3060 13.6667 1.0000
3.3120 9.8333 1.0000
3.3180 17.3333 1.0000
3.3240 11.3333 1.0000
3.3300 12.6667 1.0000
3.3360 10.1667 1.0000
3.3420 14.3333 1.0000
3.3480 7.5000 1.0000
3.3540 16.8333 1.0000
3.3600 9.3333 1.0000
3.3660 3.8333 1.0000
3.3720 6.0000 1.0000
3.3780 6.8333 1.0000
3.3840 10.0000 1.0000
3.3900 15.5000 1.0000
3.3960 7.1667 1.0000
3.4020 7.3333 1.0000
3.4080 12.8333 1.0000
3.4140 12.5000 1.0000
3.4200 8.6667 1.0000
3.4260 8.8333 1.0000
3.4320 11.3333 1.0000
3.4380 2.8333 1.0000
3.4440 8.3333 1.0000
3.4500 4.3333 1.0000
3.4560 7.5000 1.0000
3.4620 10.8333 1.0000
3.4680 7.3333 1.0000
3.4740 5.6667 1.0000
3.4800 11.1667 1.0000
3.4860 11.1667 1.0000
3.4920 6.5000 1.0000
3.4980 10.1667 1.0000
3.5040 7.0000 1.0000
3.5100 5.8333 1.0000
3.5160 10.0000 1.0000
3.5220 12.0000 1.0000
3.5280 10.6667 1.0000
3.5340 4.0000 1.0000
3.5400 9.5000 1.0000
3.5460 6.0000 1.0000
3.5520 6.6667 1.0000
3.5580 7.1667 1.0000
3.5640 8.5000 1.0000
3.5700 8.1667 1.0000
3.5760 7.8333 1.0000
3.5820 8.6667 1.0000
3.5880 9.8333 1.0000
3.5940 5.5000 1.0000
3.6000 2.5000 1.0000
3.6060 8.8333 1.0000
3.6120 8.6667 1.0000
3.6180 8.0000 1.0000
3.6240 6.1667 1.0000
3.6300 7.6667 1.0000
3.6360 8.5000 1.0000
3.6420 6.8333 1.0000
3.6480 4.3333 1.0000
3.6540 7.6667 1.0000
3.6600 14.8333 1.0000
3.6660 3.5000 1.0000
3.6720 2.5000 1.0000
3.6780 6.3333 1.0000
3.6840 8.0000 1.0000
3.6900 4.8333 1.0000
3.6960 5.5000 1.0000
3.7020 5.8333 1.0000
3.7080 4.5000 1.0000
3.7140 12.0000 1.0000
3.7200 6.8333 1.0000
3.7260 7.5000 1.0000
3.7320 6.8333 1.0000
3.7380 4.6667 1.0000
3.7440 5.3333 1.0000
3.7500 8.0000 1.0000
3.7560 5.1667 1.0000
3.7620 2.5000 1.0000
3.7680 4.0000 1.0000
3.7740 3.5000 1.0000
3.7800 7.0000 1.0000
3.7860 3.5000 1.0000
3.7920 5.6667 1.0000
3.7980 10.3333 1.0000
3.8040 4.5000 1.0000
3.8100 5.8333 1.0000
3.8160 1.5000 1.0000
3.8220 5.3333 1.0000
3.8280 3.3333 1.0000
3.8340 4.8333 1.0000
3.8400 2.3333 1.0000
3.8460 4.5000 1.0000
3.8520 4.3333 1.0000
3.8580 5.5000 1.0000
3.8640 7.3333 1.0000
3.8700 9.1667 1.0000
3.8760 0.5000 1.0000
3.8820 3.5000 1.0000
3.8880 5.1667 1.0000
3.8940 5.6667 1.0000
3.9000 11.3333 1.0000
3.9060 3.1667 1.0000
3.9120 3.5000 1.0000
3.9180 2.1667 1.0000
3.9240 5.3333 1.0000
3.9300 5.6667 1.0000
3.9360 0.1667 1.0000
3.9420 3.5000 1.0000
3.9480 6.3333 1.0000
3.9540 4.3333 1.0000
3.9600 4.1667 1.0000
3.9660 2.5000 1.0000
3.9720 2.3333 1.0000
3.9780 3.1667 1.0000
3.9840 1.3333 1.0000
3.9900 4.5000 1.0000
3.9960 9.3333 1.0000
4.0020 5.3333 1.0000
4.0080 6.3333 1.0000
4.0140 2.0000 1.0000
4.0200 3.5000 1.0000
4.0260 4.3333 1.0000
4.0320 4.8333 1.0000
4.0380 2.8333 1.0000
4.0440 3.5000 1.0000
4.0500 6.3333 1.0000
4.0560 3.3333 1.0000
4.0620 2.5000 1.0000
4.0680 1.3333 1.0000
4.0740 6.3333 1.0000
4.0800 4.3333 1.0000
4.0860 0.5000 1.0000
4.0920 11.3333 1.0000
4.0980 5.3333 1.0000
4.1040 2.3333 1.0000
4.1100 4.3333 1.0000
4.1160 5.0000 1.0000
4.1220 6.3333 1.0000
4.1280 0.0000 1.0000
4.1340 2.3333 1.0000
4.1400 0.1667 1.0000
4.1460 1.1667 1.0000
4.1520 0.1667 1.0000
4.1580 1.3333 1.0000
4.1640 4.1667 1.0000
4.1700 6.5000 1.0000
4.1760 5.6667 1.0000
4.1820 7.3333 1.0000
4.1880 2.3333 1.0000
4.1940 3.6667 1.0000
4.2000 0.1667 1.0000
4.2060 1.1667 1.0000
4.2120 3.5000 1.0000
4.2180 1.3333 1.0000
4.2240 0.1667 1.0000
4.2300 2.1667 1.0000
4.2360 0.1667 1.0000
4.2420 1.3333 1.0000
4.2480 8.0000 1.0000
4.2540 3.0000 1.0000
4.2600 2.1667 1.0000
4.2660 3.0000 1.0000
4.2720 2.1667 1.0000
4.2780 0.0000 1.0000
4.2840 1.1667 1.0000
4.2900 0.0000 1.0000
4.2960 4.1667 1.0000
4.3020 2.5000 1.0000
4.3080 7.5000 1.0000
4.3140 5.5000 1.0000
4.3200 2.1667 1.0000
4.3260 1.5000 1.0000
4.3320 3.0000 1.0000
4.3380 0.1667 1.0000
4.3440 2.1667 1.0000
4.3500 3.5000 1.0000
4.3560 7.1667 1.0000
4.3620 5.1667 1.0000
4.3680 1.3333 1.0000
4.3740 3.5000 1.0000
4.3800 0.1667 1.0000
4.3860 1.3333 1.0000
4.3920 5.3333 1.0000
4.3980 1.1667 1.0000
4.4040 1.1667 1.0000
4.4100 1.5000 1.0000
4.4160 2.3333 1.0000
4.4220 0.0000 1.0000
4.4280 2.0000 1.0000
4.4340 0.1667 1.0000
4.4400 6.0000 1.0000
4.4460 4.3333 1.0000
4.4520 4.1667 1.0000
4.4580 4.3333 1.0000
4.4640 3.5000 1.0000
4.4700 0.3333 1.0000
4.4760 0.3333 1.0000
4.4820 2.5000 1.0000
4.4880 2.1667 1.0000
4.4940 4.0000 1.0000
4.5000 1.5000 1.0000
4.5060 0.0000 1.0000
4.5120 5.0000 1.0000
4.5180 0.0000 1.0000
4.5240 4.0000 1.0000
4.5300 3.3333 1.0000
4.5360 3.6667 1.0000
4.5420 0.0000 1.0000
4.5480 2.5000 1.0000
4.5540 0.0000 1.0000
4.5600 5.1667 1.0000
4.5660 2.0000 1.0000
4.5720 3.1667 1.0000
4.5780 2.3333 1.0000
4.5840 2.1667 1.0000
4.5900 2.1667 1.0000
4.5960 3.3333 1.0000
4.6020 3.3333 1.0000
4.6080 2.1667 1.0000
4.6140 0.0000 1.0000
4.6200 0.0000 1.0000
4.6260 5.1667 1.0000
4.6320 0.0000 1.0000
4.6380 0.0000 1.0000
4.6440 5.5000 1.0000
4.6500 2.0000 1.0000
4.6560 1.1667 1.0000
4.6620 3.5000 1.0000
4.6680 0.1667 1.0000
4.6740 0.0000 1.0000
4.6800 0.0000 1.0000
4.6860 1.3333 1.0000
4.6920 2.3333 1.0000
4.6980 4.1667 1.0000
4.7040 0.0000 1.0000
4.7100 1.1667 1.0000
4.7160 0.0000 1.0000
4.7220 1.3333 1.0000
4.7280 3.0000 1.0000
4.7340 2.3333 1.0000
4.7400 0.0000 1.0000
4.7460 0.1667 1.0000
4.7520 0.0000 1.0000
4.7580 2.3333 1.0000
4.7640 0.0000 1.0000
4.7700 0.0000 1.0000
4.7760 0.0000 1.0000
4.7820 0.0000 1.0000
4.7880 0.0000 1.0000
4.7940 0.0000 1.0000
4.8000 2.3333 1.0000
4.8060 0.0000 1.0000
4.8120 0.0000 1.0000
4.8180 1.1667 1.0000
4.8240 0.1667 1.0000
4.8300 0.0000 1.0000
4.8360 1.1667 1.0000
4.8420 0.0000 1.0000
4.8480 0.0000 1.0000
4.8540 0.0000 1.0000
4.8600 0.0000 1.0000
4.8660 4.1667 1.0000
4.8720 3.1667 1.0000
4.8780 0.0000 1.0000
4.8840 3.1667 1.0000
4.8900 0.1667 1.0000
4.8960 0.0000 1.0000
4.9020 0.0000 1.0000
4.9080 0.1667 1.0000
4.9140 2.0000 1.0000
4.9200 0.0000 1.0000
4.9260 2.1667 1.0000
4.9320 1.1667 1.0000
4.9380 0.0000 1.0000
4.9440 0.0000 1.0000
4.9500 0.0000 1.0000
4.9560 0.0000 1.0000
4.9620 3.0000 1.0000
4.9680 2.0000 1.0000
4.9740 1.1667 1.0000
4.9800 0.0000 1.0000
4.9860 2.3333 1.0000
4.9920 0.0000 1.0000
4.9980 0.0000 1.0000
5.0040 4.0000 1.0000
5.0100 0.0000 1.0000
5.0160 0.0000 1.0000
5.0220 2.0000 1.0000
5.0280 1.3333 1.0000
5.0340 0.0000 1.0000
5.0400 0.1667 1.0000
5.0460 0.1667 1.0000
5.0520 0.0000 1.0000
5.0580 0.0000 1.0000
5.0640 0.0000 1.0000
5.0700 3.3333 1.0000
5.0760 2.0000 1.0000
5.0820 0.0000 1.0000
5.0880 4.0000 1.0000
5.0940 0.0000 1.0000
5.1000 0.0000 1.0000
5.1060 1.5000 1.0000
5.1120 0.0000 1.0000
5.1180 0.0000 1.0000
5.1240 0.1667 1.0000
5.1300 1.1667 1.0000
5.1360 3.3333 1.0000
5.1420 0.0000 1.0000
5.1480 1.3333 1.0000
5.1540 2.1667 1.0000
5.1600 4.1667 1.0000
5.1660 0.0000 1.0000
5.1720 1.1667 1.0000
5.1780 4.3333 1.0000
5.1840 0.0000 1.0000
5.1900 2.0000 1.0000
5.1960 0.0000 1.0000
5.2020 3.0000 1.0000
5.2080 0.1667 1.0000
5.2140 0.0000 1.0000
5.2200 0.0000 1.0000
5.2260 3.0000 1.0000
5.2320 1.1667 1.0000
5.2380 0.0000 1.0000
5.2440 0.1667 1.0000
5.2500 0.0000 1.0000
5.2560 0.0000 1.0000
5.2620 0.0000 1.0000
5.2680 0.0000 1.0000
5.2740 0.0000 1.0000
5.2800 0.0000 1.0000
5.2860 0.3333 1.0000
5.2920 0.0000 1.0000
5.2980 0.0000 1.0000
5.3040 0.0000 1.0000
5.3100 0.0000 1.0000
5.3160 0.0000 1.0000
5.3220 0.0000 1.0000
5.3280 0.0000 1.0000
5.3340 0.0000 1.0000
5.3400 2.1667 1.0000
5.3460 0.0000 1.0000
5.3520 2.1667 1.0000
5.3580 0.0000 1.0000
5.3640 0.0000 1.0000
5.3700 0.0000 1.0000
5.3760 0.0000 1.0000
5.3820 0.0000 1.0000
5.3880 0.0000 1.0000
5.3940 0.0000 1.0000
5.4000 2.1667 1.0000
5.4060 0.0000 1.0000
5.4120 0.0000 1.0000
5.4180 0.0000 1.0000
5.4240 0.0000 1.0000
5.4300 3.1667 1.0000
5.4360 0.0000 1.0000
5.4420 0.0000 1.0000
5.4480 0.0000 1.0000
5.4540 1.1667 1.0000
5.4600 0.0000 1.0000
5.4660 0.0000 1.0000
5.4720 0.0000 1.0000
5.4780 0.0000 1.0000
5.4840 0.0000 1.0000
5.4900 3.0000 1.0000
5.4960 0.0000 1.0000
5.5020 2.3333 1.0000
5.5080 0.1667 1.0000
5.5140 0.0000 1.0000
5.5200 0.0000 1.0000
5.5260 1.1667 1.0000
5.5320 0.0000 1.0000
5.5380 0.0000 1.0000
5.5440 0.0000 1.0000
5.5500 0.0000 1.0000
5.5560 0.0000 1.0000
5.5620 0.0000 1.0000
5.5680 0.0000 1.0000
5.5740 0.0000 1.0000
5.5800 0.0000 1.0000
5.5860 0.0000 1.0000
5.5920 0.0000 1.0000
5.5980 1.1667 1.0000
5.6040 0.0000 1.0000
5.6100 0.0000 1.0000
5.6160 0.0000 1.0000
5.6220 0.0000 1.0000
5.6280 0.1667 1.0000
5.6340 0.0000 1.0000
5.6400 0.0000 1.0000
5.6460 0.0000 1.0000
5.6520 0.0000 1.0000
5.6580 0.0000 1.0000
5.6640 0.0000 1.0000
5.6700 3.0000 1.0000
5.6760 0.0000 1.0000
5.6820 0.0000 1.0000
5.6880 0.1667 1.0000
5.6940 0.0000 1.0000
5.7000 0.0000 1.0000
5.7060 0.0000 1.0000
5.7120 0.0000 1.0000
5.7180 1.1667 1.0000
5.7240 0.0000 1.0000
5.7300 0.0000 1.0000
5.7360 0.0000 1.0000
5.7420 1.1667 1.0000
5.7480 0.0000 1.0000
5.7540 0.0000 1.0000
5.7600 0.0000 1.0000
5.7660 0.0000 1.0000
5.7720 0.0000 1.0000
5.7780 1.1667 1.0000
5.7840 0.0000 1.0000
5.7900 0.0000 1.0000
5.7960 0.1667 1.0000
5.8020 0.0000 1.0000
5.8080 1.3333 1.0000
5.8140 3.0000 1.0000
5.8200 1.1667 1.0000
5.8260 2.0000 1.0000
5.8320 0.0000 1.0000
5.8380 0.0000 1.0000
5.8440 0.0000 1.0000
5.8500 0.0000 1.0000
5.8560 0.0000 1.0000
5.8620 0.0000 1.0000
5.8680 0.0000 1.0000
5.8740 0.0000 1.0000
5.8800 0.0000 1.0000
5.8860 2.1667 1.0000
5.8920 0.0000 1.0000
5.8980 0.0000 1.0000
5.9040 0.0000 1.0000
5.9100 0.0000 1.0000
5.9160 0.0000 1.0000
5.9220 0.0000 1.0000
5.9280 0.0000 1.0000
5.9340 0.0000 1.0000
5.9400 0.0000 1.0000
5.9460 0.0000 1.0000
5.9520 0.0000 1.0000
5.9580 0.0000 1.0000
5.9640 0.0000 1.0000
5.9700 0.0000 1.0000
5.9760 0.0000 1.0000
5.9820 0.0000 1.0000
5.9880 0.0000 1.0000
5.9940 1.1667 1.0000
6.0000 0.0000 1.0000
*RAS_INT_END
*RAS_DATA_END