File: xrr_temp/CWOI4_reflectivity.ras
*RAS_DATA_START
*RAS_HEADER_START
*DISP_FMT_X "%.4f"
*DISP_FMT_Y "%.0f"
*DISP_FULLSCALE "2048866.8550000002"
*DISP_LINE_COLOR "255.0000000000"
*DISP_LINE_STYLE "0.0000000000"
*DISP_LINE_WIDTH "0.2500000000"
*DISP_NOTE "Collected Data-29"
*DISP_OFFSET_Y "0.0000000000"
*DISP_PEAKSEARCH_UNIT_Y "cps"
*DISP_RANGE_BOTTOM "0.0100000000"
*DISP_RANGE_LEFT "-0.0006000000"
*DISP_RANGE_LOGCUTOFF "0.0100000000"
*DISP_RANGE_RIGHT "10.0008000000"
*DISP_RANGE_TOP "2048866.8550000002"
*DISP_SCALE_MODE_Y "2.0000000000"
*DISP_TAB_NAME "2-Theta/Omega"
*DISP_TITLE_Y "Intensity"
*DISP_UNIT_Y "cps"
*DISP_WINDOW_NAME "MSG_MACROENGINE"
*FILE_COMMENT " "
*FILE_MD5 ""
*FILE_MEMO " "
*FILE_OPERATOR "Administrator"
*FILE_PART_ID "MEAS_KHP2_00055"
*FILE_SAMPLE "cwoI4"
*FILE_TYPE "RAS_RAW"
*FILE_USERGROUP "System Manager"
*FILE_VERSION "1.0000000000"
*HW_ATTACHMENT_ID "ATT0025"
*HW_ATTACHMENT_NAME "標準|Standard"
*HW_COUNTER_ID-0 "CUT0025"
*HW_COUNTER_ID-1 "CUT0020"
*HW_COUNTER_ID-2 "CUT0020"
*HW_COUNTER_ID-3 "CSL0021"
*HW_COUNTER_ID-4 "CMC0021"
*HW_COUNTER_NAME-0 "D/teX Ultra|D/teX Ultra"
*HW_COUNTER_NAME-1 "None|None"
*HW_COUNTER_NAME-2 "None|None"
*HW_COUNTER_NAME-3 "BBM|BBM"
*HW_COUNTER_NAME-4 "検出器モノクロメータ|Detector monochromator"
*HW_COUNTER_SELECT_NAME "D/teX Ultra|D/teX Ultra"
*HW_GONIOMETER_ID "GON0023"
*HW_GONIOMETER_NAME "SmartLab|SmartLab"
*HW_GONIOMETER_RADIUS-0 "90.0"
*HW_GONIOMETER_RADIUS-1 "114.0"
*HW_GONIOMETER_RADIUS-2 "190.0"
*HW_GONIOMETER_RADIUS-3 "300.0"
*HW_GONIOMETER_RADIUS-4 "187.0"
*HW_GONIOMETER_RADIUS-5 "300.0"
*HW_GONIOMETER_RADIUS-6 "113.0"
*HW_GONIOMETER_RADIUS-7 "331.0"
*HW_I_OPT_ID-0 "CBO0021"
*HW_I_OPT_ID-1 "ICR0021"
*HW_I_OPT_ID-2 "ISL0021"
*HW_I_OPT_ID-3 "ISO0021"
*HW_I_OPT_ID-4 "IAD0021"
*HW_I_OPT_ID-5 "IPR0001"
*HW_I_OPT_NAME-0 "CBOユニット|CBO unit"
*HW_I_OPT_NAME-1 "標準入射光学ユニット|Standard incident optical unit"
*HW_I_OPT_NAME-2 "標準入射スリットボックス|Standard incident slit box"
*HW_I_OPT_NAME-3 "入射平行スリット|Incident parallel slit"
*HW_I_OPT_NAME-4 "長手制限スリット|Length limiting slit"
*HW_I_OPT_NAME-5 "None|None"
*HW_R_ATTENUATER_AUTOMODE "1"
*HW_R_OPT_ID-0 "RSS0021"
*HW_R_OPT_ID-1 "RCR0023"
*HW_R_OPT_ID-2 "RSO0021"
*HW_R_OPT_ID-3 "RRS0021"
*HW_R_OPT_ID-4 "ATN0021"
*HW_R_OPT_ID-5 "RFL0021"
*HW_R_OPT_ID-6 "RAD0021"
*HW_R_OPT_NAME-0 "標準受光スリットボックス1|Standard receiving slit box # 1"
*HW_R_OPT_NAME-1 "標準受光光学ユニット1|Standard receiving unit # 1"
*HW_R_OPT_NAME-2 "標準受光光学ユニット2|Standard receiving optical unit # 2"
*HW_R_OPT_NAME-3 "標準受光スリットボックス2|Standard receiving slit box # 2"
*HW_R_OPT_NAME-4 "標準アッテネータ|Standard Attenuator"
*HW_R_OPT_NAME-5 "Cu Kβ|Cu K-beta"
*HW_R_OPT_NAME-6 "調整用受光スリット|Alignment receiving slit"
*HW_SAMPLE_HOLDER_ID "SMP0021"
*HW_SAMPLE_HOLDER_NAME "χφZクレードル|Chi phi Z cradle"
*HW_XG_CURRENT_MAX "200"
*HW_XG_CURRENT_MIN "10"
*HW_XG_CURRENT_RESOLUTION "1"
*HW_XG_CURRENT_UNIT "mA"
*HW_XG_FOCUS "0.4mm x 8mm"
*HW_XG_FOCUS_TYPE "Normal"
*HW_XG_ID "1700"
*HW_XG_NAME "9kW 開放管(45kV 200mA ID:1700)|9kW Rotating anode(45kV 200mA ID:1700)"
*HW_XG_TARGET_ATOMIC_NUMBER "29.0000000000"
*HW_XG_TARGET_NAME "Cu"
*HW_XG_TYPE "Rota"
*HW_XG_VOLTAGE_MAX "45"
*HW_XG_VOLTAGE_MIN "20"
*HW_XG_VOLTAGE_RESOLUTION "1"
*HW_XG_VOLTAGE_UNIT "kV"
*HW_XG_WATT_MAX "9.00"
*HW_XG_WATT_UNIT "kW"
*HW_XG_WAVE_LENGTH_ALPHA1 "1.540593"
*HW_XG_WAVE_LENGTH_ALPHA2 "1.544414"
*HW_XG_WAVE_LENGTH_BETA "1.392250"
*MEAS_COND_AXIS_NAME-0 "Theta/2-Theta"
*MEAS_COND_AXIS_NAME-1 "2-Theta"
*MEAS_COND_AXIS_NAME-2 "Omega"
*MEAS_COND_AXIS_NAME-3 "Chi"
*MEAS_COND_AXIS_NAME-4 "Phi"
*MEAS_COND_AXIS_NAME-5 "Z"
*MEAS_COND_AXIS_NAME-6 "2-Theta/Omega"
*MEAS_COND_AXIS_NAME-7 "Theta_s"
*MEAS_COND_AXIS_NAME-8 "Theta_d"
*MEAS_COND_AXIS_NAME-9 "Ts"
*MEAS_COND_AXIS_NAME-10 "CBO selection slit"
*MEAS_COND_AXIS_NAME-11 "M"
*MEAS_COND_AXIS_NAME-12 "Incident parallel slit"
*MEAS_COND_AXIS_NAME-13 "Incident slit"
*MEAS_COND_AXIS_NAME-14 ""
*MEAS_COND_AXIS_NAME-15 "Zs"
*MEAS_COND_AXIS_NAME-16 "Incident optical device"
*MEAS_COND_AXIS_NAME-17 "Omega_m"
*MEAS_COND_AXIS_NAME-18 "Length limiting slit"
*MEAS_COND_AXIS_NAME-19 "Center slit"
*MEAS_COND_AXIS_NAME-20 "Filter"
*MEAS_COND_AXIS_NAME-21 "Receiving slit # 1"
*MEAS_COND_AXIS_NAME-22 "Receiving slit # 2"
*MEAS_COND_AXIS_NAME-23 "Receiving optical device"
*MEAS_COND_AXIS_NAME-24 "Receiving parallel slit"
*MEAS_COND_AXIS_NAME-25 "Alignment receiving slit"
*MEAS_COND_AXIS_NAME-26 ""
*MEAS_COND_AXIS_NAME-27 ""
*MEAS_COND_AXIS_NAME-28 "Zd"
*MEAS_COND_AXIS_NAME-29 "Attenuator"
*MEAS_COND_AXIS_NAME-30 "Diffracted beam monochromator"
*MEAS_COND_AXIS_NAME-31 "Monochromator slit"
*MEAS_COND_AXIS_NAME-32 ""
*MEAS_COND_AXIS_NAME-33 ""
*MEAS_COND_AXIS_NAME-34 "Primary beam"
*MEAS_COND_AXIS_NAME-35 "PHA"
*MEAS_COND_AXIS_NAME_INTERNAL-0 "TwoThetaTheta"
*MEAS_COND_AXIS_NAME_INTERNAL-1 "TwoTheta"
*MEAS_COND_AXIS_NAME_INTERNAL-2 "Omega"
*MEAS_COND_AXIS_NAME_INTERNAL-3 "Chi"
*MEAS_COND_AXIS_NAME_INTERNAL-4 "Phi"
*MEAS_COND_AXIS_NAME_INTERNAL-5 "Z"
*MEAS_COND_AXIS_NAME_INTERNAL-6 "TwoThetaOmega"
*MEAS_COND_AXIS_NAME_INTERNAL-7 "ThetaS"
*MEAS_COND_AXIS_NAME_INTERNAL-8 "ThetaD"
*MEAS_COND_AXIS_NAME_INTERNAL-9 "Ts"
*MEAS_COND_AXIS_NAME_INTERNAL-10 "CBO"
*MEAS_COND_AXIS_NAME_INTERNAL-11 "CBO-M"
*MEAS_COND_AXIS_NAME_INTERNAL-12 "IncidentSollerSlit"
*MEAS_COND_AXIS_NAME_INTERNAL-13 "IncidentSlitBox"
*MEAS_COND_AXIS_NAME_INTERNAL-14 "IncidentSlitBox-_Axis"
*MEAS_COND_AXIS_NAME_INTERNAL-15 "Zs"
*MEAS_COND_AXIS_NAME_INTERNAL-16 "IncidentMonochromator"
*MEAS_COND_AXIS_NAME_INTERNAL-17 "IncidentMonochromator-OmegaM"
*MEAS_COND_AXIS_NAME_INTERNAL-18 "IncidentAxdSlit"
*MEAS_COND_AXIS_NAME_INTERNAL-19 "CenterSlit"
*MEAS_COND_AXIS_NAME_INTERNAL-20 "Filter"
*MEAS_COND_AXIS_NAME_INTERNAL-21 "ReceivingSlitBox1"
*MEAS_COND_AXIS_NAME_INTERNAL-22 "ReceivingSlitBox2"
*MEAS_COND_AXIS_NAME_INTERNAL-23 "ReceivingOptics"
*MEAS_COND_AXIS_NAME_INTERNAL-24 "ReceivingSollerSlit"
*MEAS_COND_AXIS_NAME_INTERNAL-25 "ReceivingAxdSlit"
*MEAS_COND_AXIS_NAME_INTERNAL-26 "ReceivingSlitBox1-_Axis"
*MEAS_COND_AXIS_NAME_INTERNAL-27 "ReceivingSlitBox2-_Axis"
*MEAS_COND_AXIS_NAME_INTERNAL-28 "ReceivingSlitBox2-Zd"
*MEAS_COND_AXIS_NAME_INTERNAL-29 "Attenuator"
*MEAS_COND_AXIS_NAME_INTERNAL-30 "CounterMonochromator"
*MEAS_COND_AXIS_NAME_INTERNAL-31 "CounterSlit"
*MEAS_COND_AXIS_NAME_INTERNAL-32 "AlphaR"
*MEAS_COND_AXIS_NAME_INTERNAL-33 "BetaR"
*MEAS_COND_AXIS_NAME_INTERNAL-34 "IncidentPrimary"
*MEAS_COND_AXIS_NAME_INTERNAL-35 "PHA"
*MEAS_COND_AXIS_NAME_MAGICNO-0 "83951616.0000000000"
*MEAS_COND_AXIS_NAME_MAGICNO-1 "268632064.0000000000"
*MEAS_COND_AXIS_NAME_MAGICNO-2 "268500992.0000000000"
*MEAS_COND_AXIS_NAME_MAGICNO-3 "268500992.0000000000"
*MEAS_COND_AXIS_NAME_MAGICNO-4 "268500992.0000000000"
*MEAS_COND_AXIS_NAME_MAGICNO-5 "285278208.0000000000"
*MEAS_COND_AXIS_NAME_MAGICNO-6 "83951616.0000000000"
*MEAS_COND_AXIS_NAME_MAGICNO-7 "131072.0000000000"
*MEAS_COND_AXIS_NAME_MAGICNO-8 "131072.0000000000"
*MEAS_COND_AXIS_NAME_MAGICNO-9 "318898176.0000000000"
*MEAS_COND_AXIS_NAME_MAGICNO-10 "20971521.0000000000"
*MEAS_COND_AXIS_NAME_MAGICNO-11 "285343744.0000000000"
*MEAS_COND_AXIS_NAME_MAGICNO-12 "20971521.0000000000"
*MEAS_COND_AXIS_NAME_MAGICNO-13 "22020097.0000000000"
*MEAS_COND_AXIS_NAME_MAGICNO-14 "25165824.0000000000"
*MEAS_COND_AXIS_NAME_MAGICNO-15 "318898176.0000000000"
*MEAS_COND_AXIS_NAME_MAGICNO-16 "20971521.0000000000"
*MEAS_COND_AXIS_NAME_MAGICNO-17 "285343744.0000000000"
*MEAS_COND_AXIS_NAME_MAGICNO-18 "20971521.0000000000"
*MEAS_COND_AXIS_NAME_MAGICNO-19 "20971521.0000000000"
*MEAS_COND_AXIS_NAME_MAGICNO-20 "20971521.0000000000"
*MEAS_COND_AXIS_NAME_MAGICNO-21 "23068673.0000000000"
*MEAS_COND_AXIS_NAME_MAGICNO-22 "23068673.0000000000"
*MEAS_COND_AXIS_NAME_MAGICNO-23 "20971521.0000000000"
*MEAS_COND_AXIS_NAME_MAGICNO-24 "20971521.0000000000"
*MEAS_COND_AXIS_NAME_MAGICNO-25 "20971521.0000000000"
*MEAS_COND_AXIS_NAME_MAGICNO-26 "25165824.0000000000"
*MEAS_COND_AXIS_NAME_MAGICNO-27 "25165824.0000000000"
*MEAS_COND_AXIS_NAME_MAGICNO-28 "285343744.0000000000"
*MEAS_COND_AXIS_NAME_MAGICNO-29 "17301505.0000000000"
*MEAS_COND_AXIS_NAME_MAGICNO-30 "20971521.0000000000"
*MEAS_COND_AXIS_NAME_MAGICNO-31 "20971521.0000000000"
*MEAS_COND_AXIS_NAME_MAGICNO-32 "8388608.0000000000"
*MEAS_COND_AXIS_NAME_MAGICNO-33 "8388608.0000000000"
*MEAS_COND_AXIS_NAME_MAGICNO-34 "20971521.0000000000"
*MEAS_COND_AXIS_NAME_MAGICNO-35 "0.0000000000"
*MEAS_COND_AXIS_OFFSET-0 "-"
*MEAS_COND_AXIS_OFFSET-1 "0.7797000000"
*MEAS_COND_AXIS_OFFSET-2 "0.6370000000"
*MEAS_COND_AXIS_OFFSET-3 "0.0000000000"
*MEAS_COND_AXIS_OFFSET-4 "0.0000000000"
*MEAS_COND_AXIS_OFFSET-5 "-"
*MEAS_COND_AXIS_OFFSET-6 "-"
*MEAS_COND_AXIS_OFFSET-7 "0.6370000000"
*MEAS_COND_AXIS_OFFSET-8 "0.1427000000"
*MEAS_COND_AXIS_OFFSET-9 "-"
*MEAS_COND_AXIS_OFFSET-10 "-"
*MEAS_COND_AXIS_OFFSET-11 "-"
*MEAS_COND_AXIS_OFFSET-12 "-"
*MEAS_COND_AXIS_OFFSET-13 "-"
*MEAS_COND_AXIS_OFFSET-14 "-"
*MEAS_COND_AXIS_OFFSET-15 "-"
*MEAS_COND_AXIS_OFFSET-16 "-"
*MEAS_COND_AXIS_OFFSET-17 "-"
*MEAS_COND_AXIS_OFFSET-18 "-"
*MEAS_COND_AXIS_OFFSET-19 "-"
*MEAS_COND_AXIS_OFFSET-20 "-"
*MEAS_COND_AXIS_OFFSET-21 "-"
*MEAS_COND_AXIS_OFFSET-22 "-"
*MEAS_COND_AXIS_OFFSET-23 "-"
*MEAS_COND_AXIS_OFFSET-24 "-"
*MEAS_COND_AXIS_OFFSET-25 "-"
*MEAS_COND_AXIS_OFFSET-26 "-"
*MEAS_COND_AXIS_OFFSET-27 "-"
*MEAS_COND_AXIS_OFFSET-28 "-"
*MEAS_COND_AXIS_OFFSET-29 "-"
*MEAS_COND_AXIS_OFFSET-30 "-"
*MEAS_COND_AXIS_OFFSET-31 "-"
*MEAS_COND_AXIS_OFFSET-32 "0.0000000000"
*MEAS_COND_AXIS_OFFSET-33 "0.0000000000"
*MEAS_COND_AXIS_OFFSET-34 "-"
*MEAS_COND_AXIS_OFFSET-35 "-"
*MEAS_COND_AXIS_POSITION-0 "-0.0008000000"
*MEAS_COND_AXIS_POSITION-1 "-0.0009000000"
*MEAS_COND_AXIS_POSITION-2 "-0.0004000000"
*MEAS_COND_AXIS_POSITION-3 "0.0000000000"
*MEAS_COND_AXIS_POSITION-4 "4.2440000000"
*MEAS_COND_AXIS_POSITION-5 "-1.4277000000"
*MEAS_COND_AXIS_POSITION-6 "-0.0008000000"
*MEAS_COND_AXIS_POSITION-7 "-0.0004000000"
*MEAS_COND_AXIS_POSITION-8 "-0.0005000000"
*MEAS_COND_AXIS_POSITION-9 "-4.3477500000"
*MEAS_COND_AXIS_POSITION-10 "PB"
*MEAS_COND_AXIS_POSITION-11 "0.0000000000"
*MEAS_COND_AXIS_POSITION-12 "Soller_slit_open_s"
*MEAS_COND_AXIS_POSITION-13 "0.250mm"
*MEAS_COND_AXIS_POSITION-14 "0.2500000000"
*MEAS_COND_AXIS_POSITION-15 "-0.6878100000"
*MEAS_COND_AXIS_POSITION-16 "Ge(220)x2"
*MEAS_COND_AXIS_POSITION-17 "0.0000000000"
*MEAS_COND_AXIS_POSITION-18 "2.0mm"
*MEAS_COND_AXIS_POSITION-19 "None"
*MEAS_COND_AXIS_POSITION-20 "None"
*MEAS_COND_AXIS_POSITION-21 "0.250mm"
*MEAS_COND_AXIS_POSITION-22 "0.250mm"
*MEAS_COND_AXIS_POSITION-23 "No_unit"
*MEAS_COND_AXIS_POSITION-24 "Soller_slit_5.0deg"
*MEAS_COND_AXIS_POSITION-25 "None"
*MEAS_COND_AXIS_POSITION-26 "0.2500000000"
*MEAS_COND_AXIS_POSITION-27 "0.2500000000"
*MEAS_COND_AXIS_POSITION-28 "0.0809400000"
*MEAS_COND_AXIS_POSITION-29 "1/10000"
*MEAS_COND_AXIS_POSITION-30 "None"
*MEAS_COND_AXIS_POSITION-31 "None"
*MEAS_COND_AXIS_POSITION-32 "0.0000000000"
*MEAS_COND_AXIS_POSITION-33 "0.0000000000"
*MEAS_COND_AXIS_POSITION-34 "None"
*MEAS_COND_AXIS_POSITION-35 "34.0000000000"
*MEAS_COND_AXIS_UNIT-0 "deg"
*MEAS_COND_AXIS_UNIT-1 "deg"
*MEAS_COND_AXIS_UNIT-2 "deg"
*MEAS_COND_AXIS_UNIT-3 "deg"
*MEAS_COND_AXIS_UNIT-4 "deg"
*MEAS_COND_AXIS_UNIT-5 "mm"
*MEAS_COND_AXIS_UNIT-6 "deg"
*MEAS_COND_AXIS_UNIT-7 "deg"
*MEAS_COND_AXIS_UNIT-8 "deg"
*MEAS_COND_AXIS_UNIT-9 "mm"
*MEAS_COND_AXIS_UNIT-10 ""
*MEAS_COND_AXIS_UNIT-11 "pulse"
*MEAS_COND_AXIS_UNIT-12 ""
*MEAS_COND_AXIS_UNIT-13 ""
*MEAS_COND_AXIS_UNIT-14 "mm"
*MEAS_COND_AXIS_UNIT-15 "mm"
*MEAS_COND_AXIS_UNIT-16 ""
*MEAS_COND_AXIS_UNIT-17 "pulse"
*MEAS_COND_AXIS_UNIT-18 ""
*MEAS_COND_AXIS_UNIT-19 ""
*MEAS_COND_AXIS_UNIT-20 ""
*MEAS_COND_AXIS_UNIT-21 ""
*MEAS_COND_AXIS_UNIT-22 ""
*MEAS_COND_AXIS_UNIT-23 ""
*MEAS_COND_AXIS_UNIT-24 ""
*MEAS_COND_AXIS_UNIT-25 ""
*MEAS_COND_AXIS_UNIT-26 "mm"
*MEAS_COND_AXIS_UNIT-27 "mm"
*MEAS_COND_AXIS_UNIT-28 "mm"
*MEAS_COND_AXIS_UNIT-29 ""
*MEAS_COND_AXIS_UNIT-30 ""
*MEAS_COND_AXIS_UNIT-31 ""
*MEAS_COND_AXIS_UNIT-32 "deg"
*MEAS_COND_AXIS_UNIT-33 "deg"
*MEAS_COND_AXIS_UNIT-34 ""
*MEAS_COND_AXIS_UNIT-35 "div"
*MEAS_COND_COUNTER_CNTLOSS_CORR "0.0000000000"
*MEAS_COND_COUNTER_PHABASE "34.0000000000"
*MEAS_COND_COUNTER_PHAWINDOW "19.0000000000"
*MEAS_COND_COUNTER_PHA_UNIT "div"
*MEAS_COND_COUNTER_TAUDIFF "2.0000000000"
*MEAS_COND_COUNTER_TAUINT "0.1000000000"
*MEAS_COND_IRRADIATION_MODE "OFF"
*MEAS_COND_IRRADIATION_WIDTH ""
*MEAS_COND_OPT_ATTR "High resolution parallel beam Ge(220)x2/RS"
*MEAS_COND_OPT_NAME "@High resolution PB-Ge(220)x2"
*MEAS_COND_UNSYMMETRIC_MODE "OFF"
*MEAS_COND_XG_CURRENT "200.0000000000"
*MEAS_COND_XG_VOLTAGE "45.0000000000"
*MEAS_COND_XG_WAVE_TYPE "Ka1"
*MEAS_DATA_COUNT "5001.0000000000"
*MEAS_SCAN_AXIS_X "2-Theta/Omega"
*MEAS_SCAN_AXIS_X_INTERNAL "TwoThetaOmega"
*MEAS_SCAN_END_TIME "10/23/23 10:31:58"
*MEAS_SCAN_MODE "CONTINUOUS"
*MEAS_SCAN_MONITOR "0"
*MEAS_SCAN_RESOLUTION_X "0.0002"
*MEAS_SCAN_SPEED "0.500000"
*MEAS_SCAN_SPEED_UNIT "deg/min"
*MEAS_SCAN_SPEED_USER "0.500000"
*MEAS_SCAN_START "0.0000000000"
*MEAS_SCAN_START_TIME "10/23/23 10:11:40"
*MEAS_SCAN_STEP "0.0020000000"
*MEAS_SCAN_STOP "10.0000000000"
*MEAS_SCAN_UNIT_X "deg"
*MEAS_SCAN_UNIT_Y "counts"
*RAS_HEADER_END
*RAS_INT_START
0.0000 377197.0625 1.0000
0.0080 398646.4688 1.0000
0.0160 396233.4375 1.0000
0.0240 381174.1563 1.0000
0.0320 346378.4063 1.0000
0.0400 272988.5938 1.0000
0.0480 184777.8438 1.0000
0.0560 107202.4375 1.0000
0.0640 56183.3203 1.0000
0.0720 22776.1660 1.0000
0.0800 12592.3330 1.0000
0.0880 9319.5000 1.0000
0.0960 8368.5000 1.0000
0.1040 8288.0000 1.0000
0.1120 8291.6670 1.0000
0.1200 8519.1670 1.0000
0.1280 9106.3330 1.0000
0.1360 9409.3330 1.0000
0.1440 9860.6670 1.0000
0.1520 10306.0000 1.0000
0.1600 10650.0000 1.0000
0.1680 11062.1670 1.0000
0.1760 11618.8330 1.0000
0.1840 11855.8330 1.0000
0.1920 12101.3330 1.0000
0.2000 12537.0000 1.0000
0.2080 12971.8330 1.0000
0.2160 13415.3330 1.0000
0.2240 13888.1670 1.0000
0.2320 14363.5000 1.0000
0.2400 14894.6670 1.0000
0.2480 15057.3330 1.0000
0.2560 15497.0000 1.0000
0.2640 16337.0000 1.0000
0.2720 16464.0000 1.0000
0.2800 16797.1660 1.0000
0.2880 17739.6660 1.0000
0.2960 17709.1660 1.0000
0.3040 18318.5000 1.0000
0.3120 18873.8340 1.0000
0.3200 19029.8340 1.0000
0.3280 19667.6660 1.0000
0.3360 19940.3340 1.0000
0.3440 20528.1660 1.0000
0.3520 20903.0000 1.0000
0.3600 21231.6660 1.0000
0.3680 21423.1660 1.0000
0.3760 22116.6660 1.0000
0.3840 22446.8340 1.0000
0.3920 22834.0000 1.0000
0.4000 23363.8340 1.0000
0.4080 23714.8340 1.0000
0.4160 24102.0000 1.0000
0.4240 24637.1660 1.0000
0.4320 24799.5000 1.0000
0.4400 25296.3340 1.0000
0.4480 25355.5000 1.0000
0.4560 25564.0000 1.0000
0.4640 26400.5000 1.0000
0.4720 26748.3340 1.0000
0.4800 27044.1660 1.0000
0.4880 27632.3340 1.0000
0.4960 27462.8340 1.0000
0.5040 27879.1660 1.0000
0.5120 28289.1660 1.0000
0.5200 28482.6660 1.0000
0.5280 28364.0000 1.0000
0.5360 29025.6660 1.0000
0.5440 29129.6660 1.0000
0.5520 29842.1660 1.0000
0.5600 29622.1660 1.0000
0.5680 29571.6660 1.0000
0.5760 30022.0000 1.0000
0.5840 29878.8340 1.0000
0.5920 29842.3340 1.0000
0.6000 30154.1660 1.0000
0.6080 29546.8340 1.0000
0.6160 29426.0000 1.0000
0.6240 29214.8340 1.0000
0.6320 28270.1660 1.0000
0.6400 27247.0000 1.0000
0.6480 26808.3340 1.0000
0.6560 25011.3340 1.0000
0.6640 24159.6660 1.0000
0.6720 22059.0000 1.0000
0.6800 20556.0000 1.0000
0.6880 18894.8340 1.0000
0.6960 16665.5000 1.0000
0.7040 15023.0000 1.0000
0.7120 13483.5000 1.0000
0.7200 11626.5000 1.0000
0.7280 10411.1670 1.0000
0.7360 9249.0000 1.0000
0.7440 8030.3335 1.0000
0.7520 7189.1665 1.0000
0.7600 6521.0000 1.0000
0.7680 5801.6665 1.0000
0.7760 5503.0000 1.0000
0.7840 5158.0000 1.0000
0.7920 4765.0000 1.0000
0.8000 4548.0000 1.0000
0.8080 4341.5000 1.0000
0.8160 4148.5000 1.0000
0.8240 4076.1667 1.0000
0.8320 3808.5000 1.0000
0.8400 3715.8333 1.0000
0.8480 3422.6667 1.0000
0.8560 3270.6667 1.0000
0.8640 3191.1667 1.0000
0.8720 3039.3333 1.0000
0.8800 2809.0000 1.0000
0.8880 2684.0000 1.0000
0.8960 2474.0000 1.0000
0.9040 2296.6667 1.0000
0.9120 2130.1667 1.0000
0.9200 2074.1667 1.0000
0.9280 1979.0000 1.0000
0.9360 1862.5000 1.0000
0.9440 1632.5000 1.0000
0.9520 1584.8334 1.0000
0.9600 1580.0000 1.0000
0.9680 1469.3334 1.0000
0.9760 1377.5000 1.0000
0.9840 1338.0000 1.0000
0.9920 1350.8334 1.0000
1.0000 1262.3334 1.0000
1.0080 1242.3334 1.0000
1.0160 1188.5000 1.0000
1.0240 1255.5000 1.0000
1.0320 1200.0000 1.0000
1.0400 1182.6666 1.0000
1.0480 1187.8334 1.0000
1.0560 1183.0000 1.0000
1.0640 1102.3334 1.0000
1.0720 1100.8334 1.0000
1.0800 1080.6666 1.0000
1.0880 1079.0000 1.0000
1.0960 1026.1666 1.0000
1.1040 952.8333 1.0000
1.1120 1038.3334 1.0000
1.1200 989.8333 1.0000
1.1280 989.1667 1.0000
1.1360 908.0000 1.0000
1.1440 874.6667 1.0000
1.1520 808.3333 1.0000
1.1600 703.1667 1.0000
1.1680 737.3333 1.0000
1.1760 686.0000 1.0000
1.1840 629.3333 1.0000
1.1920 615.3333 1.0000
1.2000 587.6667 1.0000
1.2080 535.5000 1.0000
1.2160 489.3333 1.0000
1.2240 476.8333 1.0000
1.2320 486.3333 1.0000
1.2400 425.5000 1.0000
1.2480 494.1667 1.0000
1.2560 460.3333 1.0000
1.2640 387.0000 1.0000
1.2720 410.3333 1.0000
1.2800 408.8333 1.0000
1.2880 416.5000 1.0000
1.2960 413.0000 1.0000
1.3040 419.0000 1.0000
1.3120 402.8333 1.0000
1.3200 411.0000 1.0000
1.3280 428.8333 1.0000
1.3360 406.3333 1.0000
1.3440 411.3333 1.0000
1.3520 481.3333 1.0000
1.3600 447.5000 1.0000
1.3680 459.1667 1.0000
1.3760 412.5000 1.0000
1.3840 444.3333 1.0000
1.3920 420.8333 1.0000
1.4000 422.1667 1.0000
1.4080 451.8333 1.0000
1.4160 430.6667 1.0000
1.4240 388.0000 1.0000
1.4320 421.6667 1.0000
1.4400 375.8333 1.0000
1.4480 384.6667 1.0000
1.4560 355.1667 1.0000
1.4640 340.8333 1.0000
1.4720 324.1667 1.0000
1.4800 320.6667 1.0000
1.4880 301.1667 1.0000
1.4960 276.6667 1.0000
1.5040 249.5000 1.0000
1.5120 236.3333 1.0000
1.5200 213.5000 1.0000
1.5280 229.0000 1.0000
1.5360 204.0000 1.0000
1.5440 203.3333 1.0000
1.5520 160.8333 1.0000
1.5600 141.0000 1.0000
1.5680 149.8333 1.0000
1.5760 128.3333 1.0000
1.5840 132.6667 1.0000
1.5920 146.3333 1.0000
1.6000 122.1667 1.0000
1.6080 131.8333 1.0000
1.6160 151.1667 1.0000
1.6240 110.5000 1.0000
1.6320 140.3333 1.0000
1.6400 133.8333 1.0000
1.6480 138.0000 1.0000
1.6560 123.6667 1.0000
1.6640 151.5000 1.0000
1.6720 152.1667 1.0000
1.6800 162.5000 1.0000
1.6880 159.5000 1.0000
1.6960 162.3333 1.0000
1.7040 166.1667 1.0000
1.7120 185.6667 1.0000
1.7200 167.3333 1.0000
1.7280 157.1667 1.0000
1.7360 181.5000 1.0000
1.7440 164.5000 1.0000
1.7520 171.3333 1.0000
1.7600 151.8333 1.0000
1.7680 132.1667 1.0000
1.7760 151.0000 1.0000
1.7840 171.3333 1.0000
1.7920 144.8333 1.0000
1.8000 128.1667 1.0000
1.8080 128.8333 1.0000
1.8160 123.1667 1.0000
1.8240 112.0000 1.0000
1.8320 110.5000 1.0000
1.8400 110.8333 1.0000
1.8480 104.3333 1.0000
1.8560 111.0000 1.0000
1.8640 91.8333 1.0000
1.8720 75.6667 1.0000
1.8800 79.0000 1.0000
1.8880 78.3333 1.0000
1.8960 63.3333 1.0000
1.9040 78.3333 1.0000
1.9120 60.3333 1.0000
1.9200 64.0000 1.0000
1.9280 71.0000 1.0000
1.9360 65.8333 1.0000
1.9440 62.1667 1.0000
1.9520 58.5000 1.0000
1.9600 70.3333 1.0000
1.9680 62.0000 1.0000
1.9760 63.8333 1.0000
1.9840 65.0000 1.0000
1.9920 77.1667 1.0000
2.0000 71.0000 1.0000
2.0080 62.8333 1.0000
2.0160 69.6667 1.0000
2.0240 78.1667 1.0000
2.0320 78.8333 1.0000
2.0400 62.0000 1.0000
2.0480 81.1667 1.0000
2.0560 63.5000 1.0000
2.0640 77.1667 1.0000
2.0720 75.8333 1.0000
2.0800 63.5000 1.0000
2.0880 80.6667 1.0000
2.0960 74.3333 1.0000
2.1040 78.8333 1.0000
2.1120 64.8333 1.0000
2.1200 70.0000 1.0000
2.1280 64.6667 1.0000
2.1360 86.6667 1.0000
2.1440 58.0000 1.0000
2.1520 57.5000 1.0000
2.1600 55.8333 1.0000
2.1680 56.5000 1.0000
2.1760 60.5000 1.0000
2.1840 47.5000 1.0000
2.1920 58.0000 1.0000
2.2000 61.0000 1.0000
2.2080 60.8333 1.0000
2.2160 49.8333 1.0000
2.2240 38.8333 1.0000
2.2320 56.6667 1.0000
2.2400 43.8333 1.0000
2.2480 23.8333 1.0000
2.2560 47.5000 1.0000
2.2640 33.5000 1.0000
2.2720 29.6667 1.0000
2.2800 29.8333 1.0000
2.2880 34.6667 1.0000
2.2960 32.0000 1.0000
2.3040 33.0000 1.0000
2.3120 28.3333 1.0000
2.3200 30.0000 1.0000
2.3280 28.1667 1.0000
2.3360 31.8333 1.0000
2.3440 36.3333 1.0000
2.3520 28.0000 1.0000
2.3600 34.8333 1.0000
2.3680 25.5000 1.0000
2.3760 29.5000 1.0000
2.3840 47.0000 1.0000
2.3920 33.8333 1.0000
2.4000 35.3333 1.0000
2.4080 35.3333 1.0000
2.4160 36.5000 1.0000
2.4240 33.3333 1.0000
2.4320 35.6667 1.0000
2.4400 37.8333 1.0000
2.4480 32.5000 1.0000
2.4560 33.6667 1.0000
2.4640 33.3333 1.0000
2.4720 37.3333 1.0000
2.4800 35.6667 1.0000
2.4880 46.3333 1.0000
2.4960 27.6667 1.0000
2.5040 34.6667 1.0000
2.5120 35.3333 1.0000
2.5200 25.6667 1.0000
2.5280 29.3333 1.0000
2.5360 23.6667 1.0000
2.5440 41.8333 1.0000
2.5520 24.3333 1.0000
2.5600 29.5000 1.0000
2.5680 27.0000 1.0000
2.5760 20.0000 1.0000
2.5840 18.6667 1.0000
2.5920 16.0000 1.0000
2.6000 24.6667 1.0000
2.6080 15.5000 1.0000
2.6160 12.6667 1.0000
2.6240 16.3333 1.0000
2.6320 24.5000 1.0000
2.6400 14.0000 1.0000
2.6480 19.1667 1.0000
2.6560 17.5000 1.0000
2.6640 11.5000 1.0000
2.6720 19.3333 1.0000
2.6800 17.6667 1.0000
2.6880 15.8333 1.0000
2.6960 16.0000 1.0000
2.7040 28.6667 1.0000
2.7120 9.8333 1.0000
2.7200 19.8333 1.0000
2.7280 19.1667 1.0000
2.7360 22.3333 1.0000
2.7440 17.0000 1.0000
2.7520 26.8333 1.0000
2.7600 19.1667 1.0000
2.7680 17.5000 1.0000
2.7760 20.1667 1.0000
2.7840 22.8333 1.0000
2.7920 25.8333 1.0000
2.8000 24.3333 1.0000
2.8080 20.1667 1.0000
2.8160 24.0000 1.0000
2.8240 17.1667 1.0000
2.8320 16.0000 1.0000
2.8400 27.8333 1.0000
2.8480 22.1667 1.0000
2.8560 20.0000 1.0000
2.8640 16.1667 1.0000
2.8720 16.8333 1.0000
2.8800 15.5000 1.0000
2.8880 24.1667 1.0000
2.8960 8.0000 1.0000
2.9040 15.1667 1.0000
2.9120 16.1667 1.0000
2.9200 9.6667 1.0000
2.9280 11.5000 1.0000
2.9360 18.0000 1.0000
2.9440 8.8333 1.0000
2.9520 11.0000 1.0000
2.9600 17.0000 1.0000
2.9680 9.3333 1.0000
2.9760 8.0000 1.0000
2.9840 10.3333 1.0000
2.9920 9.3333 1.0000
3.0000 11.0000 1.0000
3.0080 6.5000 1.0000
3.0160 7.1667 1.0000
3.0240 11.1667 1.0000
3.0320 4.0000 1.0000
3.0400 9.1667 1.0000
3.0480 6.6667 1.0000
3.0560 8.8333 1.0000
3.0640 11.3333 1.0000
3.0720 10.3333 1.0000
3.0800 11.8333 1.0000
3.0880 8.1667 1.0000
3.0960 9.1667 1.0000
3.1040 11.1667 1.0000
3.1120 7.3333 1.0000
3.1200 14.1667 1.0000
3.1280 12.5000 1.0000
3.1360 16.0000 1.0000
3.1440 16.1667 1.0000
3.1520 15.3333 1.0000
3.1600 9.5000 1.0000
3.1680 11.6667 1.0000
3.1760 12.0000 1.0000
3.1840 11.1667 1.0000
3.1920 16.1667 1.0000
3.2000 7.5000 1.0000
3.2080 12.1667 1.0000
3.2160 12.6667 1.0000
3.2240 11.1667 1.0000
3.2320 4.8333 1.0000
3.2400 9.3333 1.0000
3.2480 10.0000 1.0000
3.2560 8.6667 1.0000
3.2640 8.8333 1.0000
3.2720 1.8333 1.0000
3.2800 5.5000 1.0000
3.2880 3.6667 1.0000
3.2960 7.1667 1.0000
3.3040 1.6667 1.0000
3.3120 7.6667 1.0000
3.3200 17.3333 1.0000
3.3280 11.0000 1.0000
3.3360 8.6667 1.0000
3.3440 11.6667 1.0000
3.3520 9.5000 1.0000
3.3600 9.3333 1.0000
3.3680 7.6667 1.0000
3.3760 8.3333 1.0000
3.3840 3.6667 1.0000
3.3920 8.3333 1.0000
3.4000 3.3333 1.0000
3.4080 5.5000 1.0000
3.4160 3.5000 1.0000
3.4240 3.5000 1.0000
3.4320 5.1667 1.0000
3.4400 5.1667 1.0000
3.4480 0.5000 1.0000
3.4560 10.1667 1.0000
3.4640 5.3333 1.0000
3.4720 5.0000 1.0000
3.4800 7.3333 1.0000
3.4880 6.3333 1.0000
3.4960 7.8333 1.0000
3.5040 9.8333 1.0000
3.5120 6.6667 1.0000
3.5200 5.0000 1.0000
3.5280 8.8333 1.0000
3.5360 5.0000 1.0000
3.5440 1.8333 1.0000
3.5520 7.8333 1.0000
3.5600 2.8333 1.0000
3.5680 6.3333 1.0000
3.5760 8.6667 1.0000
3.5840 0.0000 1.0000
3.5920 12.5000 1.0000
3.6000 8.0000 1.0000
3.6080 5.1667 1.0000
3.6160 7.5000 1.0000
3.6240 7.3333 1.0000
3.6320 2.3333 1.0000
3.6400 3.3333 1.0000
3.6480 1.5000 1.0000
3.6560 3.6667 1.0000
3.6640 4.1667 1.0000
3.6720 2.5000 1.0000
3.6800 6.6667 1.0000
3.6880 0.5000 1.0000
3.6960 6.5000 1.0000
3.7040 0.0000 1.0000
3.7120 0.8333 1.0000
3.7200 2.3333 1.0000
3.7280 1.8333 1.0000
3.7360 2.0000 1.0000
3.7440 4.6667 1.0000
3.7520 0.8333 1.0000
3.7600 3.5000 1.0000
3.7680 6.1667 1.0000
3.7760 6.0000 1.0000
3.7840 4.1667 1.0000
3.7920 3.5000 1.0000
3.8000 4.1667 1.0000
3.8080 2.0000 1.0000
3.8160 3.1667 1.0000
3.8240 3.0000 1.0000
3.8320 5.1667 1.0000
3.8400 0.0000 1.0000
3.8480 2.6667 1.0000
3.8560 5.6667 1.0000
3.8640 0.0000 1.0000
3.8720 3.8333 1.0000
3.8800 1.8333 1.0000
3.8880 1.1667 1.0000
3.8960 2.0000 1.0000
3.9040 8.0000 1.0000
3.9120 2.1667 1.0000
3.9200 5.5000 1.0000
3.9280 3.0000 1.0000
3.9360 5.3333 1.0000
3.9440 0.0000 1.0000
3.9520 2.5000 1.0000
3.9600 1.5000 1.0000
3.9680 4.1667 1.0000
3.9760 2.5000 1.0000
3.9840 2.3333 1.0000
3.9920 2.5000 1.0000
4.0000 3.0000 1.0000
4.0080 3.0000 1.0000
4.0160 1.8333 1.0000
4.0240 3.6667 1.0000
4.0320 1.1667 1.0000
4.0400 0.0000 1.0000
4.0480 0.8333 1.0000
4.0560 1.1667 1.0000
4.0640 0.0000 1.0000
4.0720 0.8333 1.0000
4.0800 2.1667 1.0000
4.0880 0.0000 1.0000
4.0960 3.5000 1.0000
4.1040 2.3333 1.0000
4.1120 0.0000 1.0000
4.1200 4.6667 1.0000
4.1280 6.5000 1.0000
4.1360 5.6667 1.0000
4.1440 0.0000 1.0000
4.1520 2.1667 1.0000
4.1600 2.0000 1.0000
4.1680 4.0000 1.0000
4.1760 2.1667 1.0000
4.1840 1.8333 1.0000
4.1920 3.5000 1.0000
4.2000 4.5000 1.0000
4.2080 2.8333 1.0000
4.2160 0.0000 1.0000
4.2240 0.0000 1.0000
4.2320 1.0000 1.0000
4.2400 0.5000 1.0000
4.2480 1.1667 1.0000
4.2560 0.0000 1.0000
4.2640 0.0000 1.0000
4.2720 0.5000 1.0000
4.2800 2.0000 1.0000
4.2880 0.8333 1.0000
4.2960 1.1667 1.0000
4.3040 0.0000 1.0000
4.3120 0.0000 1.0000
4.3200 0.1667 1.0000
4.3280 0.8333 1.0000
4.3360 3.6667 1.0000
4.3440 0.0000 1.0000
4.3520 0.0000 1.0000
4.3600 0.0000 1.0000
4.3680 2.1667 1.0000
4.3760 0.8333 1.0000
4.3840 0.0000 1.0000
4.3920 0.0000 1.0000
4.4000 4.8333 1.0000
4.4080 1.8333 1.0000
4.4160 0.0000 1.0000
4.4240 0.0000 1.0000
4.4320 2.3333 1.0000
4.4400 1.1667 1.0000
4.4480 0.0000 1.0000
4.4560 1.8333 1.0000
4.4640 0.0000 1.0000
4.4720 0.0000 1.0000
4.4800 1.3333 1.0000
4.4880 0.0000 1.0000
4.4960 0.8333 1.0000
4.5040 0.8333 1.0000
4.5120 1.1667 1.0000
4.5200 0.0000 1.0000
4.5280 0.0000 1.0000
4.5360 0.0000 1.0000
4.5440 2.0000 1.0000
4.5520 0.0000 1.0000
4.5600 0.0000 1.0000
4.5680 0.0000 1.0000
4.5760 1.5000 1.0000
4.5840 0.0000 1.0000
4.5920 0.0000 1.0000
4.6000 0.0000 1.0000
4.6080 0.0000 1.0000
4.6160 0.0000 1.0000
4.6240 0.0000 1.0000
4.6320 0.1667 1.0000
4.6400 1.8333 1.0000
4.6480 0.0000 1.0000
4.6560 0.0000 1.0000
4.6640 0.0000 1.0000
4.6720 0.0000 1.0000
4.6800 0.0000 1.0000
4.6880 1.5000 1.0000
4.6960 3.8333 1.0000
4.7040 0.0000 1.0000
4.7120 1.5000 1.0000
4.7200 2.3333 1.0000
4.7280 3.1667 1.0000
4.7360 0.0000 1.0000
4.7440 0.0000 1.0000
4.7520 2.0000 1.0000
4.7600 0.0000 1.0000
4.7680 0.0000 1.0000
4.7760 0.0000 1.0000
4.7840 0.0000 1.0000
4.7920 0.0000 1.0000
4.8000 1.3333 1.0000
4.8080 0.8333 1.0000
4.8160 0.0000 1.0000
4.8240 0.0000 1.0000
4.8320 0.0000 1.0000
4.8400 0.5000 1.0000
4.8480 0.0000 1.0000
4.8560 0.0000 1.0000
4.8640 0.0000 1.0000
4.8720 0.1667 1.0000
4.8800 0.0000 1.0000
4.8880 0.8333 1.0000
4.8960 0.0000 1.0000
4.9040 0.0000 1.0000
4.9120 0.0000 1.0000
4.9200 0.1667 1.0000
4.9280 0.0000 1.0000
4.9360 0.0000 1.0000
4.9440 0.0000 1.0000
4.9520 0.0000 1.0000
4.9600 2.0000 1.0000
4.9680 0.0000 1.0000
4.9760 0.0000 1.0000
4.9840 0.0000 1.0000
4.9920 0.0000 1.0000
5.0000 0.5000 1.0000
5.0080 0.0000 1.0000
5.0160 0.3333 1.0000
5.0240 0.0000 1.0000
5.0320 0.0000 1.0000
5.0400 0.0000 1.0000
5.0480 0.5000 1.0000
5.0560 0.0000 1.0000
5.0640 1.1667 1.0000
5.0720 0.0000 1.0000
5.0800 0.0000 1.0000
5.0880 0.0000 1.0000
5.0960 2.0000 1.0000
5.1040 0.0000 1.0000
5.1120 0.0000 1.0000
5.1200 0.0000 1.0000
5.1280 0.0000 1.0000
5.1360 2.0000 1.0000
5.1440 0.0000 1.0000
5.1520 0.0000 1.0000
5.1600 0.0000 1.0000
5.1680 0.0000 1.0000
5.1760 0.8333 1.0000
5.1840 0.0000 1.0000
5.1920 0.0000 1.0000
5.2000 0.0000 1.0000
5.2080 0.0000 1.0000
5.2160 0.0000 1.0000
5.2240 0.0000 1.0000
5.2320 2.0000 1.0000
5.2400 0.0000 1.0000
5.2480 0.5000 1.0000
5.2560 0.0000 1.0000
5.2640 0.0000 1.0000
5.2720 0.0000 1.0000
5.2800 1.1667 1.0000
5.2880 0.0000 1.0000
5.2960 0.0000 1.0000
5.3040 2.1667 1.0000
5.3120 0.0000 1.0000
5.3200 0.0000 1.0000
5.3280 1.1667 1.0000
5.3360 0.0000 1.0000
5.3440 1.8333 1.0000
5.3520 0.0000 1.0000
5.3600 0.0000 1.0000
5.3680 0.0000 1.0000
5.3760 0.0000 1.0000
5.3840 0.0000 1.0000
5.3920 0.0000 1.0000
5.4000 0.0000 1.0000
5.4080 0.0000 1.0000
5.4160 0.0000 1.0000
5.4240 0.0000 1.0000
5.4320 1.8333 1.0000
5.4400 0.0000 1.0000
5.4480 0.0000 1.0000
5.4560 0.8333 1.0000
5.4640 0.0000 1.0000
5.4720 1.1667 1.0000
5.4800 0.0000 1.0000
5.4880 0.0000 1.0000
5.4960 0.0000 1.0000
5.5040 0.0000 1.0000
5.5120 0.0000 1.0000
5.5200 0.0000 1.0000
5.5280 0.0000 1.0000
5.5360 0.0000 1.0000
5.5440 0.0000 1.0000
5.5520 0.0000 1.0000
5.5600 0.0000 1.0000
5.5680 0.0000 1.0000
5.5760 0.0000 1.0000
5.5840 0.0000 1.0000
5.5920 0.0000 1.0000
5.6000 0.0000 1.0000
5.6080 0.0000 1.0000
5.6160 0.0000 1.0000
5.6240 0.0000 1.0000
5.6320 0.0000 1.0000
5.6400 0.0000 1.0000
5.6480 0.0000 1.0000
5.6560 0.0000 1.0000
5.6640 0.0000 1.0000
5.6720 0.0000 1.0000
5.6800 0.0000 1.0000
5.6880 0.0000 1.0000
5.6960 0.0000 1.0000
5.7040 0.0000 1.0000
5.7120 0.0000 1.0000
5.7200 0.0000 1.0000
5.7280 0.0000 1.0000
5.7360 0.0000 1.0000
5.7440 0.0000 1.0000
5.7520 0.0000 1.0000
5.7600 0.0000 1.0000
5.7680 0.0000 1.0000
5.7760 0.0000 1.0000
5.7840 0.0000 1.0000
5.7920 0.0000 1.0000
5.8000 0.0000 1.0000
5.8080 0.0000 1.0000
5.8160 0.0000 1.0000
5.8240 0.0000 1.0000
5.8320 0.0000 1.0000
5.8400 0.0000 1.0000
5.8480 0.0000 1.0000
5.8560 2.0000 1.0000
5.8640 0.0000 1.0000
5.8720 0.0000 1.0000
5.8800 0.0000 1.0000
5.8880 0.0000 1.0000
5.8960 0.0000 1.0000
5.9040 0.0000 1.0000
5.9120 0.0000 1.0000
5.9200 0.0000 1.0000
5.9280 0.0000 1.0000
5.9360 0.0000 1.0000
5.9440 0.0000 1.0000
5.9520 0.0000 1.0000
5.9600 0.0000 1.0000
5.9680 0.0000 1.0000
5.9760 0.0000 1.0000
5.9840 0.0000 1.0000
5.9920 0.0000 1.0000
6.0000 0.0000 1.0000
6.0080 0.0000 1.0000
6.0160 0.0000 1.0000
6.0240 0.0000 1.0000
6.0320 0.0000 1.0000
6.0400 0.0000 1.0000
6.0480 0.0000 1.0000
6.0560 0.0000 1.0000
6.0640 0.0000 1.0000
6.0720 0.0000 1.0000
6.0800 0.0000 1.0000
6.0880 0.0000 1.0000
6.0960 0.0000 1.0000
6.1040 0.0000 1.0000
6.1120 0.0000 1.0000
6.1200 0.0000 1.0000
6.1280 0.0000 1.0000
6.1360 0.0000 1.0000
6.1440 0.0000 1.0000
6.1520 0.0000 1.0000
6.1600 0.0000 1.0000
6.1680 0.0000 1.0000
6.1760 0.0000 1.0000
6.1840 0.0000 1.0000
6.1920 0.0000 1.0000
6.2000 0.0000 1.0000
6.2080 0.0000 1.0000
6.2160 0.0000 1.0000
6.2240 0.0000 1.0000
6.2320 0.0000 1.0000
6.2400 0.0000 1.0000
6.2480 0.0000 1.0000
6.2560 0.0000 1.0000
6.2640 0.0000 1.0000
6.2720 0.0000 1.0000
6.2800 0.0000 1.0000
6.2880 0.0000 1.0000
6.2960 0.0000 1.0000
6.3040 0.0000 1.0000
6.3120 0.0000 1.0000
6.3200 0.0000 1.0000
6.3280 1.8333 1.0000
6.3360 0.0000 1.0000
6.3440 0.0000 1.0000
6.3520 0.0000 1.0000
6.3600 0.0000 1.0000
6.3680 0.0000 1.0000
6.3760 0.0000 1.0000
6.3840 0.0000 1.0000
6.3920 0.0000 1.0000
6.4000 0.0000 1.0000
6.4080 0.0000 1.0000
6.4160 0.0000 1.0000
6.4240 0.0000 1.0000
6.4320 0.0000 1.0000
6.4400 0.0000 1.0000
6.4480 0.0000 1.0000
6.4560 0.0000 1.0000
6.4640 0.0000 1.0000
6.4720 0.0000 1.0000
6.4800 0.0000 1.0000
6.4880 0.0000 1.0000
6.4960 0.0000 1.0000
6.5040 0.0000 1.0000
6.5120 0.0000 1.0000
6.5200 0.0000 1.0000
6.5280 0.0000 1.0000
6.5360 0.0000 1.0000
6.5440 0.0000 1.0000
6.5520 0.0000 1.0000
6.5600 0.0000 1.0000
6.5680 0.0000 1.0000
6.5760 0.0000 1.0000
6.5840 0.0000 1.0000
6.5920 0.0000 1.0000
6.6000 0.0000 1.0000
6.6080 0.0000 1.0000
6.6160 0.0000 1.0000
6.6240 0.0000 1.0000
6.6320 0.0000 1.0000
6.6400 0.0000 1.0000
6.6480 0.0000 1.0000
6.6560 0.0000 1.0000
6.6640 0.0000 1.0000
6.6720 0.0000 1.0000
6.6800 0.0000 1.0000
6.6880 0.0000 1.0000
6.6960 0.0000 1.0000
6.7040 0.0000 1.0000
6.7120 0.0000 1.0000
6.7200 0.0000 1.0000
6.7280 0.0000 1.0000
6.7360 0.0000 1.0000
6.7440 0.0000 1.0000
6.7520 0.0000 1.0000
6.7600 0.0000 1.0000
6.7680 0.0000 1.0000
6.7760 0.0000 1.0000
6.7840 0.0000 1.0000
6.7920 0.0000 1.0000
6.8000 0.0000 1.0000
6.8080 0.0000 1.0000
6.8160 0.0000 1.0000
6.8240 0.0000 1.0000
6.8320 0.0000 1.0000
6.8400 0.0000 1.0000
6.8480 0.0000 1.0000
6.8560 0.0000 1.0000
6.8640 0.0000 1.0000
6.8720 0.0000 1.0000
6.8800 0.0000 1.0000
6.8880 0.0000 1.0000
6.8960 0.0000 1.0000
6.9040 0.0000 1.0000
6.9120 0.0000 1.0000
6.9200 0.0000 1.0000
6.9280 0.0000 1.0000
6.9360 0.0000 1.0000
6.9440 0.0000 1.0000
6.9520 0.0000 1.0000
6.9600 0.0000 1.0000
6.9680 0.0000 1.0000
6.9760 0.0000 1.0000
6.9840 0.0000 1.0000
6.9920 0.0000 1.0000
7.0000 0.0000 1.0000
7.0080 0.0000 1.0000
7.0160 0.0000 1.0000
7.0240 0.0000 1.0000
7.0320 0.0000 1.0000
7.0400 0.0000 1.0000
7.0480 0.0000 1.0000
7.0560 0.0000 1.0000
7.0640 0.0000 1.0000
7.0720 0.0000 1.0000
7.0800 0.0000 1.0000
7.0880 0.0000 1.0000
7.0960 0.0000 1.0000
7.1040 0.0000 1.0000
7.1120 0.0000 1.0000
7.1200 0.0000 1.0000
7.1280 0.0000 1.0000
7.1360 0.0000 1.0000
7.1440 0.0000 1.0000
7.1520 0.0000 1.0000
7.1600 0.0000 1.0000
7.1680 0.0000 1.0000
7.1760 0.0000 1.0000
7.1840 0.0000 1.0000
7.1920 0.0000 1.0000
7.2000 0.0000 1.0000
7.2080 0.0000 1.0000
7.2160 0.0000 1.0000
7.2240 0.0000 1.0000
7.2320 0.0000 1.0000
7.2400 0.0000 1.0000
7.2480 0.0000 1.0000
7.2560 0.0000 1.0000
7.2640 0.0000 1.0000
7.2720 0.0000 1.0000
7.2800 0.0000 1.0000
7.2880 0.0000 1.0000
7.2960 0.0000 1.0000
7.3040 0.0000 1.0000
7.3120 0.0000 1.0000
7.3200 0.0000 1.0000
7.3280 0.0000 1.0000
7.3360 0.0000 1.0000
7.3440 0.0000 1.0000
7.3520 0.0000 1.0000
7.3600 0.0000 1.0000
7.3680 0.0000 1.0000
7.3760 0.0000 1.0000
7.3840 0.0000 1.0000
7.3920 0.0000 1.0000
7.4000 0.0000 1.0000
7.4080 0.0000 1.0000
7.4160 0.0000 1.0000
7.4240 0.0000 1.0000
7.4320 0.0000 1.0000
7.4400 0.0000 1.0000
7.4480 0.0000 1.0000
7.4560 0.0000 1.0000
7.4640 0.0000 1.0000
7.4720 0.0000 1.0000
7.4800 0.0000 1.0000
7.4880 0.0000 1.0000
7.4960 0.0000 1.0000
7.5040 0.0000 1.0000
7.5120 0.0000 1.0000
7.5200 0.0000 1.0000
7.5280 0.0000 1.0000
7.5360 0.0000 1.0000
7.5440 0.0000 1.0000
7.5520 0.0000 1.0000
7.5600 0.0000 1.0000
7.5680 0.0000 1.0000
7.5760 0.0000 1.0000
7.5840 0.0000 1.0000
7.5920 0.0000 1.0000
7.6000 0.0000 1.0000
7.6080 0.0000 1.0000
7.6160 0.0000 1.0000
7.6240 0.0000 1.0000
7.6320 0.0000 1.0000
7.6400 0.0000 1.0000
7.6480 0.0000 1.0000
7.6560 0.0000 1.0000
7.6640 0.0000 1.0000
7.6720 0.0000 1.0000
7.6800 0.0000 1.0000
7.6880 0.0000 1.0000
7.6960 0.0000 1.0000
7.7040 0.0000 1.0000
7.7120 0.0000 1.0000
7.7200 0.0000 1.0000
7.7280 0.0000 1.0000
7.7360 0.0000 1.0000
7.7440 0.0000 1.0000
7.7520 0.0000 1.0000
7.7600 0.0000 1.0000
7.7680 0.0000 1.0000
7.7760 0.0000 1.0000
7.7840 0.0000 1.0000
7.7920 0.0000 1.0000
7.8000 0.0000 1.0000
7.8080 0.0000 1.0000
7.8160 0.0000 1.0000
7.8240 0.0000 1.0000
7.8320 0.0000 1.0000
7.8400 0.0000 1.0000
7.8480 0.0000 1.0000
7.8560 0.0000 1.0000
7.8640 0.0000 1.0000
7.8720 0.0000 1.0000
7.8800 0.0000 1.0000
7.8880 0.0000 1.0000
7.8960 0.0000 1.0000
7.9040 0.0000 1.0000
7.9120 0.0000 1.0000
7.9200 0.0000 1.0000
7.9280 0.0000 1.0000
7.9360 0.0000 1.0000
7.9440 0.0000 1.0000
7.9520 0.0000 1.0000
7.9600 0.0000 1.0000
7.9680 0.0000 1.0000
7.9760 0.0000 1.0000
7.9840 0.0000 1.0000
7.9920 0.0000 1.0000
8.0000 0.0000 1.0000
8.0080 0.0000 1.0000
8.0160 0.0000 1.0000
8.0240 0.0000 1.0000
8.0320 0.0000 1.0000
8.0400 0.0000 1.0000
8.0480 0.0000 1.0000
8.0560 0.0000 1.0000
8.0640 0.0000 1.0000
8.0720 0.0000 1.0000
8.0800 0.0000 1.0000
8.0880 0.0000 1.0000
8.0960 0.0000 1.0000
8.1040 0.0000 1.0000
8.1120 0.0000 1.0000
8.1200 0.0000 1.0000
8.1280 0.0000 1.0000
8.1360 0.0000 1.0000
8.1440 0.0000 1.0000
8.1520 0.0000 1.0000
8.1600 0.0000 1.0000
8.1680 0.0000 1.0000
8.1760 0.0000 1.0000
8.1840 0.0000 1.0000
8.1920 0.0000 1.0000
8.2000 0.0000 1.0000
8.2080 0.0000 1.0000
8.2160 0.0000 1.0000
8.2240 0.0000 1.0000
8.2320 0.0000 1.0000
8.2400 0.0000 1.0000
8.2480 0.0000 1.0000
8.2560 0.0000 1.0000
8.2640 0.0000 1.0000
8.2720 0.0000 1.0000
8.2800 0.0000 1.0000
8.2880 0.0000 1.0000
8.2960 0.0000 1.0000
8.3040 0.0000 1.0000
8.3120 0.0000 1.0000
8.3200 0.0000 1.0000
8.3280 0.0000 1.0000
8.3360 0.0000 1.0000
8.3440 0.0000 1.0000
8.3520 0.0000 1.0000
8.3600 0.0000 1.0000
8.3680 0.0000 1.0000
8.3760 0.0000 1.0000
8.3840 0.0000 1.0000
8.3920 0.0000 1.0000
8.4000 0.0000 1.0000
8.4080 0.0000 1.0000
8.4160 0.0000 1.0000
8.4240 0.0000 1.0000
8.4320 0.0000 1.0000
8.4400 0.0000 1.0000
8.4480 0.0000 1.0000
8.4560 0.0000 1.0000
8.4640 0.0000 1.0000
8.4720 0.0000 1.0000
8.4800 0.0000 1.0000
8.4880 0.0000 1.0000
8.4960 0.0000 1.0000
8.5040 0.0000 1.0000
8.5120 0.0000 1.0000
8.5200 0.0000 1.0000
8.5280 0.0000 1.0000
8.5360 0.0000 1.0000
8.5440 0.0000 1.0000
8.5520 0.0000 1.0000
8.5600 0.0000 1.0000
8.5680 0.0000 1.0000
8.5760 0.0000 1.0000
8.5840 0.0000 1.0000
8.5920 0.0000 1.0000
8.6000 0.0000 1.0000
8.6080 0.0000 1.0000
8.6160 0.0000 1.0000
8.6240 0.0000 1.0000
8.6320 0.0000 1.0000
8.6400 0.0000 1.0000
8.6480 0.0000 1.0000
8.6560 0.0000 1.0000
8.6640 0.0000 1.0000
8.6720 0.0000 1.0000
8.6800 0.0000 1.0000
8.6880 0.0000 1.0000
8.6960 0.0000 1.0000
8.7040 0.0000 1.0000
8.7120 0.0000 1.0000
8.7200 0.0000 1.0000
8.7280 0.0000 1.0000
8.7360 0.0000 1.0000
8.7440 0.0000 1.0000
8.7520 0.0000 1.0000
8.7600 0.0000 1.0000
8.7680 0.0000 1.0000
8.7760 0.0000 1.0000
8.7840 0.0000 1.0000
8.7920 0.0000 1.0000
8.8000 0.0000 1.0000
8.8080 0.0000 1.0000
8.8160 0.0000 1.0000
8.8240 0.0000 1.0000
8.8320 0.0000 1.0000
8.8400 0.0000 1.0000
8.8480 0.0000 1.0000
8.8560 0.0000 1.0000
8.8640 0.0000 1.0000
8.8720 0.0000 1.0000
8.8800 0.0000 1.0000
8.8880 0.0000 1.0000
8.8960 0.0000 1.0000
8.9040 0.0000 1.0000
8.9120 0.0000 1.0000
8.9200 0.0000 1.0000
8.9280 0.0000 1.0000
8.9360 0.0000 1.0000
8.9440 0.0000 1.0000
8.9520 0.0000 1.0000
8.9600 0.0000 1.0000
8.9680 0.0000 1.0000
8.9760 0.0000 1.0000
8.9840 0.0000 1.0000
8.9920 0.0000 1.0000
9.0000 0.0000 1.0000
9.0080 0.0000 1.0000
9.0160 0.0000 1.0000
9.0240 0.0000 1.0000
9.0320 0.0000 1.0000
9.0400 0.0000 1.0000
9.0480 0.0000 1.0000
9.0560 0.0000 1.0000
9.0640 0.0000 1.0000
9.0720 0.0000 1.0000
9.0800 0.0000 1.0000
9.0880 0.0000 1.0000
9.0960 0.0000 1.0000
9.1040 0.0000 1.0000
9.1120 0.0000 1.0000
9.1200 0.0000 1.0000
9.1280 0.0000 1.0000
9.1360 0.0000 1.0000
9.1440 0.0000 1.0000
9.1520 0.0000 1.0000
9.1600 0.0000 1.0000
9.1680 0.0000 1.0000
9.1760 0.0000 1.0000
9.1840 0.0000 1.0000
9.1920 0.0000 1.0000
9.2000 0.0000 1.0000
9.2080 0.0000 1.0000
9.2160 0.0000 1.0000
9.2240 0.0000 1.0000
9.2320 0.0000 1.0000
9.2400 0.0000 1.0000
9.2480 0.0000 1.0000
9.2560 0.0000 1.0000
9.2640 0.0000 1.0000
9.2720 0.0000 1.0000
9.2800 0.0000 1.0000
9.2880 0.0000 1.0000
9.2960 0.0000 1.0000
9.3040 0.0000 1.0000
9.3120 0.0000 1.0000
9.3200 0.0000 1.0000
9.3280 0.0000 1.0000
9.3360 0.0000 1.0000
9.3440 0.0000 1.0000
9.3520 0.0000 1.0000
9.3600 0.0000 1.0000
9.3680 0.0000 1.0000
9.3760 0.0000 1.0000
9.3840 0.0000 1.0000
9.3920 0.0000 1.0000
9.4000 0.0000 1.0000
9.4080 0.0000 1.0000
9.4160 0.0000 1.0000
9.4240 0.0000 1.0000
9.4320 0.0000 1.0000
9.4400 0.0000 1.0000
9.4480 0.0000 1.0000
9.4560 0.0000 1.0000
9.4640 0.0000 1.0000
9.4720 0.0000 1.0000
9.4800 0.0000 1.0000
9.4880 0.0000 1.0000
9.4960 0.0000 1.0000
9.5040 0.0000 1.0000
9.5120 0.0000 1.0000
9.5200 0.0000 1.0000
9.5280 0.0000 1.0000
9.5360 0.0000 1.0000
9.5440 0.0000 1.0000
9.5520 0.0000 1.0000
9.5600 0.0000 1.0000
9.5680 0.0000 1.0000
9.5760 0.0000 1.0000
9.5840 0.0000 1.0000
9.5920 0.0000 1.0000
9.6000 0.0000 1.0000
9.6080 0.0000 1.0000
9.6160 0.0000 1.0000
9.6240 0.0000 1.0000
9.6320 0.0000 1.0000
9.6400 0.0000 1.0000
9.6480 0.0000 1.0000
9.6560 0.0000 1.0000
9.6640 0.0000 1.0000
9.6720 0.0000 1.0000
9.6800 0.0000 1.0000
9.6880 0.0000 1.0000
9.6960 0.0000 1.0000
9.7040 0.0000 1.0000
9.7120 0.0000 1.0000
9.7200 0.0000 1.0000
9.7280 0.0000 1.0000
9.7360 0.0000 1.0000
9.7440 0.0000 1.0000
9.7520 0.0000 1.0000
9.7600 0.0000 1.0000
9.7680 0.0000 1.0000
9.7760 0.0000 1.0000
9.7840 0.0000 1.0000
9.7920 0.0000 1.0000
9.8000 0.0000 1.0000
9.8080 0.0000 1.0000
9.8160 0.0000 1.0000
9.8240 0.0000 1.0000
9.8320 0.0000 1.0000
9.8400 0.0000 1.0000
9.8480 0.0000 1.0000
9.8560 0.0000 1.0000
9.8640 0.0000 1.0000
9.8720 0.0000 1.0000
9.8800 0.0000 1.0000
9.8880 0.0000 1.0000
9.8960 0.0000 1.0000
9.9040 0.0000 1.0000
9.9120 0.0000 1.0000
9.9200 0.0000 1.0000
9.9280 0.0000 1.0000
9.9360 0.0000 1.0000
9.9440 0.0000 1.0000
9.9520 0.0000 1.0000
9.9600 0.0000 1.0000
9.9680 0.0000 1.0000
9.9760 0.0000 1.0000
9.9840 0.0000 1.0000
9.9920 0.0000 1.0000
10.0000 0.0000 1.0000
*RAS_INT_END
*RAS_DATA_END