File: xrr_temp/CWOI7_reflectivity.ras
*RAS_DATA_START
*RAS_HEADER_START
*DISP_FMT_X "%.4f"
*DISP_FMT_Y "%.0f"
*DISP_FULLSCALE "29238934.0000000040"
*DISP_LINE_COLOR "255.0000000000"
*DISP_LINE_STYLE "0.0000000000"
*DISP_LINE_WIDTH "0.2500000000"
*DISP_NOTE "Collected Data-8"
*DISP_OFFSET_Y "0.0000000000"
*DISP_PEAKSEARCH_UNIT_Y "cps"
*DISP_RANGE_BOTTOM "0.0100000000"
*DISP_RANGE_LEFT "-0.0006000000"
*DISP_RANGE_LOGCUTOFF "0.0100000000"
*DISP_RANGE_RIGHT "6.0006000000"
*DISP_RANGE_TOP "29238934.0000000040"
*DISP_SCALE_MODE_Y "2.0000000000"
*DISP_TAB_NAME "2-Theta/Omega"
*DISP_TITLE_Y "Intensity"
*DISP_UNIT_Y "cps"
*DISP_WINDOW_NAME "MSG_MACROENGINE"
*FILE_COMMENT " "
*FILE_MD5 ""
*FILE_MEMO " "
*FILE_OPERATOR "Administrator"
*FILE_PART_ID "MEAS_KHP2_00055"
*FILE_SAMPLE "CWO I-7"
*FILE_TYPE "RAS_RAW"
*FILE_USERGROUP "System Manager"
*FILE_VERSION "1.0000000000"
*HW_ATTACHMENT_ID "ATT0025"
*HW_ATTACHMENT_NAME "標準|Standard"
*HW_COUNTER_ID-0 "CUT0025"
*HW_COUNTER_ID-1 "CUT0020"
*HW_COUNTER_ID-2 "CUT0020"
*HW_COUNTER_ID-3 "CSL0021"
*HW_COUNTER_ID-4 "CMC0021"
*HW_COUNTER_NAME-0 "D/teX Ultra|D/teX Ultra"
*HW_COUNTER_NAME-1 "None|None"
*HW_COUNTER_NAME-2 "None|None"
*HW_COUNTER_NAME-3 "BBM|BBM"
*HW_COUNTER_NAME-4 "検出器モノクロメータ|Detector monochromator"
*HW_COUNTER_SELECT_NAME "D/teX Ultra|D/teX Ultra"
*HW_GONIOMETER_ID "GON0023"
*HW_GONIOMETER_NAME "SmartLab|SmartLab"
*HW_GONIOMETER_RADIUS-0 "90.0"
*HW_GONIOMETER_RADIUS-1 "114.0"
*HW_GONIOMETER_RADIUS-2 "190.0"
*HW_GONIOMETER_RADIUS-3 "300.0"
*HW_GONIOMETER_RADIUS-4 "187.0"
*HW_GONIOMETER_RADIUS-5 "300.0"
*HW_GONIOMETER_RADIUS-6 "113.0"
*HW_GONIOMETER_RADIUS-7 "331.0"
*HW_I_OPT_ID-0 "CBO0021"
*HW_I_OPT_ID-1 "ICR0021"
*HW_I_OPT_ID-2 "ISL0021"
*HW_I_OPT_ID-3 "ISO0021"
*HW_I_OPT_ID-4 "IAD0021"
*HW_I_OPT_ID-5 "IPR0001"
*HW_I_OPT_NAME-0 "CBOユニット|CBO unit"
*HW_I_OPT_NAME-1 "標準入射光学ユニット|Standard incident optical unit"
*HW_I_OPT_NAME-2 "標準入射スリットボックス|Standard incident slit box"
*HW_I_OPT_NAME-3 "入射平行スリット|Incident parallel slit"
*HW_I_OPT_NAME-4 "長手制限スリット|Length limiting slit"
*HW_I_OPT_NAME-5 "None|None"
*HW_R_ATTENUATER_AUTOMODE "1"
*HW_R_OPT_ID-0 "RSS0021"
*HW_R_OPT_ID-1 "RCR0023"
*HW_R_OPT_ID-2 "RSO0021"
*HW_R_OPT_ID-3 "RRS0021"
*HW_R_OPT_ID-4 "ATN0021"
*HW_R_OPT_ID-5 "RFL0021"
*HW_R_OPT_ID-6 "RAD0021"
*HW_R_OPT_NAME-0 "標準受光スリットボックス1|Standard receiving slit box # 1"
*HW_R_OPT_NAME-1 "標準受光光学ユニット1|Standard receiving unit # 1"
*HW_R_OPT_NAME-2 "標準受光光学ユニット2|Standard receiving optical unit # 2"
*HW_R_OPT_NAME-3 "標準受光スリットボックス2|Standard receiving slit box # 2"
*HW_R_OPT_NAME-4 "標準アッテネータ|Standard Attenuator"
*HW_R_OPT_NAME-5 "Cu Kβ|Cu K-beta"
*HW_R_OPT_NAME-6 "調整用受光スリット|Alignment receiving slit"
*HW_SAMPLE_HOLDER_ID "SMP0021"
*HW_SAMPLE_HOLDER_NAME "χφZクレードル|Chi phi Z cradle"
*HW_XG_CURRENT_MAX "200"
*HW_XG_CURRENT_MIN "10"
*HW_XG_CURRENT_RESOLUTION "1"
*HW_XG_CURRENT_UNIT "mA"
*HW_XG_FOCUS "0.4mm x 8mm"
*HW_XG_FOCUS_TYPE "Normal"
*HW_XG_ID "1700"
*HW_XG_NAME "9kW 開放管(45kV 200mA ID:1700)|9kW Rotating anode(45kV 200mA ID:1700)"
*HW_XG_TARGET_ATOMIC_NUMBER "29.0000000000"
*HW_XG_TARGET_NAME "Cu"
*HW_XG_TYPE "Rota"
*HW_XG_VOLTAGE_MAX "45"
*HW_XG_VOLTAGE_MIN "20"
*HW_XG_VOLTAGE_RESOLUTION "1"
*HW_XG_VOLTAGE_UNIT "kV"
*HW_XG_WATT_MAX "9.00"
*HW_XG_WATT_UNIT "kW"
*HW_XG_WAVE_LENGTH_ALPHA1 "1.540593"
*HW_XG_WAVE_LENGTH_ALPHA2 "1.544414"
*HW_XG_WAVE_LENGTH_BETA "1.392250"
*MEAS_COND_AXIS_NAME-0 "Theta/2-Theta"
*MEAS_COND_AXIS_NAME-1 "2-Theta"
*MEAS_COND_AXIS_NAME-2 "Omega"
*MEAS_COND_AXIS_NAME-3 "Chi"
*MEAS_COND_AXIS_NAME-4 "Phi"
*MEAS_COND_AXIS_NAME-5 "Z"
*MEAS_COND_AXIS_NAME-6 "2-Theta/Omega"
*MEAS_COND_AXIS_NAME-7 "Theta_s"
*MEAS_COND_AXIS_NAME-8 "Theta_d"
*MEAS_COND_AXIS_NAME-9 "Ts"
*MEAS_COND_AXIS_NAME-10 "CBO selection slit"
*MEAS_COND_AXIS_NAME-11 "M"
*MEAS_COND_AXIS_NAME-12 "Incident parallel slit"
*MEAS_COND_AXIS_NAME-13 "Incident slit"
*MEAS_COND_AXIS_NAME-14 ""
*MEAS_COND_AXIS_NAME-15 "Zs"
*MEAS_COND_AXIS_NAME-16 "Incident optical device"
*MEAS_COND_AXIS_NAME-17 "Omega_m"
*MEAS_COND_AXIS_NAME-18 "Length limiting slit"
*MEAS_COND_AXIS_NAME-19 "Center slit"
*MEAS_COND_AXIS_NAME-20 "Filter"
*MEAS_COND_AXIS_NAME-21 "Receiving slit # 1"
*MEAS_COND_AXIS_NAME-22 "Receiving slit # 2"
*MEAS_COND_AXIS_NAME-23 "Receiving optical device"
*MEAS_COND_AXIS_NAME-24 "Receiving parallel slit"
*MEAS_COND_AXIS_NAME-25 "Alignment receiving slit"
*MEAS_COND_AXIS_NAME-26 ""
*MEAS_COND_AXIS_NAME-27 ""
*MEAS_COND_AXIS_NAME-28 "Zd"
*MEAS_COND_AXIS_NAME-29 "Attenuator"
*MEAS_COND_AXIS_NAME-30 "Diffracted beam monochromator"
*MEAS_COND_AXIS_NAME-31 "Monochromator slit"
*MEAS_COND_AXIS_NAME-32 "Primary beam"
*MEAS_COND_AXIS_NAME-33 ""
*MEAS_COND_AXIS_NAME-34 ""
*MEAS_COND_AXIS_NAME-35 "PHA"
*MEAS_COND_AXIS_NAME_INTERNAL-0 "TwoThetaTheta"
*MEAS_COND_AXIS_NAME_INTERNAL-1 "TwoTheta"
*MEAS_COND_AXIS_NAME_INTERNAL-2 "Omega"
*MEAS_COND_AXIS_NAME_INTERNAL-3 "Chi"
*MEAS_COND_AXIS_NAME_INTERNAL-4 "Phi"
*MEAS_COND_AXIS_NAME_INTERNAL-5 "Z"
*MEAS_COND_AXIS_NAME_INTERNAL-6 "TwoThetaOmega"
*MEAS_COND_AXIS_NAME_INTERNAL-7 "ThetaS"
*MEAS_COND_AXIS_NAME_INTERNAL-8 "ThetaD"
*MEAS_COND_AXIS_NAME_INTERNAL-9 "Ts"
*MEAS_COND_AXIS_NAME_INTERNAL-10 "CBO"
*MEAS_COND_AXIS_NAME_INTERNAL-11 "CBO-M"
*MEAS_COND_AXIS_NAME_INTERNAL-12 "IncidentSollerSlit"
*MEAS_COND_AXIS_NAME_INTERNAL-13 "IncidentSlitBox"
*MEAS_COND_AXIS_NAME_INTERNAL-14 "IncidentSlitBox-_Axis"
*MEAS_COND_AXIS_NAME_INTERNAL-15 "Zs"
*MEAS_COND_AXIS_NAME_INTERNAL-16 "IncidentMonochromator"
*MEAS_COND_AXIS_NAME_INTERNAL-17 "IncidentMonochromator-OmegaM"
*MEAS_COND_AXIS_NAME_INTERNAL-18 "IncidentAxdSlit"
*MEAS_COND_AXIS_NAME_INTERNAL-19 "CenterSlit"
*MEAS_COND_AXIS_NAME_INTERNAL-20 "Filter"
*MEAS_COND_AXIS_NAME_INTERNAL-21 "ReceivingSlitBox1"
*MEAS_COND_AXIS_NAME_INTERNAL-22 "ReceivingSlitBox2"
*MEAS_COND_AXIS_NAME_INTERNAL-23 "ReceivingOptics"
*MEAS_COND_AXIS_NAME_INTERNAL-24 "ReceivingSollerSlit"
*MEAS_COND_AXIS_NAME_INTERNAL-25 "ReceivingAxdSlit"
*MEAS_COND_AXIS_NAME_INTERNAL-26 "ReceivingSlitBox1-_Axis"
*MEAS_COND_AXIS_NAME_INTERNAL-27 "ReceivingSlitBox2-_Axis"
*MEAS_COND_AXIS_NAME_INTERNAL-28 "ReceivingSlitBox2-Zd"
*MEAS_COND_AXIS_NAME_INTERNAL-29 "Attenuator"
*MEAS_COND_AXIS_NAME_INTERNAL-30 "CounterMonochromator"
*MEAS_COND_AXIS_NAME_INTERNAL-31 "CounterSlit"
*MEAS_COND_AXIS_NAME_INTERNAL-32 "IncidentPrimary"
*MEAS_COND_AXIS_NAME_INTERNAL-33 "AlphaR"
*MEAS_COND_AXIS_NAME_INTERNAL-34 "BetaR"
*MEAS_COND_AXIS_NAME_INTERNAL-35 "PHA"
*MEAS_COND_AXIS_NAME_MAGICNO-0 "83951616.0000000000"
*MEAS_COND_AXIS_NAME_MAGICNO-1 "268632064.0000000000"
*MEAS_COND_AXIS_NAME_MAGICNO-2 "268500992.0000000000"
*MEAS_COND_AXIS_NAME_MAGICNO-3 "268500992.0000000000"
*MEAS_COND_AXIS_NAME_MAGICNO-4 "268500992.0000000000"
*MEAS_COND_AXIS_NAME_MAGICNO-5 "285278208.0000000000"
*MEAS_COND_AXIS_NAME_MAGICNO-6 "83951616.0000000000"
*MEAS_COND_AXIS_NAME_MAGICNO-7 "131072.0000000000"
*MEAS_COND_AXIS_NAME_MAGICNO-8 "131072.0000000000"
*MEAS_COND_AXIS_NAME_MAGICNO-9 "318898176.0000000000"
*MEAS_COND_AXIS_NAME_MAGICNO-10 "20971521.0000000000"
*MEAS_COND_AXIS_NAME_MAGICNO-11 "285343744.0000000000"
*MEAS_COND_AXIS_NAME_MAGICNO-12 "20971521.0000000000"
*MEAS_COND_AXIS_NAME_MAGICNO-13 "22020097.0000000000"
*MEAS_COND_AXIS_NAME_MAGICNO-14 "25165824.0000000000"
*MEAS_COND_AXIS_NAME_MAGICNO-15 "318898176.0000000000"
*MEAS_COND_AXIS_NAME_MAGICNO-16 "20971521.0000000000"
*MEAS_COND_AXIS_NAME_MAGICNO-17 "285343744.0000000000"
*MEAS_COND_AXIS_NAME_MAGICNO-18 "20971521.0000000000"
*MEAS_COND_AXIS_NAME_MAGICNO-19 "20971521.0000000000"
*MEAS_COND_AXIS_NAME_MAGICNO-20 "20971521.0000000000"
*MEAS_COND_AXIS_NAME_MAGICNO-21 "23068673.0000000000"
*MEAS_COND_AXIS_NAME_MAGICNO-22 "23068673.0000000000"
*MEAS_COND_AXIS_NAME_MAGICNO-23 "20971521.0000000000"
*MEAS_COND_AXIS_NAME_MAGICNO-24 "20971521.0000000000"
*MEAS_COND_AXIS_NAME_MAGICNO-25 "20971521.0000000000"
*MEAS_COND_AXIS_NAME_MAGICNO-26 "25165824.0000000000"
*MEAS_COND_AXIS_NAME_MAGICNO-27 "25165824.0000000000"
*MEAS_COND_AXIS_NAME_MAGICNO-28 "285343744.0000000000"
*MEAS_COND_AXIS_NAME_MAGICNO-29 "17301505.0000000000"
*MEAS_COND_AXIS_NAME_MAGICNO-30 "20971521.0000000000"
*MEAS_COND_AXIS_NAME_MAGICNO-31 "20971521.0000000000"
*MEAS_COND_AXIS_NAME_MAGICNO-32 "20971521.0000000000"
*MEAS_COND_AXIS_NAME_MAGICNO-33 "8388608.0000000000"
*MEAS_COND_AXIS_NAME_MAGICNO-34 "8388608.0000000000"
*MEAS_COND_AXIS_NAME_MAGICNO-35 "0.0000000000"
*MEAS_COND_AXIS_OFFSET-0 "-"
*MEAS_COND_AXIS_OFFSET-1 "0.9258000000"
*MEAS_COND_AXIS_OFFSET-2 "0.9293000000"
*MEAS_COND_AXIS_OFFSET-3 "0.0000000000"
*MEAS_COND_AXIS_OFFSET-4 "0.0000000000"
*MEAS_COND_AXIS_OFFSET-5 "-"
*MEAS_COND_AXIS_OFFSET-6 "-"
*MEAS_COND_AXIS_OFFSET-7 "0.9293000000"
*MEAS_COND_AXIS_OFFSET-8 "-0.0035000000"
*MEAS_COND_AXIS_OFFSET-9 "-"
*MEAS_COND_AXIS_OFFSET-10 "-"
*MEAS_COND_AXIS_OFFSET-11 "-"
*MEAS_COND_AXIS_OFFSET-12 "-"
*MEAS_COND_AXIS_OFFSET-13 "-"
*MEAS_COND_AXIS_OFFSET-14 "-"
*MEAS_COND_AXIS_OFFSET-15 "-"
*MEAS_COND_AXIS_OFFSET-16 "-"
*MEAS_COND_AXIS_OFFSET-17 "-"
*MEAS_COND_AXIS_OFFSET-18 "-"
*MEAS_COND_AXIS_OFFSET-19 "-"
*MEAS_COND_AXIS_OFFSET-20 "-"
*MEAS_COND_AXIS_OFFSET-21 "-"
*MEAS_COND_AXIS_OFFSET-22 "-"
*MEAS_COND_AXIS_OFFSET-23 "-"
*MEAS_COND_AXIS_OFFSET-24 "-"
*MEAS_COND_AXIS_OFFSET-25 "-"
*MEAS_COND_AXIS_OFFSET-26 "-"
*MEAS_COND_AXIS_OFFSET-27 "-"
*MEAS_COND_AXIS_OFFSET-28 "-"
*MEAS_COND_AXIS_OFFSET-29 "-"
*MEAS_COND_AXIS_OFFSET-30 "-"
*MEAS_COND_AXIS_OFFSET-31 "-"
*MEAS_COND_AXIS_OFFSET-32 "-"
*MEAS_COND_AXIS_OFFSET-33 "0.0000000000"
*MEAS_COND_AXIS_OFFSET-34 "0.0000000000"
*MEAS_COND_AXIS_OFFSET-35 "-"
*MEAS_COND_AXIS_POSITION-0 "-0.0008000000"
*MEAS_COND_AXIS_POSITION-1 "-0.0008000000"
*MEAS_COND_AXIS_POSITION-2 "-0.0004000000"
*MEAS_COND_AXIS_POSITION-3 "0.0000000000"
*MEAS_COND_AXIS_POSITION-4 "0.0000000000"
*MEAS_COND_AXIS_POSITION-5 "-1.4515000000"
*MEAS_COND_AXIS_POSITION-6 "-0.0008000000"
*MEAS_COND_AXIS_POSITION-7 "-0.0004000000"
*MEAS_COND_AXIS_POSITION-8 "-0.0004000000"
*MEAS_COND_AXIS_POSITION-9 "-4.9464400000"
*MEAS_COND_AXIS_POSITION-10 "PB"
*MEAS_COND_AXIS_POSITION-11 "0.0000000000"
*MEAS_COND_AXIS_POSITION-12 "Soller_slit_open_s"
*MEAS_COND_AXIS_POSITION-13 "0.250mm"
*MEAS_COND_AXIS_POSITION-14 "0.2500000000"
*MEAS_COND_AXIS_POSITION-15 "-0.8990600000"
*MEAS_COND_AXIS_POSITION-16 "Ge(220)x2"
*MEAS_COND_AXIS_POSITION-17 "0.0000000000"
*MEAS_COND_AXIS_POSITION-18 "2.0mm"
*MEAS_COND_AXIS_POSITION-19 "None"
*MEAS_COND_AXIS_POSITION-20 "None"
*MEAS_COND_AXIS_POSITION-21 "0.250mm"
*MEAS_COND_AXIS_POSITION-22 "0.250mm"
*MEAS_COND_AXIS_POSITION-23 "No_unit"
*MEAS_COND_AXIS_POSITION-24 "Soller_slit_5.0deg"
*MEAS_COND_AXIS_POSITION-25 "None"
*MEAS_COND_AXIS_POSITION-26 "0.2500000000"
*MEAS_COND_AXIS_POSITION-27 "0.2500000000"
*MEAS_COND_AXIS_POSITION-28 "0.0878100000"
*MEAS_COND_AXIS_POSITION-29 "1/10000"
*MEAS_COND_AXIS_POSITION-30 "None"
*MEAS_COND_AXIS_POSITION-31 "None"
*MEAS_COND_AXIS_POSITION-32 "None"
*MEAS_COND_AXIS_POSITION-33 "0.0000000000"
*MEAS_COND_AXIS_POSITION-34 "0.0000000000"
*MEAS_COND_AXIS_POSITION-35 "34.0000000000"
*MEAS_COND_AXIS_UNIT-0 "deg"
*MEAS_COND_AXIS_UNIT-1 "deg"
*MEAS_COND_AXIS_UNIT-2 "deg"
*MEAS_COND_AXIS_UNIT-3 "deg"
*MEAS_COND_AXIS_UNIT-4 "deg"
*MEAS_COND_AXIS_UNIT-5 "mm"
*MEAS_COND_AXIS_UNIT-6 "deg"
*MEAS_COND_AXIS_UNIT-7 "deg"
*MEAS_COND_AXIS_UNIT-8 "deg"
*MEAS_COND_AXIS_UNIT-9 "mm"
*MEAS_COND_AXIS_UNIT-10 ""
*MEAS_COND_AXIS_UNIT-11 "pulse"
*MEAS_COND_AXIS_UNIT-12 ""
*MEAS_COND_AXIS_UNIT-13 ""
*MEAS_COND_AXIS_UNIT-14 "mm"
*MEAS_COND_AXIS_UNIT-15 "mm"
*MEAS_COND_AXIS_UNIT-16 ""
*MEAS_COND_AXIS_UNIT-17 "pulse"
*MEAS_COND_AXIS_UNIT-18 ""
*MEAS_COND_AXIS_UNIT-19 ""
*MEAS_COND_AXIS_UNIT-20 ""
*MEAS_COND_AXIS_UNIT-21 ""
*MEAS_COND_AXIS_UNIT-22 ""
*MEAS_COND_AXIS_UNIT-23 ""
*MEAS_COND_AXIS_UNIT-24 ""
*MEAS_COND_AXIS_UNIT-25 ""
*MEAS_COND_AXIS_UNIT-26 "mm"
*MEAS_COND_AXIS_UNIT-27 "mm"
*MEAS_COND_AXIS_UNIT-28 "mm"
*MEAS_COND_AXIS_UNIT-29 ""
*MEAS_COND_AXIS_UNIT-30 ""
*MEAS_COND_AXIS_UNIT-31 ""
*MEAS_COND_AXIS_UNIT-32 ""
*MEAS_COND_AXIS_UNIT-33 "deg"
*MEAS_COND_AXIS_UNIT-34 "deg"
*MEAS_COND_AXIS_UNIT-35 "div"
*MEAS_COND_COUNTER_CNTLOSS_CORR "0.0000000000"
*MEAS_COND_COUNTER_PHABASE "34.0000000000"
*MEAS_COND_COUNTER_PHAWINDOW "19.0000000000"
*MEAS_COND_COUNTER_PHA_UNIT "div"
*MEAS_COND_COUNTER_TAUDIFF "2.0000000000"
*MEAS_COND_COUNTER_TAUINT "0.1000000000"
*MEAS_COND_IRRADIATION_MODE "OFF"
*MEAS_COND_IRRADIATION_WIDTH ""
*MEAS_COND_OPT_ATTR "High resolution parallel beam Ge(220)x2/RS"
*MEAS_COND_OPT_NAME "@High resolution PB-Ge(220)x2"
*MEAS_COND_UNSYMMETRIC_MODE "OFF"
*MEAS_COND_XG_CURRENT "200.0000000000"
*MEAS_COND_XG_VOLTAGE "45.0000000000"
*MEAS_COND_XG_WAVE_TYPE "Ka1"
*MEAS_DATA_COUNT "3001.0000000000"
*MEAS_SCAN_AXIS_X "2-Theta/Omega"
*MEAS_SCAN_AXIS_X_INTERNAL "TwoThetaOmega"
*MEAS_SCAN_END_TIME "10/29/23 12:02:10"
*MEAS_SCAN_MODE "CONTINUOUS"
*MEAS_SCAN_MONITOR "0"
*MEAS_SCAN_RESOLUTION_X "0.0002"
*MEAS_SCAN_SPEED "0.500000"
*MEAS_SCAN_SPEED_UNIT "deg/min"
*MEAS_SCAN_SPEED_USER "0.500000"
*MEAS_SCAN_START "0.0000000000"
*MEAS_SCAN_START_TIME "10/29/23 11:49:39"
*MEAS_SCAN_STEP "0.0020000000"
*MEAS_SCAN_STOP "6.0000000000"
*MEAS_SCAN_UNIT_X "deg"
*MEAS_SCAN_UNIT_Y "counts"
*RAS_HEADER_END
*RAS_INT_START
0.0000 5528365.5000 1.0000
0.0060 5676077.0000 1.0000
0.0120 5505884.5000 1.0000
0.0180 5533330.5000 1.0000
0.0240 5324934.0000 1.0000
0.0300 5102883.5000 1.0000
0.0360 4698090.0000 1.0000
0.0420 3806440.2500 1.0000
0.0480 2866243.0000 1.0000
0.0540 1944802.8750 1.0000
0.0600 1159519.5000 1.0000
0.0660 612425.7500 1.0000
0.0720 297007.5000 1.0000
0.0780 164765.8281 1.0000
0.0840 120310.4141 1.0000
0.0900 95926.5938 1.0000
0.0960 87950.0859 1.0000
0.1020 88300.1328 1.0000
0.1080 92470.8516 1.0000
0.1140 98496.0547 1.0000
0.1200 100968.6953 1.0000
0.1260 105377.7422 1.0000
0.1320 112050.8984 1.0000
0.1380 116951.4922 1.0000
0.1440 119334.7656 1.0000
0.1500 121941.4688 1.0000
0.1560 131459.6563 1.0000
0.1620 135287.7656 1.0000
0.1680 136404.9219 1.0000
0.1740 142214.1563 1.0000
0.1800 143852.6406 1.0000
0.1860 151426.9844 1.0000
0.1920 154182.6250 1.0000
0.1980 160423.8125 1.0000
0.2040 166374.5469 1.0000
0.2100 170813.3750 1.0000
0.2160 176168.2969 1.0000
0.2220 177739.7656 1.0000
0.2280 181850.9063 1.0000
0.2340 183280.8594 1.0000
0.2400 189306.0625 1.0000
0.2460 197677.2969 1.0000
0.2520 199099.8125 1.0000
0.2580 199338.1406 1.0000
0.2640 213950.5625 1.0000
0.2700 214114.4063 1.0000
0.2760 224913.5938 1.0000
0.2820 219260.7813 1.0000
0.2880 224444.3906 1.0000
0.2940 230856.8750 1.0000
0.3000 232219.7969 1.0000
0.3060 246407.7031 1.0000
0.3120 243525.4375 1.0000
0.3180 249029.2969 1.0000
0.3240 249438.9219 1.0000
0.3300 254503.3750 1.0000
0.3360 264274.7813 1.0000
0.3420 272124.6563 1.0000
0.3480 273033.2813 1.0000
0.3540 276027.2813 1.0000
0.3600 280160.7500 1.0000
0.3660 281263.0313 1.0000
0.3720 287049.9063 1.0000
0.3780 292114.3438 1.0000
0.3840 289745.9688 1.0000
0.3900 301818.7188 1.0000
0.3960 303442.3125 1.0000
0.4020 312267.8750 1.0000
0.4080 303002.9063 1.0000
0.4140 313548.8750 1.0000
0.4200 313965.9375 1.0000
0.4260 317362.0938 1.0000
0.4320 320043.2813 1.0000
0.4380 321100.8438 1.0000
0.4440 330544.5625 1.0000
0.4500 336890.0313 1.0000
0.4560 339064.7500 1.0000
0.4620 343071.6250 1.0000
0.4680 340457.4688 1.0000
0.4740 338774.2813 1.0000
0.4800 352776.0000 1.0000
0.4860 357334.0000 1.0000
0.4920 356656.2500 1.0000
0.4980 357840.4375 1.0000
0.5040 357482.9375 1.0000
0.5100 366680.8750 1.0000
0.5160 360387.5625 1.0000
0.5220 380563.4375 1.0000
0.5280 372668.8438 1.0000
0.5340 370300.4688 1.0000
0.5400 375081.9063 1.0000
0.5460 380340.0000 1.0000
0.5520 383557.4063 1.0000
0.5580 377018.3125 1.0000
0.5640 384294.7188 1.0000
0.5700 386633.3125 1.0000
0.5760 384287.2813 1.0000
0.5820 382291.3125 1.0000
0.5880 379178.1563 1.0000
0.5940 378887.6875 1.0000
0.6000 378150.3750 1.0000
0.6060 374061.5625 1.0000
0.6120 372214.5313 1.0000
0.6180 366412.7813 1.0000
0.6240 368602.4063 1.0000
0.6300 358309.6563 1.0000
0.6360 346914.6563 1.0000
0.6420 342565.1563 1.0000
0.6480 332726.7500 1.0000
0.6540 318211.1563 1.0000
0.6600 303732.7813 1.0000
0.6660 286543.4688 1.0000
0.6720 267291.0938 1.0000
0.6780 248612.2344 1.0000
0.6840 226529.7500 1.0000
0.6900 210688.4531 1.0000
0.6960 190549.8281 1.0000
0.7020 176198.0781 1.0000
0.7080 158658.7031 1.0000
0.7140 143137.6719 1.0000
0.7200 129962.6563 1.0000
0.7260 115901.3672 1.0000
0.7320 111283.7813 1.0000
0.7380 95859.5625 1.0000
0.7440 91323.8984 1.0000
0.7500 83667.6484 1.0000
0.7560 78819.1875 1.0000
0.7620 72652.4766 1.0000
0.7680 68794.5547 1.0000
0.7740 64862.1641 1.0000
0.7800 63499.2305 1.0000
0.7860 60036.0430 1.0000
0.7920 57205.9102 1.0000
0.7980 55837.5000 1.0000
0.8040 53193.3320 1.0000
0.8100 51537.1680 1.0000
0.8160 49539.0000 1.0000
0.8220 48152.1680 1.0000
0.8280 46379.0000 1.0000
0.8340 44579.0000 1.0000
0.8400 43004.0000 1.0000
0.8460 40921.1680 1.0000
0.8520 39974.1680 1.0000
0.8580 37494.5000 1.0000
0.8640 36127.5000 1.0000
0.8700 34792.1680 1.0000
0.8760 32905.5000 1.0000
0.8820 31735.6660 1.0000
0.8880 30222.5000 1.0000
0.8940 28952.1660 1.0000
0.9000 27663.8340 1.0000
0.9060 26206.6660 1.0000
0.9120 25128.0000 1.0000
0.9180 23995.5000 1.0000
0.9240 23040.3340 1.0000
0.9300 22357.5000 1.0000
0.9360 21343.5000 1.0000
0.9420 20839.3340 1.0000
0.9480 19736.0000 1.0000
0.9540 19029.1660 1.0000
0.9600 18589.5000 1.0000
0.9660 18048.3340 1.0000
0.9720 17334.3340 1.0000
0.9780 16892.8340 1.0000
0.9840 16888.8340 1.0000
0.9900 16312.3330 1.0000
0.9960 15722.6670 1.0000
1.0020 15592.0000 1.0000
1.0080 15473.8330 1.0000
1.0140 14903.8330 1.0000
1.0200 14978.6670 1.0000
1.0260 14494.8330 1.0000
1.0320 14367.1670 1.0000
1.0380 13931.6670 1.0000
1.0440 14057.6670 1.0000
1.0500 13653.8330 1.0000
1.0560 13433.0000 1.0000
1.0620 12993.1670 1.0000
1.0680 12839.8330 1.0000
1.0740 12568.6670 1.0000
1.0800 12202.1670 1.0000
1.0860 11945.1670 1.0000
1.0920 11650.8330 1.0000
1.0980 11260.0000 1.0000
1.1040 10975.6670 1.0000
1.1100 10730.6670 1.0000
1.1160 10344.8330 1.0000
1.1220 10088.5000 1.0000
1.1280 9610.1670 1.0000
1.1340 9237.8330 1.0000
1.1400 8940.6670 1.0000
1.1460 8850.1670 1.0000
1.1520 8356.3330 1.0000
1.1580 8220.3330 1.0000
1.1640 7898.5000 1.0000
1.1700 7642.5000 1.0000
1.1760 7351.6665 1.0000
1.1820 7180.1665 1.0000
1.1880 6887.3335 1.0000
1.1940 6666.1665 1.0000
1.2000 6370.3335 1.0000
1.2060 6218.8335 1.0000
1.2120 6050.8335 1.0000
1.2180 6123.5000 1.0000
1.2240 5914.3335 1.0000
1.2300 5680.1665 1.0000
1.2360 5636.1665 1.0000
1.2420 5570.3335 1.0000
1.2480 5561.6665 1.0000
1.2540 5378.6665 1.0000
1.2600 5345.8335 1.0000
1.2660 5292.8335 1.0000
1.2720 5180.5000 1.0000
1.2780 5356.6665 1.0000
1.2840 5154.5000 1.0000
1.2900 5174.0000 1.0000
1.2960 5244.6665 1.0000
1.3020 5055.1665 1.0000
1.3080 5105.0000 1.0000
1.3140 5144.8335 1.0000
1.3200 5044.6665 1.0000
1.3260 5010.8335 1.0000
1.3320 4911.6665 1.0000
1.3380 4850.1665 1.0000
1.3440 4892.5000 1.0000
1.3500 4849.8335 1.0000
1.3560 4711.6665 1.0000
1.3620 4500.0000 1.0000
1.3680 4576.1665 1.0000
1.3740 4620.5000 1.0000
1.3800 4497.6665 1.0000
1.3860 4330.1665 1.0000
1.3920 4266.5000 1.0000
1.3980 4222.3335 1.0000
1.4040 4002.1667 1.0000
1.4100 3956.5000 1.0000
1.4160 3810.5000 1.0000
1.4220 3852.6667 1.0000
1.4280 3743.3333 1.0000
1.4340 3605.6667 1.0000
1.4400 3449.1667 1.0000
1.4460 3382.0000 1.0000
1.4520 3213.8333 1.0000
1.4580 3104.5000 1.0000
1.4640 3005.0000 1.0000
1.4700 3017.0000 1.0000
1.4760 2864.1667 1.0000
1.4820 2733.0000 1.0000
1.4880 2646.0000 1.0000
1.4940 2676.0000 1.0000
1.5000 2439.8333 1.0000
1.5060 2448.5000 1.0000
1.5120 2349.0000 1.0000
1.5180 2350.5000 1.0000
1.5240 2236.5000 1.0000
1.5300 2235.0000 1.0000
1.5360 2156.3333 1.0000
1.5420 2019.0000 1.0000
1.5480 2053.3333 1.0000
1.5540 2035.8334 1.0000
1.5600 1997.6666 1.0000
1.5660 2064.0000 1.0000
1.5720 2006.0000 1.0000
1.5780 2002.8334 1.0000
1.5840 1952.6666 1.0000
1.5900 2021.5000 1.0000
1.5960 2031.3334 1.0000
1.6020 1947.1666 1.0000
1.6080 2023.0000 1.0000
1.6140 2027.8334 1.0000
1.6200 1997.3334 1.0000
1.6260 2048.5000 1.0000
1.6320 1963.8334 1.0000
1.6380 2076.1667 1.0000
1.6440 2019.6666 1.0000
1.6500 1946.0000 1.0000
1.6560 1983.5000 1.0000
1.6620 1949.8334 1.0000
1.6680 1963.3334 1.0000
1.6740 2019.5000 1.0000
1.6800 1919.0000 1.0000
1.6860 1908.0000 1.0000
1.6920 1974.1666 1.0000
1.6980 1900.1666 1.0000
1.7040 1893.1666 1.0000
1.7100 1854.8334 1.0000
1.7160 1825.6666 1.0000
1.7220 1707.5000 1.0000
1.7280 1660.3334 1.0000
1.7340 1788.5000 1.0000
1.7400 1660.5000 1.0000
1.7460 1644.8334 1.0000
1.7520 1542.0000 1.0000
1.7580 1535.6666 1.0000
1.7640 1489.5000 1.0000
1.7700 1430.8334 1.0000
1.7760 1343.0000 1.0000
1.7820 1348.3334 1.0000
1.7880 1348.6666 1.0000
1.7940 1282.6666 1.0000
1.8000 1215.0000 1.0000
1.8060 1184.3334 1.0000
1.8120 1117.6666 1.0000
1.8180 1143.1666 1.0000
1.8240 1093.8334 1.0000
1.8300 1011.5000 1.0000
1.8360 1024.1666 1.0000
1.8420 994.3333 1.0000
1.8480 924.5000 1.0000
1.8540 942.6667 1.0000
1.8600 954.0000 1.0000
1.8660 925.6667 1.0000
1.8720 902.1667 1.0000
1.8780 931.6667 1.0000
1.8840 902.8333 1.0000
1.8900 862.3333 1.0000
1.8960 913.6667 1.0000
1.9020 844.5000 1.0000
1.9080 855.3333 1.0000
1.9140 884.1667 1.0000
1.9200 886.8333 1.0000
1.9260 890.0000 1.0000
1.9320 860.3333 1.0000
1.9380 888.3333 1.0000
1.9440 912.8333 1.0000
1.9500 926.5000 1.0000
1.9560 965.3333 1.0000
1.9620 877.8333 1.0000
1.9680 923.0000 1.0000
1.9740 927.5000 1.0000
1.9800 933.3333 1.0000
1.9860 932.0000 1.0000
1.9920 970.6667 1.0000
1.9980 904.3333 1.0000
2.0040 934.6667 1.0000
2.0100 954.8333 1.0000
2.0160 927.5000 1.0000
2.0220 922.6667 1.0000
2.0280 896.6667 1.0000
2.0340 925.5000 1.0000
2.0400 892.1667 1.0000
2.0460 909.1667 1.0000
2.0520 842.0000 1.0000
2.0580 837.5000 1.0000
2.0640 824.1667 1.0000
2.0700 771.6667 1.0000
2.0760 823.0000 1.0000
2.0820 771.8333 1.0000
2.0880 803.5000 1.0000
2.0940 669.5000 1.0000
2.1000 698.6667 1.0000
2.1060 719.1667 1.0000
2.1120 698.5000 1.0000
2.1180 627.3333 1.0000
2.1240 586.6667 1.0000
2.1300 610.1667 1.0000
2.1360 587.8333 1.0000
2.1420 583.6667 1.0000
2.1480 570.8333 1.0000
2.1540 548.3333 1.0000
2.1600 495.6667 1.0000
2.1660 519.0000 1.0000
2.1720 432.3333 1.0000
2.1780 509.1667 1.0000
2.1840 463.1667 1.0000
2.1900 444.1667 1.0000
2.1960 458.6667 1.0000
2.2020 463.6667 1.0000
2.2080 401.1667 1.0000
2.2140 411.5000 1.0000
2.2200 430.1667 1.0000
2.2260 432.5000 1.0000
2.2320 418.8333 1.0000
2.2380 411.0000 1.0000
2.2440 405.6667 1.0000
2.2500 413.3333 1.0000
2.2560 414.1667 1.0000
2.2620 417.0000 1.0000
2.2680 405.0000 1.0000
2.2740 446.8333 1.0000
2.2800 526.5000 1.0000
2.2860 435.3333 1.0000
2.2920 458.0000 1.0000
2.2980 447.0000 1.0000
2.3040 455.8333 1.0000
2.3100 454.8333 1.0000
2.3160 483.1667 1.0000
2.3220 435.6667 1.0000
2.3280 468.1667 1.0000
2.3340 440.8333 1.0000
2.3400 481.0000 1.0000
2.3460 464.8333 1.0000
2.3520 457.3333 1.0000
2.3580 426.3333 1.0000
2.3640 433.3333 1.0000
2.3700 464.6667 1.0000
2.3760 433.3333 1.0000
2.3820 426.8333 1.0000
2.3880 457.3333 1.0000
2.3940 459.0000 1.0000
2.4000 444.0000 1.0000
2.4060 428.1667 1.0000
2.4120 416.1667 1.0000
2.4180 397.0000 1.0000
2.4240 376.6667 1.0000
2.4300 376.6667 1.0000
2.4360 358.0000 1.0000
2.4420 349.5000 1.0000
2.4480 326.5000 1.0000
2.4540 352.3333 1.0000
2.4600 346.1667 1.0000
2.4660 328.0000 1.0000
2.4720 275.3333 1.0000
2.4780 323.6667 1.0000
2.4840 303.6667 1.0000
2.4900 295.6667 1.0000
2.4960 276.0000 1.0000
2.5020 269.1667 1.0000
2.5080 247.5000 1.0000
2.5140 249.6667 1.0000
2.5200 243.6667 1.0000
2.5260 229.5000 1.0000
2.5320 236.1667 1.0000
2.5380 215.8333 1.0000
2.5440 214.1667 1.0000
2.5500 207.5000 1.0000
2.5560 187.3333 1.0000
2.5620 186.1667 1.0000
2.5680 292.3333 1.0000
2.5740 207.6667 1.0000
2.5800 209.0000 1.0000
2.5860 202.0000 1.0000
2.5920 211.6667 1.0000
2.5980 224.0000 1.0000
2.6040 208.1667 1.0000
2.6100 221.8333 1.0000
2.6160 246.0000 1.0000
2.6220 229.1667 1.0000
2.6280 207.5000 1.0000
2.6340 249.0000 1.0000
2.6400 205.6667 1.0000
2.6460 209.0000 1.0000
2.6520 236.3333 1.0000
2.6580 249.5000 1.0000
2.6640 229.5000 1.0000
2.6700 199.3333 1.0000
2.6760 216.8333 1.0000
2.6820 258.8333 1.0000
2.6880 239.8333 1.0000
2.6940 238.0000 1.0000
2.7000 231.8333 1.0000
2.7060 229.1667 1.0000
2.7120 213.6667 1.0000
2.7180 207.3333 1.0000
2.7240 233.0000 1.0000
2.7300 213.5000 1.0000
2.7360 206.1667 1.0000
2.7420 205.0000 1.0000
2.7480 182.8333 1.0000
2.7540 218.1667 1.0000
2.7600 201.1667 1.0000
2.7660 209.8333 1.0000
2.7720 212.3333 1.0000
2.7780 202.1667 1.0000
2.7840 184.5000 1.0000
2.7900 194.0000 1.0000
2.7960 200.0000 1.0000
2.8020 166.6667 1.0000
2.8080 176.1667 1.0000
2.8140 146.0000 1.0000
2.8200 162.3333 1.0000
2.8260 139.0000 1.0000
2.8320 127.3333 1.0000
2.8380 158.3333 1.0000
2.8440 154.0000 1.0000
2.8500 143.1667 1.0000
2.8560 115.6667 1.0000
2.8620 127.1667 1.0000
2.8680 125.1667 1.0000
2.8740 136.8333 1.0000
2.8800 112.8333 1.0000
2.8860 125.6667 1.0000
2.8920 103.1667 1.0000
2.8980 125.5000 1.0000
2.9040 115.6667 1.0000
2.9100 100.1667 1.0000
2.9160 98.6667 1.0000
2.9220 98.8333 1.0000
2.9280 103.5000 1.0000
2.9340 121.1667 1.0000
2.9400 123.5000 1.0000
2.9460 105.1667 1.0000
2.9520 123.8333 1.0000
2.9580 109.5000 1.0000
2.9640 100.8333 1.0000
2.9700 102.0000 1.0000
2.9760 106.6667 1.0000
2.9820 115.6667 1.0000
2.9880 114.5000 1.0000
2.9940 120.3333 1.0000
3.0000 121.6667 1.0000
3.0060 126.0000 1.0000
3.0120 134.6667 1.0000
3.0180 136.3333 1.0000
3.0240 122.5000 1.0000
3.0300 122.6667 1.0000
3.0360 137.3333 1.0000
3.0420 112.6667 1.0000
3.0480 122.3333 1.0000
3.0540 131.3333 1.0000
3.0600 114.6667 1.0000
3.0660 124.5000 1.0000
3.0720 96.8333 1.0000
3.0780 117.0000 1.0000
3.0840 106.8333 1.0000
3.0900 109.0000 1.0000
3.0960 119.6667 1.0000
3.1020 112.8333 1.0000
3.1080 115.0000 1.0000
3.1140 107.1667 1.0000
3.1200 104.3333 1.0000
3.1260 92.3333 1.0000
3.1320 114.8333 1.0000
3.1380 100.3333 1.0000
3.1440 87.1667 1.0000
3.1500 86.6667 1.0000
3.1560 95.3333 1.0000
3.1620 78.3333 1.0000
3.1680 93.8333 1.0000
3.1740 87.6667 1.0000
3.1800 94.6667 1.0000
3.1860 93.3333 1.0000
3.1920 61.1667 1.0000
3.1980 75.8333 1.0000
3.2040 60.8333 1.0000
3.2100 76.3333 1.0000
3.2160 70.3333 1.0000
3.2220 59.3333 1.0000
3.2280 57.6667 1.0000
3.2340 65.0000 1.0000
3.2400 67.8333 1.0000
3.2460 68.3333 1.0000
3.2520 68.1667 1.0000
3.2580 69.5000 1.0000
3.2640 63.8333 1.0000
3.2700 49.6667 1.0000
3.2760 56.3333 1.0000
3.2820 77.1667 1.0000
3.2880 62.5000 1.0000
3.2940 51.3333 1.0000
3.3000 63.8333 1.0000
3.3060 62.8333 1.0000
3.3120 56.5000 1.0000
3.3180 62.5000 1.0000
3.3240 67.0000 1.0000
3.3300 57.6667 1.0000
3.3360 55.5000 1.0000
3.3420 57.1667 1.0000
3.3480 59.6667 1.0000
3.3540 67.6667 1.0000
3.3600 56.0000 1.0000
3.3660 55.1667 1.0000
3.3720 68.0000 1.0000
3.3780 75.0000 1.0000
3.3840 63.0000 1.0000
3.3900 65.1667 1.0000
3.3960 85.3333 1.0000
3.4020 61.5000 1.0000
3.4080 62.0000 1.0000
3.4140 64.6667 1.0000
3.4200 65.8333 1.0000
3.4260 67.6667 1.0000
3.4320 60.3333 1.0000
3.4380 72.6667 1.0000
3.4440 57.6667 1.0000
3.4500 48.0000 1.0000
3.4560 63.1667 1.0000
3.4620 60.5000 1.0000
3.4680 40.6667 1.0000
3.4740 56.0000 1.0000
3.4800 40.1667 1.0000
3.4860 51.0000 1.0000
3.4920 44.0000 1.0000
3.4980 50.1667 1.0000
3.5040 51.0000 1.0000
3.5100 40.1667 1.0000
3.5160 39.3333 1.0000
3.5220 37.6667 1.0000
3.5280 49.6667 1.0000
3.5340 49.8333 1.0000
3.5400 31.3333 1.0000
3.5460 40.5000 1.0000
3.5520 36.6667 1.0000
3.5580 47.6667 1.0000
3.5640 41.0000 1.0000
3.5700 37.0000 1.0000
3.5760 37.5000 1.0000
3.5820 34.5000 1.0000
3.5880 27.3333 1.0000
3.5940 44.5000 1.0000
3.6000 41.0000 1.0000
3.6060 32.1667 1.0000
3.6120 36.8333 1.0000
3.6180 24.3333 1.0000
3.6240 35.8333 1.0000
3.6300 38.6667 1.0000
3.6360 28.1667 1.0000
3.6420 42.8333 1.0000
3.6480 37.1667 1.0000
3.6540 36.3333 1.0000
3.6600 36.5000 1.0000
3.6660 36.6667 1.0000
3.6720 28.1667 1.0000
3.6780 36.0000 1.0000
3.6840 43.5000 1.0000
3.6900 28.0000 1.0000
3.6960 39.3333 1.0000
3.7020 33.1667 1.0000
3.7080 38.8333 1.0000
3.7140 39.1667 1.0000
3.7200 32.1667 1.0000
3.7260 31.0000 1.0000
3.7320 37.6667 1.0000
3.7380 43.1667 1.0000
3.7440 35.0000 1.0000
3.7500 39.0000 1.0000
3.7560 37.3333 1.0000
3.7620 30.6667 1.0000
3.7680 34.3333 1.0000
3.7740 36.0000 1.0000
3.7800 28.1667 1.0000
3.7860 34.3333 1.0000
3.7920 29.3333 1.0000
3.7980 39.3333 1.0000
3.8040 36.5000 1.0000
3.8100 29.6667 1.0000
3.8160 28.5000 1.0000
3.8220 21.6667 1.0000
3.8280 23.0000 1.0000
3.8340 27.1667 1.0000
3.8400 38.1667 1.0000
3.8460 36.0000 1.0000
3.8520 22.5000 1.0000
3.8580 26.1667 1.0000
3.8640 21.8333 1.0000
3.8700 24.6667 1.0000
3.8760 26.8333 1.0000
3.8820 30.3333 1.0000
3.8880 25.1667 1.0000
3.8940 21.3333 1.0000
3.9000 14.6667 1.0000
3.9060 16.5000 1.0000
3.9120 17.8333 1.0000
3.9180 24.8333 1.0000
3.9240 15.8333 1.0000
3.9300 21.6667 1.0000
3.9360 17.8333 1.0000
3.9420 26.1667 1.0000
3.9480 15.6667 1.0000
3.9540 21.5000 1.0000
3.9600 22.6667 1.0000
3.9660 25.3333 1.0000
3.9720 21.6667 1.0000
3.9780 23.1667 1.0000
3.9840 17.6667 1.0000
3.9900 21.0000 1.0000
3.9960 28.5000 1.0000
4.0020 25.1667 1.0000
4.0080 19.5000 1.0000
4.0140 15.0000 1.0000
4.0200 15.8333 1.0000
4.0260 16.8333 1.0000
4.0320 19.3333 1.0000
4.0380 32.0000 1.0000
4.0440 34.0000 1.0000
4.0500 14.0000 1.0000
4.0560 17.6667 1.0000
4.0620 17.1667 1.0000
4.0680 27.0000 1.0000
4.0740 33.8333 1.0000
4.0800 11.8333 1.0000
4.0860 10.1667 1.0000
4.0920 10.5000 1.0000
4.0980 15.3333 1.0000
4.1040 19.6667 1.0000
4.1100 16.6667 1.0000
4.1160 14.6667 1.0000
4.1220 19.5000 1.0000
4.1280 23.0000 1.0000
4.1340 19.0000 1.0000
4.1400 12.3333 1.0000
4.1460 15.1667 1.0000
4.1520 17.1667 1.0000
4.1580 13.6667 1.0000
4.1640 13.8333 1.0000
4.1700 16.0000 1.0000
4.1760 17.5000 1.0000
4.1820 12.8333 1.0000
4.1880 14.5000 1.0000
4.1940 11.8333 1.0000
4.2000 14.0000 1.0000
4.2060 18.5000 1.0000
4.2120 13.8333 1.0000
4.2180 19.3333 1.0000
4.2240 12.0000 1.0000
4.2300 19.1667 1.0000
4.2360 15.0000 1.0000
4.2420 13.3333 1.0000
4.2480 8.6667 1.0000
4.2540 11.8333 1.0000
4.2600 9.5000 1.0000
4.2660 15.3333 1.0000
4.2720 4.1667 1.0000
4.2780 9.8333 1.0000
4.2840 13.0000 1.0000
4.2900 10.5000 1.0000
4.2960 8.3333 1.0000
4.3020 12.0000 1.0000
4.3080 11.1667 1.0000
4.3140 14.5000 1.0000
4.3200 6.3333 1.0000
4.3260 9.6667 1.0000
4.3320 9.1667 1.0000
4.3380 18.0000 1.0000
4.3440 6.0000 1.0000
4.3500 9.8333 1.0000
4.3560 14.6667 1.0000
4.3620 10.0000 1.0000
4.3680 13.6667 1.0000
4.3740 11.3333 1.0000
4.3800 11.8333 1.0000
4.3860 12.1667 1.0000
4.3920 11.8333 1.0000
4.3980 11.0000 1.0000
4.4040 3.1667 1.0000
4.4100 11.0000 1.0000
4.4160 11.8333 1.0000
4.4220 11.3333 1.0000
4.4280 10.5000 1.0000
4.4340 9.3333 1.0000
4.4400 13.8333 1.0000
4.4460 15.8333 1.0000
4.4520 12.5000 1.0000
4.4580 2.8333 1.0000
4.4640 13.6667 1.0000
4.4700 14.0000 1.0000
4.4760 5.5000 1.0000
4.4820 12.3333 1.0000
4.4880 12.5000 1.0000
4.4940 12.0000 1.0000
4.5000 13.5000 1.0000
4.5060 9.3333 1.0000
4.5120 7.5000 1.0000
4.5180 11.5000 1.0000
4.5240 8.8333 1.0000
4.5300 0.6667 1.0000
4.5360 8.5000 1.0000
4.5420 6.8333 1.0000
4.5480 1.5000 1.0000
4.5540 3.6667 1.0000
4.5600 8.3333 1.0000
4.5660 13.5000 1.0000
4.5720 6.8333 1.0000
4.5780 4.6667 1.0000
4.5840 3.6667 1.0000
4.5900 3.6667 1.0000
4.5960 8.5000 1.0000
4.6020 4.8333 1.0000
4.6080 5.0000 1.0000
4.6140 5.6667 1.0000
4.6200 6.5000 1.0000
4.6260 10.1667 1.0000
4.6320 7.3333 1.0000
4.6380 7.6667 1.0000
4.6440 4.5000 1.0000
4.6500 5.1667 1.0000
4.6560 7.6667 1.0000
4.6620 9.5000 1.0000
4.6680 4.3333 1.0000
4.6740 7.8333 1.0000
4.6800 8.1667 1.0000
4.6860 8.6667 1.0000
4.6920 1.5000 1.0000
4.6980 5.5000 1.0000
4.7040 2.6667 1.0000
4.7100 5.5000 1.0000
4.7160 3.6667 1.0000
4.7220 6.6667 1.0000
4.7280 4.3333 1.0000
4.7340 8.0000 1.0000
4.7400 5.5000 1.0000
4.7460 10.3333 1.0000
4.7520 0.5000 1.0000
4.7580 10.6667 1.0000
4.7640 3.1667 1.0000
4.7700 4.3333 1.0000
4.7760 6.5000 1.0000
4.7820 5.6667 1.0000
4.7880 7.6667 1.0000
4.7940 5.5000 1.0000
4.8000 2.3333 1.0000
4.8060 2.3333 1.0000
4.8120 3.3333 1.0000
4.8180 3.5000 1.0000
4.8240 2.3333 1.0000
4.8300 4.3333 1.0000
4.8360 3.0000 1.0000
4.8420 2.6667 1.0000
4.8480 4.1667 1.0000
4.8540 7.3333 1.0000
4.8600 3.3333 1.0000
4.8660 2.1667 1.0000
4.8720 3.3333 1.0000
4.8780 5.5000 1.0000
4.8840 3.5000 1.0000
4.8900 2.1667 1.0000
4.8960 5.5000 1.0000
4.9020 2.3333 1.0000
4.9080 0.0000 1.0000
4.9140 6.5000 1.0000
4.9200 4.1667 1.0000
4.9260 1.5000 1.0000
4.9320 5.5000 1.0000
4.9380 8.5000 1.0000
4.9440 3.0000 1.0000
4.9500 6.3333 1.0000
4.9560 2.3333 1.0000
4.9620 6.1667 1.0000
4.9680 0.0000 1.0000
4.9740 4.0000 1.0000
4.9800 1.3333 1.0000
4.9860 0.0000 1.0000
4.9920 4.3333 1.0000
4.9980 6.5000 1.0000
5.0040 4.3333 1.0000
5.0100 2.5000 1.0000
5.0160 2.5000 1.0000
5.0220 1.1667 1.0000
5.0280 0.0000 1.0000
5.0340 3.5000 1.0000
5.0400 7.0000 1.0000
5.0460 2.0000 1.0000
5.0520 3.1667 1.0000
5.0580 3.5000 1.0000
5.0640 7.8333 1.0000
5.0700 3.5000 1.0000
5.0760 1.1667 1.0000
5.0820 4.0000 1.0000
5.0880 2.3333 1.0000
5.0940 2.0000 1.0000
5.1000 1.1667 1.0000
5.1060 0.0000 1.0000
5.1120 6.3333 1.0000
5.1180 2.1667 1.0000
5.1240 3.3333 1.0000
5.1300 4.3333 1.0000
5.1360 6.1667 1.0000
5.1420 1.5000 1.0000
5.1480 5.0000 1.0000
5.1540 4.6667 1.0000
5.1600 6.6667 1.0000
5.1660 7.3333 1.0000
5.1720 0.0000 1.0000
5.1780 0.0000 1.0000
5.1840 0.3333 1.0000
5.1900 2.3333 1.0000
5.1960 2.5000 1.0000
5.2020 0.0000 1.0000
5.2080 0.0000 1.0000
5.2140 3.0000 1.0000
5.2200 3.3333 1.0000
5.2260 0.0000 1.0000
5.2320 1.1667 1.0000
5.2380 2.0000 1.0000
5.2440 2.1667 1.0000
5.2500 2.1667 1.0000
5.2560 1.1667 1.0000
5.2620 2.1667 1.0000
5.2680 3.3333 1.0000
5.2740 0.0000 1.0000
5.2800 0.1667 1.0000
5.2860 3.0000 1.0000
5.2920 3.1667 1.0000
5.2980 3.1667 1.0000
5.3040 1.1667 1.0000
5.3100 0.1667 1.0000
5.3160 0.0000 1.0000
5.3220 0.1667 1.0000
5.3280 4.6667 1.0000
5.3340 2.1667 1.0000
5.3400 2.0000 1.0000
5.3460 0.1667 1.0000
5.3520 0.0000 1.0000
5.3580 1.1667 1.0000
5.3640 1.3333 1.0000
5.3700 0.1667 1.0000
5.3760 1.1667 1.0000
5.3820 2.3333 1.0000
5.3880 0.0000 1.0000
5.3940 0.1667 1.0000
5.4000 1.3333 1.0000
5.4060 0.1667 1.0000
5.4120 2.3333 1.0000
5.4180 0.0000 1.0000
5.4240 1.1667 1.0000
5.4300 0.1667 1.0000
5.4360 0.0000 1.0000
5.4420 3.1667 1.0000
5.4480 0.0000 1.0000
5.4540 0.0000 1.0000
5.4600 3.6667 1.0000
5.4660 0.0000 1.0000
5.4720 4.1667 1.0000
5.4780 2.1667 1.0000
5.4840 1.1667 1.0000
5.4900 0.0000 1.0000
5.4960 0.0000 1.0000
5.5020 0.0000 1.0000
5.5080 0.0000 1.0000
5.5140 0.0000 1.0000
5.5200 1.3333 1.0000
5.5260 0.0000 1.0000
5.5320 2.0000 1.0000
5.5380 3.3333 1.0000
5.5440 4.0000 1.0000
5.5500 0.0000 1.0000
5.5560 1.3333 1.0000
5.5620 0.0000 1.0000
5.5680 0.0000 1.0000
5.5740 0.0000 1.0000
5.5800 3.0000 1.0000
5.5860 2.1667 1.0000
5.5920 2.5000 1.0000
5.5980 1.1667 1.0000
5.6040 1.1667 1.0000
5.6100 3.0000 1.0000
5.6160 3.0000 1.0000
5.6220 3.0000 1.0000
5.6280 0.0000 1.0000
5.6340 1.1667 1.0000
5.6400 0.0000 1.0000
5.6460 0.0000 1.0000
5.6520 0.1667 1.0000
5.6580 0.0000 1.0000
5.6640 0.0000 1.0000
5.6700 0.0000 1.0000
5.6760 0.0000 1.0000
5.6820 2.0000 1.0000
5.6880 0.0000 1.0000
5.6940 0.0000 1.0000
5.7000 1.1667 1.0000
5.7060 0.1667 1.0000
5.7120 0.0000 1.0000
5.7180 0.0000 1.0000
5.7240 0.0000 1.0000
5.7300 0.0000 1.0000
5.7360 2.0000 1.0000
5.7420 1.1667 1.0000
5.7480 0.0000 1.0000
5.7540 0.0000 1.0000
5.7600 1.1667 1.0000
5.7660 0.0000 1.0000
5.7720 2.0000 1.0000
5.7780 4.0000 1.0000
5.7840 2.0000 1.0000
5.7900 0.1667 1.0000
5.7960 0.0000 1.0000
5.8020 0.0000 1.0000
5.8080 3.0000 1.0000
5.8140 0.0000 1.0000
5.8200 0.1667 1.0000
5.8260 0.0000 1.0000
5.8320 1.1667 1.0000
5.8380 0.0000 1.0000
5.8440 0.0000 1.0000
5.8500 0.0000 1.0000
5.8560 3.0000 1.0000
5.8620 0.0000 1.0000
5.8680 0.0000 1.0000
5.8740 2.3333 1.0000
5.8800 1.1667 1.0000
5.8860 0.5000 1.0000
5.8920 0.0000 1.0000
5.8980 0.0000 1.0000
5.9040 0.0000 1.0000
5.9100 0.0000 1.0000
5.9160 0.0000 1.0000
5.9220 0.0000 1.0000
5.9280 0.0000 1.0000
5.9340 1.1667 1.0000
5.9400 0.0000 1.0000
5.9460 0.0000 1.0000
5.9520 1.1667 1.0000
5.9580 0.0000 1.0000
5.9640 0.0000 1.0000
5.9700 0.0000 1.0000
5.9760 0.0000 1.0000
5.9820 0.0000 1.0000
5.9880 0.0000 1.0000
5.9940 0.0000 1.0000
6.0000 0.0000 1.0000
*RAS_INT_END
*RAS_DATA_END