File: xrr_temp/CWOI11_reflectivity.ras
*RAS_DATA_START
*RAS_HEADER_START
*DISP_FMT_X "%.4f"
*DISP_FMT_Y "%.0f"
*DISP_FULLSCALE "695501655.2931908400"
*DISP_LINE_COLOR "255.0000000000"
*DISP_LINE_STYLE "0.0000000000"
*DISP_LINE_WIDTH "0.2500000000"
*DISP_NOTE "Collected Data-18"
*DISP_OFFSET_Y "0.0000000000"
*DISP_PEAKSEARCH_UNIT_Y "cps"
*DISP_RANGE_BOTTOM "0.0100000000"
*DISP_RANGE_LEFT "-0.0006000000"
*DISP_RANGE_LOGCUTOFF "0.0100000000"
*DISP_RANGE_RIGHT "85.0000000000"
*DISP_RANGE_TOP "695501655.2931908400"
*DISP_SCALE_MODE_Y "2.0000000000"
*DISP_TAB_NAME "2-Theta/Omega"
*DISP_TITLE_Y "Intensity"
*DISP_UNIT_Y "cps"
*DISP_WINDOW_NAME "MSG_MACROENGINE"
*FILE_COMMENT " "
*FILE_MD5 ""
*FILE_MEMO " "
*FILE_OPERATOR "Administrator"
*FILE_PART_ID "MEAS_KHP2_00055"
*FILE_SAMPLE "CWOI11"
*FILE_TYPE "RAS_RAW"
*FILE_USERGROUP "System Manager"
*FILE_VERSION "1.0000000000"
*HW_ATTACHMENT_ID "ATT0025"
*HW_ATTACHMENT_NAME "標準|Standard"
*HW_COUNTER_ID-0 "CUT0025"
*HW_COUNTER_ID-1 "CUT0020"
*HW_COUNTER_ID-2 "CUT0020"
*HW_COUNTER_ID-3 "CSL0021"
*HW_COUNTER_ID-4 "CMC0021"
*HW_COUNTER_NAME-0 "D/teX Ultra|D/teX Ultra"
*HW_COUNTER_NAME-1 "None|None"
*HW_COUNTER_NAME-2 "None|None"
*HW_COUNTER_NAME-3 "BBM|BBM"
*HW_COUNTER_NAME-4 "検出器モノクロメータ|Detector monochromator"
*HW_COUNTER_SELECT_NAME "D/teX Ultra|D/teX Ultra"
*HW_GONIOMETER_ID "GON0023"
*HW_GONIOMETER_NAME "SmartLab|SmartLab"
*HW_GONIOMETER_RADIUS-0 "90.0"
*HW_GONIOMETER_RADIUS-1 "114.0"
*HW_GONIOMETER_RADIUS-2 "190.0"
*HW_GONIOMETER_RADIUS-3 "300.0"
*HW_GONIOMETER_RADIUS-4 "187.0"
*HW_GONIOMETER_RADIUS-5 "300.0"
*HW_GONIOMETER_RADIUS-6 "113.0"
*HW_GONIOMETER_RADIUS-7 "331.0"
*HW_I_OPT_ID-0 "CBO0021"
*HW_I_OPT_ID-1 "ICR0021"
*HW_I_OPT_ID-2 "ISL0021"
*HW_I_OPT_ID-3 "ISO0021"
*HW_I_OPT_ID-4 "IAD0021"
*HW_I_OPT_ID-5 "IPR0001"
*HW_I_OPT_NAME-0 "CBOユニット|CBO unit"
*HW_I_OPT_NAME-1 "標準入射光学ユニット|Standard incident optical unit"
*HW_I_OPT_NAME-2 "標準入射スリットボックス|Standard incident slit box"
*HW_I_OPT_NAME-3 "入射平行スリット|Incident parallel slit"
*HW_I_OPT_NAME-4 "長手制限スリット|Length limiting slit"
*HW_I_OPT_NAME-5 "None|None"
*HW_R_ATTENUATER_AUTOMODE "1"
*HW_R_OPT_ID-0 "RSS0021"
*HW_R_OPT_ID-1 "RCR0023"
*HW_R_OPT_ID-2 "RSO0021"
*HW_R_OPT_ID-3 "RRS0021"
*HW_R_OPT_ID-4 "ATN0021"
*HW_R_OPT_ID-5 "RFL0021"
*HW_R_OPT_ID-6 "RAD0021"
*HW_R_OPT_NAME-0 "標準受光スリットボックス1|Standard receiving slit box # 1"
*HW_R_OPT_NAME-1 "標準受光光学ユニット1|Standard receiving unit # 1"
*HW_R_OPT_NAME-2 "標準受光光学ユニット2|Standard receiving optical unit # 2"
*HW_R_OPT_NAME-3 "標準受光スリットボックス2|Standard receiving slit box # 2"
*HW_R_OPT_NAME-4 "標準アッテネータ|Standard Attenuator"
*HW_R_OPT_NAME-5 "Cu Kβ|Cu K-beta"
*HW_R_OPT_NAME-6 "調整用受光スリット|Alignment receiving slit"
*HW_SAMPLE_HOLDER_ID "SMP0021"
*HW_SAMPLE_HOLDER_NAME "χφZクレードル|Chi phi Z cradle"
*HW_XG_CURRENT_MAX "200"
*HW_XG_CURRENT_MIN "10"
*HW_XG_CURRENT_RESOLUTION "1"
*HW_XG_CURRENT_UNIT "mA"
*HW_XG_FOCUS "0.4mm x 8mm"
*HW_XG_FOCUS_TYPE "Normal"
*HW_XG_ID "1700"
*HW_XG_NAME "9kW 開放管(45kV 200mA ID:1700)|9kW Rotating anode(45kV 200mA ID:1700)"
*HW_XG_TARGET_ATOMIC_NUMBER "29.0000000000"
*HW_XG_TARGET_NAME "Cu"
*HW_XG_TYPE "Rota"
*HW_XG_VOLTAGE_MAX "45"
*HW_XG_VOLTAGE_MIN "20"
*HW_XG_VOLTAGE_RESOLUTION "1"
*HW_XG_VOLTAGE_UNIT "kV"
*HW_XG_WATT_MAX "9.00"
*HW_XG_WATT_UNIT "kW"
*HW_XG_WAVE_LENGTH_ALPHA1 "1.540593"
*HW_XG_WAVE_LENGTH_ALPHA2 "1.544414"
*HW_XG_WAVE_LENGTH_BETA "1.392250"
*MEAS_COND_AXIS_NAME-0 "Theta/2-Theta"
*MEAS_COND_AXIS_NAME-1 "2-Theta"
*MEAS_COND_AXIS_NAME-2 "Omega"
*MEAS_COND_AXIS_NAME-3 "Chi"
*MEAS_COND_AXIS_NAME-4 "Phi"
*MEAS_COND_AXIS_NAME-5 "Z"
*MEAS_COND_AXIS_NAME-6 "2-Theta/Omega"
*MEAS_COND_AXIS_NAME-7 "Theta_s"
*MEAS_COND_AXIS_NAME-8 "Theta_d"
*MEAS_COND_AXIS_NAME-9 "Ts"
*MEAS_COND_AXIS_NAME-10 "CBO selection slit"
*MEAS_COND_AXIS_NAME-11 "M"
*MEAS_COND_AXIS_NAME-12 "Incident parallel slit"
*MEAS_COND_AXIS_NAME-13 "Incident slit"
*MEAS_COND_AXIS_NAME-14 ""
*MEAS_COND_AXIS_NAME-15 "Zs"
*MEAS_COND_AXIS_NAME-16 "Incident optical device"
*MEAS_COND_AXIS_NAME-17 "Omega_m"
*MEAS_COND_AXIS_NAME-18 "Length limiting slit"
*MEAS_COND_AXIS_NAME-19 "Center slit"
*MEAS_COND_AXIS_NAME-20 "Filter"
*MEAS_COND_AXIS_NAME-21 "Receiving slit # 1"
*MEAS_COND_AXIS_NAME-22 "Receiving slit # 2"
*MEAS_COND_AXIS_NAME-23 "Receiving optical device"
*MEAS_COND_AXIS_NAME-24 "Receiving parallel slit"
*MEAS_COND_AXIS_NAME-25 "Alignment receiving slit"
*MEAS_COND_AXIS_NAME-26 ""
*MEAS_COND_AXIS_NAME-27 ""
*MEAS_COND_AXIS_NAME-28 "Zd"
*MEAS_COND_AXIS_NAME-29 "Attenuator"
*MEAS_COND_AXIS_NAME-30 "Diffracted beam monochromator"
*MEAS_COND_AXIS_NAME-31 "Monochromator slit"
*MEAS_COND_AXIS_NAME-32 "Primary beam"
*MEAS_COND_AXIS_NAME-33 ""
*MEAS_COND_AXIS_NAME-34 ""
*MEAS_COND_AXIS_NAME-35 "PHA"
*MEAS_COND_AXIS_NAME_INTERNAL-0 "TwoThetaTheta"
*MEAS_COND_AXIS_NAME_INTERNAL-1 "TwoTheta"
*MEAS_COND_AXIS_NAME_INTERNAL-2 "Omega"
*MEAS_COND_AXIS_NAME_INTERNAL-3 "Chi"
*MEAS_COND_AXIS_NAME_INTERNAL-4 "Phi"
*MEAS_COND_AXIS_NAME_INTERNAL-5 "Z"
*MEAS_COND_AXIS_NAME_INTERNAL-6 "TwoThetaOmega"
*MEAS_COND_AXIS_NAME_INTERNAL-7 "ThetaS"
*MEAS_COND_AXIS_NAME_INTERNAL-8 "ThetaD"
*MEAS_COND_AXIS_NAME_INTERNAL-9 "Ts"
*MEAS_COND_AXIS_NAME_INTERNAL-10 "CBO"
*MEAS_COND_AXIS_NAME_INTERNAL-11 "CBO-M"
*MEAS_COND_AXIS_NAME_INTERNAL-12 "IncidentSollerSlit"
*MEAS_COND_AXIS_NAME_INTERNAL-13 "IncidentSlitBox"
*MEAS_COND_AXIS_NAME_INTERNAL-14 "IncidentSlitBox-_Axis"
*MEAS_COND_AXIS_NAME_INTERNAL-15 "Zs"
*MEAS_COND_AXIS_NAME_INTERNAL-16 "IncidentMonochromator"
*MEAS_COND_AXIS_NAME_INTERNAL-17 "IncidentMonochromator-OmegaM"
*MEAS_COND_AXIS_NAME_INTERNAL-18 "IncidentAxdSlit"
*MEAS_COND_AXIS_NAME_INTERNAL-19 "CenterSlit"
*MEAS_COND_AXIS_NAME_INTERNAL-20 "Filter"
*MEAS_COND_AXIS_NAME_INTERNAL-21 "ReceivingSlitBox1"
*MEAS_COND_AXIS_NAME_INTERNAL-22 "ReceivingSlitBox2"
*MEAS_COND_AXIS_NAME_INTERNAL-23 "ReceivingOptics"
*MEAS_COND_AXIS_NAME_INTERNAL-24 "ReceivingSollerSlit"
*MEAS_COND_AXIS_NAME_INTERNAL-25 "ReceivingAxdSlit"
*MEAS_COND_AXIS_NAME_INTERNAL-26 "ReceivingSlitBox1-_Axis"
*MEAS_COND_AXIS_NAME_INTERNAL-27 "ReceivingSlitBox2-_Axis"
*MEAS_COND_AXIS_NAME_INTERNAL-28 "ReceivingSlitBox2-Zd"
*MEAS_COND_AXIS_NAME_INTERNAL-29 "Attenuator"
*MEAS_COND_AXIS_NAME_INTERNAL-30 "CounterMonochromator"
*MEAS_COND_AXIS_NAME_INTERNAL-31 "CounterSlit"
*MEAS_COND_AXIS_NAME_INTERNAL-32 "IncidentPrimary"
*MEAS_COND_AXIS_NAME_INTERNAL-33 "AlphaR"
*MEAS_COND_AXIS_NAME_INTERNAL-34 "BetaR"
*MEAS_COND_AXIS_NAME_INTERNAL-35 "PHA"
*MEAS_COND_AXIS_NAME_MAGICNO-0 "83951616.0000000000"
*MEAS_COND_AXIS_NAME_MAGICNO-1 "268632064.0000000000"
*MEAS_COND_AXIS_NAME_MAGICNO-2 "268500992.0000000000"
*MEAS_COND_AXIS_NAME_MAGICNO-3 "268500992.0000000000"
*MEAS_COND_AXIS_NAME_MAGICNO-4 "268500992.0000000000"
*MEAS_COND_AXIS_NAME_MAGICNO-5 "285278208.0000000000"
*MEAS_COND_AXIS_NAME_MAGICNO-6 "83951616.0000000000"
*MEAS_COND_AXIS_NAME_MAGICNO-7 "131072.0000000000"
*MEAS_COND_AXIS_NAME_MAGICNO-8 "131072.0000000000"
*MEAS_COND_AXIS_NAME_MAGICNO-9 "318898176.0000000000"
*MEAS_COND_AXIS_NAME_MAGICNO-10 "20971521.0000000000"
*MEAS_COND_AXIS_NAME_MAGICNO-11 "285343744.0000000000"
*MEAS_COND_AXIS_NAME_MAGICNO-12 "20971521.0000000000"
*MEAS_COND_AXIS_NAME_MAGICNO-13 "22020097.0000000000"
*MEAS_COND_AXIS_NAME_MAGICNO-14 "25165824.0000000000"
*MEAS_COND_AXIS_NAME_MAGICNO-15 "318898176.0000000000"
*MEAS_COND_AXIS_NAME_MAGICNO-16 "20971521.0000000000"
*MEAS_COND_AXIS_NAME_MAGICNO-17 "285343744.0000000000"
*MEAS_COND_AXIS_NAME_MAGICNO-18 "20971521.0000000000"
*MEAS_COND_AXIS_NAME_MAGICNO-19 "20971521.0000000000"
*MEAS_COND_AXIS_NAME_MAGICNO-20 "20971521.0000000000"
*MEAS_COND_AXIS_NAME_MAGICNO-21 "23068673.0000000000"
*MEAS_COND_AXIS_NAME_MAGICNO-22 "23068673.0000000000"
*MEAS_COND_AXIS_NAME_MAGICNO-23 "20971521.0000000000"
*MEAS_COND_AXIS_NAME_MAGICNO-24 "20971521.0000000000"
*MEAS_COND_AXIS_NAME_MAGICNO-25 "20971521.0000000000"
*MEAS_COND_AXIS_NAME_MAGICNO-26 "25165824.0000000000"
*MEAS_COND_AXIS_NAME_MAGICNO-27 "25165824.0000000000"
*MEAS_COND_AXIS_NAME_MAGICNO-28 "285343744.0000000000"
*MEAS_COND_AXIS_NAME_MAGICNO-29 "17301505.0000000000"
*MEAS_COND_AXIS_NAME_MAGICNO-30 "20971521.0000000000"
*MEAS_COND_AXIS_NAME_MAGICNO-31 "20971521.0000000000"
*MEAS_COND_AXIS_NAME_MAGICNO-32 "20971521.0000000000"
*MEAS_COND_AXIS_NAME_MAGICNO-33 "8388608.0000000000"
*MEAS_COND_AXIS_NAME_MAGICNO-34 "8388608.0000000000"
*MEAS_COND_AXIS_NAME_MAGICNO-35 "0.0000000000"
*MEAS_COND_AXIS_OFFSET-0 "-"
*MEAS_COND_AXIS_OFFSET-1 "0.8864000000"
*MEAS_COND_AXIS_OFFSET-2 "0.4222000000"
*MEAS_COND_AXIS_OFFSET-3 "0.0000000000"
*MEAS_COND_AXIS_OFFSET-4 "0.0000000000"
*MEAS_COND_AXIS_OFFSET-5 "-"
*MEAS_COND_AXIS_OFFSET-6 "-"
*MEAS_COND_AXIS_OFFSET-7 "0.4222000000"
*MEAS_COND_AXIS_OFFSET-8 "0.4642000000"
*MEAS_COND_AXIS_OFFSET-9 "-"
*MEAS_COND_AXIS_OFFSET-10 "-"
*MEAS_COND_AXIS_OFFSET-11 "-"
*MEAS_COND_AXIS_OFFSET-12 "-"
*MEAS_COND_AXIS_OFFSET-13 "-"
*MEAS_COND_AXIS_OFFSET-14 "-"
*MEAS_COND_AXIS_OFFSET-15 "-"
*MEAS_COND_AXIS_OFFSET-16 "-"
*MEAS_COND_AXIS_OFFSET-17 "-"
*MEAS_COND_AXIS_OFFSET-18 "-"
*MEAS_COND_AXIS_OFFSET-19 "-"
*MEAS_COND_AXIS_OFFSET-20 "-"
*MEAS_COND_AXIS_OFFSET-21 "-"
*MEAS_COND_AXIS_OFFSET-22 "-"
*MEAS_COND_AXIS_OFFSET-23 "-"
*MEAS_COND_AXIS_OFFSET-24 "-"
*MEAS_COND_AXIS_OFFSET-25 "-"
*MEAS_COND_AXIS_OFFSET-26 "-"
*MEAS_COND_AXIS_OFFSET-27 "-"
*MEAS_COND_AXIS_OFFSET-28 "-"
*MEAS_COND_AXIS_OFFSET-29 "-"
*MEAS_COND_AXIS_OFFSET-30 "-"
*MEAS_COND_AXIS_OFFSET-31 "-"
*MEAS_COND_AXIS_OFFSET-32 "-"
*MEAS_COND_AXIS_OFFSET-33 "0.0000000000"
*MEAS_COND_AXIS_OFFSET-34 "0.0000000000"
*MEAS_COND_AXIS_OFFSET-35 "-"
*MEAS_COND_AXIS_POSITION-0 "-0.0008000000"
*MEAS_COND_AXIS_POSITION-1 "-0.0008000000"
*MEAS_COND_AXIS_POSITION-2 "-0.0004000000"
*MEAS_COND_AXIS_POSITION-3 "0.0000000000"
*MEAS_COND_AXIS_POSITION-4 "0.0000000000"
*MEAS_COND_AXIS_POSITION-5 "-1.4199000000"
*MEAS_COND_AXIS_POSITION-6 "-0.0008000000"
*MEAS_COND_AXIS_POSITION-7 "-0.0004000000"
*MEAS_COND_AXIS_POSITION-8 "-0.0004000000"
*MEAS_COND_AXIS_POSITION-9 "-4.7346300000"
*MEAS_COND_AXIS_POSITION-10 "PB"
*MEAS_COND_AXIS_POSITION-11 "0.0000000000"
*MEAS_COND_AXIS_POSITION-12 "Soller_slit_open_s"
*MEAS_COND_AXIS_POSITION-13 "0.250mm"
*MEAS_COND_AXIS_POSITION-14 "0.2500000000"
*MEAS_COND_AXIS_POSITION-15 "-1.7618800000"
*MEAS_COND_AXIS_POSITION-16 "Ge(220)x2"
*MEAS_COND_AXIS_POSITION-17 "0.0000000000"
*MEAS_COND_AXIS_POSITION-18 "2.0mm"
*MEAS_COND_AXIS_POSITION-19 "None"
*MEAS_COND_AXIS_POSITION-20 "None"
*MEAS_COND_AXIS_POSITION-21 "0.250mm"
*MEAS_COND_AXIS_POSITION-22 "0.250mm"
*MEAS_COND_AXIS_POSITION-23 "No_unit"
*MEAS_COND_AXIS_POSITION-24 "Soller_slit_5.0deg"
*MEAS_COND_AXIS_POSITION-25 "None"
*MEAS_COND_AXIS_POSITION-26 "0.2500000000"
*MEAS_COND_AXIS_POSITION-27 "0.2500000000"
*MEAS_COND_AXIS_POSITION-28 "0.0903100000"
*MEAS_COND_AXIS_POSITION-29 "1/10000"
*MEAS_COND_AXIS_POSITION-30 "None"
*MEAS_COND_AXIS_POSITION-31 "None"
*MEAS_COND_AXIS_POSITION-32 "None"
*MEAS_COND_AXIS_POSITION-33 "0.0000000000"
*MEAS_COND_AXIS_POSITION-34 "0.0000000000"
*MEAS_COND_AXIS_POSITION-35 "34.0000000000"
*MEAS_COND_AXIS_UNIT-0 "deg"
*MEAS_COND_AXIS_UNIT-1 "deg"
*MEAS_COND_AXIS_UNIT-2 "deg"
*MEAS_COND_AXIS_UNIT-3 "deg"
*MEAS_COND_AXIS_UNIT-4 "deg"
*MEAS_COND_AXIS_UNIT-5 "mm"
*MEAS_COND_AXIS_UNIT-6 "deg"
*MEAS_COND_AXIS_UNIT-7 "deg"
*MEAS_COND_AXIS_UNIT-8 "deg"
*MEAS_COND_AXIS_UNIT-9 "mm"
*MEAS_COND_AXIS_UNIT-10 ""
*MEAS_COND_AXIS_UNIT-11 "pulse"
*MEAS_COND_AXIS_UNIT-12 ""
*MEAS_COND_AXIS_UNIT-13 ""
*MEAS_COND_AXIS_UNIT-14 "mm"
*MEAS_COND_AXIS_UNIT-15 "mm"
*MEAS_COND_AXIS_UNIT-16 ""
*MEAS_COND_AXIS_UNIT-17 "pulse"
*MEAS_COND_AXIS_UNIT-18 ""
*MEAS_COND_AXIS_UNIT-19 ""
*MEAS_COND_AXIS_UNIT-20 ""
*MEAS_COND_AXIS_UNIT-21 ""
*MEAS_COND_AXIS_UNIT-22 ""
*MEAS_COND_AXIS_UNIT-23 ""
*MEAS_COND_AXIS_UNIT-24 ""
*MEAS_COND_AXIS_UNIT-25 ""
*MEAS_COND_AXIS_UNIT-26 "mm"
*MEAS_COND_AXIS_UNIT-27 "mm"
*MEAS_COND_AXIS_UNIT-28 "mm"
*MEAS_COND_AXIS_UNIT-29 ""
*MEAS_COND_AXIS_UNIT-30 ""
*MEAS_COND_AXIS_UNIT-31 ""
*MEAS_COND_AXIS_UNIT-32 ""
*MEAS_COND_AXIS_UNIT-33 "deg"
*MEAS_COND_AXIS_UNIT-34 "deg"
*MEAS_COND_AXIS_UNIT-35 "div"
*MEAS_COND_COUNTER_CNTLOSS_CORR "0.0000000000"
*MEAS_COND_COUNTER_PHABASE "34.0000000000"
*MEAS_COND_COUNTER_PHAWINDOW "19.0000000000"
*MEAS_COND_COUNTER_PHA_UNIT "div"
*MEAS_COND_COUNTER_TAUDIFF "2.0000000000"
*MEAS_COND_COUNTER_TAUINT "0.1000000000"
*MEAS_COND_IRRADIATION_MODE "OFF"
*MEAS_COND_IRRADIATION_WIDTH ""
*MEAS_COND_OPT_ATTR "High resolution parallel beam Ge(220)x2/RS"
*MEAS_COND_OPT_NAME "@High resolution PB-Ge(220)x2"
*MEAS_COND_UNSYMMETRIC_MODE "OFF"
*MEAS_COND_XG_CURRENT "200.0000000000"
*MEAS_COND_XG_VOLTAGE "45.0000000000"
*MEAS_COND_XG_WAVE_TYPE "Ka1"
*MEAS_DATA_COUNT "3001.0000000000"
*MEAS_SCAN_AXIS_X "2-Theta/Omega"
*MEAS_SCAN_AXIS_X_INTERNAL "TwoThetaOmega"
*MEAS_SCAN_END_TIME "11/21/23 14:32:50"
*MEAS_SCAN_MODE "CONTINUOUS"
*MEAS_SCAN_MONITOR "0"
*MEAS_SCAN_RESOLUTION_X "0.0002"
*MEAS_SCAN_SPEED "0.500000"
*MEAS_SCAN_SPEED_UNIT "deg/min"
*MEAS_SCAN_SPEED_USER "0.500000"
*MEAS_SCAN_START "0.0000000000"
*MEAS_SCAN_START_TIME "11/21/23 14:20:19"
*MEAS_SCAN_STEP "0.0020000000"
*MEAS_SCAN_STOP "6.0000000000"
*MEAS_SCAN_UNIT_X "deg"
*MEAS_SCAN_UNIT_Y "counts"
*RAS_HEADER_END
*RAS_INT_START
0.0000 5239975.5000 1.0000
0.0060 5530296.0000 1.0000
0.0120 5394997.0000 1.0000
0.0180 5345346.0000 1.0000
0.0240 5090746.5000 1.0000
0.0300 4983445.5000 1.0000
0.0360 4521553.0000 1.0000
0.0420 3771960.2500 1.0000
0.0480 2810799.5000 1.0000
0.0540 1921080.7500 1.0000
0.0600 1142990.8750 1.0000
0.0660 611800.1250 1.0000
0.0720 291168.4688 1.0000
0.0780 161213.2813 1.0000
0.0840 110576.2500 1.0000
0.0900 85335.9375 1.0000
0.0960 75907.1250 1.0000
0.1020 76905.1250 1.0000
0.1080 78528.7266 1.0000
0.1140 76949.8125 1.0000
0.1200 83868.7344 1.0000
0.1260 86460.5391 1.0000
0.1320 93811.4375 1.0000
0.1380 97639.5625 1.0000
0.1440 96671.3594 1.0000
0.1500 100924.0078 1.0000
0.1560 104290.3750 1.0000
0.1620 111730.6484 1.0000
0.1680 112750.9844 1.0000
0.1740 116050.3203 1.0000
0.1800 123073.5156 1.0000
0.1860 124764.1563 1.0000
0.1920 133299.2344 1.0000
0.1980 138713.7188 1.0000
0.2040 138862.6719 1.0000
0.2100 144612.3125 1.0000
0.2160 146734.9219 1.0000
0.2220 149468.2344 1.0000
0.2280 150615.1719 1.0000
0.2340 158740.6406 1.0000
0.2400 164840.3125 1.0000
0.2460 164147.6719 1.0000
0.2520 169644.0938 1.0000
0.2580 172012.4688 1.0000
0.2640 175959.7500 1.0000
0.2700 183370.2344 1.0000
0.2760 188821.9531 1.0000
0.2820 190006.1406 1.0000
0.2880 192456.4531 1.0000
0.2940 193767.2500 1.0000
0.3000 196187.7500 1.0000
0.3060 204968.6094 1.0000
0.3120 201066.0000 1.0000
0.3180 206271.9531 1.0000
0.3240 217666.9688 1.0000
0.3300 216840.2656 1.0000
0.3360 221048.2344 1.0000
0.3420 219938.5156 1.0000
0.3480 219543.7813 1.0000
0.3540 226760.6250 1.0000
0.3600 235169.0938 1.0000
0.3660 230529.1719 1.0000
0.3720 240002.6719 1.0000
0.3780 248210.0469 1.0000
0.3840 246519.4219 1.0000
0.3900 249409.1406 1.0000
0.3960 248962.2813 1.0000
0.4020 257050.4844 1.0000
0.4080 257124.9688 1.0000
0.4140 258904.9688 1.0000
0.4200 267953.9375 1.0000
0.4260 269421.1563 1.0000
0.4320 277136.9688 1.0000
0.4380 273912.1250 1.0000
0.4440 273725.9375 1.0000
0.4500 287288.2188 1.0000
0.4560 281620.5000 1.0000
0.4620 287392.5000 1.0000
0.4680 282149.2813 1.0000
0.4740 291161.0313 1.0000
0.4800 295532.8438 1.0000
0.4860 300522.8125 1.0000
0.4920 298407.6563 1.0000
0.4980 305877.7188 1.0000
0.5040 306786.3438 1.0000
0.5100 309303.6875 1.0000
0.5160 312580.6563 1.0000
0.5220 316796.0625 1.0000
0.5280 312528.5313 1.0000
0.5340 319164.4375 1.0000
0.5400 313206.2813 1.0000
0.5460 318069.6250 1.0000
0.5520 314770.3125 1.0000
0.5580 323327.7188 1.0000
0.5640 324243.7813 1.0000
0.5700 329278.4688 1.0000
0.5760 328809.2500 1.0000
0.5820 324214.0000 1.0000
0.5880 323662.8750 1.0000
0.5940 326872.8438 1.0000
0.6000 328645.4063 1.0000
0.6060 321190.2188 1.0000
0.6120 320333.7500 1.0000
0.6180 314613.9063 1.0000
0.6240 311686.9375 1.0000
0.6300 301803.8125 1.0000
0.6360 297960.8125 1.0000
0.6420 287675.5000 1.0000
0.6480 282320.5938 1.0000
0.6540 269547.7500 1.0000
0.6600 249245.2813 1.0000
0.6660 237254.4688 1.0000
0.6720 223185.7344 1.0000
0.6780 209154.2344 1.0000
0.6840 191830.8438 1.0000
0.6900 172868.9531 1.0000
0.6960 160758.9688 1.0000
0.7020 151307.8125 1.0000
0.7080 133053.4531 1.0000
0.7140 122425.5703 1.0000
0.7200 109689.9688 1.0000
0.7260 102800.8359 1.0000
0.7320 92545.3281 1.0000
0.7380 86073.2656 1.0000
0.7440 78618.1016 1.0000
0.7500 70306.4453 1.0000
0.7560 65368.6094 1.0000
0.7620 62113.9570 1.0000
0.7680 56140.8867 1.0000
0.7740 54696.3320 1.0000
0.7800 51625.5000 1.0000
0.7860 48652.8320 1.0000
0.7920 46393.1680 1.0000
0.7980 43629.6680 1.0000
0.8040 42301.8320 1.0000
0.8100 40242.6680 1.0000
0.8160 38925.6680 1.0000
0.8220 37731.5000 1.0000
0.8280 36100.3320 1.0000
0.8340 34974.0000 1.0000
0.8400 33907.3320 1.0000
0.8460 32324.0000 1.0000
0.8520 31142.3340 1.0000
0.8580 30246.3340 1.0000
0.8640 29499.3340 1.0000
0.8700 28606.1660 1.0000
0.8760 27355.5000 1.0000
0.8820 26213.5000 1.0000
0.8880 25582.3340 1.0000
0.8940 24568.3340 1.0000
0.9000 23786.3340 1.0000
0.9060 22811.1660 1.0000
0.9120 21989.0000 1.0000
0.9180 21175.1660 1.0000
0.9240 20087.1660 1.0000
0.9300 19478.5000 1.0000
0.9360 18423.8340 1.0000
0.9420 17992.5000 1.0000
0.9480 17203.6660 1.0000
0.9540 16422.0000 1.0000
0.9600 15829.8330 1.0000
0.9660 15426.1670 1.0000
0.9720 14790.1670 1.0000
0.9780 14285.3330 1.0000
0.9840 13868.6670 1.0000
0.9900 13307.0000 1.0000
0.9960 12738.6670 1.0000
1.0020 12470.3330 1.0000
1.0080 12057.5000 1.0000
1.0140 11737.8330 1.0000
1.0200 11624.0000 1.0000
1.0260 11074.5000 1.0000
1.0320 10944.6670 1.0000
1.0380 10817.6670 1.0000
1.0440 10367.1670 1.0000
1.0500 10197.3330 1.0000
1.0560 10143.5000 1.0000
1.0620 9817.6670 1.0000
1.0680 9644.3330 1.0000
1.0740 9534.3330 1.0000
1.0800 9333.3330 1.0000
1.0860 8925.0000 1.0000
1.0920 8785.1670 1.0000
1.0980 8814.3330 1.0000
1.1040 8730.0000 1.0000
1.1100 8365.1670 1.0000
1.1160 8272.0000 1.0000
1.1220 8026.1665 1.0000
1.1280 7886.5000 1.0000
1.1340 7906.6665 1.0000
1.1400 7623.1665 1.0000
1.1460 7606.3335 1.0000
1.1520 7220.3335 1.0000
1.1580 7107.5000 1.0000
1.1640 6942.3335 1.0000
1.1700 6870.3335 1.0000
1.1760 6697.6665 1.0000
1.1820 6503.5000 1.0000
1.1880 6301.1665 1.0000
1.1940 6187.3335 1.0000
1.2000 5974.5000 1.0000
1.2060 5801.3335 1.0000
1.2120 5742.3335 1.0000
1.2180 5496.0000 1.0000
1.2240 5414.1665 1.0000
1.2300 5332.8335 1.0000
1.2360 5076.0000 1.0000
1.2420 4955.8335 1.0000
1.2480 4930.6665 1.0000
1.2540 4685.1665 1.0000
1.2600 4628.8335 1.0000
1.2660 4445.5000 1.0000
1.2720 4413.5000 1.0000
1.2780 4372.1665 1.0000
1.2840 4184.5000 1.0000
1.2900 4079.8333 1.0000
1.2960 3975.0000 1.0000
1.3020 4046.6667 1.0000
1.3080 3882.1667 1.0000
1.3140 3807.6667 1.0000
1.3200 3626.3333 1.0000
1.3260 3745.8333 1.0000
1.3320 3682.3333 1.0000
1.3380 3576.1667 1.0000
1.3440 3477.5000 1.0000
1.3500 3457.0000 1.0000
1.3560 3486.3333 1.0000
1.3620 3405.1667 1.0000
1.3680 3324.5000 1.0000
1.3740 3150.0000 1.0000
1.3800 3269.6667 1.0000
1.3860 3194.6667 1.0000
1.3920 3178.0000 1.0000
1.3980 3102.5000 1.0000
1.4040 3123.3333 1.0000
1.4100 3045.3333 1.0000
1.4160 2950.8333 1.0000
1.4220 3021.5000 1.0000
1.4280 2957.5000 1.0000
1.4340 2921.8333 1.0000
1.4400 2784.5000 1.0000
1.4460 2750.6667 1.0000
1.4520 2770.5000 1.0000
1.4580 2807.8333 1.0000
1.4640 2643.8333 1.0000
1.4700 2703.3333 1.0000
1.4760 2594.1667 1.0000
1.4820 2502.5000 1.0000
1.4880 2462.6667 1.0000
1.4940 2420.5000 1.0000
1.5000 2384.1667 1.0000
1.5060 2366.6667 1.0000
1.5120 2192.8333 1.0000
1.5180 2261.3333 1.0000
1.5240 2208.8333 1.0000
1.5300 2194.1667 1.0000
1.5360 2090.8333 1.0000
1.5420 2139.5000 1.0000
1.5480 2012.8334 1.0000
1.5540 2018.6666 1.0000
1.5600 1925.5000 1.0000
1.5660 1882.1666 1.0000
1.5720 1883.6666 1.0000
1.5780 1849.8334 1.0000
1.5840 1719.8334 1.0000
1.5900 1777.5000 1.0000
1.5960 1713.0000 1.0000
1.6020 1656.5000 1.0000
1.6080 1640.6666 1.0000
1.6140 1686.1666 1.0000
1.6200 1629.5000 1.0000
1.6260 1561.8334 1.0000
1.6320 1648.6666 1.0000
1.6380 1523.3334 1.0000
1.6440 1534.5000 1.0000
1.6500 1503.1666 1.0000
1.6560 1458.0000 1.0000
1.6620 1481.8334 1.0000
1.6680 1514.1666 1.0000
1.6740 1475.1666 1.0000
1.6800 1447.3334 1.0000
1.6860 1430.3334 1.0000
1.6920 1374.5000 1.0000
1.6980 1386.1666 1.0000
1.7040 1394.1666 1.0000
1.7100 1410.6666 1.0000
1.7160 1417.1666 1.0000
1.7220 1315.5000 1.0000
1.7280 1308.5000 1.0000
1.7340 1287.6666 1.0000
1.7400 1325.6666 1.0000
1.7460 1279.6666 1.0000
1.7520 1330.6666 1.0000
1.7580 1248.5000 1.0000
1.7640 1237.6666 1.0000
1.7700 1195.8334 1.0000
1.7760 1260.3334 1.0000
1.7820 1163.0000 1.0000
1.7880 1130.3334 1.0000
1.7940 1134.6666 1.0000
1.8000 1146.6666 1.0000
1.8060 1127.8334 1.0000
1.8120 1067.6666 1.0000
1.8180 1051.6666 1.0000
1.8240 1038.5000 1.0000
1.8300 1030.6666 1.0000
1.8360 1017.8333 1.0000
1.8420 958.8333 1.0000
1.8480 967.5000 1.0000
1.8540 980.5000 1.0000
1.8600 926.3333 1.0000
1.8660 915.8333 1.0000
1.8720 894.8333 1.0000
1.8780 902.3333 1.0000
1.8840 877.0000 1.0000
1.8900 879.5000 1.0000
1.8960 794.1667 1.0000
1.9020 823.1667 1.0000
1.9080 829.5000 1.0000
1.9140 798.8333 1.0000
1.9200 816.0000 1.0000
1.9260 764.5000 1.0000
1.9320 792.6667 1.0000
1.9380 746.1667 1.0000
1.9440 768.8333 1.0000
1.9500 752.8333 1.0000
1.9560 746.0000 1.0000
1.9620 711.3333 1.0000
1.9680 734.3333 1.0000
1.9740 733.0000 1.0000
1.9800 705.1667 1.0000
1.9860 676.5000 1.0000
1.9920 731.3333 1.0000
1.9980 664.6667 1.0000
2.0040 723.1667 1.0000
2.0100 689.1667 1.0000
2.0160 650.0000 1.0000
2.0220 678.3333 1.0000
2.0280 642.3333 1.0000
2.0340 663.3333 1.0000
2.0400 649.8333 1.0000
2.0460 656.8333 1.0000
2.0520 643.0000 1.0000
2.0580 651.1667 1.0000
2.0640 594.5000 1.0000
2.0700 667.0000 1.0000
2.0760 617.5000 1.0000
2.0820 635.5000 1.0000
2.0880 617.6667 1.0000
2.0940 591.1667 1.0000
2.1000 613.0000 1.0000
2.1060 543.6667 1.0000
2.1120 531.5000 1.0000
2.1180 542.0000 1.0000
2.1240 571.8333 1.0000
2.1300 572.0000 1.0000
2.1360 549.3333 1.0000
2.1420 509.0000 1.0000
2.1480 521.0000 1.0000
2.1540 507.8333 1.0000
2.1600 528.8333 1.0000
2.1660 498.3333 1.0000
2.1720 469.8333 1.0000
2.1780 496.5000 1.0000
2.1840 506.3333 1.0000
2.1900 447.1667 1.0000
2.1960 460.5000 1.0000
2.2020 460.0000 1.0000
2.2080 442.3333 1.0000
2.2140 435.8333 1.0000
2.2200 432.1667 1.0000
2.2260 433.0000 1.0000
2.2320 442.0000 1.0000
2.2380 408.1667 1.0000
2.2440 477.6667 1.0000
2.2500 412.8333 1.0000
2.2560 415.0000 1.0000
2.2620 398.3333 1.0000
2.2680 391.5000 1.0000
2.2740 405.0000 1.0000
2.2800 330.5000 1.0000
2.2860 383.6667 1.0000
2.2920 376.5000 1.0000
2.2980 348.8333 1.0000
2.3040 395.8333 1.0000
2.3100 369.0000 1.0000
2.3160 344.1667 1.0000
2.3220 332.0000 1.0000
2.3280 353.6667 1.0000
2.3340 363.3333 1.0000
2.3400 323.3333 1.0000
2.3460 368.5000 1.0000
2.3520 330.3333 1.0000
2.3580 334.1667 1.0000
2.3640 318.6667 1.0000
2.3700 354.6667 1.0000
2.3760 335.3333 1.0000
2.3820 327.5000 1.0000
2.3880 331.0000 1.0000
2.3940 349.6667 1.0000
2.4000 312.3333 1.0000
2.4060 316.3333 1.0000
2.4120 322.3333 1.0000
2.4180 310.5000 1.0000
2.4240 304.3333 1.0000
2.4300 338.5000 1.0000
2.4360 308.0000 1.0000
2.4420 299.0000 1.0000
2.4480 286.8333 1.0000
2.4540 255.1667 1.0000
2.4600 256.8333 1.0000
2.4660 255.0000 1.0000
2.4720 277.3333 1.0000
2.4780 273.6667 1.0000
2.4840 252.1667 1.0000
2.4900 255.0000 1.0000
2.4960 279.1667 1.0000
2.5020 266.5000 1.0000
2.5080 263.8333 1.0000
2.5140 228.5000 1.0000
2.5200 237.1667 1.0000
2.5260 232.1667 1.0000
2.5320 235.1667 1.0000
2.5380 231.6667 1.0000
2.5440 208.5000 1.0000
2.5500 241.8333 1.0000
2.5560 222.6667 1.0000
2.5620 214.6667 1.0000
2.5680 213.5000 1.0000
2.5740 223.0000 1.0000
2.5800 195.5000 1.0000
2.5860 198.0000 1.0000
2.5920 214.0000 1.0000
2.5980 207.3333 1.0000
2.6040 217.6667 1.0000
2.6100 224.5000 1.0000
2.6160 214.3333 1.0000
2.6220 204.1667 1.0000
2.6280 184.0000 1.0000
2.6340 206.1667 1.0000
2.6400 215.0000 1.0000
2.6460 211.5000 1.0000
2.6520 211.1667 1.0000
2.6580 205.1667 1.0000
2.6640 189.5000 1.0000
2.6700 204.6667 1.0000
2.6760 208.1667 1.0000
2.6820 184.8333 1.0000
2.6880 195.0000 1.0000
2.6940 191.3333 1.0000
2.7000 191.5000 1.0000
2.7060 183.3333 1.0000
2.7120 173.1667 1.0000
2.7180 168.8333 1.0000
2.7240 196.1667 1.0000
2.7300 200.3333 1.0000
2.7360 174.0000 1.0000
2.7420 177.5000 1.0000
2.7480 177.6667 1.0000
2.7540 180.1667 1.0000
2.7600 182.0000 1.0000
2.7660 161.6667 1.0000
2.7720 146.8333 1.0000
2.7780 144.5000 1.0000
2.7840 159.5000 1.0000
2.7900 169.8333 1.0000
2.7960 148.3333 1.0000
2.8020 147.6667 1.0000
2.8080 153.3333 1.0000
2.8140 155.0000 1.0000
2.8200 144.1667 1.0000
2.8260 137.0000 1.0000
2.8320 152.6667 1.0000
2.8380 137.1667 1.0000
2.8440 140.0000 1.0000
2.8500 123.6667 1.0000
2.8560 141.3333 1.0000
2.8620 117.0000 1.0000
2.8680 121.0000 1.0000
2.8740 137.5000 1.0000
2.8800 141.3333 1.0000
2.8860 115.3333 1.0000
2.8920 115.6667 1.0000
2.8980 137.1667 1.0000
2.9040 144.5000 1.0000
2.9100 131.8333 1.0000
2.9160 129.1667 1.0000
2.9220 105.6667 1.0000
2.9280 99.5000 1.0000
2.9340 117.8333 1.0000
2.9400 128.1667 1.0000
2.9460 119.8333 1.0000
2.9520 97.1667 1.0000
2.9580 126.6667 1.0000
2.9640 114.8333 1.0000
2.9700 123.8333 1.0000
2.9760 107.8333 1.0000
2.9820 106.8333 1.0000
2.9880 114.3333 1.0000
2.9940 124.3333 1.0000
3.0000 128.6667 1.0000
3.0060 132.8333 1.0000
3.0120 105.1667 1.0000
3.0180 106.6667 1.0000
3.0240 121.3333 1.0000
3.0300 87.5000 1.0000
3.0360 104.6667 1.0000
3.0420 95.5000 1.0000
3.0480 100.5000 1.0000
3.0540 97.5000 1.0000
3.0600 118.0000 1.0000
3.0660 111.8333 1.0000
3.0720 112.5000 1.0000
3.0780 93.1667 1.0000
3.0840 87.0000 1.0000
3.0900 101.6667 1.0000
3.0960 100.6667 1.0000
3.1020 90.3333 1.0000
3.1080 88.3333 1.0000
3.1140 85.6667 1.0000
3.1200 99.1667 1.0000
3.1260 85.1667 1.0000
3.1320 85.3333 1.0000
3.1380 80.1667 1.0000
3.1440 70.5000 1.0000
3.1500 78.5000 1.0000
3.1560 69.8333 1.0000
3.1620 84.1667 1.0000
3.1680 86.0000 1.0000
3.1740 78.5000 1.0000
3.1800 83.8333 1.0000
3.1860 89.8333 1.0000
3.1920 84.8333 1.0000
3.1980 63.8333 1.0000
3.2040 79.8333 1.0000
3.2100 88.1667 1.0000
3.2160 71.5000 1.0000
3.2220 93.8333 1.0000
3.2280 85.6667 1.0000
3.2340 60.0000 1.0000
3.2400 53.1667 1.0000
3.2460 72.8333 1.0000
3.2520 58.6667 1.0000
3.2580 60.3333 1.0000
3.2640 60.8333 1.0000
3.2700 69.8333 1.0000
3.2760 75.1667 1.0000
3.2820 62.5000 1.0000
3.2880 78.0000 1.0000
3.2940 59.1667 1.0000
3.3000 78.3333 1.0000
3.3060 61.6667 1.0000
3.3120 64.1667 1.0000
3.3180 63.3333 1.0000
3.3240 61.3333 1.0000
3.3300 48.5000 1.0000
3.3360 54.5000 1.0000
3.3420 63.6667 1.0000
3.3480 61.1667 1.0000
3.3540 91.5000 1.0000
3.3600 63.3333 1.0000
3.3660 60.0000 1.0000
3.3720 54.1667 1.0000
3.3780 49.6667 1.0000
3.3840 65.6667 1.0000
3.3900 57.1667 1.0000
3.3960 54.6667 1.0000
3.4020 59.8333 1.0000
3.4080 59.5000 1.0000
3.4140 57.3333 1.0000
3.4200 63.5000 1.0000
3.4260 64.0000 1.0000
3.4320 46.5000 1.0000
3.4380 45.1667 1.0000
3.4440 46.8333 1.0000
3.4500 44.8333 1.0000
3.4560 63.5000 1.0000
3.4620 45.6667 1.0000
3.4680 54.8333 1.0000
3.4740 36.5000 1.0000
3.4800 44.6667 1.0000
3.4860 47.3333 1.0000
3.4920 43.8333 1.0000
3.4980 49.8333 1.0000
3.5040 49.3333 1.0000
3.5100 25.6667 1.0000
3.5160 59.0000 1.0000
3.5220 44.1667 1.0000
3.5280 47.3333 1.0000
3.5340 43.1667 1.0000
3.5400 57.0000 1.0000
3.5460 42.3333 1.0000
3.5520 47.1667 1.0000
3.5580 43.8333 1.0000
3.5640 47.5000 1.0000
3.5700 43.1667 1.0000
3.5760 38.6667 1.0000
3.5820 42.8333 1.0000
3.5880 39.5000 1.0000
3.5940 35.5000 1.0000
3.6000 43.3333 1.0000
3.6060 29.8333 1.0000
3.6120 23.3333 1.0000
3.6180 35.6667 1.0000
3.6240 30.5000 1.0000
3.6300 30.5000 1.0000
3.6360 43.3333 1.0000
3.6420 36.3333 1.0000
3.6480 40.6667 1.0000
3.6540 34.0000 1.0000
3.6600 26.1667 1.0000
3.6660 39.1667 1.0000
3.6720 42.8333 1.0000
3.6780 27.5000 1.0000
3.6840 36.0000 1.0000
3.6900 25.1667 1.0000
3.6960 37.6667 1.0000
3.7020 38.8333 1.0000
3.7080 34.1667 1.0000
3.7140 23.8333 1.0000
3.7200 28.0000 1.0000
3.7260 33.3333 1.0000
3.7320 30.5000 1.0000
3.7380 22.3333 1.0000
3.7440 46.3333 1.0000
3.7500 42.3333 1.0000
3.7560 34.5000 1.0000
3.7620 39.8333 1.0000
3.7680 35.8333 1.0000
3.7740 28.5000 1.0000
3.7800 25.6667 1.0000
3.7860 29.3333 1.0000
3.7920 32.1667 1.0000
3.7980 34.1667 1.0000
3.8040 22.1667 1.0000
3.8100 21.8333 1.0000
3.8160 29.1667 1.0000
3.8220 19.1667 1.0000
3.8280 31.3333 1.0000
3.8340 34.3333 1.0000
3.8400 33.8333 1.0000
3.8460 23.8333 1.0000
3.8520 18.0000 1.0000
3.8580 19.0000 1.0000
3.8640 30.6667 1.0000
3.8700 22.0000 1.0000
3.8760 43.1667 1.0000
3.8820 30.6667 1.0000
3.8880 20.5000 1.0000
3.8940 26.0000 1.0000
3.9000 26.8333 1.0000
3.9060 27.6667 1.0000
3.9120 21.3333 1.0000
3.9180 24.3333 1.0000
3.9240 25.0000 1.0000
3.9300 24.6667 1.0000
3.9360 19.1667 1.0000
3.9420 21.1667 1.0000
3.9480 30.8333 1.0000
3.9540 25.5000 1.0000
3.9600 21.8333 1.0000
3.9660 26.3333 1.0000
3.9720 18.6667 1.0000
3.9780 32.1667 1.0000
3.9840 20.5000 1.0000
3.9900 21.0000 1.0000
3.9960 22.0000 1.0000
4.0020 19.8333 1.0000
4.0080 20.1667 1.0000
4.0140 19.6667 1.0000
4.0200 24.5000 1.0000
4.0260 28.3333 1.0000
4.0320 24.8333 1.0000
4.0380 17.6667 1.0000
4.0440 20.8333 1.0000
4.0500 17.6667 1.0000
4.0560 17.6667 1.0000
4.0620 34.5000 1.0000
4.0680 22.6667 1.0000
4.0740 34.3333 1.0000
4.0800 14.8333 1.0000
4.0860 29.6667 1.0000
4.0920 24.8333 1.0000
4.0980 21.8333 1.0000
4.1040 23.5000 1.0000
4.1100 17.6667 1.0000
4.1160 25.0000 1.0000
4.1220 13.3333 1.0000
4.1280 20.0000 1.0000
4.1340 17.5000 1.0000
4.1400 15.3333 1.0000
4.1460 21.5000 1.0000
4.1520 20.0000 1.0000
4.1580 18.6667 1.0000
4.1640 12.1667 1.0000
4.1700 13.6667 1.0000
4.1760 13.5000 1.0000
4.1820 19.1667 1.0000
4.1880 12.8333 1.0000
4.1940 15.6667 1.0000
4.2000 11.1667 1.0000
4.2060 12.3333 1.0000
4.2120 31.6667 1.0000
4.2180 12.1667 1.0000
4.2240 15.5000 1.0000
4.2300 22.8333 1.0000
4.2360 11.6667 1.0000
4.2420 17.8333 1.0000
4.2480 11.3333 1.0000
4.2540 18.3333 1.0000
4.2600 11.1667 1.0000
4.2660 17.3333 1.0000
4.2720 13.5000 1.0000
4.2780 11.5000 1.0000
4.2840 17.5000 1.0000
4.2900 11.8333 1.0000
4.2960 15.1667 1.0000
4.3020 13.3333 1.0000
4.3080 14.3333 1.0000
4.3140 15.3333 1.0000
4.3200 9.3333 1.0000
4.3260 11.3333 1.0000
4.3320 11.6667 1.0000
4.3380 17.6667 1.0000
4.3440 11.6667 1.0000
4.3500 14.6667 1.0000
4.3560 11.8333 1.0000
4.3620 12.8333 1.0000
4.3680 14.3333 1.0000
4.3740 13.1667 1.0000
4.3800 13.6667 1.0000
4.3860 16.0000 1.0000
4.3920 19.8333 1.0000
4.3980 10.1667 1.0000
4.4040 12.6667 1.0000
4.4100 12.0000 1.0000
4.4160 12.3333 1.0000
4.4220 16.6667 1.0000
4.4280 15.3333 1.0000
4.4340 12.1667 1.0000
4.4400 9.5000 1.0000
4.4460 9.0000 1.0000
4.4520 8.8333 1.0000
4.4580 9.0000 1.0000
4.4640 14.8333 1.0000
4.4700 16.0000 1.0000
4.4760 5.3333 1.0000
4.4820 6.0000 1.0000
4.4880 16.0000 1.0000
4.4940 9.1667 1.0000
4.5000 8.6667 1.0000
4.5060 11.5000 1.0000
4.5120 5.1667 1.0000
4.5180 7.5000 1.0000
4.5240 7.3333 1.0000
4.5300 9.6667 1.0000
4.5360 9.3333 1.0000
4.5420 13.3333 1.0000
4.5480 8.6667 1.0000
4.5540 4.1667 1.0000
4.5600 8.6667 1.0000
4.5660 12.3333 1.0000
4.5720 7.0000 1.0000
4.5780 7.8333 1.0000
4.5840 11.1667 1.0000
4.5900 5.5000 1.0000
4.5960 13.0000 1.0000
4.6020 8.0000 1.0000
4.6080 7.3333 1.0000
4.6140 11.1667 1.0000
4.6200 7.8333 1.0000
4.6260 6.6667 1.0000
4.6320 10.3333 1.0000
4.6380 3.1667 1.0000
4.6440 14.5000 1.0000
4.6500 12.0000 1.0000
4.6560 6.8333 1.0000
4.6620 18.6667 1.0000
4.6680 4.6667 1.0000
4.6740 9.5000 1.0000
4.6800 8.3333 1.0000
4.6860 10.5000 1.0000
4.6920 6.6667 1.0000
4.6980 6.3333 1.0000
4.7040 5.6667 1.0000
4.7100 7.3333 1.0000
4.7160 7.5000 1.0000
4.7220 9.0000 1.0000
4.7280 1.1667 1.0000
4.7340 8.1667 1.0000
4.7400 10.5000 1.0000
4.7460 7.6667 1.0000
4.7520 5.5000 1.0000
4.7580 5.8333 1.0000
4.7640 3.8333 1.0000
4.7700 6.6667 1.0000
4.7760 9.0000 1.0000
4.7820 6.6667 1.0000
4.7880 3.3333 1.0000
4.7940 5.1667 1.0000
4.8000 7.6667 1.0000
4.8060 7.3333 1.0000
4.8120 3.3333 1.0000
4.8180 4.5000 1.0000
4.8240 5.8333 1.0000
4.8300 2.6667 1.0000
4.8360 11.5000 1.0000
4.8420 7.6667 1.0000
4.8480 3.3333 1.0000
4.8540 0.5000 1.0000
4.8600 5.6667 1.0000
4.8660 4.1667 1.0000
4.8720 7.1667 1.0000
4.8780 7.6667 1.0000
4.8840 3.3333 1.0000
4.8900 6.1667 1.0000
4.8960 9.1667 1.0000
4.9020 7.6667 1.0000
4.9080 3.3333 1.0000
4.9140 1.1667 1.0000
4.9200 11.3333 1.0000
4.9260 7.3333 1.0000
4.9320 2.3333 1.0000
4.9380 3.5000 1.0000
4.9440 8.1667 1.0000
4.9500 3.8333 1.0000
4.9560 3.3333 1.0000
4.9620 7.1667 1.0000
4.9680 0.1667 1.0000
4.9740 2.8333 1.0000
4.9800 7.8333 1.0000
4.9860 5.5000 1.0000
4.9920 2.3333 1.0000
4.9980 9.5000 1.0000
5.0040 9.1667 1.0000
5.0100 0.1667 1.0000
5.0160 7.5000 1.0000
5.0220 4.1667 1.0000
5.0280 3.3333 1.0000
5.0340 6.0000 1.0000
5.0400 5.1667 1.0000
5.0460 2.1667 1.0000
5.0520 6.5000 1.0000
5.0580 8.1667 1.0000
5.0640 9.3333 1.0000
5.0700 6.3333 1.0000
5.0760 2.5000 1.0000
5.0820 5.0000 1.0000
5.0880 4.0000 1.0000
5.0940 1.5000 1.0000
5.1000 2.5000 1.0000
5.1060 1.1667 1.0000
5.1120 3.5000 1.0000
5.1180 3.1667 1.0000
5.1240 6.0000 1.0000
5.1300 4.6667 1.0000
5.1360 8.3333 1.0000
5.1420 0.1667 1.0000
5.1480 8.3333 1.0000
5.1540 3.3333 1.0000
5.1600 3.3333 1.0000
5.1660 6.0000 1.0000
5.1720 5.1667 1.0000
5.1780 5.0000 1.0000
5.1840 5.0000 1.0000
5.1900 2.1667 1.0000
5.1960 6.5000 1.0000
5.2020 2.3333 1.0000
5.2080 4.0000 1.0000
5.2140 0.3333 1.0000
5.2200 0.0000 1.0000
5.2260 0.1667 1.0000
5.2320 1.6667 1.0000
5.2380 0.1667 1.0000
5.2440 3.0000 1.0000
5.2500 3.1667 1.0000
5.2560 2.3333 1.0000
5.2620 4.3333 1.0000
5.2680 0.0000 1.0000
5.2740 2.1667 1.0000
5.2800 0.3333 1.0000
5.2860 7.3333 1.0000
5.2920 0.0000 1.0000
5.2980 1.1667 1.0000
5.3040 1.1667 1.0000
5.3100 0.0000 1.0000
5.3160 2.1667 1.0000
5.3220 1.3333 1.0000
5.3280 3.3333 1.0000
5.3340 5.0000 1.0000
5.3400 2.3333 1.0000
5.3460 0.0000 1.0000
5.3520 0.1667 1.0000
5.3580 4.1667 1.0000
5.3640 1.5000 1.0000
5.3700 4.1667 1.0000
5.3760 1.1667 1.0000
5.3820 3.1667 1.0000
5.3880 2.3333 1.0000
5.3940 0.0000 1.0000
5.4000 2.1667 1.0000
5.4060 0.1667 1.0000
5.4120 2.3333 1.0000
5.4180 6.3333 1.0000
5.4240 2.1667 1.0000
5.4300 0.0000 1.0000
5.4360 2.0000 1.0000
5.4420 5.3333 1.0000
5.4480 1.1667 1.0000
5.4540 6.3333 1.0000
5.4600 0.1667 1.0000
5.4660 3.0000 1.0000
5.4720 3.6667 1.0000
5.4780 0.1667 1.0000
5.4840 0.0000 1.0000
5.4900 0.0000 1.0000
5.4960 1.1667 1.0000
5.5020 0.0000 1.0000
5.5080 3.1667 1.0000
5.5140 4.1667 1.0000
5.5200 0.1667 1.0000
5.5260 2.1667 1.0000
5.5320 2.1667 1.0000
5.5380 0.1667 1.0000
5.5440 0.3333 1.0000
5.5500 0.1667 1.0000
5.5560 0.0000 1.0000
5.5620 0.0000 1.0000
5.5680 2.1667 1.0000
5.5740 2.1667 1.0000
5.5800 2.0000 1.0000
5.5860 3.3333 1.0000
5.5920 0.0000 1.0000
5.5980 0.0000 1.0000
5.6040 2.0000 1.0000
5.6100 0.0000 1.0000
5.6160 3.0000 1.0000
5.6220 2.6667 1.0000
5.6280 0.1667 1.0000
5.6340 0.1667 1.0000
5.6400 0.0000 1.0000
5.6460 3.0000 1.0000
5.6520 2.0000 1.0000
5.6580 2.1667 1.0000
5.6640 1.1667 1.0000
5.6700 0.0000 1.0000
5.6760 2.3333 1.0000
5.6820 2.3333 1.0000
5.6880 2.1667 1.0000
5.6940 0.0000 1.0000
5.7000 3.5000 1.0000
5.7060 4.0000 1.0000
5.7120 0.1667 1.0000
5.7180 0.1667 1.0000
5.7240 0.0000 1.0000
5.7300 0.0000 1.0000
5.7360 2.3333 1.0000
5.7420 0.3333 1.0000
5.7480 0.1667 1.0000
5.7540 0.3333 1.0000
5.7600 0.0000 1.0000
5.7660 0.0000 1.0000
5.7720 1.1667 1.0000
5.7780 1.3333 1.0000
5.7840 0.1667 1.0000
5.7900 1.1667 1.0000
5.7960 0.1667 1.0000
5.8020 0.0000 1.0000
5.8080 3.0000 1.0000
5.8140 0.3333 1.0000
5.8200 2.1667 1.0000
5.8260 0.0000 1.0000
5.8320 3.0000 1.0000
5.8380 0.0000 1.0000
5.8440 1.1667 1.0000
5.8500 1.3333 1.0000
5.8560 0.1667 1.0000
5.8620 0.0000 1.0000
5.8680 3.0000 1.0000
5.8740 0.0000 1.0000
5.8800 3.1667 1.0000
5.8860 0.1667 1.0000
5.8920 2.1667 1.0000
5.8980 0.1667 1.0000
5.9040 0.0000 1.0000
5.9100 0.0000 1.0000
5.9160 0.3333 1.0000
5.9220 0.0000 1.0000
5.9280 1.1667 1.0000
5.9340 0.0000 1.0000
5.9400 1.1667 1.0000
5.9460 0.1667 1.0000
5.9520 0.0000 1.0000
5.9580 0.0000 1.0000
5.9640 3.0000 1.0000
5.9700 0.0000 1.0000
5.9760 4.1667 1.0000
5.9820 0.1667 1.0000
5.9880 0.0000 1.0000
5.9940 1.1667 1.0000
6.0000 0.0000 1.0000
*RAS_INT_END
*RAS_DATA_END